<?xml version="1.0" ?>
<sdf version="1.5">
	<model name="Arm robot">
		<link name="base_link">
			<pose>0.0 0.0 0.0 0.0 -0.0 0.0</pose>
			<inertial>
				<mass>1000.0</mass>
				<pose>0 0 0 0 0 0</pose>
				<inertia>
					<ixx>100.0</ixx>
					<ixy>0.0</ixy>
					<ixz>0.0</ixz>
					<iyy>100.0</iyy>
					<iyz>0.0</iyz>
					<izz>100.0</izz>
				</inertia>
			</inertial>
			<collision name="COL_base_link_collision">
				<pose>0.0 0.0 0.5 0.0 -0.0 0.0</pose>
				<geometry>
					<mesh>
						<uri>model://Arm_robot/meshes/collisions/COL_base_link_collision.dae</uri>
					</mesh>
				</geometry>
			</collision>
			<collision name="COL_base_link_collision_1">
				<pose>0.0 0.0 0.5 0.0 -0.0 0.0</pose>
				<geometry>
					<mesh>
						<uri>model://Arm_robot/meshes/collisions/COL_base_link_collision_1.dae</uri>
					</mesh>
				</geometry>
			</collision>
			<collision name="COL_base_link_collision_2">
				<pose>0.0 0.0 0.5 0.0 -0.0 0.0</pose>
				<geometry>
					<mesh>
						<uri>model://Arm_robot/meshes/collisions/COL_base_link_collision_2.dae</uri>
					</mesh>
				</geometry>
			</collision>
			<visual name="VIS_base_link_visual">
				<pose>0.0 0.0 0.5 0.0 -0.0 0.0</pose>
				<geometry>
					<mesh>
						<uri>model://Arm_robot/meshes/visual/VIS_base_link_visual.dae</uri>
					</mesh>
				</geometry>
			</visual>
		</link>
		<link name="hollie_real_left_arm">
			<pose>0.0 -0.40000000596 1.0 0.0 -0.0 1.623156189918518</pose>
			<inertial>
				<mass>0.29363998770713806</mass>
				<pose>0 0 0 0 0 0</pose>
				<inertia>
					<ixx>0.009999999776482582</ixx>
					<ixy>0.0</ixy>
					<ixz>0.0</ixz>
					<iyy>0.009999999776482582</iyy>
					<iyz>0.0</iyz>
					<izz>0.009999999776482582</izz>
				</inertia>
			</inertial>
		</link>
		<link name="hollie_real_000">
			<pose>3.46469219811e-18 -0.40000000596 1.1099999994 0.0 -0.0 1.623156189918518</pose>
			<inertial>
				<mass>0.29363998770713806</mass>
				<pose>0 0 0 0 0 0</pose>
				<inertia>
					<ixx>0.009999999776482582</ixx>
					<ixy>0.0</ixy>
					<ixz>0.0</ixz>
					<iyy>0.009999999776482582</iyy>
					<iyz>0.0</iyz>
					<izz>0.009999999776482582</izz>
				</inertia>
			</inertial>
			<collision name="COL_hollie_real.000_collision">
				<pose>3.502620060658046e-08 9.967757108597652e-08 1.3113021850585938e-06 0.0 -0.0 -1.2665987014770508e-07</pose>
				<geometry>
					<mesh>
						<uri>model://Arm_robot/meshes/collisions/COL_hollie_real_000_collision.dae</uri>
					</mesh>
				</geometry>
			</collision>
			<visual name="VIS_hollie_real.000_visual">
				<pose>3.502620060658046e-08 9.967757108597652e-08 1.3113021850585938e-06 -2.1012502315898018e-07 1.1580814529565941e-08 -1.2665987014770508e-07</pose>
				<geometry>
					<mesh>
						<uri>model://Arm_robot/meshes/visual/VIS_hollie_real_000_visual.dae</uri>
					</mesh>
				</geometry>
			</visual>
		</link>
		<link name="hollie_real_001">
			<pose>6.92938439622e-18 -0.40000000596 1.1099999994 1.5707963705062866 -0.0 1.623156189918518</pose>
			<inertial>
				<mass>1.683109998703003</mass>
				<pose>0 0 0 0 0 0</pose>
				<inertia>
					<ixx>0.029999999329447746</ixx>
					<ixy>0.0</ixy>
					<ixz>0.0</ixz>
					<iyy>0.029999999329447746</iyy>
					<iyz>0.0</iyz>
					<izz>0.029999999329447746</izz>
				</inertia>
			</inertial>
			<collision name="COL_hollie_real.001_collision">
				<pose>4.440184220300125e-09 1.5512088111790945e-06 -3.959155669974734e-09 -7.549789415861596e-08 -7.450580596923828e-08 -3.42975354783448e-08</pose>
				<geometry>
					<mesh>
						<uri>model://Arm_robot/meshes/collisions/COL_hollie_real_001_collision.dae</uri>
					</mesh>
				</geometry>
			</collision>
			<visual name="VIS_hollie_real.001_visual">
				<pose>4.440184220300125e-09 1.5512088111790945e-06 -3.959155669974734e-09 -7.549789415861596e-08 4.842877388000488e-08 5.42986633433884e-08</pose>
				<geometry>
					<mesh>
						<uri>model://Arm_robot/meshes/visual/VIS_hollie_real_001_visual.dae</uri>
					</mesh>
				</geometry>
			</visual>
		</link>
		<link name="hollie_real_002">
			<pose>-1.26858188779e-06 -0.400000072444 1.45999999344 1.5707961956607377 -8.742278039484667e-08 -1.5184365510940514</pose>
			<inertial>
				<mass>2.0999999046325684</mass>
				<pose>0 0 0 0 0 0</pose>
				<inertia>
					<ixx>0.029999999329447746</ixx>
					<ixy>0.0</ixy>
					<ixz>0.0</ixz>
					<iyy>0.029999999329447746</iyy>
					<iyz>0.0</iyz>
					<izz>0.029999999329447746</izz>
				</inertia>
			</inertial>
			<collision name="COL_hollie_real.002_collision">
				<pose>-1.6313825312863628e-07 9.193994401357486e-07 1.2008214866909839e-08 1.750278215695289e-07 -3.688037679694389e-07 3.710286122782236e-08</pose>
				<geometry>
					<mesh>
						<uri>model://Arm_robot/meshes/collisions/COL_hollie_real_002_collision.dae</uri>
					</mesh>
				</geometry>
			</collision>
			<visual name="VIS_hollie_real.002_visual">
				<pose>-1.6313825312863628e-07 9.193994401357486e-07 1.2008214866909839e-08 5.581852846603397e-08 5.885958671569824e-07 -1.7066166435597552e-07</pose>
				<geometry>
					<mesh>
						<uri>model://Arm_robot/meshes/visual/VIS_hollie_real_002_visual.dae</uri>
					</mesh>
				</geometry>
			</visual>
		</link>
		<link name="hollie_real_003">
			<pose>-1.26858188779e-06 -0.400000072444 1.45999999344 1.7484554892810745e-07 2.3841857949268303e-07 1.6231561024957617</pose>
			<inertial>
				<mass>1.683109998703003</mass>
				<pose>0 0 0 0 0 0</pose>
				<inertia>
					<ixx>0.10000000149011612</ixx>
					<ixy>0.0</ixy>
					<ixz>0.0</ixz>
					<iyy>0.10000000149011612</iyy>
					<iyz>0.0</iyz>
					<izz>0.10000000149011612</izz>
				</inertia>
			</inertial>
			<collision name="COL_hollie_real.003_collision">
				<pose>2.965595413684241e-08 -2.801496350457455e-07 -5.2729024702102834e-08 6.974032373818773e-08 3.080916854969473e-09 -4.0978225257504164e-08</pose>
				<geometry>
					<mesh>
						<uri>model://Arm_robot/meshes/collisions/COL_hollie_real_003_collision.dae</uri>
					</mesh>
				</geometry>
			</collision>
			<visual name="VIS_hollie_real.003_visual">
				<pose>2.965595413684241e-08 -2.801496350457455e-07 -5.2729024702102834e-08 2.2452533698924526e-07 6.1754015234782855e-09 -4.0978225257504164e-08</pose>
				<geometry>
					<mesh>
						<uri>model://Arm_robot/meshes/visual/VIS_hollie_real_003_visual.dae</uri>
					</mesh>
				</geometry>
			</visual>
		</link>
		<link name="hollie_real_004">
			<pose>-0.0052512203928 -0.400269976584 1.76500000151 1.5707961956607017 -2.384185530917369e-07 -1.5184364000982324</pose>
			<inertial>
				<mass>0.8069999814033508</mass>
				<pose>0 0 0 0 0 0</pose>
				<inertia>
					<ixx>0.029999999329447746</ixx>
					<ixy>0.0</ixy>
					<ixz>0.0</ixz>
					<iyy>0.029999999329447746</iyy>
					<iyz>0.0</iyz>
					<izz>0.029999999329447746</izz>
				</inertia>
			</inertial>
			<collision name="COL_hollie_real.004_collision">
				<pose>-1.6731675600567542e-07 6.537723038491094e-07 -6.429149834730197e-08 1.750278357803836e-07 -2.533197687171196e-07 9.097730568896623e-09</pose>
				<geometry>
					<mesh>
						<uri>model://Arm_robot/meshes/collisions/COL_hollie_real_004_collision.dae</uri>
					</mesh>
				</geometry>
			</collision>
			<visual name="VIS_hollie_real.004_visual">
				<pose>-1.6731675600567542e-07 6.537723038491094e-07 -6.429149834730197e-08 1.4863301203149604e-06 -1.7993152141571045e-06 -1.6434250937891193e-07</pose>
				<geometry>
					<mesh>
						<uri>model://Arm_robot/meshes/visual/VIS_hollie_real_004_visual.dae</uri>
					</mesh>
				</geometry>
			</visual>
		</link>
		<link name="hollie_real_005">
			<pose>-0.0052512203928 -0.400269976584 1.76500000151 -1.7484558489933022e-07 -2.384185530917369e-07 -1.5184364000982324</pose>
			<inertial>
				<mass>0.8190000057220459</mass>
				<pose>0 0 0 0 0 0</pose>
				<inertia>
					<ixx>0.009999999776482582</ixx>
					<ixy>0.0</ixy>
					<ixz>0.0</ixz>
					<iyy>0.009999999776482582</iyy>
					<iyz>0.0</iyz>
					<izz>0.009999999776482582</izz>
				</inertia>
			</inertial>
			<collision name="COL_hollie_real.005_collision">
				<pose>-6.61928254430677e-08 3.525356930822454e-07 1.4763578519705334e-06 2.4868999139735296e-14 -2.398082072003517e-14 -1.7508870087112882e-07</pose>
				<geometry>
					<mesh>
						<uri>model://Arm_robot/meshes/collisions/COL_hollie_real_005_collision.dae</uri>
					</mesh>
				</geometry>
			</collision>
			<visual name="VIS_hollie_real.005_visual">
				<pose>-6.61928254430677e-08 3.525356930822454e-07 1.4763578519705334e-06 1.2880501287781954e-07 -3.815348037505828e-11 4.2468306560294877e-07</pose>
				<geometry>
					<mesh>
						<uri>model://Arm_robot/meshes/visual/VIS_hollie_real_005_visual.dae</uri>
					</mesh>
				</geometry>
			</visual>
		</link>
		<link name="hollie_real_006">
			<pose>-0.00525120417999 -0.40026995186 1.865000003 -1.7484558489933022e-07 -2.384185530917369e-07 -1.5184364000982324</pose>
			<inertial>
				<mass>9.999999747378752e-06</mass>
				<pose>0 0 0 0 0 0</pose>
				<inertia>
					<ixx>0.009999999776482582</ixx>
					<ixy>0.0</ixy>
					<ixz>0.0</ixz>
					<iyy>0.009999999776482582</iyy>
					<iyz>0.0</iyz>
					<izz>0.009999999776482582</izz>
				</inertia>
			</inertial>
			<collision name="COL_hollie_real.006_collision">
				<pose>-1.6401645552832633e-07 9.84966504802287e-07 -0.03199799358844757 -3.375078333673655e-14 -8.437695664777548e-14 -1.7881400538044545e-07</pose>
				<geometry>
					<mesh>
						<uri>model://Arm_robot/meshes/collisions/COL_hollie_real_006_collision.dae</uri>
					</mesh>
				</geometry>
			</collision>
			<visual name="VIS_hollie_real.006_visual">
				<pose>-1.6401645552832633e-07 9.84966504802287e-07 -0.03199799358844757 -5.191037999452419e-08 -7.896225895365205e-10 6.33298924412884e-08</pose>
				<geometry>
					<mesh>
						<uri>model://Arm_robot/meshes/visual/VIS_hollie_real_006_visual.dae</uri>
					</mesh>
				</geometry>
			</visual>
		</link>
		<link name="hollie_real_007">
			<pose>-0.018361201363 -0.400959999037 1.8650000053 -1.7484558489933022e-07 -2.384185530917369e-07 -1.5184364000982324</pose>
			<inertial>
				<mass>9.999999747378752e-06</mass>
				<pose>0 0 0 0 0 0</pose>
				<inertia>
					<ixx>0.009999999776482582</ixx>
					<ixy>0.0</ixy>
					<ixz>0.0</ixz>
					<iyy>0.009999999776482582</iyy>
					<iyz>0.0</iyz>
					<izz>0.009999999776482582</izz>
				</inertia>
			</inertial>
			<collision name="COL_hollie_real.007_collision">
				<pose>-4.105544348931289e-08 0.01313019823282957 2.1919192931818543e-06 -8.8817850440342e-15 -5.595524721737147e-14 -1.7508870087112882e-07</pose>
				<geometry>
					<mesh>
						<uri>model://Arm_robot/meshes/collisions/COL_hollie_real_007_collision.dae</uri>
					</mesh>
				</geometry>
			</collision>
			<visual name="VIS_hollie_real.007_visual">
				<pose>-4.105544348931289e-08 0.01313019823282957 2.1919192931818543e-06 3.141590118408203 2.290735636734098e-07 -6.51925802230835e-07</pose>
				<geometry>
					<mesh>
						<uri>model://Arm_robot/meshes/visual/VIS_hollie_real_007_visual.dae</uri>
					</mesh>
				</geometry>
			</visual>
		</link>
		<link name="hollie_real_008">
			<pose>0.00873885416746 -0.416459901211 1.86500000474 -2.468290531170692e-07 0.2617995699299688 0.05235990652395092</pose>
			<inertial>
				<mass>9.999999747378752e-06</mass>
				<pose>0 0 0 0 0 0</pose>
				<inertia>
					<ixx>0.009999999776482582</ixx>
					<ixy>0.0</ixy>
					<ixz>0.0</ixz>
					<iyy>0.009999999776482582</iyy>
					<iyz>0.0</iyz>
					<izz>0.009999999776482582</izz>
				</inertia>
			</inertial>
			<collision name="COL_hollie_real.008_collision">
				<pose>2.0582228899002075e-07 -7.271654567375663e-07 0.024417871609330177 -7.1366548226592386e-09 8.899950643126431e-08 3.061263242898349e-08</pose>
				<geometry>
					<mesh>
						<uri>model://Arm_robot/meshes/collisions/COL_hollie_real_008_collision.dae</uri>
					</mesh>
				</geometry>
			</collision>
			<visual name="VIS_hollie_real.008_visual">
				<pose>2.0582228899002075e-07 -7.271654567375663e-07 0.024417871609330177 -2.559269887569826e-06 3.1415889263153076 -2.5472886591160204e-06</pose>
				<geometry>
					<mesh>
						<uri>model://Arm_robot/meshes/visual/VIS_hollie_real_008_visual.dae</uri>
					</mesh>
				</geometry>
			</visual>
		</link>
		<link name="hollie_real_left_hand_Thumb_Helper_link">
			<pose>0.020619278112 -0.415839868748 1.90938989184 3.1415915814163577 -1.3089966813669145 0.05236086019726231</pose>
			<inertial>
				<mass>9.999999747378752e-06</mass>
				<pose>0 0 0 0 0 0</pose>
				<inertia>
					<ixx>0.009999999776482582</ixx>
					<ixy>0.0</ixy>
					<ixz>0.0</ixz>
					<iyy>0.009999999776482582</iyy>
					<iyz>0.0</iyz>
					<izz>0.009999999776482582</izz>
				</inertia>
			</inertial>
		</link>
		<link name="hollie_real_009">
			<pose>0.020619278112 -0.415839868748 1.90938989184 -1.8834043242899619 -0.570602331441126 -1.3456024148070085</pose>
			<inertial>
				<mass>9.999999747378752e-06</mass>
				<pose>0 0 0 0 0 0</pose>
				<inertia>
					<ixx>0.009999999776482582</ixx>
					<ixy>0.0</ixy>
					<ixz>0.0</ixz>
					<iyy>0.009999999776482582</iyy>
					<iyz>0.0</iyz>
					<izz>0.009999999776482582</izz>
				</inertia>
			</inertial>
			<collision name="COL_hollie_real.009_collision">
				<pose>1.1101365089416504e-06 2.4423934519290924e-07 -2.905726432800293e-07 -7.63684582238966e-08 2.0116564769523393e-07 1.4901159772762185e-07</pose>
				<geometry>
					<mesh>
						<uri>model://Arm_robot/meshes/collisions/COL_hollie_real_009_collision.dae</uri>
					</mesh>
				</geometry>
			</collision>
			<visual name="VIS_hollie_real.009_visual">
				<pose>1.1101365089416504e-06 2.4423934519290924e-07 -2.905726432800293e-07 -3.141590118408203 3.539025499321724e-07 1.2889503295809845e-06</pose>
				<geometry>
					<mesh>
						<uri>model://Arm_robot/meshes/visual/VIS_hollie_real_009_visual.dae</uri>
					</mesh>
				</geometry>
			</visual>
		</link>
		<link name="hollie_real_010">
			<pose>0.0297291685108 -0.455619831516 1.93558998721 -1.8834043242899619 -0.570602331441126 -1.3456024148070085</pose>
			<inertial>
				<mass>9.999999747378752e-06</mass>
				<pose>0 0 0 0 0 0</pose>
				<inertia>
					<ixx>0.009999999776482582</ixx>
					<ixy>0.0</ixy>
					<ixz>0.0</ixz>
					<iyy>0.009999999776482582</iyy>
					<iyz>0.0</iyz>
					<izz>0.009999999776482582</izz>
				</inertia>
			</inertial>
			<collision name="COL_hollie_real.010_collision">
				<pose>-5.038455128669739e-07 -1.1296942830085754e-06 5.345791578292847e-07 -4.395843120619247e-07 1.4156103134155273e-07 -4.842877388000488e-08</pose>
				<geometry>
					<mesh>
						<uri>model://Arm_robot/meshes/collisions/COL_hollie_real_010_collision.dae</uri>
					</mesh>
				</geometry>
			</collision>
			<visual name="VIS_hollie_real.010_visual">
				<pose>-5.038455128669739e-07 -1.1296942830085754e-06 5.345791578292847e-07 3.141590118408203 -4.0978189730367376e-08 1.8626449218572816e-06</pose>
				<geometry>
					<mesh>
						<uri>model://Arm_robot/meshes/visual/VIS_hollie_real_010_visual.dae</uri>
					</mesh>
				</geometry>
			</visual>
		</link>
		<link name="hollie_real_011">
			<pose>0.0353691007785 -0.480229808961 1.95179004648 -1.8834043242899619 -0.570602331441126 -1.3456024148070085</pose>
			<inertial>
				<mass>9.999999747378752e-06</mass>
				<pose>0 0 0 0 0 0</pose>
				<inertia>
					<ixx>0.009999999776482582</ixx>
					<ixy>0.0</ixy>
					<ixz>0.0</ixz>
					<iyy>0.009999999776482582</iyy>
					<iyz>0.0</iyz>
					<izz>0.009999999776482582</izz>
				</inertia>
			</inertial>
			<collision name="COL_hollie_real.011_collision">
				<pose>-5.820766091346741e-08 -1.7229467630386353e-07 -3.3527612686157227e-08 -6.407499313354492e-07 2.868473814032768e-07 -1.8998983364326705e-07</pose>
				<geometry>
					<mesh>
						<uri>model://Arm_robot/meshes/collisions/COL_hollie_real_011_collision.dae</uri>
					</mesh>
				</geometry>
			</collision>
			<visual name="VIS_hollie_real.011_visual">
				<pose>-5.820766091346741e-08 -1.7229467630386353e-07 -3.3527612686157227e-08 3.141590118408203 3.874302478834579e-07 1.7769636997400085e-06</pose>
				<geometry>
					<mesh>
						<uri>model://Arm_robot/meshes/visual/VIS_hollie_real_011_visual.dae</uri>
					</mesh>
				</geometry>
			</visual>
		</link>
		<link name="hollie_real_left_hand_f1_link">
			<pose>-0.018361201363 -0.400959999037 1.8650000053 -1.7484558489933022e-07 -2.384185530917369e-07 -1.5184364000982324</pose>
			<inertial>
				<mass>9.999999747378752e-06</mass>
				<pose>0 0 0 0 0 0</pose>
				<inertia>
					<ixx>0.009999999776482582</ixx>
					<ixy>0.0</ixy>
					<ixz>0.0</ixz>
					<iyy>0.009999999776482582</iyy>
					<iyz>0.0</iyz>
					<izz>0.009999999776482582</izz>
				</inertia>
			</inertial>
		</link>
		<link name="hollie_real_left_hand_f2_link">
			<pose>-0.018361201363 -0.400959999037 1.8650000053 -1.7484558489933022e-07 -2.384185530917369e-07 -1.5184364000982324</pose>
			<inertial>
				<mass>9.999999747378752e-06</mass>
				<pose>0 0 0 0 0 0</pose>
				<inertia>
					<ixx>0.009999999776482582</ixx>
					<ixy>0.0</ixy>
					<ixz>0.0</ixz>
					<iyy>0.009999999776482582</iyy>
					<iyz>0.0</iyz>
					<izz>0.009999999776482582</izz>
				</inertia>
			</inertial>
		</link>
		<link name="hollie_real_left_hand_f3_link">
			<pose>-0.018361201363 -0.400959999037 1.8650000053 -1.7484558489933022e-07 -2.384185530917369e-07 -1.5184364000982324</pose>
			<inertial>
				<mass>9.999999747378752e-06</mass>
				<pose>0 0 0 0 0 0</pose>
				<inertia>
					<ixx>0.009999999776482582</ixx>
					<ixy>0.0</ixy>
					<ixz>0.0</ixz>
					<iyy>0.009999999776482582</iyy>
					<iyz>0.0</iyz>
					<izz>0.009999999776482582</izz>
				</inertia>
			</inertial>
		</link>
		<link name="hollie_real_012">
			<pose>-0.017051093699 -0.425919966674 1.97500001066 -0.7501074984185336 -1.5707960878092948 0.8024674688265603</pose>
			<inertial>
				<mass>9.999999747378752e-06</mass>
				<pose>0 0 0 0 0 0</pose>
				<inertia>
					<ixx>0.009999999776482582</ixx>
					<ixy>0.0</ixy>
					<ixz>0.0</ixz>
					<iyy>0.009999999776482582</iyy>
					<iyz>0.0</iyz>
					<izz>0.009999999776482582</izz>
				</inertia>
			</inertial>
			<collision name="COL_hollie_real.012_collision">
				<pose>1.820733217527959e-07 -2.5844545348263637e-07 0.013210196048021317 3.352760913344355e-08 5.101668776319457e-08 -1.8900411191680178e-07</pose>
				<geometry>
					<mesh>
						<uri>model://Arm_robot/meshes/collisions/COL_hollie_real_012_collision.dae</uri>
					</mesh>
				</geometry>
			</collision>
			<visual name="VIS_hollie_real.012_visual">
				<pose>1.820733217527959e-07 -2.5844545348263637e-07 0.013210196048021317 4.470348002882929e-08 4.081545057488256e-07 -2.0772087339082645e-07</pose>
				<geometry>
					<mesh>
						<uri>model://Arm_robot/meshes/visual/VIS_hollie_real_012_visual.dae</uri>
					</mesh>
				</geometry>
			</visual>
		</link>
		<link name="hollie_real_013">
			<pose>-0.017051093699 -0.425919966674 1.97500001066 -2.3209038689248205 -1.5707960878092948 0.8024674688265603</pose>
			<inertial>
				<mass>9.999999747378752e-06</mass>
				<pose>0 0 0 0 0 0</pose>
				<inertia>
					<ixx>0.009999999776482582</ixx>
					<ixy>0.0</ixy>
					<ixz>0.0</ixz>
					<iyy>0.009999999776482582</iyy>
					<iyz>0.0</iyz>
					<izz>0.009999999776482582</izz>
				</inertia>
			</inertial>
			<collision name="COL_hollie_real.013_collision">
				<pose>-4.3098827973153675e-07 -1.2665623216889799e-08 1.0136992045772786e-07 -1.1548395661975519e-07 2.1880642009364237e-07 -4.397820774215688e-08</pose>
				<geometry>
					<mesh>
						<uri>model://Arm_robot/meshes/collisions/COL_hollie_real_013_collision.dae</uri>
					</mesh>
				</geometry>
			</collision>
			<visual name="VIS_hollie_real.013_visual">
				<pose>-4.3098827973153675e-07 -1.2665623216889799e-08 1.0136992045772786e-07 -2.9765069484710693e-06 2.1256749960230081e-07 -1.630241257544185e-07</pose>
				<geometry>
					<mesh>
						<uri>model://Arm_robot/meshes/visual/VIS_hollie_real_013_visual.dae</uri>
					</mesh>
				</geometry>
			</visual>
		</link>
		<link name="hollie_real_014">
			<pose>-0.0170509615857 -0.425920235852 2.02304000952 -2.3209038689248205 -1.5707960878092948 0.8024674688265603</pose>
			<inertial>
				<mass>9.999999747378752e-06</mass>
				<pose>0 0 0 0 0 0</pose>
				<inertia>
					<ixx>0.009999999776482582</ixx>
					<ixy>0.0</ixy>
					<ixz>0.0</ixz>
					<iyy>0.009999999776482582</iyy>
					<iyz>0.0</iyz>
					<izz>0.009999999776482582</izz>
				</inertia>
			</inertial>
			<collision name="COL_hollie_real.014_collision">
				<pose>1.6505802591382235e-07 -4.227253498356731e-07 -1.2170801255706465e-08 -6.705518273975031e-08 2.1880640588278766e-07 -4.39782219530116e-08</pose>
				<geometry>
					<mesh>
						<uri>model://Arm_robot/meshes/collisions/COL_hollie_real_014_collision.dae</uri>
					</mesh>
				</geometry>
			</collision>
			<visual name="VIS_hollie_real.014_visual">
				<pose>1.6505802591382235e-07 -4.227253498356731e-07 -1.2170801255706465e-08 -2.8051435947418213e-06 2.1256749960230081e-07 -1.630241399652732e-07</pose>
				<geometry>
					<mesh>
						<uri>model://Arm_robot/meshes/visual/VIS_hollie_real_014_visual.dae</uri>
					</mesh>
				</geometry>
			</visual>
		</link>
		<link name="hollie_real_015">
			<pose>-0.0170508900839 -0.425920381536 2.04904001006 -2.3209038689248205 -1.5707960878092948 0.8024674688265603</pose>
			<inertial>
				<mass>9.999999747378752e-06</mass>
				<pose>0 0 0 0 0 0</pose>
				<inertia>
					<ixx>0.009999999776482582</ixx>
					<ixy>0.0</ixy>
					<ixz>0.0</ixz>
					<iyy>0.009999999776482582</iyy>
					<iyz>0.0</iyz>
					<izz>0.009999999776482582</izz>
				</inertia>
			</inertial>
			<collision name="COL_hollie_real.015_collision">
				<pose>-3.117791038675932e-07 4.232504124956904e-08 -4.3108894942633924e-07 -7.078046593278486e-08 2.1880637746107823e-07 -4.3978232611152634e-08</pose>
				<geometry>
					<mesh>
						<uri>model://Arm_robot/meshes/collisions/COL_hollie_real_015_collision.dae</uri>
					</mesh>
				</geometry>
			</collision>
			<visual name="VIS_hollie_real.015_visual">
				<pose>-3.117791038675932e-07 4.232504124956904e-08 -4.3108894942633924e-07 -2.5704500785650453e-06 2.250452979524198e-07 7.506766763754058e-08</pose>
				<geometry>
					<mesh>
						<uri>model://Arm_robot/meshes/visual/VIS_hollie_real_015_visual.dae</uri>
					</mesh>
				</geometry>
			</visual>
		</link>
		<link name="hollie_real_016">
			<pose>-0.0183611835289 -0.40095997184 1.9750000047 -0.7501074984185336 -1.5707960878092948 0.8024674688265603</pose>
			<inertial>
				<mass>9.999999747378752e-06</mass>
				<pose>0 0 0 0 0 0</pose>
				<inertia>
					<ixx>0.009999999776482582</ixx>
					<ixy>0.0</ixy>
					<ixz>0.0</ixz>
					<iyy>0.009999999776482582</iyy>
					<iyz>0.0</iyz>
					<izz>0.009999999776482582</izz>
				</inertia>
			</inertial>
			<collision name="COL_hollie_real.016_collision">
				<pose>-1.773834270579755e-07 -1.0730068424891215e-06 0.013210099190473557 7.450581485102248e-09 4.3566096508129704e-08 -1.2939946714141115e-07</pose>
				<geometry>
					<mesh>
						<uri>model://Arm_robot/meshes/collisions/COL_hollie_real_016_collision.dae</uri>
					</mesh>
				</geometry>
			</collision>
			<visual name="VIS_hollie_real.016_visual">
				<pose>-1.773834270579755e-07 -1.0730068424891215e-06 0.013210099190473557 1.1548399214689198e-07 4.007038683084829e-07 -1.4811625703714526e-07</pose>
				<geometry>
					<mesh>
						<uri>model://Arm_robot/meshes/visual/VIS_hollie_real_016_visual.dae</uri>
					</mesh>
				</geometry>
			</visual>
		</link>
		<link name="hollie_real_017">
			<pose>-0.0183611835289 -0.40095997184 1.9750000047 -2.3209038689248205 -1.5707960878092948 0.8024674688265603</pose>
			<inertial>
				<mass>9.999999747378752e-06</mass>
				<pose>0 0 0 0 0 0</pose>
				<inertia>
					<ixx>0.009999999776482582</ixx>
					<ixy>0.0</ixy>
					<ixz>0.0</ixz>
					<iyy>0.009999999776482582</iyy>
					<iyz>0.0</iyz>
					<izz>0.009999999776482582</izz>
				</inertia>
			</inertial>
			<collision name="COL_hollie_real.017_collision">
				<pose>-7.093109388733865e-08 1.1585674997149908e-07 -7.596530622322462e-07 -5.587929763350985e-08 1.654406815987386e-07 7.506769605925001e-08</pose>
				<geometry>
					<mesh>
						<uri>model://Arm_robot/meshes/collisions/COL_hollie_real_017_collision.dae</uri>
					</mesh>
				</geometry>
			</collision>
			<visual name="VIS_hollie_real.017_visual">
				<pose>-7.093109388733865e-08 1.1585674997149908e-07 -7.596530622322462e-07 4.2095786056961515e-07 1.654406815987386e-07 7.506769605925001e-08</pose>
				<geometry>
					<mesh>
						<uri>model://Arm_robot/meshes/visual/VIS_hollie_real_017_visual.dae</uri>
					</mesh>
				</geometry>
			</visual>
		</link>
		<link name="hollie_real_018">
			<pose>-0.0183610459154 -0.400960252225 2.02504000389 -2.3209038689248205 -1.5707960878092948 0.8024674688265603</pose>
			<inertial>
				<mass>9.999999747378752e-06</mass>
				<pose>0 0 0 0 0 0</pose>
				<inertia>
					<ixx>0.009999999776482582</ixx>
					<ixy>0.0</ixy>
					<ixz>0.0</ixz>
					<iyy>0.009999999776482582</iyy>
					<iyz>0.0</iyz>
					<izz>0.009999999776482582</izz>
				</inertia>
			</inertial>
			<collision name="COL_hollie_real.018_collision">
				<pose>-1.501442397966457e-06 6.291925274126697e-07 -5.03334149470902e-07 -6.332989954671575e-08 1.5920174689654232e-07 -4.39782219530116e-08</pose>
				<geometry>
					<mesh>
						<uri>model://Arm_robot/meshes/collisions/COL_hollie_real_018_collision.dae</uri>
					</mesh>
				</geometry>
			</collision>
			<visual name="VIS_hollie_real.018_visual">
				<pose>-1.501442397966457e-06 6.291925274126697e-07 -5.03334149470902e-07 5.960467319710006e-08 1.5920174689654232e-07 -4.39782219530116e-08</pose>
				<geometry>
					<mesh>
						<uri>model://Arm_robot/meshes/visual/VIS_hollie_real_018_visual.dae</uri>
					</mesh>
				</geometry>
			</visual>
		</link>
		<link name="hollie_real_019">
			<pose>-0.0183609579132 -0.400960431528 2.05704000541 -2.3209038689248205 -1.5707960878092948 0.8024674688265603</pose>
			<inertial>
				<mass>9.999999747378752e-06</mass>
				<pose>0 0 0 0 0 0</pose>
				<inertia>
					<ixx>0.009999999776482582</ixx>
					<ixy>0.0</ixy>
					<ixz>0.0</ixz>
					<iyy>0.009999999776482582</iyy>
					<iyz>0.0</iyz>
					<izz>0.009999999776482582</izz>
				</inertia>
			</inertial>
			<collision name="COL_hollie_real.019_collision">
				<pose>-7.093117204703958e-08 -1.0300618669134565e-07 -8.32249440918531e-07 -6.332989954671575e-08 1.5920176110739703e-07 -4.397822550572528e-08</pose>
				<geometry>
					<mesh>
						<uri>model://Arm_robot/meshes/collisions/COL_hollie_real_019_collision.dae</uri>
					</mesh>
				</geometry>
			</collision>
			<visual name="VIS_hollie_real.019_visual">
				<pose>-7.093117204703958e-08 -1.0300618669134565e-07 -8.32249440918531e-07 -5.401670932769775e-07 1.529628548269102e-07 -1.630241399652732e-07</pose>
				<geometry>
					<mesh>
						<uri>model://Arm_robot/meshes/visual/VIS_hollie_real_019_visual.dae</uri>
					</mesh>
				</geometry>
			</visual>
		</link>
		<link name="hollie_real_020">
			<pose>-0.0133312627298 -0.38226997201 1.90250000135 -1.7484558489933022e-07 -2.384185530917369e-07 -1.5184364000982324</pose>
			<inertial>
				<mass>9.999999747378752e-06</mass>
				<pose>0 0 0 0 0 0</pose>
				<inertia>
					<ixx>0.009999999776482582</ixx>
					<ixy>0.0</ixy>
					<ixz>0.0</ixz>
					<iyy>0.009999999776482582</iyy>
					<iyz>0.0</iyz>
					<izz>0.009999999776482582</izz>
				</inertia>
			</inertial>
			<collision name="COL_hollie_real.020_collision">
				<pose>0.0006995591102167964 1.979294381726504e-07 -0.010019254870712757 -8.8817850440342e-15 -5.595524721737147e-14 -1.7881400538044545e-07</pose>
				<geometry>
					<mesh>
						<uri>model://Arm_robot/meshes/collisions/COL_hollie_real_020_collision.dae</uri>
					</mesh>
				</geometry>
			</collision>
			<visual name="VIS_hollie_real.020_visual">
				<pose>0.0006995591102167964 1.979294381726504e-07 -0.010019254870712757 3.141590118408203 -2.3037616259102833e-08 -4.1723257027115324e-07</pose>
				<geometry>
					<mesh>
						<uri>model://Arm_robot/meshes/visual/VIS_hollie_real_020_visual.dae</uri>
					</mesh>
				</geometry>
			</visual>
		</link>
		<link name="hollie_real_left_hand_f5_link">
			<pose>-0.019331261753 -0.382579993617 1.9025000024 -1.7484558489933022e-07 -2.384185530917369e-07 -1.5184364000982324</pose>
			<inertial>
				<mass>9.999999747378752e-06</mass>
				<pose>0 0 0 0 0 0</pose>
				<inertia>
					<ixx>0.009999999776482582</ixx>
					<ixy>0.0</ixy>
					<ixz>0.0</ixz>
					<iyy>0.009999999776482582</iyy>
					<iyz>0.0</iyz>
					<izz>0.009999999776482582</izz>
				</inertia>
			</inertial>
		</link>
		<link name="hollie_real_left_hand_f6_link">
			<pose>-0.019331261753 -0.382579993617 1.9025000024 -1.7484558489933022e-07 -2.384185530917369e-07 -1.5184364000982324</pose>
			<inertial>
				<mass>9.999999747378752e-06</mass>
				<pose>0 0 0 0 0 0</pose>
				<inertia>
					<ixx>0.009999999776482582</ixx>
					<ixy>0.0</ixy>
					<ixz>0.0</ixz>
					<iyy>0.009999999776482582</iyy>
					<iyz>0.0</iyz>
					<izz>0.009999999776482582</izz>
				</inertia>
			</inertial>
		</link>
		<link name="hollie_real_left_hand_f7_link">
			<pose>-0.019331261753 -0.382579993617 1.9025000024 -1.7484558489933022e-07 -2.384185530917369e-07 -1.5184364000982324</pose>
			<inertial>
				<mass>9.999999747378752e-06</mass>
				<pose>0 0 0 0 0 0</pose>
				<inertia>
					<ixx>0.009999999776482582</ixx>
					<ixy>0.0</ixy>
					<ixz>0.0</ixz>
					<iyy>0.009999999776482582</iyy>
					<iyz>0.0</iyz>
					<izz>0.009999999776482582</izz>
				</inertia>
			</inertial>
		</link>
		<link name="hollie_real_021">
			<pose>-0.0206513438344 -0.357259984317 1.95849999808 2.3914850677484796 -1.5707960878092948 0.8024674688265603</pose>
			<inertial>
				<mass>9.999999747378752e-06</mass>
				<pose>0 0 0 0 0 0</pose>
				<inertia>
					<ixx>0.009999999776482582</ixx>
					<ixy>0.0</ixy>
					<ixz>0.0</ixz>
					<iyy>0.009999999776482582</iyy>
					<iyz>0.0</iyz>
					<izz>0.009999999776482582</izz>
				</inertia>
			</inertial>
			<collision name="COL_hollie_real.021_collision">
				<pose>-7.810164106558659e-07 -1.712164362288604e-06 -0.013210095465183258 -0.09847992658615112 -8.888411571206234e-07 1.7572572232893435e-06</pose>
				<geometry>
					<mesh>
						<uri>model://Arm_robot/meshes/collisions/COL_hollie_real_021_collision.dae</uri>
					</mesh>
				</geometry>
			</collision>
			<visual name="VIS_hollie_real.021_visual">
				<pose>-7.810164106558659e-07 -1.712164362288604e-06 -0.013210095465183258 0.48761188983917236 -5.156666702532675e-07 -1.785832296263834e-06</pose>
				<geometry>
					<mesh>
						<uri>model://Arm_robot/meshes/visual/VIS_hollie_real_021_visual.dae</uri>
					</mesh>
				</geometry>
			</visual>
		</link>
		<link name="hollie_real_022">
			<pose>-0.0206513438344 -0.357259984317 1.95849999808 -2.3209038689248205 -1.5707960878092948 0.8024674688265603</pose>
			<inertial>
				<mass>9.999999747378752e-06</mass>
				<pose>0 0 0 0 0 0</pose>
				<inertia>
					<ixx>0.009999999776482582</ixx>
					<ixy>0.0</ixy>
					<ixz>0.0</ixz>
					<iyy>0.009999999776482582</iyy>
					<iyz>0.0</iyz>
					<izz>0.009999999776482582</izz>
				</inertia>
			</inertial>
			<collision name="COL_hollie_real.022_collision">
				<pose>6.473467806245026e-07 3.88592468425486e-07 1.542613006222382e-07 -1.1548391398719104e-07 2.1638309988247784e-07 -4.430493305562777e-08</pose>
				<geometry>
					<mesh>
						<uri>model://Arm_robot/meshes/collisions/COL_hollie_real_022_collision.dae</uri>
					</mesh>
				</geometry>
			</collision>
			<visual name="VIS_hollie_real.022_visual">
				<pose>6.473467806245026e-07 3.88592468425486e-07 1.542613006222382e-07 1.2665992699112394e-07 2.1014417939113628e-07 -1.633508475151757e-07</pose>
				<geometry>
					<mesh>
						<uri>model://Arm_robot/meshes/visual/VIS_hollie_real_022_visual.dae</uri>
					</mesh>
				</geometry>
			</visual>
		</link>
		<link name="hollie_real_023">
			<pose>-0.0206512213463 -0.357260233884 2.0030399973 -2.3209038689248205 -1.5707960878092948 0.8024674688265603</pose>
			<inertial>
				<mass>9.999999747378752e-06</mass>
				<pose>0 0 0 0 0 0</pose>
				<inertia>
					<ixx>0.009999999776482582</ixx>
					<ixy>0.0</ixy>
					<ixz>0.0</ixz>
					<iyy>0.009999999776482582</iyy>
					<iyz>0.0</iyz>
					<izz>0.009999999776482582</izz>
				</inertia>
			</inertial>
			<collision name="COL_hollie_real.023_collision">
				<pose>-1.4984202607593033e-06 6.877301075292053e-07 1.5127184838092944e-07 -1.1920920428565296e-07 2.1638308567162312e-07 -4.430493305562777e-08</pose>
				<geometry>
					<mesh>
						<uri>model://Arm_robot/meshes/collisions/COL_hollie_real_023_collision.dae</uri>
					</mesh>
				</geometry>
			</collision>
			<visual name="VIS_hollie_real.023_visual">
				<pose>-1.4984202607593033e-06 6.877301075292053e-07 1.5127184838092944e-07 -3.576277265437966e-07 2.2262199195210997e-07 7.474096008763809e-08</pose>
				<geometry>
					<mesh>
						<uri>model://Arm_robot/meshes/visual/VIS_hollie_real_023_visual.dae</uri>
					</mesh>
				</geometry>
			</visual>
		</link>
		<link name="hollie_real_024">
			<pose>-0.0206511608448 -0.357260357155 2.02503999718 -2.3209038689248205 -1.5707960878092948 0.8024674688265603</pose>
			<inertial>
				<mass>9.999999747378752e-06</mass>
				<pose>0 0 0 0 0 0</pose>
				<inertia>
					<ixx>0.009999999776482582</ixx>
					<ixy>0.0</ixy>
					<ixz>0.0</ixz>
					<iyy>0.009999999776482582</iyy>
					<iyz>0.0</iyz>
					<izz>0.009999999776482582</izz>
				</inertia>
			</inertial>
			<collision name="COL_hollie_real.024_collision">
				<pose>-3.0632790526397e-07 -5.707330501536489e-07 4.811482199329475e-07 -1.266597848825768e-07 2.1638308567162312e-07 -4.430493305562777e-08</pose>
				<geometry>
					<mesh>
						<uri>model://Arm_robot/meshes/collisions/COL_hollie_real_024_collision.dae</uri>
					</mesh>
				</geometry>
			</collision>
			<visual name="VIS_hollie_real.024_visual">
				<pose>-3.0632790526397e-07 -5.707330501536489e-07 4.811482199329475e-07 -2.4586910285506747e-07 2.0390524468894e-07 -2.82396769080151e-07</pose>
				<geometry>
					<mesh>
						<uri>model://Arm_robot/meshes/visual/VIS_hollie_real_024_visual.dae</uri>
					</mesh>
				</geometry>
			</visual>
		</link>
		<link name="hollie_real_left_hand_f8_link">
			<pose>-0.019331261753 -0.382579993617 1.9025000024 -1.7484558489933022e-07 -2.384185530917369e-07 -1.5184364000982324</pose>
			<inertial>
				<mass>9.999999747378752e-06</mass>
				<pose>0 0 0 0 0 0</pose>
				<inertia>
					<ixx>0.009999999776482582</ixx>
					<ixy>0.0</ixy>
					<ixz>0.0</ixz>
					<iyy>0.009999999776482582</iyy>
					<iyz>0.0</iyz>
					<izz>0.009999999776482582</izz>
				</inertia>
			</inertial>
		</link>
		<link name="hollie_real_025">
			<pose>-0.0195312649949 -0.378729978111 1.96800000011 2.3914850677484796 -1.5707960878092948 0.8024674688265603</pose>
			<inertial>
				<mass>9.999999747378752e-06</mass>
				<pose>0 0 0 0 0 0</pose>
				<inertia>
					<ixx>0.009999999776482582</ixx>
					<ixy>0.0</ixy>
					<ixz>0.0</ixz>
					<iyy>0.009999999776482582</iyy>
					<iyz>0.0</iyz>
					<izz>0.009999999776482582</izz>
				</inertia>
			</inertial>
			<collision name="COL_hollie_real.025_collision">
				<pose>-1.8887023145452986e-07 -5.999492032060516e-07 -0.013209988363087177 -5.5879372240497105e-08 -1.2950026757607702e-06 2.7011009251509677e-07</pose>
				<geometry>
					<mesh>
						<uri>model://Arm_robot/meshes/collisions/COL_hollie_real_025_collision.dae</uri>
					</mesh>
				</geometry>
			</collision>
			<visual name="VIS_hollie_real.025_visual">
				<pose>-1.8887023145452986e-07 -5.999492032060516e-07 -0.013209988363087177 0.22647900879383087 -1.2950026757607702e-06 2.7011009251509677e-07</pose>
				<geometry>
					<mesh>
						<uri>model://Arm_robot/meshes/visual/VIS_hollie_real_025_visual.dae</uri>
					</mesh>
				</geometry>
			</visual>
		</link>
		<link name="hollie_real_026">
			<pose>-0.0195312649949 -0.378729978111 1.96800000011 -2.3209038689248205 -1.5707960878092948 0.8024674688265603</pose>
			<inertial>
				<mass>9.999999747378752e-06</mass>
				<pose>0 0 0 0 0 0</pose>
				<inertia>
					<ixx>0.009999999776482582</ixx>
					<ixy>0.0</ixy>
					<ixz>0.0</ixz>
					<iyy>0.009999999776482582</iyy>
					<iyz>0.0</iyz>
					<izz>0.009999999776482582</izz>
				</inertia>
			</inertial>
			<collision name="COL_hollie_real.026_collision">
				<pose>-5.47861645827652e-07 4.920964897792146e-07 -7.250807243508461e-07 -2.421437557131867e-07 2.3128421844376135e-07 -4.4304922397486735e-08</pose>
				<geometry>
					<mesh>
						<uri>model://Arm_robot/meshes/collisions/COL_hollie_real_026_collision.dae</uri>
					</mesh>
				</geometry>
			</collision>
			<visual name="VIS_hollie_real.026_visual">
				<pose>-5.47861645827652e-07 4.920964897792146e-07 -7.250807243508461e-07 -0.05260705575346947 2.1880640588278766e-07 -2.82396769080151e-07</pose>
				<geometry>
					<mesh>
						<uri>model://Arm_robot/meshes/visual/VIS_hollie_real_026_visual.dae</uri>
					</mesh>
				</geometry>
			</visual>
		</link>
		<link name="hollie_real_027">
			<pose>-0.0195311273814 -0.378730258496 2.0180399993 -2.3209038689248205 -1.5707960878092948 0.8024674688265603</pose>
			<inertial>
				<mass>9.999999747378752e-06</mass>
				<pose>0 0 0 0 0 0</pose>
				<inertia>
					<ixx>0.009999999776482582</ixx>
					<ixy>0.0</ixy>
					<ixz>0.0</ixz>
					<iyy>0.009999999776482582</iyy>
					<iyz>0.0</iyz>
					<izz>0.009999999776482582</izz>
				</inertia>
			</inertial>
			<collision name="COL_hollie_real.027_collision">
				<pose>-7.102472210362976e-08 2.120043518516468e-08 -5.608406468127214e-07 -1.1920921849650767e-07 2.3128424686547078e-07 -4.430501832075606e-08</pose>
				<geometry>
					<mesh>
						<uri>model://Arm_robot/meshes/collisions/COL_hollie_real_027_collision.dae</uri>
					</mesh>
				</geometry>
			</collision>
			<visual name="VIS_hollie_real.027_visual">
				<pose>-7.102472210362976e-08 2.120043518516468e-08 -5.608406468127214e-07 -3.5762778338721546e-07 2.3752316735681234e-07 7.474093166592866e-08</pose>
				<geometry>
					<mesh>
						<uri>model://Arm_robot/meshes/visual/VIS_hollie_real_027_visual.dae</uri>
					</mesh>
				</geometry>
			</visual>
		</link>
		<link name="hollie_real_lef">
			<pose>-0.0195310393792 -0.378730437799 2.05004000082 -2.3209038689248205 -1.5707960878092948 0.8024674688265603</pose>
			<inertial>
				<mass>9.999999747378752e-06</mass>
				<pose>0 0 0 0 0 0</pose>
				<inertia>
					<ixx>0.009999999776482582</ixx>
					<ixy>0.0</ixy>
					<ixz>0.0</ixz>
					<iyy>0.009999999776482582</iyy>
					<iyz>0.0</iyz>
					<izz>0.009999999776482582</izz>
				</inertia>
			</inertial>
			<collision name="COL_hollie_real_lef_collision">
				<pose>8.826496014080476e-07 -1.0768030733743217e-07 -2.0978791326342616e-07 -1.229345087949696e-07 2.3128423265461606e-07 -4.430501832075606e-08</pose>
				<geometry>
					<mesh>
						<uri>model://Arm_robot/meshes/collisions/COL_hollie_real_lef_collision.dae</uri>
					</mesh>
				</geometry>
			</collision>
			<visual name="VIS_hollie_real_lef_visual">
				<pose>8.826496014080476e-07 -1.0768030733743217e-07 -2.0978791326342616e-07 0.02001773566007614 2.1880639167193294e-07 -2.823968543452793e-07</pose>
				<geometry>
					<mesh>
						<uri>model://Arm_robot/meshes/visual/VIS_hollie_real_lef_visual.dae</uri>
					</mesh>
				</geometry>
			</visual>
		</link>
		<joint name="hollie_real_left_arm" type="prismatic">
			<parent>base_link</parent>
			<child>hollie_real_left_arm</child>
			<axis>
				<xyz>0.0 0.0 1.0</xyz>
				<use_parent_model_frame>true</use_parent_model_frame>
				<limit>
					<lower>0.0</lower>
					<upper>0.0</upper>
				</limit>
			</axis>
		</joint>
		<joint name="hollie_real_000" type="revolute">
			<parent>hollie_real_left_arm</parent>
			<child>hollie_real_000</child>
			<axis>
				<xyz>0.0 0.0 1.0</xyz>
				<use_parent_model_frame>true</use_parent_model_frame>
				<limit>
					<lower>-1.3725499951131953e+20</lower>
					<upper>1.3725499951131953e+20</upper>
				</limit>
			</axis>
		</joint>
		<joint name="hollie_real_001" type="revolute">
			<parent>hollie_real_000</parent>
			<child>hollie_real_001</child>
			<axis>
				<xyz>0.0 0.0 1.0</xyz>
				<use_parent_model_frame>true</use_parent_model_frame>
				<limit>
					<lower>-2864.7899792081876</lower>
					<upper>2864.7899792081876</upper>
				</limit>
			</axis>
		</joint>
		<joint name="hollie_real_002" type="revolute">
			<parent>hollie_real_001</parent>
			<child>hollie_real_002</child>
			<axis>
				<xyz>0.0 0.0 1.0</xyz>
				<use_parent_model_frame>true</use_parent_model_frame>
				<limit>
					<lower>-1.3674900483077548e+20</lower>
					<upper>1.3674900483077548e+20</upper>
				</limit>
			</axis>
		</joint>
		<joint name="hollie_real_003" type="revolute">
			<parent>hollie_real_002</parent>
			<child>hollie_real_003</child>
			<axis>
				<xyz>0.0 0.0 1.0</xyz>
				<use_parent_model_frame>true</use_parent_model_frame>
				<limit>
					<lower>-4.5218797907546595e+19</lower>
					<upper>4.5218797907546595e+19</upper>
				</limit>
			</axis>
		</joint>
		<joint name="hollie_real_004" type="revolute">
			<parent>hollie_real_003</parent>
			<child>hollie_real_004</child>
			<axis>
				<xyz>0.0 0.0 1.0</xyz>
				<use_parent_model_frame>true</use_parent_model_frame>
				<limit>
					<lower>-1.3674900483077548e+20</lower>
					<upper>1.3674900483077548e+20</upper>
				</limit>
			</axis>
		</joint>
		<joint name="hollie_real_005" type="revolute">
			<parent>hollie_real_004</parent>
			<child>hollie_real_005</child>
			<axis>
				<xyz>0.0 0.0 1.0</xyz>
				<use_parent_model_frame>true</use_parent_model_frame>
				<limit>
					<lower>-4.5218797907546595e+19</lower>
					<upper>4.5218797907546595e+19</upper>
				</limit>
			</axis>
		</joint>
		<joint name="hollie_real_006" type="prismatic">
			<parent>hollie_real_005</parent>
			<child>hollie_real_006</child>
			<axis>
				<xyz>0.0 0.0 1.0</xyz>
				<use_parent_model_frame>true</use_parent_model_frame>
				<limit>
					<lower>0.0</lower>
					<upper>0.0</upper>
				</limit>
			</axis>
		</joint>
		<joint name="hollie_real_007" type="prismatic">
			<parent>hollie_real_006</parent>
			<child>hollie_real_007</child>
			<axis>
				<xyz>0.0 0.0 1.0</xyz>
				<use_parent_model_frame>true</use_parent_model_frame>
				<limit>
					<lower>0.0</lower>
					<upper>0.0</upper>
				</limit>
			</axis>
		</joint>
		<joint name="hollie_real_008" type="revolute">
			<parent>hollie_real_007</parent>
			<child>hollie_real_008</child>
			<axis>
				<xyz>0.0 0.0 1.0</xyz>
				<use_parent_model_frame>true</use_parent_model_frame>
				<limit>
					<lower>0.0</lower>
					<upper>2.1580500199391818e+19</upper>
				</limit>
			</axis>
		</joint>
		<joint name="hollie_real_left_hand_Thumb_Helper_link" type="prismatic">
			<parent>hollie_real_008</parent>
			<child>hollie_real_left_hand_Thumb_Helper_link</child>
			<axis>
				<xyz>0.0 0.0 1.0</xyz>
				<use_parent_model_frame>true</use_parent_model_frame>
				<limit>
					<lower>0.0</lower>
					<upper>0.0</upper>
				</limit>
			</axis>
		</joint>
		<joint name="hollie_real_009" type="revolute">
			<parent>hollie_real_left_hand_Thumb_Helper_link</parent>
			<child>hollie_real_009</child>
			<axis>
				<xyz>0.0 0.0 1.0</xyz>
				<use_parent_model_frame>true</use_parent_model_frame>
				<limit>
					<lower>-5.000000258101105</lower>
					<upper>2.11981990572085e+19</upper>
				</limit>
			</axis>
		</joint>
		<joint name="hollie_real_010" type="revolute">
			<parent>hollie_real_009</parent>
			<child>hollie_real_010</child>
			<axis>
				<xyz>0.0 0.0 1.0</xyz>
				<use_parent_model_frame>true</use_parent_model_frame>
				<limit>
					<lower>-5.000000258101105</lower>
					<upper>0.0</upper>
				</limit>
			</axis>
		</joint>
		<joint name="hollie_real_011" type="revolute">
			<parent>hollie_real_010</parent>
			<child>hollie_real_011</child>
			<axis>
				<xyz>0.0 0.0 1.0</xyz>
				<use_parent_model_frame>true</use_parent_model_frame>
				<limit>
					<lower>0.0</lower>
					<upper>3.071390118108257e+19</upper>
				</limit>
			</axis>
		</joint>
		<joint name="hollie_real_left_hand_f1_link" type="prismatic">
			<parent>hollie_real_007</parent>
			<child>hollie_real_left_hand_f1_link</child>
			<axis>
				<xyz>0.0 0.0 1.0</xyz>
				<use_parent_model_frame>true</use_parent_model_frame>
				<limit>
					<lower>0.0</lower>
					<upper>0.0</upper>
				</limit>
			</axis>
		</joint>
		<joint name="hollie_real_left_hand_f2_link" type="prismatic">
			<parent>hollie_real_left_hand_f1_link</parent>
			<child>hollie_real_left_hand_f2_link</child>
			<axis>
				<xyz>0.0 0.0 1.0</xyz>
				<use_parent_model_frame>true</use_parent_model_frame>
				<limit>
					<lower>0.0</lower>
					<upper>0.0</upper>
				</limit>
			</axis>
		</joint>
		<joint name="hollie_real_left_hand_f3_link" type="prismatic">
			<parent>hollie_real_left_hand_f2_link</parent>
			<child>hollie_real_left_hand_f3_link</child>
			<axis>
				<xyz>0.0 0.0 1.0</xyz>
				<use_parent_model_frame>true</use_parent_model_frame>
				<limit>
					<lower>0.0</lower>
					<upper>0.0</upper>
				</limit>
			</axis>
		</joint>
		<joint name="hollie_real_012" type="revolute">
			<parent>hollie_real_left_hand_f3_link</parent>
			<child>hollie_real_012</child>
			<axis>
				<xyz>0.0 0.0 1.0</xyz>
				<use_parent_model_frame>true</use_parent_model_frame>
				<limit>
					<lower>0.0</lower>
					<upper>6.298519948777303e+18</upper>
				</limit>
			</axis>
		</joint>
		<joint name="hollie_real_013" type="revolute">
			<parent>hollie_real_012</parent>
			<child>hollie_real_013</child>
			<axis>
				<xyz>0.0 0.0 1.0</xyz>
				<use_parent_model_frame>true</use_parent_model_frame>
				<limit>
					<lower>0.0</lower>
					<upper>1.7442900126691746e+19</upper>
				</limit>
			</axis>
		</joint>
		<joint name="hollie_real_014" type="revolute">
			<parent>hollie_real_013</parent>
			<child>hollie_real_014</child>
			<axis>
				<xyz>0.0 0.0 1.0</xyz>
				<use_parent_model_frame>true</use_parent_model_frame>
				<limit>
					<lower>0.0</lower>
					<upper>2.914100091256776e+19</upper>
				</limit>
			</axis>
		</joint>
		<joint name="hollie_real_015" type="revolute">
			<parent>hollie_real_014</parent>
			<child>hollie_real_015</child>
			<axis>
				<xyz>0.0 0.0 1.0</xyz>
				<use_parent_model_frame>true</use_parent_model_frame>
				<limit>
					<lower>0.0</lower>
					<upper>3.045169996273525e+19</upper>
				</limit>
			</axis>
		</joint>
		<joint name="hollie_real_016" type="prismatic">
			<parent>hollie_real_left_hand_f1_link</parent>
			<child>hollie_real_016</child>
			<axis>
				<xyz>0.0 0.0 1.0</xyz>
				<use_parent_model_frame>true</use_parent_model_frame>
				<limit>
					<lower>0.0</lower>
					<upper>0.0</upper>
				</limit>
			</axis>
		</joint>
		<joint name="hollie_real_017" type="revolute">
			<parent>hollie_real_016</parent>
			<child>hollie_real_017</child>
			<axis>
				<xyz>0.0 0.0 1.0</xyz>
				<use_parent_model_frame>true</use_parent_model_frame>
				<limit>
					<lower>0.0</lower>
					<upper>1.7442900126691746e+19</upper>
				</limit>
			</axis>
		</joint>
		<joint name="hollie_real_018" type="revolute">
			<parent>hollie_real_017</parent>
			<child>hollie_real_018</child>
			<axis>
				<xyz>0.0 0.0 1.0</xyz>
				<use_parent_model_frame>true</use_parent_model_frame>
				<limit>
					<lower>0.0</lower>
					<upper>2.914100091256776e+19</upper>
				</limit>
			</axis>
		</joint>
		<joint name="hollie_real_019" type="revolute">
			<parent>hollie_real_018</parent>
			<child>hollie_real_019</child>
			<axis>
				<xyz>0.0 0.0 1.0</xyz>
				<use_parent_model_frame>true</use_parent_model_frame>
				<limit>
					<lower>0.0</lower>
					<upper>2.914100091256776e+19</upper>
				</limit>
			</axis>
		</joint>
		<joint name="hollie_real_020" type="revolute">
			<parent>hollie_real_007</parent>
			<child>hollie_real_020</child>
			<axis>
				<xyz>0.0 0.0 1.0</xyz>
				<use_parent_model_frame>true</use_parent_model_frame>
				<limit>
					<lower>0.0</lower>
					<upper>2.15796011816775e+19</upper>
				</limit>
			</axis>
		</joint>
		<joint name="hollie_real_left_hand_f5_link" type="prismatic">
			<parent>hollie_real_020</parent>
			<child>hollie_real_left_hand_f5_link</child>
			<axis>
				<xyz>0.0 0.0 1.0</xyz>
				<use_parent_model_frame>true</use_parent_model_frame>
				<limit>
					<lower>0.0</lower>
					<upper>0.0</upper>
				</limit>
			</axis>
		</joint>
		<joint name="hollie_real_left_hand_f6_link" type="prismatic">
			<parent>hollie_real_left_hand_f5_link</parent>
			<child>hollie_real_left_hand_f6_link</child>
			<axis>
				<xyz>0.0 0.0 1.0</xyz>
				<use_parent_model_frame>true</use_parent_model_frame>
				<limit>
					<lower>0.0</lower>
					<upper>0.0</upper>
				</limit>
			</axis>
		</joint>
		<joint name="hollie_real_left_hand_f7_link" type="prismatic">
			<parent>hollie_real_left_hand_f6_link</parent>
			<child>hollie_real_left_hand_f7_link</child>
			<axis>
				<xyz>0.0 0.0 1.0</xyz>
				<use_parent_model_frame>true</use_parent_model_frame>
				<limit>
					<lower>0.0</lower>
					<upper>0.0</upper>
				</limit>
			</axis>
		</joint>
		<joint name="hollie_real_021" type="revolute">
			<parent>hollie_real_left_hand_f7_link</parent>
			<child>hollie_real_021</child>
			<axis>
				<xyz>0.0 0.0 1.0</xyz>
				<use_parent_model_frame>true</use_parent_model_frame>
				<limit>
					<lower>0.0</lower>
					<upper>1.2733399514723783e+19</upper>
				</limit>
			</axis>
		</joint>
		<joint name="hollie_real_022" type="revolute">
			<parent>hollie_real_021</parent>
			<child>hollie_real_022</child>
			<axis>
				<xyz>0.0 0.0 1.0</xyz>
				<use_parent_model_frame>true</use_parent_model_frame>
				<limit>
					<lower>0.0</lower>
					<upper>2.144620021706815e+19</upper>
				</limit>
			</axis>
		</joint>
		<joint name="hollie_real_023" type="revolute">
			<parent>hollie_real_022</parent>
			<child>hollie_real_023</child>
			<axis>
				<xyz>0.0 0.0 1.0</xyz>
				<use_parent_model_frame>true</use_parent_model_frame>
				<limit>
					<lower>0.0</lower>
					<upper>2.914100091256776e+19</upper>
				</limit>
			</axis>
		</joint>
		<joint name="hollie_real_024" type="revolute">
			<parent>hollie_real_023</parent>
			<child>hollie_real_024</child>
			<axis>
				<xyz>0.0 0.0 1.0</xyz>
				<use_parent_model_frame>true</use_parent_model_frame>
				<limit>
					<lower>0.0</lower>
					<upper>3.051939894422263e+19</upper>
				</limit>
			</axis>
		</joint>
		<joint name="hollie_real_left_hand_f8_link" type="prismatic">
			<parent>hollie_real_left_hand_f6_link</parent>
			<child>hollie_real_left_hand_f8_link</child>
			<axis>
				<xyz>0.0 0.0 1.0</xyz>
				<use_parent_model_frame>true</use_parent_model_frame>
				<limit>
					<lower>0.0</lower>
					<upper>0.0</upper>
				</limit>
			</axis>
		</joint>
		<joint name="hollie_real_025" type="revolute">
			<parent>hollie_real_left_hand_f8_link</parent>
			<child>hollie_real_025</child>
			<axis>
				<xyz>0.0 0.0 1.0</xyz>
				<use_parent_model_frame>true</use_parent_model_frame>
				<limit>
					<lower>0.0</lower>
					<upper>6.298519948777303e+18</upper>
				</limit>
			</axis>
		</joint>
		<joint name="hollie_real_026" type="revolute">
			<parent>hollie_real_025</parent>
			<child>hollie_real_026</child>
			<axis>
				<xyz>0.0 0.0 1.0</xyz>
				<use_parent_model_frame>true</use_parent_model_frame>
				<limit>
					<lower>0.0</lower>
					<upper>2.144620021706815e+19</upper>
				</limit>
			</axis>
		</joint>
		<joint name="hollie_real_027" type="revolute">
			<parent>hollie_real_026</parent>
			<child>hollie_real_027</child>
			<axis>
				<xyz>0.0 0.0 1.0</xyz>
				<use_parent_model_frame>true</use_parent_model_frame>
				<limit>
					<lower>0.0</lower>
					<upper>2.914100091256776e+19</upper>
				</limit>
			</axis>
		</joint>
		<joint name="hollie_real_lef" type="revolute">
			<parent>hollie_real_027</parent>
			<child>hollie_real_lef</child>
			<axis>
				<xyz>0.0 0.0 1.0</xyz>
				<use_parent_model_frame>true</use_parent_model_frame>
				<limit>
					<lower>0.0</lower>
					<upper>3.0473600623775904e+19</upper>
				</limit>
			</axis>
		</joint>
	</model>
</sdf>
