<?xml version="1.0" ?>
<robot name="roboy_left_arm">
  <joint name="elbow_left" type="revolute">
    <parent link="upper_arm_left"/>
    <child link="lower_arm_left"/>
    <origin rpy="0  0  0" xyz="0.28916  0.00929 -0.02115"/>
    <axis xyz="0.01118  0.0229   0.99967"/>
    <limit effort="0.0" lower="-1.57079632679" upper="0.0" velocity="0.0"/>
  </joint>
  <joint name="sphere_axis0" type="revolute">
    <parent link="torso"/>
    <child link="sphere_link1"/>
    <origin rpy="0  0  0" xyz="0.29218  0.00769  0.54861"/>
    <axis xyz="0.99863  0.05074 -0.01234"/>
    <limit effort="0.0" lower="-3.14159265359" upper="3.14159265359" velocity="0.0"/>
  </joint>
  <joint name="sphere_axis1" type="revolute">
    <parent link="sphere_link1"/>
    <child link="sphere_link2"/>
    <origin rpy="0  0  0" xyz="0  0  0"/>
    <axis xyz="-0.05101  0.99844 -0.02231"/>
    <limit effort="0.0" lower="-3.14159265359" upper="3.14159265359" velocity="0.0"/>
  </joint>
  <joint name="sphere_axis2" type="revolute">
    <parent link="sphere_link2"/>
    <child link="upper_arm_left"/>
    <origin rpy="0  0  0" xyz="0  0  0"/>
    <axis xyz="0.99863  0.05074 -0.01234"/>
    <limit effort="0.0" lower="-3.14159265359" upper="3.14159265359" velocity="0.0"/>
  </joint>
  <link name="torso">
    <inertial>
      <mass value="1058.5841171133354"/>
      <origin rpy="0  0  0" xyz="0  0  0"/>
      <inertia ixx="197.52903910430388" ixy="0.02820614924870949" ixz="-0.07910306243304488" iyy="197.7643453001651" iyz="0.052476001481225734" izz="387.32871403101603"/>
    </inertial>
    <collision name="torso_collision">
      <origin rpy="0  0  0" xyz="0  0  0"/>
      <geometry>
        <mesh filename="package://roboy_models/roboy_left_arm/meshes/CAD/torso.stl" scale="0.001 0.001 0.001"/>
      </geometry>
    </collision>
    <visual name="torso_visual">
      <origin rpy="0  0  0" xyz="0  0  0"/>
      <geometry>
        <mesh filename="package://roboy_models/roboy_left_arm/meshes/CAD/torso.stl" scale="0.001 0.001 0.001"/>
      </geometry>
    </visual>
  </link>
  <link name="upper_arm_left">
    <inertial>
      <mass value="1.190952442545569"/>
      <origin rpy="0  0  0" xyz="0.17354  0.00937  0.01032"/>
      <inertia ixx="0.374857927474275" ixy="-0.009672216636765636" ixz="-0.011348775039493443" iyy="0.6355287176008303" iyz="-0.3102277717095622" izz="0.2650728892540181"/>
    </inertial>
    <collision name="upper_arm_left_collision">
      <origin rpy="0  0  0" xyz="0.17354  0.00937  0.01032"/>
      <geometry>
        <mesh filename="package://roboy_models/roboy_left_arm/meshes/CAD/upper_arm_left.stl" scale="0.001 0.001 0.001"/>
      </geometry>
    </collision>
    <visual name="upper_arm_left_visual">
      <origin rpy="0  0  0" xyz="0.17354  0.00937  0.01032"/>
      <geometry>
        <mesh filename="package://roboy_models/roboy_left_arm/meshes/CAD/upper_arm_left.stl" scale="0.001 0.001 0.001"/>
      </geometry>
    </visual>
  </link>
  <link name="lower_arm_left">
    <inertial>
      <mass value="0.2532515779247919"/>
      <origin rpy="0  0  0" xyz="0.06921  0.00928  0.01855"/>
      <inertia ixx="0.075817137289443" ixy="-0.004359811997345667" ixz="-0.0036329322160039285" iyy="0.18349824316572577" iyz="-0.08994380872070017" izz="0.10815959891982849"/>
    </inertial>
    <collision name="lower_arm_left_collision">
      <origin rpy="0  0  0" xyz="0.06921  0.00928  0.01855"/>
      <geometry>
        <mesh filename="package://roboy_models/roboy_left_arm/meshes/CAD/lower_arm_left.stl" scale="0.001 0.001 0.001"/>
      </geometry>
    </collision>
    <visual name="lower_arm_left_visual">
      <origin rpy="0  0  0" xyz="0.06921  0.00928  0.01855"/>
      <geometry>
        <mesh filename="package://roboy_models/roboy_left_arm/meshes/CAD/lower_arm_left.stl" scale="0.001 0.001 0.001"/>
      </geometry>
    </visual>
  </link>
  <link name="sphere_link1">
    <inertial>
      <mass value="0.046755519327953375"/>
      <origin rpy="0  0  0" xyz="0  0  0"/>
      <inertia ixx="0.014081079691620597" ixy="-0.00010506593379475995" ixz="-0.00019727774254638377" iyy="0.018069794508113985" iyz="-0.00749462944662583" izz="0.004000220151190864"/>
    </inertial>
    <collision name="sphere_link1_collision">
      <origin rpy="0  0  0" xyz="0  0  0"/>
      <geometry>
        <mesh filename="package://roboy_models/roboy_left_arm/meshes/CAD/sphere_link1.stl" scale="0.001 0.001 0.001"/>
      </geometry>
    </collision>
    <visual name="sphere_link1_visual">
      <origin rpy="0  0  0" xyz="0  0  0"/>
      <geometry>
        <mesh filename="package://roboy_models/roboy_left_arm/meshes/CAD/sphere_link1.stl" scale="0.001 0.001 0.001"/>
      </geometry>
    </visual>
  </link>
  <link name="sphere_link2">
    <inertial>
      <mass value="0.031340208481721615"/>
      <origin rpy="0  0  0" xyz="0  0  0"/>
      <inertia ixx="0.00943723649341556" ixy="-7.042286174839997e-05" ixz="-0.00013222993537338276" iyy="0.0121108711445115" iyz="-0.005023647663244027" izz="0.002680040477109837"/>
    </inertial>
    <collision name="sphere_link2_collision">
      <origin rpy="0  0  0" xyz="0  0  0"/>
      <geometry>
        <mesh filename="package://roboy_models/roboy_left_arm/meshes/CAD/sphere_link2.stl" scale="0.001 0.001 0.001"/>
      </geometry>
    </collision>
    <visual name="sphere_link2_visual">
      <origin rpy="0  0  0" xyz="0  0  0"/>
      <geometry>
        <mesh filename="package://roboy_models/roboy_left_arm/meshes/CAD/sphere_link2.stl" scale="0.001 0.001 0.001"/>
      </geometry>
    </visual>
  </link>
</robot>
