<?xml version="1.0" ?>
<sdf version="1.6">
	<model name="Roboy2.0_Upper_Body_simplified">
		<link name="torso">
			<pose frame="">0.0 0.0 0.0 1.5707963267948966 -0.0 0.0</pose>
			<inertial>
				<pose frame="">-0.0024627105840188727 0.2276607186577584 -6.606619526434446e-05 0 0 0</pose>
				<mass>41.037576224695336</mass>
				<inertia>
					<ixx>2.76044624501344</ixx>
					<ixy>0.03833769432416248</ixy>
					<ixz>-0.033458366441540724</ixz>
					<iyy>1.108133854554502</iyy>
					<iyz>0.004260270196651721</iyz>
					<izz>3.656294307211186</izz>
				</inertia>
			</inertial>
			<collision name="torso_collision">
				<geometry>
					<mesh>
						<uri>model://Roboy2.0_Upper_Body_simplified/meshes/CAD/torso.stl</uri>
						<scale>0.001 0.001 0.001</scale>
					</mesh>
				</geometry>
			</collision>
			<visual name="torso_visual">
				<geometry>
					<mesh>
						<uri>model://Roboy2.0_Upper_Body_simplified/meshes/CAD/torso.stl</uri>
						<scale>0.001 0.001 0.001</scale>
					</mesh>
				</geometry>
			</visual>
		</link>
		<link name="lower_arm_left">
			<pose frame="">0.0 0.0 0.0 1.5707963267948966 -0.0 0.0</pose>
			<inertial>
				<pose frame="">0.7333988834949675 0.2672580118987967 -0.00038349247780890175 0 0 0</pose>
				<mass>11.16029189630678</mass>
				<inertia>
					<ixx>0.8072626821541625</ixx>
					<ixy>-2.1873387847824564</ixy>
					<ixz>0.0011354234298856798</ixz>
					<iyy>6.064659116110058</iyy>
					<iyz>0.0026447722014624163</iyz>
					<izz>6.861911024199142</izz>
				</inertia>
			</inertial>
			<collision name="lower_arm_left_collision">
				<geometry>
					<mesh>
						<uri>model://Roboy2.0_Upper_Body_simplified/meshes/CAD/lower_arm_left.stl</uri>
						<scale>0.001 0.001 0.001</scale>
					</mesh>
				</geometry>
			</collision>
			<visual name="lower_arm_left_visual">
				<geometry>
					<mesh>
						<uri>model://Roboy2.0_Upper_Body_simplified/meshes/CAD/lower_arm_left.stl</uri>
						<scale>0.001 0.001 0.001</scale>
					</mesh>
				</geometry>
			</visual>
		</link>
		<link name="lower_arm_right">
			<pose frame="">0.0 0.0 0.0 1.5707963267948966 -0.0 0.0</pose>
			<inertial>
				<pose frame="">-0.7401944435475356 0.2674541997550525 -6.120801230971365e-05 0 0 0</pose>
				<mass>10.56746859618293</mass>
				<inertia>
					<ixx>0.7656555252303671</ixx>
					<ixy>2.092002558935388</ixy>
					<ixz>0.00017204701295805343</ixz>
					<iyy>5.842212018786946</iyy>
					<iyz>-0.00041692257707003</iyz>
					<izz>6.598134277297804</izz>
				</inertia>
			</inertial>
			<collision name="lower_arm_right_collision">
				<geometry>
					<mesh>
						<uri>model://Roboy2.0_Upper_Body_simplified/meshes/CAD/lower_arm_right.stl</uri>
						<scale>0.001 0.001 0.001</scale>
					</mesh>
				</geometry>
			</collision>
			<visual name="lower_arm_right_visual">
				<geometry>
					<mesh>
						<uri>model://Roboy2.0_Upper_Body_simplified/meshes/CAD/lower_arm_right.stl</uri>
						<scale>0.001 0.001 0.001</scale>
					</mesh>
				</geometry>
			</visual>
		</link>
		<link name="upper_arm_right">
			<pose frame="">0.0 0.0 0.0 1.5707963267948966 -0.0 0.0</pose>
			<inertial>
				<pose frame="">-0.4424691908082744 0.28168355106491944 -7.485515972389958e-05 0 0 0</pose>
				<mass>14.701862035313637</mass>
				<inertia>
					<ixx>1.2007986941422244</ixx>
					<ixy>1.8364677431544225</ixy>
					<ixz>4.566043664722084e-05</ixz>
					<iyy>2.947109149215348</iyy>
					<iyz>-0.00045252981140722474</iyz>
					<izz>4.094683784482445</izz>
				</inertia>
			</inertial>
			<collision name="upper_arm_right_collision">
				<geometry>
					<mesh>
						<uri>model://Roboy2.0_Upper_Body_simplified/meshes/CAD/upper_arm_right.stl</uri>
						<scale>0.001 0.001 0.001</scale>
					</mesh>
				</geometry>
			</collision>
			<visual name="upper_arm_right_visual">
				<geometry>
					<mesh>
						<uri>model://Roboy2.0_Upper_Body_simplified/meshes/CAD/upper_arm_right.stl</uri>
						<scale>0.001 0.001 0.001</scale>
					</mesh>
				</geometry>
			</visual>
		</link>
		<link name="upper_arm_left">
			<pose frame="">0.0 0.0 0.0 1.5707963267948966 -0.0 0.0</pose>
			<inertial>
				<pose frame="">0.4500031654880824 0.2808880430005111 -1.4387084035142798e-06 0 0 0</pose>
				<mass>15.762062772797279</mass>
				<inertia>
					<ixx>1.2788549368585869</ixx>
					<ixy>-1.995057291643979</ixy>
					<ixz>0.00027124660218077437</ixz>
					<iyy>3.2738040299005795</iyy>
					<iyz>0.00011647380915558168</iyz>
					<izz>4.498666665180277</izz>
				</inertia>
			</inertial>
			<collision name="upper_arm_left_collision">
				<geometry>
					<mesh>
						<uri>model://Roboy2.0_Upper_Body_simplified/meshes/CAD/upper_arm_left.stl</uri>
						<scale>0.001 0.001 0.001</scale>
					</mesh>
				</geometry>
			</collision>
			<visual name="upper_arm_left_visual">
				<geometry>
					<mesh>
						<uri>model://Roboy2.0_Upper_Body_simplified/meshes/CAD/upper_arm_left.stl</uri>
						<scale>0.001 0.001 0.001</scale>
					</mesh>
				</geometry>
			</visual>
		</link>
		<link name="head">
			<pose frame="">0.0 0.0 0.0 1.5707963267948966 -0.0 0.0</pose>
			<inertial>
				<pose frame="">0.0011168747156670936 0.5699880307319406 -0.050132377337986485 0 0 0</pose>
				<mass>19.451689163028952</mass>
				<inertia>
					<ixx>6.613084179850771</ixx>
					<ixy>-0.015024459832730378</ixy>
					<ixz>0.5829280007776142</ixz>
					<iyy>0.2515302194477491</iyy>
					<iyz>0.001375296848608166</iyz>
					<izz>6.569983639456649</izz>
				</inertia>
			</inertial>
			<collision name="head_collision">
				<geometry>
					<mesh>
						<uri>model://Roboy2.0_Upper_Body_simplified/meshes/CAD/head.stl</uri>
						<scale>0.001 0.001 0.001</scale>
					</mesh>
				</geometry>
			</collision>
			<visual name="head_visual">
				<geometry>
					<mesh>
						<uri>model://Roboy2.0_Upper_Body_simplified/meshes/CAD/head.stl</uri>
						<scale>0.001 0.001 0.001</scale>
					</mesh>
				</geometry>
			</visual>
		</link>
		<link name="upper_arm_left">
			<pose frame="">0.0 0.0 0.0 1.5707963267948966 -0.0 0.0</pose>
			<inertial>
				<pose frame="">0.44137302196885736 0.2817992924156056 4.0382747886046726e-05 0 0 0</pose>
				<mass>14.559376397462364</mass>
				<inertia>
					<ixx>1.1903082534772749</ixx>
					<ixy>-1.8151540872005376</ixy>
					<ixz>9.882110841482389e-05</ixz>
					<iyy>2.9032029455161275</iyy>
					<iyz>-0.0002185389639928257</iyz>
					<izz>4.040390498769728</izz>
				</inertia>
			</inertial>
			<collision name="upper_arm_left_collision">
				<geometry>
					<mesh>
						<uri>model://Roboy2.0_Upper_Body_simplified/meshes/CAD/upper_arm_left.stl</uri>
						<scale>0.001 0.001 0.001</scale>
					</mesh>
				</geometry>
			</collision>
			<visual name="upper_arm_left_visual">
				<geometry>
					<mesh>
						<uri>model://Roboy2.0_Upper_Body_simplified/meshes/CAD/upper_arm_left.stl</uri>
						<scale>0.001 0.001 0.001</scale>
					</mesh>
				</geometry>
			</visual>
		</link>
		<joint name="elbow_right" type="revolute">
			<parent>upper_arm_right</parent>
			<child>lower_arm_right</child>
			<pose frame="">-0.5931662822956038 0.24953935249816767 0.00498488179652667 0 0 0</pose>
			<axis>
				<xyz>-2.611394507793141e-15 1.0000000000000002 -3.398725557595853e-16</xyz>
				<limit>
					<lower>-0.0</lower>
					<upper>-0.0</upper>
				</limit>
				<use_parent_model_frame>0</use_parent_model_frame>
			</axis>
		</joint>
		<joint name="shoulder_left" type="ball">
			<parent>torso</parent>
			<child>upper_arm_left</child>
			<pose frame="">0.29199999999999937 0.2672393525034074 -1.5118203067120675e-05 0 0 0</pose>
		</joint>
		<joint name="shoulder_right" type="ball">
			<parent>torso</parent>
			<child>upper_arm_right</child>
			<pose frame="">-0.29199999999999937 0.2672393525034074 -1.5118203067120675e-05 0 0 0</pose>
		</joint>
		<joint name="neck" type="revolute">
			<parent>head</parent>
			<child>torso</child>
			<pose frame="">-1.3915247089779886e-31 0.445556650344963 -1.2468963320897772e-16 0 0 0</pose>
			<axis>
				<xyz>-3.9423785961606735e-31 1.0 -6.69603261727048e-16</xyz>
				<limit>
					<lower>-0.0</lower>
					<upper>-0.0</upper>
				</limit>
				<use_parent_model_frame>0</use_parent_model_frame>
			</axis>
		</joint>
		<plugin filename="libmyomuscle_plugin.so" name="myomuscle_plugin">
			<myoMuscle name="motor0">
				<link name="torso">
					<viaPoint type="FIXPOINT">-0.05089754820435121 0.4047293965411953 0.04410299214720642</viaPoint>
				</link>
				<link name="head">
					<viaPoint type="FIXPOINT">-0.04976406017739997 0.460322497508037 0.012633145075212435</viaPoint>
				</link>
			</myoMuscle>
			<myoMuscle name="motor1">
				<link name="torso">
					<viaPoint type="FIXPOINT">-0.050838501387362955 0.4049257092340916 -0.04306471151042283</viaPoint>
				</link>
				<link name="head">
					<viaPoint type="FIXPOINT">-0.04976406017739996 0.455519202909372 -0.014607692256464862</viaPoint>
				</link>
			</myoMuscle>
			<myoMuscle name="motor10">
				<link name="torso">
					<viaPoint type="FIXPOINT">0.23925355454762604 0.183938143951179 -0.0470429190812417</viaPoint>
				</link>
				<link name="upper_arm_left">
					<viaPoint type="FIXPOINT">0.3408980735509448 0.2493174330933888 -0.017776982933358745</viaPoint>
				</link>
			</myoMuscle>
			<myoMuscle name="motor11">
				<link name="torso">
					<viaPoint type="FIXPOINT">0.286969383812244 0.29445161528908875 -0.018062323930585523</viaPoint>
				</link>
				<link name="upper_arm_left">
					<viaPoint type="FIXPOINT">0.3408980735509449 0.29014513074907045 -0.019388432915852346</viaPoint>
				</link>
			</myoMuscle>
			<myoMuscle name="motor12">
				<link name="torso">
					<viaPoint type="FIXPOINT">-0.286969383812244 0.29445161528908875 -0.018062323930585523</viaPoint>
				</link>
				<link name="upper_arm_right">
					<viaPoint type="FIXPOINT">-0.34089807355094387 0.2901451307490704 -0.019388432915854893</viaPoint>
				</link>
			</myoMuscle>
			<myoMuscle name="motor13">
				<link name="torso">
					<viaPoint type="FIXPOINT">-0.23925355454762604 0.183938143951179 -0.0470429190812417</viaPoint>
				</link>
				<link name="upper_arm_right">
					<viaPoint type="FIXPOINT">-0.3408980735509438 0.24931743309335708 -0.01777698293337705</viaPoint>
				</link>
			</myoMuscle>
			<myoMuscle name="motor14">
				<link name="torso">
					<viaPoint type="FIXPOINT">-0.249677429464262 0.23124059947600512 -0.038264925804017406</viaPoint>
				</link>
				<link name="upper_arm_right">
					<viaPoint type="FIXPOINT">-0.3408980735509432 0.2647507162461308 -0.029777022468188395</viaPoint>
				</link>
			</myoMuscle>
			<myoMuscle name="motor15">
				<link name="torso">
					<viaPoint type="FIXPOINT">-0.27852662268679934 0.275 -0.03578735460920132</viaPoint>
				</link>
				<link name="upper_arm_right">
					<viaPoint type="FIXPOINT">-0.34089807355094365 0.28609182611688255 -0.022051094211706545</viaPoint>
				</link>
			</myoMuscle>
			<myoMuscle name="motor16">
				<link name="torso">
					<viaPoint type="FIXPOINT">-0.27852662268679934 0.275 0.03575711820306708</viaPoint>
				</link>
				<link name="upper_arm_right">
					<viaPoint type="FIXPOINT">-0.340898073550946 0.28609182611688255 0.022020857805567232</viaPoint>
				</link>
			</myoMuscle>
			<myoMuscle name="motor17">
				<link name="torso">
					<viaPoint type="FIXPOINT">-0.249677429464261 0.231240599476012 0.033420071355846404</viaPoint>
				</link>
				<link name="upper_arm_right">
					<viaPoint type="FIXPOINT">-0.3408980735509463 0.2647507162461308 0.029746786062049002</viaPoint>
				</link>
			</myoMuscle>
			<myoMuscle name="motor18">
				<link name="torso">
					<viaPoint type="FIXPOINT">-0.23925355454762703 0.1839381439511788 0.0286420780786218</viaPoint>
				</link>
				<link name="upper_arm_right">
					<viaPoint type="FIXPOINT">-0.34089807355094565 0.24931743309338877 0.017746746527221965</viaPoint>
				</link>
			</myoMuscle>
			<myoMuscle name="motor19">
				<link name="torso">
					<viaPoint type="FIXPOINT">-0.28749999999999937 0.29375000000000007 0.01877088179692888</viaPoint>
				</link>
				<link name="upper_arm_right">
					<viaPoint type="FIXPOINT">-0.3408980735509458 0.28927532851204424 0.01883735541040557</viaPoint>
				</link>
			</myoMuscle>
			<myoMuscle name="motor2">
				<link name="torso">
					<viaPoint type="FIXPOINT">0.05130415696557245 0.40703538941640666 0.044515873503976414</viaPoint>
				</link>
				<link name="head">
					<viaPoint type="FIXPOINT">0.04976406017740008 0.460322497508037 0.012633145075212444</viaPoint>
				</link>
			</myoMuscle>
			<myoMuscle name="motor20">
				<link name="upper_arm_right">
					<viaPoint type="FIXPOINT">-0.4769078272579116 0.27294900502809843 0.06436543682402071</viaPoint>
				</link>
				<link name="lower_arm_right">
					<viaPoint type="FIXPOINT">-0.6171662822956097 0.26743935249816736 0.010109493593997907</viaPoint>
				</link>
			</myoMuscle>
			<myoMuscle name="motor21">
				<link name="upper_arm_right">
					<viaPoint type="FIXPOINT">-0.476907827257905 0.26812969997871555 -0.06439567324065264</viaPoint>
				</link>
				<link name="lower_arm_right">
					<viaPoint type="FIXPOINT">-0.617166282295567 0.26743935249816736 -0.0280151187697443</viaPoint>
				</link>
			</myoMuscle>
			<myoMuscle name="motor22">
				<link name="upper_arm_left">
					<viaPoint type="FIXPOINT">0.4769078272579083 0.2681296999787156 0.0643654368345088</viaPoint>
				</link>
				<link name="lower_arm_left">
					<viaPoint type="FIXPOINT">0.6181662822955981 0.26713935250340654 0.010109493589191658</viaPoint>
				</link>
			</myoMuscle>
			<myoMuscle name="motor23">
				<link name="upper_arm_left">
					<viaPoint type="FIXPOINT">0.4769078272579083 0.27294900502809843 -0.06439567323016455</viaPoint>
				</link>
				<link name="lower_arm_left">
					<viaPoint type="FIXPOINT">0.6181662822955981 0.26713935250340654 -0.028015118774550544</viaPoint>
				</link>
			</myoMuscle>
			<myoMuscle name="motor3">
				<link name="torso">
					<viaPoint type="FIXPOINT">0.051245110148584204 0.4072317021093032 -0.043477592867192785</viaPoint>
				</link>
				<link name="head">
					<viaPoint type="FIXPOINT">0.049764060177400087 0.455519202909372 -0.014607692256464853</viaPoint>
				</link>
			</myoMuscle>
			<myoMuscle name="motor4">
				<link name="torso">
					<viaPoint type="FIXPOINT">0.28749999999999937 0.29375000000000007 0.01877088179692888</viaPoint>
				</link>
				<link name="upper_arm_left">
					<viaPoint type="FIXPOINT">0.3408980735509449 0.28661266721619255 0.02289066004259596</viaPoint>
				</link>
			</myoMuscle>
			<myoMuscle name="motor5">
				<link name="torso">
					<viaPoint type="FIXPOINT">0.23925355454762703 0.1839381439511788 0.0286420780786218</viaPoint>
				</link>
				<link name="upper_arm_left">
					<viaPoint type="FIXPOINT">0.3408980735509448 0.25252672532215503 0.02134843917162836</viaPoint>
				</link>
			</myoMuscle>
			<myoMuscle name="motor6">
				<link name="torso">
					<viaPoint type="FIXPOINT">0.249677429464261 0.231240599476012 0.033420071355846404</viaPoint>
				</link>
				<link name="upper_arm_left">
					<viaPoint type="FIXPOINT">0.3408980735509448 0.25029446856643117 0.017488630429430038</viaPoint>
				</link>
			</myoMuscle>
			<myoMuscle name="motor7">
				<link name="torso">
					<viaPoint type="FIXPOINT">0.27852662268679934 0.275 0.03575711820306708</viaPoint>
				</link>
				<link name="upper_arm_left">
					<viaPoint type="FIXPOINT">0.34089807355094487 0.26475071624613083 0.029746786062051615</viaPoint>
				</link>
			</myoMuscle>
			<myoMuscle name="motor8">
				<link name="torso">
					<viaPoint type="FIXPOINT">0.27852662268679934 0.275 -0.03578735460920132</viaPoint>
				</link>
				<link name="upper_arm_left">
					<viaPoint type="FIXPOINT">0.3408980735509449 0.28661266721619133 -0.022920896448728828</viaPoint>
				</link>
			</myoMuscle>
			<myoMuscle name="motor9">
				<link name="torso">
					<viaPoint type="FIXPOINT">0.249677429464262 0.23124059947600512 -0.038264925804017406</viaPoint>
				</link>
				<link name="upper_arm_left">
					<viaPoint type="FIXPOINT">0.34089807355094487 0.26475071624613083 -0.02977702246818578</viaPoint>
				</link>
			</myoMuscle>
		</plugin>
	</model>
</sdf>
