<?xml version="1.0" ?>
<sdf version="1.6">
	<model name="Roboy2.0_Upper_Body_simplified">
		<link name="torso">
			<pose frame="">0.0 0.0 0.0 1.5707963267948966 -0.0 0.0</pose>
			<inertial>
				<pose frame="">-5.554990396133997e-05 0.23946271996201607 -0.0016625656687291649 0 0 0</pose>
				<mass>44.36637263137859</mass>
				<inertia>
					<ixx>3.2598824935067685</ixx>
					<ixy>0.00021269414586383767</ixy>
					<ixz>-0.010653448290850794</ixz>
					<iyy>1.1427981450371427</iyy>
					<iyz>0.0006371165895487078</iyz>
					<izz>4.180078331348225</izz>
				</inertia>
			</inertial>
			<collision name="torso_collision">
				<geometry>
					<mesh>
						<uri>model://Roboy2.0_Upper_Body_simplified/meshes/CAD/torso.stl</uri>
						<scale>0.001 0.001 0.001</scale>
					</mesh>
				</geometry>
			</collision>
			<visual name="torso_visual">
				<geometry>
					<mesh>
						<uri>model://Roboy2.0_Upper_Body_simplified/meshes/CAD/torso.stl</uri>
						<scale>0.001 0.001 0.001</scale>
					</mesh>
				</geometry>
			</visual>
		</link>
		<link name="lower_arm_left">
			<pose frame="">0.0 0.0 0.0 1.5707963267948966 -0.0 0.0</pose>
			<inertial>
				<pose frame="">0.7333988834949703 0.26721598945546593 -0.0010852383223811312 0 0 0</pose>
				<mass>11.16029189630678</mass>
				<inertia>
					<ixx>0.8070235257336131</ixx>
					<ixy>-2.1869948333916795</ixy>
					<ixz>0.0032279958230085793</ixz>
					<iyy>6.0646706187514114</iyy>
					<iyz>0.008388523399313742</iyz>
					<izz>6.86166036513733</izz>
				</inertia>
			</inertial>
			<collision name="lower_arm_left_collision">
				<geometry>
					<mesh>
						<uri>model://Roboy2.0_Upper_Body_simplified/meshes/CAD/lower_arm_left.stl</uri>
						<scale>0.001 0.001 0.001</scale>
					</mesh>
				</geometry>
			</collision>
			<visual name="lower_arm_left_visual">
				<geometry>
					<mesh>
						<uri>model://Roboy2.0_Upper_Body_simplified/meshes/CAD/lower_arm_left.stl</uri>
						<scale>0.001 0.001 0.001</scale>
					</mesh>
				</geometry>
			</visual>
		</link>
		<link name="lower_arm_right">
			<pose frame="">0.0 0.0 0.0 1.5707963267948966 -0.0 0.0</pose>
			<inertial>
				<pose frame="">-0.7401944435475385 0.26741217731413175 -0.0007629538166071563 0 0 0</pose>
				<mass>10.567468596182934</mass>
				<inertia>
					<ixx>0.7654241183967729</ixx>
					<ixy>2.0916738601810576</ixy>
					<ixz>0.0021550620818261666</ixz>
					<iyy>5.842218130504648</iyy>
					<iyz>-0.005905965257124277</iyz>
					<izz>6.597896758746588</izz>
				</inertia>
			</inertial>
			<collision name="lower_arm_right_collision">
				<geometry>
					<mesh>
						<uri>model://Roboy2.0_Upper_Body_simplified/meshes/CAD/lower_arm_right.stl</uri>
						<scale>0.001 0.001 0.001</scale>
					</mesh>
				</geometry>
			</collision>
			<visual name="lower_arm_right_visual">
				<geometry>
					<mesh>
						<uri>model://Roboy2.0_Upper_Body_simplified/meshes/CAD/lower_arm_right.stl</uri>
						<scale>0.001 0.001 0.001</scale>
					</mesh>
				</geometry>
			</visual>
		</link>
		<link name="upper_arm_right">
			<pose frame="">0.0 0.0 0.0 1.5707963267948966 -0.0 0.0</pose>
			<inertial>
				<pose frame="">-0.4424691908082703 0.28164152862776193 -0.0007766009012015644 0 0 0</pose>
				<mass>14.70186203531296</mass>
				<inertia>
					<ixx>1.200459451778189</ixx>
					<ixy>1.8361943820937328</ixy>
					<ixz>0.0029513013680547303</ixz>
					<iyy>2.9471179336617235</iyy>
					<iyz>-0.005017471141079862</iyz>
					<izz>4.094335757671659</izz>
				</inertia>
			</inertial>
			<collision name="upper_arm_right_collision">
				<geometry>
					<mesh>
						<uri>model://Roboy2.0_Upper_Body_simplified/meshes/CAD/upper_arm_right.stl</uri>
						<scale>0.001 0.001 0.001</scale>
					</mesh>
				</geometry>
			</collision>
			<visual name="upper_arm_right_visual">
				<geometry>
					<mesh>
						<uri>model://Roboy2.0_Upper_Body_simplified/meshes/CAD/upper_arm_right.stl</uri>
						<scale>0.001 0.001 0.001</scale>
					</mesh>
				</geometry>
			</visual>
		</link>
		<link name="upper_arm_left">
			<pose frame="">0.0 0.0 0.0 1.5707963267948966 -0.0 0.0</pose>
			<inertial>
				<pose frame="">0.4500031654880834 0.2808460205923537 -0.0007031836666947284 0 0 0</pose>
				<mass>15.762062772797305</mass>
				<inertia>
					<ixx>1.2784906602871244</ixx>
					<ixy>-1.994759227391485</ixy>
					<ixz>0.003377671380343624</ixz>
					<iyy>3.2738118236979963</iyy>
					<iyz>0.005093939835164849</iyz>
					<izz>4.49829459481145</izz>
				</inertia>
			</inertial>
			<collision name="upper_arm_left_collision">
				<geometry>
					<mesh>
						<uri>model://Roboy2.0_Upper_Body_simplified/meshes/CAD/upper_arm_left.stl</uri>
						<scale>0.001 0.001 0.001</scale>
					</mesh>
				</geometry>
			</collision>
			<visual name="upper_arm_left_visual">
				<geometry>
					<mesh>
						<uri>model://Roboy2.0_Upper_Body_simplified/meshes/CAD/upper_arm_left.stl</uri>
						<scale>0.001 0.001 0.001</scale>
					</mesh>
				</geometry>
			</visual>
		</link>
		<link name="head">
			<pose frame="">0.0 0.0 0.0 1.5707963267948966 -0.0 0.0</pose>
			<inertial>
				<pose frame="">0.001117201085706475 0.5795894099613026 -0.005251982893448237 0 0 0</pose>
				<mass>19.45138345772556</mass>
				<inertia>
					<ixx>6.779325973325731</ixx>
					<ixy>-0.015174766520499833</ixy>
					<ixz>0.06462388329882045</ixz>
					<iyy>0.19134335279008596</iyy>
					<iyz>-0.000519985448415185</iyz>
					<izz>6.796411634447759</izz>
				</inertia>
			</inertial>
			<collision name="head_collision">
				<geometry>
					<mesh>
						<uri>model://Roboy2.0_Upper_Body_simplified/meshes/CAD/head.stl</uri>
						<scale>0.001 0.001 0.001</scale>
					</mesh>
				</geometry>
			</collision>
			<visual name="head_visual">
				<geometry>
					<mesh>
						<uri>model://Roboy2.0_Upper_Body_simplified/meshes/CAD/head.stl</uri>
						<scale>0.001 0.001 0.001</scale>
					</mesh>
				</geometry>
			</visual>
		</link>
		<joint name="shoulder_left" type="ball">
			<parent>torso</parent>
			<child>upper_arm_left</child>
			<pose frame="">0.29199999999999987 0.2671973300628304 -0.0007168640016546135 0 0 0</pose>
		</joint>
		<joint name="shoulder_right" type="ball">
			<parent>torso</parent>
			<child>upper_arm_right</child>
			<pose frame="">-0.2919999999999988 0.2671973300628304 -0.0007168640016546135 0 0 0</pose>
		</joint>
		<joint name="neck" type="ball">
			<parent>torso</parent>
			<child>head</child>
			<pose frame="">5.329070518200753e-16 0.445514627904386 -0.0007017457985876234 0 0 0</pose>
		</joint>
		<joint name="elbow_right" type="revolute">
			<parent>upper_arm_right</parent>
			<child>lower_arm_right</child>
			<pose frame="">-0.5931662822956034 0.24949733005759125 0.004283135997968286 0 0 0</pose>
			<axis>
				<xyz>-2.2620794126737537e-15 1.000000000000001 2.162387995910413e-15</xyz>
				<limit>
					<lower>-0.0</lower>
					<upper>-0.0</upper>
				</limit>
				<use_parent_model_frame>0</use_parent_model_frame>
			</axis>
		</joint>
		<joint name="elbow_left" type="revolute">
			<parent>upper_arm_left</parent>
			<child>lower_arm_left</child>
			<pose frame="">0.5931662822955996 0.241197330062829 0.0042831359931060796 0 0 0</pose>
			<axis>
				<xyz>-2.6557203526654557e-15 -1.0000000000000002 1.730399875529501e-16</xyz>
				<limit>
					<lower>-0.0</lower>
					<upper>1.5707963267948966</upper>
				</limit>
				<use_parent_model_frame>0</use_parent_model_frame>
			</axis>
		</joint>
		<plugin filename="libmyomuscle_plugin.so" name="myomuscle_plugin">
			<myoMuscle name="motor0">
				<link name="torso">
					<viaPoint type="FIXPOINT">-0.05089754820435121 0.4047293965411953 0.04410299214720642</viaPoint>
				</link>
				<link name="head">
					<viaPoint type="FIXPOINT">-0.04976406017739997 0.460322497508037 0.012633145075212435</viaPoint>
				</link>
			</myoMuscle>
			<myoMuscle name="motor1">
				<link name="torso">
					<viaPoint type="FIXPOINT">-0.050838501387362955 0.4049257092340916 -0.04306471151042283</viaPoint>
				</link>
				<link name="head">
					<viaPoint type="FIXPOINT">-0.04976406017739996 0.455519202909372 -0.014607692256464862</viaPoint>
				</link>
			</myoMuscle>
			<myoMuscle name="motor10">
				<link name="torso">
					<viaPoint type="FIXPOINT">0.23925355454762604 0.183938143951179 -0.0470429190812417</viaPoint>
				</link>
				<link name="upper_arm_left">
					<viaPoint type="FIXPOINT">0.3408980735509448 0.2493174330933888 -0.017776982933358745</viaPoint>
				</link>
			</myoMuscle>
			<myoMuscle name="motor11">
				<link name="torso">
					<viaPoint type="FIXPOINT">0.286969383812244 0.29445161528908875 -0.018062323930585523</viaPoint>
				</link>
				<link name="upper_arm_left">
					<viaPoint type="FIXPOINT">0.3408980735509449 0.29014513074907045 -0.019388432915852346</viaPoint>
				</link>
			</myoMuscle>
			<myoMuscle name="motor12">
				<link name="torso">
					<viaPoint type="FIXPOINT">-0.286969383812244 0.29445161528908875 -0.018062323930585523</viaPoint>
				</link>
				<link name="upper_arm_right">
					<viaPoint type="FIXPOINT">-0.34089807355094387 0.2901451307490704 -0.019388432915854893</viaPoint>
				</link>
			</myoMuscle>
			<myoMuscle name="motor13">
				<link name="torso">
					<viaPoint type="FIXPOINT">-0.23925355454762604 0.183938143951179 -0.0470429190812417</viaPoint>
				</link>
				<link name="upper_arm_right">
					<viaPoint type="FIXPOINT">-0.3408980735509438 0.24931743309335708 -0.01777698293337705</viaPoint>
				</link>
			</myoMuscle>
			<myoMuscle name="motor14">
				<link name="torso">
					<viaPoint type="FIXPOINT">-0.249677429464262 0.23124059947600512 -0.038264925804017406</viaPoint>
				</link>
				<link name="upper_arm_right">
					<viaPoint type="FIXPOINT">-0.3408980735509432 0.2647507162461308 -0.029777022468188395</viaPoint>
				</link>
			</myoMuscle>
			<myoMuscle name="motor15">
				<link name="torso">
					<viaPoint type="FIXPOINT">-0.27852662268679934 0.275 -0.03578735460920132</viaPoint>
				</link>
				<link name="upper_arm_right">
					<viaPoint type="FIXPOINT">-0.34089807355094365 0.28609182611688255 -0.022051094211706545</viaPoint>
				</link>
			</myoMuscle>
			<myoMuscle name="motor16">
				<link name="torso">
					<viaPoint type="FIXPOINT">-0.27852662268679934 0.275 0.03575711820306708</viaPoint>
				</link>
				<link name="upper_arm_right">
					<viaPoint type="FIXPOINT">-0.340898073550946 0.28609182611688255 0.022020857805567232</viaPoint>
				</link>
			</myoMuscle>
			<myoMuscle name="motor17">
				<link name="torso">
					<viaPoint type="FIXPOINT">-0.249677429464261 0.231240599476012 0.033420071355846404</viaPoint>
				</link>
				<link name="upper_arm_right">
					<viaPoint type="FIXPOINT">-0.3408980735509463 0.2647507162461308 0.029746786062049002</viaPoint>
				</link>
			</myoMuscle>
			<myoMuscle name="motor18">
				<link name="torso">
					<viaPoint type="FIXPOINT">-0.23925355454762703 0.1839381439511788 0.0286420780786218</viaPoint>
				</link>
				<link name="upper_arm_right">
					<viaPoint type="FIXPOINT">-0.34089807355094565 0.24931743309338877 0.017746746527221965</viaPoint>
				</link>
			</myoMuscle>
			<myoMuscle name="motor19">
				<link name="torso">
					<viaPoint type="FIXPOINT">-0.28749999999999937 0.29375000000000007 0.01877088179692888</viaPoint>
				</link>
				<link name="upper_arm_right">
					<viaPoint type="FIXPOINT">-0.3408980735509458 0.28927532851204424 0.01883735541040557</viaPoint>
				</link>
			</myoMuscle>
			<myoMuscle name="motor2">
				<link name="torso">
					<viaPoint type="FIXPOINT">0.05130415696557245 0.40703538941640666 0.044515873503976414</viaPoint>
				</link>
				<link name="head">
					<viaPoint type="FIXPOINT">0.04976406017740008 0.460322497508037 0.012633145075212444</viaPoint>
				</link>
			</myoMuscle>
			<myoMuscle name="motor20">
				<link name="upper_arm_right">
					<viaPoint type="FIXPOINT">-0.4769078272579116 0.27294900502809843 0.06436543682402071</viaPoint>
				</link>
				<link name="lower_arm_right">
					<viaPoint type="FIXPOINT">-0.6171662822956097 0.26743935249816736 0.010109493593997907</viaPoint>
				</link>
			</myoMuscle>
			<myoMuscle name="motor21">
				<link name="upper_arm_right">
					<viaPoint type="FIXPOINT">-0.476907827257905 0.26812969997871555 -0.06439567324065264</viaPoint>
				</link>
				<link name="lower_arm_right">
					<viaPoint type="FIXPOINT">-0.617166282295567 0.26743935249816736 -0.0280151187697443</viaPoint>
				</link>
			</myoMuscle>
			<myoMuscle name="motor22">
				<link name="upper_arm_left">
					<viaPoint type="FIXPOINT">0.4769078272579083 0.2681296999787156 0.0643654368345088</viaPoint>
				</link>
				<link name="lower_arm_left">
					<viaPoint type="FIXPOINT">0.6181662822955981 0.26713935250340654 0.010109493589191658</viaPoint>
				</link>
			</myoMuscle>
			<myoMuscle name="motor23">
				<link name="upper_arm_left">
					<viaPoint type="FIXPOINT">0.4769078272579083 0.27294900502809843 -0.06439567323016455</viaPoint>
				</link>
				<link name="lower_arm_left">
					<viaPoint type="FIXPOINT">0.6181662822955981 0.26713935250340654 -0.028015118774550544</viaPoint>
				</link>
			</myoMuscle>
			<myoMuscle name="motor3">
				<link name="torso">
					<viaPoint type="FIXPOINT">0.051245110148584204 0.4072317021093032 -0.043477592867192785</viaPoint>
				</link>
				<link name="head">
					<viaPoint type="FIXPOINT">0.049764060177400087 0.455519202909372 -0.014607692256464853</viaPoint>
				</link>
			</myoMuscle>
			<myoMuscle name="motor4">
				<link name="torso">
					<viaPoint type="FIXPOINT">0.28749999999999937 0.29375000000000007 0.01877088179692888</viaPoint>
				</link>
				<link name="upper_arm_left">
					<viaPoint type="FIXPOINT">0.3408980735509449 0.28661266721619255 0.02289066004259596</viaPoint>
				</link>
			</myoMuscle>
			<myoMuscle name="motor5">
				<link name="torso">
					<viaPoint type="FIXPOINT">0.23925355454762703 0.1839381439511788 0.0286420780786218</viaPoint>
				</link>
				<link name="upper_arm_left">
					<viaPoint type="FIXPOINT">0.3408980735509448 0.25252672532215503 0.02134843917162836</viaPoint>
				</link>
			</myoMuscle>
			<myoMuscle name="motor6">
				<link name="torso">
					<viaPoint type="FIXPOINT">0.249677429464261 0.231240599476012 0.033420071355846404</viaPoint>
				</link>
				<link name="upper_arm_left">
					<viaPoint type="FIXPOINT">0.3408980735509448 0.25029446856643117 0.017488630429430038</viaPoint>
				</link>
			</myoMuscle>
			<myoMuscle name="motor7">
				<link name="torso">
					<viaPoint type="FIXPOINT">0.27852662268679934 0.275 0.03575711820306708</viaPoint>
				</link>
				<link name="upper_arm_left">
					<viaPoint type="FIXPOINT">0.34089807355094487 0.26475071624613083 0.029746786062051615</viaPoint>
				</link>
			</myoMuscle>
			<myoMuscle name="motor8">
				<link name="torso">
					<viaPoint type="FIXPOINT">0.27852662268679934 0.275 -0.03578735460920132</viaPoint>
				</link>
				<link name="upper_arm_left">
					<viaPoint type="FIXPOINT">0.3408980735509449 0.28661266721619133 -0.022920896448728828</viaPoint>
				</link>
			</myoMuscle>
			<myoMuscle name="motor9">
				<link name="torso">
					<viaPoint type="FIXPOINT">0.249677429464262 0.23124059947600512 -0.038264925804017406</viaPoint>
				</link>
				<link name="upper_arm_left">
					<viaPoint type="FIXPOINT">0.34089807355094487 0.26475071624613083 -0.02977702246818578</viaPoint>
				</link>
			</myoMuscle>
		</plugin>
	</model>
</sdf>
