<?xml version="1.0" ?>
<sdf version="1.6">
	<model name="roboy_xylophone_left_arm">
		<link name="upper_arm_left">
			<self_collide>false</self_collide>
			<pose frame="">0.38168743171845093 0.012531347306432074 0.5613694888271816 0.0 -0.0 0.0</pose>
			<inertial>
				<pose frame="">0.0 0.0 0.0 0 0 0</pose>
				<mass>0.1</mass>
				<inertia>
					<ixx>0.1</ixx>
					<ixy>0.0</ixy>
					<ixz>0.0</ixz>
					<iyy>0.1</iyy>
					<iyz>0.0</iyz>
					<izz>0.1</izz>
				</inertia>
			</inertial>
			<collision name="upper_arm_left_collision">
				<geometry>
					<mesh>
						<uri>model://roboy_xylophone_left_arm/meshes/CAD/upper_arm_left.stl</uri>
						<scale>0.001 0.001 0.001</scale>
					</mesh>
				</geometry>
			</collision>
			<visual name="upper_arm_left_visual">
				<geometry>
					<mesh>
						<uri>model://roboy_xylophone_left_arm/meshes/CAD/upper_arm_left.stl</uri>
						<scale>0.001 0.001 0.001</scale>
					</mesh>
				</geometry>
			</visual>
		</link>
		<link name="torso">
			<self_collide>false</self_collide>
			<pose frame="">-2.5210583336983455e-16 2.5830904394012438e-15 0.3009128442572498 0.0 -0.0 0.0</pose>
			<inertial>
				<pose frame="">0.0 0.0 0.0 0 0 0</pose>
				<mass>0.1</mass>
				<inertia>
					<ixx>0.1</ixx>
					<ixy>0.0</ixy>
					<ixz>0.0</ixz>
					<iyy>0.1</iyy>
					<iyz>0.0</iyz>
					<izz>0.1</izz>
				</inertia>
			</inertial>
			<collision name="torso_collision">
				<geometry>
					<mesh>
						<uri>model://roboy_xylophone_left_arm/meshes/CAD/torso.stl</uri>
						<scale>0.001 0.001 0.001</scale>
					</mesh>
				</geometry>
			</collision>
			<visual name="torso_visual">
				<geometry>
					<mesh>
						<uri>model://roboy_xylophone_left_arm/meshes/CAD/torso.stl</uri>
						<scale>0.001 0.001 0.001</scale>
					</mesh>
				</geometry>
			</visual>
		</link>
		<link name="base">
			<self_collide>false</self_collide>
			<pose frame="">0.0 0.0 0.0 0.0 -0.0 0.0</pose>
			<inertial>
				<pose frame="">0.0 0.0 0.0 0 0 0</pose>
				<mass>0.1</mass>
				<inertia>
					<ixx>0.1</ixx>
					<ixy>0.0</ixy>
					<ixz>0.0</ixz>
					<iyy>0.1</iyy>
					<iyz>0.0</iyz>
					<izz>0.1</izz>
				</inertia>
			</inertial>
			<collision name="base_collision">
				<geometry>
					<mesh>
						<uri>model://roboy_xylophone_left_arm/meshes/CAD/base.stl</uri>
						<scale>0.001 0.001 0.001</scale>
					</mesh>
				</geometry>
			</collision>
			<visual name="base_visual">
				<geometry>
					<mesh>
						<uri>model://roboy_xylophone_left_arm/meshes/CAD/base.stl</uri>
						<scale>0.001 0.001 0.001</scale>
					</mesh>
				</geometry>
			</visual>
		</link>
		<link name="hand_left">
			<self_collide>false</self_collide>
			<pose frame="">0.9409052109712956 0.030447147800822187 0.5442482629971966 0.0 -0.0 0.0</pose>
			<inertial>
				<pose frame="">0.0 0.0 0.0 0 0 0</pose>
				<mass>0.1</mass>
				<inertia>
					<ixx>0.1</ixx>
					<ixy>0.0</ixy>
					<ixz>0.0</ixz>
					<iyy>0.1</iyy>
					<iyz>0.0</iyz>
					<izz>0.1</izz>
				</inertia>
			</inertial>
			<collision name="hand_left_collision">
				<geometry>
					<mesh>
						<uri>model://roboy_xylophone_left_arm/meshes/CAD/hand_left.stl</uri>
						<scale>0.001 0.001 0.001</scale>
					</mesh>
				</geometry>
			</collision>
			<visual name="hand_left_visual">
				<geometry>
					<mesh>
						<uri>model://roboy_xylophone_left_arm/meshes/CAD/hand_left.stl</uri>
						<scale>0.001 0.001 0.001</scale>
					</mesh>
				</geometry>
			</visual>
		</link>
		<link name="lower_arm_left">
			<self_collide>false</self_collide>
			<pose frame="">0.7720537499627952 0.03206567887183061 0.5430484315962018 0.0 -0.0 0.0</pose>
			<inertial>
				<pose frame="">0.0 0.0 0.0 0 0 0</pose>
				<mass>0.1</mass>
				<inertia>
					<ixx>0.1</ixx>
					<ixy>0.0</ixy>
					<ixz>0.0</ixz>
					<iyy>0.1</iyy>
					<iyz>0.0</iyz>
					<izz>0.1</izz>
				</inertia>
			</inertial>
			<collision name="lower_arm_left_collision">
				<geometry>
					<mesh>
						<uri>model://roboy_xylophone_left_arm/meshes/CAD/lower_arm_left.stl</uri>
						<scale>0.001 0.001 0.001</scale>
					</mesh>
				</geometry>
			</collision>
			<visual name="lower_arm_left_visual">
				<geometry>
					<mesh>
						<uri>model://roboy_xylophone_left_arm/meshes/CAD/lower_arm_left.stl</uri>
						<scale>0.001 0.001 0.001</scale>
					</mesh>
				</geometry>
			</visual>
		</link>
		<link name="sphere_link1">
			<self_collide>false</self_collide>
			<pose frame="">0.2921800561556851 0.0076882557614745385 0.5492779566488885 0.0 -0.0 0.0</pose>
			<inertial>
				<pose frame="">0.0 0.0 0.0 0 0 0</pose>
				<mass>0.1</mass>
				<inertia>
					<ixx>0.1</ixx>
					<ixy>0.0</ixy>
					<ixz>0.0</ixz>
					<iyy>0.1</iyy>
					<iyz>0.0</iyz>
					<izz>0.1</izz>
				</inertia>
			</inertial>
			<collision name="sphere_link1_collision">
				<geometry>
					<mesh>
						<uri>model://roboy_xylophone_left_arm/meshes/CAD/sphere_link1.stl</uri>
						<scale>0.001 0.001 0.001</scale>
					</mesh>
				</geometry>
			</collision>
			<visual name="sphere_link1_visual">
				<geometry>
					<mesh>
						<uri>model://roboy_xylophone_left_arm/meshes/CAD/sphere_link1.stl</uri>
						<scale>0.001 0.001 0.001</scale>
					</mesh>
				</geometry>
			</visual>
		</link>
		<link name="sphere_link2">
			<self_collide>false</self_collide>
			<pose frame="">0.292180056155685 0.007688255761474526 0.5492779566488886 0.0 -0.0 0.0</pose>
			<inertial>
				<pose frame="">0.0 0.0 0.0 0 0 0</pose>
				<mass>0.1</mass>
				<inertia>
					<ixx>0.1</ixx>
					<ixy>0.0</ixy>
					<ixz>0.0</ixz>
					<iyy>0.1</iyy>
					<iyz>0.0</iyz>
					<izz>0.1</izz>
				</inertia>
			</inertial>
			<collision name="sphere_link2_collision">
				<geometry>
					<mesh>
						<uri>model://roboy_xylophone_left_arm/meshes/CAD/sphere_link2.stl</uri>
						<scale>0.001 0.001 0.001</scale>
					</mesh>
				</geometry>
			</collision>
			<visual name="sphere_link2_visual">
				<geometry>
					<mesh>
						<uri>model://roboy_xylophone_left_arm/meshes/CAD/sphere_link2.stl</uri>
						<scale>0.001 0.001 0.001</scale>
					</mesh>
				</geometry>
			</visual>
		</link>
		<link name="spine_v0_sphere_link1">
			<self_collide>false</self_collide>
			<pose frame="">-2.5535129566378586e-17 1.21968551632576e-15 0.16545118854293278 0.0 -0.0 0.0</pose>
			<inertial>
				<pose frame="">0.0 0.0 0.0 0 0 0</pose>
				<mass>0.1</mass>
				<inertia>
					<ixx>0.1</ixx>
					<ixy>0.0</ixy>
					<ixz>0.0</ixz>
					<iyy>0.1</iyy>
					<iyz>0.0</iyz>
					<izz>0.1</izz>
				</inertia>
			</inertial>
			<collision name="spine_v0_sphere_link1_collision">
				<geometry>
					<mesh>
						<uri>model://roboy_xylophone_left_arm/meshes/CAD/spine_v0_sphere_link1.stl</uri>
						<scale>0.001 0.001 0.001</scale>
					</mesh>
				</geometry>
			</collision>
			<visual name="spine_v0_sphere_link1_visual">
				<geometry>
					<mesh>
						<uri>model://roboy_xylophone_left_arm/meshes/CAD/spine_v0_sphere_link1.stl</uri>
						<scale>0.001 0.001 0.001</scale>
					</mesh>
				</geometry>
			</visual>
		</link>
		<link name="spine_v0_sphere_link2">
			<self_collide>false</self_collide>
			<pose frame="">-2.5535129566378586e-17 1.21968551632576e-15 0.16545118854293278 0.0 -0.0 0.0</pose>
			<inertial>
				<pose frame="">0.0 0.0 0.0 0 0 0</pose>
				<mass>0.1</mass>
				<inertia>
					<ixx>0.1</ixx>
					<ixy>0.0</ixy>
					<ixz>0.0</ixz>
					<iyy>0.1</iyy>
					<iyz>0.0</iyz>
					<izz>0.1</izz>
				</inertia>
			</inertial>
			<collision name="spine_v0_sphere_link2_collision">
				<geometry>
					<mesh>
						<uri>model://roboy_xylophone_left_arm/meshes/CAD/spine_v0_sphere_link2.stl</uri>
						<scale>0.001 0.001 0.001</scale>
					</mesh>
				</geometry>
			</collision>
			<visual name="spine_v0_sphere_link2_visual">
				<geometry>
					<mesh>
						<uri>model://roboy_xylophone_left_arm/meshes/CAD/spine_v0_sphere_link2.stl</uri>
						<scale>0.001 0.001 0.001</scale>
					</mesh>
				</geometry>
			</visual>
		</link>
		<link name="spine_v1_sphere_link1">
			<self_collide>false</self_collide>
			<pose frame="">-2.4424906541753444e-17 1.4876988529977098e-15 0.2044511885429327 0.0 -0.0 0.0</pose>
			<inertial>
				<pose frame="">0.0 0.0 0.0 0 0 0</pose>
				<mass>0.1</mass>
				<inertia>
					<ixx>0.1</ixx>
					<ixy>0.0</ixy>
					<ixz>0.0</ixz>
					<iyy>0.1</iyy>
					<iyz>0.0</iyz>
					<izz>0.1</izz>
				</inertia>
			</inertial>
			<collision name="spine_v1_sphere_link1_collision">
				<geometry>
					<mesh>
						<uri>model://roboy_xylophone_left_arm/meshes/CAD/spine_v1_sphere_link1.stl</uri>
						<scale>0.001 0.001 0.001</scale>
					</mesh>
				</geometry>
			</collision>
			<visual name="spine_v1_sphere_link1_visual">
				<geometry>
					<mesh>
						<uri>model://roboy_xylophone_left_arm/meshes/CAD/spine_v1_sphere_link1.stl</uri>
						<scale>0.001 0.001 0.001</scale>
					</mesh>
				</geometry>
			</visual>
		</link>
		<link name="spine_v1_sphere_link2">
			<self_collide>false</self_collide>
			<pose frame="">0.038287181318673716 -0.014496202783849334 -0.4472744037881896 0.0 -0.0 0.0</pose>
			<inertial>
				<pose frame="">0.0 0.0 0.0 0 0 0</pose>
				<mass>0.1</mass>
				<inertia>
					<ixx>0.1</ixx>
					<ixy>0.0</ixy>
					<ixz>0.0</ixz>
					<iyy>0.1</iyy>
					<iyz>0.0</iyz>
					<izz>0.1</izz>
				</inertia>
			</inertial>
			<collision name="spine_v1_sphere_link2_collision">
				<geometry>
					<mesh>
						<uri>model://roboy_xylophone_left_arm/meshes/CAD/spine_v1_sphere_link2.stl</uri>
						<scale>0.001 0.001 0.001</scale>
					</mesh>
				</geometry>
			</collision>
			<visual name="spine_v1_sphere_link2_visual">
				<geometry>
					<mesh>
						<uri>model://roboy_xylophone_left_arm/meshes/CAD/spine_v1_sphere_link2.stl</uri>
						<scale>0.001 0.001 0.001</scale>
					</mesh>
				</geometry>
			</visual>
		</link>
		<link name="spine_v2_sphere_link1">
			<self_collide>false</self_collide>
			<pose frame="">-2.55351295663786e-17 1.7563728249569977e-15 0.24345118854293277 0.0 -0.0 0.0</pose>
			<inertial>
				<pose frame="">0.0 0.0 0.0 0 0 0</pose>
				<mass>0.1</mass>
				<inertia>
					<ixx>0.1</ixx>
					<ixy>0.0</ixy>
					<ixz>0.0</ixz>
					<iyy>0.1</iyy>
					<iyz>0.0</iyz>
					<izz>0.1</izz>
				</inertia>
			</inertial>
			<collision name="spine_v2_sphere_link1_collision">
				<geometry>
					<mesh>
						<uri>model://roboy_xylophone_left_arm/meshes/CAD/spine_v2_sphere_link1.stl</uri>
						<scale>0.001 0.001 0.001</scale>
					</mesh>
				</geometry>
			</collision>
			<visual name="spine_v2_sphere_link1_visual">
				<geometry>
					<mesh>
						<uri>model://roboy_xylophone_left_arm/meshes/CAD/spine_v2_sphere_link1.stl</uri>
						<scale>0.001 0.001 0.001</scale>
					</mesh>
				</geometry>
			</visual>
		</link>
		<link name="spine_v2_sphere_link2">
			<self_collide>false</self_collide>
			<pose frame="">-2.55351295663786e-17 1.7563728249569977e-15 0.24345118854293277 0.0 -0.0 0.0</pose>
			<inertial>
				<pose frame="">0.0 0.0 0.0 0 0 0</pose>
				<mass>0.1</mass>
				<inertia>
					<ixx>0.1</ixx>
					<ixy>0.0</ixy>
					<ixz>0.0</ixz>
					<iyy>0.1</iyy>
					<iyz>0.0</iyz>
					<izz>0.1</izz>
				</inertia>
			</inertial>
			<collision name="spine_v2_sphere_link2_collision">
				<geometry>
					<mesh>
						<uri>model://roboy_xylophone_left_arm/meshes/CAD/spine_v2_sphere_link2.stl</uri>
						<scale>0.001 0.001 0.001</scale>
					</mesh>
				</geometry>
			</collision>
			<visual name="spine_v2_sphere_link2_visual">
				<geometry>
					<mesh>
						<uri>model://roboy_xylophone_left_arm/meshes/CAD/spine_v2_sphere_link2.stl</uri>
						<scale>0.001 0.001 0.001</scale>
					</mesh>
				</geometry>
			</visual>
		</link>
		<link name="spine_link1">
			<self_collide>false</self_collide>
			<pose frame="">0.011189120381749301 -0.008901810376598441 -0.66001016790189 0.0 -0.0 0.0</pose>
			<inertial>
				<pose frame="">0.0 0.0 0.0 0 0 0</pose>
				<mass>0.1</mass>
				<inertia>
					<ixx>0.1</ixx>
					<ixy>0.0</ixy>
					<ixz>0.0</ixz>
					<iyy>0.1</iyy>
					<iyz>0.0</iyz>
					<izz>0.1</izz>
				</inertia>
			</inertial>
			<collision name="spine_link1_collision">
				<geometry>
					<mesh>
						<uri>model://roboy_xylophone_left_arm/meshes/CAD/spine_link1.stl</uri>
						<scale>0.001 0.001 0.001</scale>
					</mesh>
				</geometry>
			</collision>
			<visual name="spine_link1_visual">
				<geometry>
					<mesh>
						<uri>model://roboy_xylophone_left_arm/meshes/CAD/spine_link1.stl</uri>
						<scale>0.001 0.001 0.001</scale>
					</mesh>
				</geometry>
			</visual>
		</link>
		<link name="spine_link2">
			<self_collide>false</self_collide>
			<pose frame="">0.002603966933772271 -0.002625720941718209 -0.6978369271400604 0.0 -0.0 0.0</pose>
			<inertial>
				<pose frame="">0.0 0.0 0.0 0 0 0</pose>
				<mass>0.1</mass>
				<inertia>
					<ixx>0.1</ixx>
					<ixy>0.0</ixy>
					<ixz>0.0</ixz>
					<iyy>0.1</iyy>
					<iyz>0.0</iyz>
					<izz>0.1</izz>
				</inertia>
			</inertial>
			<collision name="spine_link2_collision">
				<geometry>
					<mesh>
						<uri>model://roboy_xylophone_left_arm/meshes/CAD/spine_link2.stl</uri>
						<scale>0.001 0.001 0.001</scale>
					</mesh>
				</geometry>
			</collision>
			<visual name="spine_link2_visual">
				<geometry>
					<mesh>
						<uri>model://roboy_xylophone_left_arm/meshes/CAD/spine_link2.stl</uri>
						<scale>0.001 0.001 0.001</scale>
					</mesh>
				</geometry>
			</visual>
		</link>
		<joint name="wrist_left" type="revolute">
			<parent>lower_arm_left</parent>
			<child>hand_left</child>
			<pose frame="">-0.058968171343846194 0.00720460105233474 -0.0032218165351137174 0 0 0</pose>
			<axis>
				<xyz>0.998070009825298 0.04989378316758063 -0.036971149408146046</xyz>
				<limit>
					<lower>-1.5707963267948966</lower>
					<upper>1.5707963267948966</upper>
				</limit>
				<use_parent_model_frame>0</use_parent_model_frame>
			</axis>
		</joint>
		<joint name="elbow_left" type="revolute">
			<parent>upper_arm_left</parent>
			<child>lower_arm_left</child>
			<pose frame="">-0.15051663900487464 -0.013039730040602915 -0.016086388301349005 0 0 0</pose>
			<axis>
				<xyz>-0.011188426489530806 -0.022909252225328334 -0.9996749398055218</xyz>
				<limit>
					<lower>-1.5707963267948966</lower>
					<upper>0.0</upper>
				</limit>
				<use_parent_model_frame>0</use_parent_model_frame>
			</axis>
		</joint>
		<joint name="sphere_axis0" type="revolute">
			<parent>torso</parent>
			<child>sphere_link1</child>
			<pose frame="">1.8118839761882555e-15 2.5006720669218384e-06 -0.0006642072681172095 0 0 0</pose>
			<axis>
				<xyz>0.9986354432836129 0.050744296328168334 -0.012339684270769953</xyz>
				<limit>
					<lower>-3.141592653589793</lower>
					<upper>3.141592653589793</upper>
				</limit>
				<use_parent_model_frame>0</use_parent_model_frame>
			</axis>
		</joint>
		<joint name="sphere_axis1" type="revolute">
			<parent>sphere_link1</parent>
			<child>sphere_link2</child>
			<pose frame="">1.6697754290362355e-15 2.500672066912957e-06 -0.0006642072681174227 0 0 0</pose>
			<axis>
				<xyz>-0.05101049431667491 0.9984488883025682 -0.022310242422111142</xyz>
				<limit>
					<lower>-3.141592653589793</lower>
					<upper>3.141592653589793</upper>
				</limit>
				<use_parent_model_frame>0</use_parent_model_frame>
			</axis>
		</joint>
		<joint name="sphere_axis2" type="revolute">
			<parent>sphere_link2</parent>
			<child>upper_arm_left</child>
			<pose frame="">-0.0895073755057556 -0.00484059198874423 -0.012755739421477301 0 0 0</pose>
			<axis>
				<xyz>0.9986354432836148 0.05074429632816839 -0.012339684270770136</xyz>
				<limit>
					<lower>-3.141592653589793</lower>
					<upper>3.141592653589793</upper>
				</limit>
				<use_parent_model_frame>0</use_parent_model_frame>
			</axis>
		</joint>
		<joint name="spine_v0_axis0" type="revolute">
			<parent>base</parent>
			<child>spine_v0_sphere_link1</child>
			<pose frame="">0.0 0.0 0.0 0 0 0</pose>
			<axis>
				<xyz>1.0 -1.3884488160727078e-17 9.557898670517335e-32</xyz>
				<limit>
					<lower>-0.08726646259971647</lower>
					<upper>0.08726646259971647</upper>
				</limit>
				<use_parent_model_frame>0</use_parent_model_frame>
			</axis>
		</joint>
		<joint name="spine_v0_axis2" type="revolute">
			<parent>spine_v0_sphere_link2</parent>
			<child>spine_link1</child>
			<pose frame="">-0.011189120381749327 0.00890181037659967 0.8254613564448228 0 0 0</pose>
			<axis>
				<xyz>1.650853085000251e-33 7.002767308714536e-15 1.0</xyz>
				<limit>
					<lower>-0.08726646259971647</lower>
					<upper>0.08726646259971647</upper>
				</limit>
				<use_parent_model_frame>0</use_parent_model_frame>
			</axis>
		</joint>
		<joint name="spine_v0_axis1" type="revolute">
			<parent>spine_v0_sphere_link1</parent>
			<child>spine_v0_sphere_link2</child>
			<pose frame="">-1.1832913578315177e-32 2.9154875750830205e-17 -7.105427357601002e-17 0 0 0</pose>
			<axis>
				<xyz>-1.3884488160727078e-17 -1.0 7.002767308714536e-15</xyz>
				<limit>
					<lower>-0.08726646259971647</lower>
					<upper>0.08726646259971647</upper>
				</limit>
				<use_parent_model_frame>0</use_parent_model_frame>
			</axis>
		</joint>
		<joint name="spine_v1_axis0" type="revolute">
			<parent>spine_link1</parent>
			<child>spine_v1_sphere_link1</child>
			<pose frame="">-1.1102230246251408e-18 4.575236400207278e-19 0.0 0 0 0</pose>
			<axis>
				<xyz>1.0 -1.3884488160727078e-17 9.557898670517335e-32</xyz>
				<limit>
					<lower>-0.08726646259971647</lower>
					<upper>0.08726646259971647</upper>
				</limit>
				<use_parent_model_frame>0</use_parent_model_frame>
			</axis>
		</joint>
		<joint name="spine_v1_axis2" type="revolute">
			<parent>spine_v1_sphere_link2</parent>
			<child>spine_link2</child>
			<pose frame="">-0.002603966933772298 0.002625720941719706 0.902288115682993 0 0 0</pose>
			<axis>
				<xyz>1.650853085000251e-33 7.002767308714536e-15 1.0</xyz>
				<limit>
					<lower>-0.08726646259971647</lower>
					<upper>0.08726646259971647</upper>
				</limit>
				<use_parent_model_frame>0</use_parent_model_frame>
			</axis>
		</joint>
		<joint name="spine_v1_axis1" type="revolute">
			<parent>spine_v1_sphere_link1</parent>
			<child>spine_v1_sphere_link2</child>
			<pose frame="">-0.038287181318673744 0.014496202783850852 0.6517255923311224 0 0 0</pose>
			<axis>
				<xyz>-1.3884488160727078e-17 -1.0 7.002767308714536e-15</xyz>
				<limit>
					<lower>-0.08726646259971647</lower>
					<upper>0.08726646259971647</upper>
				</limit>
				<use_parent_model_frame>0</use_parent_model_frame>
			</axis>
		</joint>
		<joint name="spine_v2_axis0" type="revolute">
			<parent>spine_link2</parent>
			<child>spine_v2_sphere_link1</child>
			<pose frame="">1.5777218104420236e-32 2.544119927043743e-19 0.0 0 0 0</pose>
			<axis>
				<xyz>1.0 -1.3884488160727078e-17 9.557898670517335e-32</xyz>
				<limit>
					<lower>-0.08726646259971647</lower>
					<upper>0.08726646259971647</upper>
				</limit>
				<use_parent_model_frame>0</use_parent_model_frame>
			</axis>
		</joint>
		<joint name="spine_v2_axis2" type="revolute">
			<parent>spine_v2_sphere_link2</parent>
			<child>torso</child>
			<pose frame="">2.2546048077883077e-16 -8.175814182545408e-16 -0.057461655714317036 0 0 0</pose>
			<axis>
				<xyz>1.650853085000251e-33 7.002767308714536e-15 1.0</xyz>
				<limit>
					<lower>-0.08726646259971647</lower>
					<upper>0.08726646259971647</upper>
				</limit>
				<use_parent_model_frame>0</use_parent_model_frame>
			</axis>
		</joint>
		<joint name="spine_v2_axis1" type="revolute">
			<parent>spine_v2_sphere_link1</parent>
			<child>spine_v2_sphere_link2</child>
			<pose frame="">3.944304526105059e-33 2.940928774353559e-17 3.552713678800501e-17 0 0 0</pose>
			<axis>
				<xyz>-1.3884488160727078e-17 -1.0 7.002767308714536e-15</xyz>
				<limit>
					<lower>-0.08726646259971647</lower>
					<upper>0.08726646259971647</upper>
				</limit>
				<use_parent_model_frame>0</use_parent_model_frame>
			</axis>
		</joint>
		<plugin filename="libmusc_plugin.so" name="musc_plugin">
			<myoMuscle name="motor0">
				<link name="torso">
					<viaPoint type="FIXPOINT">0.2376902809880496 -0.017689027265440305 0.12858346006581597</viaPoint>
					<viaPoint type="FIXPOINT">0.2719330451177387 -0.013737008525793537 0.2674943860318247</viaPoint>
					<viaPoint type="FIXPOINT">0.2889410922378474 -0.010689615277496609 0.2753417911253602</viaPoint>
				</link>
				<link name="upper_arm_left">
					<viaPoint type="FIXPOINT">-0.017877238675911684 -0.020085054046078375 0.010369300632405683</viaPoint>
				</link>
			</myoMuscle>
			<myoMuscle name="motor1">
				<link name="torso">
					<viaPoint type="FIXPOINT">0.2400353945194028 -0.025509439663539683 0.16638120522593233</viaPoint>
				</link>
				<link name="upper_arm_left">
					<viaPoint type="FIXPOINT">-0.018416237230042258 -0.019411435625892495 -0.030481077403727568</viaPoint>
				</link>
			</myoMuscle>
			<myoMuscle name="motor2">
				<link name="torso">
					<viaPoint type="FIXPOINT">0.25121801331283644 -0.028667405657348308 0.21364625546833005</viaPoint>
				</link>
				<link name="upper_arm_left">
					<viaPoint type="FIXPOINT">-0.029359285972953588 -0.014888786093752205 -0.0075328734684702425</viaPoint>
				</link>
			</myoMuscle>
			<myoMuscle name="motor3">
				<link name="torso">
					<viaPoint type="FIXPOINT">0.28063665292590706 -0.028534400330320377 0.2570875816989544</viaPoint>
				</link>
				<link name="upper_arm_left">
					<viaPoint type="FIXPOINT">-0.017736568673508514 -0.023692964431501113 0.006916795480576638</viaPoint>
				</link>
			</myoMuscle>
			<myoMuscle name="motor4">
				<link name="torso">
					<viaPoint type="FIXPOINT">0.30339350272539384 2.7462612419274214e-15 0.2952321087635332</viaPoint>
				</link>
				<link name="upper_arm_left">
					<viaPoint type="FIXPOINT">-0.010797024311095598 -0.00017331182222428244 0.0169302755157112</viaPoint>
				</link>
			</myoMuscle>
			<myoMuscle name="motor5">
				<link name="torso">
					<viaPoint type="FIXPOINT">0.2769871340021273 0.04289909901328245 0.25549140716655055</viaPoint>
				</link>
				<link name="upper_arm_left">
					<viaPoint type="FIXPOINT">-0.011864639849746084 0.01900742939997809 0.009406136462714017</viaPoint>
				</link>
			</myoMuscle>
			<myoMuscle name="motor6">
				<link name="torso">
					<viaPoint type="FIXPOINT">0.24756132617262325 0.04290640006489047 0.21204694580365818</viaPoint>
				</link>
				<link name="upper_arm_left">
					<viaPoint type="FIXPOINT">-0.03070596302291385 0.011470264557435597 -0.008121863868413967</viaPoint>
				</link>
			</myoMuscle>
			<myoMuscle name="motor7">
				<link name="torso">
					<viaPoint type="FIXPOINT">0.236174665401922 0.0500581616119091 0.16469265459157925</viaPoint>
				</link>
				<link name="upper_arm_left">
					<viaPoint type="FIXPOINT">-0.020376137421781734 0.019726821064350683 -0.028145726040115733</viaPoint>
				</link>
			</myoMuscle>
			<myoMuscle name="motor8">
				<link name="torso">
					<viaPoint type="FIXPOINT">0.23414595021784793 0.05384194818674343 0.12702585696969615</viaPoint>
					<viaPoint type="FIXPOINT">0.26969226825276893 0.027710898774527478 0.2670559881812207</viaPoint>
					<viaPoint type="FIXPOINT">0.2865401700456325 0.02607560577031493 0.2752279682345082</viaPoint>
				</link>
				<link name="upper_arm_left">
					<viaPoint type="FIXPOINT">-0.011977430731824867 0.020805688626636596 0.007673063477909992</viaPoint>
				</link>
			</myoMuscle>
			<myoMuscle name="motor9">
				<link name="upper_arm_left">
					<viaPoint type="FIXPOINT">0.11999644555612583 -0.058625120924673625 -0.012313168773832785</viaPoint>
				</link>
				<link name="lower_arm_left">
					<viaPoint type="FIXPOINT">-0.12509466532089733 -0.016491665267938948 0.0017780021441362237</viaPoint>
				</link>
			</myoMuscle>
			<myoMuscle name="motor10">
				<link name="upper_arm_left">
					<viaPoint type="FIXPOINT">0.1134821981232372 0.07004667295093085 -0.010368121868768725</viaPoint>
				</link>
				<link name="lower_arm_left">
					<viaPoint type="FIXPOINT">-0.12703942064320345 0.02157381156360588 0.0009274328000523724</viaPoint>
				</link>
			</myoMuscle>
			<myoMuscle name="motor11">
				<link name="upper_arm_left">
					<viaPoint type="FIXPOINT">0.1446115250484685 0.0006536350064882645 0.03477835535218596</viaPoint>
					<viaPoint type="FIXPOINT">0.17636951728988343 0.0017237164697407347 0.02211498235026312</viaPoint>
				</link>
				<link name="lower_arm_left">
					<viaPoint type="FIXPOINT">-0.1270827422174935 -0.010423896754005124 0.04817631980318183</viaPoint>
					<viaPoint type="FIXPOINT">-0.11193627218989662 -0.05876045560771059 0.001416383073526646</viaPoint>
				</link>
			</myoMuscle>
			<myoMuscle name="motor12">
				<link name="upper_arm_left">
					<viaPoint type="FIXPOINT">0.14379042572931497 0.015515817606305427 0.029445327116564002</viaPoint>
					<viaPoint type="FIXPOINT">0.16918419471883658 0.024155474124269008 0.027303050384283767</viaPoint>
				</link>
				<link name="lower_arm_left">
					<viaPoint type="FIXPOINT">-0.12709952485722767 -0.010458260632343338 0.04667680739347247</viaPoint>
					<viaPoint type="FIXPOINT">-0.11731600160476817 0.04711131437846328 0.001416383073526646</viaPoint>
				</link>
			</myoMuscle>
			<myoMuscle name="motor13">
				<link name="base">
					<viaPoint type="FIXPOINT">-0.19499999851461478 -0.11347765649897372 0.08723717349165262</viaPoint>
				</link>
				<link name="torso">
					<viaPoint type="FIXPOINT">0.1354387645981041 -0.06208086211105069 0.02591907067123657</viaPoint>
				</link>
			</myoMuscle>
			<myoMuscle name="motor14">
				<link name="base">
					<viaPoint type="FIXPOINT">0.1949999985146147 -0.1134776564989737 0.0872371734916526</viaPoint>
				</link>
				<link name="torso">
					<viaPoint type="FIXPOINT">-0.13663898856535087 -0.060004688697670255 0.024116581729240354</viaPoint>
				</link>
			</myoMuscle>
			<myoMuscle name="motor15">
				<link name="base">
					<viaPoint type="FIXPOINT">-0.22500000148538477 0.0015223435010262346 0.08723717349165344</viaPoint>
				</link>
				<link name="torso">
					<viaPoint type="FIXPOINT">-0.15008296104407892 2.5006720666453067e-06 0.014700010668195382</viaPoint>
				</link>
			</myoMuscle>
			<myoMuscle name="motor16">
				<link name="base">
					<viaPoint type="FIXPOINT">0.2250000014853848 0.0015223435010263528 0.08723717349165344</viaPoint>
				</link>
				<link name="torso">
					<viaPoint type="FIXPOINT">0.15008296104408259 2.5006720675284203e-06 0.014700010668195667</viaPoint>
				</link>
			</myoMuscle>
			<myoMuscle name="motor17">
				<link name="base">
					<viaPoint type="FIXPOINT">-0.19499999851461464 0.11652234350102626 0.08723717349165426</viaPoint>
				</link>
				<link name="torso">
					<viaPoint type="FIXPOINT">0.11845723973009772 0.06717115764172059 -0.0037543238378714605</viaPoint>
				</link>
			</myoMuscle>
			<myoMuscle name="motor18">
				<link name="base">
					<viaPoint type="FIXPOINT">0.19499999851461486 0.1165223435010261 0.08723717349165426</viaPoint>
				</link>
				<link name="torso">
					<viaPoint type="FIXPOINT">-0.1154412573596858 0.06857597545288585 -0.007486660540101511</viaPoint>
				</link>
			</myoMuscle>
			<endEffector link="hand_left" name="endeffector0">0.12126360984138898 -0.22572718122777527 -0.0007270220833336083</endEffector>
		</plugin>
	</model>
</sdf>
