<?xml version="1.0" ?>
<sdf version="1.6">
	<model name="roboy_xylophone_left_arm">
		<link name="upper_arm_left">
			<self_collide>false</self_collide>
			<pose frame="">0.4100706463412088 0.45489205694246326 0.035546763993294324 0.0 -0.0 0.0</pose>
			<inertial>
				<pose frame="">0.0 0.0 0.0 0 0 0</pose>
				<mass>1</mass>
				<inertia>
					<ixx>0.01</ixx>
					<ixy>0.0</ixy>
					<ixz>0.0</ixz>
					<iyy>0.01</iyy>
					<iyz>0.0</iyz>
					<izz>0.01</izz>
				</inertia>
			</inertial>
			<collision name="upper_arm_left_collision">
				<geometry>
					<mesh>
						<uri>model://roboy_xylophone_left_arm/meshes/CAD/upper_arm_left.stl</uri>
						<scale>0.001 0.001 0.001</scale>
					</mesh>
				</geometry>
			</collision>
			<visual name="upper_arm_left_visual">
				<geometry>
					<mesh>
						<uri>model://roboy_xylophone_left_arm/meshes/CAD/upper_arm_left.stl</uri>
						<scale>0.001 0.001 0.001</scale>
					</mesh>
				</geometry>
			</visual>
		</link>
		<link name="lower_arm_left">
			<self_collide>false</self_collide>
			<pose frame="">0.46644921463301176 0.3384918435821719 0.22660235540454346 0.0 -0.0 0.0</pose>
			<inertial>
				<pose frame="">0.0 0.0 0.0 0 0 0</pose>
				<mass>0.5</mass>
				<inertia>
					<ixx>0.01</ixx>
					<ixy>0.0</ixy>
					<ixz>0.0</ixz>
					<iyy>0.01</iyy>
					<iyz>0.0</iyz>
					<izz>0.01</izz>
				</inertia>
			</inertial>
			<collision name="lower_arm_left_collision">
				<geometry>
					<mesh>
						<uri>model://roboy_xylophone_left_arm/meshes/CAD/lower_arm_left.stl</uri>
						<scale>0.001 0.001 0.001</scale>
					</mesh>
				</geometry>
			</collision>
			<visual name="lower_arm_left_visual">
				<geometry>
					<mesh>
						<uri>model://roboy_xylophone_left_arm/meshes/CAD/lower_arm_left.stl</uri>
						<scale>0.001 0.001 0.001</scale>
					</mesh>
				</geometry>
			</visual>
		</link>
		<link name="torso">
			<self_collide>false</self_collide>
			<pose frame="">-0.00499999999999861 0.04650000000000084 -0.005674885790744078 0.0 -0.0 0.0</pose>
			<inertial>
				<pose frame="">0.0 0.0 0.0 0 0 0</pose>
				<mass>10</mass>
				<inertia>
					<ixx>0.01</ixx>
					<ixy>0.0</ixy>
					<ixz>0.0</ixz>
					<iyy>0.01</iyy>
					<iyz>0.0</iyz>
					<izz>0.01</izz>
				</inertia>
			</inertial>
			<collision name="torso_collision">
				<geometry>
					<mesh>
						<uri>model://roboy_xylophone_left_arm/meshes/CAD/torso.stl</uri>
						<scale>0.001 0.001 0.001</scale>
					</mesh>
				</geometry>
			</collision>
			<visual name="torso_visual">
				<geometry>
					<mesh>
						<uri>model://roboy_xylophone_left_arm/meshes/CAD/torso.stl</uri>
						<scale>0.001 0.001 0.001</scale>
					</mesh>
				</geometry>
			</visual>
		</link>
		<link name="shoulder_left_link2">
			<self_collide>false</self_collide>
			<pose frame="">0.2876048416483075 0.5944435631591347 -0.013042466787542933 0.0 -0.0 0.0</pose>
			<inertial>
				<pose frame="">0.0 0.0 0.0 0 0 0</pose>
				<mass>0.0001</mass>
				<inertia>
					<ixx>0.01</ixx>
					<ixy>0.0</ixy>
					<ixz>0.0</ixz>
					<iyy>0.01</iyy>
					<iyz>0.0</iyz>
					<izz>0.01</izz>
				</inertia>
			</inertial>
			<collision name="shoulder_left_link2_collision">
				<geometry>
					<mesh>
						<uri>model://roboy_xylophone_left_arm/meshes/CAD/shoulder_left_link2.stl</uri>
						<scale>0.001 0.001 0.001</scale>
					</mesh>
				</geometry>
			</collision>
			<visual name="shoulder_left_link2_visual">
				<geometry>
					<mesh>
						<uri>model://roboy_xylophone_left_arm/meshes/CAD/shoulder_left_link2.stl</uri>
						<scale>0.001 0.001 0.001</scale>
					</mesh>
				</geometry>
			</visual>
		</link>
		<link name="shoulder_left_link3">
			<self_collide>false</self_collide>
			<pose frame="">0.2876048416483075 0.5944435631591348 -0.013042466787542941 0.0 -0.0 0.0</pose>
			<inertial>
				<pose frame="">0.0 0.0 0.0 0 0 0</pose>
				<mass>0.0001</mass>
				<inertia>
					<ixx>0.01</ixx>
					<ixy>0.0</ixy>
					<ixz>0.0</ixz>
					<iyy>0.01</iyy>
					<iyz>0.0</iyz>
					<izz>0.01</izz>
				</inertia>
			</inertial>
			<collision name="shoulder_left_link3_collision">
				<geometry>
					<mesh>
						<uri>model://roboy_xylophone_left_arm/meshes/CAD/shoulder_left_link3.stl</uri>
						<scale>0.001 0.001 0.001</scale>
					</mesh>
				</geometry>
			</collision>
			<visual name="shoulder_left_link3_visual">
				<geometry>
					<mesh>
						<uri>model://roboy_xylophone_left_arm/meshes/CAD/shoulder_left_link3.stl</uri>
						<scale>0.001 0.001 0.001</scale>
					</mesh>
				</geometry>
			</visual>
		</link>
		<link name="base">
			<self_collide>false</self_collide>
			<pose frame="">0.1811382928871777 -0.26864496038762165 -0.002847881300303099 0.0 -0.0 0.0</pose>
			<inertial>
				<pose frame="">0.0 0.0 0.0 0 0 0</pose>
				<mass>933.2436721945746</mass>
				<inertia>
					<ixx>174.14147750133725</ixx>
					<ixy>0.09806071324502409</ixy>
					<ixz>0.11129666964557769</ixz>
					<iyy>347.0634323190336</iyy>
					<iyz>-0.026480256273293527</iyz>
					<izz>174.13475410712158</izz>
				</inertia>
			</inertial>
			<collision name="base_collision">
				<geometry>
					<mesh>
						<uri>model://roboy_xylophone_left_arm/meshes/CAD/base.stl</uri>
						<scale>0.001 0.001 0.001</scale>
					</mesh>
				</geometry>
			</collision>
			<visual name="base_visual">
				<geometry>
					<mesh>
						<uri>model://roboy_xylophone_left_arm/meshes/CAD/base.stl</uri>
						<scale>0.001 0.001 0.001</scale>
					</mesh>
				</geometry>
			</visual>
		</link>
		<link name="hand_left">
			<self_collide>false</self_collide>
			<pose frame="">0.428333224189446 0.30957115126631307 0.43781245268887836 0.0 -0.0 0.0</pose>
			<inertial>
				<pose frame="">0.0 0.0 0.0 0 0 0</pose>
				<mass>0.3</mass>
				<inertia>
					<ixx>0.01</ixx>
					<ixy>0.0</ixy>
					<ixz>0.0</ixz>
					<iyy>0.01</iyy>
					<iyz>0.0</iyz>
					<izz>0.01</izz>
				</inertia>
			</inertial>
			<collision name="hand_left_collision">
				<geometry>
					<mesh>
						<uri>model://roboy_xylophone_left_arm/meshes/CAD/hand_left.stl</uri>
						<scale>0.001 0.001 0.001</scale>
					</mesh>
				</geometry>
			</collision>
			<visual name="hand_left_visual">
				<geometry>
					<mesh>
						<uri>model://roboy_xylophone_left_arm/meshes/CAD/hand_left.stl</uri>
						<scale>0.001 0.001 0.001</scale>
					</mesh>
				</geometry>
			</visual>
		</link>
		<joint name="elbow_left" type="revolute">
			<parent>upper_arm_left</parent>
			<child>lower_arm_left</child>
			<pose frame="">-0.00408853405367303 -0.004125865752205229 -0.15807832000571787 0 0 0</pose>
			<axis>
				<xyz>0.7594274010491028 0.6297741060326124 0.16326235912370105</xyz>
				<limit>
					<lower>0.0</lower>
					<upper>1.5707963267948966</upper>
				</limit>
				<use_parent_model_frame>0</use_parent_model_frame>
			</axis>
		</joint>
		<joint name="shoulder_left_axis_3" type="revolute">
			<parent>shoulder_left_link3</parent>
			<child>upper_arm_left</child>
			<pose frame="">-0.11488555770836228 0.12948525908076497 -0.04538091088651733 0 0 0</pose>
			<axis>
				<xyz>0.5866987569960098 -0.7713822345104742 0.24648329927393786</xyz>
				<limit>
					<lower>-3.141592653589793</lower>
					<upper>3.141592653589793</upper>
				</limit>
				<use_parent_model_frame>0</use_parent_model_frame>
			</axis>
		</joint>
		<joint name="shoulder_left_axis_1" type="revolute">
			<parent>torso</parent>
			<child>shoulder_left_link2</child>
			<pose frame="">-0.000270200396726068 -0.00011817639554919878 -0.005288740862922948 0 0 0</pose>
			<axis>
				<xyz>0.051010494316667994 0.02231024242210457 0.9984488883025681</xyz>
				<limit>
					<lower>-3.141592653589793</lower>
					<upper>3.141592653589793</upper>
				</limit>
				<use_parent_model_frame>0</use_parent_model_frame>
			</axis>
		</joint>
		<joint name="shoulder_left_axis_2" type="revolute">
			<parent>shoulder_left_link2</parent>
			<child>shoulder_left_link3</child>
			<pose frame="">0.004015240174514183 0.0029671816983948673 -0.0002714389612516821 0 0 0</pose>
			<axis>
				<xyz>-0.8030480349026285 -0.5934363396789987 0.05428779225032456</xyz>
				<limit>
					<lower>-3.141592653589793</lower>
					<upper>3.141592653589793</upper>
				</limit>
				<use_parent_model_frame>0</use_parent_model_frame>
			</axis>
		</joint>
		<joint name="wrist_left" type="revolute">
			<parent>lower_arm_left</parent>
			<child>hand_left</child>
			<pose frame="">0.0048678713276773065 0.02058260294314078 -0.10898752801840779 0 0 0</pose>
			<axis>
				<xyz>-0.19385160612841565 -0.05923743990890483 0.9792407673879149</xyz>
				<limit>
					<lower>-1.5707963267948966</lower>
					<upper>1.5707963267948966</upper>
				</limit>
				<use_parent_model_frame>0</use_parent_model_frame>
			</axis>
		</joint>
		<joint name="base_joint" type="revolute">
			<parent>base</parent>
			<child>torso</child>
			<pose frame="">-4.9404924595819467e-17 7.105427357601002e-17 -6.661338147750939e-18 0 0 0</pose>
			<axis>
				<xyz>3.3617487931000495e-15 -1.0000000000000016 2.8746917347582347e-16</xyz>
				<limit>
					<lower>-1.57</lower>
					<upper>1.57</upper>
				</limit>
				<use_parent_model_frame>0</use_parent_model_frame>
			</axis>
		</joint>
		<plugin filename="libmoveit_plugin.so" name="moveit_plugin"></plugin>
		<!--<plugin filename="libmusc_plugin.so" name="musc_plugin">-->
			<!--<myoMuscle name="motor0">-->
				<!--<link name="torso">-->
					<!--<viaPoint type="FIXPOINT">0.23757805790055161 0.42944722178973777 0.015492439711174616</viaPoint>-->
					<!--<viaPoint type="FIXPOINT">0.2718871356728519 0.5683871510708945 0.012838404526322811</viaPoint>-->
					<!--<viaPoint type="FIXPOINT">0.28894109223784553 0.5762546353826103 0.010689615277497923</viaPoint>-->
				<!--</link>-->
				<!--<link name="upper_arm_left">-->
					<!--<viaPoint type="FIXPOINT">-0.07535068399890087 0.09017367094760352 -0.015105150550292988</viaPoint>-->
				<!--</link>-->
			<!--</myoMuscle>-->
			<!--<myoMuscle name="motor1">-->
				<!--<link name="torso">-->
					<!--<viaPoint type="FIXPOINT">0.24003539451940126 0.4672940494831832 0.025509439663540263</viaPoint>-->
				<!--</link>-->
				<!--<link name="upper_arm_left">-->
					<!--<viaPoint type="FIXPOINT">-0.09901927756261383 0.07575918855613586 -0.01604939794333579</viaPoint>-->
				<!--</link>-->
			<!--</myoMuscle>-->
			<!--<myoMuscle name="motor2">-->
				<!--<link name="torso">-->
					<!--<viaPoint type="FIXPOINT">0.2512180133128348 0.5145590997255809 0.028667405657349203</viaPoint>-->
				<!--</link>-->
				<!--<link name="upper_arm_left">-->
					<!--<viaPoint type="FIXPOINT">-0.09027617582093549 0.100183773521481 -0.017704349620765846</viaPoint>-->
				<!--</link>-->
			<!--</myoMuscle>-->
			<!--<myoMuscle name="motor3">-->
				<!--<link name="torso">-->
					<!--<viaPoint type="FIXPOINT">0.28063665292590523 0.5580004259562044 0.028534400330321574</viaPoint>-->
				<!--</link>-->
				<!--<link name="upper_arm_left">-->
					<!--<viaPoint type="FIXPOINT">-0.07144666095453495 0.09967744234003476 -0.0068264762889217595</viaPoint>-->
				<!--</link>-->
			<!--</myoMuscle>-->
			<!--<myoMuscle name="motor4">-->
				<!--<link name="torso">-->
					<!--<viaPoint type="FIXPOINT">0.30339350272539195 0.5961449530207843 -7.360778653264788e-16</viaPoint>-->
				<!--</link>-->
				<!--<link name="upper_arm_left">-->
					<!--<viaPoint type="FIXPOINT">-0.057686117619861435 0.1034888273052779 -0.027652467478161313</viaPoint>-->
				<!--</link>-->
			<!--</myoMuscle>-->
			<!--<myoMuscle name="motor8">-->
				<!--<link name="torso">-->
					<!--<viaPoint type="FIXPOINT">0.23414595021784673 0.427938701226947 -0.053841948186743455</viaPoint>-->
					<!--<viaPoint type="FIXPOINT">0.26979225356546843 0.5677688240604152 -0.026839119223290568</viaPoint>-->
					<!--<viaPoint type="FIXPOINT">0.2865401700456306 0.5761408124917585 -0.026075605770313627</viaPoint>-->
				<!--</link>-->
				<!--<link name="upper_arm_left">-->
					<!--<viaPoint type="FIXPOINT">-0.06822190628509824 0.08654690681622838 -0.043423768744111774</viaPoint>-->
				<!--</link>-->
			<!--</myoMuscle>-->
			<!--<myoMuscle name="motor5">-->
				<!--<link name="torso">-->
					<!--<viaPoint type="FIXPOINT">0.2769871340021255 0.5564042514238009 -0.04289909901328127</viaPoint>-->
				<!--</link>-->
				<!--<link name="upper_arm_left">-->
					<!--<viaPoint type="FIXPOINT">-0.0599438034724102 0.0945741596486657 -0.05017746121953253</viaPoint>-->
				<!--</link>-->
			<!--</myoMuscle>-->
			<!--<myoMuscle name="motor6">-->
				<!--<link name="torso">-->
					<!--<viaPoint type="FIXPOINT">0.24756132617262158 0.5129597900609095 -0.04290640006488961</viaPoint>-->
				<!--</link>-->
				<!--<link name="upper_arm_left">-->
					<!--<viaPoint type="FIXPOINT">-0.082009663466049 0.09597818713572202 -0.05054254665407749</viaPoint>-->
				<!--</link>-->
			<!--</myoMuscle>-->
			<!--<myoMuscle name="motor7">-->
				<!--<link name="torso">-->
					<!--<viaPoint type="FIXPOINT">0.23617466540192045 0.4656054988488306 -0.05005816161190855</viaPoint>-->
				<!--</link>-->
				<!--<link name="upper_arm_left">-->
					<!--<viaPoint type="FIXPOINT">-0.08959716288761613 0.07257190974315628 -0.05250847345608161</viaPoint>-->
				<!--</link>-->
			<!--</myoMuscle>-->
			<!--<myoMuscle name="motor9">-->
				<!--<link name="upper_arm_left">-->
					<!--<viaPoint type="FIXPOINT">0.026207489136729406 -0.06932976923597799 0.05413962704921827</viaPoint>-->
				<!--</link>-->
				<!--<link name="lower_arm_left">-->
					<!--<viaPoint type="FIXPOINT">-0.005083700668161839 0.01706652688108946 -0.13290817856966958</viaPoint>-->
				<!--</link>-->
			<!--</myoMuscle>-->
			<!--<myoMuscle name="motor10">-->
				<!--<link name="upper_arm_left">-->
					<!--<viaPoint type="FIXPOINT">0.05966064141699071 -0.09097650262680532 -0.006878304627277978</viaPoint>-->
					<!--<viaPoint type="FIXPOINT">0.08759915860269288 -0.14278643195352245 0.0568914012875422</viaPoint>-->
				<!--</link>-->
			<!--</myoMuscle>-->
			<!--<endEffector link="hand_left" name="endeffector0">-0.024264608425818394 0.2520644191149032 0.06797017315300487</endEffector>-->
		<!--</plugin>-->
	</model>
</sdf>
