<?xml version="1.0" ?>
<sdf version="1.6">
	<model name="roboy_xylophone_left_arm">
		<link name="upper_arm_left">
			<self_collide>false</self_collide>
			<pose frame="">0.47525602631534186 0.01714193037585743 0.5581680840350569 0.0 -0.0 0.0</pose>
			<inertial>
				<pose frame="">0.0 0.0 0.0 0 0 0</pose>
				<mass>1.2824428697417236</mass>
				<inertia>
					<ixx>0.4024486697593224</ixx>
					<ixy>-0.010686402192530009</ixy>
					<ixz>-0.012264295959232901</ixz>
					<iyy>0.6959076882859703</iyy>
					<iyz>-0.3402753322906723</iyz>
					<izz>0.2979984162484978</izz>
				</inertia>
			</inertial>
			<collision name="upper_arm_left_collision">
				<geometry>
					<mesh>
						<uri>model://roboy_xylophone_left_arm/meshes/CAD/upper_arm_left.stl</uri>
						<scale>0.001 0.001 0.001</scale>
					</mesh>
				</geometry>
			</collision>
			<visual name="upper_arm_left_visual">
				<geometry>
					<mesh>
						<uri>model://roboy_xylophone_left_arm/meshes/CAD/upper_arm_left.stl</uri>
						<scale>0.001 0.001 0.001</scale>
					</mesh>
				</geometry>
			</visual>
		</link>
		<link name="torso">
			<self_collide>false</self_collide>
			<pose frame="">0.008583084223350608 -0.008164586655353396 0.39844861642463053 0.0 -0.0 0.0</pose>
			<inertial>
				<pose frame="">0.0 0.0 0.0 0 0 0</pose>
				<mass>17.35475770563241</mass>
				<inertia>
					<ixx>3.1867053233126024</ixx>
					<ixy>-0.0013339320204242078</ixy>
					<ixz>0.06576212150919633</ixz>
					<iyy>3.4213033758007674</iyy>
					<iyz>-0.07512681864475856</iyz>
					<izz>0.3313904450729579</izz>
				</inertia>
			</inertial>
			<collision name="torso_collision">
				<geometry>
					<mesh>
						<uri>model://roboy_xylophone_left_arm/meshes/CAD/torso.stl</uri>
						<scale>0.001 0.001 0.001</scale>
					</mesh>
				</geometry>
			</collision>
			<visual name="torso_visual">
				<geometry>
					<mesh>
						<uri>model://roboy_xylophone_left_arm/meshes/CAD/torso.stl</uri>
						<scale>0.001 0.001 0.001</scale>
					</mesh>
				</geometry>
			</visual>
		</link>
		<link name="base">
			<self_collide>false</self_collide>
			<pose frame="">0.0 0.0 0.0 0.0 -0.0 0.0</pose>
			<inertial>
				<pose frame="">0.0 0.0 0.0 0 0 0</pose>
				<mass>1041.2293594077037</mass>
				<inertia>
					<ixx>194.34233377142348</ixx>
					<ixy>0.02954008126913422</ixy>
					<ixz>-0.1448651839771188</ixz>
					<iyy>194.34304191479657</iyy>
					<iyz>0.12760282012592977</iyz>
					<izz>386.9973235859431</izz>
				</inertia>
			</inertial>
			<collision name="base_collision">
				<geometry>
					<mesh>
						<uri>model://roboy_xylophone_left_arm/meshes/CAD/base.stl</uri>
						<scale>0.001 0.001 0.001</scale>
					</mesh>
				</geometry>
			</collision>
			<visual name="base_visual">
				<geometry>
					<mesh>
						<uri>model://roboy_xylophone_left_arm/meshes/CAD/base.stl</uri>
						<scale>0.001 0.001 0.001</scale>
					</mesh>
				</geometry>
			</visual>
		</link>
		<link name="hand_left">
			<self_collide>false</self_collide>
			<pose frame="">1.014405416091643 -0.07258178738675686 0.5440029417463432 0.0 -0.0 0.0</pose>
			<inertial>
				<pose frame="">0.0 0.0 0.0 0 0 0</pose>
				<mass>0.2621183506250116</mass>
				<inertia>
					<ixx>0.08263826825614953</ixx>
					<ixy>0.02069544069060682</ixy>
					<ixz>0.010310290089089642</ixz>
					<iyy>0.34815034428368635</iyy>
					<iyz>-0.14462880541745232</iyz>
					<izz>0.27554009671382473</izz>
				</inertia>
			</inertial>
			<collision name="hand_left_collision">
				<geometry>
					<mesh>
						<uri>model://roboy_xylophone_left_arm/meshes/CAD/hand_left.stl</uri>
						<scale>0.001 0.001 0.001</scale>
					</mesh>
				</geometry>
			</collision>
			<visual name="hand_left_visual">
				<geometry>
					<mesh>
						<uri>model://roboy_xylophone_left_arm/meshes/CAD/hand_left.stl</uri>
						<scale>0.001 0.001 0.001</scale>
					</mesh>
				</geometry>
			</visual>
		</link>
		<link name="lower_arm_left">
			<self_collide>false</self_collide>
			<pose frame="">0.7611244486335261 0.03188960467199163 0.5427045280375045 0.0 -0.0 0.0</pose>
			<inertial>
				<pose frame="">0.0 0.0 0.0 0 0 0</pose>
				<mass>1.4832954265656815</mass>
				<inertia>
					<ixx>0.4397367507514243</ixx>
					<ixy>-0.036275904566478674</ixy>
					<ixz>-0.025665712851064774</ixz>
					<iyy>1.304192037567609</iyy>
					<iyz>-0.612600917299232</iyz>
					<izz>0.8688206829384404</izz>
				</inertia>
			</inertial>
			<collision name="lower_arm_left_collision">
				<geometry>
					<mesh>
						<uri>model://roboy_xylophone_left_arm/meshes/CAD/lower_arm_left.stl</uri>
						<scale>0.001 0.001 0.001</scale>
					</mesh>
				</geometry>
			</collision>
			<visual name="lower_arm_left_visual">
				<geometry>
					<mesh>
						<uri>model://roboy_xylophone_left_arm/meshes/CAD/lower_arm_left.stl</uri>
						<scale>0.001 0.001 0.001</scale>
					</mesh>
				</geometry>
			</visual>
		</link>
		<link name="sphere_link1">
			<self_collide>false</self_collide>
			<pose frame="">0.29218005222734217 0.0076909234120174945 0.5486137870423161 0.0 -0.0 0.0</pose>
			<inertial>
				<pose frame="">0.0 0.0 0.0 0 0 0</pose>
				<mass>0.046755519327953375</mass>
				<inertia>
					<ixx>0.014081079691620597</ixx>
					<ixy>-0.00010506593379475995</ixy>
					<ixz>-0.00019727774254638377</ixz>
					<iyy>0.018069794508113985</iyy>
					<iyz>-0.00749462944662583</iyz>
					<izz>0.004000220151190864</izz>
				</inertia>
			</inertial>
			<collision name="sphere_link1_collision">
				<geometry>
					<mesh>
						<uri>model://roboy_xylophone_left_arm/meshes/CAD/sphere_link1.stl</uri>
						<scale>0.001 0.001 0.001</scale>
					</mesh>
				</geometry>
			</collision>
			<visual name="sphere_link1_visual">
				<geometry>
					<mesh>
						<uri>model://roboy_xylophone_left_arm/meshes/CAD/sphere_link1.stl</uri>
						<scale>0.001 0.001 0.001</scale>
					</mesh>
				</geometry>
			</visual>
		</link>
		<link name="sphere_link2">
			<self_collide>false</self_collide>
			<pose frame="">0.2921800660285933 0.007690617219246413 0.5486137752945589 0.0 -0.0 0.0</pose>
			<inertial>
				<pose frame="">0.0 0.0 0.0 0 0 0</pose>
				<mass>0.031340208481721615</mass>
				<inertia>
					<ixx>0.00943723649341556</ixx>
					<ixy>-7.042286174839997e-05</ixy>
					<ixz>-0.00013222993537338276</ixz>
					<iyy>0.0121108711445115</iyy>
					<iyz>-0.005023647663244027</iyz>
					<izz>0.002680040477109837</izz>
				</inertia>
			</inertial>
			<collision name="sphere_link2_collision">
				<geometry>
					<mesh>
						<uri>model://roboy_xylophone_left_arm/meshes/CAD/sphere_link2.stl</uri>
						<scale>0.001 0.001 0.001</scale>
					</mesh>
				</geometry>
			</collision>
			<visual name="sphere_link2_visual">
				<geometry>
					<mesh>
						<uri>model://roboy_xylophone_left_arm/meshes/CAD/sphere_link2.stl</uri>
						<scale>0.001 0.001 0.001</scale>
					</mesh>
				</geometry>
			</visual>
		</link>
		<joint name="joint_hip" type="revolute">
			<parent>base</parent>
			<child>torso</child>
			<pose frame="">-0.0085830842233506 0.009686930156379774 -0.31521144293297654 0 0 0</pose>
			<axis>
				<xyz>-2.3609670781633625e-15 -1.1366942706288076e-14 -0.9999999999999987</xyz>
				<limit>
					<lower>-0.2617993877991494</lower>
					<upper>0.2617993877991494</upper>
				</limit>
				<use_parent_model_frame>0</use_parent_model_frame>
			</axis>
		</joint>
		<joint name="wrist_left" type="revolute">
			<parent>lower_arm_left</parent>
			<child>hand_left</child>
			<pose frame="">-0.13246837646419352 0.11023353623991378 -0.0029764952842603522 0 0 0</pose>
			<axis>
				<xyz>0.998070009825298 0.04989378316758063 -0.036971149408146046</xyz>
				<limit>
					<lower>-1.5707963267948966</lower>
					<upper>1.5707963267948966</upper>
				</limit>
				<use_parent_model_frame>0</use_parent_model_frame>
			</axis>
		</joint>
		<joint name="elbow_left" type="revolute">
			<parent>upper_arm_left</parent>
			<child>lower_arm_left</child>
			<pose frame="">-0.13958733767560552 -0.012863655840763938 -0.015742484742651754 0 0 0</pose>
			<axis>
				<xyz>-0.011188426489530806 -0.022909252225328334 -0.9996749398055218</xyz>
				<limit>
					<lower>0</lower>
					<upper>1.5707963267948966</upper>
				</limit>
				<use_parent_model_frame>0</use_parent_model_frame>
			</axis>
		</joint>
		<joint name="sphere_axis0" type="revolute">
			<parent>torso</parent>
			<child>sphere_link1</child>
			<pose frame="">3.9283447250682e-09 -1.669784760338633e-07 -3.766154485163043e-08 0 0 0</pose>
			<axis>
				<xyz>0.9986354432836129 0.050744296328168334 -0.012339684270769953</xyz>
				<limit>
					<lower>-3.141592653589793</lower>
					<upper>3.141592653589793</upper>
				</limit>
				<use_parent_model_frame>0</use_parent_model_frame>
			</axis>
		</joint>
		<joint name="sphere_axis1" type="revolute">
			<parent>sphere_link1</parent>
			<child>sphere_link2</child>
			<pose frame="">-9.872906652219626e-09 1.392142950262798e-07 -2.5913787808917733e-08 0 0 0</pose>
			<axis>
				<xyz>-0.05101049431667491 0.9984488883025682 -0.022310242422111142</xyz>
				<limit>
					<lower>-3.141592653589793</lower>
					<upper>3.141592653589793</upper>
				</limit>
				<use_parent_model_frame>0</use_parent_model_frame>
			</axis>
		</joint>
		<joint name="sphere_axis2" type="revolute">
			<parent>sphere_link2</parent>
			<child>upper_arm_left</child>
			<pose frame="">-0.1830759701026465 -0.009451175058169585 -0.00955433462935261 0 0 0</pose>
			<axis>
				<xyz>0.9986354432836148 0.05074429632816839 -0.012339684270770136</xyz>
				<limit>
					<lower>-3.141592653589793</lower>
					<upper>3.141592653589793</upper>
				</limit>
				<use_parent_model_frame>0</use_parent_model_frame>
			</axis>
		</joint>
		<plugin filename="libmusc_plugin.so" name="musc_plugin">
			<myoMuscle name="motor0">
				<link name="torso">
					<viaPoint type="FIXPOINT">0.22910719676469873 -0.009524440610084325 0.031047687898435258</viaPoint>
					<viaPoint type="FIXPOINT">0.26334996089438784 -0.005572421870437558 0.16995861386444397</viaPoint>
					<viaPoint type="FIXPOINT">0.28035800801449656 -0.0025250286221406306 0.1778060189579795</viaPoint>
				</link>
				<link name="upper_arm_left">
					<viaPoint type="FIXPOINT">-0.1114458332728026 -0.024695637115503728 0.013570705424530373</viaPoint>
				</link>
			</myoMuscle>
			<myoMuscle name="motor1">
				<link name="torso">
					<viaPoint type="FIXPOINT">0.23145231029605196 -0.0173448530081837 0.0688454330585516</viaPoint>
				</link>
				<link name="upper_arm_left">
					<viaPoint type="FIXPOINT">-0.11198483182693317 -0.02402201869531785 -0.027279672611602877</viaPoint>
				</link>
			</myoMuscle>
			<myoMuscle name="motor2">
				<link name="torso">
					<viaPoint type="FIXPOINT">0.2426349290894856 -0.020502819001992325 0.11611048330094931</viaPoint>
				</link>
				<link name="upper_arm_left">
					<viaPoint type="FIXPOINT">-0.1229278805698445 -0.01949936916317756 -0.004331468676345551</viaPoint>
				</link>
			</myoMuscle>
			<myoMuscle name="motor3">
				<link name="torso">
					<viaPoint type="FIXPOINT">0.2720535687025562 -0.020369813674964394 0.15955180953157366</viaPoint>
				</link>
				<link name="upper_arm_left">
					<viaPoint type="FIXPOINT">-0.11130516327039942 -0.028303547500926465 0.01011820027270133</viaPoint>
				</link>
			</myoMuscle>
			<myoMuscle name="motor4">
				<link name="torso">
					<viaPoint type="FIXPOINT">0.294810418502043 0.008164586655358725 0.19769633659615246</viaPoint>
				</link>
				<link name="upper_arm_left">
					<viaPoint type="FIXPOINT">-0.1043656189079865 -0.004783894891649638 0.020131680307835895</viaPoint>
				</link>
			</myoMuscle>
			<myoMuscle name="motor5">
				<link name="torso">
					<viaPoint type="FIXPOINT">0.26840404977877647 0.05106368566863843 0.1579556349991698</viaPoint>
				</link>
				<link name="upper_arm_left">
					<viaPoint type="FIXPOINT">-0.10543323444663699 0.014396846330552736 0.012607541254838707</viaPoint>
				</link>
			</myoMuscle>
			<myoMuscle name="motor6">
				<link name="torso">
					<viaPoint type="FIXPOINT">0.2389782419492724 0.05107098672024646 0.11451117363627746</viaPoint>
				</link>
				<link name="upper_arm_left">
					<viaPoint type="FIXPOINT">-0.12427455761980476 0.006859681488010241 -0.004920459076289276</viaPoint>
				</link>
			</myoMuscle>
			<myoMuscle name="motor7">
				<link name="torso">
					<viaPoint type="FIXPOINT">0.22759158117857115 0.05822274826726508 0.06715688242419851</viaPoint>
				</link>
				<link name="upper_arm_left">
					<viaPoint type="FIXPOINT">-0.11394473201867264 0.015116237994925326 -0.024944321247991043</viaPoint>
				</link>
			</myoMuscle>
			<myoMuscle name="motor8">
				<link name="torso">
					<viaPoint type="FIXPOINT">0.22556286599449707 0.062006534842099406 0.02949008480231541</viaPoint>
					<viaPoint type="FIXPOINT">0.2611091840294181 0.03587548542988346 0.16952021601383999</viaPoint>
					<viaPoint type="FIXPOINT">0.2779570858222816 0.03424019242567091 0.17769219606712747</viaPoint>
				</link>
				<link name="upper_arm_left">
					<viaPoint type="FIXPOINT">-0.10554602532871578 0.01619510555721124 0.010874468270034684</viaPoint>
				</link>
			</myoMuscle>
			<myoMuscle name="motor9">
				<link name="upper_arm_left">
					<viaPoint type="FIXPOINT">0.02642785095923493 -0.06323570399409899 -0.009111763981708095</viaPoint>
				</link>
				<link name="lower_arm_left">
					<viaPoint type="FIXPOINT">-0.11416536399162823 -0.01631559106809997 0.002121905702833473</viaPoint>
				</link>
			</myoMuscle>
			<myoMuscle name="motor10">
				<link name="upper_arm_left">
					<viaPoint type="FIXPOINT">0.019913603526346295 0.0654360898815055 -0.0071667170766440335</viaPoint>
				</link>
				<link name="lower_arm_left">
					<viaPoint type="FIXPOINT">-0.11611011931393435 0.02174988576344486 0.0012713363587496219</viaPoint>
				</link>
			</myoMuscle>
			<!--<myoMuscle name="motor11">-->
				<!--<link name="upper_arm_left">-->
					<!--<viaPoint type="FIXPOINT">0.0510429304515776 -0.003956948062937091 0.03797976014431065</viaPoint>-->
					<!--<viaPoint type="FIXPOINT">0.08280092269299254 -0.002886866599684621 0.025316387142387813</viaPoint>-->
				<!--</link>-->
				<!--<link name="lower_arm_left">-->
					<!--<viaPoint type="FIXPOINT">-0.1161534408882244 -0.010247822554166145 0.048520223361879077</viaPoint>-->
					<!--<viaPoint type="FIXPOINT">-0.10100697086062752 -0.05858438140787162 0.0017602866322238952</viaPoint>-->
				<!--</link>-->
			<!--</myoMuscle>-->
			<!--<myoMuscle name="motor12">-->
				<!--<link name="upper_arm_left">-->
					<!--<viaPoint type="FIXPOINT">0.05022183113242406 0.010905234536880071 0.03264673190868869</viaPoint>-->
					<!--<viaPoint type="FIXPOINT">0.0756156001219457 0.019544891054843652 0.030504455176408457</viaPoint>-->
				<!--</link>-->
				<!--<link name="lower_arm_left">-->
					<!--<viaPoint type="FIXPOINT">-0.11617022352795857 -0.01028218643250436 0.047020710952169725</viaPoint>-->
					<!--<viaPoint type="FIXPOINT">-0.10638670027549907 0.04728738857830227 0.0017602866322238952</viaPoint>-->
				<!--</link>-->
			<!--</myoMuscle>-->
			<myoMuscle name="motor13">
				<link name="base">
					<viaPoint type="FIXPOINT">-0.19499999851461478 -0.11347765649897372 0.08723717349165262</viaPoint>
				</link>
				<link name="torso">
					<viaPoint type="FIXPOINT">0.12685568037475325 -0.05391627545569471 -0.07161670149614416</viaPoint>
				</link>
			</myoMuscle>
			<myoMuscle name="motor14">
				<link name="base">
					<viaPoint type="FIXPOINT">0.1949999985146147 -0.1134776564989737 0.0872371734916526</viaPoint>
				</link>
				<link name="torso">
					<viaPoint type="FIXPOINT">-0.14522207278870172 -0.05184010204231427 -0.07341919043814038</viaPoint>
				</link>
			</myoMuscle>
			<myoMuscle name="motor15">
				<link name="base">
					<viaPoint type="FIXPOINT">-0.22500000148538477 0.0015223435010262346 0.08723717349165344</viaPoint>
				</link>
				<link name="torso">
					<viaPoint type="FIXPOINT">-0.15866604526742978 0.008167087327422625 -0.08283576149918535</viaPoint>
				</link>
			</myoMuscle>
			<myoMuscle name="motor16">
				<link name="base">
					<viaPoint type="FIXPOINT">0.2250000014853848 0.0015223435010263528 0.08723717349165344</viaPoint>
				</link>
				<link name="torso">
					<viaPoint type="FIXPOINT">0.14149987682073173 0.008167087327423508 -0.08283576149918506</viaPoint>
				</link>
			</myoMuscle>
			<myoMuscle name="motor17">
				<link name="base">
					<viaPoint type="FIXPOINT">-0.19499999851461464 0.11652234350102626 0.08723717349165426</viaPoint>
				</link>
				<link name="torso">
					<viaPoint type="FIXPOINT">0.10987415550674687 0.07533574429707657 -0.10129009600525218</viaPoint>
				</link>
			</myoMuscle>
			<myoMuscle name="motor18">
				<link name="base">
					<viaPoint type="FIXPOINT">0.19499999851461486 0.1165223435010261 0.08723717349165426</viaPoint>
				</link>
				<link name="torso">
					<viaPoint type="FIXPOINT">-0.12402434158303666 0.07674056210824183 -0.10502243270748224</viaPoint>
				</link>
			</myoMuscle>
			<endEffector link="hand_left" name="endeffector0">0.047763404721041666 -0.12269824604019622 -0.000481700832480243</endEffector>
		</plugin>
	</model>
</sdf>
