<?xml version="1.0" ?>
<sdf version="1.6">
	<model name="roboy_xylophone_left_arm">
		<link name="base">
			<self_collide>false</self_collide>
			<pose frame="">0.0 0.0 0.0 0.0 -0.0 0.0</pose>
			<inertial>
				<pose frame="">0.0 0.0 0.0 0 0 0</pose>
				<mass>1000</mass>
				<inertia>
					<ixx>0.1</ixx>
					<ixy>0.0</ixy>
					<ixz>0.0</ixz>
					<iyy>0.1</iyy>
					<iyz>0.0</iyz>
					<izz>0.1</izz>
				</inertia>
			</inertial>
			<collision name="base_collision">
				<geometry>
					<mesh>
						<uri>model://roboy_xylophone_left_arm/meshes/CAD/base.stl</uri>
						<scale>0.001 0.001 0.001</scale>
					</mesh>
				</geometry>
			</collision>
			<visual name="base_visual">
				<geometry>
					<mesh>
						<uri>model://roboy_xylophone_left_arm/meshes/CAD/base.stl</uri>
						<scale>0.001 0.001 0.001</scale>
					</mesh>
				</geometry>
			</visual>
		</link>
		<link name="torso">
			<self_collide>false</self_collide>
			<pose frame="">-2.5210583336983455e-16 2.5830904394012438e-15 0.3009128442572498 0.0 -0.0 0.0</pose>
			<inertial>
				<pose frame="">0.0 0.0 0.0 0 0 0</pose>
				<mass>0.1</mass>
				<inertia>
					<ixx>0.1</ixx>
					<ixy>0.0</ixy>
					<ixz>0.0</ixz>
					<iyy>0.1</iyy>
					<iyz>0.0</iyz>
					<izz>0.1</izz>
				</inertia>
			</inertial>
			<collision name="torso_collision">
				<geometry>
					<mesh>
						<uri>model://roboy_xylophone_left_arm/meshes/CAD/torso.stl</uri>
						<scale>0.001 0.001 0.001</scale>
					</mesh>
				</geometry>
			</collision>
			<visual name="torso_visual">
				<geometry>
					<mesh>
						<uri>model://roboy_xylophone_left_arm/meshes/CAD/torso.stl</uri>
						<scale>0.001 0.001 0.001</scale>
					</mesh>
				</geometry>
			</visual>
		</link>
		<link name="sphere_link1">
			<self_collide>false</self_collide>
			<pose frame="">0.2921800561556851 0.0076882557614745385 0.5492779566488885 0.0 -0.0 0.0</pose>
			<inertial>
				<pose frame="">0.0 0.0 0.0 0 0 0</pose>
				<mass>0.0001</mass>
				<inertia>
					<ixx>0.0001</ixx>
					<ixy>0.0</ixy>
					<ixz>0.0</ixz>
					<iyy>0.0001</iyy>
					<iyz>0.0</iyz>
					<izz>0.0001</izz>
				</inertia>
			</inertial>
			<collision name="sphere_link1_collision">
				<geometry>
					<mesh>
						<uri>model://roboy_xylophone_left_arm/meshes/CAD/sphere_link1.stl</uri>
						<scale>0.001 0.001 0.001</scale>
					</mesh>
				</geometry>
			</collision>
			<visual name="sphere_link1_visual">
				<geometry>
					<mesh>
						<uri>model://roboy_xylophone_left_arm/meshes/CAD/sphere_link1.stl</uri>
						<scale>0.001 0.001 0.001</scale>
					</mesh>
				</geometry>
			</visual>
		</link>
		<link name="sphere_link2">
			<self_collide>false</self_collide>
			<pose frame="">0.292180056155685 0.007688255761474526 0.5492779566488886 0.0 -0.0 0.0</pose>
			<inertial>
				<pose frame="">0.0 0.0 0.0 0 0 0</pose>
				<mass>0.0001</mass>
				<inertia>
					<ixx>0.0001</ixx>
					<ixy>0.0</ixy>
					<ixz>0.0</ixz>
					<iyy>0.0001</iyy>
					<iyz>0.0</iyz>
					<izz>0.0001</izz>
				</inertia>
			</inertial>
			<collision name="sphere_link2_collision">
				<geometry>
					<mesh>
						<uri>model://roboy_xylophone_left_arm/meshes/CAD/sphere_link2.stl</uri>
						<scale>0.001 0.001 0.001</scale>
					</mesh>
				</geometry>
			</collision>
			<visual name="sphere_link2_visual">
				<geometry>
					<mesh>
						<uri>model://roboy_xylophone_left_arm/meshes/CAD/sphere_link2.stl</uri>
						<scale>0.001 0.001 0.001</scale>
					</mesh>
				</geometry>
			</visual>
		</link>
		<link name="upper_arm_left">
			<self_collide>false</self_collide>
			<pose frame="">0.38168743171845093 0.012531347306432074 0.5613694888271816 0.0 -0.0 0.0</pose>
			<inertial>
				<pose frame="">0.0 0.0 0.0 0 0 0</pose>
				<mass>0.1</mass>
				<inertia>
					<ixx>0.1</ixx>
					<ixy>0.0</ixy>
					<ixz>0.0</ixz>
					<iyy>0.1</iyy>
					<iyz>0.0</iyz>
					<izz>0.1</izz>
				</inertia>
			</inertial>
			<collision name="upper_arm_left_collision">
				<geometry>
					<mesh>
						<uri>model://roboy_xylophone_left_arm/meshes/CAD/upper_arm_left.stl</uri>
						<scale>0.001 0.001 0.001</scale>
					</mesh>
				</geometry>
			</collision>
			<visual name="upper_arm_left_visual">
				<geometry>
					<mesh>
						<uri>model://roboy_xylophone_left_arm/meshes/CAD/upper_arm_left.stl</uri>
						<scale>0.001 0.001 0.001</scale>
					</mesh>
				</geometry>
			</visual>
		</link>

		<link name="lower_arm_left">
			<self_collide>false</self_collide>
			<pose frame="">0.7720537499627952 0.03206567887183061 0.5430484315962018 0.0 -0.0 0.0</pose>
			<inertial>
				<pose frame="">0.0 0.0 0.0 0 0 0</pose>
				<mass>0.1</mass>
				<inertia>
					<ixx>0.1</ixx>
					<ixy>0.0</ixy>
					<ixz>0.0</ixz>
					<iyy>0.1</iyy>
					<iyz>0.0</iyz>
					<izz>0.1</izz>
				</inertia>
			</inertial>
			<collision name="lower_arm_left_collision">
				<geometry>
					<mesh>
						<uri>model://roboy_xylophone_left_arm/meshes/CAD/lower_arm_left.stl</uri>
						<scale>0.001 0.001 0.001</scale>
					</mesh>
				</geometry>
			</collision>
			<visual name="lower_arm_left_visual">
				<geometry>
					<mesh>
						<uri>model://roboy_xylophone_left_arm/meshes/CAD/lower_arm_left.stl</uri>
						<scale>0.001 0.001 0.001</scale>
					</mesh>
				</geometry>
			</visual>
		</link>
		<link name="hand_left">
			<self_collide>false</self_collide>
			<pose frame="">0.9409052109712956 0.030447147800822187 0.5442482629971966 0.0 -0.0 0.0</pose>
			<inertial>
				<pose frame="">0.0 0.0 0.0 0 0 0</pose>
				<mass>0.1</mass>
				<inertia>
					<ixx>0.1</ixx>
					<ixy>0.0</ixy>
					<ixz>0.0</ixz>
					<iyy>0.1</iyy>
					<iyz>0.0</iyz>
					<izz>0.1</izz>
				</inertia>
			</inertial>
			<collision name="hand_left_collision">
				<geometry>
					<mesh>
						<uri>model://roboy_xylophone_left_arm/meshes/CAD/hand_left.stl</uri>
						<scale>0.001 0.001 0.001</scale>
					</mesh>
				</geometry>
			</collision>
			<visual name="hand_left_visual">
				<geometry>
					<mesh>
						<uri>model://roboy_xylophone_left_arm/meshes/CAD/hand_left.stl</uri>
						<scale>0.001 0.001 0.001</scale>
					</mesh>
				</geometry>
			</visual>
		</link>


		<joint name="base_joint" type="revolute">
			<parent>base</parent>
			<child>torso</child>
			<pose frame="">2.5099561034520937e-16 -2.464296575766352e-15 -0.30091284425724985 0 0 0</pose>
			<axis>
				<xyz>-5.680911057209429e-16 6.847300504375648e-15 1.000000000000001</xyz>
				<limit>
					<lower>-3.141592653589793</lower>
					<upper>3.141592653589793</upper>
				</limit>
				<use_parent_model_frame>0</use_parent_model_frame>
			</axis>
		</joint>
		<joint name="sphere_axis0" type="revolute">
			<parent>torso</parent>
			<child>sphere_link1</child>
			<pose frame="">-1.4210854715202004e-16 -1.2212453270876722e-17 7.105427357601002e-17 0 0 0</pose>
			<axis>
				<xyz>0.9986354432836129 0.050744296328168334 -0.012339684270769964</xyz>
				<limit>
					<lower>-3.141592653589793</lower>
					<upper>3.141592653589793</upper>
				</limit>
				<use_parent_model_frame>0</use_parent_model_frame>
			</axis>
		</joint>
		<joint name="sphere_axis1" type="revolute">
			<parent>sphere_link1</parent>
			<child>sphere_link2</child>
			<pose frame="">-7.105427357601002e-17 -5.551115123125783e-18 -2.1316282072803005e-16 0 0 0</pose>
			<axis>
				<xyz>-0.05101049431667491 0.9984488883025682 -0.02231024242211136</xyz>
				<limit>
					<lower>-3.141592653589793</lower>
					<upper>3.141592653589793</upper>
				</limit>
				<use_parent_model_frame>0</use_parent_model_frame>
			</axis>
		</joint>
		<joint name="sphere_axis2" type="revolute">
			<parent>sphere_link2</parent>
			<child>upper_arm_left</child>
			<pose frame="">-0.08950737550575738 -0.004843092660811124 -0.012091532153359594 0 0 0</pose>
			<axis>
				<xyz>0.9986354432836148 0.05074429632816838 -0.012339684270770146</xyz>
				<limit>
					<lower>-3.141592653589793</lower>
					<upper>3.141592653589793</upper>
				</limit>
				<use_parent_model_frame>0</use_parent_model_frame>
			</axis>
		</joint>
		<joint name="elbow_left" type="revolute">
			<parent>upper_arm_left</parent>
			<child>lower_arm_left</child>
			<pose frame="">-0.15051663900487683 -0.013042230712669895 -0.015422181033231936 0 0 0</pose>
			<axis>
				<xyz>-0.011188426489530806 -0.022909252225328525 -0.9996749398055218</xyz>
				<limit>
					<lower>0</lower>
					<upper>1.5707963267948966</upper>
				</limit>
				<use_parent_model_frame>0</use_parent_model_frame>
			</axis>
		</joint>
		<joint name="wrist_left" type="revolute">
			<parent>lower_arm_left</parent>
			<child>hand_left</child>
			<pose frame="">-0.058968171343847756 0.00720210038026786 -0.002557609266996437 0 0 0</pose>
			<axis>
				<xyz>0.998070009825298 0.04989378316758063 -0.03697114940814605</xyz>
				<limit>
					<lower>-1.5707963267948966</lower>
					<upper>1.5707963267948966</upper>
				</limit>
				<use_parent_model_frame>0</use_parent_model_frame>
			</axis>
		</joint>
		<plugin filename="libmusc_plugin.so" name="musc_plugin">
			<myoMuscle name="motor0">
				<link name="torso">
					<viaPoint type="FIXPOINT">0.2376902809880496 -0.017689027265440305 0.12858346006581597</viaPoint>
					<viaPoint type="FIXPOINT">0.2719330451177387 -0.013737008525793537 0.2674943860318247</viaPoint>
					<viaPoint type="FIXPOINT">0.2889410922378474 -0.010689615277496609 0.2753417911253602</viaPoint>
				</link>
				<link name="upper_arm_left">
					<viaPoint type="FIXPOINT">-0.017877238675911684 -0.020085054046078375 0.010369300632405683</viaPoint>
				</link>
			</myoMuscle>
			<myoMuscle name="motor1">
				<link name="torso">
					<viaPoint type="FIXPOINT">0.2400353945194028 -0.025509439663539683 0.16638120522593233</viaPoint>
				</link>
				<link name="upper_arm_left">
					<viaPoint type="FIXPOINT">-0.018416237230042258 -0.019411435625892495 -0.030481077403727568</viaPoint>
				</link>
			</myoMuscle>
			<myoMuscle name="motor2">
				<link name="torso">
					<viaPoint type="FIXPOINT">0.25121801331283644 -0.028667405657348308 0.21364625546833005</viaPoint>
				</link>
				<link name="upper_arm_left">
					<viaPoint type="FIXPOINT">-0.029359285972953588 -0.014888786093752205 -0.0075328734684702425</viaPoint>
				</link>
			</myoMuscle>
			<myoMuscle name="motor3">
				<link name="torso">
					<viaPoint type="FIXPOINT">0.28063665292590706 -0.028534400330320377 0.2570875816989544</viaPoint>
				</link>
				<link name="upper_arm_left">
					<viaPoint type="FIXPOINT">-0.017736568673508514 -0.023692964431501113 0.006916795480576638</viaPoint>
				</link>
			</myoMuscle>
			<myoMuscle name="motor4">
				<link name="torso">
					<viaPoint type="FIXPOINT">0.30339350272539384 2.7462612419274214e-15 0.2952321087635332</viaPoint>
				</link>
				<link name="upper_arm_left">
					<viaPoint type="FIXPOINT">-0.010797024311095598 -0.00017331182222428244 0.0169302755157112</viaPoint>
				</link>
			</myoMuscle>
			<myoMuscle name="motor5">
				<link name="torso">
					<viaPoint type="FIXPOINT">0.2769871340021273 0.04289909901328245 0.25549140716655055</viaPoint>
				</link>
				<link name="upper_arm_left">
					<viaPoint type="FIXPOINT">-0.011864639849746084 0.01900742939997809 0.009406136462714017</viaPoint>
				</link>
			</myoMuscle>
			<myoMuscle name="motor6">
				<link name="torso">
					<viaPoint type="FIXPOINT">0.24756132617262325 0.04290640006489047 0.21204694580365818</viaPoint>
				</link>
				<link name="upper_arm_left">
					<viaPoint type="FIXPOINT">-0.03070596302291385 0.011470264557435597 -0.008121863868413967</viaPoint>
				</link>
			</myoMuscle>
			<myoMuscle name="motor7">
				<link name="torso">
					<viaPoint type="FIXPOINT">0.236174665401922 0.0500581616119091 0.16469265459157925</viaPoint>
				</link>
				<link name="upper_arm_left">
					<viaPoint type="FIXPOINT">-0.020376137421781734 0.019726821064350683 -0.028145726040115733</viaPoint>
				</link>
			</myoMuscle>
			<myoMuscle name="motor8">
				<link name="torso">
					<viaPoint type="FIXPOINT">0.23414595021784793 0.05384194818674343 0.12702585696969615</viaPoint>
					<viaPoint type="FIXPOINT">0.26969226825276893 0.027710898774527478 0.2670559881812207</viaPoint>
					<viaPoint type="FIXPOINT">0.2865401700456325 0.02607560577031493 0.2752279682345082</viaPoint>
				</link>
				<link name="upper_arm_left">
					<viaPoint type="FIXPOINT">-0.011977430731824867 0.020805688626636596 0.007673063477909992</viaPoint>
				</link>
			</myoMuscle>
			<myoMuscle name="motor9">
				<link name="upper_arm_left">
					<viaPoint type="FIXPOINT">0.11999644555612583 -0.058625120924673625 -0.012313168773832785</viaPoint>
				</link>
				<link name="lower_arm_left">
					<viaPoint type="FIXPOINT">-0.12509466532089733 -0.016491665267938948 0.0017780021441362237</viaPoint>
				</link>
			</myoMuscle>
			<myoMuscle name="motor10">
				<link name="upper_arm_left">
					<viaPoint type="FIXPOINT">0.1134821981232372 0.07004667295093085 -0.010368121868768725</viaPoint>
				</link>
				<link name="lower_arm_left">
					<viaPoint type="FIXPOINT">-0.12703942064320345 0.02157381156360588 0.0009274328000523724</viaPoint>
				</link>
			</myoMuscle>
			<myoMuscle name="motor11">
				<link name="base">
					<viaPoint type="FIXPOINT">-0.600000000000001 -0.5500000000000003 0.055000000000007106</viaPoint>
				</link>
				<link name="torso">
					<viaPoint type="FIXPOINT">-0.05999999999999973 -2.5798401793812898e-15 -0.2209128442572493</viaPoint>
				</link>
			</myoMuscle>
			<myoMuscle name="motor12">
				<link name="base">
					<viaPoint type="FIXPOINT">0.4284597678705658 0.6754105462204388 0.05499999999999929</viaPoint>
				</link>
				<link name="torso">
					<viaPoint type="FIXPOINT">0.0600000000000003 -2.578992818626307e-15 -0.22091284425724922</viaPoint>
				</link>
			</myoMuscle>
			<myoMuscle name="motor13">
				<link name="base">
					<viaPoint type="FIXPOINT">0.6854701854697349 -0.41589522696987724 0.055000000000007036</viaPoint>
				</link>
				<link name="torso">
					<viaPoint type="FIXPOINT">0.060000000000000296 -2.5789928186263104e-15 -0.22091284425724972</viaPoint>
				</link>
			</myoMuscle>
			<myoMuscle name="motor14">
				<link name="base">
					<viaPoint type="FIXPOINT">-0.5343407965201672 0.6200544562760026 0.05499999999999908</viaPoint>
				</link>
				<link name="torso">
					<viaPoint type="FIXPOINT">-0.05999999999999979 -2.5798401793812933e-15 -0.2209128442572498</viaPoint>
				</link>
			</myoMuscle>
			<myoMuscle name="motor15">
				<link name="upper_arm_left">
					<viaPoint type="FIXPOINT">0.1446115250484685 0.0006536350064882645 0.03477835535218596</viaPoint>
					<viaPoint type="FIXPOINT">0.17636951728988343 0.0017237164697407347 0.02211498235026312</viaPoint>
				</link>
				<link name="lower_arm_left">
					<viaPoint type="FIXPOINT">-0.1270827422174935 -0.010423896754005124 0.04817631980318183</viaPoint>
					<viaPoint type="FIXPOINT">-0.11193627218989662 -0.05876045560771059 0.001416383073526646</viaPoint>
				</link>
			</myoMuscle>
			<myoMuscle name="motor16">
				<link name="upper_arm_left">
					<viaPoint type="FIXPOINT">0.14379042572931497 0.015515817606305427 0.029445327116564002</viaPoint>
					<viaPoint type="FIXPOINT">0.16918419471883658 0.024155474124269008 0.027303050384283767</viaPoint>
				</link>
				<link name="lower_arm_left">
					<viaPoint type="FIXPOINT">-0.12709952485722767 -0.010458260632343338 0.04667680739347247</viaPoint>
					<viaPoint type="FIXPOINT">-0.11731600160476817 0.04711131437846328 0.001416383073526646</viaPoint>
				</link>
			</myoMuscle>
			<endEffector link="hand_left" name="endeffector0">0.12126360984138898 -0.22572718122777527 -0.0007270220833336083</endEffector>
		</plugin>
	</model>
</sdf>
