<?xml version="1.0" ?>
<robot name="roboy_xylophone_left_arm">
  <joint name="elbow_left" type="revolute">
    <parent link="upper_arm_left"/>
    <child link="lower_arm_left"/>
    <origin rpy="0  0  0" xyz="0.32935  0.01133 -0.02165"/>
    <axis xyz="-0.01118 -0.0229  -0.99967"/>
    <limit effort="0.0" lower="-1.57079632679" upper="0.0" velocity="0.0"/>
  </joint>
  <joint name="sphere_axis0" type="revolute">
    <parent link="torso"/>
    <child link="sphere_link1"/>
    <origin rpy="0  0  0" xyz="0.29218  0.00769  0.30516"/>
    <axis xyz="0.99863  0.05074 -0.01234"/>
    <limit effort="0.0" lower="-3.14159265359" upper="3.14159265359" velocity="0.0"/>
  </joint>
  <joint name="sphere_axis1" type="fixed">
    <parent link="sphere_link1"/>
    <child link="sphere_link2"/>
    <origin rpy="0  0  0" xyz="0  0  0"/>
    <axis xyz="-0.05101  0.99844 -0.02231"/>
    <limit effort="0.0" lower="0.0" upper="0.0" velocity="0.0"/>
  </joint>
  <joint name="sphere_axis2" type="fixed">
    <parent link="sphere_link2"/>
    <child link="upper_arm_left"/>
    <origin rpy="0  0  0" xyz="0  0  0"/>
    <axis xyz="0.99863  0.05074 -0.01234"/>
    <limit effort="0.0" lower="0.0" upper="0.0" velocity="0.0"/>
  </joint>
  <joint name="spine_v2_axis0" type="revolute">
    <parent link="spine_link2"/>
    <child link="spine_v2_sphere_link1"/>
    <origin rpy="0  0  0" xyz="0     0     0.039"/>
    <axis xyz="1  0  0"/>
    <limit effort="0.0" lower="-0.0872664625997" upper="0.0872664625997" velocity="0.0"/>
  </joint>
  <joint name="spine_v2_axis2" type="revolute">
    <parent link="spine_v2_sphere_link2"/>
    <child link="torso"/>
    <origin rpy="0  0  0" xyz="0  0  0"/>
    <axis xyz="0  0  1"/>
    <limit effort="0.0" lower="-0.0872664625997" upper="0.0872664625997" velocity="0.0"/>
  </joint>
  <joint name="spine_v2_axis1" type="revolute">
    <parent link="spine_v2_sphere_link1"/>
    <child link="spine_v2_sphere_link2"/>
    <origin rpy="0  0  0" xyz="0  0  0"/>
    <axis xyz="0 -1  0"/>
    <limit effort="0.0" lower="-0.0872664625997" upper="0.0872664625997" velocity="0.0"/>
  </joint>
  <joint name="wrist_left" type="revolute">
    <parent link="lower_arm_left"/>
    <child link="hand_left"/>
    <origin rpy="0  0  0" xyz="0.2604   0.01862  0.01406"/>
    <axis xyz="0.99807  0.04989 -0.03697"/>
    <limit effort="0.0" lower="-1.57079632679" upper="1.57079632679" velocity="0.0"/>
  </joint>
  <joint name="spine_v1_axis0" type="revolute">
    <parent link="spine_link1"/>
    <child link="spine_v1_sphere_link1"/>
    <origin rpy="0  0  0" xyz="0     0     0.039"/>
    <axis xyz="1  0  0"/>
    <limit effort="0.0" lower="-0.0872664625997" upper="0.0872664625997" velocity="0.0"/>
  </joint>
  <joint name="spine_v1_axis2" type="revolute">
    <parent link="spine_v1_sphere_link2"/>
    <child link="spine_link2"/>
    <origin rpy="0  0  0" xyz="0  0  0"/>
    <axis xyz="0  0  1"/>
    <limit effort="0.0" lower="-0.0872664625997" upper="0.0872664625997" velocity="0.0"/>
  </joint>
  <joint name="spine_v1_axis1" type="revolute">
    <parent link="spine_v1_sphere_link1"/>
    <child link="spine_v1_sphere_link2"/>
    <origin rpy="0  0  0" xyz="0  0  0"/>
    <axis xyz="0 -1  0"/>
    <limit effort="0.0" lower="-0.0872664625997" upper="0.0872664625997" velocity="0.0"/>
  </joint>
  <joint name="spine_v0_axis0" type="revolute">
    <parent link="base"/>
    <child link="spine_v0_sphere_link1"/>
    <origin rpy="0  0  0" xyz="0       0       0.16545"/>
    <axis xyz="1  0  0"/>
    <limit effort="0.0" lower="-0.0872664625997" upper="0.0872664625997" velocity="0.0"/>
  </joint>
  <joint name="spine_v0_axis2" type="revolute">
    <parent link="spine_v0_sphere_link2"/>
    <child link="spine_link1"/>
    <origin rpy="0  0  0" xyz="0  0  0"/>
    <axis xyz="0  0  1"/>
    <limit effort="0.0" lower="-0.0872664625997" upper="0.0872664625997" velocity="0.0"/>
  </joint>
  <joint name="spine_v0_axis1" type="revolute">
    <parent link="spine_v0_sphere_link1"/>
    <child link="spine_v0_sphere_link2"/>
    <origin rpy="0  0  0" xyz="0  0  0"/>
    <axis xyz="0 -1  0"/>
    <limit effort="0.0" lower="-0.0872664625997" upper="0.0872664625997" velocity="0.0"/>
  </joint>
  <link name="upper_arm_left">
    <inertial>
      <mass value="0.1"/>
      <origin rpy="0  0  0" xyz="0.0895   0.00484  0.01275"/>
      <inertia ixx="0.1" ixy="0.0" ixz="0.0" iyy="0.1" iyz="0.0" izz="0.1"/>
    </inertial>
    <collision name="upper_arm_left_collision">
      <origin rpy="0  0  0" xyz="0.0895   0.00484  0.01275"/>
      <geometry>
        <mesh filename="package://roboy_models/roboy_xylophone_left_arm/meshes/CAD/upper_arm_left.stl" scale="0.001 0.001 0.001"/>
      </geometry>
    </collision>
    <visual name="upper_arm_left_visual">
      <origin rpy="0  0  0" xyz="0.0895   0.00484  0.01275"/>
      <geometry>
        <mesh filename="package://roboy_models/roboy_xylophone_left_arm/meshes/CAD/upper_arm_left.stl" scale="0.001 0.001 0.001"/>
      </geometry>
    </visual>
  </link>
  <link name="torso">
    <inertial>
      <mass value="0.1"/>
      <origin rpy="0  0  0" xyz="0       0       0.05746"/>
      <inertia ixx="0.1" ixy="0.0" ixz="0.0" iyy="0.1" iyz="0.0" izz="0.1"/>
    </inertial>
    <collision name="torso_collision">
      <origin rpy="0  0  0" xyz="0       0       0.05746"/>
      <geometry>
        <mesh filename="package://roboy_models/roboy_head/meshes/CAD/torso.stl OR roboy_models/roboy_xylophone_left_arm/meshes/CAD/torso.stl" scale="0.001 0.001 0.001"/>
      </geometry>
    </collision>
    <visual name="torso_visual">
      <origin rpy="0  0  0" xyz="0       0       0.05746"/>
      <geometry>
        <mesh filename="package://roboy_models/roboy_head/meshes/CAD/torso.stl OR roboy_models/roboy_xylophone_left_arm/meshes/CAD/torso.stl" scale="0.001 0.001 0.001"/>
      </geometry>
    </visual>
  </link>
  <link name="base">
    <inertial>
      <mass value="0.1"/>
      <origin rpy="0  0  0" xyz="0    0   -0.16"/>
      <inertia ixx="0.1" ixy="0.0" ixz="0.0" iyy="0.1" iyz="0.0" izz="0.1"/>
    </inertial>
    <collision name="base_collision">
      <origin rpy="0  0  0" xyz="0    0   -0.16"/>
      <geometry>
        <mesh filename="package://roboy_models/6DOF_arm/meshes/CAD/base.stl OR roboy_models/cable_robot_6dof/meshes/CAD/base.stl OR roboy_models/nst_arm/meshes/CAD/base.stl OR roboy_models/robot_arm_3dof/meshes/CAD/base.stl OR roboy_models/roboy_vr_booth/meshes/CAD/base.stl OR roboy_models/roboy_xylophone_left_arm/meshes/CAD/base.stl OR roboy_models/TestRobot/meshes/CAD/base.stl" scale="0.001 0.001 0.001"/>
      </geometry>
    </collision>
    <visual name="base_visual">
      <origin rpy="0  0  0" xyz="0    0   -0.16"/>
      <geometry>
        <mesh filename="package://roboy_models/6DOF_arm/meshes/CAD/base.stl OR roboy_models/cable_robot_6dof/meshes/CAD/base.stl OR roboy_models/nst_arm/meshes/CAD/base.stl OR roboy_models/robot_arm_3dof/meshes/CAD/base.stl OR roboy_models/roboy_vr_booth/meshes/CAD/base.stl OR roboy_models/roboy_xylophone_left_arm/meshes/CAD/base.stl OR roboy_models/TestRobot/meshes/CAD/base.stl" scale="0.001 0.001 0.001"/>
      </geometry>
    </visual>
  </link>
  <link name="hand_left">
    <inertial>
      <mass value="0.1"/>
      <origin rpy="0  0  0" xyz="0.05896 -0.0072   0.00322"/>
      <inertia ixx="0.1" ixy="0.0" ixz="0.0" iyy="0.1" iyz="0.0" izz="0.1"/>
    </inertial>
    <collision name="hand_left_collision">
      <origin rpy="0  0  0" xyz="0.05896 -0.0072   0.00322"/>
      <geometry>
        <mesh filename="package://roboy_models/roboy_xylophone_left_arm/meshes/CAD/hand_left.stl" scale="0.001 0.001 0.001"/>
      </geometry>
    </collision>
    <visual name="hand_left_visual">
      <origin rpy="0  0  0" xyz="0.05896 -0.0072   0.00322"/>
      <geometry>
        <mesh filename="package://roboy_models/roboy_xylophone_left_arm/meshes/CAD/hand_left.stl" scale="0.001 0.001 0.001"/>
      </geometry>
    </visual>
  </link>
  <link name="lower_arm_left">
    <inertial>
      <mass value="0.1"/>
      <origin rpy="0  0  0" xyz="0.15051  0.01304  0.01608"/>
      <inertia ixx="0.1" ixy="0.0" ixz="0.0" iyy="0.1" iyz="0.0" izz="0.1"/>
    </inertial>
    <collision name="lower_arm_left_collision">
      <origin rpy="0  0  0" xyz="0.15051  0.01304  0.01608"/>
      <geometry>
        <mesh filename="package://roboy_models/roboy_xylophone_left_arm/meshes/CAD/lower_arm_left.stl" scale="0.001 0.001 0.001"/>
      </geometry>
    </collision>
    <visual name="lower_arm_left_visual">
      <origin rpy="0  0  0" xyz="0.15051  0.01304  0.01608"/>
      <geometry>
        <mesh filename="package://roboy_models/roboy_xylophone_left_arm/meshes/CAD/lower_arm_left.stl" scale="0.001 0.001 0.001"/>
      </geometry>
    </visual>
  </link>
  <link name="sphere_link1">
    <inertial>
      <mass value="0.1"/>
      <origin rpy="0  0  0" xyz="0       0       0.00066"/>
      <inertia ixx="0.1" ixy="0.0" ixz="0.0" iyy="0.1" iyz="0.0" izz="0.1"/>
    </inertial>
    <collision name="sphere_link1_collision">
      <origin rpy="0  0  0" xyz="0       0       0.00066"/>
      <geometry>
        <mesh filename="package://roboy_models/roboy_head/meshes/CAD/sphere_link1.stl OR roboy_models/roboy_xylophone_left_arm/meshes/CAD/sphere_link1.stl" scale="0.001 0.001 0.001"/>
      </geometry>
    </collision>
    <visual name="sphere_link1_visual">
      <origin rpy="0  0  0" xyz="0       0       0.00066"/>
      <geometry>
        <mesh filename="package://roboy_models/roboy_head/meshes/CAD/sphere_link1.stl OR roboy_models/roboy_xylophone_left_arm/meshes/CAD/sphere_link1.stl" scale="0.001 0.001 0.001"/>
      </geometry>
    </visual>
  </link>
  <link name="sphere_link2">
    <inertial>
      <mass value="0.1"/>
      <origin rpy="0  0  0" xyz="0       0       0.00066"/>
      <inertia ixx="0.1" ixy="0.0" ixz="0.0" iyy="0.1" iyz="0.0" izz="0.1"/>
    </inertial>
    <collision name="sphere_link2_collision">
      <origin rpy="0  0  0" xyz="0       0       0.00066"/>
      <geometry>
        <mesh filename="package://roboy_models/roboy_xylophone_left_arm/meshes/CAD/sphere_link2.stl" scale="0.001 0.001 0.001"/>
      </geometry>
    </collision>
    <visual name="sphere_link2_visual">
      <origin rpy="0  0  0" xyz="0       0       0.00066"/>
      <geometry>
        <mesh filename="package://roboy_models/roboy_xylophone_left_arm/meshes/CAD/sphere_link2.stl" scale="0.001 0.001 0.001"/>
      </geometry>
    </visual>
  </link>
  <link name="spine_v0_sphere_link1">
    <inertial>
      <mass value="0.1"/>
      <origin rpy="0  0  0" xyz="0     0    -0.085"/>
      <inertia ixx="0.1" ixy="0.0" ixz="0.0" iyy="0.1" iyz="0.0" izz="0.1"/>
    </inertial>
    <collision name="spine_v0_sphere_link1_collision">
      <origin rpy="0  0  0" xyz="0     0    -0.085"/>
      <geometry>
        <mesh filename="package://roboy_models/roboy_xylophone_left_arm/meshes/CAD/spine_v0_sphere_link1.stl" scale="0.001 0.001 0.001"/>
      </geometry>
    </collision>
    <visual name="spine_v0_sphere_link1_visual">
      <origin rpy="0  0  0" xyz="0     0    -0.085"/>
      <geometry>
        <mesh filename="package://roboy_models/roboy_xylophone_left_arm/meshes/CAD/spine_v0_sphere_link1.stl" scale="0.001 0.001 0.001"/>
      </geometry>
    </visual>
  </link>
  <link name="spine_v0_sphere_link2">
    <inertial>
      <mass value="0.1"/>
      <origin rpy="0  0  0" xyz="0     0    -0.085"/>
      <inertia ixx="0.1" ixy="0.0" ixz="0.0" iyy="0.1" iyz="0.0" izz="0.1"/>
    </inertial>
    <collision name="spine_v0_sphere_link2_collision">
      <origin rpy="0  0  0" xyz="0     0    -0.085"/>
      <geometry>
        <mesh filename="package://roboy_models/roboy_xylophone_left_arm/meshes/CAD/spine_v0_sphere_link2.stl" scale="0.001 0.001 0.001"/>
      </geometry>
    </collision>
    <visual name="spine_v0_sphere_link2_visual">
      <origin rpy="0  0  0" xyz="0     0    -0.085"/>
      <geometry>
        <mesh filename="package://roboy_models/roboy_xylophone_left_arm/meshes/CAD/spine_v0_sphere_link2.stl" scale="0.001 0.001 0.001"/>
      </geometry>
    </visual>
  </link>
  <link name="spine_v1_sphere_link1">
    <inertial>
      <mass value="0.1"/>
      <origin rpy="0  0  0" xyz="0     0    -0.085"/>
      <inertia ixx="0.1" ixy="0.0" ixz="0.0" iyy="0.1" iyz="0.0" izz="0.1"/>
    </inertial>
    <collision name="spine_v1_sphere_link1_collision">
      <origin rpy="0  0  0" xyz="0     0    -0.085"/>
      <geometry>
        <mesh filename="package://roboy_models/roboy_xylophone_left_arm/meshes/CAD/spine_v1_sphere_link1.stl" scale="0.001 0.001 0.001"/>
      </geometry>
    </collision>
    <visual name="spine_v1_sphere_link1_visual">
      <origin rpy="0  0  0" xyz="0     0    -0.085"/>
      <geometry>
        <mesh filename="package://roboy_models/roboy_xylophone_left_arm/meshes/CAD/spine_v1_sphere_link1.stl" scale="0.001 0.001 0.001"/>
      </geometry>
    </visual>
  </link>
  <link name="spine_v1_sphere_link2">
    <inertial>
      <mass value="0.1"/>
      <origin rpy="0  0  0" xyz="0     0    -0.085"/>
      <inertia ixx="0.1" ixy="0.0" ixz="0.0" iyy="0.1" iyz="0.0" izz="0.1"/>
    </inertial>
    <collision name="spine_v1_sphere_link2_collision">
      <origin rpy="0  0  0" xyz="0     0    -0.085"/>
      <geometry>
        <mesh filename="package://roboy_models/roboy_xylophone_left_arm/meshes/CAD/spine_v1_sphere_link2.stl" scale="0.001 0.001 0.001"/>
      </geometry>
    </collision>
    <visual name="spine_v1_sphere_link2_visual">
      <origin rpy="0  0  0" xyz="0     0    -0.085"/>
      <geometry>
        <mesh filename="package://roboy_models/roboy_xylophone_left_arm/meshes/CAD/spine_v1_sphere_link2.stl" scale="0.001 0.001 0.001"/>
      </geometry>
    </visual>
  </link>
  <link name="spine_v2_sphere_link1">
    <inertial>
      <mass value="0.1"/>
      <origin rpy="0  0  0" xyz="0     0    -0.085"/>
      <inertia ixx="0.1" ixy="0.0" ixz="0.0" iyy="0.1" iyz="0.0" izz="0.1"/>
    </inertial>
    <collision name="spine_v2_sphere_link1_collision">
      <origin rpy="0  0  0" xyz="0     0    -0.085"/>
      <geometry>
        <mesh filename="package://roboy_models/roboy_xylophone_left_arm/meshes/CAD/spine_v2_sphere_link1.stl" scale="0.001 0.001 0.001"/>
      </geometry>
    </collision>
    <visual name="spine_v2_sphere_link1_visual">
      <origin rpy="0  0  0" xyz="0     0    -0.085"/>
      <geometry>
        <mesh filename="package://roboy_models/roboy_xylophone_left_arm/meshes/CAD/spine_v2_sphere_link1.stl" scale="0.001 0.001 0.001"/>
      </geometry>
    </visual>
  </link>
  <link name="spine_v2_sphere_link2">
    <inertial>
      <mass value="0.1"/>
      <origin rpy="0  0  0" xyz="0     0    -0.085"/>
      <inertia ixx="0.1" ixy="0.0" ixz="0.0" iyy="0.1" iyz="0.0" izz="0.1"/>
    </inertial>
    <collision name="spine_v2_sphere_link2_collision">
      <origin rpy="0  0  0" xyz="0     0    -0.085"/>
      <geometry>
        <mesh filename="package://roboy_models/roboy_xylophone_left_arm/meshes/CAD/spine_v2_sphere_link2.stl" scale="0.001 0.001 0.001"/>
      </geometry>
    </collision>
    <visual name="spine_v2_sphere_link2_visual">
      <origin rpy="0  0  0" xyz="0     0    -0.085"/>
      <geometry>
        <mesh filename="package://roboy_models/roboy_xylophone_left_arm/meshes/CAD/spine_v2_sphere_link2.stl" scale="0.001 0.001 0.001"/>
      </geometry>
    </visual>
  </link>
  <link name="spine_link1">
    <inertial>
      <mass value="0.1"/>
      <origin rpy="0  0  0" xyz="0       0      -0.06446"/>
      <inertia ixx="0.1" ixy="0.0" ixz="0.0" iyy="0.1" iyz="0.0" izz="0.1"/>
    </inertial>
    <collision name="spine_link1_collision">
      <origin rpy="0  0  0" xyz="0       0      -0.06446"/>
      <geometry>
        <mesh filename="package://roboy_models/roboy_xylophone_left_arm/meshes/CAD/spine_link1.stl" scale="0.001 0.001 0.001"/>
      </geometry>
    </collision>
    <visual name="spine_link1_visual">
      <origin rpy="0  0  0" xyz="0       0      -0.06446"/>
      <geometry>
        <mesh filename="package://roboy_models/roboy_xylophone_left_arm/meshes/CAD/spine_link1.stl" scale="0.001 0.001 0.001"/>
      </geometry>
    </visual>
  </link>
  <link name="spine_link2">
    <inertial>
      <mass value="0.1"/>
      <origin rpy="0  0  0" xyz="0       0      -0.06446"/>
      <inertia ixx="0.1" ixy="0.0" ixz="0.0" iyy="0.1" iyz="0.0" izz="0.1"/>
    </inertial>
    <collision name="spine_link2_collision">
      <origin rpy="0  0  0" xyz="0       0      -0.06446"/>
      <geometry>
        <mesh filename="package://roboy_models/roboy_xylophone_left_arm/meshes/CAD/spine_link2.stl" scale="0.001 0.001 0.001"/>
      </geometry>
    </collision>
    <visual name="spine_link2_visual">
      <origin rpy="0  0  0" xyz="0       0      -0.06446"/>
      <geometry>
        <mesh filename="package://roboy_models/roboy_xylophone_left_arm/meshes/CAD/spine_link2.stl" scale="0.001 0.001 0.001"/>
      </geometry>
    </visual>
  </link>
</robot>
