<?xml version="1.0" ?>
<robot name="roboy_xylophone_left_arm">
  <joint name="elbow_left" type="revolute">
    <parent link="upper_arm_left"/>
    <child link="lower_arm_left"/>
    <origin rpy="0  0  0" xyz="-0.02111 -0.01344 -0.32931"/>
    <axis xyz="-0.99863 -0.05074  0.01234"/>
    <limit effort="0.0" lower="-1.57079632679" upper="0.0" velocity="0.0"/>
  </joint>
  <joint name="sphere_axis0" type="revolute">
    <parent link="torso"/>
    <child link="sphere_link1"/>
    <origin rpy="0  0  0" xyz="0.29218  0.00768  0.54927"/>
    <axis xyz="0.05101 -0.99844  0.02231"/>
    <limit effort="0.0" lower="-3.14159265359" upper="3.14159265359" velocity="0.0"/>
  </joint>
  <joint name="sphere_axis1" type="revolute">
    <parent link="torso"/>
    <child link="sphere_link2"/>
    <origin rpy="0  0  0" xyz="0.29218  0.00768  0.54927"/>
    <axis xyz="0.99863  0.05074 -0.01234"/>
    <limit effort="0.0" lower="-3.14159265359" upper="3.14159265359" velocity="0.0"/>
  </joint>
  <joint name="sphere_axis2" type="revolute">
    <parent link="sphere_link2"/>
    <child link="upper_arm_left"/>
    <origin rpy="0  0  0" xyz="0  0  0"/>
    <axis xyz="-0.01118 -0.0229  -0.99967"/>
    <limit effort="0.0" lower="-3.14159265359" upper="3.14159265359" velocity="0.0"/>
  </joint>
  <joint name="base_joint" type="revolute">
    <parent link="base"/>
    <child link="torso"/>
    <origin rpy="0  0  0" xyz="0  0  0"/>
    <axis xyz="0  0  1"/>
    <limit effort="0.0" lower="-3.14159265359" upper="3.14159265359" velocity="0.0"/>
  </joint>
  <joint name="wrist_left" type="revolute">
    <parent link="lower_arm_left"/>
    <child link="hand_left"/>
    <origin rpy="0  0  0" xyz="0.03062 -0.25964  0.0006"/>
    <axis xyz="0.02638 -0.99939  0.02287"/>
    <limit effort="0.0" lower="-1.57079632679" upper="1.57079632679" velocity="0.0"/>
  </joint>
  <link name="torso">
    <inertial>
      <mass value="10"/>
      <origin rpy="0  0  0" xyz="0       0       0.30091"/>
      <inertia ixx="0.01" ixy="0" ixz="0" iyy="0.01" iyz="0" izz="0.01"/>
    </inertial>
    <collision name="torso_collision">
      <origin rpy="0  0  0" xyz="0       0       0.30091"/>
      <geometry>
        <mesh filename="package://roboy_models/roboy_2_0_arm_elbow/meshes/CAD/torso.stl OR roboy_models/roboy_2_0_head_simplified/meshes/CAD/torso.stl OR roboy_models/roboy_2_0_left_arm_elbow/meshes/CAD/torso.stl OR roboy_models/roboy_2_0_left_arm_right/meshes/CAD/torso.stl OR roboy_models/roboy_2_0_left_arm_simplified/meshes/CAD/torso.stl OR roboy_models/roboy_2_0_simplified/meshes/CAD/torso.stl OR roboy_models/roboy_xylophone_left_arm/meshes/CAD/torso.stl" scale="0.001 0.001 0.001"/>
      </geometry>
    </collision>
    <visual name="torso_visual">
      <origin rpy="0  0  0" xyz="0       0       0.30091"/>
      <geometry>
        <mesh filename="package://roboy_models/roboy_2_0_arm_elbow/meshes/CAD/torso.stl OR roboy_models/roboy_2_0_head_simplified/meshes/CAD/torso.stl OR roboy_models/roboy_2_0_left_arm_elbow/meshes/CAD/torso.stl OR roboy_models/roboy_2_0_left_arm_right/meshes/CAD/torso.stl OR roboy_models/roboy_2_0_left_arm_simplified/meshes/CAD/torso.stl OR roboy_models/roboy_2_0_simplified/meshes/CAD/torso.stl OR roboy_models/roboy_xylophone_left_arm/meshes/CAD/torso.stl" scale="0.001 0.001 0.001"/>
      </geometry>
    </visual>
  </link>
  <link name="upper_arm_left">
    <inertial>
      <mass value="0.5"/>
      <origin rpy="0  0  0" xyz="0.007    0.00368 -0.23674"/>
      <inertia ixx="0.01" ixy="0" ixz="0" iyy="0.01" iyz="0" izz="0.01"/>
    </inertial>
    <collision name="upper_arm_left_collision">
      <origin rpy="0  0  0" xyz="0.007    0.00368 -0.23674"/>
      <geometry>
        <mesh filename="package://roboy_models/roboy_2_0_arm_elbow/meshes/CAD/upper_arm_left.stl OR roboy_models/roboy_2_0_left_arm_elbow/meshes/CAD/upper_arm_left.stl OR roboy_models/roboy_2_0_left_arm_right/meshes/CAD/upper_arm_left.stl OR roboy_models/roboy_2_0_left_arm_simplified/meshes/CAD/upper_arm_left.stl OR roboy_models/roboy_2_0_simplified/meshes/CAD/upper_arm_left.stl OR roboy_models/roboy_xylophone_left_arm/meshes/CAD/upper_arm_left.stl" scale="0.001 0.001 0.001"/>
      </geometry>
    </collision>
    <visual name="upper_arm_left_visual">
      <origin rpy="0  0  0" xyz="0.007    0.00368 -0.23674"/>
      <geometry>
        <mesh filename="package://roboy_models/roboy_2_0_arm_elbow/meshes/CAD/upper_arm_left.stl OR roboy_models/roboy_2_0_left_arm_elbow/meshes/CAD/upper_arm_left.stl OR roboy_models/roboy_2_0_left_arm_right/meshes/CAD/upper_arm_left.stl OR roboy_models/roboy_2_0_left_arm_simplified/meshes/CAD/upper_arm_left.stl OR roboy_models/roboy_2_0_simplified/meshes/CAD/upper_arm_left.stl OR roboy_models/roboy_xylophone_left_arm/meshes/CAD/upper_arm_left.stl" scale="0.001 0.001 0.001"/>
      </geometry>
    </visual>
  </link>
  <link name="hand_left">
    <inertial>
      <mass value="0.2"/>
      <origin rpy="0  0  0" xyz="0.00272 -0.06303 -0.00774"/>
      <inertia ixx="0.01" ixy="0" ixz="0" iyy="0.01" iyz="0" izz="0.01"/>
    </inertial>
    <collision name="hand_left_collision">
      <origin rpy="0  0  0" xyz="0.00272 -0.06303 -0.00774"/>
      <geometry>
        <mesh filename="package://roboy_models/roboy_2_0_simplified/meshes/CAD/hand_left.stl OR roboy_models/roboy_xylophone_left_arm/meshes/CAD/hand_left.stl" scale="0.001 0.001 0.001"/>
      </geometry>
    </collision>
    <visual name="hand_left_visual">
      <origin rpy="0  0  0" xyz="0.00272 -0.06303 -0.00774"/>
      <geometry>
        <mesh filename="package://roboy_models/roboy_2_0_simplified/meshes/CAD/hand_left.stl OR roboy_models/roboy_xylophone_left_arm/meshes/CAD/hand_left.stl" scale="0.001 0.001 0.001"/>
      </geometry>
    </visual>
  </link>
  <link name="lower_arm_left">
    <inertial>
      <mass value="0.5"/>
      <origin rpy="0  0  0" xyz="0.02501 -0.14978 -0.00184"/>
      <inertia ixx="0.01" ixy="0" ixz="0" iyy="0.01" iyz="0" izz="0.01"/>
    </inertial>
    <collision name="lower_arm_left_collision">
      <origin rpy="0  0  0" xyz="0.02501 -0.14978 -0.00184"/>
      <geometry>
        <mesh filename="package://roboy_models/roboy_2_0_arm_elbow/meshes/CAD/lower_arm_left.stl OR roboy_models/roboy_2_0_left_arm_elbow/meshes/CAD/lower_arm_left.stl OR roboy_models/roboy_2_0_left_arm_right/meshes/CAD/lower_arm_left.stl OR roboy_models/roboy_2_0_left_arm_simplified/meshes/CAD/lower_arm_left.stl OR roboy_models/roboy_2_0_simplified/meshes/CAD/lower_arm_left.stl OR roboy_models/roboy_xylophone_left_arm/meshes/CAD/lower_arm_left.stl" scale="0.001 0.001 0.001"/>
      </geometry>
    </collision>
    <visual name="lower_arm_left_visual">
      <origin rpy="0  0  0" xyz="0.02501 -0.14978 -0.00184"/>
      <geometry>
        <mesh filename="package://roboy_models/roboy_2_0_arm_elbow/meshes/CAD/lower_arm_left.stl OR roboy_models/roboy_2_0_left_arm_elbow/meshes/CAD/lower_arm_left.stl OR roboy_models/roboy_2_0_left_arm_right/meshes/CAD/lower_arm_left.stl OR roboy_models/roboy_2_0_left_arm_simplified/meshes/CAD/lower_arm_left.stl OR roboy_models/roboy_2_0_simplified/meshes/CAD/lower_arm_left.stl OR roboy_models/roboy_xylophone_left_arm/meshes/CAD/lower_arm_left.stl" scale="0.001 0.001 0.001"/>
      </geometry>
    </visual>
  </link>
  <link name="base">
    <inertial>
      <mass value="933.2307564477226"/>
      <origin rpy="0  0  0" xyz="0  0  0"/>
      <inertia ixx="174.29025998658256" ixy="0.026483455432128905" ixz="-0.12985684272785786" iyy="174.2835357800932" iyz="0.11441361775128898" izz="347.0634426014895"/>
    </inertial>
    <collision name="base_collision">
      <origin rpy="0  0  0" xyz="0  0  0"/>
      <geometry>
        <mesh filename="package://roboy_models/cable_robot_6dof/meshes/CAD/base.stl OR roboy_models/nst_arm/meshes/CAD/base.stl" scale="0.001 0.001 0.001"/>
      </geometry>
    </collision>
    <visual name="base_visual">
      <origin rpy="0  0  0" xyz="0  0  0"/>
      <geometry>
        <mesh filename="package://roboy_models/cable_robot_6dof/meshes/CAD/base.stl OR roboy_models/nst_arm/meshes/CAD/base.stl" scale="0.001 0.001 0.001"/>
      </geometry>
    </visual>
  </link>
  <link name="sphere_link1">
    <inertial>
      <mass value="0.001"/>
      <origin rpy="0  0  0" xyz="0  0  0"/>
      <inertia ixx="0.001" ixy="0" ixz="0" iyy="0.001" iyz="0" izz="0.001"/>
    </inertial>
    <collision name="sphere_link1_collision">
      <origin rpy="0  0  0" xyz="0  0  0"/>
      <geometry>
        <mesh filename="package://roboy_models/roboy_xylophone_left_arm/meshes/CAD/sphere_link1.stl" scale="0.001 0.001 0.001"/>
      </geometry>
    </collision>
    <visual name="sphere_link1_visual">
      <origin rpy="0  0  0" xyz="0  0  0"/>
      <geometry>
        <mesh filename="package://roboy_models/roboy_xylophone_left_arm/meshes/CAD/sphere_link1.stl" scale="0.001 0.001 0.001"/>
      </geometry>
    </visual>
  </link>
  <link name="sphere_link2">
    <inertial>
      <mass value="0.001"/>
      <origin rpy="0  0  0" xyz="-0.25852 -0.00661 -0.56391"/>
      <inertia ixx="0.001" ixy="0" ixz="0" iyy="0.001" iyz="0" izz="0.001"/>
    </inertial>
    <collision name="sphere_link2_collision">
      <origin rpy="0  0  0" xyz="-0.25852 -0.00661 -0.56391"/>
      <geometry>
        <mesh filename="package://roboy_models/roboy_xylophone_left_arm/meshes/CAD/sphere_link2.stl" scale="0.001 0.001 0.001"/>
      </geometry>
    </collision>
    <visual name="sphere_link2_visual">
      <origin rpy="0  0  0" xyz="-0.25852 -0.00661 -0.56391"/>
      <geometry>
        <mesh filename="package://roboy_models/roboy_xylophone_left_arm/meshes/CAD/sphere_link2.stl" scale="0.001 0.001 0.001"/>
      </geometry>
    </visual>
  </link>
</robot>
