<?xml version="1.0" ?>
<sdf version="1.6">
	<model name="roboy_xylophone_left_arm">
		<link name="upper_arm_left">
			<self_collide>false</self_collide>
			<pose frame="">0.29918151155750894 0.011369580595914091 0.31253833035168344 0.0 -0.0 0.0</pose>
			<inertial>
				<pose frame="">0.0 0.0 0.0 0 0 0</pose>
				<mass>2.9373922866908293</mass>
				<inertia>
					<ixx>0.4141023130540913</ixx>
					<ixy>-0.0036139802775392357</ixy>
					<ixz>-0.004649940484527234</ixz>
					<iyy>0.6804098562416945</iyy>
					<iyz>-0.3272500353871178</iyz>
					<izz>0.27573309553466746</izz>
				</inertia>
			</inertial>
			<collision name="upper_arm_left_collision">
				<geometry>
					<mesh>
						<uri>model://roboy_xylophone_left_arm/meshes/CAD/upper_arm_left.stl</uri>
						<scale>0.001 0.001 0.001</scale>
					</mesh>
				</geometry>
			</collision>
			<visual name="upper_arm_left_visual">
				<geometry>
					<mesh>
						<uri>model://roboy_xylophone_left_arm/meshes/CAD/upper_arm_left.stl</uri>
						<scale>0.001 0.001 0.001</scale>
					</mesh>
				</geometry>
			</visual>
		</link>
		<link name="torso">
			<self_collide>false</self_collide>
			<pose frame="">-2.5210583336983455e-16 2.5830904394012438e-15 0.3009128442572498 0.0 -0.0 0.0</pose>
			<inertial>
				<pose frame="">0.0 0.0 0.0 0 0 0</pose>
				<mass>11.643744728583687</mass>
				<inertia>
					<ixx>2.8463837157125496</ixx>
					<ixy>-0.0012433611652691832</ixy>
					<ixz>0.03913837973360937</ixz>
					<iyy>3.064545105530511</iyy>
					<iyz>-0.06936776268453516</iyz>
					<izz>0.3132575627630051</izz>
				</inertia>
			</inertial>
			<collision name="torso_collision">
				<geometry>
					<mesh>
						<uri>model://roboy_xylophone_left_arm/meshes/CAD/torso.stl</uri>
						<scale>0.001 0.001 0.001</scale>
					</mesh>
				</geometry>
			</collision>
			<visual name="torso_visual">
				<geometry>
					<mesh>
						<uri>model://roboy_xylophone_left_arm/meshes/CAD/torso.stl</uri>
						<scale>0.001 0.001 0.001</scale>
					</mesh>
				</geometry>
			</visual>
		</link>
		<link name="hand_left">
			<self_collide>false</self_collide>
			<pose frame="">0.30442049624244366 -0.32842961298019435 0.21283053116373596 0.0 -0.0 0.0</pose>
			<inertial>
				<pose frame="">0.0 0.0 0.0 0 0 0</pose>
				<mass>1.1634530113059427</mass>
				<inertia>
					<ixx>0.41745573289998594</ixx>
					<ixy>0.15057565057163763</ixy>
					<ixz>0.2058633544395063</ixz>
					<iyy>0.32741533772019266</iyy>
					<iyz>-0.1520171407721289</iyz>
					<izz>0.3153212218952332</izz>
				</inertia>
			</inertial>
			<collision name="hand_left_collision">
				<geometry>
					<mesh>
						<uri>model://roboy_xylophone_left_arm/meshes/CAD/hand_left.stl</uri>
						<scale>0.001 0.001 0.001</scale>
					</mesh>
				</geometry>
			</collision>
			<visual name="hand_left_visual">
				<geometry>
					<mesh>
						<uri>model://roboy_xylophone_left_arm/meshes/CAD/hand_left.stl</uri>
						<scale>0.001 0.001 0.001</scale>
					</mesh>
				</geometry>
			</visual>
		</link>
		<link name="lower_arm_left">
			<self_collide>false</self_collide>
			<pose frame="">0.2960816955776892 -0.15553696772591058 0.21811602369510363 0.0 -0.0 0.0</pose>
			<inertial>
				<pose frame="">0.0 0.0 0.0 0 0 0</pose>
				<mass>1.4964651734345906</mass>
				<inertia>
					<ixx>0.10983805357461027</ixx>
					<ixy>0.06388756057932181</ixy>
					<ixz>0.04696291574935086</ixz>
					<iyy>0.20312453895260563</iyy>
					<iyz>-0.09629586750052653</iyz>
					<izz>0.17004481562838614</izz>
				</inertia>
			</inertial>
			<collision name="lower_arm_left_collision">
				<geometry>
					<mesh>
						<uri>model://roboy_xylophone_left_arm/meshes/CAD/lower_arm_left.stl</uri>
						<scale>0.001 0.001 0.001</scale>
					</mesh>
				</geometry>
			</collision>
			<visual name="lower_arm_left_visual">
				<geometry>
					<mesh>
						<uri>model://roboy_xylophone_left_arm/meshes/CAD/lower_arm_left.stl</uri>
						<scale>0.001 0.001 0.001</scale>
					</mesh>
				</geometry>
			</visual>
		</link>
		<link name="base">
			<self_collide>false</self_collide>
			<pose frame="">0.0 0.0 0.0 0.0 -0.0 0.0</pose>
			<inertial>
				<pose frame="">0.0 0.0 0.0 0 0 0</pose>
				<mass>933.2307564477226</mass>
				<inertia>
					<ixx>174.29025998658256</ixx>
					<ixy>0.026483455432128905</ixy>
					<ixz>-0.12985684272785786</ixz>
					<iyy>174.2835357800932</iyy>
					<iyz>0.11441361775128898</iyz>
					<izz>347.0634426014895</izz>
				</inertia>
			</inertial>
			<collision name="base_collision">
				<geometry>
					<mesh>
						<uri>model://roboy_xylophone_left_arm/meshes/CAD/base.stl</uri>
						<scale>0.001 0.001 0.001</scale>
					</mesh>
				</geometry>
			</collision>
			<visual name="base_visual">
				<geometry>
					<mesh>
						<uri>model://roboy_xylophone_left_arm/meshes/CAD/base.stl</uri>
						<scale>0.001 0.001 0.001</scale>
					</mesh>
				</geometry>
			</visual>
		</link>
		<link name="sphere_link1">
			<self_collide>false</self_collide>
			<pose frame="">0.2921800561556851 0.0076882557614745385 0.5492779566488885 0.0 -0.0 0.0</pose>
			<inertial>
				<pose frame="">0.0 0.0 0.0 0 0 0</pose>
				<mass>0.046755519327953424</mass>
				<inertia>
					<ixx>0.014115173313322345</ixx>
					<ixy>-0.00010503177203843484</ixy>
					<ixz>-0.0001974523652045118</ixz>
					<iyy>0.018103889927972235</iyy>
					<iyz>-0.007503703202094315</iyz>
					<izz>0.004000218353034255</izz>
				</inertia>
			</inertial>
			<collision name="sphere_link1_collision">
				<geometry>
					<mesh>
						<uri>model://roboy_xylophone_left_arm/meshes/CAD/sphere_link1.stl</uri>
						<scale>0.001 0.001 0.001</scale>
					</mesh>
				</geometry>
			</collision>
			<visual name="sphere_link1_visual">
				<geometry>
					<mesh>
						<uri>model://roboy_xylophone_left_arm/meshes/CAD/sphere_link1.stl</uri>
						<scale>0.001 0.001 0.001</scale>
					</mesh>
				</geometry>
			</visual>
		</link>
		<link name="sphere_link2">
			<self_collide>false</self_collide>
			<pose frame="">0.03365587285659524 -0.003925581378171482 -0.004638978334057254 0.0 -0.0 0.0</pose>
			<inertial>
				<pose frame="">0.0 0.0 0.0 0 0 0</pose>
				<mass>0.03134020848172138</mass>
				<inertia>
					<ixx>0.009460089435523117</ixx>
					<ixy>-7.039997333794983e-05</ixy>
					<ixz>-0.0001323469977108327</ixz>
					<iyy>0.012133725290292965</iyy>
					<iyz>-0.0050297297974830355</iyz>
					<izz>0.0026800392713477433</izz>
				</inertia>
			</inertial>
			<collision name="sphere_link2_collision">
				<geometry>
					<mesh>
						<uri>model://roboy_xylophone_left_arm/meshes/CAD/sphere_link2.stl</uri>
						<scale>0.001 0.001 0.001</scale>
					</mesh>
				</geometry>
			</collision>
			<visual name="sphere_link2_visual">
				<geometry>
					<mesh>
						<uri>model://roboy_xylophone_left_arm/meshes/CAD/sphere_link2.stl</uri>
						<scale>0.001 0.001 0.001</scale>
					</mesh>
				</geometry>
			</visual>
		</link>
		<joint name="elbow_left" type="revolute">
			<parent>upper_arm_left</parent>
			<child>lower_arm_left</child>
			<pose frame="">-0.02811163391155347 -0.017126069237037515 -0.09257322148007895 0 0 0</pose>
			<axis>
				<xyz>-0.9986354432836171 -0.05074429632816361 0.012339684270766395</xyz>
				<limit>
					<lower>-1.5707963267948966</lower>
					<upper>0.0</upper>
				</limit>
				<use_parent_model_frame>0</use_parent_model_frame>
			</axis>
		</joint>
		<joint name="wrist_left" type="revolute">
			<parent>lower_arm_left</parent>
			<child>hand_left</child>
			<pose frame="">0.005612859988731529 -0.10986276237898675 0.002454872643511088 0 0 0</pose>
			<axis>
				<xyz>0.026382389429096362 -0.9993900891826023 0.022878355963713168</xyz>
				<limit>
					<lower>-1.5707963267948966</lower>
					<upper>1.5707963267948966</upper>
				</limit>
				<use_parent_model_frame>0</use_parent_model_frame>
			</axis>
		</joint>
		<joint name="base_joint" type="revolute">
			<parent>base</parent>
			<child>torso</child>
			<pose frame="">1.5368196702895297e-17 -4.2971225516635905e-16 2.2026824808563106e-15 0 0 0</pose>
			<axis>
				<xyz>-5.680911057209429e-16 6.847300504375648e-15 1.000000000000001</xyz>
				<limit>
					<lower>-3.141592653589793</lower>
					<upper>3.141592653589793</upper>
				</limit>
				<use_parent_model_frame>0</use_parent_model_frame>
			</axis>
		</joint>
		<joint name="sphere_axis0" type="revolute">
			<parent>torso</parent>
			<child>sphere_link1</child>
			<pose frame="">0.2921800561556852 0.0076882557614719425 0.24836511239163878 0 0 0</pose>
			<axis>
				<xyz>0.05101049431667499 -0.9984488883025685 0.022310242422111375</xyz>
				<limit>
					<lower>-3.141592653589793</lower>
					<upper>3.141592653589793</upper>
				</limit>
				<use_parent_model_frame>0</use_parent_model_frame>
			</axis>
		</joint>
		<joint name="sphere_axis2" type="revolute">
			<parent>sphere_link2</parent>
			<child>upper_arm_left</child>
			<pose frame="">0.25852418329908966 0.011613837139646001 0.5539169349829458 0 0 0</pose>
			<axis>
				<xyz>-0.01118842648953415 -0.022909252225333823 -0.9996749398055161</xyz>
				<limit>
					<lower>-3.141592653589793</lower>
					<upper>3.141592653589793</upper>
				</limit>
				<use_parent_model_frame>0</use_parent_model_frame>
			</axis>
		</joint>
		<joint name="sphere_axis1" type="revolute">
			<parent>sphere_link1</parent>
			<child>sphere_link2</child>
			<pose frame="">-1.7763568394002506e-16 -1.7763568394002505e-17 -1.4210854715202004e-16 0 0 0</pose>
			<axis>
				<xyz>0.9986354432836124 0.050744296328168306 -0.012339684270770068</xyz>
				<limit>
					<lower>-3.141592653589793</lower>
					<upper>3.141592653589793</upper>
				</limit>
				<use_parent_model_frame>0</use_parent_model_frame>
			</axis>
		</joint>
		<plugin filename="libmusc_plugin.so" name="musc_plugin">
			<myoMuscle name="motor0">
				<link name="torso">
					<viaPoint type="FIXPOINT">0.2376902809880496 -0.017689027265440305 0.12858346006581597</viaPoint>
					<viaPoint type="FIXPOINT">0.2719330451177387 -0.013737008525793537 0.2674943860318247</viaPoint>
					<viaPoint type="FIXPOINT">0.2889410922378474 -0.010689615277496609 0.2753417911253602</viaPoint>
				</link>
				<link name="upper_arm_left">
					<viaPoint type="FIXPOINT">0.016072728630030432 -0.023476936906392562 0.16643031914286505</viaPoint>
				</link>
			</myoMuscle>
			<myoMuscle name="motor1">
				<link name="torso">
					<viaPoint type="FIXPOINT">0.2400353945194028 -0.025509439663539683 0.16638120522593233</viaPoint>
				</link>
				<link name="upper_arm_left">
					<viaPoint type="FIXPOINT">-0.024781458176804882 -0.02393975925107067 0.16689816820167877</viaPoint>
				</link>
			</myoMuscle>
			<myoMuscle name="motor2">
				<link name="torso">
					<viaPoint type="FIXPOINT">0.25121801331283644 -0.028667405657348308 0.21364625546833005</viaPoint>
				</link>
				<link name="upper_arm_left">
					<viaPoint type="FIXPOINT">-0.0020006510365530874 -0.017970229185799932 0.17749176415739384</viaPoint>
				</link>
			</myoMuscle>
			<myoMuscle name="motor3">
				<link name="torso">
					<viaPoint type="FIXPOINT">0.28063665292590706 -0.028534400330320377 0.2570875816989544</viaPoint>
				</link>
				<link name="upper_arm_left">
					<viaPoint type="FIXPOINT">0.012725278054959474 -0.027183173570044607 0.16655271874532454</viaPoint>
				</link>
			</myoMuscle>
			<myoMuscle name="motor4">
				<link name="torso">
					<viaPoint type="FIXPOINT">0.3033935027253936 2.269971956991472e-15 0.2952321087635334</viaPoint>
				</link>
				<link name="upper_arm_left">
					<viaPoint type="FIXPOINT">0.022169027556373243 -0.0037736810777565834 0.16591055533850763</viaPoint>
				</link>
			</myoMuscle>
			<myoMuscle name="motor5">
				<link name="upper_arm_left">
					<viaPoint type="FIXPOINT">0.011157894780130562 0.01791868984856187 0.16553667505762776</viaPoint>
				</link>
				<link name="torso">
					<viaPoint type="FIXPOINT">0.2769871340021273 0.04289909901328245 0.25549140716655055</viaPoint>
				</link>
			</myoMuscle>
			<myoMuscle name="motor6">
				<link name="torso">
					<viaPoint type="FIXPOINT">0.24756132617262325 0.04290640006489047 0.21204694580365818</viaPoint>
				</link>
				<link name="upper_arm_left">
					<viaPoint type="FIXPOINT">-0.003347328086513315 0.008388821465387839 0.17690277375745012</viaPoint>
				</link>
			</myoMuscle>
			<myoMuscle name="motor7">
				<link name="torso">
					<viaPoint type="FIXPOINT">0.236174665401922 0.0500581616119091 0.16469265459157925</viaPoint>
				</link>
				<link name="upper_arm_left">
					<viaPoint type="FIXPOINT">-0.02357235233119738 0.015287828229899936 0.16598566889681274</viaPoint>
				</link>
			</myoMuscle>
			<myoMuscle name="motor8">
				<link name="torso">
					<viaPoint type="FIXPOINT">0.23414595021784793 0.05384194818674343 0.12702585696969615</viaPoint>
					<viaPoint type="FIXPOINT">0.26969226825276893 0.027710898774527478 0.2670559881812207</viaPoint>
					<viaPoint type="FIXPOINT">0.2865401700456325 0.02607560577031493 0.2752279682345082</viaPoint>
				</link>
				<link name="upper_arm_left">
					<viaPoint type="FIXPOINT">0.010388407912919463 0.018557324080128813 0.16553065181426888</viaPoint>
				</link>
			</myoMuscle>
			<myoMuscle name="motor9">
				<link name="upper_arm_left">
					<viaPoint type="FIXPOINT">-0.005138554390814072 -0.07264740526982914 0.03174056270007931</viaPoint>
				</link>
				<link name="lower_arm_left">
					<viaPoint type="FIXPOINT">-0.005891487620418161 0.12606392446871115 0.017308124213706685</viaPoint>
				</link>
			</myoMuscle>
			<myoMuscle name="motor10">
				<link name="upper_arm_left">
					<viaPoint type="FIXPOINT">-0.006893993429666772 0.05615853417436983 0.02880840241728372</viaPoint>
				</link>
				<link name="lower_arm_left">
					<viaPoint type="FIXPOINT">-0.00659282106739905 0.125730781951873 -0.040819904394658484</viaPoint>
				</link>
			</myoMuscle>
			<endEffector link="hand_left" name="endeffector0">-0.016022497811992623 0.6152870263626005 0.8043076916227997</endEffector>
		</plugin>
	</model>
</sdf>
