<sdf version="1.6">
    <model name="PaBiRoboy">
        <link name="hip">
            <pose frame="">0.0 0.0 0.0 1.5707963267948966 -0.0 0.0</pose>
            <inertial>
                <pose frame="">-0.15002041534933927 1.1716972724158143 -0.5040047115226668 0 0 0</pose>
                <mass>4.515518105125237</mass>
                <inertia>
                    <ixx>7.407739933398221</ixx>
                    <ixy>0.7937299806675692</ixy>
                    <ixz>2.666594736599786</ixz>
                    <iyy>1.286253981870223</iyy>
                    <iyz>-0.3416972307213158</iyz>
                    <izz>6.325208064031285</izz>
                </inertia>
            </inertial>
            <collision name="hip_collision">
                <geometry>
                    <mesh>
                        <uri>model://PaBiRoboy/meshes/hip.STL</uri>
                        <scale>0.001 0.001 0.001</scale>
                    </mesh>
                </geometry>
            </collision>
            <visual name="hip_visual">
                <geometry>
                    <mesh>
                        <uri>model://PaBiRoboy/meshes/hip.STL</uri>
                        <scale>0.001 0.001 0.001</scale>
                    </mesh>
                </geometry>
            </visual>
        </link>
        <link name="shank_1">
            <pose frame="">0.0 0.0 0.0 1.5707963267948966 -0.0 0.0</pose>
            <inertial>
                <pose frame="">-0.1498899919696913 0.11454015564436557 -0.3977472766994466 0 0 0</pose>
                <mass>2.0625685823803326</mass>
                <inertia>
                    <ixx>0.41051160028001255</ixx>
                    <ixy>0.03536587354463122</ixy>
                    <ixz>0.09868851688853236</ixz>
                    <iyy>0.3844693086888858</iyy>
                    <iyz>-0.12296427581377094</iyz>
                    <izz>0.13881430150315646</izz>
                </inertia>
            </inertial>
            <collision name="shank_1_collision">
                <geometry>
                    <mesh>
                        <uri>model://PaBiRoboy/meshes/shank_1.STL</uri>
                        <scale>0.001 0.001 0.001</scale>
                    </mesh>
                </geometry>
            </collision>
            <visual name="shank_1_visual">
                <geometry>
                    <mesh>
                        <uri>model://PaBiRoboy/meshes/shank_1.STL</uri>
                        <scale>0.001 0.001 0.001</scale>
                    </mesh>
                </geometry>
            </visual>
        </link>
        <link name="thigh_1">
            <pose frame="">0.0 0.0 0.0 1.5707963267948966 -0.0 0.0</pose>
            <inertial>
                <pose frame="">-0.14999736092521762 0.7487547394663646 -0.4191048166970805 0 0 0</pose>
                <mass>2.6030004321947455</mass>
                <inertia>
                    <ixx>1.965247721462291</ixx>
                    <ixy>0.29241453399707795</ixy>
                    <ixz>0.8176001518602699</ixz>
                    <iyy>0.5186775209873178</iyy>
                    <iyz>-0.16376074275087069</iyz>
                    <izz>1.5640303772254374</izz>
                </inertia>
            </inertial>
            <collision name="thigh_1_collision">
                <geometry>
                    <mesh>
                        <uri>model://PaBiRoboy/meshes/thigh_1.STL</uri>
                        <scale>0.001 0.001 0.001</scale>
                    </mesh>
                </geometry>
            </collision>
            <visual name="thigh_1_visual">
                <geometry>
                    <mesh>
                        <uri>model://PaBiRoboy/meshes/thigh_1.STL</uri>
                        <scale>0.001 0.001 0.001</scale>
                    </mesh>
                </geometry>
            </visual>
        </link>
        <link name="shank_2">
            <pose frame="">0.0 0.0 0.0 1.5707963267948966 -0.0 0.0</pose>
            <inertial>
                <pose frame="">-0.1503004395037226 0.11454013690016886 -0.6102608068692738 0 0 0</pose>
                <mass>2.0625684626201046</mass>
                <inertia>
                    <ixx>0.8523453884801894</ixx>
                    <ixy>0.0355531838187655</ixy>
                    <ixz>0.13945025914903858</ixz>
                    <iyy>0.8265572509379822</iyy>
                    <iyz>-0.1891812363603959</iyz>
                    <izz>0.13906841015606541</izz>
                </inertia>
            </inertial>
            <collision name="shank_2_collision">
                <geometry>
                    <mesh>
                        <uri>model://PaBiRoboy/meshes/shank_2.STL</uri>
                        <scale>0.001 0.001 0.001</scale>
                    </mesh>
                </geometry>
            </collision>
            <visual name="shank_2_visual">
                <geometry>
                    <mesh>
                        <uri>model://PaBiRoboy/meshes/shank_2.STL</uri>
                        <scale>0.001 0.001 0.001</scale>
                    </mesh>
                </geometry>
            </visual>
        </link>
        <link name="thigh_2">
            <pose frame="">0.0 0.0 0.0 1.5707963267948966 -0.0 0.0</pose>
            <inertial>
                <pose frame="">-0.15014342022873625 0.7487547497997309 -0.5889044407762414 0 0 0</pose>
                <mass>2.603000551950703</mass>
                <inertia>
                    <ixx>2.410775842792121</ixx>
                    <ixy>0.29256184740247115</ixy>
                    <ixz>1.1470166148065495</ixz>
                    <iyy>0.9643193370822432</iyy>
                    <iyz>-0.23028167935546787</iyz>
                    <izz>1.5641442977245283</izz>
                </inertia>
            </inertial>
            <collision name="thigh_2_collision">
                <geometry>
                    <mesh>
                        <uri>model://PaBiRoboy/meshes/thigh_2.STL</uri>
                        <scale>0.001 0.001 0.001</scale>
                    </mesh>
                </geometry>
            </collision>
            <visual name="thigh_2_visual">
                <geometry>
                    <mesh>
                        <uri>model://PaBiRoboy/meshes/thigh_2.STL</uri>
                        <scale>0.001 0.001 0.001</scale>
                    </mesh>
                </geometry>
            </visual>
        </link>
        <joint name="hip_1" type="revolute">
            <parent>hip</parent>
            <child>thigh_1</child>
            <pose frame="">-0.14742021315326947 1.0234244082948523 -0.41910403188054424 0 0 0</pose>
            <axis>
                <xyz>0.9999999999999951 5.068636417698733e-16 -4.612020293685559e-16</xyz>
                <limit>
                    <lower>-10.0</lower>
                    <upper>10.0</upper>
                </limit>
                <use_parent_model_frame>0</use_parent_model_frame>
            </axis>
        </joint>
        <joint name="knee_1" type="revolute">
            <parent>thigh_1</parent>
            <child>shank_1</child>
            <pose frame="">-0.14994999999998782 0.48742440829485256 -0.4191040318805473 0 0 0</pose>
            <axis>
                <xyz>0.9999999999999927 1.1557058777634089e-15 9.87758344710424e-16</xyz>
                <limit>
                    <lower>-10.0</lower>
                    <upper>10.0</upper>
                </limit>
                <use_parent_model_frame>0</use_parent_model_frame>
            </axis>
        </joint>
        <joint name="hip_2" type="revolute">
            <parent>hip</parent>
            <child>thigh_2</child>
            <pose frame="">-0.14762021315326976 1.0234244082948518 -0.5889040318805452 0 0 0</pose>
            <axis>
                <xyz>-0.9999999999999909 -2.1451149500899796e-15 -7.752511193481003e-17</xyz>
                <limit>
                    <lower>-10.0</lower>
                    <upper>10.0</upper>
                </limit>
                <use_parent_model_frame>0</use_parent_model_frame>
            </axis>
        </joint>
        <joint name="knee_2" type="revolute">
            <parent>thigh_2</parent>
            <child>shank_2</child>
            <pose frame="">-0.1476904263065515 0.48742440829485384 -0.5889040318805463 0 0 0</pose>
            <axis>
                <xyz>-0.9999999999999893 -1.393094538353255e-15 -1.2098029496354482e-15</xyz>
                <limit>
                    <lower>-10.0</lower>
                    <upper>10.0</upper>
                </limit>
                <use_parent_model_frame>0</use_parent_model_frame>
            </axis>
        </joint>
	<!--
        <plugin filename="libWalkController.so" name="walkController">
            <myoMuscle name="motor0">
                <link name="hip">
                    <viaPoint type="FIXPOINT">-0.148639 1.162521 -0.384353</viaPoint>
                </link>
                <link name="thigh_1">
                    <viaPoint type="FIXPOINT">-0.150344 0.985622 -0.414871</viaPoint>
                </link>
                <spanningJoint name="hip_1">extensor</spanningJoint>
            </myoMuscle>

            <myoMuscle name="motor1">
                <link name="hip">
                    <viaPoint type="FIXPOINT">-0.148543 1.135528 -0.454545</viaPoint>
                </link>
                <link name="thigh_1">
                    <viaPoint type="FIXPOINT">-0.151316 0.993531 -0.444029</viaPoint>
                </link>
                <spanningJoint name="hip_1">extensor</spanningJoint>
            </myoMuscle>

            <myoMuscle name="motor2">
                <link name="hip">
                    <viaPoint type="FIXPOINT">-0.152150 1.133932 -0.548977</viaPoint>
                </link>
                <link name="thigh_2">
                    <viaPoint type="FIXPOINT">-0.151930 0.983643 -0.584347</viaPoint>
                </link>
                <spanningJoint name="hip_2">extensor</spanningJoint>
            </myoMuscle>

            <myoMuscle name="motor3">
                <link name="hip">
                    <viaPoint type="FIXPOINT">-0.148296 1.158805 -0.628435</viaPoint>
                </link>
                <link name="thigh_2">
                    <viaPoint type="FIXPOINT">-0.153492 0.994259 -0.613671</viaPoint>
                </link>
                <spanningJoint name="hip_2">flexor</spanningJoint>
            </myoMuscle>

            <myoMuscle name="motor4">
                <link name="thigh_1">
                    <viaPoint type="FIXPOINT">-0.152466 0.667015 -0.378780</viaPoint>
                </link>
                <link name="shank_1">
                    <viaPoint type="FIXPOINT">-0.151344 0.447012 -0.414533</viaPoint>
                </link>
                <spanningJoint name="knee_1">extensor</spanningJoint>
            </myoMuscle>

            <myoMuscle name="motor5">
                <link name="thigh_1">
                    <viaPoint type="FIXPOINT">-0.148231 0.694709 -0.457648</viaPoint>
                </link>
                <link name="shank_1">
                    <viaPoint type="FIXPOINT">-0.149776 0.445015 -0.423157</viaPoint>
                </link>
                <spanningJoint name="knee_1">flexor</spanningJoint>
            </myoMuscle>

            <myoMuscle name="motor6">
                <link name="thigh_2">
                    <viaPoint type="FIXPOINT">-0.151904 0.695694 -0.551728</viaPoint>
                </link>
                <link name="shank_2">
                    <viaPoint type="FIXPOINT">-0.151560 0.443761 -0.584468</viaPoint>
                </link>
                <spanningJoint name="knee_2">extensor</spanningJoint>
            </myoMuscle>

            <myoMuscle name="motor7">
                <link name="thigh_2">
                    <viaPoint type="FIXPOINT">-0.148867 0.669111 -0.623447</viaPoint>
                </link>
                <link name="shank_2">
                    <viaPoint type="FIXPOINT">-0.148685 0.443278 -0.593450</viaPoint>
                </link>
                <spanningJoint name="knee_2">flexor</spanningJoint>
            </myoMuscle>

            <foot_sole_left>0 0 -0.1085</foot_sole_left>
            <foot_sole_right>0 0 -0.1085</foot_sole_right>
        </plugin>
	-->
    </model>
</sdf>
