<?xml version="1.0" ?>
<sdf version="1.6">
	<model name="LeftHand">
		<link name="palm">
			<pose frame="">-0.0005000000000004635 0.00500000000000008 0.06701500000000059 0.0 -0.0 0.0</pose>
			<inertial>
				<pose frame="">0.0 0.0 0.0 0 0 0</pose>
				<mass>0.05103757097264085</mass>
				<inertia>
					<ixx>0.00029365168015556937</ixx>
					<ixy>7.779638765261958e-08</ixy>
					<ixz>2.3869257092691023e-05</ixz>
					<iyy>0.00030829511860800963</iyy>
					<iyz>5.777597508547474e-06</iyz>
					<izz>2.4451830110659234e-05</izz>
				</inertia>
			</inertial>
			<collision name="palm_collision">
				<geometry>
					<mesh>
						<uri>model://LeftHand/meshes/CAD/palm.stl</uri>
						<scale>0.001 0.001 0.001</scale>
					</mesh>
				</geometry>
			</collision>
			<visual name="palm_visual">
				<geometry>
					<mesh>
						<uri>model://LeftHand/meshes/CAD/palm.stl</uri>
						<scale>0.001 0.001 0.001</scale>
					</mesh>
				</geometry>
			</visual>
		</link>
		<link name="ring_limb0">
			<pose frame="">0.0 0.002401923788646685 -0.11975 0.0 -0.0 0.0</pose>
			<inertial>
				<pose frame="">0.0 0.0 0.0 0 0 0</pose>
				<mass>0.0004269863688298129</mass>
				<inertia>
					<ixx>5.705186481949831e-06</ixx>
					<ixy>-4.324087879365962e-08</ixy>
					<ixz>2.641937076803204e-07</ixz>
					<iyy>5.8478299020483795e-06</iyy>
					<iyz>9.311486939256405e-07</iyz>
					<izz>1.7250855397973148e-07</izz>
				</inertia>
			</inertial>
			<collision name="ring_limb0_collision">
				<geometry>
					<mesh>
						<uri>model://LeftHand/meshes/CAD/ring_limb0.stl</uri>
						<scale>0.001 0.001 0.001</scale>
					</mesh>
				</geometry>
			</collision>
			<visual name="ring_limb0_visual">
				<geometry>
					<mesh>
						<uri>model://LeftHand/meshes/CAD/ring_limb0.stl</uri>
						<scale>0.001 0.001 0.001</scale>
					</mesh>
				</geometry>
			</visual>
		</link>
		<link name="ring_limb1">
			<pose frame="">0.0 -0.0004330127018922192 -0.136 0.0 -0.0 0.0</pose>
			<inertial>
				<pose frame="">0.0 0.0 0.0 0 0 0</pose>
				<mass>0.0038293627955222967</mass>
				<inertia>
					<ixx>7.339305240567727e-05</ixx>
					<ixy>4.533371497969332e-07</ixy>
					<ixz>-2.3633501509366096e-06</ixz>
					<iyy>7.562026048540702e-05</iyy>
					<iyz>1.3267585012058292e-05</iyz>
					<izz>2.672490773940762e-06</izz>
				</inertia>
			</inertial>
			<collision name="ring_limb1_collision">
				<geometry>
					<mesh>
						<uri>model://LeftHand/meshes/CAD/ring_limb1.stl</uri>
						<scale>0.001 0.001 0.001</scale>
					</mesh>
				</geometry>
			</collision>
			<visual name="ring_limb1_visual">
				<geometry>
					<mesh>
						<uri>model://LeftHand/meshes/CAD/ring_limb1.stl</uri>
						<scale>0.001 0.001 0.001</scale>
					</mesh>
				</geometry>
			</visual>
		</link>
		<link name="ring_limb2">
			<pose frame="">0.0 -0.0004330127018922192 -0.18824987499999998 0.0 -0.0 0.0</pose>
			<inertial>
				<pose frame="">0.0 0.0 0.0 0 0 0</pose>
				<mass>0.0016247546846143884</mass>
				<inertia>
					<ixx>4.9521147545355215e-05</ixx>
					<ixy>1.0349551422481167e-06</ixy>
					<ixz>-5.1908242512515945e-06</ixz>
					<iyy>5.088851411033832e-05</iyy>
					<iyz>9.727635364613817e-06</iyz>
					<izz>2.520289753857832e-06</izz>
				</inertia>
			</inertial>
			<collision name="ring_limb2_collision">
				<geometry>
					<mesh>
						<uri>model://LeftHand/meshes/CAD/ring_limb2.stl</uri>
						<scale>0.001 0.001 0.001</scale>
					</mesh>
				</geometry>
			</collision>
			<visual name="ring_limb2_visual">
				<geometry>
					<mesh>
						<uri>model://LeftHand/meshes/CAD/ring_limb2.stl</uri>
						<scale>0.001 0.001 0.001</scale>
					</mesh>
				</geometry>
			</visual>
		</link>
		<link name="ring_limb3">
			<pose frame="">7.35799333358205e-18 -0.00043301270189221864 -0.21393542275000002 0.0 -0.0 0.0</pose>
			<inertial>
				<pose frame="">0.0 0.0 0.0 0 0 0</pose>
				<mass>0.000694374739355696</mass>
				<inertia>
					<ixx>2.772420312266683e-05</ixx>
					<ixy>8.045563508278753e-07</ixy>
					<ixz>-3.880806904384673e-06</ixz>
					<iyy>2.8333380066827055e-05</iyy>
					<iyz>5.628302424917296e-06</iyz>
					<izz>1.727876470678125e-06</izz>
				</inertia>
			</inertial>
			<collision name="ring_limb3_collision">
				<geometry>
					<mesh>
						<uri>model://LeftHand/meshes/CAD/ring_limb3.stl</uri>
						<scale>0.001 0.001 0.001</scale>
					</mesh>
				</geometry>
			</collision>
			<visual name="ring_limb3_visual">
				<geometry>
					<mesh>
						<uri>model://LeftHand/meshes/CAD/ring_limb3.stl</uri>
						<scale>0.001 0.001 0.001</scale>
					</mesh>
				</geometry>
			</visual>
		</link>
		<link name="little_limb0">
			<pose frame="">-0.019678577469519704 0.0024019237886464583 -0.11456042553314168 0.0 -0.0 0.0</pose>
			<inertial>
				<pose frame="">0.0 0.0 0.0 0 0 0</pose>
				<mass>0.00042697726664383786</mass>
				<inertia>
					<ixx>4.355587941337751e-06</ixx>
					<ixy>-7.320318351005169e-08</ixy>
					<ixz>2.2075537435390312e-07</ixz>
					<iyy>4.8245236479853645e-06</iyy>
					<iyz>1.4391228039942184e-06</iyz>
					<izz>4.961439548441098e-07</izz>
				</inertia>
			</inertial>
			<collision name="little_limb0_collision">
				<geometry>
					<mesh>
						<uri>model://LeftHand/meshes/CAD/little_limb0.stl</uri>
						<scale>0.001 0.001 0.001</scale>
					</mesh>
				</geometry>
			</collision>
			<visual name="little_limb0_visual">
				<geometry>
					<mesh>
						<uri>model://LeftHand/meshes/CAD/little_limb0.stl</uri>
						<scale>0.001 0.001 0.001</scale>
					</mesh>
				</geometry>
			</visual>
		</link>
		<link name="little_limb1">
			<pose frame="">-0.023884386952435454 -0.0004330127018925815 -0.13025672021033885 0.0 -0.0 0.0</pose>
			<inertial>
				<pose frame="">0.0 0.0 0.0 0 0 0</pose>
				<mass>0.0038295045533402986</mass>
				<inertia>
					<ixx>5.797477921662206e-05</ixx>
					<ixy>-7.269326800012614e-07</ixy>
					<ixz>1.955102195860375e-06</ixz>
					<iyy>6.616226450884912e-05</iyy>
					<iyz>2.1814487473743102e-05</iyz>
					<izz>8.399312060484794e-06</izz>
				</inertia>
			</inertial>
			<collision name="little_limb1_collision">
				<geometry>
					<mesh>
						<uri>model://LeftHand/meshes/CAD/little_limb1.stl</uri>
						<scale>0.001 0.001 0.001</scale>
					</mesh>
				</geometry>
			</collision>
			<visual name="little_limb1_visual">
				<geometry>
					<mesh>
						<uri>model://LeftHand/meshes/CAD/little_limb1.stl</uri>
						<scale>0.001 0.001 0.001</scale>
					</mesh>
				</geometry>
			</visual>
		</link>
		<link name="little_limb2">
			<pose frame="">-0.03740764970666212 -0.00043301270189306443 -0.18072622389321544 0.0 -0.0 0.0</pose>
			<inertial>
				<pose frame="">0.0 0.0 0.0 0 0 0</pose>
				<mass>0.0016247911658487592</mass>
				<inertia>
					<ixx>3.9996531972116905e-05</ixx>
					<ixy>-3.6390588649743713e-07</ixy>
					<ixz>8.719183832996038e-07</ixz>
					<iyy>4.7021312436865695e-05</iyy>
					<iyz>1.6774663757500476e-05</iyz>
					<izz>7.084672355258347e-06</izz>
				</inertia>
			</inertial>
			<collision name="little_limb2_collision">
				<geometry>
					<mesh>
						<uri>model://LeftHand/meshes/CAD/little_limb2.stl</uri>
						<scale>0.001 0.001 0.001</scale>
					</mesh>
				</geometry>
			</collision>
			<visual name="little_limb2_visual">
				<geometry>
					<mesh>
						<uri>model://LeftHand/meshes/CAD/little_limb2.stl</uri>
						<scale>0.001 0.001 0.001</scale>
					</mesh>
				</geometry>
			</visual>
		</link>
		<link name="little_limb3">
			<pose frame="">-0.04405555864825228 -0.00043301270189319204 -0.20553655782732164 0.0 -0.0 0.0</pose>
			<inertial>
				<pose frame="">0.0 0.0 0.0 0 0 0</pose>
				<mass>0.0006943833227503114</mass>
				<inertia>
					<ixx>2.254779176782516e-05</ixx>
					<ixy>-1.4909623965506232e-07</ixy>
					<ixz>3.3963132070903757e-07</ixz>
					<iyy>2.6907536710997e-05</iyy>
					<iyz>9.918495282603982e-06</iyz>
					<izz>4.375350062641269e-06</izz>
				</inertia>
			</inertial>
			<collision name="little_limb3_collision">
				<geometry>
					<mesh>
						<uri>model://LeftHand/meshes/CAD/little_limb3.stl</uri>
						<scale>0.001 0.001 0.001</scale>
					</mesh>
				</geometry>
			</collision>
			<visual name="little_limb3_visual">
				<geometry>
					<mesh>
						<uri>model://LeftHand/meshes/CAD/little_limb3.stl</uri>
						<scale>0.001 0.001 0.001</scale>
					</mesh>
				</geometry>
			</visual>
		</link>
		<link name="thumb_limb0">
			<pose frame="">-0.02750987086491734 0.025352627083963075 -0.06582868041594034 0.0 -0.0 0.0</pose>
			<inertial>
				<pose frame="">0.0 0.0 0.0 0 0 0</pose>
				<mass>0.0004269876906727725</mass>
				<inertia>
					<ixx>2.1819939213634575e-06</ixx>
					<ixy>2.630578155479801e-07</ixy>
					<ixz>7.069522131995128e-07</ixz>
					<iyy>2.1842368765602036e-06</iyy>
					<iyz>-7.137180227455262e-07</iyz>
					<izz>5.348246264645512e-07</izz>
				</inertia>
			</inertial>
			<collision name="thumb_limb0_collision">
				<geometry>
					<mesh>
						<uri>model://LeftHand/meshes/CAD/thumb_limb0.stl</uri>
						<scale>0.001 0.001 0.001</scale>
					</mesh>
				</geometry>
			</collision>
			<visual name="thumb_limb0_visual">
				<geometry>
					<mesh>
						<uri>model://LeftHand/meshes/CAD/thumb_limb0.stl</uri>
						<scale>0.001 0.001 0.001</scale>
					</mesh>
				</geometry>
			</visual>
		</link>
		<link name="thumb_limb1">
			<pose frame="">-0.028114731247337633 0.03619573732747787 -0.07824481786162585 0.0 -0.0 0.0</pose>
			<inertial>
				<pose frame="">0.0 0.0 0.0 0 0 0</pose>
				<mass>0.0038294723137475483</mass>
				<inertia>
					<ixx>3.565912073882621e-05</ixx>
					<ixy>3.435297238614782e-06</ixy>
					<ixz>1.3536676840083773e-05</ixz>
					<iyy>3.1377032449729916e-05</iyy>
					<iyz>-7.566667605919442e-06</iyz>
					<izz>8.416817617334465e-06</izz>
				</inertia>
			</inertial>
			<collision name="thumb_limb1_collision">
				<geometry>
					<mesh>
						<uri>model://LeftHand/meshes/CAD/thumb_limb1.stl</uri>
						<scale>0.001 0.001 0.001</scale>
					</mesh>
				</geometry>
			</collision>
			<visual name="thumb_limb1_visual">
				<geometry>
					<mesh>
						<uri>model://LeftHand/meshes/CAD/thumb_limb1.stl</uri>
						<scale>0.001 0.001 0.001</scale>
					</mesh>
				</geometry>
			</visual>
		</link>
		<link name="thumb_limb2">
			<pose frame="">-0.022135196957687907 0.06696652254520784 -0.12004737022722797 0.0 -0.0 0.0</pose>
			<inertial>
				<pose frame="">0.0 0.0 0.0 0 0 0</pose>
				<mass>0.0016247845904062185</mass>
				<inertia>
					<ixx>2.938903537997989e-05</ixx>
					<ixy>1.9612845310722753e-06</ixy>
					<ixz>1.2230575080743439e-05</ixz>
					<iyy>2.3416741753792575e-05</iyy>
					<iyz>-3.667074945953049e-06</iyz>
					<izz>7.1793896012951276e-06</izz>
				</inertia>
			</inertial>
			<collision name="thumb_limb2_collision">
				<geometry>
					<mesh>
						<uri>model://LeftHand/meshes/CAD/thumb_limb2.stl</uri>
						<scale>0.001 0.001 0.001</scale>
					</mesh>
				</geometry>
			</collision>
			<visual name="thumb_limb2_visual">
				<geometry>
					<mesh>
						<uri>model://LeftHand/meshes/CAD/thumb_limb2.stl</uri>
						<scale>0.001 0.001 0.001</scale>
					</mesh>
				</geometry>
			</visual>
		</link>
		<link name="thumb_limb3">
			<pose frame="">-0.019195714068598504 0.08209315151829145 -0.14059711230524335 0.0 -0.0 0.0</pose>
			<inertial>
				<pose frame="">0.0 0.0 0.0 0 0 0</pose>
				<mass>0.0006943642123641853</mass>
				<inertia>
					<ixx>1.7993103813154486e-05</ixx>
					<ixy>9.199724796858978e-07</ixy>
					<ixz>7.736261822635602e-06</ixz>
					<iyy>1.3777754367315693e-05</iyy>
					<iyz>-1.6158560702008287e-06</iyz>
					<izz>4.605026584875153e-06</izz>
				</inertia>
			</inertial>
			<collision name="thumb_limb3_collision">
				<geometry>
					<mesh>
						<uri>model://LeftHand/meshes/CAD/thumb_limb3.stl</uri>
						<scale>0.001 0.001 0.001</scale>
					</mesh>
				</geometry>
			</collision>
			<visual name="thumb_limb3_visual">
				<geometry>
					<mesh>
						<uri>model://LeftHand/meshes/CAD/thumb_limb3.stl</uri>
						<scale>0.001 0.001 0.001</scale>
					</mesh>
				</geometry>
			</visual>
		</link>
		<link name="index_limb0">
			<pose frame="">0.033061642412710444 0.0024019237886465463 -0.10011546984427355 0.0 -0.0 0.0</pose>
			<inertial>
				<pose frame="">0.0 0.0 0.0 0 0 0</pose>
				<mass>0.000427041167171139</mass>
				<inertia>
					<ixx>5.696396315690576e-06</ixx>
					<ixy>4.35236437691448e-08</ixy>
					<ixz>2.526333252288324e-07</ixz>
					<iyy>5.856562158492152e-06</iyy>
					<iyz>-9.786861419484762e-07</iyz>
					<izz>1.8738275226371265e-07</izz>
				</inertia>
			</inertial>
			<collision name="index_limb0_collision">
				<geometry>
					<mesh>
						<uri>model://LeftHand/meshes/CAD/index_limb0.stl</uri>
						<scale>0.001 0.001 0.001</scale>
					</mesh>
				</geometry>
			</collision>
			<visual name="index_limb0_visual">
				<geometry>
					<mesh>
						<uri>model://LeftHand/meshes/CAD/index_limb0.stl</uri>
						<scale>0.001 0.001 0.001</scale>
					</mesh>
				</geometry>
			</visual>
		</link>
		<link name="index_limb1">
			<pose frame="">0.04118664241271043 6.698729810764331e-05 -0.1141883826557706 0.0 -0.0 0.0</pose>
			<inertial>
				<pose frame="">0.0 0.0 0.0 0 0 0</pose>
				<mass>0.0038295073761239707</mass>
				<inertia>
					<ixx>7.514124864528453e-05</ixx>
					<ixy>4.179435612884838e-07</ixy>
					<ixz>2.227679305032662e-06</ixz>
					<iyy>7.777573780640452e-05</iyy>
					<iyz>-1.4224170063960728e-05</iyz>
					<izz>2.8463168148581786e-06</izz>
				</inertia>
			</inertial>
			<collision name="index_limb1_collision">
				<geometry>
					<mesh>
						<uri>model://LeftHand/meshes/CAD/index_limb1.stl</uri>
						<scale>0.001 0.001 0.001</scale>
					</mesh>
				</geometry>
			</collision>
			<visual name="index_limb1_visual">
				<geometry>
					<mesh>
						<uri>model://LeftHand/meshes/CAD/index_limb1.stl</uri>
						<scale>0.001 0.001 0.001</scale>
					</mesh>
				</geometry>
			</visual>
		</link>
		<link name="index_limb2">
			<pose frame="">0.06731157991271042 -0.00043301270189252596 -0.15943810175033216 0.0 -0.0 0.0</pose>
			<inertial>
				<pose frame="">0.0 0.0 0.0 0 0 0</pose>
				<mass>0.0016247911690079504</mass>
				<inertia>
					<ixx>5.140399571045418e-05</ixx>
					<ixy>2.0283352480940668e-07</ixy>
					<ixz>9.88827307904376e-07</ixz>
					<iyy>5.356532861477602e-05</iyy>
					<iyz>-1.0584698043686475e-05</iyz>
					<izz>2.2212247949079286e-06</izz>
				</inertia>
			</inertial>
			<collision name="index_limb2_collision">
				<geometry>
					<mesh>
						<uri>model://LeftHand/meshes/CAD/index_limb2.stl</uri>
						<scale>0.001 0.001 0.001</scale>
					</mesh>
				</geometry>
			</collision>
			<visual name="index_limb2_visual">
				<geometry>
					<mesh>
						<uri>model://LeftHand/meshes/CAD/index_limb2.stl</uri>
						<scale>0.001 0.001 0.001</scale>
					</mesh>
				</geometry>
			</visual>
		</link>
		<link name="index_limb3">
			<pose frame="">0.08015435378771045 -0.0004330127018925475 -0.18168243861195038 0.0 -0.0 0.0</pose>
			<inertial>
				<pose frame="">0.0 0.0 0.0 0 0 0</pose>
				<mass>0.000694383337351409</mass>
				<inertia>
					<ixx>2.88610672911933e-05</ixx>
					<ixy>8.20490915103938e-08</ixy>
					<ixz>3.84310202223997e-07</ixz>
					<iyy>3.017582178216648e-05</iyy>
					<iyz>-6.171778299680893e-06</iyz>
					<izz>1.3303596105165044e-06</izz>
				</inertia>
			</inertial>
			<collision name="index_limb3_collision">
				<geometry>
					<mesh>
						<uri>model://LeftHand/meshes/CAD/index_limb3.stl</uri>
						<scale>0.001 0.001 0.001</scale>
					</mesh>
				</geometry>
			</collision>
			<visual name="index_limb3_visual">
				<geometry>
					<mesh>
						<uri>model://LeftHand/meshes/CAD/index_limb3.stl</uri>
						<scale>0.001 0.001 0.001</scale>
					</mesh>
				</geometry>
			</visual>
		</link>
		<link name="middle_limb0">
			<pose frame="">0.018472005363350263 0.003071637170940513 -0.11378948793749274 0.0 -0.0 0.0</pose>
			<inertial>
				<pose frame="">0.0 0.0 0.0 0 0 0</pose>
				<mass>0.0004269894661254718</mass>
				<inertia>
					<ixx>6.220931215255115e-06</ixx>
					<ixy>-2.9280517172983007e-12</ixy>
					<ixz>2.640161236737273e-07</ixz>
					<iyy>6.2124188268254754e-06</iyy>
					<iyz>4.165012047714157e-11</iyz>
					<izz>1.8698194242482268e-08</izz>
				</inertia>
			</inertial>
			<collision name="middle_limb0_collision">
				<geometry>
					<mesh>
						<uri>model://LeftHand/meshes/CAD/middle_limb0.stl</uri>
						<scale>0.001 0.001 0.001</scale>
					</mesh>
				</geometry>
			</collision>
			<visual name="middle_limb0_visual">
				<geometry>
					<mesh>
						<uri>model://LeftHand/meshes/CAD/middle_limb0.stl</uri>
						<scale>0.001 0.001 0.001</scale>
					</mesh>
				</geometry>
			</visual>
		</link>
		<link name="middle_limb1">
			<pose frame="">0.02221748182250485 -0.0046803127482647755 -0.12776779638161082 0.0 -0.0 0.0</pose>
			<inertial>
				<pose frame="">0.0 0.0 0.0 0 0 0</pose>
				<mass>0.003829477216583566</mass>
				<inertia>
					<ixx>8.179745776724744e-05</ixx>
					<ixy>-1.0101743374580697e-12</ixy>
					<ixz>2.3248966541864924e-06</ixz>
					<iyy>8.172897136982157e-05</iyy>
					<iyz>1.5576625244889544e-11</iyz>
					<izz>1.4333886290587528e-07</izz>
				</inertia>
			</inertial>
			<collision name="middle_limb1_collision">
				<geometry>
					<mesh>
						<uri>model://LeftHand/meshes/CAD/middle_limb1.stl</uri>
						<scale>0.001 0.001 0.001</scale>
					</mesh>
				</geometry>
			</collision>
			<visual name="middle_limb1_visual">
				<geometry>
					<mesh>
						<uri>model://LeftHand/meshes/CAD/middle_limb1.stl</uri>
						<scale>0.001 0.001 0.001</scale>
					</mesh>
				</geometry>
			</visual>
		</link>
		<link name="middle_limb2">
			<pose frame="">0.03488093137814949 -0.023020668794906336 -0.17502843352236203 0.0 -0.0 0.0</pose>
			<inertial>
				<pose frame="">0.0 0.0 0.0 0 0 0</pose>
				<mass>0.0016247913530675396</mass>
				<inertia>
					<ixx>5.577988183128606e-05</ixx>
					<ixy>1.1170535520958148e-12</ixy>
					<ixz>1.030184337413135e-06</ixz>
					<iyy>5.5759467602633154e-05</iyy>
					<iyz>-3.978389888487825e-11</iyz>
					<izz>3.9477655466009195e-08</izz>
				</inertia>
			</inertial>
			<collision name="middle_limb2_collision">
				<geometry>
					<mesh>
						<uri>model://LeftHand/meshes/CAD/middle_limb2.stl</uri>
						<scale>0.001 0.001 0.001</scale>
					</mesh>
				</geometry>
			</collision>
			<visual name="middle_limb2_visual">
				<geometry>
					<mesh>
						<uri>model://LeftHand/meshes/CAD/middle_limb2.stl</uri>
						<scale>0.001 0.001 0.001</scale>
					</mesh>
				</geometry>
			</visual>
		</link>
		<link name="middle_limb3">
			<pose frame="">0.04112792235421852 -0.03180564351775972 -0.1983425212394759 0.0 -0.0 0.0</pose>
			<inertial>
				<pose frame="">0.0 0.0 0.0 0 0 0</pose>
				<mass>0.0006943748373823935</mass>
				<inertia>
					<ixx>3.126942660218027e-05</ixx>
					<ixy>9.770606141777381e-14</ixy>
					<ixz>4.0004172461025493e-07</ixz>
					<iyy>3.1263854150134474e-05</iyy>
					<iyz>-3.760132469022903e-12</iyz>
					<izz>1.0032349759270289e-08</izz>
				</inertia>
			</inertial>
			<collision name="middle_limb3_collision">
				<geometry>
					<mesh>
						<uri>model://LeftHand/meshes/CAD/middle_limb3.stl</uri>
						<scale>0.001 0.001 0.001</scale>
					</mesh>
				</geometry>
			</collision>
			<visual name="middle_limb3_visual">
				<geometry>
					<mesh>
						<uri>model://LeftHand/meshes/CAD/middle_limb3.stl</uri>
						<scale>0.001 0.001 0.001</scale>
					</mesh>
				</geometry>
			</visual>
		</link>
		<joint name="palm_ring" type="revolute">
			<parent>palm</parent>
			<child>ring_limb0</child>
			<pose frame="">0.011822362340004855 0.0025980762113533297 0.0017995428891567045 0 0 0</pose>
			<axis>
				<xyz>-0.9659258262890762 -4.904700770684754e-16 -0.25881904510252224</xyz>
				<limit>
					<lower>-0.3490658503988659</lower>
					<upper>1.2217304763960306</upper>
				</limit>
				<use_parent_model_frame>0</use_parent_model_frame>
			</axis>
		</joint>
		<joint name="palm_index" type="revolute">
			<parent>palm</parent>
			<child>index_limb0</child>
			<pose frame="">-0.06037289214705163 0.002598076211353447 -0.013952701590032 0 0 0</pose>
			<axis>
				<xyz>-0.9659258262890775 -5.479394496853379e-16 0.2588190451025223</xyz>
				<limit>
					<lower>-0.3490658503988659</lower>
					<upper>1.2217304763960306</upper>
				</limit>
				<use_parent_model_frame>0</use_parent_model_frame>
			</axis>
		</joint>
		<joint name="palm_thumb" type="revolute">
			<parent>palm</parent>
			<child>thumb_limb0</child>
			<pose frame="">0.0050819281913525765 0.006211717173626217 0.0009157377423762192 0 0 0</pose>
			<axis>
				<xyz>0.3535533905932764 0.8660254037844375 0.3535533905932753</xyz>
				<limit>
					<lower>-0.3490658503988659</lower>
					<upper>1.2217304763960306</upper>
				</limit>
				<use_parent_model_frame>0</use_parent_model_frame>
			</axis>
		</joint>
		<joint name="palm_little" type="revolute">
			<parent>palm</parent>
			<child>little_limb0</child>
			<pose frame="">0.046995029353847195 0.002598076211353564 0.009395917583191835 0 0 0</pose>
			<axis>
				<xyz>0.866025403784445 4.0999510464529535e-16 0.5000000000000029</xyz>
				<limit>
					<lower>-0.0</lower>
					<upper>-0.0</upper>
				</limit>
				<use_parent_model_frame>0</use_parent_model_frame>
			</axis>
		</joint>
		<joint name="palm_middle" type="revolute">
			<parent>palm</parent>
			<child>middle_limb0</child>
			<pose frame="">-0.01347200536335027 0.0019283628290594995 -0.00746051206250721 0 0 0</pose>
			<axis>
				<xyz>-1.0000000000000089 9.930890339105123e-17 -1.4559772246072405e-17</xyz>
				<limit>
					<lower>-0.3490658503988659</lower>
					<upper>1.2217304763960306</upper>
				</limit>
				<use_parent_model_frame>0</use_parent_model_frame>
			</axis>
		</joint>
		<joint name="joint0_ring" type="revolute">
			<parent>ring_limb0</parent>
			<child>ring_limb1</child>
			<pose frame="">0.01847200536335035 0.003504649872832554 0.02221051206250708 0 0 0</pose>
			<axis>
				<xyz>-0.198266891274149 -0.6427876096865431 0.7399421116938513</xyz>
				<limit>
					<lower>-0.3141592653589793</lower>
					<upper>0.3141592653589793</upper>
				</limit>
				<use_parent_model_frame>0</use_parent_model_frame>
			</axis>
		</joint>
		<joint name="joint1_ring" type="revolute">
			<parent>ring_limb1</parent>
			<child>ring_limb2</child>
			<pose frame="">0.026194272777333615 -0.011989819655914462 0.02439012454552845 0 0 0</pose>
			<axis>
				<xyz>0.9659258262890722 -8.101158632811689e-16 0.25881904510252285</xyz>
				<limit>
					<lower>-1.9198621771937625</lower>
					<upper>-0.0</upper>
				</limit>
				<use_parent_model_frame>0</use_parent_model_frame>
			</axis>
		</joint>
		<joint name="joint2_ring" type="revolute">
			<parent>ring_limb2</parent>
			<child>ring_limb3</child>
			<pose frame="">0.035232247234782264 -0.024258412632647563 0.022141047380554717 0 0 0</pose>
			<axis>
				<xyz>0.9659258262890722 -8.101158632811689e-16 0.25881904510252285</xyz>
				<limit>
					<lower>-1.2217304763960306</lower>
					<upper>-0.0</upper>
				</limit>
				<use_parent_model_frame>0</use_parent_model_frame>
			</axis>
		</joint>
		<joint name="joint0_middle" type="revolute">
			<parent>middle_limb0</parent>
			<child>middle_limb1</child>
			<pose frame="">-0.02221748182250485 0.00708223653691146 0.008017796381610829 0 0 0</pose>
			<axis>
				<xyz>6.842277657836021e-49 -0.8660254037844388 0.5</xyz>
				<limit>
					<lower>-0.6108652381980153</lower>
					<upper>0.6108652381980153</upper>
				</limit>
				<use_parent_model_frame>0</use_parent_model_frame>
			</axis>
		</joint>
		<joint name="joint1_middle" type="revolute">
			<parent>middle_limb1</parent>
			<child>middle_limb2</child>
			<pose frame="">-0.040380931378149486 0.028087656093014116 0.0026534335223620076 0 0 0</pose>
			<axis>
				<xyz>1.0 0.0 0.0</xyz>
				<limit>
					<lower>-1.9198621771937625</lower>
					<upper>-0.0</upper>
				</limit>
				<use_parent_model_frame>0</use_parent_model_frame>
			</axis>
		</joint>
		<joint name="joint2_middle" type="revolute">
			<parent>middle_limb2</parent>
			<child>middle_limb3</child>
			<pose frame="">-0.04512792235421852 0.035372630815867494 -0.005782228760524113 0 0 0</pose>
			<axis>
				<xyz>1.0 0.0 0.0</xyz>
				<limit>
					<lower>-1.2217304763960306</lower>
					<upper>-0.0</upper>
				</limit>
				<use_parent_model_frame>0</use_parent_model_frame>
			</axis>
		</joint>
		<joint name="joint0_little" type="revolute">
			<parent>little_limb0</parent>
			<child>little_limb1</child>
			<pose frame="">0.0569460293651462 0.0028349364905392825 0.03014125036606563 0 0 0</pose>
			<axis>
				<xyz>-0.25000000000000516 -0.8660254037844385 0.43301270189221686</xyz>
				<limit>
					<lower>-0.3141592653589793</lower>
					<upper>0.3141592653589793</upper>
				</limit>
				<use_parent_model_frame>0</use_parent_model_frame>
			</axis>
		</joint>
		<joint name="joint1_little" type="revolute">
			<parent>little_limb1</parent>
			<child>little_limb2</child>
			<pose frame="">0.0920186523985582 0.005500000000000616 0.0322861671747858 0 0 0</pose>
			<axis>
				<xyz>0.8660254037844395 -7.969319648637452e-15 0.49999999999999606</xyz>
				<limit>
					<lower>-1.9198621771937625</lower>
					<upper>-0.0</upper>
				</limit>
				<use_parent_model_frame>0</use_parent_model_frame>
			</axis>
		</joint>
		<joint name="joint2_little" type="revolute">
			<parent>little_limb2</parent>
			<child>little_limb3</child>
			<pose frame="">0.11584047444582499 0.004000000000000689 0.03035041104508707 0 0 0</pose>
			<axis>
				<xyz>0.8660254037844395 -7.969319648637452e-15 0.49999999999999606</xyz>
				<limit>
					<lower>-1.2217304763960306</lower>
					<upper>-0.0</upper>
				</limit>
				<use_parent_model_frame>0</use_parent_model_frame>
			</axis>
		</joint>
		<joint name="joint0_index" type="revolute">
			<parent>index_limb0</parent>
			<child>index_limb1</child>
			<pose frame="">-0.060865219882230155 0.0023349364905388375 -0.0003720428773710793 0 0 0</pose>
			<axis>
				<xyz>0.12940952255125512 -0.866025403784444 0.48296291314453815</xyz>
				<limit>
					<lower>-0.3141592653589793</lower>
					<upper>0.3141592653589793</upper>
				</limit>
				<use_parent_model_frame>0</use_parent_model_frame>
			</axis>
		</joint>
		<joint name="joint1_index" type="revolute">
			<parent>index_limb1</parent>
			<child>index_limb2</child>
			<pose frame="">-0.10592310167534055 0.00549999999999945 -0.004530665643208689 0 0 0</pose>
			<axis>
				<xyz>0.9659258262890686 -1.2698175844150228e-15 -0.25881904510251696</xyz>
				<limit>
					<lower>-1.9198621771937625</lower>
					<upper>-0.0</upper>
				</limit>
				<use_parent_model_frame>0</use_parent_model_frame>
			</axis>
		</joint>
		<joint name="joint2_index" type="revolute">
			<parent>index_limb2</parent>
			<child>index_limb3</child>
			<pose frame="">-0.12553442678815066 0.003999999999999405 -0.013342460852465763 0 0 0</pose>
			<axis>
				<xyz>0.9659258262890686 -1.2698175844150228e-15 -0.25881904510251696</xyz>
				<limit>
					<lower>-1.2217304763960306</lower>
					<upper>-0.0</upper>
				</limit>
				<use_parent_model_frame>0</use_parent_model_frame>
			</axis>
		</joint>
		<joint name="joint0_thumb" type="revolute">
			<parent>thumb_limb0</parent>
			<child>thumb_limb1</child>
			<pose frame="">0.0006048603824202736 -0.010843110243514791 0.0124161374456855 0 0 0</pose>
			<axis>
				<xyz>-0.810092587300987 0.09449111825231682 0.5786375623578539</xyz>
				<limit>
					<lower>-0.3141592653589793</lower>
					<upper>0.3141592653589793</upper>
				</limit>
				<use_parent_model_frame>0</use_parent_model_frame>
			</axis>
		</joint>
		<joint name="joint1_thumb" type="revolute">
			<parent>thumb_limb1</parent>
			<child>thumb_limb2</child>
			<pose frame="">0.005608924006929495 -0.00812359451241547 0.014664884586929787 0 0 0</pose>
			<axis>
				<xyz>-0.48077872093720364 -0.6719147712873027 -0.5633669866258815</xyz>
				<limit>
					<lower>-1.9198621771937625</lower>
					<upper>-0.0</upper>
				</limit>
				<use_parent_model_frame>0</use_parent_model_frame>
			</axis>
		</joint>
		<joint name="joint2_thumb" type="revolute">
			<parent>thumb_limb2</parent>
			<child>thumb_limb3</child>
			<pose frame="">0.004277737429957331 -0.004886481590238177 0.009277529841299276 0 0 0</pose>
			<axis>
				<xyz>-0.48077872093720364 -0.6719147712873027 -0.5633669866258815</xyz>
				<limit>
					<lower>-1.2217304763960306</lower>
					<upper>-0.0</upper>
				</limit>
				<use_parent_model_frame>0</use_parent_model_frame>
			</axis>
		</joint>
		<plugin filename="libmyomuscle_plugin.so" name="myomuscle_plugin"/>
	</model>
</sdf>
