<?xml version="1.0" ?>
<sdf version="1.6">
	<model name="LeftHand">
		<link name="palm">
			<pose frame="">0.0 0.0 0.0 0.0 -0.0 0.0</pose>
			<inertial>
				<pose frame="">0.0 0.0 0.0 0 0 0</pose>
				<mass>10</mass>
				<inertia>
					<ixx>0.10370503908183999</ixx>
					<ixy>1.3379102641482672e-05</ixy>
					<ixz>-0.001620060262024168</ixz>
					<iyy>0.10358802097720089</iyy>
					<iyz>0.0001701705408159953</iyz>
					<izz>0.16582894798853867</izz>
				</inertia>
			</inertial>
			<collision name="palm_collision">
				<geometry>
					<mesh>
						<uri>model://LeftHand/meshes/CAD/palm.stl</uri>
						<scale>0.001 0.001 0.001</scale>
					</mesh>
				</geometry>
			</collision>
			<visual name="palm_visual">
				<geometry>
					<mesh>
						<uri>model://LeftHand/meshes/CAD/palm.stl</uri>
						<scale>0.001 0.001 0.001</scale>
					</mesh>
				</geometry>
			</visual>
		</link>
		<link name="ring_limb0">
			<pose frame="">0.0 0.0 0.0 0.0 -0.0 0.0</pose>
			<inertial>
				<pose frame="">0.0 0.0 0.0 0 0 0</pose>
				<mass>0.00001</mass>
				<inertia>
					<ixx>5.70518648194983e-06</ixx>
					<ixy>-4.3240878793659625e-08</ixy>
					<ixz>2.6419370768032044e-07</ixz>
					<iyy>5.847829902048378e-06</iyy>
					<iyz>9.311486939256404e-07</iyz>
					<izz>1.7250855397973145e-07</izz>
				</inertia>
			</inertial>
			<collision name="ring_limb0_collision">
				<geometry>
					<mesh>
						<uri>model://LeftHand/meshes/CAD/ring_limb0.stl</uri>
						<scale>0.001 0.001 0.001</scale>
					</mesh>
				</geometry>
			</collision>
			<visual name="ring_limb0_visual">
				<geometry>
					<mesh>
						<uri>model://LeftHand/meshes/CAD/ring_limb0.stl</uri>
						<scale>0.001 0.001 0.001</scale>
					</mesh>
				</geometry>
			</visual>
		</link>
		<link name="ring_limb1">
			<pose frame="">0.0 0.0 0.0 0.0 -0.0 0.0</pose>
			<inertial>
				<pose frame="">0.0 0.0 0.0 0 0 0</pose>
				<mass>0.00001</mass>
				<inertia>
					<ixx>7.265402554551641e-05</ixx>
					<ixy>4.4359390134379255e-07</ixy>
					<ixz>-2.3121848483359178e-06</ixz>
					<iyy>7.48581900470118e-05</iyy>
					<iyz>1.3127899937399327e-05</iyz>
					<izz>2.641817678600695e-06</izz>
				</inertia>
			</inertial>
			<collision name="ring_limb1_collision">
				<geometry>
					<mesh>
						<uri>model://LeftHand/meshes/CAD/ring_limb1.stl</uri>
						<scale>0.001 0.001 0.001</scale>
					</mesh>
				</geometry>
			</collision>
			<visual name="ring_limb1_visual">
				<geometry>
					<mesh>
						<uri>model://LeftHand/meshes/CAD/ring_limb1.stl</uri>
						<scale>0.001 0.001 0.001</scale>
					</mesh>
				</geometry>
			</visual>
		</link>
		<link name="ring_limb2">
			<pose frame="">0.0 0.0 0.0 0.0 -0.0 0.0</pose>
			<inertial>
				<pose frame="">0.0 0.0 0.0 0 0 0</pose>
				<mass>0.00001</mass>
				<inertia>
					<ixx>4.952114754535521e-05</ixx>
					<ixy>1.034955142248116e-06</ixy>
					<ixz>-5.19082425125159e-06</ixz>
					<iyy>5.088851411033829e-05</iyy>
					<iyz>9.72763536461381e-06</iyz>
					<izz>2.5202897538578307e-06</izz>
				</inertia>
			</inertial>
			<collision name="ring_limb2_collision">
				<geometry>
					<mesh>
						<uri>model://LeftHand/meshes/CAD/ring_limb2.stl</uri>
						<scale>0.001 0.001 0.001</scale>
					</mesh>
				</geometry>
			</collision>
			<visual name="ring_limb2_visual">
				<geometry>
					<mesh>
						<uri>model://LeftHand/meshes/CAD/ring_limb2.stl</uri>
						<scale>0.001 0.001 0.001</scale>
					</mesh>
				</geometry>
			</visual>
		</link>
		<link name="ring_limb3">
			<pose frame="">0.0 0.0 0.0 0.0 -0.0 0.0</pose>
			<inertial>
				<pose frame="">0.0 0.0 0.0 0 0 0</pose>
				<mass>0.00001</mass>
				<inertia>
					<ixx>2.7724203122666813e-05</ixx>
					<ixy>8.04556350827875e-07</ixy>
					<ixz>-3.8808069043846705e-06</ixz>
					<iyy>2.833338006682704e-05</iyy>
					<iyz>5.628302424917292e-06</iyz>
					<izz>1.727876470678124e-06</izz>
				</inertia>
			</inertial>
			<collision name="ring_limb3_collision">
				<geometry>
					<mesh>
						<uri>model://LeftHand/meshes/CAD/ring_limb3.stl</uri>
						<scale>0.001 0.001 0.001</scale>
					</mesh>
				</geometry>
			</collision>
			<visual name="ring_limb3_visual">
				<geometry>
					<mesh>
						<uri>model://LeftHand/meshes/CAD/ring_limb3.stl</uri>
						<scale>0.001 0.001 0.001</scale>
					</mesh>
				</geometry>
			</visual>
		</link>
		<link name="little_limb0">
			<pose frame="">0.0 0.0 0.0 0.0 -0.0 0.0</pose>
			<inertial>
				<pose frame="">0.0 0.0 0.0 0 0 0</pose>
				<mass>0.00001</mass>
				<inertia>
					<ixx>4.35558794133777e-06</ixx>
					<ixy>-7.320318351005178e-08</ixy>
					<ixz>2.2075537435390357e-07</ixz>
					<iyy>4.8245236479853865e-06</iyy>
					<iyz>1.439122803994224e-06</iyz>
					<izz>4.961439548441114e-07</izz>
				</inertia>
			</inertial>
			<collision name="little_limb0_collision">
				<geometry>
					<mesh>
						<uri>model://LeftHand/meshes/CAD/little_limb0.stl</uri>
						<scale>0.001 0.001 0.001</scale>
					</mesh>
				</geometry>
			</collision>
			<visual name="little_limb0_visual">
				<geometry>
					<mesh>
						<uri>model://LeftHand/meshes/CAD/little_limb0.stl</uri>
						<scale>0.001 0.001 0.001</scale>
					</mesh>
				</geometry>
			</visual>
		</link>
		<link name="little_limb1">
			<pose frame="">0.0 0.0 0.0 0.0 -0.0 0.0</pose>
			<inertial>
				<pose frame="">0.0 0.0 0.0 0 0 0</pose>
				<mass>0.00001</mass>
				<inertia>
					<ixx>5.797477920729646e-05</ixx>
					<ixy>-7.269326799885393e-07</ixy>
					<ixz>1.955102195820986e-06</ixz>
					<iyy>6.616226449855414e-05</iyy>
					<iyz>2.1814487470731944e-05</iyz>
					<izz>8.399312059509464e-06</izz>
				</inertia>
			</inertial>
			<collision name="little_limb1_collision">
				<geometry>
					<mesh>
						<uri>model://LeftHand/meshes/CAD/little_limb1.stl</uri>
						<scale>0.001 0.001 0.001</scale>
					</mesh>
				</geometry>
			</collision>
			<visual name="little_limb1_visual">
				<geometry>
					<mesh>
						<uri>model://LeftHand/meshes/CAD/little_limb1.stl</uri>
						<scale>0.001 0.001 0.001</scale>
					</mesh>
				</geometry>
			</visual>
		</link>
		<link name="little_limb2">
			<pose frame="">0.0 0.0 0.0 0.0 -0.0 0.0</pose>
			<inertial>
				<pose frame="">0.0 0.0 0.0 0 0 0</pose>
				<mass>0.00001</mass>
				<inertia>
					<ixx>3.935298315950893e-05</ixx>
					<ixy>-3.5754285677154177e-07</ixy>
					<ixz>8.565151683906668e-07</ixz>
					<iyy>4.6267387944779e-05</iyy>
					<iyz>1.650781571744048e-05</iyz>
					<izz>6.973161106688865e-06</izz>
				</inertia>
			</inertial>
			<collision name="little_limb2_collision">
				<geometry>
					<mesh>
						<uri>model://LeftHand/meshes/CAD/little_limb2.stl</uri>
						<scale>0.001 0.001 0.001</scale>
					</mesh>
				</geometry>
			</collision>
			<visual name="little_limb2_visual">
				<geometry>
					<mesh>
						<uri>model://LeftHand/meshes/CAD/little_limb2.stl</uri>
						<scale>0.001 0.001 0.001</scale>
					</mesh>
				</geometry>
			</visual>
		</link>
		<link name="little_limb3">
			<pose frame="">0.0 0.0 0.0 0.0 -0.0 0.0</pose>
			<inertial>
				<pose frame="">0.0 0.0 0.0 0 0 0</pose>
				<mass>0.00001</mass>
				<inertia>
					<ixx>2.2547791767825223e-05</ixx>
					<ixy>-1.4909623965506253e-07</ixy>
					<ixz>3.3963132070903805e-07</ixz>
					<iyy>2.6907536710997072e-05</iyy>
					<iyz>9.91849528260401e-06</iyz>
					<izz>4.375350062641281e-06</izz>
				</inertia>
			</inertial>
			<collision name="little_limb3_collision">
				<geometry>
					<mesh>
						<uri>model://LeftHand/meshes/CAD/little_limb3.stl</uri>
						<scale>0.001 0.001 0.001</scale>
					</mesh>
				</geometry>
			</collision>
			<visual name="little_limb3_visual">
				<geometry>
					<mesh>
						<uri>model://LeftHand/meshes/CAD/little_limb3.stl</uri>
						<scale>0.001 0.001 0.001</scale>
					</mesh>
				</geometry>
			</visual>
		</link>
		<link name="thumb_limb0">
			<pose frame="">0.0 0.0 0.0 0.0 -0.0 0.0</pose>
			<inertial>
				<pose frame="">0.0 0.0 0.0 0 0 0</pose>
				<mass>0.00001</mass>
				<inertia>
					<ixx>2.1819939213634567e-06</ixx>
					<ixy>2.630578155479799e-07</ixy>
					<ixz>7.069522131995127e-07</ixz>
					<iyy>2.1842368765602027e-06</iyy>
					<iyz>-7.13718022745526e-07</iyz>
					<izz>5.348246264645511e-07</izz>
				</inertia>
			</inertial>
			<collision name="thumb_limb0_collision">
				<geometry>
					<mesh>
						<uri>model://LeftHand/meshes/CAD/thumb_limb0.stl</uri>
						<scale>0.001 0.001 0.001</scale>
					</mesh>
				</geometry>
			</collision>
			<visual name="thumb_limb0_visual">
				<geometry>
					<mesh>
						<uri>model://LeftHand/meshes/CAD/thumb_limb0.stl</uri>
						<scale>0.001 0.001 0.001</scale>
					</mesh>
				</geometry>
			</visual>
		</link>
		<link name="thumb_limb1">
			<pose frame="">0.0 0.0 0.0 0.0 -0.0 0.0</pose>
			<inertial>
				<pose frame="">0.0 0.0 0.0 0 0 0</pose>
				<mass>0.00001</mass>
				<inertia>
					<ixx>3.562251426612123e-05</ixx>
					<ixy>3.2713821883161312e-06</ixy>
					<ixz>1.186626739400163e-05</ixz>
					<iyy>3.349046496438803e-05</iyy>
					<iyz>-8.569428970596472e-06</iyz>
					<izz>7.025492328146263e-06</izz>
				</inertia>
			</inertial>
			<collision name="thumb_limb1_collision">
				<geometry>
					<mesh>
						<uri>model://LeftHand/meshes/CAD/thumb_limb1.stl</uri>
						<scale>0.001 0.001 0.001</scale>
					</mesh>
				</geometry>
			</collision>
			<visual name="thumb_limb1_visual">
				<geometry>
					<mesh>
						<uri>model://LeftHand/meshes/CAD/thumb_limb1.stl</uri>
						<scale>0.001 0.001 0.001</scale>
					</mesh>
				</geometry>
			</visual>
		</link>
		<link name="thumb_limb2">
			<pose frame="">0.0 0.0 0.0 0.0 -0.0 0.0</pose>
			<inertial>
				<pose frame="">0.0 0.0 0.0 0 0 0</pose>
				<mass>0.00001</mass>
				<inertia>
					<ixx>2.9751055416704578e-05</ixx>
					<ixy>2.0744726107071765e-06</ixy>
					<ixz>1.0102131260703117e-05</ixz>
					<iyy>2.688038357001603e-05</iyy>
					<iyz>-5.294534109863701e-06</iyz>
					<izz>5.068304277953946e-06</izz>
				</inertia>
			</inertial>
			<collision name="thumb_limb2_collision">
				<geometry>
					<mesh>
						<uri>model://LeftHand/meshes/CAD/thumb_limb2.stl</uri>
						<scale>0.001 0.001 0.001</scale>
					</mesh>
				</geometry>
			</collision>
			<visual name="thumb_limb2_visual">
				<geometry>
					<mesh>
						<uri>model://LeftHand/meshes/CAD/thumb_limb2.stl</uri>
						<scale>0.001 0.001 0.001</scale>
					</mesh>
				</geometry>
			</visual>
		</link>
		<link name="thumb_limb3">
			<pose frame="">0.0 0.0 0.0 0.0 -0.0 0.0</pose>
			<inertial>
				<pose frame="">0.0 0.0 0.0 0 0 0</pose>
				<mass>0.00001</mass>
				<inertia>
					<ixx>1.8506572411630314e-05</ixx>
					<ixy>1.119158034675447e-06</ixy>
					<ixz>6.337788929721548e-06</ixz>
					<iyy>1.6493234104167078e-05</iyy>
					<iyz>-2.8237192588854132e-06</iyz>
					<izz>3.0153733036797124e-06</izz>
				</inertia>
			</inertial>
			<collision name="thumb_limb3_collision">
				<geometry>
					<mesh>
						<uri>model://LeftHand/meshes/CAD/thumb_limb3.stl</uri>
						<scale>0.001 0.001 0.001</scale>
					</mesh>
				</geometry>
			</collision>
			<visual name="thumb_limb3_visual">
				<geometry>
					<mesh>
						<uri>model://LeftHand/meshes/CAD/thumb_limb3.stl</uri>
						<scale>0.001 0.001 0.001</scale>
					</mesh>
				</geometry>
			</visual>
		</link>
		<link name="index_limb0">
			<pose frame="">0.0 0.0 0.0 0.0 -0.0 0.0</pose>
			<inertial>
				<pose frame="">0.0 0.0 0.0 0 0 0</pose>
				<mass>0.00001</mass>
				<inertia>
					<ixx>5.696396315690575e-06</ixx>
					<ixy>4.352364376914482e-08</ixy>
					<ixz>2.526333252288325e-07</ixz>
					<iyy>5.85656215849215e-06</iyy>
					<iyz>-9.786861419484764e-07</iyz>
					<izz>1.8738275226371254e-07</izz>
				</inertia>
			</inertial>
			<collision name="index_limb0_collision">
				<geometry>
					<mesh>
						<uri>model://LeftHand/meshes/CAD/index_limb0.stl</uri>
						<scale>0.001 0.001 0.001</scale>
					</mesh>
				</geometry>
			</collision>
			<visual name="index_limb0_visual">
				<geometry>
					<mesh>
						<uri>model://LeftHand/meshes/CAD/index_limb0.stl</uri>
						<scale>0.001 0.001 0.001</scale>
					</mesh>
				</geometry>
			</visual>
		</link>
		<link name="index_limb1">
			<pose frame="">0.0 0.0 0.0 0.0 -0.0 0.0</pose>
			<inertial>
				<pose frame="">0.0 0.0 0.0 0 0 0</pose>
				<mass>0.00001</mass>
				<inertia>
					<ixx>7.533171793117199e-05</ixx>
					<ixy>4.492241461728259e-07</ixy>
					<ixz>2.3921493926142674e-06</ixz>
					<iyy>7.796512931418711e-05</iyy>
					<iyz>-1.4265341307765165e-05</iyz>
					<izz>2.8656360821360042e-06</izz>
				</inertia>
			</inertial>
			<collision name="index_limb1_collision">
				<geometry>
					<mesh>
						<uri>model://LeftHand/meshes/CAD/index_limb1.stl</uri>
						<scale>0.001 0.001 0.001</scale>
					</mesh>
				</geometry>
			</collision>
			<visual name="index_limb1_visual">
				<geometry>
					<mesh>
						<uri>model://LeftHand/meshes/CAD/index_limb1.stl</uri>
						<scale>0.001 0.001 0.001</scale>
					</mesh>
				</geometry>
			</visual>
		</link>
		<link name="index_limb2">
			<pose frame="">0.0 0.0 0.0 0.0 -0.0 0.0</pose>
			<inertial>
				<pose frame="">0.0 0.0 0.0 0 0 0</pose>
				<mass>0.00001</mass>
				<inertia>
					<ixx>5.150513740195316e-05</ixx>
					<ixy>2.2111491965128255e-07</ixy>
					<ixz>1.0773047560158625e-06</ixz>
					<iyy>5.366828680317941e-05</iyy>
					<iyz>-1.0607817002180134e-05</iyz>
					<izz>2.2301760846463064e-06</izz>
				</inertia>
			</inertial>
			<collision name="index_limb2_collision">
				<geometry>
					<mesh>
						<uri>model://LeftHand/meshes/CAD/index_limb2.stl</uri>
						<scale>0.001 0.001 0.001</scale>
					</mesh>
				</geometry>
			</collision>
			<visual name="index_limb2_visual">
				<geometry>
					<mesh>
						<uri>model://LeftHand/meshes/CAD/index_limb2.stl</uri>
						<scale>0.001 0.001 0.001</scale>
					</mesh>
				</geometry>
			</visual>
		</link>
		<link name="index_limb3">
			<pose frame="">0.0 0.0 0.0 0.0 -0.0 0.0</pose>
			<inertial>
				<pose frame="">0.0 0.0 0.0 0 0 0</pose>
				<mass>0.00001</mass>
				<inertia>
					<ixx>2.89101342305928e-05</ixx>
					<ixy>9.13166725961899e-08</ixy>
					<ixz>4.275517346457047e-07</ixz>
					<iyy>3.0226416068812014e-05</iyy>
					<iyz>-6.183306903236268e-06</iyz>
					<izz>1.3343173846196303e-06</izz>
				</inertia>
			</inertial>
			<collision name="index_limb3_collision">
				<geometry>
					<mesh>
						<uri>model://LeftHand/meshes/CAD/index_limb3.stl</uri>
						<scale>0.001 0.001 0.001</scale>
					</mesh>
				</geometry>
			</collision>
			<visual name="index_limb3_visual">
				<geometry>
					<mesh>
						<uri>model://LeftHand/meshes/CAD/index_limb3.stl</uri>
						<scale>0.001 0.001 0.001</scale>
					</mesh>
				</geometry>
			</visual>
		</link>
		<link name="middle_limb0">
			<pose frame="">0.0 0.0 0.0 0.0 -0.0 0.0</pose>
			<inertial>
				<pose frame="">0.0 0.0 0.0 0 0 0</pose>
				<mass>0.00001</mass>
				<inertia>
					<ixx>6.220931215255119e-06</ixx>
					<ixy>-2.9280517172989784e-12</ixy>
					<ixz>2.6401612367372733e-07</ixz>
					<iyy>6.21241882682548e-06</iyy>
					<iyz>4.165012047708736e-11</iyz>
					<izz>1.869819424248227e-08</izz>
				</inertia>
			</inertial>
			<collision name="middle_limb0_collision">
				<geometry>
					<mesh>
						<uri>model://LeftHand/meshes/CAD/middle_limb0.stl</uri>
						<scale>0.001 0.001 0.001</scale>
					</mesh>
				</geometry>
			</collision>
			<visual name="middle_limb0_visual">
				<geometry>
					<mesh>
						<uri>model://LeftHand/meshes/CAD/middle_limb0.stl</uri>
						<scale>0.001 0.001 0.001</scale>
					</mesh>
				</geometry>
			</visual>
		</link>
		<link name="middle_limb1">
			<pose frame="">0.0 0.0 0.0 0.0 -0.0 0.0</pose>
			<inertial>
				<pose frame="">0.0 0.0 0.0 0 0 0</pose>
				<mass>0.00001</mass>
				<inertia>
					<ixx>8.096748853092092e-05</ixx>
					<ixy>-1.010033148855116e-12</ixy>
					<ixz>2.3057982785490035e-06</ixz>
					<iyy>8.089935723228345e-05</iyy>
					<iyz>1.5570927857065174e-11</iyz>
					<izz>1.4238044463764945e-07</izz>
				</inertia>
			</inertial>
			<collision name="middle_limb1_collision">
				<geometry>
					<mesh>
						<uri>model://LeftHand/meshes/CAD/middle_limb1.stl</uri>
						<scale>0.001 0.001 0.001</scale>
					</mesh>
				</geometry>
			</collision>
			<visual name="middle_limb1_visual">
				<geometry>
					<mesh>
						<uri>model://LeftHand/meshes/CAD/middle_limb1.stl</uri>
						<scale>0.001 0.001 0.001</scale>
					</mesh>
				</geometry>
			</visual>
		</link>
		<link name="middle_limb2">
			<pose frame="">0.0 0.0 0.0 0.0 -0.0 0.0</pose>
			<inertial>
				<pose frame="">0.0 0.0 0.0 0 0 0</pose>
				<mass>0.00001</mass>
				<inertia>
					<ixx>5.577988183128855e-05</ixx>
					<ixy>1.1170535500077128e-12</ixy>
					<ixz>1.0301843374132112e-06</ixz>
					<iyy>5.575946760263562e-05</iyy>
					<iyz>-3.9783898817763056e-11</iyz>
					<izz>3.9477655466014145e-08</izz>
				</inertia>
			</inertial>
			<collision name="middle_limb2_collision">
				<geometry>
					<mesh>
						<uri>model://LeftHand/meshes/CAD/middle_limb2.stl</uri>
						<scale>0.001 0.001 0.001</scale>
					</mesh>
				</geometry>
			</collision>
			<visual name="middle_limb2_visual">
				<geometry>
					<mesh>
						<uri>model://LeftHand/meshes/CAD/middle_limb2.stl</uri>
						<scale>0.001 0.001 0.001</scale>
					</mesh>
				</geometry>
			</visual>
		</link>
		<link name="middle_limb3">
			<pose frame="">0.0 0.0 0.0 0.0 -0.0 0.0</pose>
			<inertial>
				<pose frame="">0.0 0.0 0.0 0 0 0</pose>
				<mass>0.00001</mass>
				<inertia>
					<ixx>3.126942660218029e-05</ixx>
					<ixy>9.770606142305848e-14</ixy>
					<ixz>4.0004172461025477e-07</ixz>
					<iyy>3.126385415013449e-05</iyy>
					<iyz>-3.760132469602895e-12</iyz>
					<izz>1.0032349759270294e-08</izz>
				</inertia>
			</inertial>
			<collision name="middle_limb3_collision">
				<geometry>
					<mesh>
						<uri>model://LeftHand/meshes/CAD/middle_limb3.stl</uri>
						<scale>0.001 0.001 0.001</scale>
					</mesh>
				</geometry>
			</collision>
			<visual name="middle_limb3_visual">
				<geometry>
					<mesh>
						<uri>model://LeftHand/meshes/CAD/middle_limb3.stl</uri>
						<scale>0.001 0.001 0.001</scale>
					</mesh>
				</geometry>
			</visual>
		</link>
		<joint name="ring0" type="revolute">
			<parent>palm</parent>
			<child>ring_limb0</child>
			<pose frame="">0.011822362340004855 0.005000000000000015 -0.11795045711084329 0 0 0</pose>
			<axis>
				<xyz>-0.9659258262890762 -4.904700770684754e-16 -0.25881904510252224</xyz>
				<limit>
					<lower>-0.3490658503988659</lower>
					<upper>1.2217304763960306</upper>
				</limit>
				<use_parent_model_frame>0</use_parent_model_frame>
			</axis>
		</joint>
		<joint name="index0" type="revolute">
			<parent>palm</parent>
			<child>index_limb0</child>
			<pose frame="">-0.027311249734341195 0.004999999999999993 -0.11406817143430555 0 0 0</pose>
			<axis>
				<xyz>-0.9659258262890775 -5.479394496853379e-16 0.2588190451025223</xyz>
				<limit>
					<lower>-0.3490658503988659</lower>
					<upper>1.2217304763960306</upper>
				</limit>
				<use_parent_model_frame>0</use_parent_model_frame>
			</axis>
		</joint>
		<joint name="thumb0" type="revolute">
			<parent>palm</parent>
			<child>thumb_limb0</child>
			<pose frame="">-0.022427942673564766 0.03156434425758929 -0.06491294267356412 0 0 0</pose>
			<axis>
				<xyz>0.3535533905932764 0.8660254037844375 0.3535533905932753</xyz>
				<limit>
					<lower>-0.3490658503988659</lower>
					<upper>1.2217304763960306</upper>
				</limit>
				<use_parent_model_frame>0</use_parent_model_frame>
			</axis>
		</joint>
		<joint name="little0" type="revolute">
			<parent>palm</parent>
			<child>little_limb0</child>
			<pose frame="">0.0273164518843275 0.005000000000000023 -0.10516450794994985 0 0 0</pose>
			<axis>
				<xyz>0.866025403784445 4.0999510464529535e-16 0.5000000000000029</xyz>
				<limit>
					<lower>-0.0</lower>
					<upper>-0.0</upper>
				</limit>
				<use_parent_model_frame>0</use_parent_model_frame>
			</axis>
		</joint>
		<joint name="middle0" type="revolute">
			<parent>palm</parent>
			<child>middle_limb0</child>
			<pose frame="">0.004999999999999992 0.005000000000000012 -0.12124999999999996 0 0 0</pose>
			<axis>
				<xyz>-1.0000000000000089 9.930890339105123e-17 -1.4559772246072405e-17</xyz>
				<limit>
					<lower>-0.3490658503988659</lower>
					<upper>1.2217304763960306</upper>
				</limit>
				<use_parent_model_frame>0</use_parent_model_frame>
			</axis>
		</joint>
		<joint name="little1" type="revolute">
			<parent>little_limb0</parent>
			<child>little_limb1</child>
			<pose frame="">0.03306164241271076 0.002401923788646701 -0.10011546984427323 0 0 0</pose>
			<axis>
				<xyz>-0.25000000000000516 -0.8660254037844385 0.43301270189221686</xyz>
				<limit>
					<lower>-0.3141592653589793</lower>
					<upper>0.3141592653589793</upper>
				</limit>
				<use_parent_model_frame>0</use_parent_model_frame>
			</axis>
		</joint>
		<joint name="little2" type="revolute">
			<parent>little_limb1</parent>
			<child>little_limb2</child>
			<pose frame="">0.05461100269189609 0.005066987298107553 -0.14844005671842964 0 0 0</pose>
			<axis>
				<xyz>0.8660254037844395 -7.969319648637452e-15 0.49999999999999606</xyz>
				<limit>
					<lower>0.0</lower>
					<upper>1.9198621771937625</upper>
				</limit>
				<use_parent_model_frame>0</use_parent_model_frame>
			</axis>
		</joint>
		<joint name="little3" type="revolute">
			<parent>little_limb2</parent>
			<child>little_limb3</child>
			<pose frame="">0.07178491579757272 0.0035669872981074963 -0.17518614678223457 0 0 0</pose>
			<axis>
				<xyz>0.8660254037844395 -7.969319648637452e-15 0.49999999999999606</xyz>
				<limit>
					<lower>0.0</lower>
					<upper>1.2217304763960306</upper>
				</limit>
				<use_parent_model_frame>0</use_parent_model_frame>
			</axis>
		</joint>
		<joint name="ring1" type="revolute">
			<parent>ring_limb0</parent>
			<child>ring_limb1</child>
			<pose frame="">0.01847200536335035 0.0030716371709403347 -0.11378948793749291 0 0 0</pose>
			<axis>
				<xyz>-0.198266891274149 -0.6427876096865431 0.7399421116938513</xyz>
				<limit>
					<lower>-0.3141592653589793</lower>
					<upper>0.3141592653589793</upper>
				</limit>
				<use_parent_model_frame>0</use_parent_model_frame>
			</axis>
		</joint>
		<joint name="ring2" type="revolute">
			<parent>ring_limb1</parent>
			<child>ring_limb2</child>
			<pose frame="">0.026194272777333615 -0.012422832357806682 -0.16385975045447154 0 0 0</pose>
			<axis>
				<xyz>0.9659258262890722 -8.101158632811689e-16 0.25881904510252285</xyz>
				<limit>
					<lower>0</lower>
					<upper>1.9198621771937625</upper>
				</limit>
				<use_parent_model_frame>0</use_parent_model_frame>
			</axis>
		</joint>
		<joint name="ring3" type="revolute">
			<parent>ring_limb2</parent>
			<child>ring_limb3</child>
			<pose frame="">0.03523224723478227 -0.02469142533453978 -0.1917943753694453 0 0 0</pose>
			<axis>
				<xyz>0.9659258262890722 -8.101158632811689e-16 0.25881904510252285</xyz>
				<limit>
					<lower>0.0</lower>
					<upper>1.2217304763960306</upper>
				</limit>
				<use_parent_model_frame>0</use_parent_model_frame>
			</axis>
		</joint>
		<joint name="thumb1" type="revolute">
			<parent>thumb_limb0</parent>
			<child>thumb_limb1</child>
			<pose frame="">-0.027104824571266863 0.02530538152483692 -0.06611799919711926 0 0 0</pose>
			<axis>
				<xyz>0.8100925873009869 -0.09449111825231679 -0.5786375623578539</xyz>
				<limit>
					<lower>-0.3141592653589793</lower>
					<upper>0.3141592653589793</upper>
				</limit>
				<use_parent_model_frame>0</use_parent_model_frame>
			</axis>
		</joint>
		<joint name="thumb2" type="revolute">
			<parent>thumb_limb1</parent>
			<child>thumb_limb2</child>
			<pose frame="">-0.022667342281404462 0.04908655483319237 -0.11325087239104441 0 0 0</pose>
			<axis>
				<xyz>-0.35355339059328617 -0.8660254037844398 -0.35355339059326946</xyz>
				<limit>
					<lower>0.0</lower>
					<upper>1.9198621771937625</upper>
				</limit>
				<use_parent_model_frame>0</use_parent_model_frame>
			</axis>
		</joint>
		<joint name="thumb3" type="revolute">
			<parent>thumb_limb2</parent>
			<child>thumb_limb3</child>
			<pose frame="">-0.02460079388733464 0.060278784507471254 -0.14297531325825383 0 0 0</pose>
			<axis>
				<xyz>-0.3535533905932865 -0.8660254037844414 -0.3535533905932668</xyz>
				<limit>
					<lower>0.0</lower>
					<upper>1.2217304763960306</upper>
				</limit>
				<use_parent_model_frame>0</use_parent_model_frame>
			</axis>
		</joint>
		<joint name="middle1" type="revolute">
			<parent>middle_limb0</parent>
			<child>middle_limb1</child>
			<pose frame="">0.0 0.002401923788646685 -0.11975 0 0 0</pose>
			<axis>
				<xyz>6.842277657836021e-49 -0.8660254037844388 0.5</xyz>
				<limit>
					<lower>-0.6108652381980153</lower>
					<upper>0.6108652381980153</upper>
				</limit>
				<use_parent_model_frame>0</use_parent_model_frame>
			</axis>
		</joint>
		<joint name="middle2" type="revolute">
			<parent>middle_limb1</parent>
			<child>middle_limb2</child>
			<pose frame="">-0.0055000000000000005 0.00506698729810778 -0.172375 0 0 0</pose>
			<axis>
				<xyz>1.0 0.0 0.0</xyz>
				<limit>
					<lower>0.0</lower>
					<upper>1.9198621771937625</upper>
				</limit>
				<use_parent_model_frame>0</use_parent_model_frame>
			</axis>
		</joint>
		<joint name="middle3" type="revolute">
			<parent>middle_limb2</parent>
			<child>middle_limb3</child>
			<pose frame="">-0.004 0.003566987298107776 -0.20412475000000002 0 0 0</pose>
			<axis>
				<xyz>1.0 0.0 0.0</xyz>
				<limit>
					<lower>0.0</lower>
					<upper>1.2217304763960306</upper>
				</limit>
				<use_parent_model_frame>0</use_parent_model_frame>
			</axis>
		</joint>
		<joint name="index1" type="revolute">
			<parent>index_limb0</parent>
			<child>index_limb1</child>
			<pose frame="">-0.01974328223079509 0.0028349364905388918 -0.11480190698971318 0 0 0</pose>
			<axis>
				<xyz>-0.12940952255125399 0.8660254037844273 -0.482962913144532</xyz>
				<limit>
					<lower>-0.3141592653589793</lower>
					<upper>0.3141592653589793</upper>
				</limit>
				<use_parent_model_frame>0</use_parent_model_frame>
			</axis>
		</joint>
		<joint name="index2" type="revolute">
			<parent>index_limb1</parent>
			<child>index_limb2</child>
			<pose frame="">-0.03865681509552307 0.005370096189431485 -0.1641378044131407 0 0 0</pose>
			<axis>
				<xyz>0.9659258262890686 -8.975054892207292e-16 -0.25881904510251696</xyz>
				<limit>
					<lower>0.0</lower>
					<upper>1.9198621771937625</upper>
				</limit>
				<use_parent_model_frame>0</use_parent_model_frame>
			</axis>
		</joint>
		<joint name="index3" type="revolute">
			<parent>index_limb2</parent>
			<child>index_limb3</child>
			<pose frame="">-0.04542536633333317 0.0038700961894312714 -0.1951939364840159 0 0 0</pose>
			<axis>
				<xyz>0.9659258262890686 -1.2698175844150228e-15 -0.25881904510251696</xyz>
				<limit>
					<lower>0.0</lower>
					<upper>1.2217304763960306</upper>
				</limit>
				<use_parent_model_frame>0</use_parent_model_frame>
			</axis>
		</joint>
		<plugin filename="libfinger_plugin.so" name="finger_plugin"/>
	</model>
</sdf>
