<?xml version="1.0" ?>
<sdf version="1.6">
	<model name="LeftHand">
		<link name="palm">
			<pose frame="">0.0008465930673992381 0.006988948113459613 -0.07018286344873657 0.0 -0.0 0.0</pose>
			<inertial>
				<pose frame="">0.0 0.0 0.0 0 0 0</pose>
				<mass>0.051037570984065514</mass>
				<inertia>
					<ixx>0.0002936516801864287</ixx>
					<ixy>7.779638835938705e-08</ixy>
					<ixz>2.386925709496385e-05</ixz>
					<iyy>0.0003082951186408721</iyy>
					<iyz>5.777597499228477e-06</iyz>
					<izz>2.4451830114452207e-05</izz>
				</inertia>
			</inertial>
			<collision name="palm_collision">
				<geometry>
					<mesh>
						<uri>model://LeftHand/meshes/CAD/palm.stl</uri>
						<scale>0.001 0.001 0.001</scale>
					</mesh>
				</geometry>
			</collision>
			<visual name="palm_visual">
				<geometry>
					<mesh>
						<uri>model://LeftHand/meshes/CAD/palm.stl</uri>
						<scale>0.001 0.001 0.001</scale>
					</mesh>
				</geometry>
			</visual>
		</link>
		<link name="ring_limb0">
			<pose frame="">8.078672351899789e-07 0.005136107528913908 -0.010543528678626282 0.0 -0.0 0.0</pose>
			<inertial>
				<pose frame="">0.0 0.0 0.0 0 0 0</pose>
				<mass>0.00042698636882981155</mass>
				<inertia>
					<ixx>5.705186481949865e-06</ixx>
					<ixy>-4.324087879365989e-08</ixy>
					<ixz>2.6419370768032256e-07</ixz>
					<iyy>5.847829902048414e-06</iyy>
					<iyz>9.311486939256451e-07</iyz>
					<izz>1.7250855397973222e-07</izz>
				</inertia>
			</inertial>
			<collision name="ring_limb0_collision">
				<geometry>
					<mesh>
						<uri>model://LeftHand/meshes/CAD/ring_limb0.stl</uri>
						<scale>0.001 0.001 0.001</scale>
					</mesh>
				</geometry>
			</collision>
			<visual name="ring_limb0_visual">
				<geometry>
					<mesh>
						<uri>model://LeftHand/meshes/CAD/ring_limb0.stl</uri>
						<scale>0.001 0.001 0.001</scale>
					</mesh>
				</geometry>
			</visual>
		</link>
		<link name="ring_limb1">
			<pose frame="">3.1551093233324955e-08 0.004674499962509607 -0.03546496884283003 0.0 -0.0 0.0</pose>
			<inertial>
				<pose frame="">0.0 0.0 0.0 0 0 0</pose>
				<mass>0.003829362795938266</mass>
				<inertia>
					<ixx>7.339305233966603e-05</ixx>
					<ixy>4.533371499380645e-07</ixy>
					<ixz>-2.3633501519324963e-06</ixz>
					<iyy>7.56202604180414e-05</iyy>
					<iyz>1.326758500270572e-05</iyz>
					<izz>2.672490772556329e-06</izz>
				</inertia>
			</inertial>
			<collision name="ring_limb1_collision">
				<geometry>
					<mesh>
						<uri>model://LeftHand/meshes/CAD/ring_limb1.stl</uri>
						<scale>0.001 0.001 0.001</scale>
					</mesh>
				</geometry>
			</collision>
			<visual name="ring_limb1_visual">
				<geometry>
					<mesh>
						<uri>model://LeftHand/meshes/CAD/ring_limb1.stl</uri>
						<scale>0.001 0.001 0.001</scale>
					</mesh>
				</geometry>
			</visual>
		</link>
		<link name="ring_limb2">
			<pose frame="">-1.442690669729192e-07 0.003903263432226213 -0.07521109040536342 0.0 -0.0 0.0</pose>
			<inertial>
				<pose frame="">0.0 0.0 0.0 0 0 0</pose>
				<mass>0.0016247546846144538</mass>
				<inertia>
					<ixx>4.9521147545355215e-05</ixx>
					<ixy>1.0349551422481156e-06</ixy>
					<ixz>-5.1908242512515894e-06</ixz>
					<iyy>5.0888514110338304e-05</iyy>
					<iyz>9.727635364613813e-06</iyz>
					<izz>2.5202897538578307e-06</izz>
				</inertia>
			</inertial>
			<collision name="ring_limb2_collision">
				<geometry>
					<mesh>
						<uri>model://LeftHand/meshes/CAD/ring_limb2.stl</uri>
						<scale>0.001 0.001 0.001</scale>
					</mesh>
				</geometry>
			</collision>
			<visual name="ring_limb2_visual">
				<geometry>
					<mesh>
						<uri>model://LeftHand/meshes/CAD/ring_limb2.stl</uri>
						<scale>0.001 0.001 0.001</scale>
					</mesh>
				</geometry>
			</visual>
		</link>
		<link name="ring_limb3">
			<pose frame="">-2.7022235191003264e-08 0.0031682988384227535 -0.10234015443097512 0.0 -0.0 0.0</pose>
			<inertial>
				<pose frame="">0.0 0.0 0.0 0 0 0</pose>
				<mass>0.0006943747393556934</mass>
				<inertia>
					<ixx>2.7724203122666803e-05</ixx>
					<ixy>8.045563508278746e-07</ixy>
					<ixz>-3.88080690438467e-06</ixz>
					<iyy>2.833338006682703e-05</iyy>
					<iyz>5.6283024249172895e-06</iyz>
					<izz>1.7278764706781233e-06</izz>
				</inertia>
			</inertial>
			<collision name="ring_limb3_collision">
				<geometry>
					<mesh>
						<uri>model://LeftHand/meshes/CAD/ring_limb3.stl</uri>
						<scale>0.001 0.001 0.001</scale>
					</mesh>
				</geometry>
			</collision>
			<visual name="ring_limb3_visual">
				<geometry>
					<mesh>
						<uri>model://LeftHand/meshes/CAD/ring_limb3.stl</uri>
						<scale>0.001 0.001 0.001</scale>
					</mesh>
				</geometry>
			</visual>
		</link>
		<link name="little_limb0">
			<pose frame="">8.078672351337994e-07 0.005136107528913858 -0.010543528678626336 0.0 -0.0 0.0</pose>
			<inertial>
				<pose frame="">0.0 0.0 0.0 0 0 0</pose>
				<mass>0.0004269772666438416</mass>
				<inertia>
					<ixx>4.355587941337768e-06</ixx>
					<ixy>-7.320318351005171e-08</ixy>
					<ixz>2.2075537435390336e-07</ixz>
					<iyy>4.824523647985384e-06</iyy>
					<iyz>1.439122803994223e-06</iyz>
					<izz>4.96143954844111e-07</izz>
				</inertia>
			</inertial>
			<collision name="little_limb0_collision">
				<geometry>
					<mesh>
						<uri>model://LeftHand/meshes/CAD/little_limb0.stl</uri>
						<scale>0.001 0.001 0.001</scale>
					</mesh>
				</geometry>
			</collision>
			<visual name="little_limb0_visual">
				<geometry>
					<mesh>
						<uri>model://LeftHand/meshes/CAD/little_limb0.stl</uri>
						<scale>0.001 0.001 0.001</scale>
					</mesh>
				</geometry>
			</visual>
		</link>
		<link name="little_limb1">
			<pose frame="">3.155157169604139e-08 0.004674499963337896 -0.035464968846822986 0.0 -0.0 0.0</pose>
			<inertial>
				<pose frame="">0.0 0.0 0.0 0 0 0</pose>
				<mass>0.0038295045524502297</mass>
				<inertia>
					<ixx>5.797477922101142e-05</ixx>
					<ixy>-7.269326800101181e-07</ixy>
					<ixz>1.9551021958800924e-06</ixz>
					<iyy>6.616226451409241e-05</iyy>
					<iyz>2.1814487475737055e-05</iyz>
					<izz>8.39931206134191e-06</izz>
				</inertia>
			</inertial>
			<collision name="little_limb1_collision">
				<geometry>
					<mesh>
						<uri>model://LeftHand/meshes/CAD/little_limb1.stl</uri>
						<scale>0.001 0.001 0.001</scale>
					</mesh>
				</geometry>
			</collision>
			<visual name="little_limb1_visual">
				<geometry>
					<mesh>
						<uri>model://LeftHand/meshes/CAD/little_limb1.stl</uri>
						<scale>0.001 0.001 0.001</scale>
					</mesh>
				</geometry>
			</visual>
		</link>
		<link name="little_limb2">
			<pose frame="">-1.4426906696422452e-07 0.003903263432226209 -0.07521109040536345 0.0 -0.0 0.0</pose>
			<inertial>
				<pose frame="">0.0 0.0 0.0 0 0 0</pose>
				<mass>0.0016247911658487128</mass>
				<inertia>
					<ixx>3.999653197211707e-05</ixx>
					<ixy>-3.639058864974396e-07</ixy>
					<ixz>8.719183832996077e-07</ixz>
					<iyy>4.702131243686592e-05</iyy>
					<iyz>1.6774663757500565e-05</iyz>
					<izz>7.084672355258392e-06</izz>
				</inertia>
			</inertial>
			<collision name="little_limb2_collision">
				<geometry>
					<mesh>
						<uri>model://LeftHand/meshes/CAD/little_limb2.stl</uri>
						<scale>0.001 0.001 0.001</scale>
					</mesh>
				</geometry>
			</collision>
			<visual name="little_limb2_visual">
				<geometry>
					<mesh>
						<uri>model://LeftHand/meshes/CAD/little_limb2.stl</uri>
						<scale>0.001 0.001 0.001</scale>
					</mesh>
				</geometry>
			</visual>
		</link>
		<link name="little_limb3">
			<pose frame="">-2.702223522120139e-08 0.0031682988384225713 -0.10234015443097544 0.0 -0.0 0.0</pose>
			<inertial>
				<pose frame="">0.0 0.0 0.0 0 0 0</pose>
				<mass>0.0006943833227503109</mass>
				<inertia>
					<ixx>2.2547791767825223e-05</ixx>
					<ixy>-1.4909623965506256e-07</ixy>
					<ixz>3.3963132070903805e-07</ixz>
					<iyy>2.6907536710997072e-05</iyy>
					<iyz>9.918495282604008e-06</iyz>
					<izz>4.37535006264128e-06</izz>
				</inertia>
			</inertial>
			<collision name="little_limb3_collision">
				<geometry>
					<mesh>
						<uri>model://LeftHand/meshes/CAD/little_limb3.stl</uri>
						<scale>0.001 0.001 0.001</scale>
					</mesh>
				</geometry>
			</collision>
			<visual name="little_limb3_visual">
				<geometry>
					<mesh>
						<uri>model://LeftHand/meshes/CAD/little_limb3.stl</uri>
						<scale>0.001 0.001 0.001</scale>
					</mesh>
				</geometry>
			</visual>
		</link>
		<link name="thumb_limb0">
			<pose frame="">8.07867235143004e-07 0.005136107528913899 -0.010543528678626188 0.0 -0.0 0.0</pose>
			<inertial>
				<pose frame="">0.0 0.0 0.0 0 0 0</pose>
				<mass>0.0004269876906727733</mass>
				<inertia>
					<ixx>2.1819939213634554e-06</ixx>
					<ixy>2.6305781554797975e-07</ixy>
					<ixz>7.06952213199512e-07</ixz>
					<iyy>2.184236876560202e-06</iyy>
					<iyz>-7.137180227455252e-07</iyz>
					<izz>5.348246264645507e-07</izz>
				</inertia>
			</inertial>
			<collision name="thumb_limb0_collision">
				<geometry>
					<mesh>
						<uri>model://LeftHand/meshes/CAD/thumb_limb0.stl</uri>
						<scale>0.001 0.001 0.001</scale>
					</mesh>
				</geometry>
			</collision>
			<visual name="thumb_limb0_visual">
				<geometry>
					<mesh>
						<uri>model://LeftHand/meshes/CAD/thumb_limb0.stl</uri>
						<scale>0.001 0.001 0.001</scale>
					</mesh>
				</geometry>
			</visual>
		</link>
		<link name="thumb_limb1">
			<pose frame="">3.1551571563485627e-08 0.004674499963337757 -0.035464968846823056 0.0 -0.0 0.0</pose>
			<inertial>
				<pose frame="">0.0 0.0 0.0 0 0 0</pose>
				<mass>0.0038294723135512097</mass>
				<inertia>
					<ixx>3.565912072519816e-05</ixx>
					<ixy>3.435297236744474e-06</ixy>
					<ixz>1.353667683558581e-05</ixz>
					<iyy>3.1377032435723576e-05</iyy>
					<iyz>-7.566667600957712e-06</iyz>
					<izz>8.416817613565124e-06</izz>
				</inertia>
			</inertial>
			<collision name="thumb_limb1_collision">
				<geometry>
					<mesh>
						<uri>model://LeftHand/meshes/CAD/thumb_limb1.stl</uri>
						<scale>0.001 0.001 0.001</scale>
					</mesh>
				</geometry>
			</collision>
			<visual name="thumb_limb1_visual">
				<geometry>
					<mesh>
						<uri>model://LeftHand/meshes/CAD/thumb_limb1.stl</uri>
						<scale>0.001 0.001 0.001</scale>
					</mesh>
				</geometry>
			</visual>
		</link>
		<link name="thumb_limb2">
			<pose frame="">-1.4426906696433286e-07 0.003903263432226205 -0.07521109040536345 0.0 -0.0 0.0</pose>
			<inertial>
				<pose frame="">0.0 0.0 0.0 0 0 0</pose>
				<mass>0.0016247845904062094</mass>
				<inertia>
					<ixx>2.9389035379980205e-05</ixx>
					<ixy>1.961284531072296e-06</ixy>
					<ixz>1.2230575080743566e-05</ixz>
					<iyy>2.3416741753792835e-05</iyy>
					<iyz>-3.667074945953091e-06</iyz>
					<izz>7.179389601295201e-06</izz>
				</inertia>
			</inertial>
			<collision name="thumb_limb2_collision">
				<geometry>
					<mesh>
						<uri>model://LeftHand/meshes/CAD/thumb_limb2.stl</uri>
						<scale>0.001 0.001 0.001</scale>
					</mesh>
				</geometry>
			</collision>
			<visual name="thumb_limb2_visual">
				<geometry>
					<mesh>
						<uri>model://LeftHand/meshes/CAD/thumb_limb2.stl</uri>
						<scale>0.001 0.001 0.001</scale>
					</mesh>
				</geometry>
			</visual>
		</link>
		<link name="thumb_limb3">
			<pose frame="">-2.7022235324104065e-08 0.0031682988384226043 -0.10234015443097544 0.0 -0.0 0.0</pose>
			<inertial>
				<pose frame="">0.0 0.0 0.0 0 0 0</pose>
				<mass>0.0006943642123641868</mass>
				<inertia>
					<ixx>1.7993103813154425e-05</ixx>
					<ixy>9.199724796858947e-07</ixy>
					<ixz>7.736261822635579e-06</ixz>
					<iyy>1.3777754367315646e-05</iyy>
					<iyz>-1.6158560702008232e-06</iyz>
					<izz>4.60502658487514e-06</izz>
				</inertia>
			</inertial>
			<collision name="thumb_limb3_collision">
				<geometry>
					<mesh>
						<uri>model://LeftHand/meshes/CAD/thumb_limb3.stl</uri>
						<scale>0.001 0.001 0.001</scale>
					</mesh>
				</geometry>
			</collision>
			<visual name="thumb_limb3_visual">
				<geometry>
					<mesh>
						<uri>model://LeftHand/meshes/CAD/thumb_limb3.stl</uri>
						<scale>0.001 0.001 0.001</scale>
					</mesh>
				</geometry>
			</visual>
		</link>
		<link name="index_limb0">
			<pose frame="">8.078672351541128e-07 0.005136107528914047 -0.010543528678625893 0.0 -0.0 0.0</pose>
			<inertial>
				<pose frame="">0.0 0.0 0.0 0 0 0</pose>
				<mass>0.0004270411671711376</mass>
				<inertia>
					<ixx>5.696396315690576e-06</ixx>
					<ixy>4.352364376914469e-08</ixy>
					<ixz>2.526333252288319e-07</ixz>
					<iyy>5.8565621584921525e-06</iyy>
					<iyz>-9.78686141948476e-07</iyz>
					<izz>1.873827522637124e-07</izz>
				</inertia>
			</inertial>
			<collision name="index_limb0_collision">
				<geometry>
					<mesh>
						<uri>model://LeftHand/meshes/CAD/index_limb0.stl</uri>
						<scale>0.001 0.001 0.001</scale>
					</mesh>
				</geometry>
			</collision>
			<visual name="index_limb0_visual">
				<geometry>
					<mesh>
						<uri>model://LeftHand/meshes/CAD/index_limb0.stl</uri>
						<scale>0.001 0.001 0.001</scale>
					</mesh>
				</geometry>
			</visual>
		</link>
		<link name="index_limb1">
			<pose frame="">3.1551571924784135e-08 0.004674499963338043 -0.03546496884682258 0.0 -0.0 0.0</pose>
			<inertial>
				<pose frame="">0.0 0.0 0.0 0 0 0</pose>
				<mass>0.0038295073766785414</mass>
				<inertia>
					<ixx>7.51412486458965e-05</ixx>
					<ixy>4.179435612889832e-07</ixy>
					<ixz>2.2276793050349664e-06</ixz>
					<iyy>7.77757378070444e-05</iyy>
					<iyz>-1.4224170064093465e-05</iyz>
					<izz>2.8463168148863768e-06</izz>
				</inertia>
			</inertial>
			<collision name="index_limb1_collision">
				<geometry>
					<mesh>
						<uri>model://LeftHand/meshes/CAD/index_limb1.stl</uri>
						<scale>0.001 0.001 0.001</scale>
					</mesh>
				</geometry>
			</collision>
			<visual name="index_limb1_visual">
				<geometry>
					<mesh>
						<uri>model://LeftHand/meshes/CAD/index_limb1.stl</uri>
						<scale>0.001 0.001 0.001</scale>
					</mesh>
				</geometry>
			</visual>
		</link>
		<link name="index_limb2">
			<pose frame="">-1.4426906697062004e-07 0.003903263432226209 -0.07521109040536345 0.0 -0.0 0.0</pose>
			<inertial>
				<pose frame="">0.0 0.0 0.0 0 0 0</pose>
				<mass>0.001624791169007945</mass>
				<inertia>
					<ixx>5.140399571045578e-05</ixx>
					<ixy>2.0283352480941494e-07</ixy>
					<ixz>9.88827307904426e-07</ixz>
					<iyy>5.3565328614777655e-05</iyy>
					<iyz>-1.0584698043686734e-05</iyz>
					<izz>2.221224794907972e-06</izz>
				</inertia>
			</inertial>
			<collision name="index_limb2_collision">
				<geometry>
					<mesh>
						<uri>model://LeftHand/meshes/CAD/index_limb2.stl</uri>
						<scale>0.001 0.001 0.001</scale>
					</mesh>
				</geometry>
			</collision>
			<visual name="index_limb2_visual">
				<geometry>
					<mesh>
						<uri>model://LeftHand/meshes/CAD/index_limb2.stl</uri>
						<scale>0.001 0.001 0.001</scale>
					</mesh>
				</geometry>
			</visual>
		</link>
		<link name="index_limb3">
			<pose frame="">-2.7022235331917607e-08 0.0031682988384226095 -0.10234015443097548 0.0 -0.0 0.0</pose>
			<inertial>
				<pose frame="">0.0 0.0 0.0 0 0 0</pose>
				<mass>0.000694383337351411</mass>
				<inertia>
					<ixx>2.886106729119322e-05</ixx>
					<ixy>8.204909151039371e-08</ixy>
					<ixz>3.8431020222399646e-07</ixz>
					<iyy>3.017582178216641e-05</iyy>
					<iyz>-6.171778299680877e-06</iyz>
					<izz>1.3303596105165014e-06</izz>
				</inertia>
			</inertial>
			<collision name="index_limb3_collision">
				<geometry>
					<mesh>
						<uri>model://LeftHand/meshes/CAD/index_limb3.stl</uri>
						<scale>0.001 0.001 0.001</scale>
					</mesh>
				</geometry>
			</collision>
			<visual name="index_limb3_visual">
				<geometry>
					<mesh>
						<uri>model://LeftHand/meshes/CAD/index_limb3.stl</uri>
						<scale>0.001 0.001 0.001</scale>
					</mesh>
				</geometry>
			</visual>
		</link>
		<link name="middle_limb0">
			<pose frame="">8.078672351106295e-07 0.005136107528913885 -0.010543528678626304 0.0 -0.0 0.0</pose>
			<inertial>
				<pose frame="">0.0 0.0 0.0 0 0 0</pose>
				<mass>0.00042698946612546875</mass>
				<inertia>
					<ixx>6.2209312152551715e-06</ixx>
					<ixy>-2.9280517172427354e-12</ixy>
					<ixz>2.6401612367373013e-07</ixz>
					<iyy>6.212418826825532e-06</iyy>
					<iyz>4.1650120476003156e-11</iyz>
					<izz>1.869819424248249e-08</izz>
				</inertia>
			</inertial>
			<collision name="middle_limb0_collision">
				<geometry>
					<mesh>
						<uri>model://LeftHand/meshes/CAD/middle_limb0.stl</uri>
						<scale>0.001 0.001 0.001</scale>
					</mesh>
				</geometry>
			</collision>
			<visual name="middle_limb0_visual">
				<geometry>
					<mesh>
						<uri>model://LeftHand/meshes/CAD/middle_limb0.stl</uri>
						<scale>0.001 0.001 0.001</scale>
					</mesh>
				</geometry>
			</visual>
		</link>
		<link name="middle_limb1">
			<pose frame="">3.155157163693056e-08 0.0046744999633378335 -0.03546496884682315 0.0 -0.0 0.0</pose>
			<inertial>
				<pose frame="">0.0 0.0 0.0 0 0 0</pose>
				<mass>0.0038294772175126385</mass>
				<inertia>
					<ixx>8.179745776726015e-05</ixx>
					<ixy>-1.0101743365068305e-12</ixy>
					<ixz>2.324896654186538e-06</ixz>
					<iyy>8.17289713698343e-05</iyy>
					<iyz>1.5576625019149935e-11</iyz>
					<izz>1.4333886290588195e-07</izz>
				</inertia>
			</inertial>
			<collision name="middle_limb1_collision">
				<geometry>
					<mesh>
						<uri>model://LeftHand/meshes/CAD/middle_limb1.stl</uri>
						<scale>0.001 0.001 0.001</scale>
					</mesh>
				</geometry>
			</collision>
			<visual name="middle_limb1_visual">
				<geometry>
					<mesh>
						<uri>model://LeftHand/meshes/CAD/middle_limb1.stl</uri>
						<scale>0.001 0.001 0.001</scale>
					</mesh>
				</geometry>
			</visual>
		</link>
		<link name="middle_limb2">
			<pose frame="">-1.4426906697284046e-07 0.003903263432226209 -0.07521109040536343 0.0 -0.0 0.0</pose>
			<inertial>
				<pose frame="">0.0 0.0 0.0 0 0 0</pose>
				<mass>0.001624791353067493</mass>
				<inertia>
					<ixx>5.5779881831285716e-05</ixx>
					<ixy>1.1170535519452018e-12</ixy>
					<ixz>1.030184337413126e-06</ixz>
					<iyy>5.5759467602632795e-05</iyy>
					<iyz>-3.978389887910476e-11</iyz>
					<izz>3.947765546600892e-08</izz>
				</inertia>
			</inertial>
			<collision name="middle_limb2_collision">
				<geometry>
					<mesh>
						<uri>model://LeftHand/meshes/CAD/middle_limb2.stl</uri>
						<scale>0.001 0.001 0.001</scale>
					</mesh>
				</geometry>
			</collision>
			<visual name="middle_limb2_visual">
				<geometry>
					<mesh>
						<uri>model://LeftHand/meshes/CAD/middle_limb2.stl</uri>
						<scale>0.001 0.001 0.001</scale>
					</mesh>
				</geometry>
			</visual>
		</link>
		<link name="middle_limb3">
			<pose frame="">-2.702223533799005e-08 0.0031682988384226095 -0.10234015443097544 0.0 -0.0 0.0</pose>
			<inertial>
				<pose frame="">0.0 0.0 0.0 0 0 0</pose>
				<mass>0.0006943748373823932</mass>
				<inertia>
					<ixx>3.126942660218029e-05</ixx>
					<ixy>9.770606142305848e-14</ixy>
					<ixz>4.0004172461025477e-07</ixz>
					<iyy>3.126385415013449e-05</iyy>
					<iyz>-3.760132469565902e-12</iyz>
					<izz>1.0032349759270292e-08</izz>
				</inertia>
			</inertial>
			<collision name="middle_limb3_collision">
				<geometry>
					<mesh>
						<uri>model://LeftHand/meshes/CAD/middle_limb3.stl</uri>
						<scale>0.001 0.001 0.001</scale>
					</mesh>
				</geometry>
			</collision>
			<visual name="middle_limb3_visual">
				<geometry>
					<mesh>
						<uri>model://LeftHand/meshes/CAD/middle_limb3.stl</uri>
						<scale>0.001 0.001 0.001</scale>
					</mesh>
				</geometry>
			</visual>
		</link>
		<joint name="palm_ring" type="revolute">
			<parent>palm</parent>
			<child>ring_limb0</child>
			<pose frame="">0.011821554472769665 -0.00013610752891389356 -0.10740692843221701 0 0 0</pose>
			<axis>
				<xyz>-0.9659258262890762 -4.904700770684754e-16 -0.25881904510252224</xyz>
				<limit>
					<lower>-0.3490658503988659</lower>
					<upper>1.2217304763960306</upper>
				</limit>
				<use_parent_model_frame>0</use_parent_model_frame>
			</axis>
		</joint>
		<joint name="palm_index" type="revolute">
			<parent>palm</parent>
			<child>index_limb0</child>
			<pose frame="">-0.02731205760157635 -0.00013610752891405397 -0.10352464275567966 0 0 0</pose>
			<axis>
				<xyz>-0.9659258262890775 -5.479394496853379e-16 0.2588190451025223</xyz>
				<limit>
					<lower>-0.3490658503988659</lower>
					<upper>1.2217304763960306</upper>
				</limit>
				<use_parent_model_frame>0</use_parent_model_frame>
			</axis>
		</joint>
		<joint name="palm_thumb" type="revolute">
			<parent>palm</parent>
			<child>thumb_limb0</child>
			<pose frame="">-0.02242875054079991 0.02642823672867539 -0.054369413994937936 0 0 0</pose>
			<axis>
				<xyz>0.3535533905932764 0.8660254037844375 0.3535533905932753</xyz>
				<limit>
					<lower>-0.3490658503988659</lower>
					<upper>1.2217304763960306</upper>
				</limit>
				<use_parent_model_frame>0</use_parent_model_frame>
			</axis>
		</joint>
		<joint name="palm_little" type="revolute">
			<parent>palm</parent>
			<child>little_limb0</child>
			<pose frame="">0.027315644017092362 -0.00013610752891383583 -0.09462097927132351 0 0 0</pose>
			<axis>
				<xyz>0.866025403784445 4.0999510464529535e-16 0.5000000000000029</xyz>
				<limit>
					<lower>-0.0</lower>
					<upper>-0.0</upper>
				</limit>
				<use_parent_model_frame>0</use_parent_model_frame>
			</axis>
		</joint>
		<joint name="palm_middle" type="revolute">
			<parent>palm</parent>
			<child>middle_limb0</child>
			<pose frame="">0.004999192132764881 -0.00013610752891387245 -0.11070647132137364 0 0 0</pose>
			<axis>
				<xyz>-1.0000000000000089 9.930890339105123e-17 -1.4559772246072405e-17</xyz>
				<limit>
					<lower>-0.3490658503988659</lower>
					<upper>1.2217304763960306</upper>
				</limit>
				<use_parent_model_frame>0</use_parent_model_frame>
			</axis>
		</joint>
		<joint name="joint0_ring" type="revolute">
			<parent>ring_limb0</parent>
			<child>ring_limb1</child>
			<pose frame="">0.01847197381225712 -0.0016028627915692722 -0.07832451909466288 0 0 0</pose>
			<axis>
				<xyz>-0.198266891274149 -0.6427876096865431 0.7399421116938513</xyz>
				<limit>
					<lower>-0.3141592653589793</lower>
					<upper>0.3141592653589793</upper>
				</limit>
				<use_parent_model_frame>0</use_parent_model_frame>
			</axis>
		</joint>
		<joint name="joint1_ring" type="revolute">
			<parent>ring_limb1</parent>
			<child>ring_limb2</child>
			<pose frame="">0.02619441704640059 -0.016326095790032892 -0.08864866004910812 0 0 0</pose>
			<axis>
				<xyz>0.9659258262890722 -8.101158632811689e-16 0.25881904510252285</xyz>
				<limit>
					<lower>-1.9198621771937625</lower>
					<upper>-0.0</upper>
				</limit>
				<use_parent_model_frame>0</use_parent_model_frame>
			</axis>
		</joint>
		<joint name="joint2_ring" type="revolute">
			<parent>ring_limb2</parent>
			<child>ring_limb3</child>
			<pose frame="">0.035232274257017464 -0.027859724172962532 -0.08945422093847018 0 0 0</pose>
			<axis>
				<xyz>0.9659258262890722 -8.101158632811689e-16 0.25881904510252285</xyz>
				<limit>
					<lower>-1.2217304763960306</lower>
					<upper>-0.0</upper>
				</limit>
				<use_parent_model_frame>0</use_parent_model_frame>
			</axis>
		</joint>
		<joint name="joint0_middle" type="revolute">
			<parent>middle_limb0</parent>
			<child>middle_limb1</child>
			<pose frame="">-3.155157163693056e-08 -0.0022725761746911484 -0.08428503115317686 0 0 0</pose>
			<axis>
				<xyz>6.842277657836021e-49 -0.8660254037844388 0.5</xyz>
				<limit>
					<lower>-0.6108652381980153</lower>
					<upper>0.6108652381980153</upper>
				</limit>
				<use_parent_model_frame>0</use_parent_model_frame>
			</axis>
		</joint>
		<joint name="joint1_middle" type="revolute">
			<parent>middle_limb1</parent>
			<child>middle_limb2</child>
			<pose frame="">-0.005499855730933027 0.0011637238658815713 -0.09716390959463658 0 0 0</pose>
			<axis>
				<xyz>1.0 0.0 0.0</xyz>
				<limit>
					<lower>-1.9198621771937625</lower>
					<upper>-0.0</upper>
				</limit>
				<use_parent_model_frame>0</use_parent_model_frame>
			</axis>
		</joint>
		<joint name="joint2_middle" type="revolute">
			<parent>middle_limb2</parent>
			<child>middle_limb3</child>
			<pose frame="">-0.003999972977764662 0.0003986884596851664 -0.10178459556902457 0 0 0</pose>
			<axis>
				<xyz>1.0 0.0 0.0</xyz>
				<limit>
					<lower>-1.2217304763960306</lower>
					<upper>-0.0</upper>
				</limit>
				<use_parent_model_frame>0</use_parent_model_frame>
			</axis>
		</joint>
		<joint name="joint0_little" type="revolute">
			<parent>little_limb0</parent>
			<child>little_limb1</child>
			<pose frame="">0.033061610861139054 -0.0022725761746911948 -0.06465050099745025 0 0 0</pose>
			<axis>
				<xyz>-0.25000000000000516 -0.8660254037844385 0.43301270189221686</xyz>
				<limit>
					<lower>-0.3141592653589793</lower>
					<upper>0.3141592653589793</upper>
				</limit>
				<use_parent_model_frame>0</use_parent_model_frame>
			</axis>
		</joint>
		<joint name="joint1_little" type="revolute">
			<parent>little_limb1</parent>
			<child>little_limb2</child>
			<pose frame="">0.05461114696096305 0.0011637238658813438 -0.07322896631306619 0 0 0</pose>
			<axis>
				<xyz>0.8660254037844395 -7.969319648637452e-15 0.49999999999999606</xyz>
				<limit>
					<lower>-1.9198621771937625</lower>
					<upper>-0.0</upper>
				</limit>
				<use_parent_model_frame>0</use_parent_model_frame>
			</axis>
		</joint>
		<joint name="joint2_little" type="revolute">
			<parent>little_limb2</parent>
			<child>little_limb3</child>
			<pose frame="">0.07178494281980795 0.00039868845968492496 -0.07284599235125913 0 0 0</pose>
			<axis>
				<xyz>0.8660254037844395 -7.969319648637452e-15 0.49999999999999606</xyz>
				<limit>
					<lower>-1.2217304763960306</lower>
					<upper>-0.0</upper>
				</limit>
				<use_parent_model_frame>0</use_parent_model_frame>
			</axis>
		</joint>
		<joint name="joint0_index" type="revolute">
			<parent>index_limb0</parent>
			<child>index_limb1</child>
			<pose frame="">-0.019678609021091656 -0.0022725761746915625 -0.07909545668631911 0 0 0</pose>
			<axis>
				<xyz>0.12940952255125512 -0.866025403784444 0.48296291314453815</xyz>
				<limit>
					<lower>-0.3141592653589793</lower>
					<upper>0.3141592653589793</upper>
				</limit>
				<use_parent_model_frame>0</use_parent_model_frame>
			</axis>
		</joint>
		<joint name="joint1_index" type="revolute">
			<parent>index_limb1</parent>
			<child>index_limb2</child>
			<pose frame="">-0.03861137749356317 0.0011637238658807154 -0.0887576769881774 0 0 0</pose>
			<axis>
				<xyz>0.9659258262890686 -1.2698175844150228e-15 -0.25881904510251696</xyz>
				<limit>
					<lower>-1.9198621771937625</lower>
					<upper>-0.0</upper>
				</limit>
				<use_parent_model_frame>0</use_parent_model_frame>
			</axis>
		</joint>
		<joint name="joint2_index" type="revolute">
			<parent>index_limb2</parent>
			<child>index_limb3</child>
			<pose frame="">-0.0453800459782049 0.00039868845968424826 -0.09268474503344067 0 0 0</pose>
			<axis>
				<xyz>0.9659258262890686 -1.2698175844150228e-15 -0.25881904510251696</xyz>
				<limit>
					<lower>-1.2217304763960306</lower>
					<upper>-0.0</upper>
				</limit>
				<use_parent_model_frame>0</use_parent_model_frame>
			</axis>
		</joint>
		<joint name="joint0_thumb" type="revolute">
			<parent>thumb_limb0</parent>
			<child>thumb_limb1</child>
			<pose frame="">-0.027509902416488922 0.02067812712062532 -0.03036371156911729 0 0 0</pose>
			<axis>
				<xyz>-0.810092587300987 0.09449111825231682 0.5786375623578539</xyz>
				<limit>
					<lower>-0.3141592653589793</lower>
					<upper>0.3141592653589793</upper>
				</limit>
				<use_parent_model_frame>0</use_parent_model_frame>
			</axis>
		</joint>
		<joint name="joint1_thumb" type="revolute">
			<parent>thumb_limb1</parent>
			<child>thumb_limb2</child>
			<pose frame="">-0.01652612868169145 0.05493966460056615 -0.030171395234934728 0 0 0</pose>
			<axis>
				<xyz>-0.48077872093720364 -0.6719147712873027 -0.5633669866258815</xyz>
				<limit>
					<lower>-1.9198621771937625</lower>
					<upper>-0.0</upper>
				</limit>
				<use_parent_model_frame>0</use_parent_model_frame>
			</axis>
		</joint>
		<joint name="joint2_thumb" type="revolute">
			<parent>thumb_limb2</parent>
			<child>thumb_limb3</child>
			<pose frame="">-0.014917949616405848 0.07403837108963067 -0.028979428032968643 0 0 0</pose>
			<axis>
				<xyz>-0.48077872093720364 -0.6719147712873027 -0.5633669866258815</xyz>
				<limit>
					<lower>-1.2217304763960306</lower>
					<upper>-0.0</upper>
				</limit>
				<use_parent_model_frame>0</use_parent_model_frame>
			</axis>
		</joint>
		<plugin filename="libmyomuscle_plugin.so" name="myomuscle_plugin"/>
	</model>
</sdf>
