<?xml version="1.0" ?>
<robot name="roboy_xylophone_left_arm_mod1">
  <joint name="joint_hip" type="revolute">
    <parent link="base"/>
    <child link="torso"/>
    <origin rpy="0  0  0" xyz="0       0.00152  0.08323"/>
    <axis xyz="0  0 -1"/>
    <limit effort="0.0" lower="-0.261799387799" upper="0.261799387799" velocity="0.0"/>
  </joint>
  <joint name="elbow_left" type="revolute">
    <parent link="upper_arm_left"/>
    <child link="lower_arm_left"/>
    <origin rpy="0  0  0" xyz="0.34911 -0.005   -0.01262"/>
    <axis xyz="0  0 -1"/>
    <limit effort="0.0" lower="0.0" upper="1.57079632679" velocity="0.0"/>
  </joint>
  <joint name="sphere_axis0" type="revolute">
    <parent link="torso"/>
    <child link="sphere_link1"/>
    <origin rpy="0  0  0" xyz="0.30091  0.001    0.46441"/>
    <axis xyz="1  0  0"/>
    <limit effort="0.0" lower="-3.14159265359" upper="3.14159265359" velocity="0.0"/>
  </joint>
  <joint name="sphere_axis1" type="revolute">
    <parent link="sphere_link1"/>
    <child link="sphere_link2"/>
    <origin rpy="0  0  0" xyz="0  0  0"/>
    <axis xyz="0  1  0"/>
    <limit effort="0.0" lower="-3.14159265359" upper="3.14159265359" velocity="0.0"/>
  </joint>
  <joint name="sphere_axis2" type="revolute">
    <parent link="sphere_link2"/>
    <child link="upper_arm_left"/>
    <origin rpy="0  0  0" xyz="0  0  0"/>
    <axis xyz="1  0  0"/>
    <limit effort="0.0" lower="-3.14159265359" upper="3.14159265359" velocity="0.0"/>
  </joint>
  <link name="base">
    <inertial>
      <mass value="1041.2293594077037"/>
      <origin rpy="0  0  0" xyz="0  0  0"/>
      <inertia ixx="194.34233377142348" ixy="0.02954008126913422" ixz="-0.1448651839771188" iyy="194.34304191479657" iyz="0.12760282012592977" izz="386.9973235859431"/>
    </inertial>
    <collision name="base_collision">
      <origin rpy="0  0  0" xyz="0  0  0"/>
      <geometry>
        <mesh filename="package://roboy_models/roboy_xylophone_left_arm_mod1/meshes/CAD/base.stl" scale="0.001 0.001 0.001"/>
      </geometry>
    </collision>
    <visual name="base_visual">
      <origin rpy="0  0  0" xyz="0  0  0"/>
      <geometry>
        <mesh filename="package://roboy_models/roboy_xylophone_left_arm_mod1/meshes/CAD/base.stl" scale="0.001 0.001 0.001"/>
      </geometry>
    </visual>
  </link>
  <link name="lower_arm_left">
    <inertial>
      <mass value="0.1639662034797443"/>
      <origin rpy="0  0  0" xyz="0.05744  0.00836  0.01872"/>
      <inertia ixx="0.05034721504021259" ixy="-0.0006621993367307967" ixz="-0.0005324601737404497" iyy="0.13286266410585928" iyz="-0.06422948881147728" izz="0.08257147674550085"/>
    </inertial>
    <collision name="lower_arm_left_collision">
      <origin rpy="0  0  0" xyz="0.05744  0.00836  0.01872"/>
      <geometry>
        <mesh filename="package://roboy_models/roboy_xylophone_left_arm_mod1/meshes/CAD/lower_arm_left.stl" scale="0.001 0.001 0.001"/>
      </geometry>
    </collision>
    <visual name="lower_arm_left_visual">
      <origin rpy="0  0  0" xyz="0.05744  0.00836  0.01872"/>
      <geometry>
        <mesh filename="package://roboy_models/roboy_xylophone_left_arm_mod1/meshes/CAD/lower_arm_left.stl" scale="0.001 0.001 0.001"/>
      </geometry>
    </visual>
  </link>
  <link name="upper_arm_left">
    <inertial>
      <mass value="1.4066729970235903"/>
      <origin rpy="0  0  0" xyz="1.93190000e-01  -1.00000000e-04   1.54000000e-02"/>
      <inertia ixx="0.4486374428979241" ixy="-0.0017035468355952727" ixz="-0.001934638909202926" iyy="0.7975932001439735" iyz="-0.3917077745810474" izz="0.352867754950354"/>
    </inertial>
    <collision name="upper_arm_left_collision">
      <origin rpy="0  0  0" xyz="1.93190000e-01  -1.00000000e-04   1.54000000e-02"/>
      <geometry>
        <mesh filename="package://roboy_models/roboy_xylophone_left_arm_mod1/meshes/CAD/upper_arm_left.stl" scale="0.001 0.001 0.001"/>
      </geometry>
    </collision>
    <visual name="upper_arm_left_visual">
      <origin rpy="0  0  0" xyz="1.93190000e-01  -1.00000000e-04   1.54000000e-02"/>
      <geometry>
        <mesh filename="package://roboy_models/roboy_xylophone_left_arm_mod1/meshes/CAD/upper_arm_left.stl" scale="0.001 0.001 0.001"/>
      </geometry>
    </visual>
  </link>
  <link name="torso">
    <inertial>
      <mass value="15.80321284930236"/>
      <origin rpy="0  0  0" xyz="0.01519 -0.00869  0.31334"/>
      <inertia ixx="2.886226976262021" ixy="-0.0012761288622997653" ixz="0.04534177387941487" iyy="3.1166228699862777" iyz="-0.12034199282146522" izz="0.3103078136361685"/>
    </inertial>
    <collision name="torso_collision">
      <origin rpy="0  0  0" xyz="0.01519 -0.00869  0.31334"/>
      <geometry>
        <mesh filename="package://roboy_models/roboy_xylophone_left_arm_mod1/meshes/CAD/torso.stl" scale="0.001 0.001 0.001"/>
      </geometry>
    </collision>
    <visual name="torso_visual">
      <origin rpy="0  0  0" xyz="0.01519 -0.00869  0.31334"/>
      <geometry>
        <mesh filename="package://roboy_models/roboy_xylophone_left_arm_mod1/meshes/CAD/torso.stl" scale="0.001 0.001 0.001"/>
      </geometry>
    </visual>
  </link>
  <link name="sphere_link1">
    <inertial>
      <mass value="0.046754103129628445"/>
      <origin rpy="0  0  0" xyz="0  0  0"/>
      <inertia ixx="0.014028930499989191" ixy="-3.55268210279209e-05" ixz="-6.465722109621308e-05" iyy="0.018262224157543774" iyz="-0.0077049471985332334" izz="0.004239863907651701"/>
    </inertial>
    <collision name="sphere_link1_collision">
      <origin rpy="0  0  0" xyz="0  0  0"/>
      <geometry>
        <mesh filename="package://roboy_models/roboy_xylophone_left_arm_mod1/meshes/CAD/sphere_link1.stl" scale="0.001 0.001 0.001"/>
      </geometry>
    </collision>
    <visual name="sphere_link1_visual">
      <origin rpy="0  0  0" xyz="0  0  0"/>
      <geometry>
        <mesh filename="package://roboy_models/roboy_xylophone_left_arm_mod1/meshes/CAD/sphere_link1.stl" scale="0.001 0.001 0.001"/>
      </geometry>
    </visual>
  </link>
  <link name="sphere_link2">
    <inertial>
      <mass value="0.031340659211905667"/>
      <origin rpy="0  0  0" xyz="0  0  0"/>
      <inertia ixx="0.009402701451181468" ixy="-2.3814669160705768e-05" ixz="-4.334162992086414e-05" iyy="0.012240403492128835" iyz="-0.005164854167460886" izz="0.002840800365783859"/>
    </inertial>
    <collision name="sphere_link2_collision">
      <origin rpy="0  0  0" xyz="0  0  0"/>
      <geometry>
        <mesh filename="package://roboy_models/roboy_xylophone_left_arm_mod1/meshes/CAD/sphere_link2.stl" scale="0.001 0.001 0.001"/>
      </geometry>
    </collision>
    <visual name="sphere_link2_visual">
      <origin rpy="0  0  0" xyz="0  0  0"/>
      <geometry>
        <mesh filename="package://roboy_models/roboy_xylophone_left_arm_mod1/meshes/CAD/sphere_link2.stl" scale="0.001 0.001 0.001"/>
      </geometry>
    </visual>
  </link>
</robot>
