<?xml version="1.0" ?>
<sdf version="1.6">
	<model name="roboy_xylophone_left_arm_mod1">
		<link name="base">
			<self_collide>false</self_collide>
			<pose frame="">-0.004997970345821523 0.0056731157257543545 0.024531453030641522 0.0 -0.0 0.0</pose>
			<inertial>
				<pose frame="">0.0 0.0 0.0 0 0 0</pose>
				<mass>1041.2293594077037</mass>
				<inertia>
					<ixx>194.34233377142357</ixx>
					<ixy>0.02954008126913404</ixy>
					<ixz>-0.1448651839771172</ixz>
					<iyy>194.3430419147966</iyy>
					<iyz>0.12760282012593194</iyz>
					<izz>386.9973235859432</izz>
				</inertia>
			</inertial>
			<collision name="base_collision">
				<geometry>
					<mesh>
						<uri>model://roboy_xylophone_left_arm_mod1/meshes/CAD/base.stl</uri>
						<scale>0.001 0.001 0.001</scale>
					</mesh>
				</geometry>
			</collision>
			<visual name="base_visual">
				<geometry>
					<mesh>
						<uri>model://roboy_xylophone_left_arm_mod1/meshes/CAD/base.stl</uri>
						<scale>0.001 0.001 0.001</scale>
					</mesh>
				</geometry>
			</visual>
		</link>
		<link name="lower_arm_left">
			<self_collide>false</self_collide>
			<pose frame="">0.790708731023547 0.00289811063517386 0.5526177427040682 0.0 -0.0 0.0</pose>
			<inertial>
				<pose frame="">0.0 0.0 0.0 0 0 0</pose>
				<mass>1.492088089970944</mass>
				<inertia>
					<ixx>0.4570210591421073</ixx>
					<ixy>-0.003353407097784592</ixy>
					<ixz>-0.0023882872421652364</ixz>
					<iyy>1.3967603888631925</iyy>
					<iyz>-0.6519648304204081</iyz>
					<izz>0.9410924924935262</izz>
				</inertia>
			</inertial>
			<collision name="lower_arm_left_collision">
				<geometry>
					<mesh>
						<uri>model://roboy_xylophone_left_arm_mod1/meshes/CAD/lower_arm_left.stl</uri>
						<scale>0.001 0.001 0.001</scale>
					</mesh>
				</geometry>
			</collision>
			<visual name="lower_arm_left_visual">
				<geometry>
					<mesh>
						<uri>model://roboy_xylophone_left_arm_mod1/meshes/CAD/lower_arm_left.stl</uri>
						<scale>0.001 0.001 0.001</scale>
					</mesh>
				</geometry>
			</visual>
		</link>
		<link name="upper_arm_left">
			<self_collide>false</self_collide>
			<pose frame="">0.49410937559160617 0.002420271200049729 0.5630545724963112 0.0 -0.0 0.0</pose>
			<inertial>
				<pose frame="">0.0 0.0 0.0 0 0 0</pose>
				<mass>1.4066729970235903</mass>
				<inertia>
					<ixx>0.4486374428979241</ixx>
					<ixy>-0.0017035468355952727</ixy>
					<ixz>-0.001934638909202926</ixz>
					<iyy>0.7975932001439735</iyy>
					<iyz>-0.3917077745810474</iyz>
					<izz>0.352867754950354</izz>
				</inertia>
			</inertial>
			<collision name="upper_arm_left_collision">
				<geometry>
					<mesh>
						<uri>model://roboy_xylophone_left_arm_mod1/meshes/CAD/upper_arm_left.stl</uri>
						<scale>0.001 0.001 0.001</scale>
					</mesh>
				</geometry>
			</collision>
			<visual name="upper_arm_left_visual">
				<geometry>
					<mesh>
						<uri>model://roboy_xylophone_left_arm_mod1/meshes/CAD/upper_arm_left.stl</uri>
						<scale>0.001 0.001 0.001</scale>
					</mesh>
				</geometry>
			</visual>
		</link>
		<link name="torso">
			<self_collide>false</self_collide>
			<pose frame="">0.015198108189375828 -0.007175945334814449 0.3965864194624781 0.0 -0.0 0.0</pose>
			<inertial>
				<pose frame="">0.0 0.0 0.0 0 0 0</pose>
				<mass>15.80321284930236</mass>
				<inertia>
					<ixx>2.886226976262021</ixx>
					<ixy>-0.0012761288622997653</ixy>
					<ixz>0.04534177387941487</ixz>
					<iyy>3.1166228699862777</iyy>
					<iyz>-0.12034199282146522</iyz>
					<izz>0.3103078136361685</izz>
				</inertia>
			</inertial>
			<collision name="torso_collision">
				<geometry>
					<mesh>
						<uri>model://roboy_xylophone_left_arm_mod1/meshes/CAD/torso.stl</uri>
						<scale>0.001 0.001 0.001</scale>
					</mesh>
				</geometry>
			</collision>
			<visual name="torso_visual">
				<geometry>
					<mesh>
						<uri>model://roboy_xylophone_left_arm_mod1/meshes/CAD/torso.stl</uri>
						<scale>0.001 0.001 0.001</scale>
					</mesh>
				</geometry>
			</visual>
		</link>
		<link name="sphere_link1">
			<self_collide>false</self_collide>
			<pose frame="">0.30091554581676005 0.0025251779766726646 0.5476527990464143 0.0 -0.0 0.0</pose>
			<inertial>
				<pose frame="">0.0 0.0 0.0 0 0 0</pose>
				<mass>0.046754103129628445</mass>
				<inertia>
					<ixx>0.014028930499989191</ixx>
					<ixy>-3.55268210279209e-05</ixy>
					<ixz>-6.465722109621308e-05</ixz>
					<iyy>0.018262224157543774</iyy>
					<iyz>-0.0077049471985332334</iyz>
					<izz>0.004239863907651701</izz>
				</inertia>
			</inertial>
			<collision name="sphere_link1_collision">
				<geometry>
					<mesh>
						<uri>model://roboy_xylophone_left_arm_mod1/meshes/CAD/sphere_link1.stl</uri>
						<scale>0.001 0.001 0.001</scale>
					</mesh>
				</geometry>
			</collision>
			<visual name="sphere_link1_visual">
				<geometry>
					<mesh>
						<uri>model://roboy_xylophone_left_arm_mod1/meshes/CAD/sphere_link1.stl</uri>
						<scale>0.001 0.001 0.001</scale>
					</mesh>
				</geometry>
			</visual>
		</link>
		<link name="sphere_link2">
			<self_collide>false</self_collide>
			<pose frame="">0.30091554581676017 0.0025251768590857553 0.547652799046415 0.0 -0.0 0.0</pose>
			<inertial>
				<pose frame="">0.0 0.0 0.0 0 0 0</pose>
				<mass>0.031340659211905667</mass>
				<inertia>
					<ixx>0.009402701451181468</ixx>
					<ixy>-2.3814669160705768e-05</ixy>
					<ixz>-4.334162992086414e-05</ixz>
					<iyy>0.012240403492128835</iyy>
					<iyz>-0.005164854167460886</iyz>
					<izz>0.002840800365783859</izz>
				</inertia>
			</inertial>
			<collision name="sphere_link2_collision">
				<geometry>
					<mesh>
						<uri>model://roboy_xylophone_left_arm_mod1/meshes/CAD/sphere_link2.stl</uri>
						<scale>0.001 0.001 0.001</scale>
					</mesh>
				</geometry>
			</collision>
			<visual name="sphere_link2_visual">
				<geometry>
					<mesh>
						<uri>model://roboy_xylophone_left_arm_mod1/meshes/CAD/sphere_link2.stl</uri>
						<scale>0.001 0.001 0.001</scale>
					</mesh>
				</geometry>
			</visual>
		</link>
		<link name="palm">
			<self_collide>false</self_collide>
			<pose frame="">0.9917273623057272 0.00358135347022755 0.5484346680591612 0.0 -0.0 0.0</pose>
			<inertial>
				<pose frame="">0.0 0.0 0.0 0 0 0</pose>
				<mass>0.05102810915560811</mass>
				<inertia>
					<ixx>0.015370803772928801</ixx>
					<ixy>-0.00018399018977599083</ixy>
					<ixz>-0.00010034856450394081</ixz>
					<iyy>0.06557534473092379</iyy>
					<iyz>-0.02775433859648656</iyz>
					<izz>0.05024488240262624</izz>
				</inertia>
			</inertial>
			<collision name="palm_collision">
				<geometry>
					<mesh>
						<uri>model://roboy_xylophone_left_arm_mod1/meshes/CAD/palm.stl</uri>
						<scale>0.001 0.001 0.001</scale>
					</mesh>
				</geometry>
			</collision>
			<visual name="palm_visual">
				<geometry>
					<mesh>
						<uri>model://roboy_xylophone_left_arm_mod1/meshes/CAD/palm.stl</uri>
						<scale>0.001 0.001 0.001</scale>
					</mesh>
				</geometry>
			</visual>
		</link>
		<link name="left_ring_limb0">
			<self_collide>false</self_collide>
			<pose frame="">1.0368977317851111 0.02162316851797089 0.5489735526867717 0.0 -0.0 0.0</pose>
			<inertial>
				<pose frame="">0.0 0.0 0.0 0 0 0</pose>
				<mass>0.000426987941259331</mass>
				<inertia>
					<ixx>0.00012888910458772884</ixx>
					<ixy>-9.572948303864532e-06</ixy>
					<ixz>-5.068653289493569e-06</ixz>
					<iyy>0.0005877665690890964</iyy>
					<iyz>-0.00024305442455160167</iyz>
					<izz>0.0004592866397577126</izz>
				</inertia>
			</inertial>
			<collision name="left_ring_limb0_collision">
				<geometry>
					<mesh>
						<uri>model://roboy_xylophone_left_arm_mod1/meshes/CAD/left_ring_limb0.stl</uri>
						<scale>0.001 0.001 0.001</scale>
					</mesh>
				</geometry>
			</collision>
			<visual name="left_ring_limb0_visual">
				<geometry>
					<mesh>
						<uri>model://roboy_xylophone_left_arm_mod1/meshes/CAD/left_ring_limb0.stl</uri>
						<scale>0.001 0.001 0.001</scale>
					</mesh>
				</geometry>
			</visual>
		</link>
		<link name="left_ring_limb1">
			<self_collide>false</self_collide>
			<pose frame="">1.0607443338303408 0.02801101966358334 0.5492102675664841 0.0 -0.0 0.0</pose>
			<inertial>
				<pose frame="">0.0 0.0 0.0 0 0 0</pose>
				<mass>0.0038292022337134226</mass>
				<inertia>
					<ixx>0.0011581477259197644</ixx>
					<ixy>-0.00011400064427020582</ixy>
					<ixz>-5.891072656300794e-05</ixz>
					<iyy>0.005464460234849094</iyy>
					<iyz>-0.0022307941750760725</iyz>
					<izz>0.004312517027519531</izz>
				</inertia>
			</inertial>
			<collision name="left_ring_limb1_collision">
				<geometry>
					<mesh>
						<uri>model://roboy_xylophone_left_arm_mod1/meshes/CAD/left_ring_limb1.stl</uri>
						<scale>0.001 0.001 0.001</scale>
					</mesh>
				</geometry>
			</collision>
			<visual name="left_ring_limb1_visual">
				<geometry>
					<mesh>
						<uri>model://roboy_xylophone_left_arm_mod1/meshes/CAD/left_ring_limb1.stl</uri>
						<scale>0.001 0.001 0.001</scale>
					</mesh>
				</geometry>
			</visual>
		</link>
		<link name="left_ring_limb2">
			<self_collide>false</self_collide>
			<pose frame="">1.0991430514945248 0.03829537014563837 0.5489218377583686 0.0 -0.0 0.0</pose>
			<inertial>
				<pose frame="">0.0 0.0 0.0 0 0 0</pose>
				<mass>0.0016247457186844246</mass>
				<inertia>
					<ixx>0.0004919730972020467</ixx>
					<ixy>-6.842793068227497e-05</ixy>
					<ixz>-3.415626677880454e-05</ixz>
					<iyy>0.0024526057115011883</iyy>
					<iyz>-0.0009802882492711913</iyz>
					<izz>0.001965438075968195</izz>
				</inertia>
			</inertial>
			<collision name="left_ring_limb2_collision">
				<geometry>
					<mesh>
						<uri>model://roboy_xylophone_left_arm_mod1/meshes/CAD/left_ring_limb2.stl</uri>
						<scale>0.001 0.001 0.001</scale>
					</mesh>
				</geometry>
			</collision>
			<visual name="left_ring_limb2_visual">
				<geometry>
					<mesh>
						<uri>model://roboy_xylophone_left_arm_mod1/meshes/CAD/left_ring_limb2.stl</uri>
						<scale>0.001 0.001 0.001</scale>
					</mesh>
				</geometry>
			</visual>
		</link>
		<link name="left_ring_limb3">
			<self_collide>false</self_collide>
			<pose frame="">1.1253574444655217 0.04531731399078948 0.5489334348720009 0.0 -0.0 0.0</pose>
			<inertial>
				<pose frame="">0.0 0.0 0.0 0 0 0</pose>
				<mass>0.0006943749658614628</mass>
				<inertia>
					<ixx>0.0002106669548104141</ixx>
					<ixy>-3.5418111983137734e-05</ixy>
					<ixz>-1.7273954333279142e-05</ixz>
					<iyy>0.0010886394397740262</iyy>
					<iyz>-0.00042894963998009716</iyz>
					<izz>0.0008808323194032198</izz>
				</inertia>
			</inertial>
			<collision name="left_ring_limb3_collision">
				<geometry>
					<mesh>
						<uri>model://roboy_xylophone_left_arm_mod1/meshes/CAD/left_ring_limb3.stl</uri>
						<scale>0.001 0.001 0.001</scale>
					</mesh>
				</geometry>
			</collision>
			<visual name="left_ring_limb3_visual">
				<geometry>
					<mesh>
						<uri>model://roboy_xylophone_left_arm_mod1/meshes/CAD/left_ring_limb3.stl</uri>
						<scale>0.001 0.001 0.001</scale>
					</mesh>
				</geometry>
			</visual>
		</link>
		<link name="left_little_limb0">
			<self_collide>false</self_collide>
			<pose frame="">1.022388887517555 0.03620720493518758 0.5491100863355073 0.0 -0.0 0.0</pose>
			<inertial>
				<pose frame="">0.0 0.0 0.0 0 0 0</pose>
				<mass>0.00042697695534903786</mass>
				<inertia>
					<ixx>0.00012930955335420158</ixx>
					<ixy>-1.5804776761449693e-05</ixy>
					<ixz>-8.48923667890854e-06</ixz>
					<iyy>0.0005750587232987558</iyy>
					<iyz>-0.00023970691077589913</iyz>
					<izz>0.00044687771299046055</izz>
				</inertia>
			</inertial>
			<collision name="left_little_limb0_collision">
				<geometry>
					<mesh>
						<uri>model://roboy_xylophone_left_arm_mod1/meshes/CAD/left_little_limb0.stl</uri>
						<scale>0.001 0.001 0.001</scale>
					</mesh>
				</geometry>
			</collision>
			<visual name="left_little_limb0_visual">
				<geometry>
					<mesh>
						<uri>model://roboy_xylophone_left_arm_mod1/meshes/CAD/left_little_limb0.stl</uri>
						<scale>0.001 0.001 0.001</scale>
					</mesh>
				</geometry>
			</visual>
		</link>
		<link name="left_little_limb1">
			<self_collide>false</self_collide>
			<pose frame="">1.0436756451900138 0.048483582291001935 0.5514928207120477 0.0 -0.0 0.0</pose>
			<inertial>
				<pose frame="">0.0 0.0 0.0 0 0 0</pose>
				<mass>0.003829229075407257</mass>
				<inertia>
					<ixx>0.0011739442263777094</ixx>
					<ixy>-0.0001941498214957915</ixy>
					<ixz>-0.00010243114230027823</ixz>
					<iyy>0.005336411892404972</iyy>
					<iyz>-0.002204102316038816</iyz>
					<izz>0.004180990744579477</izz>
				</inertia>
			</inertial>
			<collision name="left_little_limb1_collision">
				<geometry>
					<mesh>
						<uri>model://roboy_xylophone_left_arm_mod1/meshes/CAD/left_little_limb1.stl</uri>
						<scale>0.001 0.001 0.001</scale>
					</mesh>
				</geometry>
			</collision>
			<visual name="left_little_limb1_visual">
				<geometry>
					<mesh>
						<uri>model://roboy_xylophone_left_arm_mod1/meshes/CAD/left_little_limb1.stl</uri>
						<scale>0.001 0.001 0.001</scale>
					</mesh>
				</geometry>
			</visual>
		</link>
		<link name="left_little_limb2">
			<self_collide>false</self_collide>
			<pose frame="">1.0780012228578788 0.06828321540659699 0.554662742339359 0.0 -0.0 0.0</pose>
			<inertial>
				<pose frame="">0.0 0.0 0.0 0 0 0</pose>
				<mass>0.0016247442518177167</mass>
				<inertia>
					<ixx>0.0005074895576064519</ixx>
					<ixy>-0.00011966272829945726</ixy>
					<ixz>-6.15467671178585e-05</ixz>
					<iyy>0.002388084366140063</iyy>
					<iyz>-0.0009714976334769013</iyz>
					<izz>0.001895841376576713</izz>
				</inertia>
			</inertial>
			<collision name="left_little_limb2_collision">
				<geometry>
					<mesh>
						<uri>model://roboy_xylophone_left_arm_mod1/meshes/CAD/left_little_limb2.stl</uri>
						<scale>0.001 0.001 0.001</scale>
					</mesh>
				</geometry>
			</collision>
			<visual name="left_little_limb2_visual">
				<geometry>
					<mesh>
						<uri>model://roboy_xylophone_left_arm_mod1/meshes/CAD/left_little_limb2.stl</uri>
						<scale>0.001 0.001 0.001</scale>
					</mesh>
				</geometry>
			</visual>
		</link>
		<link name="left_little_limb3">
			<self_collide>false</self_collide>
			<pose frame="">1.1014196608270355 0.08179073112948107 0.5570345099876503 0.0 -0.0 0.0</pose>
			<inertial>
				<pose frame="">0.0 0.0 0.0 0 0 0</pose>
				<mass>0.0006943752176416951</mass>
				<inertia>
					<ixx>0.0002201124485971851</ixx>
					<ixy>-6.256400398146359e-05</ixy>
					<ixz>-3.163803263326531e-05</ixz>
					<iyy>0.001057843639863267</iyy>
					<iyz>-0.00042602284010751054</iyz>
					<izz>0.0008470381994435137</izz>
				</inertia>
			</inertial>
			<collision name="left_little_limb3_collision">
				<geometry>
					<mesh>
						<uri>model://roboy_xylophone_left_arm_mod1/meshes/CAD/left_little_limb3.stl</uri>
						<scale>0.001 0.001 0.001</scale>
					</mesh>
				</geometry>
			</collision>
			<visual name="left_little_limb3_visual">
				<geometry>
					<mesh>
						<uri>model://roboy_xylophone_left_arm_mod1/meshes/CAD/left_little_limb3.stl</uri>
						<scale>0.001 0.001 0.001</scale>
					</mesh>
				</geometry>
			</visual>
		</link>
		<link name="left_thumb_limb0">
			<self_collide>false</self_collide>
			<pose frame="">0.988145988507339 -0.022194480752001998 0.5310713963942968 0.0 -0.0 0.0</pose>
			<inertial>
				<pose frame="">0.0 0.0 0.0 0 0 0</pose>
				<mass>0.000427086727381085</mass>
				<inertia>
					<ixx>0.00012067203871316187</ixx>
					<ixy>9.36728975257078e-06</ixy>
					<ixz>5.034579678257114e-06</ixz>
					<iyy>0.0005374829146462438</iyy>
					<iyz>-0.00022412561221834821</iyz>
					<izz>0.0004172374747172173</izz>
				</inertia>
			</inertial>
			<collision name="left_thumb_limb0_collision">
				<geometry>
					<mesh>
						<uri>model://roboy_xylophone_left_arm_mod1/meshes/CAD/left_thumb_limb0.stl</uri>
						<scale>0.001 0.001 0.001</scale>
					</mesh>
				</geometry>
			</collision>
			<visual name="left_thumb_limb0_visual">
				<geometry>
					<mesh>
						<uri>model://roboy_xylophone_left_arm_mod1/meshes/CAD/left_thumb_limb0.stl</uri>
						<scale>0.001 0.001 0.001</scale>
					</mesh>
				</geometry>
			</visual>
		</link>
		<link name="left_thumb_limb1">
			<self_collide>false</self_collide>
			<pose frame="">1.004847505893009 -0.02801358078123116 0.5138879680945865 0.0 -0.0 0.0</pose>
			<inertial>
				<pose frame="">0.0 0.0 0.0 0 0 0</pose>
				<mass>0.003829516108975692</mass>
				<inertia>
					<ixx>0.0010148752501394469</ixx>
					<ixy>0.00010794025600166477</ixy>
					<ixz>5.498192307894222e-05</ixz>
					<iyy>0.0048789623908727184</iyy>
					<iyz>-0.001977055671801172</iyz>
					<izz>0.0038702680386776354</izz>
				</inertia>
			</inertial>
			<collision name="left_thumb_limb1_collision">
				<geometry>
					<mesh>
						<uri>model://roboy_xylophone_left_arm_mod1/meshes/CAD/left_thumb_limb1.stl</uri>
						<scale>0.001 0.001 0.001</scale>
					</mesh>
				</geometry>
			</collision>
			<visual name="left_thumb_limb1_visual">
				<geometry>
					<mesh>
						<uri>model://roboy_xylophone_left_arm_mod1/meshes/CAD/left_thumb_limb1.stl</uri>
						<scale>0.001 0.001 0.001</scale>
					</mesh>
				</geometry>
			</visual>
		</link>
		<link name="left_thumb_limb2">
			<self_collide>false</self_collide>
			<pose frame="">1.0319478733318874 -0.036689334752402346 0.4861273240510582 0.0 -0.0 0.0</pose>
			<inertial>
				<pose frame="">0.0 0.0 0.0 0 0 0</pose>
				<mass>0.0016247782054319543</mass>
				<inertia>
					<ixx>0.00038626407121438724</ixx>
					<ixy>6.15437126274469e-05</ixy>
					<ixz>2.894919308799555e-05</ixz>
					<iyy>0.0021143843128020954</iyy>
					<iyz>-0.0008150108299531603</iyz>
					<izz>0.001732535753205418</izz>
				</inertia>
			</inertial>
			<collision name="left_thumb_limb2_collision">
				<geometry>
					<mesh>
						<uri>model://roboy_xylophone_left_arm_mod1/meshes/CAD/left_thumb_limb2.stl</uri>
						<scale>0.001 0.001 0.001</scale>
					</mesh>
				</geometry>
			</collision>
			<visual name="left_thumb_limb2_visual">
				<geometry>
					<mesh>
						<uri>model://roboy_xylophone_left_arm_mod1/meshes/CAD/left_thumb_limb2.stl</uri>
						<scale>0.001 0.001 0.001</scale>
					</mesh>
				</geometry>
			</visual>
		</link>
		<link name="left_thumb_limb3">
			<self_collide>false</self_collide>
			<pose frame="">1.0503377371302234 -0.042780066843595206 0.46712111506189585 0.0 -0.0 0.0</pose>
			<inertial>
				<pose frame="">0.0 0.0 0.0 0 0 0</pose>
				<mass>0.0006943657304111824</mass>
				<inertia>
					<ixx>0.00015280255491808471</ixx>
					<ixy>3.120489133298406e-05</ixy>
					<ixz>1.387054301144781e-05</ixz>
					<iyy>0.0009175703787736211</iyy>
					<iyz>-0.00034066867724061165</iyz>
					<izz>0.0007673182111993899</izz>
				</inertia>
			</inertial>
			<collision name="left_thumb_limb3_collision">
				<geometry>
					<mesh>
						<uri>model://roboy_xylophone_left_arm_mod1/meshes/CAD/left_thumb_limb3.stl</uri>
						<scale>0.001 0.001 0.001</scale>
					</mesh>
				</geometry>
			</collision>
			<visual name="left_thumb_limb3_visual">
				<geometry>
					<mesh>
						<uri>model://roboy_xylophone_left_arm_mod1/meshes/CAD/left_thumb_limb3.stl</uri>
						<scale>0.001 0.001 0.001</scale>
					</mesh>
				</geometry>
			</visual>
		</link>
		<link name="left_index_limb0">
			<self_collide>false</self_collide>
			<pose frame="">1.0368979894239703 -0.017142716310651833 0.5493990671194052 0.0 -0.0 0.0</pose>
			<inertial>
				<pose frame="">0.0 0.0 0.0 0 0 0</pose>
				<mass>0.0004270401913445981</mass>
				<inertia>
					<ixx>0.00012903029208815117</ixx>
					<ixy>7.590183679115984e-06</ixy>
					<ixz>4.0220789865228665e-06</ixz>
					<iyy>0.0005880383133298288</iyy>
					<iyz>-0.00024327263105609182</iyz>
					<izz>0.00045926889348591094</izz>
				</inertia>
			</inertial>
			<collision name="left_index_limb0_collision">
				<geometry>
					<mesh>
						<uri>model://roboy_xylophone_left_arm_mod1/meshes/CAD/left_index_limb0.stl</uri>
						<scale>0.001 0.001 0.001</scale>
					</mesh>
				</geometry>
			</collision>
			<visual name="left_index_limb0_visual">
				<geometry>
					<mesh>
						<uri>model://roboy_xylophone_left_arm_mod1/meshes/CAD/left_index_limb0.stl</uri>
						<scale>0.001 0.001 0.001</scale>
					</mesh>
				</geometry>
			</visual>
		</link>
		<link name="left_index_limb1">
			<self_collide>false</self_collide>
			<pose frame="">1.0607444051325836 -0.023525145589367455 0.5497764870860175 0.0 -0.0 0.0</pose>
			<inertial>
				<pose frame="">0.0 0.0 0.0 0 0 0</pose>
				<mass>0.003829175633876414</mass>
				<inertia>
					<ixx>0.0011596372084566602</ixx>
					<ixy>9.577898429574336e-05</ixy>
					<ixz>4.952878839419101e-05</ixz>
					<iyy>0.005466805770764954</iyy>
					<iyz>-0.002233083635075842</iyz>
					<izz>0.004311602267508981</izz>
				</inertia>
			</inertial>
			<collision name="left_index_limb1_collision">
				<geometry>
					<mesh>
						<uri>model://roboy_xylophone_left_arm_mod1/meshes/CAD/left_index_limb1.stl</uri>
						<scale>0.001 0.001 0.001</scale>
					</mesh>
				</geometry>
			</collision>
			<visual name="left_index_limb1_visual">
				<geometry>
					<mesh>
						<uri>model://roboy_xylophone_left_arm_mod1/meshes/CAD/left_index_limb1.stl</uri>
						<scale>0.001 0.001 0.001</scale>
					</mesh>
				</geometry>
			</visual>
		</link>
		<link name="left_index_limb2">
			<self_collide>false</self_collide>
			<pose frame="">1.0991430463560352 -0.033813400820777426 0.5497140831308294 0.0 -0.0 0.0</pose>
			<inertial>
				<pose frame="">0.0 0.0 0.0 0 0 0</pose>
				<mass>0.001624745542098687</mass>
				<inertia>
					<ixx>0.0004928621041606002</ixx>
					<ixy>6.042370593322363e-05</ixy>
					<ixz>3.0202727439046753e-05</ixz>
					<iyy>0.0024540196903800036</iyy>
					<iyz>-0.0009817038065463798</iyz>
					<izz>0.0019649126413420924</izz>
				</inertia>
			</inertial>
			<collision name="left_index_limb2_collision">
				<geometry>
					<mesh>
						<uri>model://roboy_xylophone_left_arm_mod1/meshes/CAD/left_index_limb2.stl</uri>
						<scale>0.001 0.001 0.001</scale>
					</mesh>
				</geometry>
			</collision>
			<visual name="left_index_limb2_visual">
				<geometry>
					<mesh>
						<uri>model://roboy_xylophone_left_arm_mod1/meshes/CAD/left_index_limb2.stl</uri>
						<scale>0.001 0.001 0.001</scale>
					</mesh>
				</geometry>
			</visual>
		</link>
		<link name="left_index_limb3">
			<self_collide>false</self_collide>
			<pose frame="">1.1253574302104106 -0.04083342013110076 0.5498799550595459 0.0 -0.0 0.0</pose>
			<inertial>
				<pose frame="">0.0 0.0 0.0 0 0 0</pose>
				<mass>0.0006943752726750456</mass>
				<inertia>
					<ixx>0.00021112100129605</ixx>
					<ixy>3.191427415218082e-05</ixy>
					<ixz>1.559172316255988e-05</ixz>
					<iyy>0.0010893621079944816</iyy>
					<iyz>-0.0004296895911852383</iyz>
					<izz>0.000880564430659528</izz>
				</inertia>
			</inertial>
			<collision name="left_index_limb3_collision">
				<geometry>
					<mesh>
						<uri>model://roboy_xylophone_left_arm_mod1/meshes/CAD/left_index_limb3.stl</uri>
						<scale>0.001 0.001 0.001</scale>
					</mesh>
				</geometry>
			</collision>
			<visual name="left_index_limb3_visual">
				<geometry>
					<mesh>
						<uri>model://roboy_xylophone_left_arm_mod1/meshes/CAD/left_index_limb3.stl</uri>
						<scale>0.001 0.001 0.001</scale>
					</mesh>
				</geometry>
			</visual>
		</link>
		<link name="left_middle_limb0">
			<self_collide>false</self_collide>
			<pose frame="">1.0421129142672163 0.0027389069881040575 0.5490523273641641 0.0 -0.0 0.0</pose>
			<inertial>
				<pose frame="">0.0 0.0 0.0 0 0 0</pose>
				<mass>0.0004269896468747399</mass>
				<inertia>
					<ixx>0.0001287302614895804</ixx>
					<ixy>-1.2187390172826041e-06</ixy>
					<ixz>-6.420768542377764e-07</ixz>
					<iyy>0.0005924353032111436</iyy>
					<iyz>-0.00024431292716046434</iyz>
					<izz>0.00046372163306910403</izz>
				</inertia>
			</inertial>
			<collision name="left_middle_limb0_collision">
				<geometry>
					<mesh>
						<uri>model://roboy_xylophone_left_arm_mod1/meshes/CAD/left_middle_limb0.stl</uri>
						<scale>0.001 0.001 0.001</scale>
					</mesh>
				</geometry>
			</collision>
			<visual name="left_middle_limb0_visual">
				<geometry>
					<mesh>
						<uri>model://roboy_xylophone_left_arm_mod1/meshes/CAD/left_middle_limb0.stl</uri>
						<scale>0.001 0.001 0.001</scale>
					</mesh>
				</geometry>
			</visual>
		</link>
		<link name="left_middle_limb1">
			<self_collide>false</self_collide>
			<pose frame="">1.066799750478991 0.002741277430529108 0.5493385477946431 0.0 -0.0 0.0</pose>
			<inertial>
				<pose frame="">0.0 0.0 0.0 0 0 0</pose>
				<mass>0.00382922548580367</mass>
				<inertia>
					<ixx>0.0011556583473477642</ixx>
					<ixy>-1.1198289534510894e-05</ixy>
					<ixz>-5.766372546474691e-06</ixz>
					<iyy>0.005514425963112412</iyy>
					<iyz>-0.0022440687308760334</iyz>
					<izz>0.004358900017002106</izz>
				</inertia>
			</inertial>
			<collision name="left_middle_limb1_collision">
				<geometry>
					<mesh>
						<uri>model://roboy_xylophone_left_arm_mod1/meshes/CAD/left_middle_limb1.stl</uri>
						<scale>0.001 0.001 0.001</scale>
					</mesh>
				</geometry>
			</collision>
			<visual name="left_middle_limb1_visual">
				<geometry>
					<mesh>
						<uri>model://roboy_xylophone_left_arm_mod1/meshes/CAD/left_middle_limb1.stl</uri>
						<scale>0.001 0.001 0.001</scale>
					</mesh>
				</geometry>
			</visual>
		</link>
		<link name="left_middle_limb2">
			<self_collide>false</self_collide>
			<pose frame="">1.1065523971777602 0.0027389470901448398 0.5491297774664762 0.0 -0.0 0.0</pose>
			<inertial>
				<pose frame="">0.0 0.0 0.0 0 0 0</pose>
				<mass>0.0016247453566464605</mass>
				<inertia>
					<ixx>0.0004899629871096102</ixx>
					<ixy>-4.924357328152763e-06</ixy>
					<ixz>-2.4436811859295626e-06</ixz>
					<iyy>0.002479539417427546</iyy>
					<iyz>-0.000987270567642874</iyz>
					<izz>0.0019896198686448385</izz>
				</inertia>
			</inertial>
			<collision name="left_middle_limb2_collision">
				<geometry>
					<mesh>
						<uri>model://roboy_xylophone_left_arm_mod1/meshes/CAD/left_middle_limb2.stl</uri>
						<scale>0.001 0.001 0.001</scale>
					</mesh>
				</geometry>
			</collision>
			<visual name="left_middle_limb2_visual">
				<geometry>
					<mesh>
						<uri>model://roboy_xylophone_left_arm_mod1/meshes/CAD/left_middle_limb2.stl</uri>
						<scale>0.001 0.001 0.001</scale>
					</mesh>
				</geometry>
			</visual>
		</link>
		<link name="left_middle_limb3">
			<self_collide>false</self_collide>
			<pose frame="">1.133690904205956 0.0027396548017951518 0.5491957247976434 0.0 -0.0 0.0</pose>
			<inertial>
				<pose frame="">0.0 0.0 0.0 0 0 0</pose>
				<mass>0.0006943747430593866</mass>
				<inertia>
					<ixx>0.00020944442033380437</ixx>
					<ixy>-2.1566977420058455e-06</ixy>
					<ixz>-1.0447637355614393e-06</ixz>
					<iyy>0.001101912850377566</iyy>
					<iyz>-0.0004323325282610183</iyz>
					<izz>0.0008924833135538727</izz>
				</inertia>
			</inertial>
			<collision name="left_middle_limb3_collision">
				<geometry>
					<mesh>
						<uri>model://roboy_xylophone_left_arm_mod1/meshes/CAD/left_middle_limb3.stl</uri>
						<scale>0.001 0.001 0.001</scale>
					</mesh>
				</geometry>
			</collision>
			<visual name="left_middle_limb3_visual">
				<geometry>
					<mesh>
						<uri>model://roboy_xylophone_left_arm_mod1/meshes/CAD/left_middle_limb3.stl</uri>
						<scale>0.001 0.001 0.001</scale>
					</mesh>
				</geometry>
			</visual>
		</link>
		<link name="wrist_1">
			<self_collide>false</self_collide>
			<pose frame="">0.9381430427727722 0.0025113835539469797 0.551175684094774 0.0 -0.0 0.0</pose>
			<inertial>
				<pose frame="">0.0 0.0 0.0 0 0 0</pose>
				<mass>0.01273438433820051</mass>
				<inertia>
					<ixx>0.0038741487059941676</ixx>
					<ixy>-3.0003354629486747e-05</ixy>
					<ixz>-1.7637086334391412e-05</ixz>
					<iyy>0.015079859554512439</iyy>
					<iyz>-0.00658477745515705</iyz>
					<izz>0.01121039390101285</izz>
				</inertia>
			</inertial>
			<collision name="wrist_1_collision">
				<geometry>
					<mesh>
						<uri>model://roboy_xylophone_left_arm_mod1/meshes/CAD/wrist_1.stl</uri>
						<scale>0.001 0.001 0.001</scale>
					</mesh>
				</geometry>
			</collision>
			<visual name="wrist_1_visual">
				<geometry>
					<mesh>
						<uri>model://roboy_xylophone_left_arm_mod1/meshes/CAD/wrist_1.stl</uri>
						<scale>0.001 0.001 0.001</scale>
					</mesh>
				</geometry>
			</visual>
		</link>
		<joint name="joint_hip" type="revolute">
			<parent>base</parent>
			<child>torso</child>
			<pose frame="">-0.015198108189375819 0.008698288835840826 -0.3133492459708241 0 0 0</pose>
			<axis>
				<xyz>-2.3609670781633625e-15 -1.1366942706288076e-14 -0.9999999999999987</xyz>
				<limit>
					<lower>-0.2617993877991494</lower>
					<upper>0.2617993877991494</upper>
				</limit>
				<use_parent_model_frame>0</use_parent_model_frame>
			</axis>
		</joint>
		<joint name="sphere_axis0" type="revolute">
			<parent>torso</parent>
			<child>sphere_link1</child>
			<pose frame="">7.105427357601002e-17 -1.8873791418627663e-17 0.0 0 0 0</pose>
			<axis>
				<xyz>1.0000000000000007 2.9478004408376324e-15 6.503044630568056e-16</xyz>
				<limit>
					<lower>-3.141592653589793</lower>
					<upper>3.141592653589793</upper>
				</limit>
				<use_parent_model_frame>0</use_parent_model_frame>
			</axis>
		</joint>
		<joint name="sphere_axis1" type="revolute">
			<parent>sphere_link1</parent>
			<child>sphere_link2</child>
			<pose frame="">-1.4210854715202004e-16 1.1175868952495449e-09 -5.684341886080802e-16 0 0 0</pose>
			<axis>
				<xyz>-2.8112945168822607e-15 0.9999999999999994 -6.411863227862025e-15</xyz>
				<limit>
					<lower>-3.141592653589793</lower>
					<upper>3.141592653589793</upper>
				</limit>
				<use_parent_model_frame>0</use_parent_model_frame>
			</axis>
		</joint>
		<joint name="sphere_axis2" type="revolute">
			<parent>sphere_link2</parent>
			<child>upper_arm_left</child>
			<pose frame="">-0.19319382977484634 0.00010490565903583826 -0.015401773449897505 0 0 0</pose>
			<axis>
				<xyz>1.0000000000000027 2.9132096269750165e-15 4.898425415289509e-16</xyz>
				<limit>
					<lower>-3.141592653589793</lower>
					<upper>3.141592653589793</upper>
				</limit>
				<use_parent_model_frame>0</use_parent_model_frame>
			</axis>
		</joint>
		<joint name="elbow_left" type="revolute">
			<parent>upper_arm_left</parent>
			<child>lower_arm_left</child>
			<pose frame="">-0.14067728957910958 -0.005372933770851843 -0.017589943657655028 0 0 0</pose>
			<axis>
				<xyz>4.2119085996717215e-15 -1.2707667579433074e-15 -1.000000000000003</xyz>
				<limit>
					<lower>-1.5707963267948966</lower>
					<upper>0.0</upper>
				</limit>
				<use_parent_model_frame>0</use_parent_model_frame>
			</axis>
		</joint>
		<joint name="left_joint0_ring" type="revolute">
			<parent>left_ring_limb0</parent>
			<child>left_ring_limb1</child>
			<pose frame="">-0.024545304683130525 -0.006563813722983758 0.0025175292619400123 0 0 0</pose>
			<axis>
				<xyz>-0.46146797046327104 -0.11975952414898122 0.8790363863982736</xyz>
				<limit>
					<lower>-0.3141592653589793</lower>
					<upper>0.3141592653589793</upper>
				</limit>
				<use_parent_model_frame>0</use_parent_model_frame>
			</axis>
		</joint>
		<joint name="left_joint1_ring" type="revolute">
			<parent>left_ring_limb1</parent>
			<child>left_ring_limb2</child>
			<pose frame="">-0.010770245975202358 -0.008584326895309925 -0.001237460336909706 0 0 0</pose>
			<axis>
				<xyz>-0.25874039618535244 0.9659376256577377 -0.004232105923843308</xyz>
				<limit>
					<lower>0.0</lower>
					<upper>1.9198621771937625</upper>
				</limit>
				<use_parent_model_frame>0</use_parent_model_frame>
			</axis>
		</joint>
		<joint name="left_joint2_ring" type="revolute">
			<parent>left_ring_limb2</parent>
			<child>left_ring_limb3</child>
			<pose frame="">-0.006677189144057963 -0.005932251413130953 -0.0006021713650103067 0 0 0</pose>
			<axis>
				<xyz>-0.25874039618535244 0.9659376256577377 -0.004232105923843308</xyz>
				<limit>
					<lower>0.0</lower>
					<upper>1.2217304763960306</upper>
				</limit>
				<use_parent_model_frame>0</use_parent_model_frame>
			</axis>
		</joint>
		<joint name="left_palm_ring" type="revolute">
			<parent>palm</parent>
			<child>left_ring_limb0</child>
			<pose frame="">0.0026262542448772306 -0.00706121619735599 0.00014887577688718067 0 0 0</pose>
			<axis>
				<xyz>0.2587403961853512 -0.9659376256577398 0.004232105923845577</xyz>
				<limit>
					<lower>-1.2217304763960306</lower>
					<upper>0.3490658503988659</upper>
				</limit>
				<use_parent_model_frame>0</use_parent_model_frame>
			</axis>
		</joint>
		<joint name="left_palm_index" type="revolute">
			<parent>palm</parent>
			<child>left_index_limb0</child>
			<pose frame="">-0.0012551093367622456 -0.007425530357765879 0.0002489845926740486 0 0 0</pose>
			<axis>
				<xyz>-0.2587403961853503 -0.9657974405039408 0.016991506640165743</xyz>
				<limit>
					<lower>-1.2217304763960306</lower>
					<upper>0.3490658503988659</upper>
				</limit>
				<use_parent_model_frame>0</use_parent_model_frame>
			</axis>
		</joint>
		<joint name="left_palm_thumb" type="revolute">
			<parent>palm</parent>
			<child>left_thumb_limb0</child>
			<pose frame="">-0.002298231278336118 0.002230807311775087 -0.006820022282424887 0 0 0</pose>
			<axis>
				<xyz>-0.3747941359782817 0.34411640797472204 -0.8608793489211295</xyz>
				<limit>
					<lower>-1.2217304763960306</lower>
					<upper>0.3490658503988659</upper>
				</limit>
				<use_parent_model_frame>0</use_parent_model_frame>
			</axis>
		</joint>
		<joint name="left_palm_little" type="revolute">
			<parent>palm</parent>
			<child>left_little_limb0</child>
			<pose frame="">0.0043530346956653435 -0.006148635480506793 0.00015728603693190735 0 0 0</pose>
			<axis>
				<xyz>-0.4998480619593921 0.8661085479842643 0.0028103494520197447</xyz>
				<limit>
					<lower>0.0</lower>
					<upper>0.0</upper>
				</limit>
				<use_parent_model_frame>0</use_parent_model_frame>
			</axis>
		</joint>
		<joint name="left_palm_middle" type="revolute">
			<parent>palm</parent>
			<child>left_middle_limb0</child>
			<pose frame="">0.0007096119997655137 0.0050002011470932865 6.372127595298593e-05 0 0 0</pose>
			<axis>
				<xyz>5.220838056382111e-16 -0.9999396504300418 0.010986150274885906</xyz>
				<limit>
					<lower>-1.2217304763960306</lower>
					<upper>0.3490658503988659</upper>
				</limit>
				<use_parent_model_frame>0</use_parent_model_frame>
			</axis>
		</joint>
		<joint name="left_wrist_0" type="revolute">
			<parent>lower_arm_left</parent>
			<child>wrist_1</child>
			<pose frame="">0.0011870303046323727 -0.0001093122004946412 -0.009952727365672303 0 0 0</pose>
			<axis>
				<xyz>-0.024650757022313813 -0.010982811846591061 -0.999635792687601</xyz>
				<limit>
					<lower>-0.5235987755982988</lower>
					<upper>0.5235987755982988</upper>
				</limit>
				<use_parent_model_frame>0</use_parent_model_frame>
			</axis>
		</joint>
		<joint name="left_wrist_1" type="revolute">
			<parent>wrist_1</parent>
			<child>palm</child>
			<pose frame="">-0.05213845627521835 -0.018562906472964325 0.0034767223001419723 0 0 0</pose>
			<axis>
				<xyz>-2.991103845618115e-15 0.9999396504300341 -0.010986150274884462</xyz>
				<limit>
					<lower>-0.5235987755982988</lower>
					<upper>0.5235987755982988</upper>
				</limit>
				<use_parent_model_frame>0</use_parent_model_frame>
			</axis>
		</joint>
		<joint name="left_joint0_little" type="revolute">
			<parent>left_little_limb0</parent>
			<child>left_little_limb1</child>
			<pose frame="">-0.02211174774743583 -0.012762118109899108 0.0002983747112573809 0 0 0</pose>
			<axis>
				<xyz>-0.4763881019819201 -0.27763979448656084 0.834248476658803</xyz>
				<limit>
					<lower>-0.3141592653589793</lower>
					<upper>0.3141592653589793</upper>
				</limit>
				<use_parent_model_frame>0</use_parent_model_frame>
			</axis>
		</joint>
		<joint name="left_joint1_little" type="revolute">
			<parent>left_little_limb1</parent>
			<child>left_little_limb2</child>
			<pose frame="">-0.0080520835494535 -0.010989561309224172 -0.002369371339814208 0 0 0</pose>
			<axis>
				<xyz>-0.4998480619593824 0.86610854798426 0.0028103494520253145</xyz>
				<limit>
					<lower>0.0</lower>
					<upper>1.9198621771937625</upper>
				</limit>
				<use_parent_model_frame>0</use_parent_model_frame>
			</axis>
		</joint>
		<joint name="left_joint2_little" type="revolute">
			<parent>left_little_limb2</parent>
			<child>left_little_limb3</child>
			<pose frame="">-0.0048452939670174545 -0.0074103497005320665 -0.0013224211020071409 0 0 0</pose>
			<axis>
				<xyz>-0.4998480619593824 0.86610854798426 0.0028103494520253145</xyz>
				<limit>
					<lower>0.0</lower>
					<upper>1.2217304763960306</upper>
				</limit>
				<use_parent_model_frame>0</use_parent_model_frame>
			</axis>
		</joint>
		<joint name="left_joint0_thumb" type="revolute">
			<parent>left_thumb_limb0</parent>
			<child>left_thumb_limb1</child>
			<pose frame="">-0.01856756186178245 0.0036685782828237644 0.017135936582142648 0 0 0</pose>
			<axis>
				<xyz>-0.7929230725377188 -0.6001519994565747 0.1053118159830213</xyz>
				<limit>
					<lower>-0.3141592653589793</lower>
					<upper>0.3141592653589793</upper>
				</limit>
				<use_parent_model_frame>0</use_parent_model_frame>
			</axis>
		</joint>
		<joint name="left_joint1_thumb" type="revolute">
			<parent>left_thumb_limb1</parent>
			<child>left_thumb_limb2</child>
			<pose frame="">-0.010660633090485448 0.0068700497947800625 0.005510483686277255 0 0 0</pose>
			<axis>
				<xyz>0.5049080217730934 -0.5504095604883767 0.6649189463928508</xyz>
				<limit>
					<lower>0.0</lower>
					<upper>1.9198621771937625</upper>
				</limit>
				<use_parent_model_frame>0</use_parent_model_frame>
			</axis>
		</joint>
		<joint name="left_joint2_thumb" type="revolute">
			<parent>left_thumb_limb2</parent>
			<child>left_thumb_limb3</child>
			<pose frame="">-0.007101220626924913 0.004488788018724556 0.0030923789978729846 0 0 0</pose>
			<axis>
				<xyz>0.5049080217730934 -0.5504095604883767 0.6649189463928508</xyz>
				<limit>
					<lower>0.0</lower>
					<upper>1.2217304763960306</upper>
				</limit>
				<use_parent_model_frame>0</use_parent_model_frame>
			</axis>
		</joint>
		<joint name="left_joint0_index" type="revolute">
			<parent>left_index_limb0</parent>
			<child>left_index_limb1</child>
			<pose frame="">-0.02454537598537513 0.006617511428732624 0.0023727072106842686 0 0 0</pose>
			<axis>
				<xyz>-0.46146797046327337 0.13904390133546574 0.876192961474772</xyz>
				<limit>
					<lower>-0.3141592653589793</lower>
					<upper>0.3141592653589793</upper>
				</limit>
				<use_parent_model_frame>0</use_parent_model_frame>
			</axis>
		</joint>
		<joint name="left_joint1_index" type="revolute">
			<parent>left_index_limb1</parent>
			<child>left_index_limb2</child>
			<pose frame="">-0.01361638519475065 -0.0020686855440200836 -0.0012388610639534647 0 0 0</pose>
			<axis>
				<xyz>0.25874039618534495 0.9657974405039322 -0.0169915066401637</xyz>
				<limit>
					<lower>0.0</lower>
					<upper>1.9198621771937625</upper>
				</limit>
				<use_parent_model_frame>0</use_parent_model_frame>
			</axis>
		</joint>
		<joint name="left_joint2_index" type="revolute">
			<parent>left_index_limb2</parent>
			<child>left_index_limb3</child>
			<pose frame="">-0.008747098058428975 -0.001808745300647212 -0.0005964299472830703 0 0 0</pose>
			<axis>
				<xyz>0.25874039618534495 0.9657974405039322 -0.0169915066401637</xyz>
				<limit>
					<lower>0.0</lower>
					<upper>1.2217304763960306</upper>
				</limit>
				<use_parent_model_frame>0</use_parent_model_frame>
			</axis>
		</joint>
		<joint name="left_joint0_middle" type="revolute">
			<parent>left_middle_limb0</parent>
			<child>left_middle_limb1</child>
			<pose frame="">-0.025412723852475522 2.7072860091374994e-05 0.0024665354738876034 0 0 0</pose>
			<axis>
				<xyz>-0.4784998801555457 0.009646802524652031 0.8780346256795207</xyz>
				<limit>
					<lower>-0.6108652381980153</lower>
					<upper>0.6108652381980153</upper>
				</limit>
				<use_parent_model_frame>0</use_parent_model_frame>
			</axis>
		</joint>
		<joint name="left_joint1_middle" type="revolute">
			<parent>left_middle_limb1</parent>
			<child>left_middle_limb2</child>
			<pose frame="">-0.012622057863040367 -0.0055137865084427685 -0.001225531045332744 0 0 0</pose>
			<axis>
				<xyz>-3.0054773437808113e-16 0.9999396504300321 -0.010986150274885857</xyz>
				<limit>
					<lower>0.0</lower>
					<upper>1.9198621771937625</upper>
				</limit>
				<use_parent_model_frame>0</use_parent_model_frame>
			</axis>
		</joint>
		<joint name="left_joint2_middle" type="revolute">
			<parent>left_middle_limb2</parent>
			<child>left_middle_limb3</child>
			<pose frame="">-0.007983486745312405 -0.004006708896216819 -0.0005911120527350278 0 0 0</pose>
			<axis>
				<xyz>-3.0054773437808113e-16 0.9999396504300321 -0.010986150274885857</xyz>
				<limit>
					<lower>0.0</lower>
					<upper>1.2217304763960306</upper>
				</limit>
				<use_parent_model_frame>0</use_parent_model_frame>
			</axis>
		</joint>
		<plugin filename="libmusc_plugin.so" name="musc_plugin">
			<myoMuscle name="motor13">
				<link name="base">
					<viaPoint type="FIXPOINT">-0.19000202816879327 -0.11915077222472809 0.0627057204610111</viaPoint>
				</link>
				<link name="torso">
					<viaPoint type="FIXPOINT">0.12024065640872804 -0.05490491677623366 -0.06975450453399169</viaPoint>
				</link>
			</myoMuscle>
			<myoMuscle name="motor14">
				<link name="base">
					<viaPoint type="FIXPOINT">0.1999979688604362 -0.11915077222472807 0.06270572046101107</viaPoint>
				</link>
				<link name="torso">
					<viaPoint type="FIXPOINT">-0.15183709675472692 -0.05282874336285322 -0.07155699347598792</viaPoint>
				</link>
			</myoMuscle>
			<myoMuscle name="motor15">
				<link name="base">
					<viaPoint type="FIXPOINT">-0.22000203113956324 -0.004150772224728123 0.06270572046101192</viaPoint>
				</link>
				<link name="torso">
					<viaPoint type="FIXPOINT">-0.165281069233455 0.0071784460068836774 -0.08097356453703287</viaPoint>
				</link>
			</myoMuscle>
			<myoMuscle name="motor16">
				<link name="base">
					<viaPoint type="FIXPOINT">0.22999797183120632 -0.004150772224728004 0.06270572046101192</viaPoint>
				</link>
				<link name="torso">
					<viaPoint type="FIXPOINT">0.1348848528547065 0.00717844600688456 -0.0809735645370326</viaPoint>
				</link>
			</myoMuscle>
			<myoMuscle name="motor17">
				<link name="base">
					<viaPoint type="FIXPOINT">-0.19000202816879314 0.1108492277752719 0.06270572046101273</viaPoint>
				</link>
				<link name="torso">
					<viaPoint type="FIXPOINT">0.10325913154072165 0.07434710297653763 -0.09942789904309972</viaPoint>
				</link>
			</myoMuscle>
			<myoMuscle name="motor18">
				<link name="base">
					<viaPoint type="FIXPOINT">0.19999796886043636 0.11084922777527174 0.06270572046101273</viaPoint>
				</link>
				<link name="torso">
					<viaPoint type="FIXPOINT">-0.13063936554906186 0.07575192078770289 -0.10316023574532977</viaPoint>
				</link>
			</myoMuscle>
			<myoMuscle name="motor0">
				<link name="torso">
					<viaPoint type="FIXPOINT">0.2789674376273844 -0.0184778766885068 0.19083235082882566</viaPoint>
				</link>
				<link name="upper_arm_left">
					<viaPoint type="FIXPOINT">-0.09647114289182454 -0.028955066410141523 0.018956893918598325</viaPoint>
				</link>
			</myoMuscle>
			<myoMuscle name="motor1">
				<link name="torso">
					<viaPoint type="FIXPOINT">0.22816816562862838 -0.042784065678938915 0.06322130964625622</viaPoint>
				</link>
				<link name="upper_arm_left">
					<viaPoint type="FIXPOINT">-0.09647114289182454 -0.026537891436425022 -0.042284652564971596</viaPoint>
				</link>
			</myoMuscle>
			<myoMuscle name="motor2">
				<link name="torso">
					<viaPoint type="FIXPOINT">0.2438039780035806 -0.04995105559477545 0.13417499293350615</viaPoint>
				</link>
				<link name="upper_arm_left">
					<viaPoint type="FIXPOINT">-0.09647114289182454 -0.0448950943409638 -0.015401773449896156</viaPoint>
				</link>
			</myoMuscle>
			<myoMuscle name="motor3">
				<link name="torso">
					<viaPoint type="FIXPOINT">0.2655073716575845 -0.04395723129771427 0.16270735082882581</viaPoint>
				</link>
				<link name="upper_arm_left">
					<viaPoint type="FIXPOINT">-0.1129711428918246 0.00010490565903618133 0.00439822655010353</viaPoint>
				</link>
			</myoMuscle>
			<myoMuscle name="motor4">
				<link name="torso">
					<viaPoint type="FIXPOINT">0.2881953945360196 0.0071784460068867045 0.19889432629018744</viaPoint>
				</link>
				<link name="upper_arm_left">
					<viaPoint type="FIXPOINT">-0.09647114289182468 0.00010490565903634008 0.02959822655010356</viaPoint>
				</link>
			</myoMuscle>
			<myoMuscle name="motor8">
				<link name="torso">
					<viaPoint type="FIXPOINT">0.2781715133457512 0.036771931902764954 0.19188477376245844</viaPoint>
				</link>
				<link name="upper_arm_left">
					<viaPoint type="FIXPOINT">-0.1129711428918246 0.00010490565903618133 0.00439822655010353</viaPoint>
				</link>
			</myoMuscle>
			<myoMuscle name="motor5">
				<link name="torso">
					<viaPoint type="FIXPOINT">0.26550737165758415 0.0633594779206885 0.1627073508288251</viaPoint>
				</link>
				<link name="upper_arm_left">
					<viaPoint type="FIXPOINT">-0.09647114289182476 0.029164877728214106 0.01895689391859797</viaPoint>
				</link>
			</myoMuscle>
			<myoMuscle name="motor6">
				<link name="torso">
					<viaPoint type="FIXPOINT">0.24380397800358178 0.05757644014502038 0.13417499293349508</viaPoint>
				</link>
				<link name="upper_arm_left">
					<viaPoint type="FIXPOINT">-0.09647114289182483 0.04510490565903609 -0.015401773449896723</viaPoint>
				</link>
			</myoMuscle>
			<myoMuscle name="motor7">
				<link name="torso">
					<viaPoint type="FIXPOINT">0.228168165628628 0.07074343006085633 0.06322130964625586</viaPoint>
				</link>
				<link name="upper_arm_left">
					<viaPoint type="FIXPOINT">-0.09647114289182468 0.026747702754473433 -0.04228465256492441</viaPoint>
				</link>
			</myoMuscle>
			<myoMuscle name="motor9">
				<link name="upper_arm_left">
					<viaPoint type="FIXPOINT">0.03266361081514134 -0.06427564937854097 -0.009436425974584708</viaPoint>
				</link>
				<link name="lower_arm_left">
					<viaPoint type="FIXPOINT">-0.11567728957911058 -0.010497545568349633 -0.0001899436576555047</viaPoint>
				</link>
			</myoMuscle>
			<myoMuscle name="motor10">
				<link name="upper_arm_left">
					<viaPoint type="FIXPOINT">0.032663610815138994 0.06448546068613198 -0.004617120925203296</viaPoint>
				</link>
				<link name="lower_arm_left">
					<viaPoint type="FIXPOINT">-0.11567728957911072 0.02762706679539258 -0.00018994365765543365</viaPoint>
				</link>
			</myoMuscle>
		</plugin>
	</model>
</sdf>
