<?xml version="1.0" ?>
<sdf version="1.6">
	<model name="roboy_xylophone_left_arm_mod1">
		<link name="base">
			<self_collide>false</self_collide>
			<pose frame="">-0.004997970345821523 0.0056731157257543545 0.024531453030641522 0.0 -0.0 0.0</pose>
			<inertial>
				<pose frame="">0.0 0.0 0.0 0 0 0</pose>
				<mass>1041.2293594077037</mass>
				<inertia>
					<ixx>194.34233377142357</ixx>
					<ixy>0.02954008126913404</ixy>
					<ixz>-0.1448651839771172</ixz>
					<iyy>194.3430419147966</iyy>
					<iyz>0.12760282012593194</iyz>
					<izz>386.9973235859432</izz>
				</inertia>
			</inertial>
			<collision name="base_collision">
				<geometry>
					<mesh>
						<uri>model://roboy_xylophone_left_arm_mod1/meshes/CAD/base.stl</uri>
						<scale>0.001 0.001 0.001</scale>
					</mesh>
				</geometry>
			</collision>
			<visual name="base_visual">
				<geometry>
					<mesh>
						<uri>model://roboy_xylophone_left_arm_mod1/meshes/CAD/base.stl</uri>
						<scale>0.001 0.001 0.001</scale>
					</mesh>
				</geometry>
			</visual>
		</link>
		<link name="lower_arm_left">
			<self_collide>false</self_collide>
			<pose frame="">0.7074785593276005 0.005886251741667762 0.5537529620717708 0.0 -0.0 0.0</pose>
			<inertial>
				<pose frame="">0.0 0.0 0.0 0 0 0</pose>
				<mass>0.1639662034797443</mass>
				<inertia>
					<ixx>0.05034721504021259</ixx>
					<ixy>-0.0006621993367307967</ixy>
					<ixz>-0.0005324601737404497</ixz>
					<iyy>0.13286266410585928</iyy>
					<iyz>-0.06422948881147728</iyz>
					<izz>0.08257147674550085</izz>
				</inertia>
			</inertial>
			<collision name="lower_arm_left_collision">
				<geometry>
					<mesh>
						<uri>model://roboy_xylophone_left_arm_mod1/meshes/CAD/lower_arm_left.stl</uri>
						<scale>0.001 0.001 0.001</scale>
					</mesh>
				</geometry>
			</collision>
			<visual name="lower_arm_left_visual">
				<geometry>
					<mesh>
						<uri>model://roboy_xylophone_left_arm_mod1/meshes/CAD/lower_arm_left.stl</uri>
						<scale>0.001 0.001 0.001</scale>
					</mesh>
				</geometry>
			</visual>
		</link>
		<link name="upper_arm_left">
			<self_collide>false</self_collide>
			<pose frame="">0.49410937559160617 0.002420271200049729 0.5630545724963112 0.0 -0.0 0.0</pose>
			<inertial>
				<pose frame="">0.0 0.0 0.0 0 0 0</pose>
				<mass>1.4066729970235903</mass>
				<inertia>
					<ixx>0.4486374428979241</ixx>
					<ixy>-0.0017035468355952727</ixy>
					<ixz>-0.001934638909202926</ixz>
					<iyy>0.7975932001439735</iyy>
					<iyz>-0.3917077745810474</iyz>
					<izz>0.352867754950354</izz>
				</inertia>
			</inertial>
			<collision name="upper_arm_left_collision">
				<geometry>
					<mesh>
						<uri>model://roboy_xylophone_left_arm_mod1/meshes/CAD/upper_arm_left.stl</uri>
						<scale>0.001 0.001 0.001</scale>
					</mesh>
				</geometry>
			</collision>
			<visual name="upper_arm_left_visual">
				<geometry>
					<mesh>
						<uri>model://roboy_xylophone_left_arm_mod1/meshes/CAD/upper_arm_left.stl</uri>
						<scale>0.001 0.001 0.001</scale>
					</mesh>
				</geometry>
			</visual>
		</link>
		<link name="torso">
			<self_collide>false</self_collide>
			<pose frame="">0.015198108189375828 -0.007175945334814449 0.3965864194624781 0.0 -0.0 0.0</pose>
			<inertial>
				<pose frame="">0.0 0.0 0.0 0 0 0</pose>
				<mass>15.80321284930236</mass>
				<inertia>
					<ixx>2.886226976262021</ixx>
					<ixy>-0.0012761288622997653</ixy>
					<ixz>0.04534177387941487</ixz>
					<iyy>3.1166228699862777</iyy>
					<iyz>-0.12034199282146522</iyz>
					<izz>0.3103078136361685</izz>
				</inertia>
			</inertial>
			<collision name="torso_collision">
				<geometry>
					<mesh>
						<uri>model://roboy_xylophone_left_arm_mod1/meshes/CAD/torso.stl</uri>
						<scale>0.001 0.001 0.001</scale>
					</mesh>
				</geometry>
			</collision>
			<visual name="torso_visual">
				<geometry>
					<mesh>
						<uri>model://roboy_xylophone_left_arm_mod1/meshes/CAD/torso.stl</uri>
						<scale>0.001 0.001 0.001</scale>
					</mesh>
				</geometry>
			</visual>
		</link>
		<link name="sphere_link1">
			<self_collide>false</self_collide>
			<pose frame="">0.30091554581676005 0.0025251779766726646 0.5476527990464143 0.0 -0.0 0.0</pose>
			<inertial>
				<pose frame="">0.0 0.0 0.0 0 0 0</pose>
				<mass>0.046754103129628445</mass>
				<inertia>
					<ixx>0.014028930499989191</ixx>
					<ixy>-3.55268210279209e-05</ixy>
					<ixz>-6.465722109621308e-05</ixz>
					<iyy>0.018262224157543774</iyy>
					<iyz>-0.0077049471985332334</iyz>
					<izz>0.004239863907651701</izz>
				</inertia>
			</inertial>
			<collision name="sphere_link1_collision">
				<geometry>
					<mesh>
						<uri>model://roboy_xylophone_left_arm_mod1/meshes/CAD/sphere_link1.stl</uri>
						<scale>0.001 0.001 0.001</scale>
					</mesh>
				</geometry>
			</collision>
			<visual name="sphere_link1_visual">
				<geometry>
					<mesh>
						<uri>model://roboy_xylophone_left_arm_mod1/meshes/CAD/sphere_link1.stl</uri>
						<scale>0.001 0.001 0.001</scale>
					</mesh>
				</geometry>
			</visual>
		</link>
		<link name="sphere_link2">
			<self_collide>false</self_collide>
			<pose frame="">0.30091554581676017 0.0025251768590857553 0.547652799046415 0.0 -0.0 0.0</pose>
			<inertial>
				<pose frame="">0.0 0.0 0.0 0 0 0</pose>
				<mass>0.031340659211905667</mass>
				<inertia>
					<ixx>0.009402701451181468</ixx>
					<ixy>-2.3814669160705768e-05</ixy>
					<ixz>-4.334162992086414e-05</ixz>
					<iyy>0.012240403492128835</iyy>
					<iyz>-0.005164854167460886</iyz>
					<izz>0.002840800365783859</izz>
				</inertia>
			</inertial>
			<collision name="sphere_link2_collision">
				<geometry>
					<mesh>
						<uri>model://roboy_xylophone_left_arm_mod1/meshes/CAD/sphere_link2.stl</uri>
						<scale>0.001 0.001 0.001</scale>
					</mesh>
				</geometry>
			</collision>
			<visual name="sphere_link2_visual">
				<geometry>
					<mesh>
						<uri>model://roboy_xylophone_left_arm_mod1/meshes/CAD/sphere_link2.stl</uri>
						<scale>0.001 0.001 0.001</scale>
					</mesh>
				</geometry>
			</visual>
		</link>
		<joint name="joint_hip" type="revolute">
			<parent>base</parent>
			<child>torso</child>
			<pose frame="">-0.015198108189375819 0.008698288835840826 -0.3133492459708241 0 0 0</pose>
			<axis>
				<xyz>-2.3609670781633625e-15 -1.1366942706288076e-14 -0.9999999999999987</xyz>
				<limit>
					<lower>-0.2617993877991494</lower>
					<upper>0.2617993877991494</upper>
				</limit>
				<use_parent_model_frame>0</use_parent_model_frame>
			</axis>
		</joint>
		<joint name="elbow_left" type="revolute">
			<parent>upper_arm_left</parent>
			<child>lower_arm_left</child>
			<pose frame="">-0.05744711788316309 -0.008361074877345744 -0.018725163025357646 0 0 0</pose>
			<axis>
				<xyz>4.2119085996717215e-15 -1.2707667579433074e-15 -1.000000000000003</xyz>
				<limit>
					<lower>-1.5707963267948966</lower>
					<upper>0.0</upper>
				</limit>
				<use_parent_model_frame>0</use_parent_model_frame>
			</axis>
		</joint>
		<joint name="sphere_axis0" type="revolute">
			<parent>torso</parent>
			<child>sphere_link1</child>
			<pose frame="">7.105427357601002e-17 -1.8873791418627663e-17 0.0 0 0 0</pose>
			<axis>
				<xyz>1.0000000000000007 2.9478004408376324e-15 6.503044630568056e-16</xyz>
				<limit>
					<lower>-3.141592653589793</lower>
					<upper>3.141592653589793</upper>
				</limit>
				<use_parent_model_frame>0</use_parent_model_frame>
			</axis>
		</joint>
		<joint name="sphere_axis1" type="revolute">
			<parent>sphere_link1</parent>
			<child>sphere_link2</child>
			<pose frame="">-1.4210854715202004e-16 1.1175868952495449e-09 -5.684341886080802e-16 0 0 0</pose>
			<axis>
				<xyz>-2.8112945168822607e-15 0.9999999999999994 -6.411863227862025e-15</xyz>
				<limit>
					<lower>-3.141592653589793</lower>
					<upper>3.141592653589793</upper>
				</limit>
				<use_parent_model_frame>0</use_parent_model_frame>
			</axis>
		</joint>
		<joint name="sphere_axis2" type="revolute">
			<parent>sphere_link2</parent>
			<child>upper_arm_left</child>
			<pose frame="">-0.19319382977484634 0.00010490565903583826 -0.015401773449897505 0 0 0</pose>
			<axis>
				<xyz>1.0000000000000027 2.9132096269750165e-15 4.898425415289509e-16</xyz>
				<limit>
					<lower>-3.141592653589793</lower>
					<upper>3.141592653589793</upper>
				</limit>
				<use_parent_model_frame>0</use_parent_model_frame>
			</axis>
		</joint>
		<plugin filename="libmusc_plugin.so" name="musc_plugin"/>
	</model>
</sdf>
