<?xml version="1.0" ?>
<sdf version="1.6">
	<model name="Roboy">
		<link name="head">
			<pose frame="">0.0 0.0 0.0 1.5707963267948966 -0.0 0.0</pose>
			<inertial>
				<pose frame="">0.023571437214992663 1.2465899410800116 -0.22738269536338176 0 0 0</pose>
				<mass>18.11034232113242</mass>
				<inertia>
					<ixx>28.786027593799513</ixx>
					<ixy>-1.1312940060704681</ixy>
					<ixz>5.1583412996080344</ixz>
					<iyy>0.4595995776166581</iyy>
					<iyz>0.08958691560358395</iyz>
					<izz>27.074399624583446</izz>
				</inertia>
			</inertial>
			<collision name="head_collision">
				<geometry>
					<mesh>
						<uri>model://Roboy/meshes/head.stl</uri>
						<scale>0.001 0.001 0.001</scale>
					</mesh>
				</geometry>
			</collision>
			<visual name="head_visual">
				<geometry>
					<mesh>
						<uri>model://Roboy/meshes/head.stl</uri>
						<scale>0.001 0.001 0.001</scale>
					</mesh>
				</geometry>
			</visual>
		</link>
		<link name="hip">
			<pose frame="">0.0 0.0 0.0 1.5707963267948966 -0.0 0.0</pose>
			<inertial>
				<pose frame="">0.03659595134610397 0.5627885940489307 -0.10984848852084614 0 0 0</pose>
				<mass>10.217368771370289</mass>
				<inertia>
					<ixx>-95.19698775757999</ixx>
					<ixy>2.3279527357220955</ixy>
					<ixz>16.26183246977962</ixz>
					<iyy>-98.37338627543043</iyy>
					<iyz>15.64553591337368</iyz>
					<izz>-1.743575525425945</izz>
				</inertia>
			</inertial>
			<collision name="hip_collision">
				<geometry>
					<mesh>
						<uri>model://Roboy/meshes/hip.stl</uri>
						<scale>0.001 0.001 0.001</scale>
					</mesh>
				</geometry>
			</collision>
			<visual name="hip_visual">
				<geometry>
					<mesh>
						<uri>model://Roboy/meshes/hip.stl</uri>
						<scale>0.001 0.001 0.001</scale>
					</mesh>
				</geometry>
			</visual>
		</link>
		<link name="shank_right">
			<pose frame="">0.0 0.0 0.0 1.5707963267948966 -0.0 0.0</pose>
			<inertial>
				<pose frame="">-0.06511817927013205 0.15080031463219562 -0.11944518564349413 0 0 0</pose>
				<mass>4.696375065355998</mass>
				<inertia>
					<ixx>0.19711550954410864</ixx>
					<ixy>0.04473206618134859</ixy>
					<ixz>0.08371883049587618</ixz>
					<iyy>0.09157833899724709</iyy>
					<iyz>-0.0366643727017391</iyz>
					<izz>0.14938842126564142</izz>
				</inertia>
			</inertial>
			<collision name="shank_right_collision">
				<geometry>
					<mesh>
						<uri>model://Roboy/meshes/shank_right.stl</uri>
						<scale>0.001 0.001 0.001</scale>
					</mesh>
				</geometry>
			</collision>
			<visual name="shank_right_visual">
				<geometry>
					<mesh>
						<uri>model://Roboy/meshes/shank_right.stl</uri>
						<scale>0.001 0.001 0.001</scale>
					</mesh>
				</geometry>
			</visual>
		</link>
		<link name="shank_left">
			<pose frame="">0.0 0.0 0.0 1.5707963267948966 -0.0 0.0</pose>
			<inertial>
				<pose frame="">0.12115800288930531 0.14927006411800894 -0.14983924893079495 0 0 0</pose>
				<mass>4.679812674540854</mass>
				<inertia>
					<ixx>0.23260850753931336</ixx>
					<ixy>-0.08398446547497769</ixy>
					<ixz>0.10348070151421339</ixz>
					<iyy>0.17834991758438296</iyy>
					<iyz>0.08485336642852137</iyz>
					<izz>0.1955501676533839</izz>
				</inertia>
			</inertial>
			<collision name="shank_left_collision">
				<geometry>
					<mesh>
						<uri>model://Roboy/meshes/shank_left.stl</uri>
						<scale>0.001 0.001 0.001</scale>
					</mesh>
				</geometry>
			</collision>
			<visual name="shank_left_visual">
				<geometry>
					<mesh>
						<uri>model://Roboy/meshes/shank_left.stl</uri>
						<scale>0.001 0.001 0.001</scale>
					</mesh>
				</geometry>
			</visual>
		</link>
		<link name="vertebrae_2">
			<pose frame="">0.0 0.0 0.0 1.5707963267948966 -0.0 0.0</pose>
			<inertial>
				<pose frame="">0.02770116149030597 0.6084280628284916 -0.16877200693278557 0 0 0</pose>
				<mass>1.752588336432269</mass>
				<inertia>
					<ixx>0.6998594743273927</ixx>
					<ixy>-0.0295320443209151</ixy>
					<ixz>0.17997269214519634</ixz>
					<iyy>0.0529391669104827</iyy>
					<iyz>0.008197412403892566</iyz>
					<izz>0.6513059223185472</izz>
				</inertia>
			</inertial>
			<collision name="vertebrae_2_collision">
				<geometry>
					<mesh>
						<uri>model://Roboy/meshes/vertebrae_2.stl</uri>
						<scale>0.001 0.001 0.001</scale>
					</mesh>
				</geometry>
			</collision>
			<visual name="vertebrae_2_visual">
				<geometry>
					<mesh>
						<uri>model://Roboy/meshes/vertebrae_2.stl</uri>
						<scale>0.001 0.001 0.001</scale>
					</mesh>
				</geometry>
			</visual>
		</link>
		<link name="vertebrae_1">
			<pose frame="">0.0 0.0 0.0 1.5707963267948966 -0.0 0.0</pose>
			<inertial>
				<pose frame="">0.02703809125427215 0.5609332619803598 -0.1697552167070611 0 0 0</pose>
				<mass>1.6729638794350459</mass>
				<inertia>
					<ixx>0.5756534225507213</ixx>
					<ixy>-0.025366100138682037</ixy>
					<ixz>0.15931579132014212</ixz>
					<iyy>0.05096036087612898</iyy>
					<iyz>0.007684731240684977</iyz>
					<izz>0.5287091806634868</izz>
				</inertia>
			</inertial>
			<collision name="vertebrae_1_collision">
				<geometry>
					<mesh>
						<uri>model://Roboy/meshes/vertebrae_1.stl</uri>
						<scale>0.001 0.001 0.001</scale>
					</mesh>
				</geometry>
			</collision>
			<visual name="vertebrae_1_visual">
				<geometry>
					<mesh>
						<uri>model://Roboy/meshes/vertebrae_1.stl</uri>
						<scale>0.001 0.001 0.001</scale>
					</mesh>
				</geometry>
			</visual>
		</link>
		<link name="vertebrae_3">
			<pose frame="">0.0 0.0 0.0 1.5707963267948966 -0.0 0.0</pose>
			<inertial>
				<pose frame="">0.028064354822574817 0.6502737117012233 -0.1690427637999387 0 0 0</pose>
				<mass>1.3931202571321817</mass>
				<inertia>
					<ixx>0.6297992171663626</ixx>
					<ixy>-0.02542129377113573</ixy>
					<ixz>0.15311885811832826</ixz>
					<iyy>0.0423310148522969</iyy>
					<iyz>0.006614949758113972</iyz>
					<izz>0.5911239006293919</izz>
				</inertia>
			</inertial>
			<collision name="vertebrae_3_collision">
				<geometry>
					<mesh>
						<uri>model://Roboy/meshes/vertebrae_3.stl</uri>
						<scale>0.001 0.001 0.001</scale>
					</mesh>
				</geometry>
			</collision>
			<visual name="vertebrae_3_visual">
				<geometry>
					<mesh>
						<uri>model://Roboy/meshes/vertebrae_3.stl</uri>
						<scale>0.001 0.001 0.001</scale>
					</mesh>
				</geometry>
			</visual>
		</link>
		<link name="neck">
			<pose frame="">0.0 0.0 0.0 1.5707963267948966 -0.0 0.0</pose>
			<inertial>
				<pose frame="">0.02963662446730735 1.103354886028912 -0.19460676277245395 0 0 0</pose>
				<mass>1.6461973968703334</mass>
				<inertia>
					<ixx>2.0682593789533557</ixx>
					<ixy>-0.053965781199412234</ixy>
					<ixz>0.35325421794001416</ixz>
					<iyy>0.06543901466739603</iyy>
					<iyz>0.009627020261738176</iyz>
					<izz>2.0079749408394534</izz>
				</inertia>
			</inertial>
			<collision name="neck_collision">
				<geometry>
					<mesh>
						<uri>model://Roboy/meshes/neck.stl</uri>
						<scale>0.001 0.001 0.001</scale>
					</mesh>
				</geometry>
			</collision>
			<visual name="neck_visual">
				<geometry>
					<mesh>
						<uri>model://Roboy/meshes/neck.stl</uri>
						<scale>0.001 0.001 0.001</scale>
					</mesh>
				</geometry>
			</visual>
		</link>
		<link name="neck_cross">
			<pose frame="">0.0 0.0 0.0 1.5707963267948966 -0.0 0.0</pose>
			<inertial>
				<pose frame="">0.02683383519611858 1.051524342938588 -0.20015902455965015 0 0 0</pose>
				<mass>0.030866750402122216</mass>
				<inertia>
					<ixx>0.03536715342112325</ixx>
					<ixy>-0.0008709486967686622</ixy>
					<ixz>0.006496499375523114</ixz>
					<iyy>0.0012613788546759334</iyy>
					<iyz>0.00016595074197893833</iyz>
					<izz>0.03415370481697983</izz>
				</inertia>
			</inertial>
			<collision name="neck_cross_collision">
				<geometry>
					<mesh>
						<uri>model://Roboy/meshes/neck_cross.stl</uri>
						<scale>0.001 0.001 0.001</scale>
					</mesh>
				</geometry>
			</collision>
			<visual name="neck_cross_visual">
				<geometry>
					<mesh>
						<uri>model://Roboy/meshes/neck_cross.stl</uri>
						<scale>0.001 0.001 0.001</scale>
					</mesh>
				</geometry>
			</visual>
		</link>
		<link name="spine">
			<pose frame="">0.0 0.0 0.0 1.5707963267948966 -0.0 0.0</pose>
			<inertial>
				<pose frame="">0.02996428241146622 0.8164387046928316 -0.16752739437080585 0 0 0</pose>
				<mass>9.77570275765994</mass>
				<inertia>
					<ixx>6.930864026023202</ixx>
					<ixy>-0.23618567108101413</ixy>
					<ixz>1.3619119546192304</ixz>
					<iyy>0.31417660596022334</iyy>
					<iyz>0.05048815514486116</iyz>
					<izz>6.672411598638095</izz>
				</inertia>
			</inertial>
			<collision name="spine_collision">
				<geometry>
					<mesh>
						<uri>model://Roboy/meshes/spine.stl</uri>
						<scale>0.001 0.001 0.001</scale>
					</mesh>
				</geometry>
			</collision>
			<visual name="spine_visual">
				<geometry>
					<mesh>
						<uri>model://Roboy/meshes/spine.stl</uri>
						<scale>0.001 0.001 0.001</scale>
					</mesh>
				</geometry>
			</visual>
		</link>
		<link name="thigh_right">
			<pose frame="">0.0 0.0 0.0 1.5707963267948966 -0.0 0.0</pose>
			<inertial>
				<pose frame="">-0.07576422893151788 0.4152930126947152 -0.1156285678074049 0 0 0</pose>
				<mass>6.834516066711095</mass>
				<inertia>
					<ixx>1.316039028633693</ixx>
					<ixy>0.22282087603285336</ixy>
					<ixz>0.32944921131688426</ixz>
					<iyy>0.14120916502625053</iyy>
					<iyz>-0.05919014838100924</iyz>
					<izz>1.2653828457724037</izz>
				</inertia>
			</inertial>
			<collision name="thigh_right_collision">
				<geometry>
					<mesh>
						<uri>model://Roboy/meshes/thigh_right.stl</uri>
						<scale>0.001 0.001 0.001</scale>
					</mesh>
				</geometry>
			</collision>
			<visual name="thigh_right_visual">
				<geometry>
					<mesh>
						<uri>model://Roboy/meshes/thigh_right.stl</uri>
						<scale>0.001 0.001 0.001</scale>
					</mesh>
				</geometry>
			</visual>
		</link>
		<link name="thigh_left">
			<pose frame="">0.0 0.0 0.0 1.5707963267948966 -0.0 0.0</pose>
			<inertial>
				<pose frame="">0.1392541436816421 0.41310517501913235 -0.15063424719015914 0 0 0</pose>
				<mass>6.809681345808586</mass>
				<inertia>
					<ixx>1.361824550560152</ixx>
					<ixy>-0.39939599087462263</ixy>
					<ixz>0.4274156983653904</ixz>
					<iyy>0.2973725224110751</iyy>
					<iyz>0.14281948386746643</iyz>
					<izz>1.3416133077949313</izz>
				</inertia>
			</inertial>
			<collision name="thigh_left_collision">
				<geometry>
					<mesh>
						<uri>model://Roboy/meshes/thigh_left.stl</uri>
						<scale>0.001 0.001 0.001</scale>
					</mesh>
				</geometry>
			</collision>
			<visual name="thigh_left_visual">
				<geometry>
					<mesh>
						<uri>model://Roboy/meshes/thigh_left.stl</uri>
						<scale>0.001 0.001 0.001</scale>
					</mesh>
				</geometry>
			</visual>
		</link>
		<link name="torso">
			<pose frame="">0.0 0.0 0.0 1.5707963267948966 -0.0 0.0</pose>
			<inertial>
				<pose frame="">0.025882558243580874 0.9136407175078232 -0.17927700338600236 0 0 0</pose>
				<mass>32.14010572792724</mass>
				<inertia>
					<ixx>28.151848625158333</ixx>
					<ixy>-0.7591863281607107</ixy>
					<ixz>5.271330040238268</ixz>
					<iyy>1.5616413679833383</iyy>
					<iyz>0.20714595785177514</iyz>
					<izz>27.49241507949091</izz>
				</inertia>
			</inertial>
			<collision name="torso_collision">
				<geometry>
					<mesh>
						<uri>model://Roboy/meshes/torso.stl</uri>
						<scale>0.001 0.001 0.001</scale>
					</mesh>
				</geometry>
			</collision>
			<visual name="torso_visual">
				<geometry>
					<mesh>
						<uri>model://Roboy/meshes/torso.stl</uri>
						<scale>0.001 0.001 0.001</scale>
					</mesh>
				</geometry>
			</visual>
		</link>
		<link name="upper_arm_right">
			<pose frame="">0.0 0.0 0.0 1.5707963267948966 -0.0 0.0</pose>
			<inertial>
				<pose frame="">-0.17396916651503244 0.842317412523118 -0.12805413931685103 0 0 0</pose>
				<mass>3.2119283501886122</mass>
				<inertia>
					<ixx>2.3437368651302712</ixx>
					<ixy>0.4708436890430496</ixy>
					<ixz>0.3471788709091111</ixz>
					<iyy>0.15223417446013543</iyy>
					<iyz>-0.07174132455407288</iyz>
					<izz>2.389276393457405</izz>
				</inertia>
			</inertial>
			<collision name="upper_arm_right_collision">
				<geometry>
					<mesh>
						<uri>model://Roboy/meshes/upper_arm_right.stl</uri>
						<scale>0.001 0.001 0.001</scale>
					</mesh>
				</geometry>
			</collision>
			<visual name="upper_arm_right_visual">
				<geometry>
					<mesh>
						<uri>model://Roboy/meshes/upper_arm_right.stl</uri>
						<scale>0.001 0.001 0.001</scale>
					</mesh>
				</geometry>
			</visual>
		</link>
		<link name="hand_right">
			<pose frame="">0.0 0.0 0.0 1.5707963267948966 -0.0 0.0</pose>
			<inertial>
				<pose frame="">-0.15094250496707223 0.7635630047612736 0.08508567662548876 0 0 0</pose>
				<mass>1.0988889973094953</mass>
				<inertia>
					<ixx>0.6525296222160535</ixx>
					<ixy>0.1266158012799918</ixy>
					<ixz>-0.07178655707652483</ixz>
					<iyy>0.03741098309411624</iyy>
					<iyz>0.013048100734472436</iyz>
					<izz>0.6667060153775621</izz>
				</inertia>
			</inertial>
			<collision name="hand_right_collision">
				<geometry>
					<mesh>
						<uri>model://Roboy/meshes/hand_right.stl</uri>
						<scale>0.001 0.001 0.001</scale>
					</mesh>
				</geometry>
			</collision>
			<visual name="hand_right_visual">
				<geometry>
					<mesh>
						<uri>model://Roboy/meshes/hand_right.stl</uri>
						<scale>0.001 0.001 0.001</scale>
					</mesh>
				</geometry>
			</visual>
		</link>
		<link name="lower_arm_right">
			<pose frame="">0.0 0.0 0.0 1.5707963267948966 -0.0 0.0</pose>
			<inertial>
				<pose frame="">-0.16516908217832943 0.7365533196874163 -0.06088765578848913 0 0 0</pose>
				<mass>0.6108772862498815</mass>
				<inertia>
					<ixx>0.3345863393388877</ixx>
					<ixy>0.07433793609706035</ixy>
					<ixz>0.02745145644602671</ixz>
					<iyy>0.01981746986286485</iyy>
					<iyz>-0.006292596659762441</iyz>
					<izz>0.3482430011009533</izz>
				</inertia>
			</inertial>
			<collision name="lower_arm_right_collision">
				<geometry>
					<mesh>
						<uri>model://Roboy/meshes/lower_arm_right.stl</uri>
						<scale>0.001 0.001 0.001</scale>
					</mesh>
				</geometry>
			</collision>
			<visual name="lower_arm_right_visual">
				<geometry>
					<mesh>
						<uri>model://Roboy/meshes/lower_arm_right.stl</uri>
						<scale>0.001 0.001 0.001</scale>
					</mesh>
				</geometry>
			</visual>
		</link>
		<link name="upper_arm_left">
			<pose frame="">0.0 0.0 0.0 1.5707963267948966 -0.0 0.0</pose>
			<inertial>
				<pose frame="">0.2379105076514205 0.8386220151015342 -0.19314630327180607 0 0 0</pose>
				<mass>3.003095568510814</mass>
				<inertia>
					<ixx>2.236090309319992</ixx>
					<ixy>-0.5992579261270597</ixy>
					<ixz>0.4872468150724787</ixz>
					<iyy>0.2837575635429413</iyy>
					<iyz>0.138184716302801</iyz>
					<izz>2.2944732339736125</izz>
				</inertia>
			</inertial>
			<collision name="upper_arm_left_collision">
				<geometry>
					<mesh>
						<uri>model://Roboy/meshes/upper_arm_left.stl</uri>
						<scale>0.001 0.001 0.001</scale>
					</mesh>
				</geometry>
			</collision>
			<visual name="upper_arm_left_visual">
				<geometry>
					<mesh>
						<uri>model://Roboy/meshes/upper_arm_left.stl</uri>
						<scale>0.001 0.001 0.001</scale>
					</mesh>
				</geometry>
			</visual>
		</link>
		<link name="hand_left">
			<pose frame="">0.0 0.0 0.0 1.5707963267948966 -0.0 0.0</pose>
			<inertial>
				<pose frame="">0.2739481568847086 0.7638545541823186 0.014816198398159064 0 0 0</pose>
				<mass>1.0527696470734522</mass>
				<inertia>
					<ixx>0.6185549415090433</ixx>
					<ixy>-0.22040945502970277</ixy>
					<ixz>-0.01262374356238817</ixz>
					<iyy>0.08351829342985007</iyy>
					<iyz>-0.004158744572197424</iyz>
					<izz>0.6941406251541536</izz>
				</inertia>
			</inertial>
			<collision name="hand_left_collision">
				<geometry>
					<mesh>
						<uri>model://Roboy/meshes/hand_left.stl</uri>
						<scale>0.001 0.001 0.001</scale>
					</mesh>
				</geometry>
			</collision>
			<visual name="hand_left_visual">
				<geometry>
					<mesh>
						<uri>model://Roboy/meshes/hand_left.stl</uri>
						<scale>0.001 0.001 0.001</scale>
					</mesh>
				</geometry>
			</visual>
		</link>
		<link name="lower_arm_left">
			<pose frame="">0.0 0.0 0.0 1.5707963267948966 -0.0 0.0</pose>
			<inertial>
				<pose frame="">0.243119353265582 0.7322746603175962 -0.12871233445846766 0 0 0</pose>
				<mass>0.6108627312239959</mass>
				<inertia>
					<ixx>0.33857620828328394</ixx>
					<ixy>-0.10876116312045858</ixy>
					<ixz>0.05761181802375315</ixz>
					<iyy>0.047069781263304966</iyy>
					<iyz>0.019044963776066997</iyz>
					<izz>0.3638193466233057</izz>
				</inertia>
			</inertial>
			<collision name="lower_arm_left_collision">
				<geometry>
					<mesh>
						<uri>model://Roboy/meshes/lower_arm_left.stl</uri>
						<scale>0.001 0.001 0.001</scale>
					</mesh>
				</geometry>
			</collision>
			<visual name="lower_arm_left_visual">
				<geometry>
					<mesh>
						<uri>model://Roboy/meshes/lower_arm_left.stl</uri>
						<scale>0.001 0.001 0.001</scale>
					</mesh>
				</geometry>
			</visual>
		</link>
		<joint name="ankle_right" type="revolute">
			<parent>shank_right</parent>
			<child>p-fuss-rechts-v12_1</child>
			<pose frame="">-0.06110787037034556 0.03882865158056234 -0.1230520283902478 0 0 0</pose>
			<axis>
				<xyz>0.9872759050693655 -0.009884823504382701 -0.15870909719908752</xyz>
				<limit>
					<lower>-0.5235987755982988</lower>
					<upper>0.4363323129985824</upper>
				</limit>
				<use_parent_model_frame>0</use_parent_model_frame>
			</axis>
		</joint>
		<link name="p-fuss-rechts-v12_1">
			<pose frame="">0.0 0.0 0.0 1.5707963267948966 -0.0 0.0</pose>
			<inertial>
				<pose frame="">-0.05257657953915506 0.020062506889689892 -0.07825793538401137 0 0 0</pose>
				<mass>1.7645424527989586</mass>
				<inertia>
					<ixx>0.01837025601077849</ixx>
					<ixy>0.0019074353447899853</ixy>
					<ixz>0.0030467943262929512</ixz>
					<iyy>0.023401314511571316</iyy>
					<iyz>-0.008486851145941176</iyz>
					<izz>0.0069138137903881946</izz>
				</inertia>
			</inertial>
			<collision name="p-fuss-rechts-v12_1_collision">
				<geometry>
					<mesh>
						<uri>model://Roboy/meshes/p-fuss-rechts-v12_1.stl</uri>
						<scale>0.001 0.001 0.001</scale>
					</mesh>
				</geometry>
			</collision>
			<visual name="p-fuss-rechts-v12_1_visual">
				<geometry>
					<mesh>
						<uri>model://Roboy/meshes/p-fuss-rechts-v12_1.stl</uri>
						<scale>0.001 0.001 0.001</scale>
					</mesh>
				</geometry>
			</visual>
		</link>
		<joint name="knee_right" type="revolute">
			<parent>thigh_right</parent>
			<child>shank_right</child>
			<pose frame="">-0.046386454474614584 0.27066684261522933 -0.12152458222182777 0 0 0</pose>
			<axis>
				<xyz>-0.9872759050693662 0.009884823504382736 0.15870909719908738</xyz>
				<limit>
					<lower>-1.7453292519943295</lower>
					<upper>-0.0</upper>
				</limit>
				<use_parent_model_frame>0</use_parent_model_frame>
			</axis>
		</joint>
		<joint name="ankle_left" type="revolute">
			<parent>shank_left</parent>
			<child>p-fuss-links-v12_1</child>
			<pose frame="">0.11407018944936358 0.037080723742023806 -0.15161777896805773 0 0 0</pose>
			<axis>
				<xyz>-0.987275905069363 0.009884823504382597 0.15870909719909101</xyz>
				<limit>
					<lower>-0.4363323129985824</lower>
					<upper>0.5235987755982988</upper>
				</limit>
				<use_parent_model_frame>0</use_parent_model_frame>
			</axis>
		</joint>
		<link name="p-fuss-links-v12_1">
			<pose frame="">0.0 0.0 0.0 1.5707963267948966 -0.0 0.0</pose>
			<inertial>
				<pose frame="">0.11964188610288341 0.01834397515112944 -0.10634683819579899 0 0 0</pose>
				<mass>1.7644675682310655</mass>
				<inertia>
					<ixx>0.027579358929842524</ixx>
					<ixy>-0.003818575264237405</ixy>
					<ixz>0.0037113259184230083</ixz>
					<iyy>0.052917785398966896</iyy>
					<iyz>0.02179274899859968</iyz>
					<izz>0.026988517871854852</izz>
				</inertia>
			</inertial>
			<collision name="p-fuss-links-v12_1_collision">
				<geometry>
					<mesh>
						<uri>model://Roboy/meshes/p-fuss-links-v12_1.stl</uri>
						<scale>0.001 0.001 0.001</scale>
					</mesh>
				</geometry>
			</collision>
			<visual name="p-fuss-links-v12_1_visual">
				<geometry>
					<mesh>
						<uri>model://Roboy/meshes/p-fuss-links-v12_1.stl</uri>
						<scale>0.001 0.001 0.001</scale>
					</mesh>
				</geometry>
			</visual>
		</link>
		<joint name="knee_left" type="revolute">
			<parent>thigh_left</parent>
			<child>shank_left</child>
			<pose frame="">0.12879160534509157 0.2689189147766883 -0.15009033279963652 0 0 0</pose>
			<axis>
				<xyz>0.9872759050693627 -0.009884823504382856 -0.15870909719909068</xyz>
				<limit>
					<lower>-0.0</lower>
					<upper>1.7453292519943295</upper>
				</limit>
				<use_parent_model_frame>0</use_parent_model_frame>
			</axis>
		</joint>
		<joint name="groin_side_right" type="revolute">
			<parent>p-gelenkhuelse-v01_1</parent>
			<child>thigh_right</child>
			<pose frame="">-0.05274860490602505 0.5305750400845811 -0.10671978806196931 0 0 0</pose>
			<axis>
				<xyz>-0.15853332525686833 0.016570833727045795 -0.9872145624193044</xyz>
				<limit>
					<lower>-0.0</lower>
					<upper>0.2617993877991494</upper>
				</limit>
				<use_parent_model_frame>0</use_parent_model_frame>
			</axis>
		</joint>
		<joint name="spine_3" type="revolute">
			<parent>vertebrae_2</parent>
			<child>vertebrae_3</child>
			<pose frame="">0.02844176530973684 0.6282399918313742 -0.1653686288478105 0 0 0</pose>
			<axis>
				<xyz>-0.012388383771088682 -0.9998138315375665 -0.01479291092590628</xyz>
				<limit>
					<lower>-0.3490658503988659</lower>
					<upper>0.3490658503988659</upper>
				</limit>
				<use_parent_model_frame>0</use_parent_model_frame>
			</axis>
		</joint>
		<joint name="spine_4" type="ball">
			<parent>vertebrae_3</parent>
			<child>spine</child>
			<pose frame="">0.02893110646869303 0.6677326381771078 -0.1647843088662372 0 0 0</pose>
		</joint>
		<joint name="spine_2" type="ball">
			<parent>vertebrae_1</parent>
			<child>vertebrae_2</child>
			<pose frame="">0.027909064807580014 0.58524799707526 -0.16600472401762414 0 0 0</pose>
		</joint>
		<joint name="shoulder_right" type="ball">
			<parent>torso</parent>
			<child>upper_arm_right</child>
			<pose frame="">-0.17559872182248917 0.9638178547485599 -0.1323609718117505 0 0 0</pose>
		</joint>
		<joint name="shoulder_left" type="ball">
			<parent>torso</parent>
			<child>upper_arm_left</child>
			<pose frame="">0.2390571583066404 0.9596662288767189 -0.1990187926353691 0 0 0</pose>
		</joint>
		<joint name="back" type="fixed">
			<parent>spine</parent>
			<child>torso</child>
			<pose frame="">0.021311357411449457 0.9751238164857443 -0.18407307205178133 0 0 0</pose>
		</joint>
		<joint name="elbow_right" type="revolute">
			<parent>upper_arm_right</parent>
			<child>lower_arm_right</child>
			<pose frame="">-0.18357232547412916 0.7447580342547722 -0.1116193062556743 0 0 0</pose>
			<axis>
				<xyz>0.9898625958012355 -0.008370113909230268 -0.1417814608005606</xyz>
				<limit>
					<lower>-0.5235987755982988</lower>
					<upper>1.5707963267948966</upper>
				</limit>
				<use_parent_model_frame>0</use_parent_model_frame>
			</axis>
		</joint>
		<joint name="elbow_left" type="revolute">
			<parent>upper_arm_left</parent>
			<child>lower_arm_left</child>
			<pose frame="">0.23083608900603764 0.7406085009114014 -0.1782416817140972 0 0 0</pose>
			<axis>
				<xyz>0.9898625958012326 -0.008370113909230115 -0.14178146080056162</xyz>
				<limit>
					<lower>-0.0</lower>
					<upper>-0.0</upper>
				</limit>
				<use_parent_model_frame>0</use_parent_model_frame>
			</axis>
		</joint>
		<joint name="groin_side_left" type="revolute">
			<parent>p-gelenkhuelse-v01 (1)_1</parent>
			<child>thigh_left</child>
			<pose frame="">0.11948073506389632 0.5291353297533593 -0.15364772950077812 0 0 0</pose>
			<axis>
				<xyz>0.1585333252568676 -0.016570833727043374 0.9872145624193441</xyz>
				<limit>
					<lower>-0.0</lower>
					<upper>0.2617993877991494</upper>
				</limit>
				<use_parent_model_frame>0</use_parent_model_frame>
			</axis>
		</joint>
		<joint name="wrist_right" type="revolute">
			<parent>lower_arm_right</parent>
			<child>hand_right</child>
			<pose frame="">-0.19147177512432734 0.7479533509207051 -0.07526839640971669 0 0 0</pose>
			<axis>
				<xyz>0.34466642535182707 0.0845185452211893 0.9349126540748495</xyz>
				<limit>
					<lower>-3.141592653589793</lower>
					<upper>-0.0</upper>
				</limit>
				<use_parent_model_frame>0</use_parent_model_frame>
			</axis>
		</joint>
		<joint name="wrist_left" type="revolute">
			<parent>lower_arm_left</parent>
			<child>hand_left</child>
			<pose frame="">0.2648078271582264 0.7434497617589709 -0.14788812766000473 0 0 0</pose>
			<axis>
				<xyz>-0.06694158658875615 0.08799903429160061 0.9938687005581819</xyz>
				<limit>
					<lower>-0.0</lower>
					<upper>3.141592653589793</upper>
				</limit>
				<use_parent_model_frame>0</use_parent_model_frame>
			</axis>
		</joint>
		<joint name="groin_right" type="revolute">
			<parent>hip</parent>
			<child>p-gelenkhuelse-v01_1</child>
			<pose frame="">-0.0673151040970511 0.5308632269287274 -0.11399880239498555 0 0 0</pose>
			<axis>
				<xyz>-0.9872759050693602 0.009884823504382727 0.1587090971990899</xyz>
				<limit>
					<lower>-0.0</lower>
					<upper>1.5707963267948966</upper>
				</limit>
				<use_parent_model_frame>0</use_parent_model_frame>
			</axis>
		</joint>
		<link name="p-gelenkhuelse-v01_1">
			<pose frame="">0.0 0.0 0.0 1.5707963267948966 -0.0 0.0</pose>
			<inertial>
				<pose frame="">-0.05375220071124067 0.5307109135189687 -0.11617913320880785 0 0 0</pose>
				<mass>0.11109889403877178</mass>
				<inertia>
					<ixx>0.03280747365015996</ixx>
					<ixy>0.0031683768403256134</ixy>
					<ixz>0.006850223530843174</ixz>
					<iyy>0.0018386414474214996</iyy>
					<iyz>-0.0006934676655521685</iyz>
					<izz>0.03163101716307463</izz>
				</inertia>
			</inertial>
			<collision name="p-gelenkhuelse-v01_1_collision">
				<geometry>
					<mesh>
						<uri>model://Roboy/meshes/p-gelenkhuelse-v01_1.stl</uri>
						<scale>0.001 0.001 0.001</scale>
					</mesh>
				</geometry>
			</collision>
			<visual name="p-gelenkhuelse-v01_1_visual">
				<geometry>
					<mesh>
						<uri>model://Roboy/meshes/p-gelenkhuelse-v01_1.stl</uri>
						<scale>0.001 0.001 0.001</scale>
					</mesh>
				</geometry>
			</visual>
		</link>
		<joint name="spine_1" type="ball">
			<parent>hip</parent>
			<child>vertebrae_1</child>
			<pose frame="">0.027339199154129617 0.5392565608245428 -0.16668519792020464 0 0 0</pose>
		</joint>
		<joint name="groin_left" type="revolute">
			<parent>hip</parent>
			<child>p-gelenkhuelse-v01 (1)_1</child>
			<pose frame="">0.1340472342549592 0.5288471429092355 -0.14636871516774705 0 0 0</pose>
			<axis>
				<xyz>0.9872759050693561 -0.009884823504383378 -0.1587090971990918</xyz>
				<limit>
					<lower>-1.5707963267948966</lower>
					<upper>-0.0</upper>
				</limit>
				<use_parent_model_frame>0</use_parent_model_frame>
			</axis>
		</joint>
		<link name="p-gelenkhuelse-v01 (1)_1">
			<pose frame="">0.0 0.0 0.0 1.5707963267948966 -0.0 0.0</pose>
			<inertial>
				<pose frame="">0.12048406670973975 0.5289664205508346 -0.14418840629859173 0 0 0</pose>
				<mass>0.11109892401420222</mass>
				<inertia>
					<ixx>0.03341236347849828</ixx>
					<ixy>-0.007079602480574991</ixy>
					<ixz>0.008473442990892581</ixz>
					<iyy>0.003940575487343596</iyy>
					<iyz>0.001930411620059389</iyz>
					<izz>0.03271739889605254</izz>
				</inertia>
			</inertial>
			<collision name="p-gelenkhuelse-v01 (1)_1_collision">
				<geometry>
					<mesh>
						<uri>model://Roboy/meshes/p-gelenkhuelse-v01 (1)_1.stl</uri>
						<scale>0.001 0.001 0.001</scale>
					</mesh>
				</geometry>
			</collision>
			<visual name="p-gelenkhuelse-v01 (1)_1_visual">
				<geometry>
					<mesh>
						<uri>model://Roboy/meshes/p-gelenkhuelse-v01 (1)_1.stl</uri>
						<scale>0.001 0.001 0.001</scale>
					</mesh>
				</geometry>
			</visual>
		</link>
		<joint name="neck_1" type="revolute">
			<parent>spine</parent>
			<child>neck_cross</child>
			<pose frame="">0.0145061282206148 1.0516550809653264 -0.1980950046781183 0 0 0</pose>
			<axis>
				<xyz>0.9862176849480625 -0.010458996763876467 -0.16512203754301474</xyz>
				<limit>
					<lower>0.6981317007977318</lower>
					<upper>0.8726646259971648</upper>
				</limit>
				<use_parent_model_frame>0</use_parent_model_frame>
			</axis>
		</joint>
		<joint name="neck_2" type="revolute">
			<parent>neck_cross</parent>
			<child>neck</child>
			<pose frame="">0.02856003320941595 1.0533559737187592 -0.18996513884853194 0 0 0</pose>
			<axis>
				<xyz>-0.1643984692333912 -0.17444097266496672 -0.9708467903689157</xyz>
				<limit>
					<lower>-0.08726646259971647</lower>
					<upper>0.08726646259971647</upper>
				</limit>
				<use_parent_model_frame>0</use_parent_model_frame>
			</axis>
		</joint>
		<joint name="neck_3" type="revolute">
			<parent>neck</parent>
			<child>head</child>
			<pose frame="">0.02602222732046244 1.0833061850279249 -0.2070196656319496 0 0 0</pose>
			<axis>
				<xyz>-0.018649965398788142 0.9846120842455298 -0.17375621527944524</xyz>
				<limit>
					<lower>-0.6108652381980153</lower>
					<upper>0.6108652381980153</upper>
				</limit>
				<use_parent_model_frame>0</use_parent_model_frame>
			</axis>
		</joint>
	</model>
</sdf>
