<sdf version="1.6">
    <model name="Roboy">
        <link name="head">
            <pose frame="">0.0 0.0 0.0 1.5707963267948966 -0.0 0.0</pose>
            <inertial>
                <pose frame="">0.11655994509692041 1.192537131346147 -0.1800971396218141 0 0 0</pose>
                <mass>18.115692481402924</mass>
                <inertia>
                    <ixx>26.10496239188056</ixx>
                    <ixy>-3.0799034994338848</ixy>
                    <ixz>3.915252533523113</ixz>
                    <iyy>0.5241173249749574</iyy>
                    <iyz>0.37043595707832466</iyz>
                    <izz>25.161989030725717</izz>
                </inertia>
            </inertial>
            <collision name="head_collision">
                <geometry>
                    <mesh>
                        <uri>model://Roboy/meshes/head.stl</uri>
                        <scale>0.001 0.001 0.001</scale>
                    </mesh>
                </geometry>
            </collision>
            <visual name="head_visual">
                <geometry>
                    <mesh>
                        <uri>model://Roboy/meshes/head.stl</uri>
                        <scale>0.001 0.001 0.001</scale>
                    </mesh>
                </geometry>
            </visual>
        </link>
        <link name="hip">
            <pose frame="">0.0 0.0 0.0 1.5707963267948966 -0.0 0.0</pose>
            <inertial>
                <pose frame="">0.2010838504560995 0.5073031752472723 -0.11025564223621935 0 0 0</pose>
                <mass>10.217250148484712</mass>
                <inertia>
                    <ixx>-96.33073648105905</ixx>
                    <ixy>0.461254648008351</ixy>
                    <ixz>11.109241182012473</ixz>
                    <iyy>-99.38440477934513</iyy>
                    <iyz>14.25084710952683</iyz>
                    <izz>-0.012927007286278496</izz>
                </inertia>
            </inertial>
            <collision name="hip_collision">
                <geometry>
                    <mesh>
                        <uri>model://Roboy/meshes/hip.stl</uri>
                        <scale>0.001 0.001 0.001</scale>
                    </mesh>
                </geometry>
            </collision>
            <visual name="hip_visual">
                <geometry>
                    <mesh>
                        <uri>model://Roboy/meshes/hip.stl</uri>
                        <scale>0.001 0.001 0.001</scale>
                    </mesh>
                </geometry>
            </visual>
        </link>
        <link name="shank_right">
            <pose frame="">0.0 0.0 0.0 1.5707963267948966 -0.0 0.0</pose>
            <inertial>
                <pose frame="">0.1429899821314719 0.08863495431999338 -0.14915246073487531 0 0 0</pose>
                <mass>4.6961997143632574</mass>
                <inertia>
                    <ixx>0.16476385755359488</ixx>
                    <ixy>-0.05893406076656663</ixy>
                    <ixz>0.059950039583874994</ixz>
                    <iyy>0.20527947923394613</iyy>
                    <iyz>0.10015445756425045</iyz>
                    <izz>0.15537642188521653</izz>
                </inertia>
            </inertial>
            <collision name="shank_right_collision">
                <geometry>
                    <mesh>
                        <uri>model://Roboy/meshes/shank_right.stl</uri>
                        <scale>0.001 0.001 0.001</scale>
                    </mesh>
                </geometry>
            </collision>
            <visual name="shank_right_visual">
                <geometry>
                    <mesh>
                        <uri>model://Roboy/meshes/shank_right.stl</uri>
                        <scale>0.001 0.001 0.001</scale>
                    </mesh>
                </geometry>
            </visual>
        </link>
        <link name="shank_left">
            <pose frame="">0.0 0.0 0.0 1.5707963267948966 -0.0 0.0</pose>
            <inertial>
                <pose frame="">0.32840647185689464 0.10865833648454615 -0.17822029206654108 0 0 0</pose>
                <mass>4.679788206228314</mass>
                <inertia>
                    <ixx>0.2268190466982304</ixx>
                    <ixy>-0.1644227038992165</ixy>
                    <ixz>0.08821257663923912</ixz>
                    <iyy>0.6585353618255836</iyy>
                    <iyz>0.2741016151547236</iyz>
                    <izz>0.5822992671202405</izz>
                </inertia>
            </inertial>
            <collision name="shank_left_collision">
                <geometry>
                    <mesh>
                        <uri>model://Roboy/meshes/shank_left.stl</uri>
                        <scale>0.001 0.001 0.001</scale>
                    </mesh>
                </geometry>
            </collision>
            <visual name="shank_left_visual">
                <geometry>
                    <mesh>
                        <uri>model://Roboy/meshes/shank_left.stl</uri>
                        <scale>0.001 0.001 0.001</scale>
                    </mesh>
                </geometry>
            </visual>
        </link>
        <link name="vertebrae_2">
            <pose frame="">0.0 0.0 0.0 1.5707963267948966 -0.0 0.0</pose>
            <inertial>
                <pose frame="">0.18746612728213932 0.5557669159612416 -0.1659352901658949 0 0 0</pose>
                <mass>1.7524913624275196</mass>
                <inertia>
                    <ixx>0.5907196147867948</ixx>
                    <ixy>-0.18263519210148546</ixy>
                    <ixz>0.16165850552375516</ixz>
                    <iyy>0.11150856179798266</iyy>
                    <iyz>0.054514852419118486</iyz>
                    <izz>0.6040757773054247</izz>
                </inertia>
            </inertial>
            <collision name="vertebrae_2_collision">
                <geometry>
                    <mesh>
                        <uri>model://Roboy/meshes/vertebrae_2.stl</uri>
                        <scale>0.001 0.001 0.001</scale>
                    </mesh>
                </geometry>
            </collision>
            <visual name="vertebrae_2_visual">
                <geometry>
                    <mesh>
                        <uri>model://Roboy/meshes/vertebrae_2.stl</uri>
                        <scale>0.001 0.001 0.001</scale>
                    </mesh>
                </geometry>
            </visual>
        </link>
        <link name="vertebrae_1">
            <pose frame="">0.0 0.0 0.0 1.5707963267948966 -0.0 0.0</pose>
            <inertial>
                <pose frame="">0.19177481522551984 0.5086461564927633 -0.1702177325368556 0 0 0</pose>
                <mass>1.6731579691247498</mass>
                <inertia>
                    <ixx>0.4824155308508039</ixx>
                    <ixy>-0.16325195287917188</ixy>
                    <ixz>0.14490730730004836</ixz>
                    <iyy>0.11153315598566349</iyy>
                    <iyz>0.054619421552018925</iyz>
                    <izz>0.49551477863198</izz>
                </inertia>
            </inertial>
            <collision name="vertebrae_1_collision">
                <geometry>
                    <mesh>
                        <uri>model://Roboy/meshes/vertebrae_1.stl</uri>
                        <scale>0.001 0.001 0.001</scale>
                    </mesh>
                </geometry>
            </collision>
            <visual name="vertebrae_1_visual">
                <geometry>
                    <mesh>
                        <uri>model://Roboy/meshes/vertebrae_1.stl</uri>
                        <scale>0.001 0.001 0.001</scale>
                    </mesh>
                </geometry>
            </visual>
        </link>
        <link name="vertebrae_3">
            <pose frame="">0.0 0.0 0.0 1.5707963267948966 -0.0 0.0</pose>
            <inertial>
                <pose frame="">0.183454463730959 0.5973346509838479 -0.1633006285286687 0 0 0</pose>
                <mass>1.3929972760468987</mass>
                <inertia>
                    <ixx>0.5350868176320328</ixx>
                    <ixy>-0.15270226596807604</ixy>
                    <ixz>0.13589597453380514</ixz>
                    <iyy>0.08544881041618281</iyy>
                    <iyz>0.04173588005212801</iyz>
                    <izz>0.5448528567164341</izz>
                </inertia>
            </inertial>
            <collision name="vertebrae_3_collision">
                <geometry>
                    <mesh>
                        <uri>model://Roboy/meshes/vertebrae_3.stl</uri>
                        <scale>0.001 0.001 0.001</scale>
                    </mesh>
                </geometry>
            </collision>
            <visual name="vertebrae_3_visual">
                <geometry>
                    <mesh>
                        <uri>model://Roboy/meshes/vertebrae_3.stl</uri>
                        <scale>0.001 0.001 0.001</scale>
                    </mesh>
                </geometry>
            </visual>
        </link>
        <link name="neck">
            <pose frame="">0.0 0.0 0.0 1.5707963267948966 -0.0 0.0</pose>
            <inertial>
                <pose frame="">0.13765775003829706 1.0487819234321683 -0.15735804507891243 0 0 0</pose>
                <mass>1.6463270783642006</mass>
                <inertia>
                    <ixx>1.8535094261253733</ixx>
                    <ixy>-0.23780720085315227</ixy>
                    <ixz>0.2714415224834277</ixz>
                    <iyy>0.07361800758557968</iyy>
                    <iyz>0.03580841988643921</iyz>
                    <izz>1.8444969276073946</izz>
                </inertia>
            </inertial>
            <collision name="neck_collision">
                <geometry>
                    <mesh>
                        <uri>model://Roboy/meshes/neck.stl</uri>
                        <scale>0.001 0.001 0.001</scale>
                    </mesh>
                </geometry>
            </collision>
            <visual name="neck_visual">
                <geometry>
                    <mesh>
                        <uri>model://Roboy/meshes/neck.stl</uri>
                        <scale>0.001 0.001 0.001</scale>
                    </mesh>
                </geometry>
            </visual>
        </link>
        <link name="neck_cross">
            <pose frame="">0.0 0.0 0.0 1.5707963267948966 -0.0 0.0</pose>
            <inertial>
                <pose frame="">0.14028768447035833 0.9974599687759718 -0.16651225399356664 0 0 0</pose>
                <mass>0.030866715002662304</mass>
                <inertia>
                    <ixx>0.03156699294118185</ixx>
                    <ixy>-0.004319384965958551</ixy>
                    <ixz>0.0051265942319324255</ixz>
                    <iyy>0.001465807900165683</iyy>
                    <iyz>0.0007211965223303786</iyz>
                    <izz>0.031319585035748394</izz>
                </inertia>
            </inertial>
            <collision name="neck_cross_collision">
                <geometry>
                    <mesh>
                        <uri>model://Roboy/meshes/neck_cross.stl</uri>
                        <scale>0.001 0.001 0.001</scale>
                    </mesh>
                </geometry>
            </collision>
            <visual name="neck_cross_visual">
                <geometry>
                    <mesh>
                        <uri>model://Roboy/meshes/neck_cross.stl</uri>
                        <scale>0.001 0.001 0.001</scale>
                    </mesh>
                </geometry>
            </visual>
        </link>
        <link name="spine">
            <pose frame="">0.0 0.0 0.0 1.5707963267948966 -0.0 0.0</pose>
            <inertial>
                <pose frame="">0.16797068363079062 0.7622581903620353 -0.15024213065436676 0 0 0</pose>
                <mass>9.774337494627355</mass>
                <inertia>
                    <ixx>6.038339067566294</ixx>
                    <ixy>-1.2371649680576866</ixy>
                    <ixz>1.1360082855864166</ixz>
                    <iyy>0.5263924221733153</iyy>
                    <iyz>0.24647668173200935</iyz>
                    <izz>6.105324312184792</izz>
                </inertia>
            </inertial>
            <collision name="spine_collision">
                <geometry>
                    <mesh>
                        <uri>model://Roboy/meshes/spine.stl</uri>
                        <scale>0.001 0.001 0.001</scale>
                    </mesh>
                </geometry>
            </collision>
            <visual name="spine_visual">
                <geometry>
                    <mesh>
                        <uri>model://Roboy/meshes/spine.stl</uri>
                        <scale>0.001 0.001 0.001</scale>
                    </mesh>
                </geometry>
            </visual>
        </link>
        <link name="thigh_right">
            <pose frame="">0.0 0.0 0.0 1.5707963267948966 -0.0 0.0</pose>
            <inertial>
                <pose frame="">0.10475556821574389 0.3496623305592167 -0.12707392937226644 0 0 0</pose>
                <mass>6.83448322957835</mass>
                <inertia>
                    <ixx>0.9898916587908256</ixx>
                    <ixy>-0.2391276559186226</ixy>
                    <ixz>0.3025631918673785</ixz>
                    <iyy>0.197949664258259</iyy>
                    <iyz>0.09231260871217459</iyz>
                    <izz>0.9580362611567705</izz>
                </inertia>
            </inertial>
            <collision name="thigh_right_collision">
                <geometry>
                    <mesh>
                        <uri>model://Roboy/meshes/thigh_right.stl</uri>
                        <scale>0.001 0.001 0.001</scale>
                    </mesh>
                </geometry>
            </collision>
            <visual name="thigh_right_visual">
                <geometry>
                    <mesh>
                        <uri>model://Roboy/meshes/thigh_right.stl</uri>
                        <scale>0.001 0.001 0.001</scale>
                    </mesh>
                </geometry>
            </visual>
        </link>
        <link name="thigh_left">
            <pose frame="">0.0 0.0 0.0 1.5707963267948966 -0.0 0.0</pose>
            <inertial>
                <pose frame="">0.3188250880308472 0.372348077636157 -0.1605772087854732 0 0 0</pose>
                <mass>6.809220025532755</mass>
                <inertia>
                    <ixx>1.1660353719779246</ixx>
                    <ixy>-0.8122258481990908</ixy>
                    <ixz>0.4080983685692377</ixz>
                    <iyy>0.8769942945322179</iyy>
                    <iyz>0.34792673779230165</iyz>
                    <izz>1.683972161997929</izz>
                </inertia>
            </inertial>
            <collision name="thigh_left_collision">
                <geometry>
                    <mesh>
                        <uri>model://Roboy/meshes/thigh_left.stl</uri>
                        <scale>0.001 0.001 0.001</scale>
                    </mesh>
                </geometry>
            </collision>
            <visual name="thigh_left_visual">
                <geometry>
                    <mesh>
                        <uri>model://Roboy/meshes/thigh_left.stl</uri>
                        <scale>0.001 0.001 0.001</scale>
                    </mesh>
                </geometry>
            </visual>
        </link>
        <link name="torso">
            <pose frame="">0.0 0.0 0.0 1.5707963267948966 -0.0 0.0</pose>
            <inertial>
                <pose frame="">0.15375387437358826 0.8591094425809321 -0.15525343259871996 0 0 0</pose>
                <mass>32.14110236334564</mass>
                <inertia>
                    <ixx>24.789511926556813</ixx>
                    <ixy>-4.271205300934259</ixy>
                    <ixz>4.290259756658335</ixz>
                    <iyy>2.0383303914180035</iyy>
                    <iyz>0.8225471654408203</iyz>
                    <izz>25.125587520019597</izz>
                </inertia>
            </inertial>
            <collision name="torso_collision">
                <geometry>
                    <mesh>
                        <uri>model://Roboy/meshes/torso.stl</uri>
                        <scale>0.001 0.001 0.001</scale>
                    </mesh>
                </geometry>
            </collision>
            <visual name="torso_visual">
                <geometry>
                    <mesh>
                        <uri>model://Roboy/meshes/torso.stl</uri>
                        <scale>0.001 0.001 0.001</scale>
                    </mesh>
                </geometry>
            </visual>
        </link>
        <link name="upper_arm_right">
            <pose frame="">0.0 0.0 0.0 1.5707963267948966 -0.0 0.0</pose>
            <inertial>
                <pose frame="">-0.03755171947364825 0.763979713832748 -0.11055271220455438 0 0 0</pose>
                <mass>3.214129059783697</mass>
                <inertia>
                    <ixx>1.9273262168553638</ixx>
                    <ixy>0.0934223311780249</ixy>
                    <ixz>0.27142183526629926</ixz>
                    <iyy>0.04626888851053056</iyy>
                    <iyz>-0.013522306398711322</iyz>
                    <izz>1.8937650381235862</izz>
                </inertia>
            </inertial>
            <collision name="upper_arm_right_collision">
                <geometry>
                    <mesh>
                        <uri>model://Roboy/meshes/upper_arm_right.stl</uri>
                        <scale>0.001 0.001 0.001</scale>
                    </mesh>
                </geometry>
            </collision>
            <visual name="upper_arm_right_visual">
                <geometry>
                    <mesh>
                        <uri>model://Roboy/meshes/upper_arm_right.stl</uri>
                        <scale>0.001 0.001 0.001</scale>
                    </mesh>
                </geometry>
            </visual>
        </link>
        <link name="hand_right">
            <pose frame="">0.0 0.0 0.0 1.5707963267948966 -0.0 0.0</pose>
            <inertial>
                <pose frame="">-0.006414322974483745 0.6733386512486823 0.096764129437372 0 0 0</pose>
                <mass>1.0988993358904842</mass>
                <inertia>
                    <ixx>0.5124176485245501</ixx>
                    <ixy>0.004727658706651175</ixy>
                    <ixz>-0.07185876630839938</ixz>
                    <iyy>0.01479354379128648</iyy>
                    <iyz>-0.0003397071355007095</iyz>
                    <izz>0.4992022152147812</izz>
                </inertia>
            </inertial>
            <collision name="hand_right_collision">
                <geometry>
                    <mesh>
                        <uri>model://Roboy/meshes/hand_right.stl</uri>
                        <scale>0.001 0.001 0.001</scale>
                    </mesh>
                </geometry>
            </collision>
            <visual name="hand_right_visual">
                <geometry>
                    <mesh>
                        <uri>model://Roboy/meshes/hand_right.stl</uri>
                        <scale>0.001 0.001 0.001</scale>
                    </mesh>
                </geometry>
            </visual>
        </link>
        <link name="lower_arm_right">
            <pose frame="">0.0 0.0 0.0 1.5707963267948966 -0.0 0.0</pose>
            <inertial>
                <pose frame="">-0.017744226093944066 0.6552433007480045 -0.05084614947888509 0 0 0</pose>
                <mass>0.6110312851787062</mass>
                <inertia>
                    <ixx>0.2648328803352451</ixx>
                    <ixy>0.007138492573804106</ixy>
                    <ixz>0.020446969199519327</ixz>
                    <iyy>0.002656584616442772</iyy>
                    <iyz>-0.0007036085363968464</iyz>
                    <izz>0.2627142046139014</izz>
                </inertia>
            </inertial>
            <collision name="lower_arm_right_collision">
                <geometry>
                    <mesh>
                        <uri>model://Roboy/meshes/lower_arm_right.stl</uri>
                        <scale>0.001 0.001 0.001</scale>
                    </mesh>
                </geometry>
            </collision>
            <visual name="lower_arm_right_visual">
                <geometry>
                    <mesh>
                        <uri>model://Roboy/meshes/lower_arm_right.stl</uri>
                        <scale>0.001 0.001 0.001</scale>
                    </mesh>
                </geometry>
            </visual>
        </link>
        <link name="upper_arm_left">
            <pose frame="">0.0 0.0 0.0 1.5707963267948966 -0.0 0.0</pose>
            <inertial>
                <pose frame="">0.372463185563132 0.8077540117910784 -0.1727477922820894 0 0 0</pose>
                <mass>3.0031216858908167</mass>
                <inertia>
                    <ixx>2.060982350875469</ixx>
                    <ixy>-0.9025437645537843</ixy>
                    <ixz>0.4191323429887793</ixz>
                    <iyy>0.5080140443147365</iyy>
                    <iyz>0.19339719575532371</iyz>
                    <izz>2.3885764098710256</izz>
                </inertia>
            </inertial>
            <collision name="upper_arm_left_collision">
                <geometry>
                    <mesh>
                        <uri>model://Roboy/meshes/upper_arm_left.stl</uri>
                        <scale>0.001 0.001 0.001</scale>
                    </mesh>
                </geometry>
            </collision>
            <visual name="upper_arm_left_visual">
                <geometry>
                    <mesh>
                        <uri>model://Roboy/meshes/upper_arm_left.stl</uri>
                        <scale>0.001 0.001 0.001</scale>
                    </mesh>
                </geometry>
            </visual>
        </link>
        <link name="hand_left">
            <pose frame="">0.0 0.0 0.0 1.5707963267948966 -0.0 0.0</pose>
            <inertial>
                <pose frame="">0.4161173033071404 0.7228345156141934 0.02978394589416424 0 0 0</pose>
                <mass>1.0527667259023854</mass>
                <inertia>
                    <ixx>0.5550794423807275</ixx>
                    <ixy>-0.3167989178098813</ixy>
                    <ixz>-0.023115881368548648</ixz>
                    <iyy>0.18755820614231877</iyy>
                    <iyz>-0.01286933352441547</iyz>
                    <izz>0.7331394416303676</izz>
                </inertia>
            </inertial>
            <collision name="hand_left_collision">
                <geometry>
                    <mesh>
                        <uri>model://Roboy/meshes/hand_left.stl</uri>
                        <scale>0.001 0.001 0.001</scale>
                    </mesh>
                </geometry>
            </collision>
            <visual name="hand_left_visual">
                <geometry>
                    <mesh>
                        <uri>model://Roboy/meshes/hand_left.stl</uri>
                        <scale>0.001 0.001 0.001</scale>
                    </mesh>
                </geometry>
            </visual>
        </link>
        <link name="lower_arm_left">
            <pose frame="">0.0 0.0 0.0 1.5707963267948966 -0.0 0.0</pose>
            <inertial>
                <pose frame="">0.3887596762828667 0.6983020802085801 -0.11580017338971618 0 0 0</pose>
                <mass>0.6108472244519065</mass>
                <inertia>
                    <ixx>0.3069521765228555</ixx>
                    <ixy>-0.16582614477925836</ixy>
                    <ixz>0.04947171824567369</ixz>
                    <iyy>0.1013449837143297</iyy>
                    <iyz>0.02742553073208991</iyz>
                    <izz>0.39034454197151475</izz>
                </inertia>
            </inertial>
            <collision name="lower_arm_left_collision">
                <geometry>
                    <mesh>
                        <uri>model://Roboy/meshes/lower_arm_left.stl</uri>
                        <scale>0.001 0.001 0.001</scale>
                    </mesh>
                </geometry>
            </collision>
            <visual name="lower_arm_left_visual">
                <geometry>
                    <mesh>
                        <uri>model://Roboy/meshes/lower_arm_left.stl</uri>
                        <scale>0.001 0.001 0.001</scale>
                    </mesh>
                </geometry>
            </visual>
        </link>
        <joint name="shoulder_right" type="ball">
            <parent>torso</parent>
            <child>upper_arm_right</child>
            <pose frame="">-0.05186811498516573 0.8846086491043533 -0.10643997245370869 0 0 0</pose>
        </joint>
        <joint name="shoulder_left" type="ball">
            <parent>torso</parent>
            <child>upper_arm_left</child>
            <pose frame="">0.36095019991890487 0.9283773982849001 -0.1701999557891387 0 0 0</pose>
        </joint>
        <joint name="back" type="fixed">
            <parent>spine</parent>
            <child>torso</child>
            <pose frame="">0.1427814754255247 0.9199651090214723 -0.15580598384847735 0 0 0</pose>
        </joint>
        <joint name="elbow_right" type="revolute">
            <parent>upper_arm_right</parent>
            <child>lower_arm_right</child>
            <pose frame="">-0.03690005200178481 0.6650012530238028 -0.10100410295143009 0 0 0</pose>
            <axis>
                <xyz>0.9853149400747296 0.10480296183090279 -0.13479913967455673</xyz>
                <limit>
                    <lower>-0.5235987755982988</lower>
                    <upper>1.5707963267948966</upper>
                </limit>
                <use_parent_model_frame>0</use_parent_model_frame>
            </axis>
        </joint>
        <joint name="elbow_left" type="revolute">
            <parent>upper_arm_left</parent>
            <child>lower_arm_left</child>
            <pose frame="">0.37567193416726674 0.7087438014638906 -0.16473038650194227 0 0 0</pose>
            <axis>
                <xyz>0.9853149400747302 0.10480296183090311 -0.13479913967455687</xyz>
                <limit>
                    <lower>-0.0</lower>
                    <upper>-0.0</upper>
                </limit>
                <use_parent_model_frame>0</use_parent_model_frame>
            </axis>
        </joint>
        <joint name="ankle_left" type="revolute">
            <parent>shank_left</parent>
            <child>p-fuss-links-v12_1</child>
            <pose frame="">0.3330843678393615 -0.003258424744165751 -0.18782951667429795 0 0 0</pose>
            <axis>
                <xyz>-0.9829007497715961 -0.10421130757273181 0.15180948413197812</xyz>
                <limit>
                    <lower>-0.4363323129985824</lower>
                    <upper>0.5235987755982988</upper>
                </limit>
                <use_parent_model_frame>0</use_parent_model_frame>
            </axis>
        </joint>
        <link name="p-fuss-links-v12_1">
            <pose frame="">0.0 0.0 0.0 1.5707963267948966 -0.0 0.0</pose>
            <inertial>
                <pose frame="">0.3405789616763136 -0.024424043661837338 -0.14382391798096422 0 0 0</pose>
                <mass>1.764574150507824</mass>
                <inertia>
                    <ixx>0.05030184948159986</ixx>
                    <ixy>0.014708482343086002</ixy>
                    <ixz>-0.005543127556822964</ixz>
                    <iyy>0.25452504171643386</iyy>
                    <iyz>0.08592209849678073</iyz>
                    <izz>0.20690282511802277</izz>
                </inertia>
            </inertial>
            <collision name="p-fuss-links-v12_1_collision">
                <geometry>
                    <mesh>
                        <uri>model://Roboy/meshes/p-fuss-links-v12_1.stl</uri>
                        <scale>0.001 0.001 0.001</scale>
                    </mesh>
                </geometry>
            </collision>
            <visual name="p-fuss-links-v12_1_visual">
                <geometry>
                    <mesh>
                        <uri>model://Roboy/meshes/p-fuss-links-v12_1.stl</uri>
                        <scale>0.001 0.001 0.001</scale>
                    </mesh>
                </geometry>
            </visual>
        </link>
        <joint name="knee_left" type="revolute">
            <parent>thigh_left</parent>
            <child>shank_left</child>
            <pose frame="">0.3234914484428748 0.22817658924553869 -0.17011482793761004 0 0 0</pose>
            <axis>
                <xyz>0.9829007497715957 0.10421130757273143 -0.15180948413197778</xyz>
                <limit>
                    <lower>-0.0</lower>
                    <upper>1.7453292519943295</upper>
                </limit>
                <use_parent_model_frame>0</use_parent_model_frame>
            </axis>
        </joint>
        <joint name="ankle_right" type="revolute">
            <parent>shank_right</parent>
            <child>p-fuss-rechts-v12_1</child>
            <pose frame="">0.15868324354966237 -0.021783441294696927 -0.16048940679354837 0 0 0</pose>
            <axis>
                <xyz>0.9829007497715957 0.10421130757273141 -0.15180948413197623</xyz>
                <limit>
                    <lower>-0.5235987755982988</lower>
                    <upper>0.4363323129985824</upper>
                </limit>
                <use_parent_model_frame>0</use_parent_model_frame>
            </axis>
        </joint>
        <link name="p-fuss-rechts-v12_1">
            <pose frame="">0.0 0.0 0.0 1.5707963267948966 -0.0 0.0</pose>
            <inertial>
                <pose frame="">0.16913582103527042 -0.042636243416042385 -0.1168529803982668 0 0 0</pose>
                <mass>1.7645710754339488</mass>
                <inertia>
                    <ixx>0.04333008732934767</ixx>
                    <ixy>0.012767236799845528</ixy>
                    <ixz>-0.008202667942606245</ixz>
                    <iyy>0.09138419117431729</iyy>
                    <iyz>0.03312311324450561</iyz>
                    <izz>0.055034556243959</izz>
                </inertia>
            </inertial>
            <collision name="p-fuss-rechts-v12_1_collision">
                <geometry>
                    <mesh>
                        <uri>model://Roboy/meshes/p-fuss-rechts-v12_1.stl</uri>
                        <scale>0.001 0.001 0.001</scale>
                    </mesh>
                </geometry>
            </collision>
            <visual name="p-fuss-rechts-v12_1_visual">
                <geometry>
                    <mesh>
                        <uri>model://Roboy/meshes/p-fuss-rechts-v12_1.stl</uri>
                        <scale>0.001 0.001 0.001</scale>
                    </mesh>
                </geometry>
            </visual>
        </link>
        <joint name="knee_right" type="revolute">
            <parent>thigh_right</parent>
            <child>shank_right</child>
            <pose frame="">0.14909032415317539 0.20965157269500734 -0.14277471805686123 0 0 0</pose>
            <axis>
                <xyz>-0.9829007497715962 -0.10421130757273145 0.15180948413197612</xyz>
                <limit>
                    <lower>-1.7453292519943295</lower>
                    <upper>-0.0</upper>
                </limit>
                <use_parent_model_frame>0</use_parent_model_frame>
            </axis>
        </joint>
        <joint name="spine_4" type="ball">
            <parent>vertebrae_3</parent>
            <child>spine</child>
            <pose frame="">0.182490610190802 0.6144515636342662 -0.15783370770360627 0 0 0</pose>
        </joint>
        <joint name="spine_2" type="ball">
            <parent>vertebrae_1</parent>
            <child>vertebrae_2</child>
            <pose frame="">0.19009616015840575 0.5325971694116214 -0.16478091981596618 0 0 0</pose>
        </joint>
        <joint name="groin_side_right" type="revolute">
            <parent>p-gelenkhuelse-v01_1</parent>
            <child>thigh_right</child>
            <pose frame="">0.11559522177537673 0.46581017480028025 -0.11002141770142196 0 0 0</pose>
            <axis>
                <xyz>-0.15939698689805146 0.06877364093258721 -0.9848161183087428</xyz>
                <limit>
                    <lower>-0.0</lower>
                    <upper>0.2617993877991494</upper>
                </limit>
                <use_parent_model_frame>0</use_parent_model_frame>
            </axis>
        </joint>
        <joint name="spine_3" type="revolute">
            <parent>vertebrae_2</parent>
            <child>vertebrae_3</child>
            <pose frame="">0.18613205532680635 0.5752606718549385 -0.16115994865437328 0 0 0</pose>
            <axis>
                <xyz>0.09218848445580205 -0.9921744754260001 -0.08420863166496222</xyz>
                <limit>
                    <lower>-0.3490658503988659</lower>
                    <upper>0.3490658503988659</upper>
                </limit>
                <use_parent_model_frame>0</use_parent_model_frame>
            </axis>
        </joint>
        <joint name="groin_right" type="revolute">
            <parent>hip</parent>
            <child>p-gelenkhuelse-v01_1</child>
            <pose frame="">0.10107839566307263 0.465084938370948 -0.11736892011698409 0 0 0</pose>
            <axis>
                <xyz>-0.9829007497715961 -0.10421130757273157 0.15180948413197615</xyz>
                <limit>
                    <lower>-0.0</lower>
                    <upper>1.5707963267948966</upper>
                </limit>
                <use_parent_model_frame>0</use_parent_model_frame>
            </axis>
        </joint>
        <link name="p-gelenkhuelse-v01_1">
            <pose frame="">0.0 0.0 0.0 1.5707963267948966 -0.0 0.0</pose>
            <inertial>
                <pose frame="">0.11458268943896775 0.4665005584337915 -0.11945601822232405 0 0 0</pose>
                <mass>0.1110936435659654</mass>
                <inertia>
                    <ixx>0.02577844328664419</ixx>
                    <ixy>-0.005939372453477323</ixy>
                    <ixz>0.006190960666635404</ixz>
                    <iyy>0.0030616907907431716</iyy>
                    <iyz>0.001520844517159505</iyz>
                    <izz>0.025653659733445227</izz>
                </inertia>
            </inertial>
            <collision name="p-gelenkhuelse-v01_1_collision">
                <geometry>
                    <mesh>
                        <uri>model://Roboy/meshes/p-gelenkhuelse-v01_1.stl</uri>
                        <scale>0.001 0.001 0.001</scale>
                    </mesh>
                </geometry>
            </collision>
            <visual name="p-gelenkhuelse-v01_1_visual">
                <geometry>
                    <mesh>
                        <uri>model://Roboy/meshes/p-gelenkhuelse-v01_1.stl</uri>
                        <scale>0.001 0.001 0.001</scale>
                    </mesh>
                </geometry>
            </visual>
        </link>
        <joint name="spine_1" type="ball">
            <parent>hip</parent>
            <child>vertebrae_1</child>
            <pose frame="">0.19433683044337283 0.4869571435420243 -0.16865451687255423 0 0 0</pose>
        </joint>
        <joint name="groin_left" type="revolute">
            <parent>hip</parent>
            <child>p-gelenkhuelse-v01 (1)_1</child>
            <pose frame="">0.3015483882210766 0.4863396175014904 -0.14833160496715198 0 0 0</pose>
            <axis>
                <xyz>0.9829007497715961 0.10421130757273105 -0.1518094841319762</xyz>
                <limit>
                    <lower>-1.5707963267948966</lower>
                    <upper>-0.0</upper>
                </limit>
                <use_parent_model_frame>0</use_parent_model_frame>
            </axis>
        </joint>
        <link name="p-gelenkhuelse-v01 (1)_1">
            <pose frame="">0.0 0.0 0.0 1.5707963267948966 -0.0 0.0</pose>
            <inertial>
                <pose frame="">0.28804696747054237 0.48489198489554625 -0.14624764883191246 0 0 0</pose>
                <mass>0.11109364367177335</mass>
                <inertia>
                    <ixx>0.02851278933284499</ixx>
                    <ixy>-0.015515886327026156</ixy>
                    <ixz>0.00787798148742518</ixz>
                    <iyy>0.011611907759991697</iyy>
                    <iyz>0.004680376606046247</iyz>
                    <izz>0.035356455256960385</izz>
                </inertia>
            </inertial>
            <collision name="p-gelenkhuelse-v01 (1)_1_collision">
                <geometry>
                    <mesh>
                        <uri>model://Roboy/meshes/p-gelenkhuelse-v01 (1)_1.stl</uri>
                        <scale>0.001 0.001 0.001</scale>
                    </mesh>
                </geometry>
            </collision>
            <visual name="p-gelenkhuelse-v01 (1)_1_visual">
                <geometry>
                    <mesh>
                        <uri>model://Roboy/meshes/p-gelenkhuelse-v01 (1)_1.stl</uri>
                        <scale>0.001 0.001 0.001</scale>
                    </mesh>
                </geometry>
            </visual>
        </link>
        <joint name="neck_1" type="revolute">
            <parent>spine</parent>
            <child>neck_cross</child>
            <pose frame="">0.12801383052426937 0.9961602353901188 -0.16453407433259304 0 0 0</pose>
            <axis>
                <xyz>0.9819083441393149 0.10397867012173197 -0.1582543518179061</xyz>
                <limit>
                    <lower>0.6981317007977318</lower>
                    <upper>0.8726646259971648</upper>
                </limit>
                <use_parent_model_frame>0</use_parent_model_frame>
            </axis>
        </joint>
        <joint name="neck_2" type="revolute">
            <parent>neck_cross</parent>
            <child>neck</child>
            <pose frame="">0.14181295504535882 0.9987460337115193 -0.156203539566294 0 0 0</pose>
            <axis>
                <xyz>-0.14526383041405813 -0.12248237570289862 -0.9817823013354898</xyz>
                <limit>
                    <lower>-0.08726646259971647</lower>
                    <upper>0.08726646259971647</upper>
                </limit>
                <use_parent_model_frame>0</use_parent_model_frame>
            </axis>
        </joint>
        <joint name="neck_3" type="revolute">
            <parent>neck</parent>
            <child>head</child>
            <pose frame="">0.13615840195991172 1.0293846539788765 -0.17115725072829358 0 0 0</pose>
            <axis>
                <xyz>-0.12146778701789739 0.9870088671343797 -0.1051621268094396</xyz>
                <limit>
                    <lower>-0.6108652381980153</lower>
                    <upper>0.6108652381980153</upper>
                </limit>
                <use_parent_model_frame>0</use_parent_model_frame>
            </axis>
        </joint>
        <joint name="wrist_right" type="revolute">
            <parent>lower_arm_right</parent>
            <child>hand_right</child>
            <pose frame="">-0.045090229181005394 0.664811907204535 -0.06457766823797353 0 0 0</pose>
            <axis>
                <xyz>0.33394371296113967 0.05457426942028357 0.9410118201653906</xyz>
                <limit>
                    <lower>-3.141592653589793</lower>
                    <upper>-0.0</upper>
                </limit>
                <use_parent_model_frame>0</use_parent_model_frame>
            </axis>
        </joint>
        <joint name="wrist_left" type="revolute">
            <parent>lower_arm_left</parent>
            <child>hand_left</child>
            <pose frame="">0.4091605789532073 0.7129876209300708 -0.1340059553967198 0 0 0</pose>
            <axis>
                <xyz>-0.07577327739673245 0.010994747426339697 0.9970644542664181</xyz>
                <limit>
                    <lower>-0.0</lower>
                    <upper>3.141592653589793</upper>
                </limit>
                <use_parent_model_frame>0</use_parent_model_frame>
            </axis>
        </joint>
        <joint name="groin_side_left" type="revolute">
            <parent>p-gelenkhuelse-v01 (1)_1</parent>
            <child>thigh_left</child>
            <pose frame="">0.28703156210877256 0.4856143810721575 -0.15567910738271282 0 0 0</pose>
            <axis>
                <xyz>0.159396986898053 -0.06877364093258713 0.984816118308742</xyz>
                <limit>
                    <lower>-0.0</lower>
                    <upper>0.2617993877991494</upper>
                </limit>
                <use_parent_model_frame>0</use_parent_model_frame>
            </axis>
        </joint>
    </model>
</sdf>