<?xml version="1.0" ?>
<robot name="msj_platform">
  <joint name="sphere_axis0" type="revolute">
    <parent link="base"/>
    <child link="sphere_link1"/>
    <origin rpy="0  0  0" xyz="-0.00586 -0.00288  0.20086"/>
    <axis xyz="0  1  0"/>
    <limit effort="0.0" lower="-3.14159265359" upper="3.14159265359" velocity="0.0"/>
  </joint>
  <joint name="sphere_axis2" type="revolute">
    <parent link="shere_link2"/>
    <child link="top"/>
    <origin rpy="0  0  0" xyz="0  0  0"/>
    <axis xyz="1  0  0"/>
    <limit effort="0.0" lower="-3.14159265359" upper="3.14159265359" velocity="0.0"/>
  </joint>
  <joint name="sphere_axis1" type="revolute">
    <parent link="sphere_link1"/>
    <child link="shere_link2"/>
    <origin rpy="0  0  0" xyz="0  0  0"/>
    <axis xyz="0  0  1"/>
    <limit effort="0.0" lower="-3.14159265359" upper="3.14159265359" velocity="0.0"/>
  </joint>
  <link name="base">
    <inertial>
      <mass value="3.6472739252434687"/>
      <origin rpy="0  0  0" xyz="0  0  0"/>
      <inertia ixx="0.03586146387347407" ixy="-1.1303529232841489e-06" ixz="3.8887648514888094e-05" iyy="0.03589292285919629" iyz="7.866223328923923e-05" izz="0.00928448638993898"/>
    </inertial>
    <collision name="base_collision">
      <origin rpy="0  0  0" xyz="0  0  0"/>
      <geometry>
        <mesh filename="package://roboy_models/msj_platform/meshes/CAD/base.stl" scale="0.001 0.001 0.001"/>
      </geometry>
    </collision>
    <visual name="base_visual">
      <origin rpy="0  0  0" xyz="0  0  0"/>
      <geometry>
        <mesh filename="package://roboy_models/msj_platform/meshes/CAD/base.stl" scale="0.001 0.001 0.001"/>
      </geometry>
    </visual>
  </link>
  <link name="top">
    <inertial>
      <mass value="1.4067236584724057"/>
      <origin rpy="0  0  0" xyz="0.00735 -0.00183  0.04803"/>
      <inertia ixx="0.09470876042574611" ixy="3.2721529482810944e-06" ixz="0.0016712740561293726" iyy="0.09467130818879316" iyz="-0.0006166992229832789" izz="0.0014789188674900265"/>
    </inertial>
    <collision name="top_collision">
      <origin rpy="0  0  0" xyz="0.00735 -0.00183  0.04803"/>
      <geometry>
        <mesh filename="package://roboy_models/msj_platform/meshes/CAD/top.stl" scale="0.001 0.001 0.001"/>
      </geometry>
    </collision>
    <visual name="top_visual">
      <origin rpy="0  0  0" xyz="0.00735 -0.00183  0.04803"/>
      <geometry>
        <mesh filename="package://roboy_models/msj_platform/meshes/CAD/top.stl" scale="0.001 0.001 0.001"/>
      </geometry>
    </visual>
  </link>
  <link name="sphere_link1">
    <inertial>
      <mass value="0.04675410329068079"/>
      <origin rpy="0  0  0" xyz="0  0  0"/>
      <inertia ixx="0.0018926512789198065" ixy="-7.898287893384006e-07" ixz="2.706424986728297e-05" iyy="0.0018938694695371106" iyz="5.5048462229754525e-05" izz="7.968812736821967e-06"/>
    </inertial>
    <collision name="sphere_link1_collision">
      <origin rpy="0  0  0" xyz="0  0  0"/>
      <geometry>
        <mesh filename="package://roboy_models/msj_platform/meshes/CAD/sphere_link1.stl" scale="0.001 0.001 0.001"/>
      </geometry>
    </collision>
    <visual name="sphere_link1_visual">
      <origin rpy="0  0  0" xyz="0  0  0"/>
      <geometry>
        <mesh filename="package://roboy_models/msj_platform/meshes/CAD/sphere_link1.stl" scale="0.001 0.001 0.001"/>
      </geometry>
    </visual>
  </link>
  <link name="shere_link2">
    <inertial>
      <mass value="0.031340659319131624"/>
      <origin rpy="0  0  0" xyz="0  0  0"/>
      <inertia ixx="0.001267394265267775" ixy="-5.294456163448326e-07" ixz="1.8141967780247655e-05" iyy="0.001268210854500878" iyz="3.69006136177749e-05" izz="4.035823118731119e-06"/>
    </inertial>
    <collision name="shere_link2_collision">
      <origin rpy="0  0  0" xyz="0  0  0"/>
      <geometry>
        <mesh filename="package://roboy_models/msj_platform/meshes/CAD/shere_link2.stl" scale="0.001 0.001 0.001"/>
      </geometry>
    </collision>
    <visual name="shere_link2_visual">
      <origin rpy="0  0  0" xyz="0  0  0"/>
      <geometry>
        <mesh filename="package://roboy_models/msj_platform/meshes/CAD/shere_link2.stl" scale="0.001 0.001 0.001"/>
      </geometry>
    </visual>
  </link>
</robot>
