<?xml version="1.0" ?>
<sdf version="1.6">
	<model name="msj_platform">
		<link name="base">
			<self_collide>false</self_collide>
			<pose frame="">-0.00010653952220834031 -5.27229319905334e-05 0.07647012112656972 0.0 -0.0 0.0</pose>
			<inertial>
				<pose frame="">0.0 0.0 0.0 0 0 0</pose>
				<mass>3.6472739252434687</mass>
				<inertia>
					<ixx>0.03586146387347406</ixx>
					<ixy>-1.1303529232844237e-06</ixy>
					<ixz>3.888764851488904e-05</ixz>
					<iyy>0.03589292285919629</iyy>
					<iyz>7.866223328923924e-05</iyz>
					<izz>0.00928448638993898</izz>
				</inertia>
			</inertial>
			<collision name="base_collision">
				<geometry>
					<mesh>
						<uri>model://msj_platform/meshes/CAD/base.stl</uri>
						<scale>0.001 0.001 0.001</scale>
					</mesh>
				</geometry>
			</collision>
			<visual name="base_visual">
				<geometry>
					<mesh>
						<uri>model://msj_platform/meshes/CAD/base.stl</uri>
						<scale>0.001 0.001 0.001</scale>
					</mesh>
				</geometry>
			</visual>
		</link>
		<link name="top">
			<self_collide>false</self_collide>
			<pose frame="">0.001680411491249952 -0.004587880466821993 0.2580435212672607 0.0 -0.0 0.0</pose>
			<inertial>
				<pose frame="">0.0 0.0 0.0 0 0 0</pose>
				<mass>1.4067236584724316</mass>
				<inertia>
					<ixx>0.09470876042573421</ixx>
					<ixy>3.27215294821768e-06</ixy>
					<ixz>0.0016712740561302993</ixz>
					<iyy>0.09467130818878117</iyy>
					<iyz>-0.0006166992229842169</iyz>
					<izz>0.001478918867489982</izz>
				</inertia>
			</inertial>
			<collision name="top_collision">
				<geometry>
					<mesh>
						<uri>model://msj_platform/meshes/CAD/top.stl</uri>
						<scale>0.001 0.001 0.001</scale>
					</mesh>
				</geometry>
			</collision>
			<visual name="top_visual">
				<geometry>
					<mesh>
						<uri>model://msj_platform/meshes/CAD/top.stl</uri>
						<scale>0.001 0.001 0.001</scale>
					</mesh>
				</geometry>
			</visual>
		</link>
		<link name="sphere_link1">
			<self_collide>false</self_collide>
			<pose frame="">-0.005861802918013167 -0.002881920628113032 0.20086036465457277 0.0 -0.0 0.0</pose>
			<inertial>
				<pose frame="">0.0 0.0 0.0 0 0 0</pose>
				<mass>0.04675410329068079</mass>
				<inertia>
					<ixx>0.0018926512789198065</ixx>
					<ixy>-7.898287893383993e-07</ixy>
					<ixz>2.706424986728296e-05</ixz>
					<iyy>0.0018938694695371102</iyy>
					<iyz>5.504846222975452e-05</iyz>
					<izz>7.968812736821965e-06</izz>
				</inertia>
			</inertial>
			<collision name="sphere_link1_collision">
				<geometry>
					<mesh>
						<uri>model://msj_platform/meshes/CAD/sphere_link1.stl</uri>
						<scale>0.001 0.001 0.001</scale>
					</mesh>
				</geometry>
			</collision>
			<visual name="sphere_link1_visual">
				<geometry>
					<mesh>
						<uri>model://msj_platform/meshes/CAD/sphere_link1.stl</uri>
						<scale>0.001 0.001 0.001</scale>
					</mesh>
				</geometry>
			</visual>
		</link>
		<link name="shere_link2">
			<self_collide>false</self_collide>
			<pose frame="">-0.0058618029173002 -0.0028819206304085284 0.20086036465456758 0.0 -0.0 0.0</pose>
			<inertial>
				<pose frame="">0.0 0.0 0.0 0 0 0</pose>
				<mass>0.03134065931913163</mass>
				<inertia>
					<ixx>0.0012673942652677746</ixx>
					<ixy>-5.294456163448334e-07</ixy>
					<ixz>1.8141967780247638e-05</ixz>
					<iyy>0.0012682108545008775</iyy>
					<iyz>3.690061361777491e-05</iyz>
					<izz>4.0358231187311256e-06</izz>
				</inertia>
			</inertial>
			<collision name="shere_link2_collision">
				<geometry>
					<mesh>
						<uri>model://msj_platform/meshes/CAD/shere_link2.stl</uri>
						<scale>0.001 0.001 0.001</scale>
					</mesh>
				</geometry>
			</collision>
			<visual name="shere_link2_visual">
				<geometry>
					<mesh>
						<uri>model://msj_platform/meshes/CAD/shere_link2.stl</uri>
						<scale>0.001 0.001 0.001</scale>
					</mesh>
				</geometry>
			</visual>
		</link>
		<joint name="sphere_axis0" type="revolute">
			<parent>base</parent>
			<child>sphere_link1</child>
			<pose frame="">3.848287244423432e-12 -1.5770905137379998e-11 -4.629185923477053e-14 0 0 0</pose>
			<axis>
				<xyz>0.6788532852380078 -0.3927582457006513 -0.6204024319389075</xyz>
				<limit>
					<lower>-3.141592653589793</lower>
					<upper>3.141592653589793</upper>
				</limit>
				<use_parent_model_frame>0</use_parent_model_frame>
			</axis>
		</joint>
		<joint name="sphere_axis2" type="revolute">
			<parent>shere_link2</parent>
			<child>top</child>
			<pose frame="">-0.007542214405414815 0.00170595982293806 -0.05718315661273422 0 0 0</pose>
			<axis>
				<xyz>0.7342739387459998 0.3631141067781174 0.5735764363510464</xyz>
				<limit>
					<lower>-3.141592653589793</lower>
					<upper>3.141592653589793</upper>
				</limit>
				<use_parent_model_frame>0</use_parent_model_frame>
			</axis>
		</joint>
		<joint name="sphere_axis1" type="revolute">
			<parent>sphere_link1</parent>
			<child>shere_link2</child>
			<pose frame="">3.135312010016378e-12 -1.3475415783226197e-11 -4.1104897263721797e-14 0 0 0</pose>
			<axis>
				<xyz>-8.673617379884035e-17 -0.8449195854593954 0.5348933483481761</xyz>
				<limit>
					<lower>-3.141592653589793</lower>
					<upper>3.141592653589793</upper>
				</limit>
				<use_parent_model_frame>0</use_parent_model_frame>
			</axis>
		</joint>
		<plugin filename="libmusc_plugin.so" name="musc_plugin">
			<myoMuscle name="motor2">
				<link name="base">
					<viaPoint type="FIXPOINT">0.050933329076483215 0.04716539797473276 -0.06348244067849006</viaPoint>
					<viaPoint type="FIXPOINT">0.04934165148521573 0.044069464483268636 0.07852987887343028</viaPoint>
				</link>
				<link name="top">
					<viaPoint type="FIXPOINT">0.027323208462515392 0.03973662756980108 -0.014760620725112724</viaPoint>
				</link>
			</myoMuscle>
			<myoMuscle name="motor5">
				<link name="base">
					<viaPoint type="FIXPOINT">0.041812071366857585 -0.04632891916443045 -0.003549204630015046</viaPoint>
					<viaPoint type="FIXPOINT">0.012426769133307671 -0.04937837082083255 0.07852987887343028</viaPoint>
				</link>
				<link name="top">
					<viaPoint type="FIXPOINT">-0.006120156316606614 -0.0483301970349366 -0.013431128374969107</viaPoint>
				</link>
			</myoMuscle>
			<myoMuscle name="motor0">
				<link name="base">
					<viaPoint type="FIXPOINT">-0.047006135520533884 0.05087951248626539 -0.06348244067849006</viaPoint>
					<viaPoint type="FIXPOINT">-0.04391020202906977 0.04928783489499791 0.07852987887343028</viaPoint>
				</link>
				<link name="top">
					<viaPoint type="FIXPOINT">-0.04013092614173135 0.027311062290700634 -0.014548365484927146</viaPoint>
				</link>
			</myoMuscle>
			<myoMuscle name="motor1">
				<link name="base">
					<viaPoint type="FIXPOINT">-0.04159899232244091 0.04643436502841151 -0.003549204630015046</viaPoint>
					<viaPoint type="FIXPOINT">-0.012213690088890998 0.049483816684813615 0.07852987887343028</viaPoint>
				</link>
				<link name="top">
					<viaPoint type="FIXPOINT">0.00573978739886981 0.04793120788092411 -0.01487461675055691</viaPoint>
				</link>
			</myoMuscle>
			<myoMuscle name="motor3">
				<link name="base">
					<viaPoint type="FIXPOINT">0.046488181618629325 0.041758254776639775 -0.003549204630015046</viaPoint>
					<viaPoint type="FIXPOINT">0.049537633275031426 0.01237295254308986 0.07852987887343028</viaPoint>
				</link>
				<link name="top">
					<viaPoint type="FIXPOINT">0.04794592537553836 -0.006129087497454217 -0.014083174587849214</viaPoint>
				</link>
			</myoMuscle>
			<myoMuscle name="motor4">
				<link name="base">
					<viaPoint type="FIXPOINT">0.047219214564950554 -0.05077406662228433 -0.06348244067849006</viaPoint>
					<viaPoint type="FIXPOINT">0.044123281073486446 -0.049182389031016856 0.07852987887343028</viaPoint>
				</link>
				<link name="top">
					<viaPoint type="FIXPOINT">0.03975055722399454 -0.027710051444713165 -0.013757379640598871</viaPoint>
				</link>
			</myoMuscle>
			<myoMuscle name="motor6">
				<link name="base">
					<viaPoint type="FIXPOINT">-0.05072025003206652 -0.04705995211075169 -0.06348244067849006</viaPoint>
					<viaPoint type="FIXPOINT">-0.04912857244079904 -0.043964018619287594 0.07852987887343028</viaPoint>
				</link>
				<link name="top">
					<viaPoint type="FIXPOINT">-0.027703577380252194 -0.04013561672381357 -0.013545124400413293</viaPoint>
				</link>
			</myoMuscle>
			<myoMuscle name="motor7">
				<link name="base">
					<viaPoint type="FIXPOINT">-0.04627510257421263 -0.04165280891265872 -0.003549204630015046</viaPoint>
					<viaPoint type="FIXPOINT">-0.04932455423061475 -0.012267506679108817 0.07852987887343028</viaPoint>
				</link>
				<link name="top">
					<viaPoint type="FIXPOINT">-0.04832629429327517 0.005730098343441697 -0.014222570537676766</viaPoint>
				</link>
			</myoMuscle>
		</plugin>
	</model>
</sdf>
