<?xml version="1.0" ?>
<sdf version="1.6">
	<model name="msj_platform">
		<link name="base">
			<self_collide>false</self_collide>
			<pose frame="">0.0 0.0 0.0 0.0 -0.0 0.0</pose>
			<inertial>
				<pose frame="">0.0 0.0 0.0 0 0 0</pose>
				<mass>3.6472739252434687</mass>
				<inertia>
					<ixx>0.03586146387347407</ixx>
					<ixy>-1.1303529232841489e-06</ixy>
					<ixz>3.8887648514888094e-05</ixz>
					<iyy>0.03589292285919629</iyy>
					<iyz>7.866223328923923e-05</iyz>
					<izz>0.00928448638993898</izz>
				</inertia>
			</inertial>
			<collision name="base_collision">
				<geometry>
					<mesh>
						<uri>model://msj_platform/meshes/CAD/base.stl</uri>
						<scale>0.001 0.001 0.001</scale>
					</mesh>
				</geometry>
			</collision>
			<visual name="base_visual">
				<geometry>
					<mesh>
						<uri>model://msj_platform/meshes/CAD/base.stl</uri>
						<scale>0.001 0.001 0.001</scale>
					</mesh>
				</geometry>
			</visual>
		</link>
		<link name="top">
			<self_collide>false</self_collide>
			<pose frame="">0.001492193313035837 -0.004712648155687583 0.2488900898758617 0.0 -0.0 0.0</pose>
			<inertial>
				<pose frame="">0.0 0.0 0.0 0 0 0</pose>
				<mass>1.4067236584724057</mass>
				<inertia>
					<ixx>0.09470876042574611</ixx>
					<ixy>3.2721529482810944e-06</ixy>
					<ixz>0.0016712740561293726</ixz>
					<iyy>0.09467130818879316</iyy>
					<iyz>-0.0006166992229832789</iyz>
					<izz>0.0014789188674900265</izz>
				</inertia>
			</inertial>
			<collision name="top_collision">
				<geometry>
					<mesh>
						<uri>model://msj_platform/meshes/CAD/top.stl</uri>
						<scale>0.001 0.001 0.001</scale>
					</mesh>
				</geometry>
			</collision>
			<visual name="top_visual">
				<geometry>
					<mesh>
						<uri>model://msj_platform/meshes/CAD/top.stl</uri>
						<scale>0.001 0.001 0.001</scale>
					</mesh>
				</geometry>
			</visual>
		</link>
		<link name="sphere_link1">
			<self_collide>false</self_collide>
			<pose frame="">-0.005861802918013167 -0.002881920628113032 0.20086036465457277 0.0 -0.0 0.0</pose>
			<inertial>
				<pose frame="">0.0 0.0 0.0 0 0 0</pose>
				<mass>0.04675410329068079</mass>
				<inertia>
					<ixx>0.0018926512789198065</ixx>
					<ixy>-7.898287893384006e-07</ixy>
					<ixz>2.706424986728297e-05</ixz>
					<iyy>0.0018938694695371106</iyy>
					<iyz>5.5048462229754525e-05</iyz>
					<izz>7.968812736821967e-06</izz>
				</inertia>
			</inertial>
			<collision name="sphere_link1_collision">
				<geometry>
					<mesh>
						<uri>model://msj_platform/meshes/CAD/sphere_link1.stl</uri>
						<scale>0.001 0.001 0.001</scale>
					</mesh>
				</geometry>
			</collision>
			<visual name="sphere_link1_visual">
				<geometry>
					<mesh>
						<uri>model://msj_platform/meshes/CAD/sphere_link1.stl</uri>
						<scale>0.001 0.001 0.001</scale>
					</mesh>
				</geometry>
			</visual>
		</link>
		<link name="shere_link2">
			<self_collide>false</self_collide>
			<pose frame="">-0.005861802917300203 -0.0028819206304085284 0.20086036465456758 0.0 -0.0 0.0</pose>
			<inertial>
				<pose frame="">0.0 0.0 0.0 0 0 0</pose>
				<mass>0.031340659319131624</mass>
				<inertia>
					<ixx>0.001267394265267775</ixx>
					<ixy>-5.294456163448326e-07</ixy>
					<ixz>1.8141967780247655e-05</ixz>
					<iyy>0.001268210854500878</iyy>
					<iyz>3.69006136177749e-05</iyz>
					<izz>4.035823118731119e-06</izz>
				</inertia>
			</inertial>
			<collision name="shere_link2_collision">
				<geometry>
					<mesh>
						<uri>model://msj_platform/meshes/CAD/shere_link2.stl</uri>
						<scale>0.001 0.001 0.001</scale>
					</mesh>
				</geometry>
			</collision>
			<visual name="shere_link2_visual">
				<geometry>
					<mesh>
						<uri>model://msj_platform/meshes/CAD/shere_link2.stl</uri>
						<scale>0.001 0.001 0.001</scale>
					</mesh>
				</geometry>
			</visual>
		</link>
		<joint name="sphere_axis0" type="revolute">
			<parent>base</parent>
			<child>sphere_link1</child>
			<pose frame="">3.848287244423432e-12 -1.5770905137379998e-11 -4.629185923477053e-14 0 0 0</pose>
			<axis>
				<xyz>0 1 0</xyz>
				<limit>
					<lower>-3.141592653589793</lower>
					<upper>3.141592653589793</upper>
				</limit>
				<use_parent_model_frame>0</use_parent_model_frame>
			</axis>
		</joint>
		<joint name="sphere_axis2" type="revolute">
			<parent>shere_link2</parent>
			<child>top</child>
			<pose frame="">-0.007353996227200699 0.0018307275118036503 -0.048029725221335196 0 0 0</pose>
			<axis>
				<xyz>1 0 0</xyz>
				<limit>
					<lower>-3.141592653589793</lower>
					<upper>3.141592653589793</upper>
				</limit>
				<use_parent_model_frame>0</use_parent_model_frame>
			</axis>
		</joint>
		<joint name="sphere_axis1" type="revolute">
			<parent>sphere_link1</parent>
			<child>shere_link2</child>
			<pose frame="">3.1353142304624272e-12 -1.3475415783226197e-11 -4.1104897263721797e-14 0 0 0</pose>
			<axis>
				<xyz>0 0 1</xyz>
				<limit>
					<lower>-3.141592653589793</lower>
					<upper>3.141592653589793</upper>
				</limit>
				<use_parent_model_frame>0</use_parent_model_frame>
			</axis>
		</joint>
		<plugin filename="libmusc_plugin.so" name="musc_plugin">
			<myoMuscle name="motor1">
				<link name="base">
					<!--<viaPoint type="FIXPOINT">-0.04170553184464925 0.046381642096420976 0.07292091649655467</viaPoint>-->
					<viaPoint type="FIXPOINT">-0.012320229611099338 0.049431093752823084 0.155</viaPoint>
				</link>
				<link name="top">
					<viaPoint type="FIXPOINT">0.005928005577083926 0.048055975569789695 -0.005721185359157879</viaPoint>
				</link>
			</myoMuscle>
			<myoMuscle name="motor0">
				<link name="base">
					<!--<viaPoint type="FIXPOINT">-0.047112675042742226 0.05082678955427486 0.012987680448079662</viaPoint>-->
					<viaPoint type="FIXPOINT">-0.04401674155127811 0.04923511196300738 0.155</viaPoint>
				</link>
				<link name="top">
					<viaPoint type="FIXPOINT">-0.03994270796351723 0.02743582997956623 -0.005394934093528115</viaPoint>
				</link>
			</myoMuscle>
			<myoMuscle name="motor7">
				<link name="base">
					<!--<viaPoint type="FIXPOINT">-0.046381642096420976 -0.04170553184464925 0.07292091649655467</viaPoint>-->
					<viaPoint type="FIXPOINT">-0.04943109375282309 -0.012320229611099352 0.155</viaPoint>
				</link>
				<link name="top">
					<viaPoint type="FIXPOINT">-0.04813807611506105 0.005854866032307288 -0.005069139146277735</viaPoint>
				</link>
			</myoMuscle>
			<myoMuscle name="motor6">
				<link name="base">
					<!--<viaPoint type="FIXPOINT">-0.05082678955427486 -0.04711267504274222 0.012987680448079662</viaPoint>-->
					<viaPoint type="FIXPOINT">-0.04923511196300738 -0.044016741551278125 0.155</viaPoint>
				</link>
				<link name="top">
					<viaPoint type="FIXPOINT">-0.02751535920203808 -0.04001084903494799 -0.004391693009014262</viaPoint>
				</link>
			</myoMuscle>
			<myoMuscle name="motor5">
				<link name="base">
					<!--<viaPoint type="FIXPOINT">0.04170553184464924 -0.04638164209642098 0.07292091649655467</viaPoint>-->
					<viaPoint type="FIXPOINT">0.012320229611099331 -0.049431093752823084 0.155</viaPoint>
				</link>
				<link name="top">
					<viaPoint type="FIXPOINT">-0.005931938138392498 -0.04820542934607102 -0.0042776969835700744</viaPoint>
				</link>
			</myoMuscle>
			<myoMuscle name="motor4">
				<link name="base">
					<!--<viaPoint type="FIXPOINT">0.04711267504274221 -0.05082678955427486 0.012987680448079662</viaPoint>-->
					<viaPoint type="FIXPOINT">0.0440167415512781 -0.04923511196300739 0.155</viaPoint>
				</link>
				<link name="top">
					<viaPoint type="FIXPOINT">0.03993877540220865 -0.02758528375584757 -0.004603948249199839</viaPoint>
				</link>
			</myoMuscle>
			<myoMuscle name="motor3">
				<link name="base">
					<!--<viaPoint type="FIXPOINT">0.04638164209642098 0.04170553184464924 0.07292091649655467</viaPoint>-->
					<viaPoint type="FIXPOINT">0.049431093752823084 0.012320229611099328 0.155</viaPoint>
				</link>
				<link name="top">
					<viaPoint type="FIXPOINT">0.04813414355375247 -0.006004319808588627 -0.004929743196450183</viaPoint>
				</link>
			</myoMuscle>
			<myoMuscle name="motor2">
				<link name="base">
					<!--<viaPoint type="FIXPOINT">0.05082678955427487 0.047112675042742226 0.012987680448079662</viaPoint>-->
					<viaPoint type="FIXPOINT">0.04923511196300739 0.0440167415512781 0.155</viaPoint>
				</link>
				<link name="top">
					<viaPoint type="FIXPOINT">0.027511426640729506 0.039861395258666665 -0.0056071893337136915</viaPoint>
				</link>
			</myoMuscle>
		</plugin>
	</model>
</sdf>
