<?xml version="1.0" ?>
<sdf version="1.6">
	<model name="msj_platform">
		<link name="base">
			<self_collide>false</self_collide>
			<pose frame="">0.0 0.0 0.0 0.0 -0.0 0.0</pose>
			<inertial>
				<pose frame="">0.0 0.0 0.0 0 0 0</pose>
				<mass>3.8148275066330855</mass>
				<inertia>
					<ixx>0.04150068984077175</ixx>
					<ixy>4.470723592269597e-05</ixy>
					<ixz>-0.00014502796362697503</ixz>
					<iyy>0.041725216427853574</iyy>
					<iyz>0.0008715130471075753</iyz>
					<izz>0.0095173924727368</izz>
				</inertia>
			</inertial>
			<collision name="base_collision">
				<geometry>
					<mesh>
						<uri>model://msj_platform/meshes/CAD/base.stl</uri>
						<scale>0.001 0.001 0.001</scale>
					</mesh>
				</geometry>
			</collision>
			<visual name="base_visual">
				<geometry>
					<mesh>
						<uri>model://msj_platform/meshes/CAD/base.stl</uri>
						<scale>0.001 0.001 0.001</scale>
					</mesh>
				</geometry>
			</visual>
		</link>
		<link name="top">
			<self_collide>false</self_collide>
			<pose frame="">-0.0008893012765514059 -0.0020516196624920484 0.2700000000000001 0.0 -0.0 0.0</pose>
			<inertial>
				<pose frame="">0.0 0.0 0.0 0 0 0</pose>
				<mass>1.4386868841347857</mass>
				<inertia>
					<ixx>0.11326640346901959</ixx>
					<ixy>-3.2206382165718335e-06</ixy>
					<ixz>0.0008065683357513999</ixz>
					<iyy>0.11327509366805992</iyy>
					<iyz>0.00041743572684559995</iyz>
					<izz>0.0014483963655294574</izz>
				</inertia>
			</inertial>
			<collision name="top_collision">
				<geometry>
					<mesh>
						<uri>model://msj_platform/meshes/CAD/top.stl</uri>
						<scale>0.001 0.001 0.001</scale>
					</mesh>
				</geometry>
			</collision>
			<visual name="top_visual">
				<geometry>
					<mesh>
						<uri>model://msj_platform/meshes/CAD/top.stl</uri>
						<scale>0.001 0.001 0.001</scale>
					</mesh>
				</geometry>
			</visual>
		</link>
		<link name="sphere_link1">
			<self_collide>false</self_collide>
			<pose frame="">-0.000889301276551448 -0.002051619662492109 0.217 0.0 -0.0 0.0</pose>
			<inertial>
				<pose frame="">0.0 0.0 0.0 0 0 0</pose>
				<mass>0.046754103129627085</mass>
				<inertia>
					<ixx>0.0022077747497812328</ixx>
					<ixy>-8.530323448460815e-08</ixy>
					<ixz>2.0814995290395064e-05</ixz>
					<iyy>0.002207614930862665</iyy>
					<iyz>9.022530940591381e-06</iyz>
					<izz>6.207763308763075e-06</izz>
				</inertia>
			</inertial>
			<collision name="sphere_link1_collision">
				<geometry>
					<mesh>
						<uri>model://msj_platform/meshes/CAD/sphere_link1.stl</uri>
						<scale>0.001 0.001 0.001</scale>
					</mesh>
				</geometry>
			</collision>
			<visual name="sphere_link1_visual">
				<geometry>
					<mesh>
						<uri>model://msj_platform/meshes/CAD/sphere_link1.stl</uri>
						<scale>0.001 0.001 0.001</scale>
					</mesh>
				</geometry>
			</visual>
		</link>
		<link name="shere_link2">
			<self_collide>false</self_collide>
			<pose frame="">-0.0008893012765515347 -0.002051619662492078 0.21700000000000003 0.0 -0.0 0.0</pose>
			<inertial>
				<pose frame="">0.0 0.0 0.0 0 0 0</pose>
				<mass>0.03134065921190476</mass>
				<inertia>
					<ixx>0.0014786308552238916</ixx>
					<ixy>-5.7181282982661204e-08</ixy>
					<ixz>1.3952907450389782e-05</ixz>
					<iyy>0.001478523723872263</iyy>
					<iyz>6.048069549189643e-06</iyz>
					<izz>2.855339566723973e-06</izz>
				</inertia>
			</inertial>
			<collision name="shere_link2_collision">
				<geometry>
					<mesh>
						<uri>model://msj_platform/meshes/CAD/shere_link2.stl</uri>
						<scale>0.001 0.001 0.001</scale>
					</mesh>
				</geometry>
			</collision>
			<visual name="shere_link2_visual">
				<geometry>
					<mesh>
						<uri>model://msj_platform/meshes/CAD/shere_link2.stl</uri>
						<scale>0.001 0.001 0.001</scale>
					</mesh>
				</geometry>
			</visual>
		</link>
		<joint name="sphere_axis0" type="revolute">
			<parent>base</parent>
			<child>sphere_link1</child>
			<pose frame="">5.662137425588298e-17 6.078471059822732e-17 0.0 0 0 0</pose>
			<axis>
				<xyz>0.6427876096865393 -0.766044443118979 -6.390051200643889e-18</xyz>
				<limit>
					<lower>-3.141592653589793</lower>
					<upper>3.141592653589793</upper>
				</limit>
				<use_parent_model_frame>0</use_parent_model_frame>
			</axis>
		</joint>
		<joint name="sphere_axis2" type="revolute">
			<parent>shere_link2</parent>
			<child>top</child>
			<pose frame="">-2.2620794126737566e-17 -2.4147350785597155e-17 -0.05300000000000008 0 0 0</pose>
			<axis>
				<xyz>4.163336342344338e-17 -2.77555756156289e-17 1.0</xyz>
				<limit>
					<lower>-3.141592653589793</lower>
					<upper>3.141592653589793</upper>
				</limit>
				<use_parent_model_frame>0</use_parent_model_frame>
			</axis>
		</joint>
		<joint name="sphere_axis1" type="revolute">
			<parent>sphere_link1</parent>
			<child>shere_link2</child>
			<pose frame="">1.4127587988355117e-16 2.7200464103316335e-17 -7.105427357601002e-17 0 0 0</pose>
			<axis>
				<xyz>-0.7660444431189791 -0.6427876096865395 1.2507436905595332e-16</xyz>
				<limit>
					<lower>-3.141592653589793</lower>
					<upper>3.141592653589793</upper>
				</limit>
				<use_parent_model_frame>0</use_parent_model_frame>
			</axis>
		</joint>
		<plugin filename="libmusc_plugin.so" name="musc_plugin">
			<myoMuscle name="motor0">
				<link name="base">
					<viaPoint type="FIXPOINT">-0.04660000000000003 -0.04165787158657344 0.08457578409489053</viaPoint>
					<viaPoint type="FIXPOINT">-0.04923511196300738 -0.044016741551278125 0.155</viaPoint>
				</link>
				<link name="top">
					<viaPoint type="FIXPOINT">-0.006805803162371615 -0.04802011082156157 -0.005</viaPoint>
				</link>
			</myoMuscle>
			<myoMuscle name="motor1">
				<link name="base">
					<viaPoint type="FIXPOINT">-0.052500119859286494 -0.04597079381615164 0.023401396914450034</viaPoint>
					<viaPoint type="FIXPOINT">-0.04923511196300738 -0.044016741551278125 0.155</viaPoint>
				</link>
				<link name="top">
					<viaPoint type="FIXPOINT">-0.04802011082156155 0.006805803162371622 -0.005</viaPoint>
				</link>
			</myoMuscle>
			<myoMuscle name="motor4">
				<link name="base">
					<viaPoint type="FIXPOINT">0.046600000000000044 0.04165787158657345 0.08457578409489053</viaPoint>
					<viaPoint type="FIXPOINT">0.04923511196300739 0.0440167415512781 0.155</viaPoint>
				</link>
				<link name="top">
					<viaPoint type="FIXPOINT">0.04802011082156155 -0.006805803162371627 -0.005</viaPoint>
				</link>
			</myoMuscle>
			<myoMuscle name="motor5">
				<link name="base">
					<viaPoint type="FIXPOINT">0.05250011985928649 0.04597079381615165 0.023401396914450034</viaPoint>
					<viaPoint type="FIXPOINT">0.04923511196300739 0.0440167415512781 0.155</viaPoint>
				</link>
				<link name="top">
					<viaPoint type="FIXPOINT">0.0068058031623716335 0.04802011082156155 -0.005</viaPoint>
				</link>
			</myoMuscle>
			<myoMuscle name="motor2">
				<link name="base">
					<viaPoint type="FIXPOINT">0.041657871586573435 -0.04660000000000004 0.08457578409489053</viaPoint>
					<viaPoint type="FIXPOINT">0.0440167415512781 -0.04923511196300739 0.155</viaPoint>
				</link>
				<link name="top">
					<viaPoint type="FIXPOINT">-0.006805803162371615 -0.04802011082156157 -0.005</viaPoint>
				</link>
			</myoMuscle>
			<myoMuscle name="motor3">
				<link name="base">
					<viaPoint type="FIXPOINT">0.045970793816151635 -0.052500119859286494 0.023401396914450034</viaPoint>
					<viaPoint type="FIXPOINT">0.0440167415512781 -0.04923511196300739 0.155</viaPoint>
				</link>
				<link name="top">
					<viaPoint type="FIXPOINT">0.04802011082156155 -0.006805803162371627 -0.005</viaPoint>
				</link>
			</myoMuscle>
			<myoMuscle name="motor6">
				<link name="base">
					<viaPoint type="FIXPOINT">-0.04165787158657344 0.04660000000000003 0.08457578409489053</viaPoint>
					<viaPoint type="FIXPOINT">-0.04401674155127811 0.04923511196300738 0.155</viaPoint>
				</link>
				<link name="top">
					<viaPoint type="FIXPOINT">-0.04802011082156155 0.006805803162371622 -0.005</viaPoint>
				</link>
			</myoMuscle>
			<myoMuscle name="motor7">
				<link name="base">
					<viaPoint type="FIXPOINT">-0.04597079381615165 0.05250011985928649 0.023401396914450034</viaPoint>
					<viaPoint type="FIXPOINT">-0.04401674155127811 0.04923511196300738 0.155</viaPoint>
				</link>
				<link name="top">
					<viaPoint type="FIXPOINT">0.0068058031623716335 0.04802011082156155 -0.005</viaPoint>
				</link>
			</myoMuscle>
		</plugin>
	</model>
</sdf>
