<?xml version="1.0" ?>
<sdf version="1.6">
	<model name="TestRobot">
		<link name="base">
			<self_collide>false</self_collide>
			<pose frame="">0.0 0.0 0.0 0.0 -0.0 0.0</pose>
			<inertial>
				<pose frame="">0.0 0.0 0.0 0 0 0</pose>
				<mass>10000</mass>
				<inertia>
					<ixx>0.1</ixx>
					<ixy>0.0</ixy>
					<ixz>0.0</ixz>
					<iyy>0.1</iyy>
					<iyz>0.0</iyz>
					<izz>0.1</izz>
				</inertia>
			</inertial>
			<collision name="base_collision">
				<geometry>
					<mesh>
						<uri>model://TestRobot/meshes/CAD/base.stl</uri>
						<scale>0.001 0.001 0.001</scale>
					</mesh>
				</geometry>
			</collision>
			<visual name="base_visual">
				<geometry>
					<mesh>
						<uri>model://TestRobot/meshes/CAD/base.stl</uri>
						<scale>0.001 0.001 0.001</scale>
					</mesh>
				</geometry>
			</visual>
		</link>
		<link name="link0">
			<self_collide>false</self_collide>
			<pose frame="">0.0 0.0 0.02 0.0 -0.0 0.0</pose>
			<inertial>
				<pose frame="">0.0 0.0 0.0 0 0 0</pose>
				<mass>0.1</mass>
				<inertia>
					<ixx>0.1</ixx>
					<ixy>0.0</ixy>
					<ixz>0.0</ixz>
					<iyy>0.1</iyy>
					<iyz>0.0</iyz>
					<izz>0.1</izz>
				</inertia>
			</inertial>
			<collision name="link0_collision">
				<geometry>
					<mesh>
						<uri>model://TestRobot/meshes/CAD/link0.stl</uri>
						<scale>0.001 0.001 0.001</scale>
					</mesh>
				</geometry>
			</collision>
			<visual name="link0_visual">
				<geometry>
					<mesh>
						<uri>model://TestRobot/meshes/CAD/link0.stl</uri>
						<scale>0.001 0.001 0.001</scale>
					</mesh>
				</geometry>
			</visual>
		</link>
		<link name="link1">
			<self_collide>false</self_collide>
			<pose frame="">0.0 0.0 0.02 0.0 -0.0 0.0</pose>
			<inertial>
				<pose frame="">0.0 0.0 0.0 0 0 0</pose>
				<mass>0.1</mass>
				<inertia>
					<ixx>0.1</ixx>
					<ixy>0.0</ixy>
					<ixz>0.0</ixz>
					<iyy>0.1</iyy>
					<iyz>0.0</iyz>
					<izz>0.1</izz>
				</inertia>
			</inertial>
			<collision name="link1_collision">
				<geometry>
					<mesh>
						<uri>model://TestRobot/meshes/CAD/link1.stl</uri>
						<scale>0.001 0.001 0.001</scale>
					</mesh>
				</geometry>
			</collision>
			<visual name="link1_visual">
				<geometry>
					<mesh>
						<uri>model://TestRobot/meshes/CAD/link1.stl</uri>
						<scale>0.001 0.001 0.001</scale>
					</mesh>
				</geometry>
			</visual>
		</link>
		<link name="link2">
			<self_collide>false</self_collide>
			<pose frame="">2.886579864025407e-17 2.836240259503089e-18 0.2700000000000003 0.0 -0.0 0.0</pose>
			<inertial>
				<pose frame="">0.0 0.0 0.0 0 0 0</pose>
				<mass>0.1</mass>
				<inertia>
					<ixx>0.1</ixx>
					<ixy>0.0</ixy>
					<ixz>0.0</ixz>
					<iyy>0.1</iyy>
					<iyz>0.0</iyz>
					<izz>0.1</izz>
				</inertia>
			</inertial>
			<collision name="link2_collision">
				<geometry>
					<mesh>
						<uri>model://TestRobot/meshes/CAD/link2.stl</uri>
						<scale>0.001 0.001 0.001</scale>
					</mesh>
				</geometry>
			</collision>
			<visual name="link2_visual">
				<geometry>
					<mesh>
						<uri>model://TestRobot/meshes/CAD/link2.stl</uri>
						<scale>0.001 0.001 0.001</scale>
					</mesh>
				</geometry>
			</visual>
		</link>
		<link name="link3">
			<self_collide>false</self_collide>
			<pose frame="">-0.005000000000000067 1.8984017961129955e-16 0.5480000000000006 0.0 -0.0 0.0</pose>
			<inertial>
				<pose frame="">0.0 0.0 0.0 0 0 0</pose>
				<mass>0.1</mass>
				<inertia>
					<ixx>0.1</ixx>
					<ixy>0.0</ixy>
					<ixz>0.0</ixz>
					<iyy>0.1</iyy>
					<iyz>0.0</iyz>
					<izz>0.1</izz>
				</inertia>
			</inertial>
			<collision name="link3_collision">
				<geometry>
					<mesh>
						<uri>model://TestRobot/meshes/CAD/link3.stl</uri>
						<scale>0.001 0.001 0.001</scale>
					</mesh>
				</geometry>
			</collision>
			<visual name="link3_visual">
				<geometry>
					<mesh>
						<uri>model://TestRobot/meshes/CAD/link3.stl</uri>
						<scale>0.001 0.001 0.001</scale>
					</mesh>
				</geometry>
			</visual>
		</link>
		<link name="link4">
			<self_collide>false</self_collide>
			<pose frame="">-0.005000000000000067 1.8984017961129955e-16 0.5480000000000006 0.0 -0.0 0.0</pose>
			<inertial>
				<pose frame="">0.0 0.0 0.0 0 0 0</pose>
				<mass>0.1</mass>
				<inertia>
					<ixx>0.1</ixx>
					<ixy>0.0</ixy>
					<ixz>0.0</ixz>
					<iyy>0.1</iyy>
					<iyz>0.0</iyz>
					<izz>0.1</izz>
				</inertia>
			</inertial>
			<collision name="link4_collision">
				<geometry>
					<mesh>
						<uri>model://TestRobot/meshes/CAD/link4.stl</uri>
						<scale>0.001 0.001 0.001</scale>
					</mesh>
				</geometry>
			</collision>
			<visual name="link4_visual">
				<geometry>
					<mesh>
						<uri>model://TestRobot/meshes/CAD/link4.stl</uri>
						<scale>0.001 0.001 0.001</scale>
					</mesh>
				</geometry>
			</visual>
		</link>
		<link name="link5">
			<self_collide>false</self_collide>
			<pose frame="">0.0 0.0 0.6410000000000006 0.0 -0.0 0.0</pose>
			<inertial>
				<pose frame="">0.0 0.0 0.0 0 0 0</pose>
				<mass>0.1</mass>
				<inertia>
					<ixx>0.1</ixx>
					<ixy>0.0</ixy>
					<ixz>0.0</ixz>
					<iyy>0.1</iyy>
					<iyz>0.0</iyz>
					<izz>0.1</izz>
				</inertia>
			</inertial>
			<collision name="link5_collision">
				<geometry>
					<mesh>
						<uri>model://TestRobot/meshes/CAD/link5.stl</uri>
						<scale>0.001 0.001 0.001</scale>
					</mesh>
				</geometry>
			</collision>
			<visual name="link5_visual">
				<geometry>
					<mesh>
						<uri>model://TestRobot/meshes/CAD/link5.stl</uri>
						<scale>0.001 0.001 0.001</scale>
					</mesh>
				</geometry>
			</visual>
		</link>
		<joint name="joint0" type="prismatic">
			<parent>base</parent>
			<child>link0</child>
			<pose frame="">0.0 0.0 -0.01 0 0 0</pose>
			<axis>
				<xyz>1.0 0.0 0.0</xyz>
				<limit>
					<lower>-0.25</lower>
					<upper>0.25</upper>
				</limit>
				<use_parent_model_frame>0</use_parent_model_frame>
			</axis>
		</joint>
		<joint name="joint1" type="prismatic">
			<parent>link0</parent>
			<child>link1</child>
			<pose frame="">0.0 0.0 0.0 0 0 0</pose>
			<axis>
				<xyz>0.0 -1.0 0.0</xyz>
				<limit>
					<lower>-0.25</lower>
					<upper>0.25</upper>
				</limit>
				<use_parent_model_frame>0</use_parent_model_frame>
			</axis>
		</joint>
		<joint name="joint2" type="prismatic">
			<parent>link1</parent>
			<child>link2</child>
			<pose frame="">4.218847493575595e-17 -5.490229864236325e-17 -0.2500000000000003 0 0 0</pose>
			<axis>
				<xyz>0.0 6.123233995736767e-17 1.0</xyz>
				<limit>
					<lower>0.0</lower>
					<upper>0.5</upper>
				</limit>
				<use_parent_model_frame>0</use_parent_model_frame>
			</axis>
		</joint>
		<joint name="sphere_axis0" type="revolute">
			<parent>link2</parent>
			<child>link3</child>
			<pose frame="">0.0 0.0 0.0 0 0 0</pose>
			<axis>
				<xyz>1.0 0.0 0.0</xyz>
				<limit>
					<lower>-3.141592653589793</lower>
					<upper>3.141592653589793</upper>
				</limit>
				<use_parent_model_frame>0</use_parent_model_frame>
			</axis>
		</joint>
		<joint name="sphere_axis1" type="revolute">
			<parent>link3</parent>
			<child>link4</child>
			<pose frame="">0.0 -3.1554436208840473e-32 0.0 0 0 0</pose>
			<axis>
				<xyz>-0.0 -1.0 4.1389822387888045e-16</xyz>
				<limit>
					<lower>-3.141592653589793</lower>
					<upper>3.141592653589793</upper>
				</limit>
				<use_parent_model_frame>0</use_parent_model_frame>
			</axis>
		</joint>
		<joint name="sphere_axis2" type="revolute">
			<parent>link4</parent>
			<child>link5</child>
			<pose frame="">-0.005000000000000071 1.8984017961129955e-16 -0.0929999999999999 0 0 0</pose>
			<axis>
				<xyz>-1.6554376277507862e-108 4.1389822387888045e-16 1.0</xyz>
				<limit>
					<lower>-3.141592653589793</lower>
					<upper>3.141592653589793</upper>
				</limit>
				<use_parent_model_frame>0</use_parent_model_frame>
			</axis>
		</joint>

		<plugin filename="libmusc_plugin.so" name="musc_plugin">
			<myoMuscle name="motor0">
				<link name="base">
					<viaPoint type="FIXPOINT">0.49 -6.000769315822031e-17 0.03</viaPoint>
				</link>
				<link name="link0">
					<viaPoint type="FIXPOINT">0.24 0.0 0.01</viaPoint>
				</link>
			</myoMuscle>
			<myoMuscle name="motor1">
				<link name="base">
					<viaPoint type="FIXPOINT">-0.49 0.0 0.03</viaPoint>
				</link>
				<link name="link0">
					<viaPoint type="FIXPOINT">-0.24 0.0 0.01</viaPoint>
				</link>
			</myoMuscle>
			<myoMuscle name="motor2">
				<link name="base">
					<viaPoint type="FIXPOINT">-3.0003846579110155e-17 -0.49 0.03</viaPoint>
				</link>
				<link name="link1">
					<viaPoint type="FIXPOINT">-2.524354896707238e-31 -0.24000000000000007 0.010000000000000014</viaPoint>
				</link>
			</myoMuscle>
			<myoMuscle name="motor3">
				<link name="base">
					<viaPoint type="FIXPOINT">9.001153973733046e-17 0.49 0.03</viaPoint>
				</link>
				<link name="link1">
					<viaPoint type="FIXPOINT">2.524354896707238e-31 0.24000000000000007 0.009999999999999983</viaPoint>
				</link>
			</myoMuscle>
			<myoMuscle name="motor4">
				<link name="base">
					<viaPoint type="FIXPOINT">-0.34323811686932443 -0.3432381168693244 1.01</viaPoint>
				</link>
				<link name="link5">
					<viaPoint type="FIXPOINT">-0.08000000000000007 -0.06 0.01899999999999949</viaPoint>
				</link>
			</myoMuscle>
			<myoMuscle name="motor5">
				<link name="base">
					<viaPoint type="FIXPOINT">-0.3432381168693243 0.34323811686932454 1.01</viaPoint>
				</link>
				<link name="link5">
					<viaPoint type="FIXPOINT">-0.08000000000000007 0.03 -0.041000000000000515</viaPoint>
				</link>
			</myoMuscle>
			<myoMuscle name="motor6">
				<link name="base">
					<viaPoint type="FIXPOINT">0.3432381168693244 -0.34323811686932443 1.01</viaPoint>
				</link>
				<link name="link5">
					<viaPoint type="FIXPOINT">0.06999999999999994 -0.06 0.01899999999999949</viaPoint>
				</link>
			</myoMuscle>
			<myoMuscle name="motor7">
				<link name="base">
					<viaPoint type="FIXPOINT">0.34323811686932454 0.3432381168693243 1.01</viaPoint>
				</link>
				<link name="link5">
					<viaPoint type="FIXPOINT">0.06999999999999994 0.03 -0.041000000000000515</viaPoint>
				</link>
			</myoMuscle>
			<myoMuscle name="motor8">
				<link name="base">
					<viaPoint type="FIXPOINT">-7.105427357601002e-17 -0.48541200000000007 1.0100000000000002</viaPoint>
				</link>
				<link name="link5">
					<viaPoint type="FIXPOINT">-0.06 -0.07499999999999973 0.038999999999999486</viaPoint>
				</link>
			</myoMuscle>
			<myoMuscle name="motor9">
				<link name="base">
					<viaPoint type="FIXPOINT">0.48541200000000007 -1.0658141036401502e-16 1.01</viaPoint>
				</link>
				<link name="link5">
					<viaPoint type="FIXPOINT">-0.005000000000000067 2.593750812229514e-16 0.075</viaPoint>
				</link>
			</myoMuscle>
			<myoMuscle name="motor10">
				<link name="base">
					<viaPoint type="FIXPOINT">1.4210854715202004e-16 0.48541200000000007 1.01</viaPoint>
				</link>
				<link name="link5">
					<viaPoint type="FIXPOINT">0.02 0.07500000000000019 -0.05100000000000059</viaPoint>
				</link>
			</myoMuscle>
			<myoMuscle name="motor11">
				<link name="base">
					<viaPoint type="FIXPOINT">-0.48541200000000007 1.7763568394002506e-16 1.01</viaPoint>
				</link>
				<link name="link5">
					<viaPoint type="FIXPOINT">-0.06 0.07500000000000025 0.03899999999999935</viaPoint>
				</link>
			</myoMuscle>
			<myoMuscle name="motor12">
				<link name="base">
					<viaPoint type="FIXPOINT">0.34323811686932454 0.3432381168693243 0.03</viaPoint>
				</link>
				<link name="link5">
					<viaPoint type="FIXPOINT">0.06999999999999994 0.03 -0.041000000000000515</viaPoint>
				</link>
			</myoMuscle>
			<myoMuscle name="motor14">
				<link name="base">
					<viaPoint type="FIXPOINT">0.3432381168693244 -0.34323811686932443 0.03</viaPoint>
				</link>
				<link name="link5">
					<viaPoint type="FIXPOINT">0.06999999999999994 -0.06 0.01899999999999949</viaPoint>
				</link>
			</myoMuscle>
			<myoMuscle name="motor16">
				<link name="base">
					<viaPoint type="FIXPOINT">-0.34323811686932443 -0.3432381168693244 0.03</viaPoint>
				</link>
				<link name="link5">
					<viaPoint type="FIXPOINT">-0.08000000000000007 -0.06 0.01899999999999949</viaPoint>
				</link>
			</myoMuscle>
			<myoMuscle name="motor17">
				<link name="base">
					<viaPoint type="FIXPOINT">-0.49 0.0 0.03</viaPoint>
				</link>
				<link name="link5">
					<viaPoint type="FIXPOINT">-0.06 0.07500000000000025 0.03899999999999935</viaPoint>
				</link>
			</myoMuscle>
			<myoMuscle name="motor18">
				<link name="base">
					<viaPoint type="FIXPOINT">-0.3432381168693243 0.34323811686932454 0.03</viaPoint>
				</link>
				<link name="link5">
					<viaPoint type="FIXPOINT">-0.08000000000000007 0.03 -0.041000000000000515</viaPoint>
				</link>
			</myoMuscle>
			<myoMuscle name="motor19">
				<link name="base">
					<viaPoint type="FIXPOINT">9.001153973733046e-17 0.49 0.03</viaPoint>
				</link>
				<link name="link5">
					<viaPoint type="FIXPOINT">0.02 0.07500000000000019 -0.05100000000000059</viaPoint>
				</link>
			</myoMuscle>
			<myoMuscle name="motor13">
				<link name="base">
					<viaPoint type="FIXPOINT">0.49 -6.000769315822031e-17 0.03</viaPoint>
				</link>
				<link name="link5">
					<viaPoint type="FIXPOINT">-0.005000000000000067 1.9729034764111939e-16 -0.07499999999999993</viaPoint>
				</link>
			</myoMuscle>
			<myoMuscle name="motor15">
				<link name="base">
					<viaPoint type="FIXPOINT">-3.0003846579110155e-17 -0.49 0.03</viaPoint>
				</link>
				<link name="link5">
					<viaPoint type="FIXPOINT">-0.06 -0.07499999999999973 0.038999999999999486</viaPoint>
				</link>
			</myoMuscle>
			<endEffector link="link5" name="endeffector0">0.0 0.0 0.0</endEffector>
		</plugin>
	</model>
</sdf>
