<?xml version="1.0" ?>
<robot name="TestRobot">
  <joint name="joint0" type="prismatic">
    <parent link="base"/>
    <child link="link0"/>
    <origin rpy="0  0  0" xyz="0    0    0.01"/>
    <axis xyz="1  0  0"/>
    <limit effort="0.0" lower="-0.25" upper="0.25" velocity="0.0"/>
  </joint>
  <joint name="joint1" type="prismatic">
    <parent link="link0"/>
    <child link="link1"/>
    <origin rpy="0  0  0" xyz="0    0    0.01"/>
    <axis xyz="0 -1  0"/>
    <limit effort="0.0" lower="-0.25" upper="0.25" velocity="0.0"/>
  </joint>
  <joint name="joint2" type="prismatic">
    <parent link="link1"/>
    <child link="link2"/>
    <origin rpy="0  0  0" xyz="0  0  0"/>
    <axis xyz="0  0  1"/>
    <limit effort="0.0" lower="0.0" upper="0.5" velocity="0.0"/>
  </joint>
  <joint name="sphere_axis0" type="revolute">
    <parent link="link2"/>
    <child link="link3"/>
    <origin rpy="0  0  0" xyz="-0.005  0     0.528"/>
    <axis xyz="1  0  0"/>
    <limit effort="0.0" lower="-3.14159265359" upper="3.14159265359" velocity="0.0"/>
  </joint>
  <joint name="sphere_axis1" type="revolute">
    <parent link="link3"/>
    <child link="link4"/>
    <origin rpy="0  0  0" xyz="0  0  0"/>
    <axis xyz="0 -1  0"/>
    <limit effort="0.0" lower="-3.14159265359" upper="3.14159265359" velocity="0.0"/>
  </joint>
  <joint name="sphere_axis2" type="revolute">
    <parent link="link4"/>
    <child link="link5"/>
    <origin rpy="0  0  0" xyz="0  0  0"/>
    <axis xyz="0  0  1"/>
    <limit effort="0.0" lower="-3.14159265359" upper="3.14159265359" velocity="0.0"/>
  </joint>
  <link name="base">
    <inertial>
      <mass value="10000"/>
      <origin rpy="0  0  0" xyz="0  0  0"/>
      <inertia ixx="0.1" ixy="0.0" ixz="0.0" iyy="0.1" iyz="0.0" izz="0.1"/>
    </inertial>
    <collision name="base_collision">
      <origin rpy="0  0  0" xyz="0  0  0"/>
      <geometry>
        <mesh filename="package://roboy_models/TestRobot/meshes/CAD/base.stl" scale="0.001 0.001 0.001"/>
      </geometry>
    </collision>
    <visual name="base_visual">
      <origin rpy="0  0  0" xyz="0  0  0"/>
      <geometry>
        <mesh filename="package://roboy_models/TestRobot/meshes/CAD/base.stl" scale="0.001 0.001 0.001"/>
      </geometry>
    </visual>
  </link>
  <link name="link0">
    <inertial>
      <mass value="0.1"/>
      <origin rpy="0  0  0" xyz="0    0    0.01"/>
      <inertia ixx="0.1" ixy="0.0" ixz="0.0" iyy="0.1" iyz="0.0" izz="0.1"/>
    </inertial>
    <collision name="link0_collision">
      <origin rpy="0  0  0" xyz="0    0    0.01"/>
      <geometry>
        <mesh filename="package://roboy_models/TestRobot/meshes/CAD/link0.stl" scale="0.001 0.001 0.001"/>
      </geometry>
    </collision>
    <visual name="link0_visual">
      <origin rpy="0  0  0" xyz="0    0    0.01"/>
      <geometry>
        <mesh filename="package://roboy_models/TestRobot/meshes/CAD/link0.stl" scale="0.001 0.001 0.001"/>
      </geometry>
    </visual>
  </link>
  <link name="link1">
    <inertial>
      <mass value="0.1"/>
      <origin rpy="0  0  0" xyz="0  0  0"/>
      <inertia ixx="0.1" ixy="0.0" ixz="0.0" iyy="0.1" iyz="0.0" izz="0.1"/>
    </inertial>
    <collision name="link1_collision">
      <origin rpy="0  0  0" xyz="0  0  0"/>
      <geometry>
        <mesh filename="package://roboy_models/TestRobot/meshes/CAD/link1.stl" scale="0.001 0.001 0.001"/>
      </geometry>
    </collision>
    <visual name="link1_visual">
      <origin rpy="0  0  0" xyz="0  0  0"/>
      <geometry>
        <mesh filename="package://roboy_models/TestRobot/meshes/CAD/link1.stl" scale="0.001 0.001 0.001"/>
      </geometry>
    </visual>
  </link>
  <link name="link2">
    <inertial>
      <mass value="0.1"/>
      <origin rpy="0  0  0" xyz="0    0    0.25"/>
      <inertia ixx="0.1" ixy="0.0" ixz="0.0" iyy="0.1" iyz="0.0" izz="0.1"/>
    </inertial>
    <collision name="link2_collision">
      <origin rpy="0  0  0" xyz="0    0    0.25"/>
      <geometry>
        <mesh filename="package://roboy_models/TestRobot/meshes/CAD/link2.stl" scale="0.001 0.001 0.001"/>
      </geometry>
    </collision>
    <visual name="link2_visual">
      <origin rpy="0  0  0" xyz="0    0    0.25"/>
      <geometry>
        <mesh filename="package://roboy_models/TestRobot/meshes/CAD/link2.stl" scale="0.001 0.001 0.001"/>
      </geometry>
    </visual>
  </link>
  <link name="link3">
    <inertial>
      <mass value="0.1"/>
      <origin rpy="0  0  0" xyz="0  0  0"/>
      <inertia ixx="0.1" ixy="0.0" ixz="0.0" iyy="0.1" iyz="0.0" izz="0.1"/>
    </inertial>
    <collision name="link3_collision">
      <origin rpy="0  0  0" xyz="0  0  0"/>
      <geometry>
        <mesh filename="package://roboy_models/TestRobot/meshes/CAD/link3.stl" scale="0.001 0.001 0.001"/>
      </geometry>
    </collision>
    <visual name="link3_visual">
      <origin rpy="0  0  0" xyz="0  0  0"/>
      <geometry>
        <mesh filename="package://roboy_models/TestRobot/meshes/CAD/link3.stl" scale="0.001 0.001 0.001"/>
      </geometry>
    </visual>
  </link>
  <link name="link4">
    <inertial>
      <mass value="0.1"/>
      <origin rpy="0  0  0" xyz="0  0  0"/>
      <inertia ixx="0.1" ixy="0.0" ixz="0.0" iyy="0.1" iyz="0.0" izz="0.1"/>
    </inertial>
    <collision name="link4_collision">
      <origin rpy="0  0  0" xyz="0  0  0"/>
      <geometry>
        <mesh filename="package://roboy_models/TestRobot/meshes/CAD/link4.stl" scale="0.001 0.001 0.001"/>
      </geometry>
    </collision>
    <visual name="link4_visual">
      <origin rpy="0  0  0" xyz="0  0  0"/>
      <geometry>
        <mesh filename="package://roboy_models/TestRobot/meshes/CAD/link4.stl" scale="0.001 0.001 0.001"/>
      </geometry>
    </visual>
  </link>
  <link name="link5">
    <inertial>
      <mass value="0.1"/>
      <origin rpy="0  0  0" xyz="0.005  0     0.093"/>
      <inertia ixx="0.1" ixy="0.0" ixz="0.0" iyy="0.1" iyz="0.0" izz="0.1"/>
    </inertial>
    <collision name="link5_collision">
      <origin rpy="0  0  0" xyz="0.005  0     0.093"/>
      <geometry>
        <mesh filename="package://roboy_models/TestRobot/meshes/CAD/link5.stl" scale="0.001 0.001 0.001"/>
      </geometry>
    </collision>
    <visual name="link5_visual">
      <origin rpy="0  0  0" xyz="0.005  0     0.093"/>
      <geometry>
        <mesh filename="package://roboy_models/TestRobot/meshes/CAD/link5.stl" scale="0.001 0.001 0.001"/>
      </geometry>
    </visual>
  </link>
</robot>
