<?xml version="1.0" ?>
<sdf version="1.6">
	<model name="roboy_2_0_simplified">
		<link name="lower_arm_right">
			<pose frame="">-0.29218836999465536 0.2743736679995431 0.06363338040081598 0.0 -0.0 0.0</pose>
			<inertial>
				<pose frame="">0.0 0.0 0.0 0 0 0</pose>
				<mass>10.580368393671788</mass>
				<inertia>
					<ixx>1.1942606746969533</ixx>
					<ixy>0.8221036576164763</ixy>
					<ixz>-0.5191382565906925</ixz>
					<iyy>1.2172536464994175</iyy>
					<iyz>0.5208554455521323</iyz>
					<izz>1.6548179592789556</izz>
				</inertia>
			</inertial>
			<collision name="lower_arm_right_collision">
				<geometry>
					<mesh>
						<uri>model://roboy_2_0_simplified/meshes/CAD/lower_arm_right.stl</uri>
						<scale>0.001 0.001 0.001</scale>
					</mesh>
				</geometry>
			</collision>
			<visual name="lower_arm_right_visual">
				<geometry>
					<mesh>
						<uri>model://roboy_2_0_simplified/meshes/CAD/lower_arm_right.stl</uri>
						<scale>0.001 0.001 0.001</scale>
					</mesh>
				</geometry>
			</visual>
		</link>
		<link name="lower_arm_left">
			<pose frame="">0.2941390263982024 0.26622759368394755 0.026799075858034458 0.0 -0.0 0.0</pose>
			<inertial>
				<pose frame="">0.0 0.0 0.0 0 0 0</pose>
				<mass>10.990737035515798</mass>
				<inertia>
					<ixx>1.0265234577863331</ixx>
					<ixy>-0.8603149692392615</ixy>
					<ixz>-0.3848488986765689</ixz>
					<iyy>1.2028540095957048</iyy>
					<iyz>-0.42562772271899824</iyz>
					<izz>1.739562008764482</izz>
				</inertia>
			</inertial>
			<collision name="lower_arm_left_collision">
				<geometry>
					<mesh>
						<uri>model://roboy_2_0_simplified/meshes/CAD/lower_arm_left.stl</uri>
						<scale>0.001 0.001 0.001</scale>
					</mesh>
				</geometry>
			</collision>
			<visual name="lower_arm_left_visual">
				<geometry>
					<mesh>
						<uri>model://roboy_2_0_simplified/meshes/CAD/lower_arm_left.stl</uri>
						<scale>0.001 0.001 0.001</scale>
					</mesh>
				</geometry>
			</visual>
		</link>
		<link name="head">
			<pose frame="">-0.0030666329436431824 0.8266497028349796 0.006506358437061879 0.0 -0.0 0.0</pose>
			<inertial>
				<pose frame="">0.0 0.0 0.0 0 0 0</pose>
				<mass>2.1986973590671126</mass>
				<inertia>
					<ixx>1.9457059620138442</ixx>
					<ixy>0.004896672663233137</ixy>
					<ixz>0.020134037757220936</ixz>
					<iyy>0.025068367005670035</iyy>
					<iyz>-4.3476390295491864e-05</iyz>
					<izz>1.9405524949958946</izz>
				</inertia>
			</inertial>
			<collision name="head_collision">
				<geometry>
					<mesh>
						<uri>model://roboy_2_0_simplified/meshes/CAD/head.stl</uri>
						<scale>0.001 0.001 0.001</scale>
					</mesh>
				</geometry>
			</collision>
			<visual name="head_visual">
				<geometry>
					<mesh>
						<uri>model://roboy_2_0_simplified/meshes/CAD/head.stl</uri>
						<scale>0.001 0.001 0.001</scale>
					</mesh>
				</geometry>
			</visual>
		</link>
		<link name="upper_arm_left">
			<pose frame="">0.28798862680022014 0.5549254668876651 -0.013618040340742264 0.0 -0.0 0.0</pose>
			<inertial>
				<pose frame="">0.0 0.0 0.0 0 0 0</pose>
				<mass>15.849973523723046</mass>
				<inertia>
					<ixx>2.7932409541157535</ixx>
					<ixy>-1.995166219783696</ixy>
					<ixz>0.09367699027050215</ixz>
					<iyy>1.5136243481328202</iyy>
					<iyz>0.06860843725394736</iyz>
					<izz>4.246400000481182</izz>
				</inertia>
			</inertial>
			<collision name="upper_arm_left_collision">
				<geometry>
					<mesh>
						<uri>model://roboy_2_0_simplified/meshes/CAD/upper_arm_left.stl</uri>
						<scale>0.001 0.001 0.001</scale>
					</mesh>
				</geometry>
			</collision>
			<visual name="upper_arm_left_visual">
				<geometry>
					<mesh>
						<uri>model://roboy_2_0_simplified/meshes/CAD/upper_arm_left.stl</uri>
						<scale>0.001 0.001 0.001</scale>
					</mesh>
				</geometry>
			</visual>
		</link>
		<link name="upper_arm_right">
			<pose frame="">-0.29468160568595847 0.5621903189085681 0.01717623203608873 0.0 -0.0 0.0</pose>
			<inertial>
				<pose frame="">0.0 0.0 0.0 0 0 0</pose>
				<mass>14.646816943255674</mass>
				<inertia>
					<ixx>2.758742397954076</ixx>
					<ixy>1.903814448481625</ixy>
					<ixz>-0.1285930731181642</ixz>
					<iyy>1.394227292562067</iyy>
					<iyz>0.0910295579961473</iyz>
					<izz>4.087354909917636</izz>
				</inertia>
			</inertial>
			<collision name="upper_arm_right_collision">
				<geometry>
					<mesh>
						<uri>model://roboy_2_0_simplified/meshes/CAD/upper_arm_right.stl</uri>
						<scale>0.001 0.001 0.001</scale>
					</mesh>
				</geometry>
			</collision>
			<visual name="upper_arm_right_visual">
				<geometry>
					<mesh>
						<uri>model://roboy_2_0_simplified/meshes/CAD/upper_arm_right.stl</uri>
						<scale>0.001 0.001 0.001</scale>
					</mesh>
				</geometry>
			</visual>
		</link>
		<link name="torso">
			<pose frame="">-0.00500000000000026 0.33649999999999985 -0.024674885790744155 0.0 -0.0 0.0</pose>
			<inertial>
				<pose frame="">0.0 0.0 0.0 0 0 0</pose>
				<mass>416.8399576060895</mass>
				<inertia>
					<ixx>86.71859445892643</ixx>
					<ixy>0.11826198619378973</ixy>
					<ixz>0.027033592317535597</ixz>
					<iyy>154.90152088340318</iyy>
					<iyz>-0.0037223325904632235</iyz>
					<izz>87.06794584342471</izz>
				</inertia>
			</inertial>
			<collision name="torso_collision">
				<geometry>
					<mesh>
						<uri>model://roboy_2_0_simplified/meshes/CAD/torso.stl</uri>
						<scale>0.001 0.001 0.001</scale>
					</mesh>
				</geometry>
			</collision>
			<visual name="torso_visual">
				<geometry>
					<mesh>
						<uri>model://roboy_2_0_simplified/meshes/CAD/torso.stl</uri>
						<scale>0.001 0.001 0.001</scale>
					</mesh>
				</geometry>
			</visual>
		</link>
		<link name="shoulder_left_joint_link_2">
			<pose frame="">0.28713512179275735 0.5894179501767453 -0.013607855949266324 0.0 -0.0 0.0</pose>
			<inertial>
				<pose frame="">0.0 0.0 0.0 0 0 0</pose>
				<mass>0.011947756900622582</mass>
				<inertia>
					<ixx>0.004224609684716974</ixx>
					<ixy>-0.002035696946929007</ixy>
					<ixz>9.649574578557582e-05</ixz>
					<iyy>0.0009845367692220975</iyy>
					<iyz>4.6514921924002426e-05</iyz>
					<izz>0.005203730711513295</izz>
				</inertia>
			</inertial>
			<collision name="shoulder_left_joint_link_2_collision">
				<geometry>
					<mesh>
						<uri>model://roboy_2_0_simplified/meshes/CAD/shoulder_left_joint_link_2.stl</uri>
						<scale>0.001 0.001 0.001</scale>
					</mesh>
				</geometry>
			</collision>
			<visual name="shoulder_left_joint_link_2_visual">
				<geometry>
					<mesh>
						<uri>model://roboy_2_0_simplified/meshes/CAD/shoulder_left_joint_link_2.stl</uri>
						<scale>0.001 0.001 0.001</scale>
					</mesh>
				</geometry>
			</visual>
		</link>
		<link name="shoulder_left_joint_link_3">
			<pose frame="">0.28713512179275713 0.5894179501767447 -0.013607855949266296 0.0 -0.0 0.0</pose>
			<inertial>
				<pose frame="">0.0 0.0 0.0 0 0 0</pose>
				<mass>0.017192390951684323</mass>
				<inertia>
					<ixx>0.006042503381130933</ixx>
					<ixy>-0.0029241492153348533</ixy>
					<ixz>0.0001386064926500754</ixz>
					<iyy>0.0014197255030573394</iyy>
					<iyz>6.711807543954238e-05</iyz>
					<izz>0.007455297773422211</izz>
				</inertia>
			</inertial>
			<collision name="shoulder_left_joint_link_3_collision">
				<geometry>
					<mesh>
						<uri>model://roboy_2_0_simplified/meshes/CAD/shoulder_left_joint_link_3.stl</uri>
						<scale>0.001 0.001 0.001</scale>
					</mesh>
				</geometry>
			</collision>
			<visual name="shoulder_left_joint_link_3_visual">
				<geometry>
					<mesh>
						<uri>model://roboy_2_0_simplified/meshes/CAD/shoulder_left_joint_link_3.stl</uri>
						<scale>0.001 0.001 0.001</scale>
					</mesh>
				</geometry>
			</visual>
		</link>
		<link name="shoulder_right_joint_link_2">
			<pose frame="">-0.29602805125144716 0.5966598819209421 0.016471754895170877 0.0 -0.0 0.0</pose>
			<inertial>
				<pose frame="">0.0 0.0 0.0 0 0 0</pose>
				<mass>0.011947830827153387</mass>
				<inertia>
					<ixx>0.004329658029906799</ixx>
					<ixy>0.0021233011332852498</ixy>
					<ixz>-0.00011735981113008232</ixz>
					<iyy>0.0010461058421985915</iyy>
					<iyz>5.75905590039471e-05</iyz>
					<izz>0.005368391249426432</izz>
				</inertia>
			</inertial>
			<collision name="shoulder_right_joint_link_2_collision">
				<geometry>
					<mesh>
						<uri>model://roboy_2_0_simplified/meshes/CAD/shoulder_right_joint_link_2.stl</uri>
						<scale>0.001 0.001 0.001</scale>
					</mesh>
				</geometry>
			</collision>
			<visual name="shoulder_right_joint_link_2_visual">
				<geometry>
					<mesh>
						<uri>model://roboy_2_0_simplified/meshes/CAD/shoulder_right_joint_link_2.stl</uri>
						<scale>0.001 0.001 0.001</scale>
					</mesh>
				</geometry>
			</visual>
		</link>
		<link name="shoulder_right_joint_link_3">
			<pose frame="">-0.29602805125144693 0.596659881920942 0.016471754895171276 0.0 -0.0 0.0</pose>
			<inertial>
				<pose frame="">0.0 0.0 0.0 0 0 0</pose>
				<mass>0.01719247645061585</mass>
				<inertia>
					<ixx>0.006192503458318139</ixx>
					<ixy>0.003053759792012067</ixy>
					<ixz>-0.00016916773565252947</ixz>
					<iyy>0.0015123923096183505</iyy>
					<iyz>8.349437351838351e-05</iyz>
					<izz>0.007695076772928893</izz>
				</inertia>
			</inertial>
			<collision name="shoulder_right_joint_link_3_collision">
				<geometry>
					<mesh>
						<uri>model://roboy_2_0_simplified/meshes/CAD/shoulder_right_joint_link_3.stl</uri>
						<scale>0.001 0.001 0.001</scale>
					</mesh>
				</geometry>
			</collision>
			<visual name="shoulder_right_joint_link_3_visual">
				<geometry>
					<mesh>
						<uri>model://roboy_2_0_simplified/meshes/CAD/shoulder_right_joint_link_3.stl</uri>
						<scale>0.001 0.001 0.001</scale>
					</mesh>
				</geometry>
			</visual>
		</link>
		<link name="neck_link_3">
			<pose frame="">-0.005000000000001102 0.7769579775594229 -0.0056718428256846655 0.0 -0.0 0.0</pose>
			<inertial>
				<pose frame="">0.0 0.0 0.0 0 0 0</pose>
				<mass>0.017192417326343308</mass>
				<inertia>
					<ixx>0.010466481866131366</ixx>
					<ixy>6.613662178595022e-05</ixy>
					<ixz>7.607999592631032e-05</ixz>
					<iyy>1.532435475756013e-06</iyy>
					<iyz>-4.808145207667013e-07</iyz>
					<izz>0.010466339897771931</izz>
				</inertia>
			</inertial>
			<collision name="neck_link_3_collision">
				<geometry>
					<mesh>
						<uri>model://roboy_2_0_simplified/meshes/CAD/neck_link_3.stl</uri>
						<scale>0.001 0.001 0.001</scale>
					</mesh>
				</geometry>
			</collision>
			<visual name="neck_link_3_visual">
				<geometry>
					<mesh>
						<uri>model://roboy_2_0_simplified/meshes/CAD/neck_link_3.stl</uri>
						<scale>0.001 0.001 0.001</scale>
					</mesh>
				</geometry>
			</visual>
		</link>
		<link name="neck_link_2">
			<pose frame="">-0.005000000000001102 0.7769579775594229 -0.0056718428256846655 0.0 -0.0 0.0</pose>
			<inertial>
				<pose frame="">0.0 0.0 0.0 0 0 0</pose>
				<mass>0.011947622039161103</mass>
				<inertia>
					<ixx>0.007306934101953238</ixx>
					<ixy>3.731904905578473e-05</ixy>
					<ixz>5.298587603583046e-05</ixz>
					<iyy>1.2142544508732938e-06</iyy>
					<iyz>-2.70689047753505e-07</iyz>
					<izz>0.007306371462477739</izz>
				</inertia>
			</inertial>
			<collision name="neck_link_2_collision">
				<geometry>
					<mesh>
						<uri>model://roboy_2_0_simplified/meshes/CAD/neck_link_2.stl</uri>
						<scale>0.001 0.001 0.001</scale>
					</mesh>
				</geometry>
			</collision>
			<visual name="neck_link_2_visual">
				<geometry>
					<mesh>
						<uri>model://roboy_2_0_simplified/meshes/CAD/neck_link_2.stl</uri>
						<scale>0.001 0.001 0.001</scale>
					</mesh>
				</geometry>
			</visual>
		</link>
		<link name="hand_right">
			<pose frame="">-0.2520222680642473 0.5248675719297508 0.45128232319496375 0.0 -0.0 0.0</pose>
			<inertial>
				<pose frame="">0.0 0.0 0.0 0 0 0</pose>
				<mass>1.196586940756497</mass>
				<inertia>
					<ixx>0.5108879426503155</ixx>
					<ixy>0.14351362666646336</ixy>
					<ixz>-0.25135959862085727</ixz>
					<iyy>0.3094433395199244</iyy>
					<iyz>0.133408167066518</iyz>
					<izz>0.35649911145736324</izz>
				</inertia>
			</inertial>
			<collision name="hand_right_collision">
				<geometry>
					<mesh>
						<uri>model://roboy_2_0_simplified/meshes/CAD/hand_right.stl</uri>
						<scale>0.001 0.001 0.001</scale>
					</mesh>
				</geometry>
			</collision>
			<visual name="hand_right_visual">
				<geometry>
					<mesh>
						<uri>model://roboy_2_0_simplified/meshes/CAD/hand_right.stl</uri>
						<scale>0.001 0.001 0.001</scale>
					</mesh>
				</geometry>
			</visual>
		</link>
		<link name="hand_left">
			<pose frame="">0.287078998659723 0.5078150620301657 0.417830876996003 0.0 -0.0 0.0</pose>
			<inertial>
				<pose frame="">0.0 0.0 0.0 0 0 0</pose>
				<mass>1.1922293050222907</mass>
				<inertia>
					<ixx>0.45620362910831175</ixx>
					<ixy>-0.15704822159463427</ixy>
					<ixz>-0.22334336993028503</ixz>
					<iyy>0.2960609239847064</iyy>
					<iyz>-0.1391778507387225</iyz>
					<izz>0.35942938977198674</izz>
				</inertia>
			</inertial>
			<collision name="hand_left_collision">
				<geometry>
					<mesh>
						<uri>model://roboy_2_0_simplified/meshes/CAD/hand_left.stl</uri>
						<scale>0.001 0.001 0.001</scale>
					</mesh>
				</geometry>
			</collision>
			<visual name="hand_left_visual">
				<geometry>
					<mesh>
						<uri>model://roboy_2_0_simplified/meshes/CAD/hand_left.stl</uri>
						<scale>0.001 0.001 0.001</scale>
					</mesh>
				</geometry>
			</visual>
		</link>
		<link name="key_F">
			<pose frame="">-0.06499999999999939 0.2815000000000004 0.5143251142092558 0.0 -0.0 0.0</pose>
			<inertial>
				<pose frame="">0.0 0.0 0.0 0 0 0</pose>
				<mass>0.8242499999999997</mass>
				<inertia>
					<ixx>0.229782676203744</ixx>
					<ixy>0.009308529999999616</ixy>
					<ixz>-0.10340034138425735</ixz>
					<iyy>0.16556419101624362</iyy>
					<iyz>0.014649399015478546</iyz>
					<izz>0.06719952268750011</izz>
				</inertia>
			</inertial>
			<collision name="key_F_collision">
				<geometry>
					<mesh>
						<uri>model://roboy_2_0_simplified/meshes/CAD/key_F.stl</uri>
						<scale>0.001 0.001 0.001</scale>
					</mesh>
				</geometry>
			</collision>
			<visual name="key_F_visual">
				<geometry>
					<mesh>
						<uri>model://roboy_2_0_simplified/meshes/CAD/key_F.stl</uri>
						<scale>0.001 0.001 0.001</scale>
					</mesh>
				</geometry>
			</visual>
		</link>
		<link name="key_G">
			<pose frame="">-0.1349999999999994 0.2815000000000004 0.5043251142092557 0.0 -0.0 0.0</pose>
			<inertial>
				<pose frame="">0.0 0.0 0.0 0 0 0</pose>
				<mass>0.706499999999999</mass>
				<inertia>
					<ixx>0.1966504296032091</ixx>
					<ixy>0.02194153499999971</ixy>
					<ixz>-0.08862886404364916</ixz>
					<iyy>0.1490242637282087</iyy>
					<iyz>0.03453072625077184</iyz>
					<izz>0.06501784087499991</izz>
				</inertia>
			</inertial>
			<collision name="key_G_collision">
				<geometry>
					<mesh>
						<uri>model://roboy_2_0_simplified/meshes/CAD/key_G.stl</uri>
						<scale>0.001 0.001 0.001</scale>
					</mesh>
				</geometry>
			</collision>
			<visual name="key_G_visual">
				<geometry>
					<mesh>
						<uri>model://roboy_2_0_simplified/meshes/CAD/key_G.stl</uri>
						<scale>0.001 0.001 0.001</scale>
					</mesh>
				</geometry>
			</visual>
		</link>
		<link name="key_C">
			<pose frame="">0.1450000000000006 0.2815000000000004 0.5443251142092558 0.0 -0.0 0.0</pose>
			<inertial>
				<pose frame="">0.0 0.0 0.0 0 0 0</pose>
				<mass>1.177499999999998</mass>
				<inertia>
					<ixx>0.3302627160053484</ixx>
					<ixy>-0.05651607500000076</ixy>
					<ixz>-0.1477147734060819</ixz>
					<iyy>0.2706677728803488</iyy>
					<iyz>-0.08894277973683888</iyz>
					<izz>0.12814506812500112</izz>
				</inertia>
			</inertial>
			<collision name="key_C_collision">
				<geometry>
					<mesh>
						<uri>model://roboy_2_0_simplified/meshes/CAD/key_C.stl</uri>
						<scale>0.001 0.001 0.001</scale>
					</mesh>
				</geometry>
			</collision>
			<visual name="key_C_visual">
				<geometry>
					<mesh>
						<uri>model://roboy_2_0_simplified/meshes/CAD/key_C.stl</uri>
						<scale>0.001 0.001 0.001</scale>
					</mesh>
				</geometry>
			</visual>
		</link>
		<link name="key_H">
			<pose frame="">-0.2049999999999994 0.2815000000000004 0.4943251142092558 0.0 -0.0 0.0</pose>
			<inertial>
				<pose frame="">0.0 0.0 0.0 0 0 0</pose>
				<mass>0.5887499999999979</mass>
				<inertia>
					<ixx>0.16365948300267433</ixx>
					<ixy>0.029920274999999795</ixy>
					<ixz>-0.07385738670304097</ixz>
					<iyy>0.13592263644017383</iyy>
					<iyz>0.047087353978325544</iyz>
					<izz>0.06613315906249982</izz>
				</inertia>
			</inertial>
			<collision name="key_H_collision">
				<geometry>
					<mesh>
						<uri>model://roboy_2_0_simplified/meshes/CAD/key_H.stl</uri>
						<scale>0.001 0.001 0.001</scale>
					</mesh>
				</geometry>
			</collision>
			<visual name="key_H_visual">
				<geometry>
					<mesh>
						<uri>model://roboy_2_0_simplified/meshes/CAD/key_H.stl</uri>
						<scale>0.001 0.001 0.001</scale>
					</mesh>
				</geometry>
			</visual>
		</link>
		<link name="key_E">
			<pose frame="">0.005000000000000604 0.2815000000000004 0.5243251142092558 0.0 -0.0 0.0</pose>
			<inertial>
				<pose frame="">0.0 0.0 0.0 0 0 0</pose>
				<mass>0.9420000000000001</mass>
				<inertia>
					<ixx>0.2630797728042788</ixx>
					<ixy>-0.007978740000000494</ixy>
					<ixz>-0.11817181872486557</ixz>
					<iyy>0.18902781830427867</iyy>
					<iyz>-0.01255662772755434</iyz>
					<izz>0.07614005450000037</izz>
				</inertia>
			</inertial>
			<collision name="key_E_collision">
				<geometry>
					<mesh>
						<uri>model://roboy_2_0_simplified/meshes/CAD/key_E.stl</uri>
						<scale>0.001 0.001 0.001</scale>
					</mesh>
				</geometry>
			</collision>
			<visual name="key_E_visual">
				<geometry>
					<mesh>
						<uri>model://roboy_2_0_simplified/meshes/CAD/key_E.stl</uri>
						<scale>0.001 0.001 0.001</scale>
					</mesh>
				</geometry>
			</visual>
		</link>
		<link name="key_D">
			<pose frame="">0.07500000000000061 0.2815000000000004 0.5343251142092558 0.0 -0.0 0.0</pose>
			<inertial>
				<pose frame="">0.0 0.0 0.0 0 0 0</pose>
				<mass>1.0597499999999997</mass>
				<inertia>
					<ixx>0.2965652694048136</ixx>
					<ixy>-0.02992027500000062</ixy>
					<ixz>-0.13294329606547373</ixz>
					<iyy>0.22290054559231373</iyy>
					<iyz>-0.047087353978326814</iyz>
					<izz>0.0953012863125007</izz>
				</inertia>
			</inertial>
			<collision name="key_D_collision">
				<geometry>
					<mesh>
						<uri>model://roboy_2_0_simplified/meshes/CAD/key_D.stl</uri>
						<scale>0.001 0.001 0.001</scale>
					</mesh>
				</geometry>
			</collision>
			<visual name="key_D_visual">
				<geometry>
					<mesh>
						<uri>model://roboy_2_0_simplified/meshes/CAD/key_D.stl</uri>
						<scale>0.001 0.001 0.001</scale>
					</mesh>
				</geometry>
			</visual>
		</link>
		<joint name="shoulder_left_axis_1" type="revolute">
			<parent>torso</parent>
			<child>shoulder_left_joint_link_2</child>
			<pose frame="">0.00019951945882407785 0.00490743658684032 -0.0047233517011995565 0 0 0</pose>
			<axis>
				<xyz>0.051010494316667994 0.02231024242210457 0.9984488883025681</xyz>
				<limit>
					<lower>-3.141592653589793</lower>
					<upper>3.141592653589793</upper>
				</limit>
				<use_parent_model_frame>0</use_parent_model_frame>
			</axis>
		</joint>
		<joint name="shoulder_left_axis_2" type="revolute">
			<parent>shoulder_left_joint_link_2</parent>
			<child>shoulder_left_joint_link_3</child>
			<pose frame="">0.005431255365339957 0.00513551882804812 -0.0002853869619396554 0 0 0</pose>
			<axis>
				<xyz>-0.9983662720150784 -0.02463124250686317 0.051556656168533395</xyz>
				<limit>
					<lower>-3.141592653589793</lower>
					<upper>3.141592653589793</upper>
				</limit>
				<use_parent_model_frame>0</use_parent_model_frame>
			</axis>
		</joint>
		<joint name="neck_axis_2" type="revolute">
			<parent>neck_link_3</parent>
			<child>neck_link_2</child>
			<pose frame="">-0.008063589978581573 0.005003042965059308 2.2204460492503132e-17 0 0 0</pose>
			<axis>
				<xyz>-1.0 -3.432848736779223e-15 6.123233995736762e-17</xyz>
				<limit>
					<lower>-0.5235987755982988</lower>
					<upper>0.5235987755982988</upper>
				</limit>
				<use_parent_model_frame>0</use_parent_model_frame>
			</axis>
		</joint>
		<joint name="neck_axis_3" type="revolute">
			<parent>neck_link_2</parent>
			<child>head</child>
			<pose frame="">3.0429650605307003e-06 -0.047353730897741995 -0.0022321045305084674 0 0 0</pose>
			<axis>
				<xyz>1.4220056966830026e-15 -0.2588190451025207 0.9659258262890682</xyz>
				<limit>
					<lower>-3.141592653589793</lower>
					<upper>3.141592653589793</upper>
				</limit>
				<use_parent_model_frame>0</use_parent_model_frame>
			</axis>
		</joint>
		<joint name="wrist_right" type="revolute">
			<parent>lower_arm_right</parent>
			<child>hand_right</child>
			<pose frame="">-0.0167897577310249 -0.2453824657614056 -0.15889706907128967 0 0 0</pose>
			<axis>
				<xyz>0.10163627912775278 0.022223644212182994 0.9945733640124266</xyz>
				<limit>
					<lower>-1.5707963267948966</lower>
					<upper>1.5707963267948966</upper>
				</limit>
				<use_parent_model_frame>0</use_parent_model_frame>
			</axis>
		</joint>
		<joint name="wrist_left" type="revolute">
			<parent>lower_arm_left</parent>
			<child>hand_left</child>
			<pose frame="">0.007242263387563313 -0.24164862319449779 -0.16521568193271033 0 0 0</pose>
			<axis>
				<xyz>-0.02384168391198873 -0.000607586479966071 0.9997155620209742</xyz>
				<limit>
					<lower>-1.5707963267948966</lower>
					<upper>1.5707963267948966</upper>
				</limit>
				<use_parent_model_frame>0</use_parent_model_frame>
			</axis>
		</joint>
		<joint name="shoulder_right_axis_1" type="revolute">
			<parent>torso</parent>
			<child>shoulder_right_joint_link_2</child>
			<pose frame="">-5.71962226064926e-06 0.005103328716584556 0.004850515846064427 0 0 0</pose>
			<axis>
				<xyz>-0.05101049431666773 -0.022310242422105237 -0.9984488883025684</xyz>
				<limit>
					<lower>-3.141592653589793</lower>
					<upper>3.141592653589793</upper>
				</limit>
				<use_parent_model_frame>0</use_parent_model_frame>
			</axis>
		</joint>
		<joint name="shoulder_right_axis_2" type="revolute">
			<parent>shoulder_right_joint_link_2</parent>
			<child>shoulder_right_joint_link_3</child>
			<pose frame="">-0.0052482339115812945 0.004803137171476877 0.00016080527838489457 0 0 0</pose>
			<axis>
				<xyz>0.997935574407065 0.03792191184355857 -0.0518316306416172</xyz>
				<limit>
					<lower>-3.141592653589793</lower>
					<upper>3.141592653589793</upper>
				</limit>
				<use_parent_model_frame>0</use_parent_model_frame>
			</axis>
		</joint>
		<joint name="key_H" type="fixed">
			<parent>torso</parent>
			<child>key_H</child>
			<pose frame="">0.20000000000000076 -0.23500000000000035 -0.49999999999999994 0 0 0</pose>
		</joint>
		<joint name="key_G" type="fixed">
			<parent>torso</parent>
			<child>key_G</child>
			<pose frame="">0.13000000000000075 -0.23500000000000043 -0.5099999999999999 0 0 0</pose>
		</joint>
		<joint name="key_F" type="fixed">
			<parent>torso</parent>
			<child>key_F</child>
			<pose frame="">0.06000000000000074 -0.23500000000000035 -0.5199999999999999 0 0 0</pose>
		</joint>
		<joint name="key_E" type="fixed">
			<parent>torso</parent>
			<child>key_E</child>
			<pose frame="">-0.009999999999999261 -0.23500000000000035 -0.5299999999999999 0 0 0</pose>
		</joint>
		<joint name="key_D" type="fixed">
			<parent>torso</parent>
			<child>key_D</child>
			<pose frame="">-0.07999999999999927 -0.23500000000000035 -0.5399999999999999 0 0 0</pose>
		</joint>
		<joint name="key_C" type="fixed">
			<parent>torso</parent>
			<child>key_C</child>
			<pose frame="">-0.14999999999999925 -0.23500000000000035 -0.5499999999999998 0 0 0</pose>
		</joint>
		<joint name="elbow_right" type="revolute">
			<parent>upper_arm_right</parent>
			<child>lower_arm_right</child>
			<pose frame="">0.014000229666721467 0.004169619750468527 -0.037217810825038174 0 0 0</pose>
			<axis>
				<xyz>0.9948216256018391 -0.002270485932608902 -0.10161091540068079</xyz>
				<limit>
					<lower>-0.0</lower>
					<upper>1.5707963267948966</upper>
				</limit>
				<use_parent_model_frame>0</use_parent_model_frame>
			</axis>
		</joint>
		<joint name="elbow_left" type="revolute">
			<parent>upper_arm_left</parent>
			<child>lower_arm_left</child>
			<pose frame="">-0.016846814765604387 0.004596451889486168 -0.035485421788837894 0 0 0</pose>
			<axis>
				<xyz>0.9996958404329833 0.024649269359735267 -0.0008000881366474141</xyz>
				<limit>
					<lower>-0.0</lower>
					<upper>1.5707963267948966</upper>
				</limit>
				<use_parent_model_frame>0</use_parent_model_frame>
			</axis>
		</joint>
		<joint name="shoulder_left_axis_3" type="revolute">
			<parent>shoulder_left_joint_link_3</parent>
			<child>upper_arm_left</child>
			<pose frame="">-0.000653199659423791 0.026491947283847708 7.70160822393784e-06 0 0 0</pose>
			<axis>
				<xyz>0.024649043751837536 -0.9996961239187773 -0.00029062672542217393</xyz>
				<limit>
					<lower>-3.141592653589793</lower>
					<upper>3.141592653589793</upper>
				</limit>
				<use_parent_model_frame>0</use_parent_model_frame>
			</axis>
		</joint>
		<joint name="shoulder_right_axis_3" type="revolute">
			<parent>shoulder_right_joint_link_3</parent>
			<child>upper_arm_right</child>
			<pose frame="">-0.0010341710977828811 0.026474270092771805 -0.0005417771267103211 0 0 0</pose>
			<axis>
				<xyz>-0.039019466967256645 0.9990316219645872 -0.020329769118090937</xyz>
				<limit>
					<lower>-3.141592653589793</lower>
					<upper>3.141592653589793</upper>
				</limit>
				<use_parent_model_frame>0</use_parent_model_frame>
			</axis>
		</joint>
		<plugin filename="libmyomuscle_plugin.so" name="myomuscle_plugin"/>
	</model>
</sdf>
