<?xml version="1.0" ?>
<robot name="roboy_2_0_simplified">
  <joint name="shoulder_left_axis_3" type="revolute">
    <parent link="shoulder_left_joint_link_3"/>
    <child link="upper_arm_left"/>
    <origin rpy="0  0  0" xyz="-0.00523 -0.01313  0.00028"/>
    <axis xyz="2.46400000e-02  -9.99690000e-01  -2.90000000e-04"/>
    <limit effort="0.0" lower="-3.14159265359" upper="3.14159265359" velocity="0.0"/>
  </joint>
  <joint name="shoulder_left_axis_1" type="revolute">
    <parent link="torso"/>
    <child link="shoulder_left_joint_link_2"/>
    <origin rpy="0  0  0" xyz="0.28733  0.59432 -0.01833"/>
    <axis xyz="0.05101  0.02231  0.99844"/>
    <limit effort="0.0" lower="-3.14159265359" upper="3.14159265359" velocity="0.0"/>
  </joint>
  <joint name="shoulder_left_axis_2" type="revolute">
    <parent link="shoulder_left_joint_link_2"/>
    <child link="shoulder_left_joint_link_3"/>
    <origin rpy="0  0  0" xyz="0.00523  0.00022  0.00443"/>
    <axis xyz="-0.99836 -0.02463  0.05155"/>
    <limit effort="0.0" lower="-3.14159265359" upper="3.14159265359" velocity="0.0"/>
  </joint>
  <joint name="neck_axis_2" type="revolute">
    <parent link="neck_link_3"/>
    <child link="neck_link_2"/>
    <origin rpy="0  0  0" xyz="-0.00806  0.011    0"/>
    <axis xyz="-1  0  0"/>
    <limit effort="0.0" lower="-0.523598775598" upper="0.523598775598" velocity="0.0"/>
  </joint>
  <joint name="neck_axis_3" type="revolute">
    <parent link="neck_link_2"/>
    <child link="head"/>
    <origin rpy="0  0  0" xyz="0.01    -0.00266  0.00994"/>
    <axis xyz="0      -0.25881  0.96592"/>
    <limit effort="0.0" lower="-0.523598775598" upper="0.523598775598" velocity="0.0"/>
  </joint>
  <joint name="wrist_right" type="revolute">
    <parent link="lower_arm_right"/>
    <child link="hand_right"/>
    <origin rpy="0  0  0" xyz="0.00937  0.00094  0.26597"/>
    <axis xyz="0.10163  0.02222  0.99457"/>
    <limit effort="0.0" lower="-1.57079632679" upper="1.57079632679" velocity="0.0"/>
  </joint>
  <joint name="wrist_left" type="revolute">
    <parent link="lower_arm_left"/>
    <child link="hand_left"/>
    <origin rpy="0  0  0" xyz="0.01702 -0.00465  0.2613"/>
    <axis xyz="-2.38400000e-02  -6.00000000e-04   9.99710000e-01"/>
    <limit effort="0.0" lower="-1.57079632679" upper="1.57079632679" velocity="0.0"/>
  </joint>
  <joint name="shoulder_right_axis_1" type="revolute">
    <parent link="torso"/>
    <child link="shoulder_right_joint_link_2"/>
    <origin rpy="0  0  0" xyz="-0.29603  0.60176  0.02132"/>
    <axis xyz="-0.05101 -0.02231 -0.99844"/>
    <limit effort="0.0" lower="-3.14159265359" upper="3.14159265359" velocity="0.0"/>
  </joint>
  <joint name="shoulder_right_axis_2" type="revolute">
    <parent link="shoulder_right_joint_link_2"/>
    <child link="shoulder_right_joint_link_3"/>
    <origin rpy="0  0  0" xyz="-0.00524 -0.00029 -0.00469"/>
    <axis xyz="0.99793  0.03792 -0.05183"/>
    <limit effort="0.0" lower="-3.14159265359" upper="3.14159265359" velocity="0.0"/>
  </joint>
  <joint name="key_H" type="fixed">
    <parent link="torso"/>
    <child link="key_H"/>
    <origin rpy="0  0  0" xyz="-0.005    0.0465  -0.00567"/>
    <axis xyz="0  0  0"/>
    <limit effort="0" lower="0" upper="0" velocity="0"/>
  </joint>
  <joint name="key_G" type="fixed">
    <parent link="torso"/>
    <child link="key_G"/>
    <origin rpy="0  0  0" xyz="-0.005    0.0465  -0.00567"/>
    <axis xyz="0  0  0"/>
    <limit effort="0" lower="0" upper="0" velocity="0"/>
  </joint>
  <joint name="key_F" type="fixed">
    <parent link="torso"/>
    <child link="key_F"/>
    <origin rpy="0  0  0" xyz="-0.005    0.0465  -0.00567"/>
    <axis xyz="0  0  0"/>
    <limit effort="0" lower="0" upper="0" velocity="0"/>
  </joint>
  <joint name="key_E" type="fixed">
    <parent link="torso"/>
    <child link="key_E"/>
    <origin rpy="0  0  0" xyz="-0.005    0.0465  -0.00567"/>
    <axis xyz="0  0  0"/>
    <limit effort="0" lower="0" upper="0" velocity="0"/>
  </joint>
  <joint name="key_D" type="fixed">
    <parent link="torso"/>
    <child link="key_D"/>
    <origin rpy="0  0  0" xyz="-0.005    0.0465  -0.00567"/>
    <axis xyz="0  0  0"/>
    <limit effort="0" lower="0" upper="0" velocity="0"/>
  </joint>
  <joint name="key_C" type="fixed">
    <parent link="torso"/>
    <child link="key_C"/>
    <origin rpy="0  0  0" xyz="-0.005    0.0465  -0.00567"/>
    <axis xyz="0  0  0"/>
    <limit effort="0" lower="0" upper="0" velocity="0"/>
  </joint>
  <joint name="elbow_right" type="revolute">
    <parent link="upper_arm_right"/>
    <child link="lower_arm_right"/>
    <origin rpy="0  0  0" xyz="0.01752 -0.31012  0.00978"/>
    <axis xyz="0.99482 -0.00227 -0.10161"/>
    <limit effort="0.0" lower="-0.0" upper="1.57079632679" velocity="0.0"/>
  </joint>
  <joint name="elbow_left" type="revolute">
    <parent link="upper_arm_left"/>
    <child link="lower_arm_left"/>
    <origin rpy="0  0  0" xyz="-0.01004 -0.31059  0.00492"/>
    <axis xyz="9.99690000e-01   2.46400000e-02  -8.00000000e-04"/>
    <limit effort="0.0" lower="-0.0" upper="1.57079632679" velocity="0.0"/>
  </joint>
  <joint name="neck_axis_1" type="revolute">
    <parent link="torso"/>
    <child link="neck_link_3"/>
    <origin rpy="0  0  0" xyz="-0.005    0.77095 -0.00567"/>
    <axis xyz="0  1  0"/>
    <limit effort="0.0" lower="-0.523598775598" upper="0.523598775598" velocity="0.0"/>
  </joint>
  <joint name="shoulder_right_axis_3" type="revolute">
    <parent link="shoulder_right_joint_link_3"/>
    <child link="upper_arm_right"/>
    <origin rpy="0  0  0" xyz="0.00556 -0.01279  0"/>
    <axis xyz="-0.03901  0.99903 -0.02033"/>
    <limit effort="0.0" lower="-3.14159265359" upper="3.14159265359" velocity="0.0"/>
  </joint>
  <link name="lower_arm_right">
    <inertial>
      <mass value="0.1"/>
      <origin rpy="0  0  0" xyz="-0.014   -0.00417  0.03721"/>
      <inertia ixx="0.01" ixy="0.01" ixz="0.01" iyy="0.01" iyz="0.01" izz="0.01"/>
    </inertial>
    <collision name="lower_arm_right_collision">
      <origin rpy="0  0  0" xyz="-0.014   -0.00417  0.03721"/>
      <geometry>
        <sphere radius="0.03"/>
      </geometry>
    </collision>
    <visual name="lower_arm_right_visual">
      <origin rpy="0  0  0" xyz="-0.014   -0.00417  0.03721"/>
      <geometry>
        <mesh filename="package://roboy_models/roboy_2_0_simplified/meshes/CAD/lower_arm_right.stl" scale="0.001 0.001 0.001"/>
      </geometry>
    </visual>
  </link>
  <link name="lower_arm_left">
    <inertial>
      <mass value="0.1"/>
      <origin rpy="0  0  0" xyz="0.01684 -0.00459  0.03548"/>
      <inertia ixx="0.01" ixy="0.01" ixz="0.01" iyy="0.01" iyz="0.01" izz="0.01"/>
    </inertial>
    <collision name="lower_arm_left_collision">
      <origin rpy="0  0  0" xyz="0.01684 -0.00459  0.03548"/>
      <geometry>
        <sphere radius="0.03"/>
      </geometry>
    </collision>
    <visual name="lower_arm_left_visual">
      <origin rpy="0  0  0" xyz="0.01684 -0.00459  0.03548"/>
      <geometry>
        <mesh filename="package://roboy_models/roboy_2_0_simplified/meshes/CAD/lower_arm_left.stl" scale="0.001 0.001 0.001"/>
      </geometry>
    </visual>
  </link>
  <link name="head">
    <inertial>
      <mass value="0.1"/>
      <origin rpy="0  0  0" xyz="0       0.04735  0.00223"/>
      <inertia ixx="0.01" ixy="0.01" ixz="0.01" iyy="0.01" iyz="0.01" izz="0.01"/>
    </inertial>
    <collision name="head_collision">
      <origin rpy="0  0  0" xyz="0       0.04735  0.00223"/>
      <geometry>
        <sphere radius="0.03"/>
      </geometry>
    </collision>
    <visual name="head_visual">
      <origin rpy="0  0  0" xyz="0       0.04735  0.00223"/>
      <geometry>
        <mesh filename="package://roboy_models/roboy_2_0_simplified/meshes/CAD/head.stl" scale="0.001 0.001 0.001"/>
      </geometry>
    </visual>
  </link>
  <link name="upper_arm_left">
    <inertial>
      <mass value="0.1"/>
      <origin rpy="0  0  0" xyz="0.00065 -0.02649  0"/>
      <inertia ixx="0.01" ixy="0.01" ixz="0.01" iyy="0.01" iyz="0.01" izz="0.01"/>
    </inertial>
    <collision name="upper_arm_left_collision">
      <origin rpy="0  0  0" xyz="0.00065 -0.02649  0"/>
      <geometry>
        <sphere radius="0.03"/>
      </geometry>
    </collision>
    <visual name="upper_arm_left_visual">
      <origin rpy="0  0  0" xyz="0.00065 -0.02649  0"/>
      <geometry>
        <mesh filename="package://roboy_models/roboy_2_0_simplified/meshes/CAD/upper_arm_left.stl" scale="0.001 0.001 0.001"/>
      </geometry>
    </visual>
  </link>
  <link name="upper_arm_right">
    <inertial>
      <mass value="0.1"/>
      <origin rpy="0  0  0" xyz="0.00103 -0.02647  0.00054"/>
      <inertia ixx="0.01" ixy="0.01" ixz="0.01" iyy="0.01" iyz="0.01" izz="0.01"/>
    </inertial>
    <collision name="upper_arm_right_collision">
      <origin rpy="0  0  0" xyz="0.00103 -0.02647  0.00054"/>
      <geometry>
        <sphere radius="0.03"/>
      </geometry>
    </collision>
    <visual name="upper_arm_right_visual">
      <origin rpy="0  0  0" xyz="0.00103 -0.02647  0.00054"/>
      <geometry>
        <mesh filename="package://roboy_models/roboy_2_0_simplified/meshes/CAD/upper_arm_right.stl" scale="0.001 0.001 0.001"/>
      </geometry>
    </visual>
  </link>
  <link name="torso">
    <inertial>
      <mass value="100"/>
      <origin rpy="0  0  0" xyz="-0.005   -0.0035  -0.00567"/>
      <inertia ixx="1" ixy="0" ixz="0" iyy="1" iyz="0" izz="1"/>
    </inertial>
    <collision name="torso_collision">
      <origin rpy="0  0  0" xyz="-0.005   -0.0035  -0.00567"/>
      <geometry>
        <mesh filename="package://roboy_models/roboy_2_0_simplified/meshes/CAD/torso.stl" scale="0.001 0.001 0.001"/>
      </geometry>
    </collision>
    <visual name="torso_visual">
      <origin rpy="0  0  0" xyz="-0.005   -0.0035  -0.00567"/>
      <geometry>
        <mesh filename="package://roboy_models/roboy_2_0_simplified/meshes/CAD/torso.stl" scale="0.001 0.001 0.001"/>
      </geometry>
    </visual>
  </link>
  <link name="shoulder_left_joint_link_2">
    <inertial>
      <mass value="0.011947756900622582"/>
      <origin rpy="0  0  0" xyz="-0.0002  -0.0049   0.00472"/>
      <inertia ixx="0.01" ixy="0.01" ixz="0.01" iyy="0.01" iyz="0.01" izz="0.01"/>
    </inertial>
    <collision name="shoulder_left_joint_link_2_collision">
      <origin rpy="0  0  0" xyz="-0.0002  -0.0049   0.00472"/>
      <geometry>
        <sphere radius="0.03"/>
      </geometry>
    </collision>
    <visual name="shoulder_left_joint_link_2_visual">
      <origin rpy="0  0  0" xyz="-0.0002  -0.0049   0.00472"/>
      <geometry>
        <mesh filename="package://roboy_models/roboy_2_0_simplified/meshes/CAD/shoulder_left_joint_link_2.stl" scale="0.001 0.001 0.001"/>
      </geometry>
    </visual>
  </link>
  <link name="shoulder_left_joint_link_3">
    <inertial>
      <mass value="0.017192390951684323"/>
      <origin rpy="0  0  0" xyz="-0.00543 -0.00513  0.00028"/>
      <inertia ixx="0.01" ixy="0.01" ixz="0.01" iyy="0.01" iyz="0.01" izz="0.01"/>
    </inertial>
    <collision name="shoulder_left_joint_link_3_collision">
      <origin rpy="0  0  0" xyz="-0.00543 -0.00513  0.00028"/>
      <geometry>
        <sphere radius="0.03"/>
      </geometry>
    </collision>
    <visual name="shoulder_left_joint_link_3_visual">
      <origin rpy="0  0  0" xyz="-0.00543 -0.00513  0.00028"/>
      <geometry>
        <mesh filename="package://roboy_models/roboy_2_0_simplified/meshes/CAD/shoulder_left_joint_link_3.stl" scale="0.001 0.001 0.001"/>
      </geometry>
    </visual>
  </link>
  <link name="shoulder_right_joint_link_2">
    <inertial>
      <mass value="0.011947830827153384"/>
      <origin rpy="0  0  0" xyz="0      -0.0051  -0.00485"/>
      <inertia ixx="0.01" ixy="0.01" ixz="0.01" iyy="0.01" iyz="0.01" izz="0.01"/>
    </inertial>
    <collision name="shoulder_right_joint_link_2_collision">
      <origin rpy="0  0  0" xyz="0      -0.0051  -0.00485"/>
      <geometry>
        <sphere radius="0.03"/>
      </geometry>
    </collision>
    <visual name="shoulder_right_joint_link_2_visual">
      <origin rpy="0  0  0" xyz="0      -0.0051  -0.00485"/>
      <geometry>
        <mesh filename="package://roboy_models/roboy_2_0_simplified/meshes/CAD/shoulder_right_joint_link_2.stl" scale="0.001 0.001 0.001"/>
      </geometry>
    </visual>
  </link>
  <link name="shoulder_right_joint_link_3">
    <inertial>
      <mass value="0.01719247645061585"/>
      <origin rpy="0  0  0" xyz="0.00524 -0.0048  -0.00016"/>
      <inertia ixx="0.01" ixy="0.01" ixz="0.01" iyy="0.01" iyz="0.01" izz="0.01"/>
    </inertial>
    <collision name="shoulder_right_joint_link_3_collision">
      <origin rpy="0  0  0" xyz="0.00524 -0.0048  -0.00016"/>
      <geometry>
        <sphere radius="0.03"/>
      </geometry>
    </collision>
    <visual name="shoulder_right_joint_link_3_visual">
      <origin rpy="0  0  0" xyz="0.00524 -0.0048  -0.00016"/>
      <geometry>
        <mesh filename="package://roboy_models/roboy_2_0_simplified/meshes/CAD/shoulder_right_joint_link_3.stl" scale="0.001 0.001 0.001"/>
      </geometry>
    </visual>
  </link>
  <link name="neck_link_3">
    <inertial>
      <mass value="0.017192417326343308"/>
      <origin rpy="0  0  0" xyz="0     0.006  0"/>
      <inertia ixx="0.01" ixy="0.01" ixz="0.01" iyy="0.01" iyz="0.01" izz="0.01"/>
    </inertial>
    <collision name="neck_link_3_collision">
      <origin rpy="0  0  0" xyz="0     0.006  0"/>
      <geometry>
        <sphere radius="0.03"/>
      </geometry>
    </collision>
    <visual name="neck_link_3_visual">
      <origin rpy="0  0  0" xyz="0     0.006  0"/>
      <geometry>
        <mesh filename="package://roboy_models/roboy_2_0_simplified/meshes/CAD/neck_link_3.stl" scale="0.001 0.001 0.001"/>
      </geometry>
    </visual>
  </link>
  <link name="neck_link_2">
    <inertial>
      <mass value="0.011947622039161103"/>
      <origin rpy="0  0  0" xyz="0.00806 -0.005    0"/>
      <inertia ixx="0.01" ixy="0.01" ixz="0.01" iyy="0.01" iyz="0.01" izz="0.01"/>
    </inertial>
    <collision name="neck_link_2_collision">
      <origin rpy="0  0  0" xyz="0.00806 -0.005    0"/>
      <geometry>
        <sphere radius="0.03"/>
      </geometry>
    </collision>
    <visual name="neck_link_2_visual">
      <origin rpy="0  0  0" xyz="0.00806 -0.005    0"/>
      <geometry>
        <mesh filename="package://roboy_models/roboy_2_0_simplified/meshes/CAD/neck_link_2.stl" scale="0.001 0.001 0.001"/>
      </geometry>
    </visual>
  </link>
  <link name="hand_right">
    <inertial>
      <mass value="0.1"/>
      <origin rpy="0  0  0" xyz="0.01679  0.24538  0.15889"/>
      <inertia ixx="0.01" ixy="0.01" ixz="0.01" iyy="0.01" iyz="0.01" izz="0.01"/>
    </inertial>
    <collision name="hand_right_collision">
      <origin rpy="0  0  0" xyz="0.01679  0.24538  0.15889"/>
      <geometry>
        <sphere radius="0.03"/>
      </geometry>
    </collision>
    <visual name="hand_right_visual">
      <origin rpy="0  0  0" xyz="0.01679  0.24538  0.15889"/>
      <geometry>
        <mesh filename="package://roboy_models/roboy_2_0_simplified/meshes/CAD/hand_right.stl" scale="0.001 0.001 0.001"/>
      </geometry>
    </visual>
  </link>
  <link name="hand_left">
    <inertial>
      <mass value="0.1"/>
      <origin rpy="0  0  0" xyz="-0.00724  0.24164  0.16521"/>
      <inertia ixx="0.01" ixy="0.01" ixz="0.01" iyy="0.01" iyz="0.01" izz="0.01"/>
    </inertial>
    <collision name="hand_left_collision">
      <origin rpy="0  0  0" xyz="-0.00724  0.24164  0.16521"/>
      <geometry>
        <sphere radius="0.03"/>
      </geometry>
    </collision>
    <visual name="hand_left_visual">
      <origin rpy="0  0  0" xyz="-0.00724  0.24164  0.16521"/>
      <geometry>
        <mesh filename="package://roboy_models/roboy_2_0_simplified/meshes/CAD/hand_left.stl" scale="0.001 0.001 0.001"/>
      </geometry>
    </visual>
  </link>
  <link name="key_F">
    <inertial>
      <mass value="0.8242499999999997"/>
      <origin rpy="0  0  0" xyz="-0.06   0.235  0.52"/>
      <inertia ixx="0.229782676203744" ixy="0.009308529999999616" ixz="-0.10340034138425735" iyy="0.16556419101624362" iyz="0.014649399015478546" izz="0.06719952268750011"/>
    </inertial>
    <collision name="key_F_collision">
      <origin rpy="0  0  0" xyz="-0.06   0.235  0.52"/>
      <geometry>
        <mesh filename="package://roboy_models/roboy_2_0_simplified/meshes/CAD/key_F.stl" scale="0.001 0.001 0.001"/>
      </geometry>
    </collision>
    <visual name="key_F_visual">
      <origin rpy="0  0  0" xyz="-0.06   0.235  0.52"/>
      <geometry>
        <mesh filename="package://roboy_models/roboy_2_0_simplified/meshes/CAD/key_F.stl" scale="0.001 0.001 0.001"/>
      </geometry>
    </visual>
  </link>
  <link name="key_G">
    <inertial>
      <mass value="0.706499999999999"/>
      <origin rpy="0  0  0" xyz="-0.13   0.235  0.51"/>
      <inertia ixx="0.1966504296032091" ixy="0.02194153499999971" ixz="-0.08862886404364916" iyy="0.1490242637282087" iyz="0.03453072625077184" izz="0.06501784087499991"/>
    </inertial>
    <collision name="key_G_collision">
      <origin rpy="0  0  0" xyz="-0.13   0.235  0.51"/>
      <geometry>
        <mesh filename="package://roboy_models/roboy_2_0_simplified/meshes/CAD/key_G.stl" scale="0.001 0.001 0.001"/>
      </geometry>
    </collision>
    <visual name="key_G_visual">
      <origin rpy="0  0  0" xyz="-0.13   0.235  0.51"/>
      <geometry>
        <mesh filename="package://roboy_models/roboy_2_0_simplified/meshes/CAD/key_G.stl" scale="0.001 0.001 0.001"/>
      </geometry>
    </visual>
  </link>
  <link name="key_C">
    <inertial>
      <mass value="1.177499999999998"/>
      <origin rpy="0  0  0" xyz="0.15   0.235  0.55"/>
      <inertia ixx="0.3302627160053484" ixy="-0.05651607500000076" ixz="-0.1477147734060819" iyy="0.2706677728803488" iyz="-0.08894277973683888" izz="0.12814506812500112"/>
    </inertial>
    <collision name="key_C_collision">
      <origin rpy="0  0  0" xyz="0.15   0.235  0.55"/>
      <geometry>
        <mesh filename="package://roboy_models/roboy_2_0_simplified/meshes/CAD/key_C.stl" scale="0.001 0.001 0.001"/>
      </geometry>
    </collision>
    <visual name="key_C_visual">
      <origin rpy="0  0  0" xyz="0.15   0.235  0.55"/>
      <geometry>
        <mesh filename="package://roboy_models/roboy_2_0_simplified/meshes/CAD/key_C.stl" scale="0.001 0.001 0.001"/>
      </geometry>
    </visual>
  </link>
  <link name="key_H">
    <inertial>
      <mass value="0.5887499999999979"/>
      <origin rpy="0  0  0" xyz="-0.2    0.235  0.5"/>
      <inertia ixx="0.16365948300267433" ixy="0.029920274999999795" ixz="-0.07385738670304097" iyy="0.13592263644017383" iyz="0.047087353978325544" izz="0.06613315906249982"/>
    </inertial>
    <collision name="key_H_collision">
      <origin rpy="0  0  0" xyz="-0.2    0.235  0.5"/>
      <geometry>
        <mesh filename="package://roboy_models/roboy_2_0_simplified/meshes/CAD/key_H.stl" scale="0.001 0.001 0.001"/>
      </geometry>
    </collision>
    <visual name="key_H_visual">
      <origin rpy="0  0  0" xyz="-0.2    0.235  0.5"/>
      <geometry>
        <mesh filename="package://roboy_models/roboy_2_0_simplified/meshes/CAD/key_H.stl" scale="0.001 0.001 0.001"/>
      </geometry>
    </visual>
  </link>
  <link name="key_E">
    <inertial>
      <mass value="0.9420000000000001"/>
      <origin rpy="0  0  0" xyz="0.01   0.235  0.53"/>
      <inertia ixx="0.2630797728042788" ixy="-0.007978740000000494" ixz="-0.11817181872486557" iyy="0.18902781830427867" iyz="-0.01255662772755434" izz="0.07614005450000037"/>
    </inertial>
    <collision name="key_E_collision">
      <origin rpy="0  0  0" xyz="0.01   0.235  0.53"/>
      <geometry>
        <mesh filename="package://roboy_models/roboy_2_0_simplified/meshes/CAD/key_E.stl" scale="0.001 0.001 0.001"/>
      </geometry>
    </collision>
    <visual name="key_E_visual">
      <origin rpy="0  0  0" xyz="0.01   0.235  0.53"/>
      <geometry>
        <mesh filename="package://roboy_models/roboy_2_0_simplified/meshes/CAD/key_E.stl" scale="0.001 0.001 0.001"/>
      </geometry>
    </visual>
  </link>
  <link name="key_D">
    <inertial>
      <mass value="1.0597499999999997"/>
      <origin rpy="0  0  0" xyz="0.08   0.235  0.54"/>
      <inertia ixx="0.2965652694048136" ixy="-0.02992027500000062" ixz="-0.13294329606547373" iyy="0.22290054559231373" iyz="-0.047087353978326814" izz="0.0953012863125007"/>
    </inertial>
    <collision name="key_D_collision">
      <origin rpy="0  0  0" xyz="0.08   0.235  0.54"/>
      <geometry>
        <mesh filename="package://roboy_models/roboy_2_0_simplified/meshes/CAD/key_D.stl" scale="0.001 0.001 0.001"/>
      </geometry>
    </collision>
    <visual name="key_D_visual">
      <origin rpy="0  0  0" xyz="0.08   0.235  0.54"/>
      <geometry>
        <mesh filename="package://roboy_models/roboy_2_0_simplified/meshes/CAD/key_D.stl" scale="0.001 0.001 0.001"/>
      </geometry>
    </visual>
  </link>
</robot>
