<?xml version="1.0" ?>
<robot name="roboy_2_0_simplified">
  <joint name="shoulder_left_axis_1" type="revolute">
    <parent link="torso"/>
    <child link="shoulder_left_joint_link_2"/>
    <origin rpy="0  0  0" xyz="0.28733  0.59432 -0.01833"/>
    <axis xyz="0.05101  0.02231  0.99844"/>
    <limit effort="0.0" lower="-3.14159265359" upper="3.14159265359" velocity="0.0"/>
  </joint>
  <joint name="shoulder_left_axis_2" type="revolute">
    <parent link="shoulder_left_joint_link_2"/>
    <child link="shoulder_left_joint_link_3"/>
    <origin rpy="0  0  0" xyz="0.00523  0.00022  0.00443"/>
    <axis xyz="-0.99836 -0.02463  0.05155"/>
    <limit effort="0.0" lower="-3.14159265359" upper="3.14159265359" velocity="0.0"/>
  </joint>
  <joint name="neck_axis_2" type="revolute">
    <parent link="neck_link_3"/>
    <child link="neck_link_2"/>
    <origin rpy="0  0  0" xyz="-0.00806  0.011    0"/>
    <axis xyz="-1  0  0"/>
    <limit effort="0.0" lower="-0.523598775598" upper="0.523598775598" velocity="0.0"/>
  </joint>
  <joint name="neck_axis_3" type="revolute">
    <parent link="neck_link_2"/>
    <child link="head"/>
    <origin rpy="0  0  0" xyz="0.01    -0.00266  0.00994"/>
    <axis xyz="0      -0.25881  0.96592"/>
    <limit effort="0.0" lower="-3.14159265359" upper="3.14159265359" velocity="0.0"/>
  </joint>
  <joint name="wrist_right" type="revolute">
    <parent link="lower_arm_right"/>
    <child link="hand_right"/>
    <origin rpy="0  0  0" xyz="0.00937  0.00094  0.26597"/>
    <axis xyz="0.10163  0.02222  0.99457"/>
    <limit effort="0.0" lower="-1.57079632679" upper="1.57079632679" velocity="0.0"/>
  </joint>
  <joint name="wrist_left" type="revolute">
    <parent link="lower_arm_left"/>
    <child link="hand_left"/>
    <origin rpy="0  0  0" xyz="0.01702 -0.00465  0.2613"/>
    <axis xyz="-2.38400000e-02  -6.00000000e-04   9.99710000e-01"/>
    <limit effort="0.0" lower="-1.57079632679" upper="1.57079632679" velocity="0.0"/>
  </joint>
  <joint name="shoulder_right_axis_1" type="revolute">
    <parent link="torso"/>
    <child link="shoulder_right_joint_link_2"/>
    <origin rpy="0  0  0" xyz="-0.29603  0.60176  0.02132"/>
    <axis xyz="-0.05101 -0.02231 -0.99844"/>
    <limit effort="0.0" lower="-3.14159265359" upper="3.14159265359" velocity="0.0"/>
  </joint>
  <joint name="shoulder_right_axis_2" type="revolute">
    <parent link="shoulder_right_joint_link_2"/>
    <child link="shoulder_right_joint_link_3"/>
    <origin rpy="0  0  0" xyz="-0.00524 -0.00029 -0.00469"/>
    <axis xyz="0.99793  0.03792 -0.05183"/>
    <limit effort="0.0" lower="-3.14159265359" upper="3.14159265359" velocity="0.0"/>
  </joint>
  <joint name="elbow_left" type="revolute">
    <parent link="upper_arm_left"/>
    <child link="lower_arm_left"/>
    <origin rpy="0  0  0" xyz="-0.01004 -0.31059  0.00492"/>
    <axis xyz="9.99690000e-01   2.46400000e-02  -8.00000000e-04"/>
    <limit effort="0.0" lower="-0.0" upper="1.57079632679" velocity="0.0"/>
  </joint>
  <joint name="elbow_right" type="revolute">
    <parent link="upper_arm_right"/>
    <child link="lower_arm_right"/>
    <origin rpy="0  0  0" xyz="0.01752 -0.31012  0.00978"/>
    <axis xyz="0.99482 -0.00227 -0.10161"/>
    <limit effort="0.0" lower="-0.0" upper="1.57079632679" velocity="0.0"/>
  </joint>
  <joint name="shoulder_left_axis_3" type="revolute">
    <parent link="shoulder_left_joint_link_3"/>
    <child link="upper_arm_left"/>
    <origin rpy="0  0  0" xyz="-0.00523 -0.01313  0.00028"/>
    <axis xyz="2.46400000e-02  -9.99690000e-01  -2.90000000e-04"/>
    <limit effort="0.0" lower="-3.14159265359" upper="3.14159265359" velocity="0.0"/>
  </joint>
  <joint name="shoulder_right_axis_3" type="revolute">
    <parent link="shoulder_right_joint_link_3"/>
    <child link="upper_arm_right"/>
    <origin rpy="0  0  0" xyz="0.00556 -0.01279  0"/>
    <axis xyz="-0.03901  0.99903 -0.02033"/>
    <limit effort="0.0" lower="-3.14159265359" upper="3.14159265359" velocity="0.0"/>
  </joint>
  <joint name="neck_axis_1" type="revolute">
    <parent link="torso"/>
    <child link="neck_link_3"/>
    <origin rpy="0  0  0" xyz="-0.005    0.77095 -0.00567"/>
    <axis xyz="0  1  0"/>
    <limit effort="0.0" lower="-0.523598775598" upper="0.523598775598" velocity="0.0"/>
  </joint>
  <link name="lower_arm_right">
    <inertial>
      <mass value="1.0"/>
      <origin rpy="0  0  0" xyz="-0.014   -0.00417  0.03721"/>
      <inertia ixx="0.1" ixy="0.0" ixz="0.0" iyy="0.1" iyz="0.0" izz="0.1"/>
    </inertial>
    <collision name="lower_arm_right_collision">
      <origin rpy="0  0  0" xyz="-0.014   -0.00417  0.03721"/>
      <geometry>
        <mesh filename="package://roboy_models/roboy_2_0_simplified/meshes/CAD/lower_arm_right.stl" scale="0.001 0.001 0.001"/>
      </geometry>
    </collision>
    <visual name="lower_arm_right_visual">
      <origin rpy="0  0  0" xyz="-0.014   -0.00417  0.03721"/>
      <geometry>
        <mesh filename="package://roboy_models/roboy_2_0_simplified/meshes/CAD/lower_arm_right.stl" scale="0.001 0.001 0.001"/>
      </geometry>
    </visual>
  </link>
  <link name="lower_arm_left">
    <inertial>
      <mass value="1.0"/>
      <origin rpy="0  0  0" xyz="0.01684 -0.00459  0.03548"/>
      <inertia ixx="0.1" ixy="0.0" ixz="0.0" iyy="0.1" iyz="0.0" izz="0.1"/>
    </inertial>
    <collision name="lower_arm_left_collision">
      <origin rpy="0  0  0" xyz="0.01684 -0.00459  0.03548"/>
      <geometry>
        <mesh filename="package://roboy_models/roboy_2_0_simplified/meshes/CAD/lower_arm_left.stl" scale="0.001 0.001 0.001"/>
      </geometry>
    </collision>
    <visual name="lower_arm_left_visual">
      <origin rpy="0  0  0" xyz="0.01684 -0.00459  0.03548"/>
      <geometry>
        <mesh filename="package://roboy_models/roboy_2_0_simplified/meshes/CAD/lower_arm_left.stl" scale="0.001 0.001 0.001"/>
      </geometry>
    </visual>
  </link>
  <link name="head">
    <inertial>
      <mass value="1.0"/>
      <origin rpy="0  0  0" xyz="0       0.04735  0.00223"/>
      <inertia ixx="0.1" ixy="0.0" ixz="0.0" iyy="0.1" iyz="0.0" izz="0.1"/>
    </inertial>
    <collision name="head_collision">
      <origin rpy="0  0  0" xyz="0       0.04735  0.00223"/>
      <geometry>
        <mesh filename="package://roboy_models/roboy_2_0_simplified/meshes/CAD/head.stl" scale="0.001 0.001 0.001"/>
      </geometry>
    </collision>
    <visual name="head_visual">
      <origin rpy="0  0  0" xyz="0       0.04735  0.00223"/>
      <geometry>
        <mesh filename="package://roboy_models/roboy_2_0_simplified/meshes/CAD/head.stl" scale="0.001 0.001 0.001"/>
      </geometry>
    </visual>
  </link>
  <link name="upper_arm_left">
    <inertial>
      <mass value="1.0"/>
      <origin rpy="0  0  0" xyz="0.00065 -0.02649  0"/>
      <inertia ixx="0.1" ixy="0.0" ixz="0.0" iyy="0.1" iyz="0.0" izz="0.1"/>
    </inertial>
    <collision name="upper_arm_left_collision">
      <origin rpy="0  0  0" xyz="0.00065 -0.02649  0"/>
      <geometry>
        <mesh filename="package://roboy_models/roboy_2_0_simplified/meshes/CAD/upper_arm_left.stl" scale="0.001 0.001 0.001"/>
      </geometry>
    </collision>
    <visual name="upper_arm_left_visual">
      <origin rpy="0  0  0" xyz="0.00065 -0.02649  0"/>
      <geometry>
        <mesh filename="package://roboy_models/roboy_2_0_simplified/meshes/CAD/upper_arm_left.stl" scale="0.001 0.001 0.001"/>
      </geometry>
    </visual>
  </link>
  <link name="upper_arm_right">
    <inertial>
      <mass value="1.0"/>
      <origin rpy="0  0  0" xyz="0.00103 -0.02647  0.00054"/>
      <inertia ixx="0.1" ixy="0.0" ixz="0.0" iyy="0.1" iyz="0.0" izz="0.1"/>
    </inertial>
    <collision name="upper_arm_right_collision">
      <origin rpy="0  0  0" xyz="0.00103 -0.02647  0.00054"/>
      <geometry>
        <mesh filename="package://roboy_models/roboy_2_0_simplified/meshes/CAD/upper_arm_right.stl" scale="0.001 0.001 0.001"/>
      </geometry>
    </collision>
    <visual name="upper_arm_right_visual">
      <origin rpy="0  0  0" xyz="0.00103 -0.02647  0.00054"/>
      <geometry>
        <mesh filename="package://roboy_models/roboy_2_0_simplified/meshes/CAD/upper_arm_right.stl" scale="0.001 0.001 0.001"/>
      </geometry>
    </visual>
  </link>
  <link name="torso">
    <inertial>
      <mass value="140.58134585461323"/>
      <origin rpy="0  0  0" xyz="-0.005   -0.0035  -0.00567"/>
      <inertia ixx="29.75091395387961" ixy="0.04527798000469084" ixz="0.014341172930339728" iyy="51.64894893502539" iyz="-0.001340043940851699" izz="29.877245239997116"/>
    </inertial>
    <collision name="torso_collision">
      <origin rpy="0  0  0" xyz="-0.005   -0.0035  -0.00567"/>
      <geometry>
        <mesh filename="package://roboy_models/roboy_2_0_simplified/meshes/CAD/torso.stl" scale="0.001 0.001 0.001"/>
      </geometry>
    </collision>
    <visual name="torso_visual">
      <origin rpy="0  0  0" xyz="-0.005   -0.0035  -0.00567"/>
      <geometry>
        <mesh filename="package://roboy_models/roboy_2_0_simplified/meshes/CAD/torso.stl" scale="0.001 0.001 0.001"/>
      </geometry>
    </visual>
  </link>
  <link name="shoulder_left_joint_link_2">
    <inertial>
      <mass value="0.001"/>
      <origin rpy="0  0  0" xyz="-0.0002  -0.0049   0.00472"/>
      <inertia ixx="0.001" ixy="0.0" ixz="0.0" iyy="0.001" iyz="0.0" izz="0.001"/>
    </inertial>
    <collision name="shoulder_left_joint_link_2_collision">
      <origin rpy="0  0  0" xyz="-0.0002  -0.0049   0.00472"/>
      <geometry>
        <mesh filename="package://roboy_models/roboy_2_0_simplified/meshes/CAD/shoulder_left_joint_link_2.stl" scale="0.001 0.001 0.001"/>
      </geometry>
    </collision>
    <visual name="shoulder_left_joint_link_2_visual">
      <origin rpy="0  0  0" xyz="-0.0002  -0.0049   0.00472"/>
      <geometry>
        <mesh filename="package://roboy_models/roboy_2_0_simplified/meshes/CAD/shoulder_left_joint_link_2.stl" scale="0.001 0.001 0.001"/>
      </geometry>
    </visual>
  </link>
  <link name="shoulder_left_joint_link_3">
    <inertial>
      <mass value="0.001"/>
      <origin rpy="0  0  0" xyz="-0.00543 -0.00513  0.00028"/>
      <inertia ixx="0.001" ixy="0.0" ixz="0.0" iyy="0.001" iyz="0.0" izz="0.001"/>
    </inertial>
    <collision name="shoulder_left_joint_link_3_collision">
      <origin rpy="0  0  0" xyz="-0.00543 -0.00513  0.00028"/>
      <geometry>
        <mesh filename="package://roboy_models/roboy_2_0_simplified/meshes/CAD/shoulder_left_joint_link_3.stl" scale="0.001 0.001 0.001"/>
      </geometry>
    </collision>
    <visual name="shoulder_left_joint_link_3_visual">
      <origin rpy="0  0  0" xyz="-0.00543 -0.00513  0.00028"/>
      <geometry>
        <mesh filename="package://roboy_models/roboy_2_0_simplified/meshes/CAD/shoulder_left_joint_link_3.stl" scale="0.001 0.001 0.001"/>
      </geometry>
    </visual>
  </link>
  <link name="shoulder_right_joint_link_2">
    <inertial>
      <mass value="0.001"/>
      <origin rpy="0  0  0" xyz="0      -0.0051  -0.00485"/>
      <inertia ixx="0.001" ixy="0.0" ixz="0.0" iyy="0.001" iyz="0.0" izz="0.001"/>
    </inertial>
    <collision name="shoulder_right_joint_link_2_collision">
      <origin rpy="0  0  0" xyz="0      -0.0051  -0.00485"/>
      <geometry>
        <mesh filename="package://roboy_models/roboy_2_0_simplified/meshes/CAD/shoulder_right_joint_link_2.stl" scale="0.001 0.001 0.001"/>
      </geometry>
    </collision>
    <visual name="shoulder_right_joint_link_2_visual">
      <origin rpy="0  0  0" xyz="0      -0.0051  -0.00485"/>
      <geometry>
        <mesh filename="package://roboy_models/roboy_2_0_simplified/meshes/CAD/shoulder_right_joint_link_2.stl" scale="0.001 0.001 0.001"/>
      </geometry>
    </visual>
  </link>
  <link name="shoulder_right_joint_link_3">
    <inertial>
      <mass value="0.001"/>
      <origin rpy="0  0  0" xyz="0.00524 -0.0048  -0.00016"/>
      <inertia ixx="0.001" ixy="0.0" ixz="0.0" iyy="0.001" iyz="0.0" izz="0.001"/>
    </inertial>
    <collision name="shoulder_right_joint_link_3_collision">
      <origin rpy="0  0  0" xyz="0.00524 -0.0048  -0.00016"/>
      <geometry>
        <mesh filename="package://roboy_models/roboy_2_0_simplified/meshes/CAD/shoulder_right_joint_link_3.stl" scale="0.001 0.001 0.001"/>
      </geometry>
    </collision>
    <visual name="shoulder_right_joint_link_3_visual">
      <origin rpy="0  0  0" xyz="0.00524 -0.0048  -0.00016"/>
      <geometry>
        <mesh filename="package://roboy_models/roboy_2_0_simplified/meshes/CAD/shoulder_right_joint_link_3.stl" scale="0.001 0.001 0.001"/>
      </geometry>
    </visual>
  </link>
  <link name="neck_link_3">
    <inertial>
      <mass value="0.001"/>
      <origin rpy="0  0  0" xyz="0     0.006  0"/>
      <inertia ixx="0.001" ixy="0.0" ixz="0.0" iyy="0.001" iyz="0.0" izz="0.001"/>
    </inertial>
    <collision name="neck_link_3_collision">
      <origin rpy="0  0  0" xyz="0     0.006  0"/>
      <geometry>
        <mesh filename="package://roboy_models/roboy_2_0_simplified/meshes/CAD/neck_link_3.stl" scale="0.001 0.001 0.001"/>
      </geometry>
    </collision>
    <visual name="neck_link_3_visual">
      <origin rpy="0  0  0" xyz="0     0.006  0"/>
      <geometry>
        <mesh filename="package://roboy_models/roboy_2_0_simplified/meshes/CAD/neck_link_3.stl" scale="0.001 0.001 0.001"/>
      </geometry>
    </visual>
  </link>
  <link name="neck_link_2">
    <inertial>
      <mass value="0.001"/>
      <origin rpy="0  0  0" xyz="0.00806 -0.005    0"/>
      <inertia ixx="0.001" ixy="0.0" ixz="0.0" iyy="0.001" iyz="0.0" izz="0.001"/>
    </inertial>
    <collision name="neck_link_2_collision">
      <origin rpy="0  0  0" xyz="0.00806 -0.005    0"/>
      <geometry>
        <mesh filename="package://roboy_models/roboy_2_0_simplified/meshes/CAD/neck_link_2.stl" scale="0.001 0.001 0.001"/>
      </geometry>
    </collision>
    <visual name="neck_link_2_visual">
      <origin rpy="0  0  0" xyz="0.00806 -0.005    0"/>
      <geometry>
        <mesh filename="package://roboy_models/roboy_2_0_simplified/meshes/CAD/neck_link_2.stl" scale="0.001 0.001 0.001"/>
      </geometry>
    </visual>
  </link>
  <link name="hand_right">
    <inertial>
      <mass value="1.1656326292601011"/>
      <origin rpy="0  0  0" xyz="0.01679  0.24538  0.15889"/>
      <inertia ixx="0.5029411938019898" ixy="0.14125269507903973" ixz="-0.2476973120130119" iyy="0.3019735753642406" iyz="0.13008809973489568" izz="0.3519304007272712"/>
    </inertial>
    <collision name="hand_right_collision">
      <origin rpy="0  0  0" xyz="0.01679  0.24538  0.15889"/>
      <geometry>
        <mesh filename="package://roboy_models/roboy_2_0_simplified/meshes/CAD/hand_right.stl" scale="0.001 0.001 0.001"/>
      </geometry>
    </collision>
    <visual name="hand_right_visual">
      <origin rpy="0  0  0" xyz="0.01679  0.24538  0.15889"/>
      <geometry>
        <mesh filename="package://roboy_models/roboy_2_0_simplified/meshes/CAD/hand_right.stl" scale="0.001 0.001 0.001"/>
      </geometry>
    </visual>
  </link>
  <link name="hand_left">
    <inertial>
      <mass value="1.1634567189927152"/>
      <origin rpy="0  0  0" xyz="-0.00724  0.24164  0.16521"/>
      <inertia ixx="0.4500486362111723" ixy="-0.1548647694655066" ixz="-0.2204806121961216" iyy="0.289458204468589" iyz="-0.1360020042916324" izz="0.35501542462237107"/>
    </inertial>
    <collision name="hand_left_collision">
      <origin rpy="0  0  0" xyz="-0.00724  0.24164  0.16521"/>
      <geometry>
        <mesh filename="package://roboy_models/roboy_2_0_simplified/meshes/CAD/hand_left.stl" scale="0.001 0.001 0.001"/>
      </geometry>
    </collision>
    <visual name="hand_left_visual">
      <origin rpy="0  0  0" xyz="-0.00724  0.24164  0.16521"/>
      <geometry>
        <mesh filename="package://roboy_models/roboy_2_0_simplified/meshes/CAD/hand_left.stl" scale="0.001 0.001 0.001"/>
      </geometry>
    </visual>
  </link>
</robot>
