<?xml version="1.0" ?>
<robot name="roboy_2_0_simplified">
  <joint name="roboy_2_0_simplified__elbow_right" type="revolute">
    <parent link="roboy_2_0_simplified__upper_arm_right"/>
    <child link="roboy_2_0_simplified__lower_arm_right"/>
    <origin rpy="0  0  0" xyz="0.01752 -0.31012  0.00978"/>
    <axis xyz="0.99482 -0.00227 -0.10161"/>
    <limit effort="0.0" lower="-0.0" upper="1.57079632679" velocity="0.0"/>
  </joint>
  <joint name="roboy_2_0_simplified__elbow_left" type="revolute">
    <parent link="roboy_2_0_simplified__upper_arm_left"/>
    <child link="roboy_2_0_simplified__lower_arm_left"/>
    <origin rpy="0  0  0" xyz="-0.01004 -0.31059  0.00492"/>
    <axis xyz="9.99690000e-01   2.46400000e-02  -8.00000000e-04"/>
    <limit effort="0.0" lower="-0.0" upper="1.57079632679" velocity="0.0"/>
  </joint>
  <joint name="roboy_2_0_simplified__shoulder_left_axis_1" type="revolute">
    <parent link="roboy_2_0_simplified__torso"/>
    <child link="roboy_2_0_simplified__shoulder_left_joint_link_2"/>
    <origin rpy="0  0  0" xyz="0.28733  0.59432 -0.01833"/>
    <axis xyz="0.05101  0.02231  0.99844"/>
    <limit effort="0.0" lower="-3.14159265359" upper="3.14159265359" velocity="0.0"/>
  </joint>
  <joint name="roboy_2_0_simplified__shoulder_left_axis_2" type="revolute">
    <parent link="roboy_2_0_simplified__shoulder_left_joint_link_2"/>
    <child link="roboy_2_0_simplified__shoulder_left_joint_link_3"/>
    <origin rpy="0  0  0" xyz="0.00523  0.00022  0.00443"/>
    <axis xyz="-0.99836 -0.02463  0.05155"/>
    <limit effort="0.0" lower="-3.14159265359" upper="3.14159265359" velocity="0.0"/>
  </joint>
  <joint name="roboy_2_0_simplified__neck_axis_2" type="revolute">
    <parent link="roboy_2_0_simplified__neck_link_3"/>
    <child link="roboy_2_0_simplified__neck_link_2"/>
    <origin rpy="0  0  0" xyz="-0.00806  0.011    0"/>
    <axis xyz="-1  0  0"/>
    <limit effort="0.0" lower="-0.523598775598" upper="0.523598775598" velocity="0.0"/>
  </joint>
  <joint name="roboy_2_0_simplified__neck_axis_3" type="revolute">
    <parent link="roboy_2_0_simplified__neck_link_2"/>
    <child link="roboy_2_0_simplified__head"/>
    <origin rpy="0  0  0" xyz="0.01    -0.00266  0.00994"/>
    <axis xyz="0      -0.25881  0.96592"/>
    <limit effort="0.0" lower="-3.14159265359" upper="3.14159265359" velocity="0.0"/>
  </joint>
  <joint name="roboy_2_0_simplified__wrist_right" type="revolute">
    <parent link="roboy_2_0_simplified__lower_arm_right"/>
    <child link="roboy_2_0_simplified__hand_right"/>
    <origin rpy="0  0  0" xyz="0.00937  0.00094  0.26597"/>
    <axis xyz="0.10163  0.02222  0.99457"/>
    <limit effort="0.0" lower="-1.57079632679" upper="1.57079632679" velocity="0.0"/>
  </joint>
  <joint name="roboy_2_0_simplified__wrist_left" type="revolute">
    <parent link="roboy_2_0_simplified__lower_arm_left"/>
    <child link="roboy_2_0_simplified__hand_left"/>
    <origin rpy="0  0  0" xyz="0.01702 -0.00465  0.2613"/>
    <axis xyz="-2.38400000e-02  -6.00000000e-04   9.99710000e-01"/>
    <limit effort="0.0" lower="-1.57079632679" upper="1.57079632679" velocity="0.0"/>
  </joint>
  <joint name="roboy_2_0_simplified__shoulder_right_axis_1" type="revolute">
    <parent link="roboy_2_0_simplified__torso"/>
    <child link="roboy_2_0_simplified__shoulder_right_joint_link_2"/>
    <origin rpy="0  0  0" xyz="-0.29603  0.60176  0.02132"/>
    <axis xyz="-0.05101 -0.02231 -0.99844"/>
    <limit effort="0.0" lower="-3.14159265359" upper="3.14159265359" velocity="0.0"/>
  </joint>
  <joint name="roboy_2_0_simplified__shoulder_right_axis_2" type="revolute">
    <parent link="roboy_2_0_simplified__shoulder_right_joint_link_2"/>
    <child link="roboy_2_0_simplified__shoulder_right_joint_link_3"/>
    <origin rpy="0  0  0" xyz="-0.00524 -0.00029 -0.00469"/>
    <axis xyz="0.99793  0.03792 -0.05183"/>
    <limit effort="0.0" lower="-3.14159265359" upper="3.14159265359" velocity="0.0"/>
  </joint>
  <joint name="roboy_2_0_simplified__shoulder_left_axis_3" type="revolute">
    <parent link="roboy_2_0_simplified__shoulder_left_joint_link_3"/>
    <child link="roboy_2_0_simplified__upper_arm_left"/>
    <origin rpy="0  0  0" xyz="-0.00523 -0.01313  0.00028"/>
    <axis xyz="2.46400000e-02  -9.99690000e-01  -2.90000000e-04"/>
    <limit effort="0.0" lower="-3.14159265359" upper="3.14159265359" velocity="0.0"/>
  </joint>
  <joint name="roboy_2_0_simplified__shoulder_right_axis_3" type="revolute">
    <parent link="roboy_2_0_simplified__shoulder_right_joint_link_3"/>
    <child link="roboy_2_0_simplified__upper_arm_right"/>
    <origin rpy="0  0  0" xyz="0.00556 -0.01279  0"/>
    <axis xyz="-0.03901  0.99903 -0.02033"/>
    <limit effort="0.0" lower="-3.14159265359" upper="3.14159265359" velocity="0.0"/>
  </joint>
  <joint name="roboy_2_0_simplified__neck_axis_1" type="revolute">
    <parent link="roboy_2_0_simplified__torso"/>
    <child link="roboy_2_0_simplified__neck_link_3"/>
    <origin rpy="0  0  0" xyz="-0.005    0.77095 -0.00567"/>
    <axis xyz="0  1  0"/>
    <limit effort="0.0" lower="-0.523598775598" upper="0.523598775598" velocity="0.0"/>
  </joint>
  <link name="roboy_2_0_simplified__lower_arm_right">
    <inertial>
      <mass value="10.580368393671788"/>
      <origin rpy="0  0  0" xyz="0.00278 -0.00591  0.15052"/>
      <inertia ixx="1.1942606746969529" ixy="0.8221036576164761" ixz="-0.5191382565906923" iyy="1.2172536464994173" iyz="0.5208554455521323" izz="1.6548179592789551"/>
    </inertial>
    <collision name="roboy_2_0_simplified__lower_arm_right_collision">
      <origin rpy="0  0  0" xyz="0.00278 -0.00591  0.15052"/>
      <geometry>
        <mesh filename="package://roboy_models/roboy_2_0_simplified/meshes/CAD/lower_arm_right.stl" scale="0.001 0.001 0.001"/>
      </geometry>
    </collision>
    <visual name="roboy_2_0_simplified__lower_arm_right_visual">
      <origin rpy="0  0  0" xyz="0.00278 -0.00591  0.15052"/>
      <geometry>
        <mesh filename="package://roboy_models/roboy_2_0_simplified/meshes/CAD/lower_arm_right.stl" scale="0.001 0.001 0.001"/>
      </geometry>
    </visual>
  </link>
  <link name="roboy_2_0_simplified__lower_arm_left">
    <inertial>
      <mass value="10.990737035515798"/>
      <origin rpy="0  0  0" xyz="0.00497 -0.00263  0.14591"/>
      <inertia ixx="1.026523457786333" ixy="-0.8603149692392619" ixz="-0.38484889867656885" iyy="1.2028540095957043" iyz="-0.42562772271899835" izz="1.7395620087644814"/>
    </inertial>
    <collision name="roboy_2_0_simplified__lower_arm_left_collision">
      <origin rpy="0  0  0" xyz="0.00497 -0.00263  0.14591"/>
      <geometry>
        <mesh filename="package://roboy_models/roboy_2_0_simplified/meshes/CAD/lower_arm_left.stl" scale="0.001 0.001 0.001"/>
      </geometry>
    </collision>
    <visual name="roboy_2_0_simplified__lower_arm_left_visual">
      <origin rpy="0  0  0" xyz="0.00497 -0.00263  0.14591"/>
      <geometry>
        <mesh filename="package://roboy_models/roboy_2_0_simplified/meshes/CAD/lower_arm_left.stl" scale="0.001 0.001 0.001"/>
      </geometry>
    </visual>
  </link>
  <link name="roboy_2_0_simplified__head">
    <inertial>
      <mass value="2.1986973590671695"/>
      <origin rpy="0  0  0" xyz="-0.03957 -0.66511 -0.00215"/>
      <inertia ixx="1.9457059620139463" ixy="0.004896672663233763" ixz="0.02013403775722169" iyy="0.02506836700566963" iyz="-4.3476390295420435e-05" izz="1.9405524949959967"/>
    </inertial>
    <collision name="roboy_2_0_simplified__head_collision">
      <origin rpy="0  0  0" xyz="-0.03957 -0.66511 -0.00215"/>
      <geometry>
        <mesh filename="package://roboy_models/roboy_2_0_simplified/meshes/CAD/head.stl" scale="0.001 0.001 0.001"/>
      </geometry>
    </collision>
    <visual name="roboy_2_0_simplified__head_visual">
      <origin rpy="0  0  0" xyz="-0.03957 -0.66511 -0.00215"/>
      <geometry>
        <mesh filename="package://roboy_models/roboy_2_0_simplified/meshes/CAD/head.stl" scale="0.001 0.001 0.001"/>
      </geometry>
    </visual>
  </link>
  <link name="roboy_2_0_simplified__upper_arm_left">
    <inertial>
      <mass value="15.849973523722745"/>
      <origin rpy="0  0  0" xyz="-0.09289 -0.37975  0.00598"/>
      <inertia ixx="2.7932409541157655" ixy="-1.9951662197837037" ixz="0.09367699027050268" iyy="1.5136243481328255" iyz="0.06860843725394769" izz="4.2464000004812"/>
    </inertial>
    <collision name="roboy_2_0_simplified__upper_arm_left_collision">
      <origin rpy="0  0  0" xyz="-0.09289 -0.37975  0.00598"/>
      <geometry>
        <mesh filename="package://roboy_models/roboy_2_0_simplified/meshes/CAD/upper_arm_left.stl" scale="0.001 0.001 0.001"/>
      </geometry>
    </collision>
    <visual name="roboy_2_0_simplified__upper_arm_left_visual">
      <origin rpy="0  0  0" xyz="-0.09289 -0.37975  0.00598"/>
      <geometry>
        <mesh filename="package://roboy_models/roboy_2_0_simplified/meshes/CAD/upper_arm_left.stl" scale="0.001 0.001 0.001"/>
      </geometry>
    </visual>
  </link>
  <link name="roboy_2_0_simplified__torso">
    <inertial>
      <mass value="23.855478223833998"/>
      <origin rpy="0  0  0" xyz="-0.07056  0.0603   0.15054"/>
      <inertia ixx="9.23534906404782" ixy="0.07580222424100451" ixz="-0.021153531791058982" iyy="0.48485719897854107" iyz="0.007429851740980164" izz="9.587532578768219"/>
    </inertial>
    <collision name="roboy_2_0_simplified__torso_collision">
      <origin rpy="0  0  0" xyz="-0.07056  0.0603   0.15054"/>
      <geometry>
        <mesh filename="package://roboy_models/roboy_2_0_simplified/meshes/CAD/torso.stl" scale="0.001 0.001 0.001"/>
      </geometry>
    </collision>
    <visual name="roboy_2_0_simplified__torso_visual">
      <origin rpy="0  0  0" xyz="-0.07056  0.0603   0.15054"/>
      <geometry>
        <mesh filename="package://roboy_models/roboy_2_0_simplified/meshes/CAD/torso.stl" scale="0.001 0.001 0.001"/>
      </geometry>
    </visual>
  </link>
  <link name="roboy_2_0_simplified__upper_arm_right">
    <inertial>
      <mass value="14.6468169432556"/>
      <origin rpy="0  0  0" xyz="0.19635 -0.48026 -0.02338"/>
      <inertia ixx="2.7587423979541934" ixy="1.903814448481727" ixz="-0.12859307311816204" iyy="1.3942272925621555" iyz="0.09102955799614545" izz="4.087354909917843"/>
    </inertial>
    <collision name="roboy_2_0_simplified__upper_arm_right_collision">
      <origin rpy="0  0  0" xyz="0.19635 -0.48026 -0.02338"/>
      <geometry>
        <mesh filename="package://roboy_models/roboy_2_0_simplified/meshes/CAD/upper_arm_right.stl" scale="0.001 0.001 0.001"/>
      </geometry>
    </collision>
    <visual name="roboy_2_0_simplified__upper_arm_right_visual">
      <origin rpy="0  0  0" xyz="0.19635 -0.48026 -0.02338"/>
      <geometry>
        <mesh filename="package://roboy_models/roboy_2_0_simplified/meshes/CAD/upper_arm_right.stl" scale="0.001 0.001 0.001"/>
      </geometry>
    </visual>
  </link>
  <link name="roboy_2_0_simplified__shoulder_left_joint_link_2">
    <inertial>
      <mass value="0.011947756900622594"/>
      <origin rpy="0  0  0" xyz="-0.04506 -0.09274  0.01464"/>
      <inertia ixx="0.004224609684716994" ixy="-0.002035696946929016" ixz="9.649574578557653e-05" iyy="0.000984536769222102" iyz="4.6514921924002745e-05" izz="0.005203730711513319"/>
    </inertial>
    <collision name="roboy_2_0_simplified__shoulder_left_joint_link_2_collision">
      <origin rpy="0  0  0" xyz="-0.04506 -0.09274  0.01464"/>
      <geometry>
        <mesh filename="package://roboy_models/roboy_2_0_simplified/meshes/CAD/shoulder_left_joint_link_2.stl" scale="0.001 0.001 0.001"/>
      </geometry>
    </collision>
    <visual name="roboy_2_0_simplified__shoulder_left_joint_link_2_visual">
      <origin rpy="0  0  0" xyz="-0.04506 -0.09274  0.01464"/>
      <geometry>
        <mesh filename="package://roboy_models/roboy_2_0_simplified/meshes/CAD/shoulder_left_joint_link_2.stl" scale="0.001 0.001 0.001"/>
      </geometry>
    </visual>
  </link>
  <link name="roboy_2_0_simplified__shoulder_left_joint_link_3">
    <inertial>
      <mass value="0.017192390951684386"/>
      <origin rpy="0  0  0" xyz="-9.05580000e-01  -8.51890000e-01   2.90000000e-04"/>
      <inertia ixx="0.006042503381130891" ixy="-0.002924149215334832" ixz="0.00013860649265007454" iyy="0.0014197255030573286" iyz="6.711807543954196e-05" izz="0.007455297773422159"/>
    </inertial>
    <collision name="roboy_2_0_simplified__shoulder_left_joint_link_3_collision">
      <origin rpy="0  0  0" xyz="-9.05580000e-01  -8.51890000e-01   2.90000000e-04"/>
      <geometry>
        <mesh filename="package://roboy_models/roboy_2_0_simplified/meshes/CAD/shoulder_left_joint_link_3.stl" scale="0.001 0.001 0.001"/>
      </geometry>
    </collision>
    <visual name="roboy_2_0_simplified__shoulder_left_joint_link_3_visual">
      <origin rpy="0  0  0" xyz="-9.05580000e-01  -8.51890000e-01   2.90000000e-04"/>
      <geometry>
        <mesh filename="package://roboy_models/roboy_2_0_simplified/meshes/CAD/shoulder_left_joint_link_3.stl" scale="0.001 0.001 0.001"/>
      </geometry>
    </visual>
  </link>
  <link name="roboy_2_0_simplified__shoulder_right_joint_link_2">
    <inertial>
      <mass value="0.011947830827153366"/>
      <origin rpy="0  0  0" xyz="0.04641 -0.09406  0.00027"/>
      <inertia ixx="0.004329658029906806" ixy="0.0021233011332852537" ixz="-0.00011735981113008263" iyy="0.0010461058421985933" iyz="5.759055900394724e-05" izz="0.00536839124942644"/>
    </inertial>
    <collision name="roboy_2_0_simplified__shoulder_right_joint_link_2_collision">
      <origin rpy="0  0  0" xyz="0.04641 -0.09406  0.00027"/>
      <geometry>
        <mesh filename="package://roboy_models/roboy_2_0_simplified/meshes/CAD/shoulder_right_joint_link_2.stl" scale="0.001 0.001 0.001"/>
      </geometry>
    </collision>
    <visual name="roboy_2_0_simplified__shoulder_right_joint_link_2_visual">
      <origin rpy="0  0  0" xyz="0.04641 -0.09406  0.00027"/>
      <geometry>
        <mesh filename="package://roboy_models/roboy_2_0_simplified/meshes/CAD/shoulder_right_joint_link_2.stl" scale="0.001 0.001 0.001"/>
      </geometry>
    </visual>
  </link>
  <link name="roboy_2_0_simplified__shoulder_right_joint_link_3">
    <inertial>
      <mass value="0.01719247645061589"/>
      <origin rpy="0  0  0" xyz="5.19000000e-03  -1.15156000e+00  -2.30000000e-04"/>
      <inertia ixx="0.0061925034583181415" ixy="0.0030537597920120675" ixz="-0.0001691677356525295" iyy="0.001512392309618351" iyz="8.349437351838352e-05" izz="0.0076950767729288974"/>
    </inertial>
    <collision name="roboy_2_0_simplified__shoulder_right_joint_link_3_collision">
      <origin rpy="0  0  0" xyz="5.19000000e-03  -1.15156000e+00  -2.30000000e-04"/>
      <geometry>
        <mesh filename="package://roboy_models/roboy_2_0_simplified/meshes/CAD/shoulder_right_joint_link_3.stl" scale="0.001 0.001 0.001"/>
      </geometry>
    </collision>
    <visual name="roboy_2_0_simplified__shoulder_right_joint_link_3_visual">
      <origin rpy="0  0  0" xyz="5.19000000e-03  -1.15156000e+00  -2.30000000e-04"/>
      <geometry>
        <mesh filename="package://roboy_models/roboy_2_0_simplified/meshes/CAD/shoulder_right_joint_link_3.stl" scale="0.001 0.001 0.001"/>
      </geometry>
    </visual>
  </link>
  <link name="roboy_2_0_simplified__neck_link_3">
    <inertial>
      <mass value="0.017192417326343357"/>
      <origin rpy="0  0  0" xyz="-0.1027  -0.92693  0"/>
      <inertia ixx="0.010466481866131364" ixy="6.613662178595011e-05" ixz="7.607999592631023e-05" iyy="1.5324354757560118e-06" iyz="-4.808145207666988e-07" izz="0.01046633989777193"/>
    </inertial>
    <collision name="roboy_2_0_simplified__neck_link_3_collision">
      <origin rpy="0  0  0" xyz="-0.1027  -0.92693  0"/>
      <geometry>
        <mesh filename="package://roboy_models/roboy_2_0_simplified/meshes/CAD/neck_link_3.stl" scale="0.001 0.001 0.001"/>
      </geometry>
    </collision>
    <visual name="roboy_2_0_simplified__neck_link_3_visual">
      <origin rpy="0  0  0" xyz="-0.1027  -0.92693  0"/>
      <geometry>
        <mesh filename="package://roboy_models/roboy_2_0_simplified/meshes/CAD/neck_link_3.stl" scale="0.001 0.001 0.001"/>
      </geometry>
    </visual>
  </link>
  <link name="roboy_2_0_simplified__neck_link_2">
    <inertial>
      <mass value="0.011947622039161101"/>
      <origin rpy="0  0  0" xyz="0.01004 -0.1221   0.00868"/>
      <inertia ixx="0.00730693410195324" ixy="3.731904905578473e-05" ixz="5.298587603583067e-05" iyy="1.2142544508732947e-06" iyz="-2.706890477535063e-07" izz="0.0073063714624777435"/>
    </inertial>
    <collision name="roboy_2_0_simplified__neck_link_2_collision">
      <origin rpy="0  0  0" xyz="0.01004 -0.1221   0.00868"/>
      <geometry>
        <mesh filename="package://roboy_models/roboy_2_0_simplified/meshes/CAD/neck_link_2.stl" scale="0.001 0.001 0.001"/>
      </geometry>
    </collision>
    <visual name="roboy_2_0_simplified__neck_link_2_visual">
      <origin rpy="0  0  0" xyz="0.01004 -0.1221   0.00868"/>
      <geometry>
        <mesh filename="package://roboy_models/roboy_2_0_simplified/meshes/CAD/neck_link_2.stl" scale="0.001 0.001 0.001"/>
      </geometry>
    </visual>
  </link>
  <link name="roboy_2_0_simplified__hand_right">
    <inertial>
      <mass value="1.1965869407682346"/>
      <origin rpy="0  0  0" xyz="0.07808 -0.28668 -0.28757"/>
      <inertia ixx="0.5108879426503683" ixy="0.1435136266663526" ixz="-0.2513595986208623" iyy="0.3094433395199077" iyz="0.13340816706646594" izz="0.3564991114571509"/>
    </inertial>
    <collision name="roboy_2_0_simplified__hand_right_collision">
      <origin rpy="0  0  0" xyz="0.07808 -0.28668 -0.28757"/>
      <geometry>
        <mesh filename="package://roboy_models/roboy_2_0_simplified/meshes/CAD/hand_right.stl" scale="0.001 0.001 0.001"/>
      </geometry>
    </collision>
    <visual name="roboy_2_0_simplified__hand_right_visual">
      <origin rpy="0  0  0" xyz="0.07808 -0.28668 -0.28757"/>
      <geometry>
        <mesh filename="package://roboy_models/roboy_2_0_simplified/meshes/CAD/hand_right.stl" scale="0.001 0.001 0.001"/>
      </geometry>
    </visual>
  </link>
  <link name="roboy_2_0_simplified__hand_left">
    <inertial>
      <mass value="1.1922293050096704"/>
      <origin rpy="0  0  0" xyz="-0.44931 -0.30632 -0.52747"/>
      <inertia ixx="0.456203629106714" ixy="-0.15704822159383663" ixz="-0.22334336992947879" iyy="0.29606092398303524" iyz="-0.13917785073788497" izz="0.359429389770392"/>
    </inertial>
    <collision name="roboy_2_0_simplified__hand_left_collision">
      <origin rpy="0  0  0" xyz="-0.44931 -0.30632 -0.52747"/>
      <geometry>
        <mesh filename="package://roboy_models/roboy_2_0_simplified/meshes/CAD/hand_left.stl" scale="0.001 0.001 0.001"/>
      </geometry>
    </collision>
    <visual name="roboy_2_0_simplified__hand_left_visual">
      <origin rpy="0  0  0" xyz="-0.44931 -0.30632 -0.52747"/>
      <geometry>
        <mesh filename="package://roboy_models/roboy_2_0_simplified/meshes/CAD/hand_left.stl" scale="0.001 0.001 0.001"/>
      </geometry>
    </visual>
  </link>
</robot>
