<?xml version="1.0" ?>
<sdf version="1.6">
	<model name="roboy_2_0_simplified">
        <!--<joint name="fixed_to_world" type="revolute">-->
            <!--<parent>torso</parent>-->
            <!--<child>world</child>-->
            <!--<pose frame="">0 0 0 0 0 1</pose>-->
            <!--<axis>-->
                <!--<xyz>0 0 1</xyz>-->
                <!--<limit>-->
                    <!--<lower>-0.1</lower>-->
                    <!--<upper>0.1</upper>-->
                <!--</limit>-->
                <!--<use_parent_model_frame>0</use_parent_model_frame>-->
            <!--</axis>-->
        <!--</joint>-->
		<link name="lower_arm_right">
			<pose frame="">-0.29218836999465536 0.2743736679995431 0.06363338040081598 0.0 -0.0 0.0</pose>
			<inertial>
				<pose frame="">0.0 0.0 0.0 0 0 0</pose>
				<mass>0.1</mass>
				<inertia>
					<ixx>0.01</ixx>
					<ixy>0.01</ixy>
					<ixz>0.01</ixz>
					<iyy>0.01</iyy>
					<iyz>0.01</iyz>
					<izz>0.01</izz>
				</inertia>
			</inertial>
			<collision name="lower_arm_right_collision">
				<geometry>
					<sphere>
						<radius>0.03</radius>
					</sphere>
				</geometry>
			</collision>
			<visual name="lower_arm_right_visual">
				<geometry>
					<mesh>
						<uri>model://roboy_2_0_simplified/meshes/CAD/lower_arm_right.stl</uri>
						<scale>0.001 0.001 0.001</scale>
					</mesh>
				</geometry>
			</visual>
		</link>
		<link name="lower_arm_left">
			<pose frame="">0.2941390263982024 0.26622759368394755 0.026799075858034458 0.0 -0.0 0.0</pose>
			<inertial>
				<pose frame="">0.0 0.0 0.0 0 0 0</pose>
                <mass>0.1</mass>
				<inertia>
                    <ixx>0.01</ixx>
                    <ixy>0.01</ixy>
                    <ixz>0.01</ixz>
                    <iyy>0.01</iyy>
                    <iyz>0.01</iyz>
                    <izz>0.01</izz>
				</inertia>
			</inertial>
			<collision name="lower_arm_left_collision">
				<geometry>
                    <sphere>
                        <radius>0.03</radius>
                    </sphere>
				</geometry>
			</collision>
			<visual name="lower_arm_left_visual">
				<geometry>
					<mesh>
						<uri>model://roboy_2_0_simplified/meshes/CAD/lower_arm_left.stl</uri>
						<scale>0.001 0.001 0.001</scale>
					</mesh>
				</geometry>
			</visual>
		</link>
		<link name="head">
			<pose frame="">-0.0030666329436431824 0.8266497028349796 0.006506358437061879 0.0 -0.0 0.0</pose>
			<inertial>
				<pose frame="">0.0 0.0 0.0 0 0 0</pose>
                <mass>0.1</mass>
				<inertia>
                    <ixx>0.01</ixx>
                    <ixy>0.01</ixy>
                    <ixz>0.01</ixz>
                    <iyy>0.01</iyy>
                    <iyz>0.01</iyz>
                    <izz>0.01</izz>
				</inertia>
			</inertial>
			<collision name="head_collision">
				<geometry>
                    <sphere>
                        <radius>0.03</radius>
                    </sphere>
				</geometry>
			</collision>
			<visual name="head_visual">
				<geometry>
					<mesh>
						<uri>model://roboy_2_0_simplified/meshes/CAD/head.stl</uri>
						<scale>0.001 0.001 0.001</scale>
					</mesh>
				</geometry>
			</visual>
		</link>
		<link name="upper_arm_left">
			<pose frame="">0.28798862680022014 0.5549254668876651 -0.013618040340742264 0.0 -0.0 0.0</pose>
			<inertial>
				<pose frame="">0.0 0.0 0.0 0 0 0</pose>
                <mass>0.1</mass>
				<inertia>
                    <ixx>0.01</ixx>
                    <ixy>0.01</ixy>
                    <ixz>0.01</ixz>
                    <iyy>0.01</iyy>
                    <iyz>0.01</iyz>
                    <izz>0.01</izz>
				</inertia>
			</inertial>
			<collision name="upper_arm_left_collision">
				<geometry>
                    <sphere>
                        <radius>0.03</radius>
                    </sphere>
				</geometry>
			</collision>
			<visual name="upper_arm_left_visual">
				<geometry>
					<mesh>
						<uri>model://roboy_2_0_simplified/meshes/CAD/upper_arm_left.stl</uri>
						<scale>0.001 0.001 0.001</scale>
					</mesh>
				</geometry>
			</visual>
		</link>
		<link name="upper_arm_right">
			<pose frame="">-0.29468160568595847 0.5621903189085681 0.01717623203608873 0.0 -0.0 0.0</pose>
			<inertial>
				<pose frame="">0.0 0.0 0.0 0 0 0</pose>
                <mass>0.1</mass>
				<inertia>
                    <ixx>0.01</ixx>
                    <ixy>0.01</ixy>
                    <ixz>0.01</ixz>
                    <iyy>0.01</iyy>
                    <iyz>0.01</iyz>
                    <izz>0.01</izz>
				</inertia>
			</inertial>
			<collision name="upper_arm_right_collision">
				<geometry>
                    <sphere>
                        <radius>0.03</radius>
                    </sphere>
				</geometry>
			</collision>
			<visual name="upper_arm_right_visual">
				<geometry>
					<mesh>
						<uri>model://roboy_2_0_simplified/meshes/CAD/upper_arm_right.stl</uri>
						<scale>0.001 0.001 0.001</scale>
					</mesh>
				</geometry>
			</visual>
		</link>
		<link name="torso">
			<pose frame="">-0.004999999999998519 -0.0035000000000000144 -0.00567488579074407 0.0 -0.0 0.0</pose>
			<inertial>
				<pose frame="">0.0 0.0 0.0 0 0 0</pose>
                <mass>100</mass>
				<inertia>
                    <ixx>1</ixx>
                    <ixy>0</ixy>
                    <ixz>0</ixz>
                    <iyy>1</iyy>
                    <iyz>0</iyz>
                    <izz>1</izz>
				</inertia>
			</inertial>
			<collision name="torso_collision">
				<geometry>
                    <mesh>
                        <uri>model://roboy_2_0_simplified/meshes/CAD/torso.stl</uri>
                        <scale>0.001 0.001 0.001</scale>
                    </mesh>
				</geometry>
			</collision>
			<visual name="torso_visual">
				<geometry>
					<mesh>
						<uri>model://roboy_2_0_simplified/meshes/CAD/torso.stl</uri>
						<scale>0.001 0.001 0.001</scale>
					</mesh>
				</geometry>
			</visual>
		</link>
		<link name="shoulder_left_joint_link_2">
			<pose frame="">0.28713512179275735 0.5894179501767453 -0.013607855949266324 0.0 -0.0 0.0</pose>
			<inertial>
				<pose frame="">0.0 0.0 0.0 0 0 0</pose>
				<mass>0.011947756900622582</mass>
				<inertia>
                    <ixx>0.01</ixx>
                    <ixy>0.01</ixy>
                    <ixz>0.01</ixz>
                    <iyy>0.01</iyy>
                    <iyz>0.01</iyz>
                    <izz>0.01</izz>
				</inertia>
			</inertial>
			<collision name="shoulder_left_joint_link_2_collision">
				<geometry>
                    <sphere>
                        <radius>0.03</radius>
                    </sphere>
				</geometry>
			</collision>
			<visual name="shoulder_left_joint_link_2_visual">
				<geometry>
					<mesh>
						<uri>model://roboy_2_0_simplified/meshes/CAD/shoulder_left_joint_link_2.stl</uri>
						<scale>0.001 0.001 0.001</scale>
					</mesh>
				</geometry>
			</visual>
		</link>
		<link name="shoulder_left_joint_link_3">
			<pose frame="">0.28713512179275713 0.5894179501767447 -0.013607855949266296 0.0 -0.0 0.0</pose>
			<inertial>
				<pose frame="">0.0 0.0 0.0 0 0 0</pose>
				<mass>0.017192390951684323</mass>
				<inertia>
                    <ixx>0.01</ixx>
                    <ixy>0.01</ixy>
                    <ixz>0.01</ixz>
                    <iyy>0.01</iyy>
                    <iyz>0.01</iyz>
                    <izz>0.01</izz>
				</inertia>
			</inertial>
			<collision name="shoulder_left_joint_link_3_collision">
				<geometry>
                    <sphere>
                        <radius>0.03</radius>
                    </sphere>
				</geometry>
			</collision>
			<visual name="shoulder_left_joint_link_3_visual">
				<geometry>
					<mesh>
						<uri>model://roboy_2_0_simplified/meshes/CAD/shoulder_left_joint_link_3.stl</uri>
						<scale>0.001 0.001 0.001</scale>
					</mesh>
				</geometry>
			</visual>
		</link>
		<link name="shoulder_right_joint_link_2">
			<pose frame="">-0.29602805125144716 0.5966598819209421 0.016471754895170877 0.0 -0.0 0.0</pose>
			<inertial>
				<pose frame="">0.0 0.0 0.0 0 0 0</pose>
				<mass>0.011947830827153384</mass>
				<inertia>
                    <ixx>0.01</ixx>
                    <ixy>0.01</ixy>
                    <ixz>0.01</ixz>
                    <iyy>0.01</iyy>
                    <iyz>0.01</iyz>
                    <izz>0.01</izz>
				</inertia>
			</inertial>
			<collision name="shoulder_right_joint_link_2_collision">
				<geometry>
                    <sphere>
                        <radius>0.03</radius>
                    </sphere>
				</geometry>
			</collision>
			<visual name="shoulder_right_joint_link_2_visual">
				<geometry>
					<mesh>
						<uri>model://roboy_2_0_simplified/meshes/CAD/shoulder_right_joint_link_2.stl</uri>
						<scale>0.001 0.001 0.001</scale>
					</mesh>
				</geometry>
			</visual>
		</link>
		<link name="shoulder_right_joint_link_3">
			<pose frame="">-0.29602805125144693 0.596659881920942 0.016471754895171276 0.0 -0.0 0.0</pose>
			<inertial>
				<pose frame="">0.0 0.0 0.0 0 0 0</pose>
				<mass>0.01719247645061585</mass>
				<inertia>
                    <ixx>0.01</ixx>
                    <ixy>0.01</ixy>
                    <ixz>0.01</ixz>
                    <iyy>0.01</iyy>
                    <iyz>0.01</iyz>
                    <izz>0.01</izz>
				</inertia>
			</inertial>
			<collision name="shoulder_right_joint_link_3_collision">
				<geometry>
                    <sphere>
                        <radius>0.03</radius>
                    </sphere>
				</geometry>
			</collision>
			<visual name="shoulder_right_joint_link_3_visual">
				<geometry>
					<mesh>
						<uri>model://roboy_2_0_simplified/meshes/CAD/shoulder_right_joint_link_3.stl</uri>
						<scale>0.001 0.001 0.001</scale>
					</mesh>
				</geometry>
			</visual>
		</link>
		<link name="neck_link_3">
			<pose frame="">-0.005000000000001102 0.7769579775594229 -0.0056718428256846655 0.0 -0.0 0.0</pose>
			<inertial>
				<pose frame="">0.0 0.0 0.0 0 0 0</pose>
				<mass>0.017192417326343308</mass>
				<inertia>
                    <ixx>0.01</ixx>
                    <ixy>0.01</ixy>
                    <ixz>0.01</ixz>
                    <iyy>0.01</iyy>
                    <iyz>0.01</iyz>
                    <izz>0.01</izz>
				</inertia>
			</inertial>
			<collision name="neck_link_3_collision">
				<geometry>
                    <sphere>
                        <radius>0.03</radius>
                    </sphere>
				</geometry>
			</collision>
			<visual name="neck_link_3_visual">
				<geometry>
					<mesh>
						<uri>model://roboy_2_0_simplified/meshes/CAD/neck_link_3.stl</uri>
						<scale>0.001 0.001 0.001</scale>
					</mesh>
				</geometry>
			</visual>
		</link>
		<link name="neck_link_2">
			<pose frame="">-0.005000000000001102 0.7769579775594229 -0.0056718428256846655 0.0 -0.0 0.0</pose>
			<inertial>
				<pose frame="">0.0 0.0 0.0 0 0 0</pose>
				<mass>0.011947622039161103</mass>
				<inertia>
                    <ixx>0.01</ixx>
                    <ixy>0.01</ixy>
                    <ixz>0.01</ixz>
                    <iyy>0.01</iyy>
                    <iyz>0.01</iyz>
                    <izz>0.01</izz>
				</inertia>
			</inertial>
			<collision name="neck_link_2_collision">
				<geometry>
                    <sphere>
                        <radius>0.03</radius>
                    </sphere>
				</geometry>
			</collision>
			<visual name="neck_link_2_visual">
				<geometry>
					<mesh>
						<uri>model://roboy_2_0_simplified/meshes/CAD/neck_link_2.stl</uri>
						<scale>0.001 0.001 0.001</scale>
					</mesh>
				</geometry>
			</visual>
		</link>
		<link name="hand_right">
			<pose frame="">-0.2520222680642473 0.5248675719297508 0.45128232319496375 0.0 -0.0 0.0</pose>
			<inertial>
				<pose frame="">0.0 0.0 0.0 0 0 0</pose>
                <mass>0.1</mass>
				<inertia>
                    <ixx>0.01</ixx>
                    <ixy>0.01</ixy>
                    <ixz>0.01</ixz>
                    <iyy>0.01</iyy>
                    <iyz>0.01</iyz>
                    <izz>0.01</izz>
				</inertia>
			</inertial>
			<collision name="hand_right_collision">
				<geometry>
                    <sphere>
                        <radius>0.03</radius>
                    </sphere>
				</geometry>
			</collision>
			<visual name="hand_right_visual">
				<geometry>
					<mesh>
						<uri>model://roboy_2_0_simplified/meshes/CAD/hand_right.stl</uri>
						<scale>0.001 0.001 0.001</scale>
					</mesh>
				</geometry>
			</visual>
		</link>
		<link name="hand_left">
			<pose frame="">0.287078998659723 0.5078150620301657 0.417830876996003 0.0 -0.0 0.0</pose>
			<inertial>
				<pose frame="">0.0 0.0 0.0 0 0 0</pose>
                <mass>0.1</mass>
				<inertia>
                    <ixx>0.01</ixx>
                    <ixy>0.01</ixy>
                    <ixz>0.01</ixz>
                    <iyy>0.01</iyy>
                    <iyz>0.01</iyz>
                    <izz>0.01</izz>
				</inertia>
			</inertial>
			<collision name="hand_left_collision">
				<geometry>
                    <sphere>
                        <radius>0.03</radius>
                    </sphere>
				</geometry>
			</collision>
			<visual name="hand_left_visual">
				<geometry>
					<mesh>
						<uri>model://roboy_2_0_simplified/meshes/CAD/hand_left.stl</uri>
						<scale>0.001 0.001 0.001</scale>
					</mesh>
				</geometry>
			</visual>
		</link>
		<link name="key_F">
			<pose frame="">-0.06499999999999939 0.2815000000000004 0.5143251142092558 0.0 -0.0 0.0</pose>
			<inertial>
				<pose frame="">0.0 0.0 0.0 0 0 0</pose>
				<mass>0.8242499999999997</mass>
				<inertia>
					<ixx>0.229782676203744</ixx>
					<ixy>0.009308529999999616</ixy>
					<ixz>-0.10340034138425735</ixz>
					<iyy>0.16556419101624362</iyy>
					<iyz>0.014649399015478546</iyz>
					<izz>0.06719952268750011</izz>
				</inertia>
			</inertial>
			<collision name="key_F_collision">
				<geometry>
					<mesh>
						<uri>model://roboy_2_0_simplified/meshes/CAD/key_F.stl</uri>
						<scale>0.001 0.001 0.001</scale>
					</mesh>
				</geometry>
			</collision>
			<visual name="key_F_visual">
				<geometry>
					<mesh>
						<uri>model://roboy_2_0_simplified/meshes/CAD/key_F.stl</uri>
						<scale>0.001 0.001 0.001</scale>
					</mesh>
				</geometry>
			</visual>
		</link>
		<link name="key_G">
			<pose frame="">-0.1349999999999994 0.2815000000000004 0.5043251142092557 0.0 -0.0 0.0</pose>
			<inertial>
				<pose frame="">0.0 0.0 0.0 0 0 0</pose>
				<mass>0.706499999999999</mass>
				<inertia>
					<ixx>0.1966504296032091</ixx>
					<ixy>0.02194153499999971</ixy>
					<ixz>-0.08862886404364916</ixz>
					<iyy>0.1490242637282087</iyy>
					<iyz>0.03453072625077184</iyz>
					<izz>0.06501784087499991</izz>
				</inertia>
			</inertial>
			<collision name="key_G_collision">
				<geometry>
					<mesh>
						<uri>model://roboy_2_0_simplified/meshes/CAD/key_G.stl</uri>
						<scale>0.001 0.001 0.001</scale>
					</mesh>
				</geometry>
			</collision>
			<visual name="key_G_visual">
				<geometry>
					<mesh>
						<uri>model://roboy_2_0_simplified/meshes/CAD/key_G.stl</uri>
						<scale>0.001 0.001 0.001</scale>
					</mesh>
				</geometry>
			</visual>
		</link>
		<link name="key_C">
			<pose frame="">0.1450000000000006 0.2815000000000004 0.5443251142092558 0.0 -0.0 0.0</pose>
			<inertial>
				<pose frame="">0.0 0.0 0.0 0 0 0</pose>
				<mass>1.177499999999998</mass>
				<inertia>
					<ixx>0.3302627160053484</ixx>
					<ixy>-0.05651607500000076</ixy>
					<ixz>-0.1477147734060819</ixz>
					<iyy>0.2706677728803488</iyy>
					<iyz>-0.08894277973683888</iyz>
					<izz>0.12814506812500112</izz>
				</inertia>
			</inertial>
			<collision name="key_C_collision">
				<geometry>
					<mesh>
						<uri>model://roboy_2_0_simplified/meshes/CAD/key_C.stl</uri>
						<scale>0.001 0.001 0.001</scale>
					</mesh>
				</geometry>
			</collision>
			<visual name="key_C_visual">
				<geometry>
					<mesh>
						<uri>model://roboy_2_0_simplified/meshes/CAD/key_C.stl</uri>
						<scale>0.001 0.001 0.001</scale>
					</mesh>
				</geometry>
			</visual>
		</link>
		<link name="key_H">
			<pose frame="">-0.2049999999999994 0.2815000000000004 0.4943251142092558 0.0 -0.0 0.0</pose>
			<inertial>
				<pose frame="">0.0 0.0 0.0 0 0 0</pose>
				<mass>0.5887499999999979</mass>
				<inertia>
					<ixx>0.16365948300267433</ixx>
					<ixy>0.029920274999999795</ixy>
					<ixz>-0.07385738670304097</ixz>
					<iyy>0.13592263644017383</iyy>
					<iyz>0.047087353978325544</iyz>
					<izz>0.06613315906249982</izz>
				</inertia>
			</inertial>
			<collision name="key_H_collision">
				<geometry>
					<mesh>
						<uri>model://roboy_2_0_simplified/meshes/CAD/key_H.stl</uri>
						<scale>0.001 0.001 0.001</scale>
					</mesh>
				</geometry>
			</collision>
			<visual name="key_H_visual">
				<geometry>
					<mesh>
						<uri>model://roboy_2_0_simplified/meshes/CAD/key_H.stl</uri>
						<scale>0.001 0.001 0.001</scale>
					</mesh>
				</geometry>
			</visual>
		</link>
		<link name="key_E">
			<pose frame="">0.005000000000000604 0.2815000000000004 0.5243251142092558 0.0 -0.0 0.0</pose>
			<inertial>
				<pose frame="">0.0 0.0 0.0 0 0 0</pose>
				<mass>0.9420000000000001</mass>
				<inertia>
					<ixx>0.2630797728042788</ixx>
					<ixy>-0.007978740000000494</ixy>
					<ixz>-0.11817181872486557</ixz>
					<iyy>0.18902781830427867</iyy>
					<iyz>-0.01255662772755434</iyz>
					<izz>0.07614005450000037</izz>
				</inertia>
			</inertial>
			<collision name="key_E_collision">
				<geometry>
					<mesh>
						<uri>model://roboy_2_0_simplified/meshes/CAD/key_E.stl</uri>
						<scale>0.001 0.001 0.001</scale>
					</mesh>
				</geometry>
			</collision>
			<visual name="key_E_visual">
				<geometry>
					<mesh>
						<uri>model://roboy_2_0_simplified/meshes/CAD/key_E.stl</uri>
						<scale>0.001 0.001 0.001</scale>
					</mesh>
				</geometry>
			</visual>
		</link>
		<link name="key_D">
			<pose frame="">0.07500000000000061 0.2815000000000004 0.5343251142092558 0.0 -0.0 0.0</pose>
			<inertial>
				<pose frame="">0.0 0.0 0.0 0 0 0</pose>
				<mass>1.0597499999999997</mass>
				<inertia>
					<ixx>0.2965652694048136</ixx>
					<ixy>-0.02992027500000062</ixy>
					<ixz>-0.13294329606547373</ixz>
					<iyy>0.22290054559231373</iyy>
					<iyz>-0.047087353978326814</iyz>
					<izz>0.0953012863125007</izz>
				</inertia>
			</inertial>
			<collision name="key_D_collision">
				<geometry>
					<mesh>
						<uri>model://roboy_2_0_simplified/meshes/CAD/key_D.stl</uri>
						<scale>0.001 0.001 0.001</scale>
					</mesh>
				</geometry>
			</collision>
			<visual name="key_D_visual">
				<geometry>
					<mesh>
						<uri>model://roboy_2_0_simplified/meshes/CAD/key_D.stl</uri>
						<scale>0.001 0.001 0.001</scale>
					</mesh>
				</geometry>
			</visual>
		</link>
		<joint name="shoulder_left_axis_1" type="revolute">
			<parent>torso</parent>
			<child>shoulder_left_joint_link_2</child>
			<pose frame="">0.00019951945882407785 0.00490743658684032 -0.0047233517011995565 0 0 0</pose>
			<axis>
				<xyz>0.051010494316667994 0.02231024242210457 0.9984488883025681</xyz>
				<limit>
					<lower>-3.141592653589793</lower>
					<upper>3.141592653589793</upper>
				</limit>
				<use_parent_model_frame>0</use_parent_model_frame>
			</axis>
		</joint>
		<joint name="shoulder_left_axis_2" type="revolute">
			<parent>shoulder_left_joint_link_2</parent>
			<child>shoulder_left_joint_link_3</child>
			<pose frame="">0.005431255365339957 0.00513551882804812 -0.0002853869619396554 0 0 0</pose>
			<axis>
				<xyz>-0.9983662720150784 -0.02463124250686317 0.051556656168533395</xyz>
				<limit>
					<lower>-3.141592653589793</lower>
					<upper>3.141592653589793</upper>
				</limit>
				<use_parent_model_frame>0</use_parent_model_frame>
			</axis>
		</joint>
		<joint name="neck_axis_2" type="revolute">
			<parent>neck_link_3</parent>
			<child>neck_link_2</child>
			<pose frame="">-0.008063589978581573 0.005003042965059308 2.2204460492503132e-17 0 0 0</pose>
			<axis>
				<xyz>-1.0 -3.432848736779223e-15 6.123233995736762e-17</xyz>
				<limit>
					<lower>-0.5235987755982988</lower>
					<upper>0.5235987755982988</upper>
				</limit>
				<use_parent_model_frame>0</use_parent_model_frame>
			</axis>
		</joint>
		<joint name="neck_axis_3" type="revolute">
			<parent>neck_link_2</parent>
			<child>head</child>
			<pose frame="">3.0429650605307003e-06 -0.047353730897741995 -0.0022321045305084674 0 0 0</pose>
			<axis>
				<xyz>1.4220056966830026e-15 -0.2588190451025207 0.9659258262890682</xyz>
				<limit>
					<lower>-0.5235987755982988</lower>
					<upper>0.5235987755982988</upper>
				</limit>
				<use_parent_model_frame>0</use_parent_model_frame>
			</axis>
		</joint>
		<joint name="wrist_right" type="revolute">
			<parent>lower_arm_right</parent>
			<child>hand_right</child>
			<pose frame="">-0.0167897577310249 -0.2453824657614056 -0.15889706907128967 0 0 0</pose>
			<axis>
				<xyz>0.10163627912775278 0.022223644212182994 0.9945733640124266</xyz>
				<limit>
					<lower>-1.5707963267948966</lower>
					<upper>1.5707963267948966</upper>
				</limit>
				<use_parent_model_frame>0</use_parent_model_frame>
			</axis>
		</joint>
		<joint name="wrist_left" type="revolute">
			<parent>lower_arm_left</parent>
			<child>hand_left</child>
			<pose frame="">0.007242263387563313 -0.24164862319449779 -0.16521568193271033 0 0 0</pose>
			<axis>
				<xyz>-0.02384168391198873 -0.000607586479966071 0.9997155620209742</xyz>
				<limit>
					<lower>-1.5707963267948966</lower>
					<upper>1.5707963267948966</upper>
				</limit>
				<use_parent_model_frame>0</use_parent_model_frame>
			</axis>
		</joint>
		<joint name="shoulder_right_axis_1" type="revolute">
			<parent>torso</parent>
			<child>shoulder_right_joint_link_2</child>
			<pose frame="">-5.71962226064926e-06 0.005103328716584556 0.004850515846064427 0 0 0</pose>
			<axis>
				<xyz>-0.05101049431666773 -0.022310242422105237 -0.9984488883025684</xyz>
				<limit>
					<lower>-3.141592653589793</lower>
					<upper>3.141592653589793</upper>
				</limit>
				<use_parent_model_frame>0</use_parent_model_frame>
			</axis>
		</joint>
		<joint name="shoulder_right_axis_2" type="revolute">
			<parent>shoulder_right_joint_link_2</parent>
			<child>shoulder_right_joint_link_3</child>
			<pose frame="">-0.0052482339115812945 0.004803137171476877 0.00016080527838489457 0 0 0</pose>
			<axis>
				<xyz>0.997935574407065 0.03792191184355857 -0.0518316306416172</xyz>
				<limit>
					<lower>-3.141592653589793</lower>
					<upper>3.141592653589793</upper>
				</limit>
				<use_parent_model_frame>0</use_parent_model_frame>
			</axis>
		</joint>
		<!--<plugin filename="libmoveit_plugin.so" name="moveit_plugin"/>-->
		<joint name="key_H" type="fixed">
			<parent>torso</parent>
			<child>key_H</child>
			<pose frame="">0.20000000000000076 -0.23500000000000035 -0.49999999999999994 0 0 0</pose>
		</joint>
		<joint name="key_G" type="fixed">
			<parent>torso</parent>
			<child>key_G</child>
			<pose frame="">0.13000000000000075 -0.23500000000000043 -0.5099999999999999 0 0 0</pose>
		</joint>
		<joint name="key_F" type="fixed">
			<parent>torso</parent>
			<child>key_F</child>
			<pose frame="">0.06000000000000074 -0.23500000000000035 -0.5199999999999999 0 0 0</pose>
		</joint>
		<joint name="key_E" type="fixed">
			<parent>torso</parent>
			<child>key_E</child>
			<pose frame="">-0.009999999999999261 -0.23500000000000035 -0.5299999999999999 0 0 0</pose>
		</joint>
		<joint name="key_D" type="fixed">
			<parent>torso</parent>
			<child>key_D</child>
			<pose frame="">-0.07999999999999927 -0.23500000000000035 -0.5399999999999999 0 0 0</pose>
		</joint>
		<joint name="key_C" type="fixed">
			<parent>torso</parent>
			<child>key_C</child>
			<pose frame="">-0.14999999999999925 -0.23500000000000035 -0.5499999999999998 0 0 0</pose>
		</joint>
		<joint name="elbow_right" type="revolute">
			<parent>upper_arm_right</parent>
			<child>lower_arm_right</child>
			<pose frame="">0.014000229666721467 0.004169619750468527 -0.037217810825038174 0 0 0</pose>
			<axis>
				<xyz>0.9948216256018391 -0.002270485932608902 -0.10161091540068079</xyz>
				<limit>
					<lower>-0.0</lower>
					<upper>1.5707963267948966</upper>
				</limit>
				<use_parent_model_frame>0</use_parent_model_frame>
			</axis>
		</joint>
		<joint name="elbow_left" type="revolute">
			<parent>upper_arm_left</parent>
			<child>lower_arm_left</child>
			<pose frame="">-0.016846814765604387 0.004596451889486168 -0.035485421788837894 0 0 0</pose>
			<axis>
				<xyz>0.9996958404329833 0.024649269359735267 -0.0008000881366474141</xyz>
				<limit>
					<lower>-0.0</lower>
					<upper>1.5707963267948966</upper>
				</limit>
				<use_parent_model_frame>0</use_parent_model_frame>
			</axis>
		</joint>
		<joint name="shoulder_right_axis_3" type="revolute">
			<parent>shoulder_right_joint_link_3</parent>
			<child>upper_arm_right</child>
			<pose frame="">-0.0010341710977828811 0.026474270092771805 -0.0005417771267103211 0 0 0</pose>
			<axis>
				<xyz>-0.039019466967256645 0.9990316219645872 -0.020329769118090937</xyz>
				<limit>
					<lower>-3.141592653589793</lower>
					<upper>3.141592653589793</upper>
				</limit>
				<use_parent_model_frame>0</use_parent_model_frame>
			</axis>
		</joint>
		<joint name="shoulder_left_axis_3" type="revolute">
			<parent>shoulder_left_joint_link_3</parent>
			<child>upper_arm_left</child>
			<pose frame="">-0.000653199659423791 0.026491947283847708 7.70160822393784e-06 0 0 0</pose>
			<axis>
				<xyz>0.024649043751837536 -0.9996961239187773 -0.00029062672542217393</xyz>
				<limit>
					<lower>-3.141592653589793</lower>
					<upper>3.141592653589793</upper>
				</limit>
				<use_parent_model_frame>0</use_parent_model_frame>
			</axis>
		</joint>
		<joint name="neck_axis_1" type="revolute">
			<parent>torso</parent>
			<child>neck_link_3</child>
			<pose frame="">2.2204460492503132e-17 -0.005999999999999375 8.881784197001253e-18 0 0 0</pose>
			<axis>
				<xyz>-3.4580022271808862e-15 1.0 -6.328575552895589e-17</xyz>
				<limit>
					<lower>-0.5235987755982988</lower>
					<upper>0.5235987755982988</upper>
				</limit>
				<use_parent_model_frame>0</use_parent_model_frame>
			</axis>
		</joint>

        <plugin name="joint_state_publisher" filename="libgazebo_ros_joint_state_publisher.so">
            <jointName>shoulder_left_axis_1, shoulder_left_axis_2, shoulder_left_axis_3, shoulder_right_axis_1, shoulder_right_axis_2, shoulder_right_axis_3, elbow_left, elbow_right, wrist_left, wrist_right, neck_axis_1, neck_axis_2, neck_axis_3</jointName>
            <updateRate>100.0</updateRate>
            <alwaysOn>true</alwaysOn>
        </plugin>

		<plugin filename="libmyomuscle_plugin.so" name="myomuscle_plugin">
			<myoMuscle name="motor0">
				<link name="torso">
					<viaPoint type="FIXPOINT">0.23757805790055153 0.47944722178973864 0.015492439711174609</viaPoint>
					<viaPoint type="FIXPOINT">0.2718871356728518 0.6183871510708954 0.012838404526322802</viaPoint>
					<viaPoint type="FIXPOINT">0.2889410922378454 0.6262546353826112 0.010689615277497917</viaPoint>
				</link>
				<link name="upper_arm_left">
					<viaPoint type="FIXPOINT">0.024643010975561916 -0.030889028077830505 0.018157453982060336</viaPoint>
				</link>
			</myoMuscle>
			<myoMuscle name="motor1">
				<link name="torso">
					<viaPoint type="FIXPOINT">0.24003539451940115 0.517294049483184 0.02550943966354026</viaPoint>
				</link>
				<link name="upper_arm_left">
					<viaPoint type="FIXPOINT">-0.014973610842486416 -0.03186661393800385 0.02083081693210307</viaPoint>
				</link>
			</myoMuscle>
			<myoMuscle name="motor2">
				<link name="torso">
					<viaPoint type="FIXPOINT">0.25121801331283466 0.5645590997255817 0.0286674056573492</viaPoint>
				</link>
				<link name="upper_arm_left">
					<viaPoint type="FIXPOINT">0.002322440484976696 -0.031442804581393986 0.029950951418864773</viaPoint>
				</link>
			</myoMuscle>
			<myoMuscle name="motor3">
				<link name="torso">
					<viaPoint type="FIXPOINT">0.2806366529259052 0.6080004259562052 0.028534400330321567</viaPoint>
				</link>
				<link name="upper_arm_left">
					<viaPoint type="FIXPOINT">0.021298410479614702 -0.030972572861495067 0.021867341448528265</viaPoint>
				</link>
			</myoMuscle>
			<myoMuscle name="motor4">
				<link name="torso">
					<viaPoint type="FIXPOINT">0.30339350272539184 0.6461449530207852 -7.438494264988549e-16</viaPoint>
				</link>
				<link name="upper_arm_left">
					<viaPoint type="FIXPOINT">0.030726984210491574 -0.03073328741678381 -0.001555849134958922</viaPoint>
				</link>
			</myoMuscle>
			<myoMuscle name="motor5">
				<link name="torso">
					<viaPoint type="FIXPOINT">0.23414595021784665 0.47793870122694787 -0.05384194818674346</viaPoint>
					<viaPoint type="FIXPOINT">0.2697922535654683 0.617768824060416 -0.02683911922329058</viaPoint>
					<viaPoint type="FIXPOINT">0.2865401700456305 0.6261408124917593 -0.026075605770313634</viaPoint>
				</link>
				<link name="upper_arm_left">
					<viaPoint type="FIXPOINT">0.01893690959321905 -0.031017498896779544 -0.023883286999316414</viaPoint>
				</link>
			</myoMuscle>
			<myoMuscle name="motor6">
				<link name="torso">
					<viaPoint type="FIXPOINT">0.27698713400212543 0.6064042514238017 -0.042899099013281275</viaPoint>
				</link>
				<link name="upper_arm_left">
					<viaPoint type="FIXPOINT">0.01893690959321905 -0.031017498896779544 -0.023883286999316414</viaPoint>
				</link>
			</myoMuscle>
			<myoMuscle name="motor7">
				<link name="torso">
					<viaPoint type="FIXPOINT">0.24756132617262147 0.5629597900609103 -0.04290640006488962</viaPoint>
				</link>
				<link name="upper_arm_left">
					<viaPoint type="FIXPOINT">-0.003242745493337296 -0.031562709512321235 -0.029603165480376815</viaPoint>
				</link>
			</myoMuscle>
			<myoMuscle name="motor8">
				<link name="torso">
					<viaPoint type="FIXPOINT">0.23617466540192034 0.5156054988488314 -0.050058161611908555</viaPoint>
				</link>
				<link name="upper_arm_left">
					<viaPoint type="FIXPOINT">-0.018032235047571385 -0.03193108236932467 -0.016823397177565348</viaPoint>
				</link>
			</myoMuscle>
			<myoMuscle name="motor9">
				<link name="upper_arm_left">
					<viaPoint type="FIXPOINT">0.007773818467739489 -0.23307858925470734 0.032792709973664944</viaPoint>
				</link>
				<link name="lower_arm_left">
					<viaPoint type="FIXPOINT">-0.00025803579214635165 0.010124378815315289 -0.010497302969137392</viaPoint>
				</link>
			</myoMuscle>
			<myoMuscle name="motor10">
				<link name="upper_arm_left">
					<viaPoint type="FIXPOINT">0.004343548774037877 -0.24983500811143927 -0.03475989047540426</viaPoint>
				</link>
				<link name="lower_arm_left">
					<viaPoint type="FIXPOINT">0.0008712160915301937 -0.03588441931306747 -0.016965149240829893</viaPoint>
				</link>
			</myoMuscle>
			<myoMuscle name="motor11">
				<link name="torso">
					<viaPoint type="FIXPOINT">-0.24097365552001088 0.4838095382426843 -0.029699394237717235</viaPoint>
					<viaPoint type="FIXPOINT">-0.27028172243412707 0.6239563833829664 0.0027474383169322314</viaPoint>
					<viaPoint type="FIXPOINT">-0.2866154255787014 0.6332230356749987 0.0030485131282469357</viaPoint>
				</link>
				<link name="upper_arm_right">
					<viaPoint type="FIXPOINT">-0.022618330616920125 -0.03275215923128144 -0.01751600315248317</viaPoint>
				</link>
			</myoMuscle>
			<myoMuscle name="motor12">
				<link name="torso">
					<viaPoint type="FIXPOINT">-0.24167949360377855 0.5215101254963836 -0.02577665507284405</viaPoint>
				</link>
				<link name="upper_arm_right">
					<viaPoint type="FIXPOINT">0.01549378617935993 -0.031359059506596905 -0.022206848597937933</viaPoint>
				</link>
			</myoMuscle>
			<myoMuscle name="motor13">
				<link name="torso">
					<viaPoint type="FIXPOINT">-0.25111213472929267 0.5691216713591611 -0.01756698913051002</viaPoint>
				</link>
				<link name="upper_arm_right">
					<viaPoint type="FIXPOINT">-0.0003409315825091497 -0.031121580630877832 -0.02933377887055017</viaPoint>
				</link>
			</myoMuscle>
			<myoMuscle name="motor14">
				<link name="torso">
					<viaPoint type="FIXPOINT">-0.2793059806241144 0.6132781125937181 -0.014631824059475758</viaPoint>
				</link>
				<link name="upper_arm_right">
					<viaPoint type="FIXPOINT">-0.01927335230313332 -0.03269701157836281 -0.02122608078494555</viaPoint>
				</link>
			</myoMuscle>
			<myoMuscle name="motor15">
				<link name="torso">
					<viaPoint type="FIXPOINT">-0.30344447277932235 0.646144953020783 8.326672684688674e-16</viaPoint>
				</link>
				<link name="upper_arm_right">
					<viaPoint type="FIXPOINT">-0.028709664518253887 -0.03258896233548612 0.0021949664668936488</viaPoint>
				</link>
			</myoMuscle>
			<myoMuscle name="motor16">
				<link name="torso">
					<viaPoint type="FIXPOINT">-0.23721059359757005 0.4853644385773738 0.041820466689661856</viaPoint>
					<viaPoint type="FIXPOINT">-0.2682894715184393 0.6250618678837471 0.040286741163291014</viaPoint>
					<viaPoint type="FIXPOINT">-0.28527428765023155 0.6333499538383022 0.03986758566619451</viaPoint>
				</link>
				<link name="upper_arm_right">
					<viaPoint type="FIXPOINT">-0.01693648216109363 -0.03167494464730737 0.02451441686522815</viaPoint>
				</link>
			</myoMuscle>
			<myoMuscle name="motor17">
				<link name="torso">
					<viaPoint type="FIXPOINT">-0.27565646170033464 0.6148742871261215 0.05680167528412722</viaPoint>
				</link>
				<link name="upper_arm_right">
					<viaPoint type="FIXPOINT">0.002758717543458218 -0.03078199770751617 0.03059348419672231</viaPoint>
				</link>
			</myoMuscle>
			<myoMuscle name="motor18">
				<link name="torso">
					<viaPoint type="FIXPOINT">-0.24745544758907753 0.5707209810238325 0.05400681659172883</viaPoint>
				</link>
				<link name="upper_arm_right">
					<viaPoint type="FIXPOINT">0.002758717543458218 -0.03078199770751617 0.03059348419672231</viaPoint>
				</link>
			</myoMuscle>
			<myoMuscle name="motor19">
				<link name="torso">
					<viaPoint type="FIXPOINT">-0.23781876448629782 0.5231986761307362 0.04979094620260492</viaPoint>
				</link>
				<link name="upper_arm_right">
					<viaPoint type="FIXPOINT">0.020019365154750196 -0.030375400024243788 0.017445409334536543</viaPoint>
				</link>
			</myoMuscle>
			<myoMuscle name="motor20">
				<link name="upper_arm_right">
					<viaPoint type="FIXPOINT">0.003706565324078568 -0.23244465376321294 0.03741604506111661</viaPoint>
				</link>
				<link name="lower_arm_right">
					<viaPoint type="FIXPOINT">-0.0010672061282369328 0.009888731387557855 -0.010669443893673547</viaPoint>
				</link>
			</myoMuscle>
			<myoMuscle name="motor21">
				<link name="upper_arm_right">
					<viaPoint type="FIXPOINT">-0.0033697387707215046 -0.2506276405344759 -0.029373904546613032</viaPoint>
				</link>
				<link name="lower_arm_right">
					<viaPoint type="FIXPOINT">-0.0017232147122346576 -0.03626775677922559 -0.01606073346822239</viaPoint>
				</link>
			</myoMuscle>
			<myoMuscle name="motor22">
				<link name="torso">
					<viaPoint type="FIXPOINT">-0.05130415696557491 0.7420367166308673 0.044515873503976636</viaPoint>
				</link>
				<link name="head">
					<viaPoint type="FIXPOINT">-0.049764060177401453 -0.03229216160123301 0.005257012979424622</viaPoint>
				</link>
			</myoMuscle>
			<myoMuscle name="motor23">
				<link name="torso">
					<viaPoint type="FIXPOINT">-0.05124511014858664 0.7422330293237644 -0.04347759286719319</viaPoint>
				</link>
				<link name="head">
					<viaPoint type="FIXPOINT">-0.04976406017740098 -0.029881340399380462 -0.02229879945035457</viaPoint>
				</link>
			</myoMuscle>
			<myoMuscle name="motor24">
				<link name="torso">
					<viaPoint type="FIXPOINT">0.05124511014858182 0.7422330293237652 -0.04347759286719307</viaPoint>
				</link>
				<link name="head">
					<viaPoint type="FIXPOINT">0.049764060177399115 -0.02988134039938032 -0.02229879945035286</viaPoint>
				</link>
			</myoMuscle>
			<myoMuscle name="motor25">
				<link name="torso">
					<viaPoint type="FIXPOINT">0.05130415696557042 0.7420367166308671 0.044515873503976476</viaPoint>
				</link>
				<link name="head">
					<viaPoint type="FIXPOINT">0.04976406017739865 -0.03229216160123272 0.005257012979426332</viaPoint>
				</link>
			</myoMuscle>
		</plugin>
	</model>
</sdf>
