<?xml version="1.0" ?>
<robot name="robot_arm_3dof">
  <joint name="joint2" type="revolute">
    <parent link="link1"/>
    <child link="link2"/>
    <origin rpy="0  0  0" xyz="0       0       0.12984"/>
    <axis xyz="0  1  0"/>
    <limit effort="0.0" lower="-3.14159265359" upper="3.14159265359" velocity="0.0"/>
  </joint>
  <joint name="joint0" type="revolute">
    <parent link="base"/>
    <child link="link0"/>
    <origin rpy="0  0  0" xyz="0    0    0.01"/>
    <axis xyz="0  0 -1"/>
    <limit effort="0.0" lower="-3.14159265359" upper="3.14159265359" velocity="0.0"/>
  </joint>
  <joint name="joint1" type="revolute">
    <parent link="link0"/>
    <child link="link1"/>
    <origin rpy="0  0  0" xyz="0.11172  0       0.01"/>
    <axis xyz="0  0 -1"/>
    <limit effort="0.0" lower="-3.14159265359" upper="3.14159265359" velocity="0.0"/>
  </joint>
  <link name="base">
    <inertial>
      <mass value="0.1"/>
      <origin rpy="0  0  0" xyz="0  0  0"/>
      <inertia ixx="0.1" ixy="0.0" ixz="0.0" iyy="0.1" iyz="0.0" izz="0.1"/>
    </inertial>
    <collision name="base_collision">
      <origin rpy="0  0  0" xyz="0  0  0"/>
      <geometry>
        <mesh filename="package://roboy_models/robot_arm_3dof/meshes/CAD/base.stl" scale="0.001 0.001 0.001"/>
      </geometry>
    </collision>
    <visual name="base_visual">
      <origin rpy="0  0  0" xyz="0  0  0"/>
      <geometry>
        <mesh filename="package://roboy_models/robot_arm_3dof/meshes/CAD/base.stl" scale="0.001 0.001 0.001"/>
      </geometry>
    </visual>
  </link>
  <link name="link0">
    <inertial>
      <mass value="0.1"/>
      <origin rpy="0  0  0" xyz="0.055  0     0.005"/>
      <inertia ixx="0.1" ixy="0.0" ixz="0.0" iyy="0.1" iyz="0.0" izz="0.1"/>
    </inertial>
    <collision name="link0_collision">
      <origin rpy="0  0  0" xyz="0.055  0     0.005"/>
      <geometry>
        <mesh filename="package://roboy_models/robot_arm_3dof/meshes/CAD/link0.stl" scale="0.001 0.001 0.001"/>
      </geometry>
    </collision>
    <visual name="link0_visual">
      <origin rpy="0  0  0" xyz="0.055  0     0.005"/>
      <geometry>
        <mesh filename="package://roboy_models/robot_arm_3dof/meshes/CAD/link0.stl" scale="0.001 0.001 0.001"/>
      </geometry>
    </visual>
  </link>
  <link name="link1">
    <inertial>
      <mass value="0.1"/>
      <origin rpy="0  0  0" xyz="0     0     0.075"/>
      <inertia ixx="0.1" ixy="0.0" ixz="0.0" iyy="0.1" iyz="0.0" izz="0.1"/>
    </inertial>
    <collision name="link1_collision">
      <origin rpy="0  0  0" xyz="0     0     0.075"/>
      <geometry>
        <mesh filename="package://roboy_models/robot_arm_3dof/meshes/CAD/link1.stl" scale="0.001 0.001 0.001"/>
      </geometry>
    </collision>
    <visual name="link1_visual">
      <origin rpy="0  0  0" xyz="0     0     0.075"/>
      <geometry>
        <mesh filename="package://roboy_models/robot_arm_3dof/meshes/CAD/link1.stl" scale="0.001 0.001 0.001"/>
      </geometry>
    </visual>
  </link>
  <link name="link2">
    <inertial>
      <mass value="0.1"/>
      <origin rpy="0  0  0" xyz="-0.05672  0       0"/>
      <inertia ixx="0.1" ixy="0.0" ixz="0.0" iyy="0.1" iyz="0.0" izz="0.1"/>
    </inertial>
    <collision name="link2_collision">
      <origin rpy="0  0  0" xyz="-0.05672  0       0"/>
      <geometry>
        <mesh filename="package://roboy_models/robot_arm_3dof/meshes/CAD/link2.stl" scale="0.001 0.001 0.001"/>
      </geometry>
    </collision>
    <visual name="link2_visual">
      <origin rpy="0  0  0" xyz="-0.05672  0       0"/>
      <geometry>
        <mesh filename="package://roboy_models/robot_arm_3dof/meshes/CAD/link2.stl" scale="0.001 0.001 0.001"/>
      </geometry>
    </visual>
  </link>
</robot>
