<?xml version="1.0" encoding="utf-8"?>
<robot name="HoLLiE">
  <joint name="hollie_real_base_x_joint" type="fixed">
    <origin rpy="0.0 0.0 0.0" xyz="0.0 0.0 0.0"/>
    <parent link="base_link"/>
    <child link="Table"/>
    <axis xyz="1 0 0"/>
    <calibration falling="0.0" reference_position="0.0" rising="0.0"/>
    <dynamics damping="1.0"/>
    <limit effort="1.0" lower="1.0" upper="1.0" velocity="1.0"/>
  </joint>
  <joint name="hollie_real_left_arm_0_joint" type="prismatic">
    <origin rpy="0.0 0.0 1.623156189918518" xyz="0.0 -0.4000000059604645 1.0"/>
    <parent link="Table"/>
    <child link="hollie_real_left_arm_0_joint_link"/>
    <axis xyz="1 0 0"/>
    <calibration falling="0.0" reference_position="0.0" rising="0.0"/>
    <dynamics damping="1.0"/>
    <limit effort="1.0" lower="0.0" upper="0.0" velocity="1.0"/>
  </joint>
  <joint name="hollie_real_left_arm_1_joint" type="revolute">
    <origin rpy="0.0 0.0 0.0" xyz="0.0 0.0 0.10999999940395355"/>
    <parent link="hollie_real_left_arm_0_joint_link"/>
    <child link="hollie_real.000"/>
    <axis xyz="0 0 1"/>
    <calibration falling="0.0" reference_position="0.0" rising="0.0"/>
    <dynamics damping="1.0"/>
    <limit effort="1.0" lower="-1.3725518549658003e+20" upper="1.3725518549658003e+20" velocity="1.0"/>
  </joint>
  <joint name="hollie_real_left_arm_2_joint" type="revolute">
    <origin rpy="1.5707963705062866 0.0 0.0" xyz="0.0 0.0 0.0"/>
    <parent link="hollie_real.000"/>
    <child link="hollie_real.001"/>
    <axis xyz="0 0 1"/>
    <calibration falling="0.0" reference_position="0.0" rising="0.0"/>
    <dynamics damping="1.0"/>
    <limit effort="1.0" lower="-2864.7890625" upper="2864.7890625" velocity="1.0"/>
  </joint>
  <joint name="hollie_real_left_arm_3_joint" type="revolute">
    <origin rpy="0.0 -3.141592502593994 -0.0" xyz="0.0 0.3499999940395355 0.0"/>
    <parent link="hollie_real.001"/>
    <child link="hollie_real.002"/>
    <axis xyz="0 0 1"/>
    <calibration falling="0.0" reference_position="0.0" rising="0.0"/>
    <dynamics damping="1.0"/>
    <limit effort="1.0" lower="-1.3674871525645432e+20" upper="1.3674871525645432e+20" velocity="1.0"/>
  </joint>
  <joint name="hollie_real_left_arm_4_joint" type="revolute">
    <origin rpy="1.5707963705062866 0.0 3.141592502593994" xyz="0.0 0.0 0.0"/>
    <parent link="hollie_real.002"/>
    <child link="hollie_real.003"/>
    <axis xyz="0 0 1"/>
    <calibration falling="0.0" reference_position="0.0" rising="0.0"/>
    <dynamics damping="1.0"/>
    <limit effort="1.0" lower="-4.5218827465218064e+19" upper="4.5218827465218064e+19" velocity="1.0"/>
  </joint>
  <joint name="hollie_real_left_arm_5_joint" type="revolute">
    <origin rpy="1.5707963705062866 0.0 -3.141592502593994" xyz="0.0 0.0052629997953772545 0.3050000071525574"/>
    <parent link="hollie_real.003"/>
    <child link="hollie_real.004"/>
    <axis xyz="0 0 1"/>
    <calibration falling="0.0" reference_position="0.0" rising="0.0"/>
    <dynamics damping="1.0"/>
    <limit effort="1.0" lower="-1.3674871525645432e+20" upper="1.3674871525645432e+20" velocity="1.0"/>
  </joint>
  <joint name="hollie_real_left_arm_6_joint" type="revolute">
    <origin rpy="-1.5707963705062866 0.0 0.0" xyz="0.0 0.0 0.0"/>
    <parent link="hollie_real.004"/>
    <child link="hollie_real.005"/>
    <axis xyz="0 0 1"/>
    <calibration falling="0.0" reference_position="0.0" rising="0.0"/>
    <dynamics damping="1.0"/>
    <limit effort="1.0" lower="-4.5218827465218064e+19" upper="4.5218827465218064e+19" velocity="1.0"/>
  </joint>
  <joint name="hollie_real_left_hand_base_joint" type="prismatic">
    <origin rpy="0.0 0.0 0.0" xyz="0.0 0.0 0.10000000149011612"/>
    <parent link="hollie_real.005"/>
    <child link="hollie_real.006"/>
    <axis xyz="1 0 0"/>
    <calibration falling="0.0" reference_position="0.0" rising="0.0"/>
    <dynamics damping="1.0"/>
    <limit effort="1.0" lower="0.0" upper="0.0" velocity="1.0"/>
  </joint>
  <joint name="hollie_real_left_hand_f4" type="prismatic">
    <origin rpy="0.0 0.0 0.0" xyz="0.0 -0.013129999861121178 0.0"/>
    <parent link="hollie_real.006"/>
    <child link="hollie_real.007"/>
    <axis xyz="1 0 0"/>
    <calibration falling="0.0" reference_position="0.0" rising="0.0"/>
    <dynamics damping="1.0"/>
    <limit effort="1.0" lower="0.0" upper="0.0" velocity="1.0"/>
  </joint>
  <joint name="hollie_real_left_hand_Thumb_Opposition" type="revolute">
    <origin rpy="0.0 0.2617993950843811 1.5707963705062866" xyz="0.016899999231100082 0.026259999722242355 0.0"/>
    <parent link="hollie_real.007"/>
    <child link="hollie_real.008"/>
    <axis xyz="0 0 1"/>
    <calibration falling="0.0" reference_position="0.0" rising="0.0"/>
    <dynamics damping="1.0"/>
    <limit effort="1.0" lower="0.0" upper="2.158052153766183e+19" velocity="1.0"/>
  </joint>
  <joint name="hollie_real_left_hand_Thumb_Helper" type="prismatic">
    <origin rpy="-3.141592502593994 -1.570796251296997 0.0" xyz="0.0 0.0 0.04596000164747238"/>
    <parent link="hollie_real.008"/>
    <child link="hollie_real_left_hand_Thumb_Helper_link"/>
    <axis xyz="1 0 0"/>
    <calibration falling="0.0" reference_position="0.0" rising="0.0"/>
    <dynamics damping="1.0"/>
    <limit effort="1.0" lower="0.0" upper="0.0" velocity="1.0"/>
  </joint>
  <joint name="hollie_real_left_hand_Thumb_Flexion" type="revolute">
    <origin rpy="0.0 0.0 0.9773843884468079" xyz="0.0 0.0 0.0"/>
    <parent link="hollie_real_left_hand_Thumb_Helper_link"/>
    <child link="hollie_real.009"/>
    <axis xyz="0 0 1"/>
    <calibration falling="0.0" reference_position="0.0" rising="0.0"/>
    <dynamics damping="1.0"/>
    <limit effort="1.0" lower="0.0" upper="2.1198236737846903e+19" velocity="1.0"/>
  </joint>
  <joint name="hollie_real_left_hand_j3" type="revolute">
    <origin rpy="0.0 0.0 0.0" xyz="0.048500001430511475 0.0 0.0"/>
    <parent link="hollie_real.009"/>
    <child link="hollie_real.010"/>
    <axis xyz="0 0 1"/>
    <calibration falling="0.0" reference_position="0.0" rising="0.0"/>
    <dynamics damping="1.0"/>
    <limit effort="1.0" lower="0.0" upper="2.151848049455294e+19" velocity="1.0"/>
  </joint>
  <joint name="hollie_real_left_hand_j4" type="revolute">
    <origin rpy="0.0 0.0 0.0" xyz="0.029999999329447746 0.0 0.0"/>
    <parent link="hollie_real.010"/>
    <child link="hollie_real.011"/>
    <axis xyz="0 0 1"/>
    <calibration falling="0.0" reference_position="0.0" rising="0.0"/>
    <dynamics damping="1.0"/>
    <limit effort="1.0" lower="0.0" upper="3.0713850169271517e+19" velocity="1.0"/>
  </joint>
  <joint name="hollie_real_left_hand_f1" type="prismatic">
    <origin rpy="0.0 0.0 0.0" xyz="0.0 0.0 0.0"/>
    <parent link="hollie_real.007"/>
    <child link="hollie_real_left_hand_f1_link"/>
    <axis xyz="1 0 0"/>
    <calibration falling="0.0" reference_position="0.0" rising="0.0"/>
    <dynamics damping="1.0"/>
    <limit effort="1.0" lower="0.0" upper="0.0" velocity="1.0"/>
  </joint>
  <joint name="hollie_real_left_hand_f2" type="prismatic">
    <origin rpy="0.0 0.0 0.0" xyz="0.0 0.0 0.0"/>
    <parent link="hollie_real_left_hand_f1_link"/>
    <child link="hollie_real_left_hand_f2_link"/>
    <axis xyz="1 0 0"/>
    <calibration falling="0.0" reference_position="0.0" rising="0.0"/>
    <dynamics damping="1.0"/>
    <limit effort="1.0" lower="0.0" upper="0.0" velocity="1.0"/>
  </joint>
  <joint name="hollie_real_left_hand_f3" type="prismatic">
    <origin rpy="0.0 0.0 0.0" xyz="0.0 0.0 0.0"/>
    <parent link="hollie_real_left_hand_f2_link"/>
    <child link="hollie_real_left_hand_f3_link"/>
    <axis xyz="1 0 0"/>
    <calibration falling="0.0" reference_position="0.0" rising="0.0"/>
    <dynamics damping="1.0"/>
    <limit effort="1.0" lower="0.0" upper="0.0" velocity="1.0"/>
  </joint>
  <joint name="hollie_real_left_hand_index_spread" type="revolute">
    <origin rpy="1.5707963705062866 -1.570796251296997 0.0" xyz="0.02500000037252903 0.0 0.10999999940395355"/>
    <parent link="hollie_real_left_hand_f3_link"/>
    <child link="hollie_real.012"/>
    <axis xyz="0 0 1"/>
    <calibration falling="0.0" reference_position="0.0" rising="0.0"/>
    <dynamics damping="1.0"/>
    <limit effort="1.0" lower="0.0" upper="6.29852322265668e+18" velocity="1.0"/>
  </joint>
  <joint name="hollie_real_left_hand_Index_Finger_Proximal" type="revolute">
    <origin rpy="-1.5707963705062866 0.0 0.0" xyz="0.0 0.0 0.0"/>
    <parent link="hollie_real.012"/>
    <child link="hollie_real.013"/>
    <axis xyz="0 0 1"/>
    <calibration falling="0.0" reference_position="0.0" rising="0.0"/>
    <dynamics damping="1.0"/>
    <limit effort="1.0" lower="0.0" upper="1.744289215657332e+19" velocity="1.0"/>
  </joint>
  <joint name="hollie_real_left_hand_Index_Finger_Distal" type="revolute">
    <origin rpy="0.0 0.0 0.0" xyz="0.0480399988591671 0.0 0.0"/>
    <parent link="hollie_real.013"/>
    <child link="hollie_real.014"/>
    <axis xyz="0 0 1"/>
    <calibration falling="0.0" reference_position="0.0" rising="0.0"/>
    <dynamics damping="1.0"/>
    <limit effort="1.0" lower="0.0" upper="2.914102297499376e+19" velocity="1.0"/>
  </joint>
  <joint name="hollie_real_left_hand_j14" type="revolute">
    <origin rpy="0.0 0.0 0.0" xyz="0.026000000536441803 0.0 0.0"/>
    <parent link="hollie_real.014"/>
    <child link="hollie_real.015"/>
    <axis xyz="0 0 1"/>
    <calibration falling="0.0" reference_position="0.0" rising="0.0"/>
    <dynamics damping="1.0"/>
    <limit effort="1.0" lower="0.0" upper="3.0451713403070185e+19" velocity="1.0"/>
  </joint>
  <joint name="hollie_real_left_hand_middle_spread_dummy" type="prismatic">
    <origin rpy="1.5707963705062866 -1.570796251296997 0.0" xyz="0.0 0.0 0.10999999940395355"/>
    <parent link="hollie_real_left_hand_f1_link"/>
    <child link="hollie_real.016"/>
    <axis xyz="1 0 0"/>
    <calibration falling="0.0" reference_position="0.0" rising="0.0"/>
    <dynamics damping="1.0"/>
    <limit effort="1.0" lower="0.0" upper="0.0" velocity="1.0"/>
  </joint>
  <joint name="hollie_real_left_hand_Middle_Finger_Proximal" type="revolute">
    <origin rpy="-1.5707963705062866 0.0 0.0" xyz="0.0 0.0 0.0"/>
    <parent link="hollie_real.016"/>
    <child link="hollie_real.017"/>
    <axis xyz="0 0 1"/>
    <calibration falling="0.0" reference_position="0.0" rising="0.0"/>
    <dynamics damping="1.0"/>
    <limit effort="1.0" lower="0.0" upper="1.744289215657332e+19" velocity="1.0"/>
  </joint>
  <joint name="hollie_real_left_hand_Middle_Finger_Distal" type="revolute">
    <origin rpy="0.0 0.0 0.0" xyz="0.050039999186992645 0.0 0.0"/>
    <parent link="hollie_real.017"/>
    <child link="hollie_real.018"/>
    <axis xyz="0 0 1"/>
    <calibration falling="0.0" reference_position="0.0" rising="0.0"/>
    <dynamics damping="1.0"/>
    <limit effort="1.0" lower="0.0" upper="2.914102297499376e+19" velocity="1.0"/>
  </joint>
  <joint name="hollie_real_left_hand_j15" type="revolute">
    <origin rpy="0.0 0.0 0.0" xyz="0.03200000151991844 0.0 0.0"/>
    <parent link="hollie_real.018"/>
    <child link="hollie_real.019"/>
    <axis xyz="0 0 1"/>
    <calibration falling="0.0" reference_position="0.0" rising="0.0"/>
    <dynamics damping="1.0"/>
    <limit effort="1.0" lower="0.0" upper="2.914102297499376e+19" velocity="1.0"/>
  </joint>
  <joint name="hollie_real_left_hand_j5" type="revolute">
    <origin rpy="0.0 0.0 0.0" xyz="-0.018400000408291817 0.006000000052154064 0.03750000149011612"/>
    <parent link="hollie_real.007"/>
    <child link="hollie_real.020"/>
    <axis xyz="0 0 1"/>
    <calibration falling="0.0" reference_position="0.0" rising="0.0"/>
    <dynamics damping="1.0"/>
    <limit effort="1.0" lower="0.0" upper="2.157964632640612e+19" velocity="1.0"/>
  </joint>
  <joint name="hollie_real_left_hand_f5" type="prismatic">
    <origin rpy="0.0 0.0 0.0" xyz="0.0 -0.006000000052154064 0.0"/>
    <parent link="hollie_real.020"/>
    <child link="hollie_real_left_hand_f5_link"/>
    <axis xyz="1 0 0"/>
    <calibration falling="0.0" reference_position="0.0" rising="0.0"/>
    <dynamics damping="1.0"/>
    <limit effort="1.0" lower="0.0" upper="0.0" velocity="1.0"/>
  </joint>
  <joint name="hollie_real_left_hand_f6" type="prismatic">
    <origin rpy="0.0 0.0 0.0" xyz="0.0 0.0 0.0"/>
    <parent link="hollie_real_left_hand_f5_link"/>
    <child link="hollie_real_left_hand_f6_link"/>
    <axis xyz="1 0 0"/>
    <calibration falling="0.0" reference_position="0.0" rising="0.0"/>
    <dynamics damping="1.0"/>
    <limit effort="1.0" lower="0.0" upper="0.0" velocity="1.0"/>
  </joint>
  <joint name="hollie_real_left_hand_f7" type="prismatic">
    <origin rpy="0.0 0.0 0.0" xyz="0.0 0.0 0.0"/>
    <parent link="hollie_real_left_hand_f6_link"/>
    <child link="hollie_real_left_hand_f7_link"/>
    <axis xyz="1 0 0"/>
    <calibration falling="0.0" reference_position="0.0" rising="0.0"/>
    <dynamics damping="1.0"/>
    <limit effort="1.0" lower="0.0" upper="0.0" velocity="1.0"/>
  </joint>
  <joint name="hollie_real_left_hand_Finger_Spread" type="revolute">
    <origin rpy="-1.5707963705062866 -1.570796251296997 0.0" xyz="-0.02535500004887581 0.0 0.0560000017285347"/>
    <parent link="hollie_real_left_hand_f7_link"/>
    <child link="hollie_real.021"/>
    <axis xyz="0 0 1"/>
    <calibration falling="0.0" reference_position="0.0" rising="0.0"/>
    <dynamics damping="1.0"/>
    <limit effort="1.0" lower="0.0" upper="1.2733359498878517e+19" velocity="1.0"/>
  </joint>
  <joint name="hollie_real_left_hand_Pinky" type="revolute">
    <origin rpy="1.5707963705062866 0.0 0.0" xyz="0.0 0.0 0.0"/>
    <parent link="hollie_real.021"/>
    <child link="hollie_real.022"/>
    <axis xyz="0 0 1"/>
    <calibration falling="0.0" reference_position="0.0" rising="0.0"/>
    <dynamics damping="1.0"/>
    <limit effort="1.0" lower="0.0" upper="2.144617660991039e+19" velocity="1.0"/>
  </joint>
  <joint name="hollie_real_left_hand_j13" type="revolute">
    <origin rpy="0.0 0.0 0.0" xyz="0.04453999921679497 0.0 0.0"/>
    <parent link="hollie_real.022"/>
    <child link="hollie_real.023"/>
    <axis xyz="0 0 1"/>
    <calibration falling="0.0" reference_position="0.0" rising="0.0"/>
    <dynamics damping="1.0"/>
    <limit effort="1.0" lower="0.0" upper="2.914102297499376e+19" velocity="1.0"/>
  </joint>
  <joint name="hollie_real_left_hand_j17" type="revolute">
    <origin rpy="0.0 0.0 0.0" xyz="0.02199999988079071 0.0 0.0"/>
    <parent link="hollie_real.023"/>
    <child link="hollie_real.024"/>
    <axis xyz="0 0 1"/>
    <calibration falling="0.0" reference_position="0.0" rising="0.0"/>
    <dynamics damping="1.0"/>
    <limit effort="1.0" lower="0.0" upper="3.0519430125201654e+19" velocity="1.0"/>
  </joint>
  <joint name="hollie_real_left_hand_f8" type="prismatic">
    <origin rpy="0.0 0.0 0.0" xyz="0.0 0.0 0.0"/>
    <parent link="hollie_real_left_hand_f6_link"/>
    <child link="hollie_real_left_hand_f8_link"/>
    <axis xyz="1 0 0"/>
    <calibration falling="0.0" reference_position="0.0" rising="0.0"/>
    <dynamics damping="1.0"/>
    <limit effort="1.0" lower="0.0" upper="0.0" velocity="1.0"/>
  </joint>
  <joint name="hollie_real_left_hand_ring_spread" type="revolute">
    <origin rpy="-1.5707963705062866 -1.570796251296997 0.0" xyz="-0.003855000017210841 0.0 0.06549999862909317"/>
    <parent link="hollie_real_left_hand_f8_link"/>
    <child link="hollie_real.025"/>
    <axis xyz="0 0 1"/>
    <calibration falling="0.0" reference_position="0.0" rising="0.0"/>
    <dynamics damping="1.0"/>
    <limit effort="1.0" lower="0.0" upper="6.29852322265668e+18" velocity="1.0"/>
  </joint>
  <joint name="hollie_real_left_hand_Ring_Finger" type="revolute">
    <origin rpy="1.5707963705062866 0.0 0.0" xyz="0.0 0.0 0.0"/>
    <parent link="hollie_real.025"/>
    <child link="hollie_real.026"/>
    <axis xyz="0 0 1"/>
    <calibration falling="0.0" reference_position="0.0" rising="0.0"/>
    <dynamics damping="1.0"/>
    <limit effort="1.0" lower="0.0" upper="2.144617660991039e+19" velocity="1.0"/>
  </joint>
  <joint name="hollie_real_left_hand_j12" type="revolute">
    <origin rpy="0.0 0.0 0.0" xyz="0.050039999186992645 0.0 0.0"/>
    <parent link="hollie_real.026"/>
    <child link="hollie_real.027"/>
    <axis xyz="0 0 1"/>
    <calibration falling="0.0" reference_position="0.0" rising="0.0"/>
    <dynamics damping="1.0"/>
    <limit effort="1.0" lower="0.0" upper="2.914102297499376e+19" velocity="1.0"/>
  </joint>
  <joint name="hollie_real_left_hand_j16" type="revolute">
    <origin rpy="0.0 0.0 0.0" xyz="0.03200000151991844 0.0 0.0"/>
    <parent link="hollie_real.027"/>
    <child link="hollie_real_lef"/>
    <axis xyz="0 0 1"/>
    <calibration falling="0.0" reference_position="0.0" rising="0.0"/>
    <dynamics damping="1.0"/>
    <limit effort="1.0" lower="0.0" upper="3.0473556301067583e+19" velocity="1.0"/>
  </joint>
  <link name="base_link"/>
  <link name="Table">
    <inertial>
      <origin rpy="0 0 0" xyz="0 0 0"/>
      <mass value="1.0"/>
      <inertia ixx="1.0" ixy="0.0" ixz="0.0" iyy="1.0" iyz="0.0" izz="1.0"/>
    </inertial>
    <visual>
      <origin rpy="0.0 0.0 0.0" xyz="0.0 0.0 0.5"/>
      <geometry>
        <mesh filename="model://arm_robot-mit_VISCOL/meshes/VIS_Table.dae"/>
      </geometry>
    </visual>
    <collision>
      <origin xyz="0.0 0.0 0.5"/>
      <geometry>
        <mesh filename="model://arm_robot-mit_VISCOL/collisions/COL_Table.000.dae"/>
      </geometry>
    </collision>
    <collision>
      <origin xyz="0.0 0.0 0.5"/>
      <geometry>
        <mesh filename="model://arm_robot-mit_VISCOL/collisions/COL_Table.001.dae"/>
      </geometry>
    </collision>
    <collision>
      <origin xyz="0.0 0.0 0.5"/>
      <geometry>
        <mesh filename="model://arm_robot-mit_VISCOL/collisions/COL_Table.dae"/>
      </geometry>
    </collision>
  </link>
  <link name="hollie_real_left_arm_0_joint_link">
    <inertial>
      <origin rpy="0 0 0" xyz="0 0 0"/>
      <mass value="1.0"/>
      <inertia ixx="1.0" ixy="0.0" ixz="0.0" iyy="1.0" iyz="0.0" izz="1.0"/>
    </inertial>
  </link>
  <link name="hollie_real.000">
    <inertial>
      <origin rpy="0 0 0" xyz="0 0 0"/>
      <mass value="1.0"/>
      <inertia ixx="1.0" ixy="0.0" ixz="0.0" iyy="1.0" iyz="0.0" izz="1.0"/>
    </inertial>
    <visual>
      <origin rpy="-2.1012533579778392e-07 1.1580802095068066e-08 -1.564621925354004e-07" xyz="3.510419332997117e-08 9.930301558824794e-08 1.1920928955078125e-06"/>
      <geometry>
        <mesh filename="model://arm_robot-mit_VISCOL/meshes/VIS_hollie_real.000.dae"/>
      </geometry>
    </visual>
    <collision>
      <origin xyz="3.510419332997117e-08 9.930301558824794e-08 1.1920928955078125e-06"/>
      <geometry>
        <mesh filename="model://arm_robot-mit_VISCOL/collisions/COL_hollie_real.000.dae"/>
      </geometry>
    </collision>
  </link>
  <link name="hollie_real.001">
    <inertial>
      <origin rpy="0 0 0" xyz="0 0 0"/>
      <mass value="1.0"/>
      <inertia ixx="1.0" ixy="0.0" ixz="0.0" iyy="1.0" iyz="0.0" izz="1.0"/>
    </inertial>
    <visual>
      <origin rpy="-7.549789415861596e-08 4.842877388000488e-08 5.42986633433884e-08" xyz="-2.5418456672809953e-08 1.4319995216283132e-06 -4.747191084675251e-09"/>
      <geometry>
        <mesh filename="model://arm_robot-mit_VISCOL/meshes/VIS_hollie_real.001.dae"/>
      </geometry>
    </visual>
    <collision>
      <origin xyz="-2.5418456672809953e-08 1.4319995216283132e-06 -4.747191084675251e-09"/>
      <geometry>
        <mesh filename="model://arm_robot-mit_VISCOL/collisions/COL_hollie_real.001.dae"/>
      </geometry>
    </collision>
  </link>
  <link name="hollie_real.002">
    <inertial>
      <origin rpy="0 0 0" xyz="0 0 0"/>
      <mass value="1.0"/>
      <inertia ixx="1.0" ixy="0.0" ixz="0.0" iyy="1.0" iyz="0.0" izz="1.0"/>
    </inertial>
    <visual>
      <origin rpy="4.371131723246435e-08 4.0978193283081055e-07 -1.734670860287224e-07" xyz="-1.555379611772878e-07 9.551623634251882e-07 1.1435902891321348e-08"/>
      <geometry>
        <mesh filename="model://arm_robot-mit_VISCOL/meshes/VIS_hollie_real.002.dae"/>
      </geometry>
    </visual>
    <collision>
      <origin xyz="-1.555379611772878e-07 9.551623634251882e-07 1.1435902891321348e-08"/>
      <geometry>
        <mesh filename="model://arm_robot-mit_VISCOL/collisions/COL_hollie_real.002.dae"/>
      </geometry>
    </collision>
  </link>
  <link name="hollie_real.003">
    <inertial>
      <origin rpy="0 0 0" xyz="0 0 0"/>
      <mass value="1.0"/>
      <inertia ixx="1.0" ixy="0.0" ixz="0.0" iyy="1.0" iyz="0.0" izz="1.0"/>
    </inertial>
    <visual>
      <origin rpy="1.5478514114874997e-07 3.0945024320772063e-09 -2.123415470123291e-07" xyz="5.108404366183095e-08 -1.4634674982971774e-07 1.7472538615947997e-07"/>
      <geometry>
        <mesh filename="model://arm_robot-mit_VISCOL/meshes/VIS_hollie_real.003.dae"/>
      </geometry>
    </visual>
    <collision>
      <origin xyz="5.108404366183095e-08 -1.4634674982971774e-07 1.7472538615947997e-07"/>
      <geometry>
        <mesh filename="model://arm_robot-mit_VISCOL/collisions/COL_hollie_real.003.dae"/>
      </geometry>
    </collision>
  </link>
  <link name="hollie_real.004">
    <inertial>
      <origin rpy="0 0 0" xyz="0 0 0"/>
      <mass value="1.0"/>
      <inertia ixx="1.0" ixy="0.0" ixz="0.0" iyy="1.0" iyz="0.0" izz="1.0"/>
    </inertial>
    <visual>
      <origin rpy="1.47422338159231e-06 -1.695007085800171e-06 -1.440530041918464e-07" xyz="-1.878330238014314e-07 6.525791604872211e-07 -6.23986053938097e-08"/>
      <geometry>
        <mesh filename="model://arm_robot-mit_VISCOL/meshes/VIS_hollie_real.004.dae"/>
      </geometry>
    </visual>
    <collision>
      <origin xyz="-1.878330238014314e-07 6.525791604872211e-07 -6.23986053938097e-08"/>
      <geometry>
        <mesh filename="model://arm_robot-mit_VISCOL/collisions/COL_hollie_real.004.dae"/>
      </geometry>
    </collision>
  </link>
  <link name="hollie_real.005">
    <inertial>
      <origin rpy="0 0 0" xyz="0 0 0"/>
      <mass value="1.0"/>
      <inertia ixx="1.0" ixy="0.0" ixz="0.0" iyy="1.0" iyz="0.0" izz="1.0"/>
    </inertial>
    <visual>
      <origin rpy="1.288048849801271e-07 -3.810884940946835e-11 4.544854164123535e-07" xyz="-4.5222421363178e-08 3.3061951398849487e-07 1.3590478147307294e-06"/>
      <geometry>
        <mesh filename="model://arm_robot-mit_VISCOL/meshes/VIS_hollie_real.005.dae"/>
      </geometry>
    </visual>
    <collision>
      <origin xyz="-4.5222421363178e-08 3.3061951398849487e-07 1.3590478147307294e-06"/>
      <geometry>
        <mesh filename="model://arm_robot-mit_VISCOL/collisions/COL_hollie_real.005.dae"/>
      </geometry>
    </collision>
  </link>
  <link name="hollie_real.006">
    <inertial>
      <origin rpy="0 0 0" xyz="0 0 0"/>
      <mass value="1.0"/>
      <inertia ixx="1.0" ixy="0.0" ixz="0.0" iyy="1.0" iyz="0.0" izz="1.0"/>
    </inertial>
    <visual>
      <origin rpy="-5.1910255649545434e-08 -7.895630815824006e-10 2.1606683731079102e-07" xyz="-1.6857632090250263e-07 9.899958968162537e-07 -0.03199810907244682"/>
      <geometry>
        <mesh filename="model://arm_robot-mit_VISCOL/meshes/VIS_hollie_real.006.dae"/>
      </geometry>
    </visual>
    <collision>
      <origin xyz="-1.6857632090250263e-07 9.899958968162537e-07 -0.03199810907244682"/>
      <geometry>
        <mesh filename="model://arm_robot-mit_VISCOL/collisions/COL_hollie_real.006.dae"/>
      </geometry>
    </collision>
  </link>
  <link name="hollie_real.007">
    <inertial>
      <origin rpy="0 0 0" xyz="0 0 0"/>
      <mass value="1.0"/>
      <inertia ixx="1.0" ixy="0.0" ixz="0.0" iyy="1.0" iyz="0.0" izz="1.0"/>
    </inertial>
    <visual>
      <origin rpy="3.141592502593994 2.2907406105332484e-07 -6.183981895446777e-07" xyz="-6.609359104459145e-08 0.013130230829119682 2.0743034383485792e-06"/>
      <geometry>
        <mesh filename="model://arm_robot-mit_VISCOL/meshes/VIS_hollie_real.007.dae"/>
      </geometry>
    </visual>
    <collision>
      <origin xyz="-6.609359104459145e-08 0.013130230829119682 2.0743034383485792e-06"/>
      <geometry>
        <mesh filename="model://arm_robot-mit_VISCOL/collisions/COL_hollie_real.007.dae"/>
      </geometry>
    </collision>
  </link>
  <link name="hollie_real.008">
    <inertial>
      <origin rpy="0 0 0" xyz="0 0 0"/>
      <mass value="1.0"/>
      <inertia ixx="1.0" ixy="0.0" ixz="0.0" iyy="1.0" iyz="0.0" izz="1.0"/>
    </inertial>
    <visual>
      <origin rpy="-2.5923845896613784e-06 3.141589879989624 -3.5556709576667345e-07" xyz="2.5890767574310303e-07 -7.391362260023016e-07 0.024418124929070473"/>
      <geometry>
        <mesh filename="model://arm_robot-mit_VISCOL/meshes/VIS_hollie_real.008.dae"/>
      </geometry>
    </visual>
    <collision>
      <origin xyz="2.5890767574310303e-07 -7.391362260023016e-07 0.024418124929070473"/>
      <geometry>
        <mesh filename="model://arm_robot-mit_VISCOL/collisions/COL_hollie_real.008.dae"/>
      </geometry>
    </collision>
  </link>
  <link name="hollie_real_left_hand_Thumb_Helper_link">
    <inertial>
      <origin rpy="0 0 0" xyz="0 0 0"/>
      <mass value="1.0"/>
      <inertia ixx="1.0" ixy="0.0" ixz="0.0" iyy="1.0" iyz="0.0" izz="1.0"/>
    </inertial>
  </link>
  <link name="hollie_real.009">
    <inertial>
      <origin rpy="0 0 0" xyz="0 0 0"/>
      <mass value="1.0"/>
      <inertia ixx="1.0" ixy="0.0" ixz="0.0" iyy="1.0" iyz="0.0" izz="1.0"/>
    </inertial>
    <visual>
      <origin rpy="-3.1415915489196777 3.2410028438789595e-07 1.0617078487484832e-06" xyz="1.1818483471870422e-06 1.3248063623905182e-07 -2.5331974029541016e-07"/>
      <geometry>
        <mesh filename="model://arm_robot-mit_VISCOL/meshes/VIS_hollie_real.009.dae"/>
      </geometry>
    </visual>
    <collision>
      <origin xyz="1.1818483471870422e-06 1.3248063623905182e-07 -2.5331974029541016e-07"/>
      <geometry>
        <mesh filename="model://arm_robot-mit_VISCOL/collisions/COL_hollie_real.009.dae"/>
      </geometry>
    </collision>
  </link>
  <link name="hollie_real.010">
    <inertial>
      <origin rpy="0 0 0" xyz="0 0 0"/>
      <mass value="1.0"/>
      <inertia ixx="1.0" ixy="0.0" ixz="0.0" iyy="1.0" iyz="0.0" izz="1.0"/>
    </inertial>
    <visual>
      <origin rpy="-3.1415927410125732 -1.1175873559921001e-08 1.9147996681567747e-06" xyz="-6.495974957942963e-07 -1.0239891707897186e-06 4.78699803352356e-07"/>
      <geometry>
        <mesh filename="model://arm_robot-mit_VISCOL/meshes/VIS_hollie_real.010.dae"/>
      </geometry>
    </visual>
    <collision>
      <origin xyz="-6.495974957942963e-07 -1.0239891707897186e-06 4.78699803352356e-07"/>
      <geometry>
        <mesh filename="model://arm_robot-mit_VISCOL/collisions/COL_hollie_real.010.dae"/>
      </geometry>
    </collision>
  </link>
  <link name="hollie_real.011">
    <inertial>
      <origin rpy="0 0 0" xyz="0 0 0"/>
      <mass value="1.0"/>
      <inertia ixx="1.0" ixy="0.0" ixz="0.0" iyy="1.0" iyz="0.0" izz="1.0"/>
    </inertial>
    <visual>
      <origin rpy="3.141592264175415 4.842878453814592e-08 1.6726557987567503e-06" xyz="-7.497146725654602e-08 -2.477318048477173e-07 -7.450580596923828e-08"/>
      <geometry>
        <mesh filename="model://arm_robot-mit_VISCOL/meshes/VIS_hollie_real.011.dae"/>
      </geometry>
    </visual>
    <collision>
      <origin xyz="-7.497146725654602e-08 -2.477318048477173e-07 -7.450580596923828e-08"/>
      <geometry>
        <mesh filename="model://arm_robot-mit_VISCOL/collisions/COL_hollie_real.011.dae"/>
      </geometry>
    </collision>
  </link>
  <link name="hollie_real_left_hand_f1_link">
    <inertial>
      <origin rpy="0 0 0" xyz="0 0 0"/>
      <mass value="1.0"/>
      <inertia ixx="1.0" ixy="0.0" ixz="0.0" iyy="1.0" iyz="0.0" izz="1.0"/>
    </inertial>
  </link>
  <link name="hollie_real_left_hand_f2_link">
    <inertial>
      <origin rpy="0 0 0" xyz="0 0 0"/>
      <mass value="1.0"/>
      <inertia ixx="1.0" ixy="0.0" ixz="0.0" iyy="1.0" iyz="0.0" izz="1.0"/>
    </inertial>
  </link>
  <link name="hollie_real_left_hand_f3_link">
    <inertial>
      <origin rpy="0 0 0" xyz="0 0 0"/>
      <mass value="1.0"/>
      <inertia ixx="1.0" ixy="0.0" ixz="0.0" iyy="1.0" iyz="0.0" izz="1.0"/>
    </inertial>
  </link>
  <link name="hollie_real.012">
    <inertial>
      <origin rpy="0 0 0" xyz="0 0 0"/>
      <mass value="1.0"/>
      <inertia ixx="1.0" ixy="0.0" ixz="0.0" iyy="1.0" iyz="0.0" izz="1.0"/>
    </inertial>
    <visual>
      <origin rpy="3.725292518907963e-09 4.752096458560118e-07 9.030221548300688e-08" xyz="2.837136321431899e-07 -1.80778812364224e-07 0.013210158795118332"/>
      <geometry>
        <mesh filename="model://arm_robot-mit_VISCOL/meshes/VIS_hollie_real.012.dae"/>
      </geometry>
    </visual>
    <collision>
      <origin xyz="2.837136321431899e-07 -1.80778812364224e-07 0.013210158795118332"/>
      <geometry>
        <mesh filename="model://arm_robot-mit_VISCOL/collisions/COL_hollie_real.012.dae"/>
      </geometry>
    </collision>
  </link>
  <link name="hollie_real.013">
    <inertial>
      <origin rpy="0 0 0" xyz="0 0 0"/>
      <mass value="1.0"/>
      <inertia ixx="1.0" ixy="0.0" ixz="0.0" iyy="1.0" iyz="0.0" izz="1.0"/>
    </inertial>
    <visual>
      <origin rpy="-2.771615982055664e-06 -6.431557864061688e-08 7.523104983420126e-08" xyz="-5.685739665750589e-07 4.896907057627686e-08 1.0221791058029339e-07"/>
      <geometry>
        <mesh filename="model://arm_robot-mit_VISCOL/meshes/VIS_hollie_real.013.dae"/>
      </geometry>
    </visual>
    <collision>
      <origin xyz="-5.685739665750589e-07 4.896907057627686e-08 1.0221791058029339e-07"/>
      <geometry>
        <mesh filename="model://arm_robot-mit_VISCOL/collisions/COL_hollie_real.013.dae"/>
      </geometry>
    </collision>
  </link>
  <link name="hollie_real.014">
    <inertial>
      <origin rpy="0 0 0" xyz="0 0 0"/>
      <mass value="1.0"/>
      <inertia ixx="1.0" ixy="0.0" ixz="0.0" iyy="1.0" iyz="0.0" izz="1.0"/>
    </inertial>
    <visual>
      <origin rpy="-2.4065375328063965e-06 4.623149152394035e-08 7.506766763754058e-08" xyz="-2.5232056444224327e-08 -3.5639777706819586e-07 4.701361433490092e-08"/>
      <geometry>
        <mesh filename="model://arm_robot-mit_VISCOL/meshes/VIS_hollie_real.014.dae"/>
      </geometry>
    </visual>
    <collision>
      <origin xyz="-2.5232056444224327e-08 -3.5639777706819586e-07 4.701361433490092e-08"/>
      <geometry>
        <mesh filename="model://arm_robot-mit_VISCOL/collisions/COL_hollie_real.014.dae"/>
      </geometry>
    </collision>
  </link>
  <link name="hollie_real.015">
    <inertial>
      <origin rpy="0 0 0" xyz="0 0 0"/>
      <mass value="1.0"/>
      <inertia ixx="1.0" ixy="0.0" ixz="0.0" iyy="1.0" iyz="0.0" izz="1.0"/>
    </inertial>
    <visual>
      <origin rpy="-2.771615982055664e-06 3.999253905817568e-08 -4.397823971657999e-08" xyz="-2.6365052008259227e-07 1.0484615131645114e-07 -3.668480701435328e-07"/>
      <geometry>
        <mesh filename="model://arm_robot-mit_VISCOL/meshes/VIS_hollie_real.015.dae"/>
      </geometry>
    </visual>
    <collision>
      <origin xyz="-2.6365052008259227e-07 1.0484615131645114e-07 -3.668480701435328e-07"/>
      <geometry>
        <mesh filename="model://arm_robot-mit_VISCOL/collisions/COL_hollie_real.015.dae"/>
      </geometry>
    </collision>
  </link>
  <link name="hollie_real.016">
    <inertial>
      <origin rpy="0 0 0" xyz="0 0 0"/>
      <mass value="1.0"/>
      <inertia ixx="1.0" ixy="0.0" ixz="0.0" iyy="1.0" iyz="0.0" izz="1.0"/>
    </inertial>
    <visual>
      <origin rpy="1.1920928955078125e-07 3.4871314369411266e-07 9.654112176349372e-08" xyz="-8.036762011442988e-08 -9.822284710025997e-07 0.013210076838731766"/>
      <geometry>
        <mesh filename="model://arm_robot-mit_VISCOL/meshes/VIS_hollie_real.016.dae"/>
      </geometry>
    </visual>
    <collision>
      <origin xyz="-8.036762011442988e-08 -9.822284710025997e-07 0.013210076838731766"/>
      <geometry>
        <mesh filename="model://arm_robot-mit_VISCOL/collisions/COL_hollie_real.016.dae"/>
      </geometry>
    </collision>
  </link>
  <link name="hollie_real.017">
    <inertial>
      <origin rpy="0 0 0" xyz="0 0 0"/>
      <mass value="1.0"/>
      <inertia ixx="1.0" ixy="0.0" ixz="0.0" iyy="1.0" iyz="0.0" izz="1.0"/>
    </inertial>
    <visual>
      <origin rpy="5.811452865600586e-07 -5.807660130585646e-08 1.942769642937492e-07" xyz="-9.406928569433148e-08 1.1807316013801028e-07 -6.557622214131698e-07"/>
      <geometry>
        <mesh filename="model://arm_robot-mit_VISCOL/meshes/VIS_hollie_real.017.dae"/>
      </geometry>
    </visual>
    <collision>
      <origin xyz="-9.406928569433148e-08 1.1807316013801028e-07 -6.557622214131698e-07"/>
      <geometry>
        <mesh filename="model://arm_robot-mit_VISCOL/collisions/COL_hollie_real.017.dae"/>
      </geometry>
    </collision>
  </link>
  <link name="hollie_real.018">
    <inertial>
      <origin rpy="0 0 0" xyz="0 0 0"/>
      <mass value="1.0"/>
      <inertia ixx="1.0" ixy="0.0" ixz="0.0" iyy="1.0" iyz="0.0" izz="1.0"/>
    </inertial>
    <visual>
      <origin rpy="2.2351743211856956e-07 4.623152349836346e-08 7.506766763754058e-08" xyz="-1.4552476841345197e-06 6.338601110655873e-07 -4.306432970224705e-07"/>
      <geometry>
        <mesh filename="model://arm_robot-mit_VISCOL/meshes/VIS_hollie_real.018.dae"/>
      </geometry>
    </visual>
    <collision>
      <origin xyz="-1.4552476841345197e-06 6.338601110655873e-07 -4.306432970224705e-07"/>
      <geometry>
        <mesh filename="model://arm_robot-mit_VISCOL/collisions/COL_hollie_real.018.dae"/>
      </geometry>
    </collision>
  </link>
  <link name="hollie_real.019">
    <inertial>
      <origin rpy="0 0 0" xyz="0 0 0"/>
      <mass value="1.0"/>
      <inertia ixx="1.0" ixy="0.0" ixz="0.0" iyy="1.0" iyz="0.0" izz="1.0"/>
    </inertial>
    <visual>
      <origin rpy="-4.954636096954346e-07 3.375359725055205e-08 -1.6302415417612792e-07" xyz="-2.4736436898820102e-08 -1.6200681329792133e-07 -7.488844744329981e-07"/>
      <geometry>
        <mesh filename="model://arm_robot-mit_VISCOL/meshes/VIS_hollie_real.019.dae"/>
      </geometry>
    </visual>
    <collision>
      <origin xyz="-2.4736436898820102e-08 -1.6200681329792133e-07 -7.488844744329981e-07"/>
      <geometry>
        <mesh filename="model://arm_robot-mit_VISCOL/collisions/COL_hollie_real.019.dae"/>
      </geometry>
    </collision>
  </link>
  <link name="hollie_real.020">
    <inertial>
      <origin rpy="0 0 0" xyz="0 0 0"/>
      <mass value="1.0"/>
      <inertia ixx="1.0" ixy="0.0" ixz="0.0" iyy="1.0" iyz="0.0" izz="1.0"/>
    </inertial>
    <visual>
      <origin rpy="3.141592502593994 -2.3037349805576923e-08 -1.3783574104309082e-07" xyz="0.0006995258154347539 2.0023433933147317e-07 -0.010019376873970032"/>
      <geometry>
        <mesh filename="model://arm_robot-mit_VISCOL/meshes/VIS_hollie_real.020.dae"/>
      </geometry>
    </visual>
    <collision>
      <origin xyz="0.0006995258154347539 2.0023433933147317e-07 -0.010019376873970032"/>
      <geometry>
        <mesh filename="model://arm_robot-mit_VISCOL/collisions/COL_hollie_real.020.dae"/>
      </geometry>
    </collision>
  </link>
  <link name="hollie_real_left_hand_f5_link">
    <inertial>
      <origin rpy="0 0 0" xyz="0 0 0"/>
      <mass value="1.0"/>
      <inertia ixx="1.0" ixy="0.0" ixz="0.0" iyy="1.0" iyz="0.0" izz="1.0"/>
    </inertial>
  </link>
  <link name="hollie_real_left_hand_f6_link">
    <inertial>
      <origin rpy="0 0 0" xyz="0 0 0"/>
      <mass value="1.0"/>
      <inertia ixx="1.0" ixy="0.0" ixz="0.0" iyy="1.0" iyz="0.0" izz="1.0"/>
    </inertial>
  </link>
  <link name="hollie_real_left_hand_f7_link">
    <inertial>
      <origin rpy="0 0 0" xyz="0 0 0"/>
      <mass value="1.0"/>
      <inertia ixx="1.0" ixy="0.0" ixz="0.0" iyy="1.0" iyz="0.0" izz="1.0"/>
    </inertial>
  </link>
  <link name="hollie_real.021">
    <inertial>
      <origin rpy="0 0 0" xyz="0 0 0"/>
      <mass value="1.0"/>
      <inertia ixx="1.0" ixy="0.0" ixz="0.0" iyy="1.0" iyz="0.0" izz="1.0"/>
    </inertial>
    <visual>
      <origin rpy="0.3875390291213989 -5.188393288335647e-07 -1.6926823036556016e-06" xyz="-6.399376388799283e-07 -1.6936860447458457e-06 -0.01321012619882822"/>
      <geometry>
        <mesh filename="model://arm_robot-mit_VISCOL/meshes/VIS_hollie_real.021.dae"/>
      </geometry>
    </visual>
    <collision>
      <origin xyz="-6.399376388799283e-07 -1.6936860447458457e-06 -0.01321012619882822"/>
      <geometry>
        <mesh filename="model://arm_robot-mit_VISCOL/collisions/COL_hollie_real.021.dae"/>
      </geometry>
    </collision>
  </link>
  <link name="hollie_real.022">
    <inertial>
      <origin rpy="0 0 0" xyz="0 0 0"/>
      <mass value="1.0"/>
      <inertia ixx="1.0" ixy="0.0" ixz="0.0" iyy="1.0" iyz="0.0" izz="1.0"/>
    </inertial>
    <visual>
      <origin rpy="2.719462486311386e-07 9.371992604201296e-08 -1.3518211972041172e-07" xyz="6.632314466514799e-07 3.867476152663585e-07 1.8978691684878868e-07"/>
      <geometry>
        <mesh filename="model://arm_robot-mit_VISCOL/meshes/VIS_hollie_real.022.dae"/>
      </geometry>
    </visual>
    <collision>
      <origin xyz="6.632314466514799e-07 3.867476152663585e-07 1.8978691684878868e-07"/>
      <geometry>
        <mesh filename="model://arm_robot-mit_VISCOL/collisions/COL_hollie_real.022.dae"/>
      </geometry>
    </collision>
  </link>
  <link name="hollie_real.023">
    <inertial>
      <origin rpy="0 0 0" xyz="0 0 0"/>
      <mass value="1.0"/>
      <inertia ixx="1.0" ixy="0.0" ixz="0.0" iyy="1.0" iyz="0.0" izz="1.0"/>
    </inertial>
    <visual>
      <origin rpy="-4.470348358154297e-07 5.004722325452349e-08 -9.685036275186576e-07" xyz="-1.4826816823187983e-06 6.916850452398648e-07 1.9924523542158568e-07"/>
      <geometry>
        <mesh filename="model://arm_robot-mit_VISCOL/meshes/VIS_hollie_real.023.dae"/>
      </geometry>
    </visual>
    <collision>
      <origin xyz="-1.4826816823187983e-06 6.916850452398648e-07 1.9924523542158568e-07"/>
      <geometry>
        <mesh filename="model://arm_robot-mit_VISCOL/collisions/COL_hollie_real.023.dae"/>
      </geometry>
    </collision>
  </link>
  <link name="hollie_real.024">
    <inertial>
      <origin rpy="0 0 0" xyz="0 0 0"/>
      <mass value="1.0"/>
      <inertia ixx="1.0" ixy="0.0" ixz="0.0" iyy="1.0" iyz="0.0" izz="1.0"/>
    </inertial>
    <visual>
      <origin rpy="-3.0919909477233887e-07 8.12420068996289e-08 -3.7327390600694343e-07" xyz="-5.291554998620995e-07 -5.106496701046126e-07 5.226092980592512e-07"/>
      <geometry>
        <mesh filename="model://arm_robot-mit_VISCOL/meshes/VIS_hollie_real.024.dae"/>
      </geometry>
    </visual>
    <collision>
      <origin xyz="-5.291554998620995e-07 -5.106496701046126e-07 5.226092980592512e-07"/>
      <geometry>
        <mesh filename="model://arm_robot-mit_VISCOL/collisions/COL_hollie_real.024.dae"/>
      </geometry>
    </collision>
  </link>
  <link name="hollie_real_left_hand_f8_link">
    <inertial>
      <origin rpy="0 0 0" xyz="0 0 0"/>
      <mass value="1.0"/>
      <inertia ixx="1.0" ixy="0.0" ixz="0.0" iyy="1.0" iyz="0.0" izz="1.0"/>
    </inertial>
  </link>
  <link name="hollie_real.025">
    <inertial>
      <origin rpy="0 0 0" xyz="0 0 0"/>
      <mass value="1.0"/>
      <inertia ixx="1.0" ixy="0.0" ixz="0.0" iyy="1.0" iyz="0.0" izz="1.0"/>
    </inertial>
    <visual>
      <origin rpy="0.1913410872220993 -1.294845105803688e-06 -4.381991232094151e-07" xyz="-4.2705092795358723e-08 -5.413465373749204e-07 -0.013209964148700237"/>
      <geometry>
        <mesh filename="model://arm_robot-mit_VISCOL/meshes/VIS_hollie_real.025.dae"/>
      </geometry>
    </visual>
    <collision>
      <origin xyz="-4.2705092795358723e-08 -5.413465373749204e-07 -0.013209964148700237"/>
      <geometry>
        <mesh filename="model://arm_robot-mit_VISCOL/collisions/COL_hollie_real.025.dae"/>
      </geometry>
    </collision>
  </link>
  <link name="hollie_real.026">
    <inertial>
      <origin rpy="0 0 0" xyz="0 0 0"/>
      <mass value="1.0"/>
      <inertia ixx="1.0" ixy="0.0" ixz="0.0" iyy="1.0" iyz="0.0" izz="1.0"/>
    </inertial>
    <visual>
      <origin rpy="-0.05260714516043663 6.876398828126185e-08 -6.11365749136894e-07" xyz="-7.664125405426603e-07 4.999449174647452e-07 -6.275574833125575e-07"/>
      <geometry>
        <mesh filename="model://arm_robot-mit_VISCOL/meshes/VIS_hollie_real.026.dae"/>
      </geometry>
    </visual>
    <collision>
      <origin xyz="-7.664125405426603e-07 4.999449174647452e-07 -6.275574833125575e-07"/>
      <geometry>
        <mesh filename="model://arm_robot-mit_VISCOL/collisions/COL_hollie_real.026.dae"/>
      </geometry>
    </collision>
  </link>
  <link name="hollie_real.027">
    <inertial>
      <origin rpy="0 0 0" xyz="0 0 0"/>
      <mass value="1.0"/>
      <inertia ixx="1.0" ixy="0.0" ixz="0.0" iyy="1.0" iyz="0.0" izz="1.0"/>
    </inertial>
    <visual>
      <origin rpy="-3.1664964694755326e-07 9.995868310852529e-08 -1.6136306513203635e-08" xyz="-2.8972232257729047e-07 8.259053174697328e-08 -4.6175784973456757e-07"/>
      <geometry>
        <mesh filename="model://arm_robot-mit_VISCOL/meshes/VIS_hollie_real.027.dae"/>
      </geometry>
    </visual>
    <collision>
      <origin xyz="-2.8972232257729047e-07 8.259053174697328e-08 -4.6175784973456757e-07"/>
      <geometry>
        <mesh filename="model://arm_robot-mit_VISCOL/collisions/COL_hollie_real.027.dae"/>
      </geometry>
    </collision>
  </link>
  <link name="hollie_real_lef">
    <inertial>
      <origin rpy="0 0 0" xyz="0 0 0"/>
      <mass value="1.0"/>
      <inertia ixx="1.0" ixy="0.0" ixz="0.0" iyy="1.0" iyz="0.0" izz="1.0"/>
    </inertial>
    <visual>
      <origin rpy="0.02001788653433323 8.748081370413274e-08 -2.5422815497222473e-07" xyz="9.022235190059291e-07 -4.653043106372934e-08 -2.1286152218635834e-07"/>
      <geometry>
        <mesh filename="model://arm_robot-mit_VISCOL/meshes/VIS_hollie_real_lef.dae"/>
      </geometry>
    </visual>
    <collision>
      <origin xyz="9.022235190059291e-07 -4.653043106372934e-08 -2.1286152218635834e-07"/>
      <geometry>
        <mesh filename="model://arm_robot-mit_VISCOL/collisions/COL_hollie_real_lef.dae"/>
      </geometry>
    </collision>
  </link>
  <gazebo>
    <plugin filename="libgeneric_controller_plugin.so" name="generic_controller">
      <controller joint_name="hollie_real_base_x_joint">
        <type>position</type>
        <pid>1.0 1.0 1.0</pid>
      </controller>
      <controller joint_name="hollie_real_left_arm_0_joint">
        <type>position</type>
        <pid>1.0 1.0 1.0</pid>
      </controller>
      <controller joint_name="hollie_real_left_arm_1_joint">
        <type>position</type>
        <pid>1.0 1.0 1.0</pid>
      </controller>
      <controller joint_name="hollie_real_left_arm_2_joint">
        <type>position</type>
        <pid>1.0 1.0 1.0</pid>
      </controller>
      <controller joint_name="hollie_real_left_arm_3_joint">
        <type>position</type>
        <pid>1.0 1.0 1.0</pid>
      </controller>
      <controller joint_name="hollie_real_left_arm_4_joint">
        <type>position</type>
        <pid>1.0 1.0 1.0</pid>
      </controller>
      <controller joint_name="hollie_real_left_arm_5_joint">
        <type>position</type>
        <pid>1.0 1.0 1.0</pid>
      </controller>
      <controller joint_name="hollie_real_left_arm_6_joint">
        <type>position</type>
        <pid>1.0 1.0 1.0</pid>
      </controller>
      <controller joint_name="hollie_real_left_hand_base_joint">
        <type>position</type>
        <pid>1.0 1.0 1.0</pid>
      </controller>
      <controller joint_name="hollie_real_left_hand_f4">
        <type>position</type>
        <pid>1.0 1.0 1.0</pid>
      </controller>
      <controller joint_name="hollie_real_left_hand_Thumb_Opposition">
        <type>position</type>
        <pid>1.0 1.0 1.0</pid>
      </controller>
      <controller joint_name="hollie_real_left_hand_Thumb_Helper">
        <type>position</type>
        <pid>1.0 1.0 1.0</pid>
      </controller>
      <controller joint_name="hollie_real_left_hand_Thumb_Flexion">
        <type>position</type>
        <pid>1.0 1.0 1.0</pid>
      </controller>
      <controller joint_name="hollie_real_left_hand_j3">
        <type>position</type>
        <pid>1.0 1.0 1.0</pid>
      </controller>
      <controller joint_name="hollie_real_left_hand_j4">
        <type>position</type>
        <pid>1.0 1.0 1.0</pid>
      </controller>
      <controller joint_name="hollie_real_left_hand_f1">
        <type>position</type>
        <pid>1.0 1.0 1.0</pid>
      </controller>
      <controller joint_name="hollie_real_left_hand_f2">
        <type>position</type>
        <pid>1.0 1.0 1.0</pid>
      </controller>
      <controller joint_name="hollie_real_left_hand_f3">
        <type>position</type>
        <pid>1.0 1.0 1.0</pid>
      </controller>
      <controller joint_name="hollie_real_left_hand_index_spread">
        <type>position</type>
        <pid>1.0 1.0 1.0</pid>
      </controller>
      <controller joint_name="hollie_real_left_hand_Index_Finger_Proximal">
        <type>position</type>
        <pid>1.0 1.0 1.0</pid>
      </controller>
      <controller joint_name="hollie_real_left_hand_Index_Finger_Distal">
        <type>position</type>
        <pid>1.0 1.0 1.0</pid>
      </controller>
      <controller joint_name="hollie_real_left_hand_j14">
        <type>position</type>
        <pid>1.0 1.0 1.0</pid>
      </controller>
      <controller joint_name="hollie_real_left_hand_middle_spread_dummy">
        <type>position</type>
        <pid>1.0 1.0 1.0</pid>
      </controller>
      <controller joint_name="hollie_real_left_hand_Middle_Finger_Proximal">
        <type>position</type>
        <pid>1.0 1.0 1.0</pid>
      </controller>
      <controller joint_name="hollie_real_left_hand_Middle_Finger_Distal">
        <type>position</type>
        <pid>1.0 1.0 1.0</pid>
      </controller>
      <controller joint_name="hollie_real_left_hand_j15">
        <type>position</type>
        <pid>1.0 1.0 1.0</pid>
      </controller>
      <controller joint_name="hollie_real_left_hand_j5">
        <type>position</type>
        <pid>1.0 1.0 1.0</pid>
      </controller>
      <controller joint_name="hollie_real_left_hand_f5">
        <type>position</type>
        <pid>1.0 1.0 1.0</pid>
      </controller>
      <controller joint_name="hollie_real_left_hand_f6">
        <type>position</type>
        <pid>1.0 1.0 1.0</pid>
      </controller>
      <controller joint_name="hollie_real_left_hand_f7">
        <type>position</type>
        <pid>1.0 1.0 1.0</pid>
      </controller>
      <controller joint_name="hollie_real_left_hand_Finger_Spread">
        <type>position</type>
        <pid>1.0 1.0 1.0</pid>
      </controller>
      <controller joint_name="hollie_real_left_hand_Pinky">
        <type>position</type>
        <pid>1.0 1.0 1.0</pid>
      </controller>
      <controller joint_name="hollie_real_left_hand_j13">
        <type>position</type>
        <pid>1.0 1.0 1.0</pid>
      </controller>
      <controller joint_name="hollie_real_left_hand_j17">
        <type>position</type>
        <pid>1.0 1.0 1.0</pid>
      </controller>
      <controller joint_name="hollie_real_left_hand_f8">
        <type>position</type>
        <pid>1.0 1.0 1.0</pid>
      </controller>
      <controller joint_name="hollie_real_left_hand_ring_spread">
        <type>position</type>
        <pid>1.0 1.0 1.0</pid>
      </controller>
      <controller joint_name="hollie_real_left_hand_Ring_Finger">
        <type>position</type>
        <pid>1.0 1.0 1.0</pid>
      </controller>
      <controller joint_name="hollie_real_left_hand_j12">
        <type>position</type>
        <pid>1.0 1.0 1.0</pid>
      </controller>
      <controller joint_name="hollie_real_left_hand_j16">
        <type>position</type>
        <pid>1.0 1.0 1.0</pid>
      </controller>
    </plugin>
  </gazebo>
</robot>
