<?xml version="1.0" ?>
<sdf version="1.6">
	<model name="xylophone">
		<static>true</static>
		<link name="C_3">
			<self_collide>false</self_collide>
			<pose frame="">0.9590000000000001 0.047 0.3069818365204466 0.0 -0.0 0.0</pose>
			<inertial>
				<pose frame="">0.0 0.0 0.0 0 0 0</pose>
				<mass>0.046262938070170255</mass>
				<inertia>
					<ixx>0.004468641590711636</ixx>
					<ixy>-0.0015983216200490234</ixy>
					<ixz>-0.0005116561660459249</ixz>
					<iyy>0.04695823484865622</iyy>
					<iyz>-0.01362002937056699</iyz>
					<izz>0.042613410779438726</izz>
				</inertia>
			</inertial>
			<collision name="C_3_collision">
				<geometry>
					<mesh>
						<uri>model://xylophone/meshes/CAD/C_3.stl</uri>
						<scale>0.001 0.001 0.001</scale>
					</mesh>
				</geometry>
			</collision>
			<visual name="C_3_visual">
				<geometry>
					<mesh>
						<uri>model://xylophone/meshes/CAD/C_3.stl</uri>
						<scale>0.001 0.001 0.001</scale>
					</mesh>
				</geometry>
			</visual>
		</link>
		<link name="A_1">
			<self_collide>false</self_collide>
			<pose frame="">0.566 0.047 0.3352876820319288 0.0 -0.0 0.0</pose>
			<inertial>
				<pose frame="">0.0 0.0 0.0 0 0 0</pose>
				<mass>0.0775205380701704</mass>
				<inertia>
					<ixx>0.009037352961263678</ixx>
					<ixy>-0.0015802331903749663</ixy>
					<ixz>-0.0009361136422652744</ixz>
					<iyy>0.03377664433155821</iyy>
					<iyz>-0.014711379748236306</iyz>
					<izz>0.024946650037388687</izz>
				</inertia>
			</inertial>
			<collision name="A_1_collision">
				<geometry>
					<mesh>
						<uri>model://xylophone/meshes/CAD/A_1.stl</uri>
						<scale>0.001 0.001 0.001</scale>
					</mesh>
				</geometry>
			</collision>
			<visual name="A_1_visual">
				<geometry>
					<mesh>
						<uri>model://xylophone/meshes/CAD/A_1.stl</uri>
						<scale>0.001 0.001 0.001</scale>
					</mesh>
				</geometry>
			</visual>
		</link>
		<link name="A_2">
			<self_collide>false</self_collide>
			<pose frame="">0.8710000000000001 0.047 0.3133200411133485 0.0 -0.0 0.0</pose>
			<inertial>
				<pose frame="">0.0 0.0 0.0 0 0 0</pose>
				<mass>0.05217653807017026</mass>
				<inertia>
					<ixx>0.005259143147316312</ixx>
					<ixy>-0.001637082561278282</ixy>
					<ixz>-0.0005889205091811338</ixz>
					<iyy>0.04477781527656005</iyy>
					<iyz>-0.01423939344321782</iyz>
					<izz>0.03965829473233789</izz>
				</inertia>
			</inertial>
			<collision name="A_2_collision">
				<geometry>
					<mesh>
						<uri>model://xylophone/meshes/CAD/A_2.stl</uri>
						<scale>0.001 0.001 0.001</scale>
					</mesh>
				</geometry>
			</collision>
			<visual name="A_2_visual">
				<geometry>
					<mesh>
						<uri>model://xylophone/meshes/CAD/A_2.stl</uri>
						<scale>0.001 0.001 0.001</scale>
					</mesh>
				</geometry>
			</visual>
		</link>
		<link name="G_2">
			<self_collide>false</self_collide>
			<pose frame="">0.8280000000000002 0.047 0.31641711835760733 0.0 -0.0 0.0</pose>
			<inertial>
				<pose frame="">0.0 0.0 0.0 0 0 0</pose>
				<mass>0.05640053807017019</mass>
				<inertia>
					<ixx>0.005806969898557939</ixx>
					<ixy>-0.0016821713190982523</ixy>
					<ixz>-0.0006428552411394649</ixz>
					<iyy>0.04440463401300784</iyy>
					<iyz>-0.014776819288500827</iyz>
					<izz>0.03874857606154405</izz>
				</inertia>
			</inertial>
			<collision name="G_2_collision">
				<geometry>
					<mesh>
						<uri>model://xylophone/meshes/CAD/G_2.stl</uri>
						<scale>0.001 0.001 0.001</scale>
					</mesh>
				</geometry>
			</collision>
			<visual name="G_2_visual">
				<geometry>
					<mesh>
						<uri>model://xylophone/meshes/CAD/G_2.stl</uri>
						<scale>0.001 0.001 0.001</scale>
					</mesh>
				</geometry>
			</visual>
		</link>
		<link name="D_2">
			<self_collide>false</self_collide>
			<pose frame="">0.6980000000000003 0.047 0.325780375142576 0.0 -0.0 0.0</pose>
			<inertial>
				<pose frame="">0.0 0.0 0.0 0 0 0</pose>
				<mass>0.06696053807017052</mass>
				<inertia>
					<ixx>0.007337686641961435</ixx>
					<ixy>-0.0016834155645446495</ixy>
					<ixz>-0.0007857260248432192</ixz>
					<iyy>0.039878923257399626</iyy>
					<iyz>-0.015226687270864922</iyz>
					<izz>0.03272037192253233</izz>
				</inertia>
			</inertial>
			<collision name="D_2_collision">
				<geometry>
					<mesh>
						<uri>model://xylophone/meshes/CAD/D_2.stl</uri>
						<scale>0.001 0.001 0.001</scale>
					</mesh>
				</geometry>
			</collision>
			<visual name="D_2_visual">
				<geometry>
					<mesh>
						<uri>model://xylophone/meshes/CAD/D_2.stl</uri>
						<scale>0.001 0.001 0.001</scale>
					</mesh>
				</geometry>
			</visual>
		</link>
		<link name="H_1">
			<self_collide>false</self_collide>
			<pose frame="">0.6110000000000001 0.047 0.3320465546832858 0.0 -0.0 0.0</pose>
			<inertial>
				<pose frame="">0.0 0.0 0.0 0 0 0</pose>
				<mass>0.07329653807017017</mass>
				<inertia>
					<ixx>0.008364509295087762</ixx>
					<ixy>-0.0016129576736123596</ixy>
					<ixz>-0.0008765720669925233</ixz>
					<iyy>0.035637812851991975</iyy>
					<iyz>-0.014870511057288687</iyz>
					<izz>0.027469372879998354</izz>
				</inertia>
			</inertial>
			<collision name="H_1_collision">
				<geometry>
					<mesh>
						<uri>model://xylophone/meshes/CAD/H_1.stl</uri>
						<scale>0.001 0.001 0.001</scale>
					</mesh>
				</geometry>
			</collision>
			<visual name="H_1_visual">
				<geometry>
					<mesh>
						<uri>model://xylophone/meshes/CAD/H_1.stl</uri>
						<scale>0.001 0.001 0.001</scale>
					</mesh>
				</geometry>
			</visual>
		</link>
		<link name="C_2">
			<self_collide>false</self_collide>
			<pose frame="">0.655 0.047 0.3288774523868349 0.0 -0.0 0.0</pose>
			<inertial>
				<pose frame="">0.0 0.0 0.0 0 0 0</pose>
				<mass>0.07118453807017067</mass>
				<inertia>
					<ixx>0.007964317282338223</ixx>
					<ixy>-0.0016793107606040576</ixy>
					<ixz>-0.0008432046498673693</ixz>
					<iyy>0.038416942750220645</iyy>
					<iyz>-0.01533436530651601</iyz>
					<izz>0.030643050118976566</izz>
				</inertia>
			</inertial>
			<collision name="C_2_collision">
				<geometry>
					<mesh>
						<uri>model://xylophone/meshes/CAD/C_2.stl</uri>
						<scale>0.001 0.001 0.001</scale>
					</mesh>
				</geometry>
			</collision>
			<visual name="C_2_visual">
				<geometry>
					<mesh>
						<uri>model://xylophone/meshes/CAD/C_2.stl</uri>
						<scale>0.001 0.001 0.001</scale>
					</mesh>
				</geometry>
			</visual>
		</link>
		<link name="F_0">
			<self_collide>false</self_collide>
			<pose frame="">0.17900000000000005 0.047 0.3631613772302587 0.0 -0.0 0.0</pose>
			<inertial>
				<pose frame="">0.0 0.0 0.0 0 0 0</pose>
				<mass>0.11089013807017029</mass>
				<inertia>
					<ixx>0.015412603204139834</ixx>
					<ixy>-0.0007147909246711448</ixy>
					<ixz>-0.0014501944920431332</ixz>
					<iyy>0.018830367324334386</iyy>
					<iyz>-0.007208501504708849</iyz>
					<izz>0.0037143086048886903</izz>
				</inertia>
			</inertial>
			<collision name="F_0_collision">
				<geometry>
					<mesh>
						<uri>model://xylophone/meshes/CAD/F_0.stl</uri>
						<scale>0.001 0.001 0.001</scale>
					</mesh>
				</geometry>
			</collision>
			<visual name="F_0_visual">
				<geometry>
					<mesh>
						<uri>model://xylophone/meshes/CAD/F_0.stl</uri>
						<scale>0.001 0.001 0.001</scale>
					</mesh>
				</geometry>
			</visual>
		</link>
		<link name="H_0">
			<self_collide>false</self_collide>
			<pose frame="">0.30600000000000016 0.047 0.3540141956018662 0.0 -0.0 0.0</pose>
			<inertial>
				<pose frame="">0.0 0.0 0.0 0 0 0</pose>
				<mass>0.09864053807016995</mass>
				<inertia>
					<ixx>0.012944484506039078</ixx>
					<ixy>-0.0010869891113039932</ixy>
					<ixz>-0.0012575558020390233</ixz>
					<iyy>0.022060383927095265</iyy>
					<iyz>-0.010685558784856289</iyz>
					<izz>0.009379704808150329</izz>
				</inertia>
			</inertial>
			<collision name="H_0_collision">
				<geometry>
					<mesh>
						<uri>model://xylophone/meshes/CAD/H_0.stl</uri>
						<scale>0.001 0.001 0.001</scale>
					</mesh>
				</geometry>
			</collision>
			<visual name="H_0_visual">
				<geometry>
					<mesh>
						<uri>model://xylophone/meshes/CAD/H_0.stl</uri>
						<scale>0.001 0.001 0.001</scale>
					</mesh>
				</geometry>
			</visual>
		</link>
		<link name="G_0">
			<self_collide>false</self_collide>
			<pose frame="">0.21999999999999995 0.047 0.360208350090384 0.0 -0.0 0.0</pose>
			<inertial>
				<pose frame="">0.0 0.0 0.0 0 0 0</pose>
				<mass>0.10666613807017078</mass>
				<inertia>
					<ixx>0.014551847976541143</ixx>
					<ixy>-0.0008450586715243968</ixy>
					<ixz>-0.0013836310297981693</ixz>
					<iyy>0.019584347293769257</iyy>
					<iyz>-0.008452846461894106</iyz>
					<izz>0.005317754457922258</izz>
				</inertia>
			</inertial>
			<collision name="G_0_collision">
				<geometry>
					<mesh>
						<uri>model://xylophone/meshes/CAD/G_0.stl</uri>
						<scale>0.001 0.001 0.001</scale>
					</mesh>
				</geometry>
			</collision>
			<visual name="G_0_visual">
				<geometry>
					<mesh>
						<uri>model://xylophone/meshes/CAD/G_0.stl</uri>
						<scale>0.001 0.001 0.001</scale>
					</mesh>
				</geometry>
			</visual>
		</link>
		<link name="F_sharp_1">
			<self_collide>false</self_collide>
			<pose frame="">0.5010000000000001 0.077 0.15956186497844507 0.0 -0.0 0.0</pose>
			<inertial>
				<pose frame="">0.0 0.0 0.0 0 0 0</pose>
				<mass>0.08385653807017032</mass>
				<inertia>
					<ixx>0.002780721261920319</ixx>
					<ixy>-0.0027734000138923513</ixy>
					<ixz>-0.0008832957669564701</ixz>
					<iyy>0.023469748628894383</iyy>
					<iyz>-0.006703551483436315</iyz>
					<izz>0.02142666682764713</izz>
				</inertia>
			</inertial>
			<collision name="F_sharp_1_collision">
				<geometry>
					<mesh>
						<uri>model://xylophone/meshes/CAD/F_sharp_1.stl</uri>
						<scale>0.001 0.001 0.001</scale>
					</mesh>
				</geometry>
			</collision>
			<visual name="F_sharp_1_visual">
				<geometry>
					<mesh>
						<uri>model://xylophone/meshes/CAD/F_sharp_1.stl</uri>
						<scale>0.001 0.001 0.001</scale>
					</mesh>
				</geometry>
			</visual>
		</link>
		<link name="G_1">
			<self_collide>false</self_collide>
			<pose frame="">0.5240000000000001 0.047 0.3383127342239956 0.0 -0.0 0.0</pose>
			<inertial>
				<pose frame="">0.0 0.0 0.0 0 0 0</pose>
				<mass>0.08216693807017006</mass>
				<inertia>
					<ixx>0.009774993260078342</ixx>
					<ixy>-0.0015506206427371855</ixy>
					<ixz>-0.001001147947956296</ixz>
					<iyy>0.032235524372049996</iyy>
					<iyz>-0.01456626339744207</iyz>
					<izz>0.0226803080574658</izz>
				</inertia>
			</inertial>
			<collision name="G_1_collision">
				<geometry>
					<mesh>
						<uri>model://xylophone/meshes/CAD/G_1.stl</uri>
						<scale>0.001 0.001 0.001</scale>
					</mesh>
				</geometry>
			</collision>
			<visual name="G_1_visual">
				<geometry>
					<mesh>
						<uri>model://xylophone/meshes/CAD/G_1.stl</uri>
						<scale>0.001 0.001 0.001</scale>
					</mesh>
				</geometry>
			</visual>
		</link>
		<link name="C_sharo_0">
			<self_collide>false</self_collide>
			<pose frame="">0.06697488781747402 0.06601007319771955 0.16878686053587413 0.0 -0.0 0.0</pose>
			<inertial>
				<pose frame="">0.0 0.0 0.0 0 0 0</pose>
				<mass>0.11976053807017031</mass>
				<inertia>
					<ixx>0.0034595727410071135</ixx>
					<ixy>-0.0005296597823748469</ixy>
					<ixz>-0.0010536802952301279</ixz>
					<iyy>0.003484564993003536</iyy>
					<iyz>-0.0010694804906878584</iyz>
					<izz>0.0010783236166694852</izz>
				</inertia>
			</inertial>
			<collision name="C_sharo_0_collision">
				<geometry>
					<mesh>
						<uri>model://xylophone/meshes/CAD/C_sharo_0.stl</uri>
						<scale>0.001 0.001 0.001</scale>
					</mesh>
				</geometry>
			</collision>
			<visual name="C_sharo_0_visual">
				<geometry>
					<mesh>
						<uri>model://xylophone/meshes/CAD/C_sharo_0.stl</uri>
						<scale>0.001 0.001 0.001</scale>
					</mesh>
				</geometry>
			</visual>
		</link>
		<link name="C_sharp_1">
			<self_collide>false</self_collide>
			<pose frame="">0.37199999999999994 0.077 0.15175184410161838 0.0 -0.0 0.0</pose>
			<inertial>
				<pose frame="">0.0 0.0 0.0 0 0 0</pose>
				<mass>0.09441653807017004</mass>
				<inertia>
					<ixx>0.0029845236280197605</ixx>
					<ixy>-0.002318556027063816</ixy>
					<ixz>-0.0009458205484534187</ixz>
					<iyy>0.015646010234371073</iyy>
					<iyz>-0.005329944811403786</iyz>
					<izz>0.013491976627024378</izz>
				</inertia>
			</inertial>
			<collision name="C_sharp_1_collision">
				<geometry>
					<mesh>
						<uri>model://xylophone/meshes/CAD/C_sharp_1.stl</uri>
						<scale>0.001 0.001 0.001</scale>
					</mesh>
				</geometry>
			</collision>
			<visual name="C_sharp_1_visual">
				<geometry>
					<mesh>
						<uri>model://xylophone/meshes/CAD/C_sharp_1.stl</uri>
						<scale>0.001 0.001 0.001</scale>
					</mesh>
				</geometry>
			</visual>
		</link>
		<link name="G_sharp_1">
			<self_collide>false</self_collide>
			<pose frame="">0.544 0.077 0.16216520527072065 0.0 -0.0 0.0</pose>
			<inertial>
				<pose frame="">0.0 0.0 0.0 0 0 0</pose>
				<mass>0.0796325380701699</mass>
				<inertia>
					<ixx>0.0026815851024128328</ixx>
					<ixy>-0.002859776411448326</ixy>
					<ixz>-0.0008524971225280453</ixz>
					<iyy>0.02590670747605715</iyy>
					<iyz>-0.007025018179372322</iyz>
					<izz>0.023925621610317378</izz>
				</inertia>
			</inertial>
			<collision name="G_sharp_1_collision">
				<geometry>
					<mesh>
						<uri>model://xylophone/meshes/CAD/G_sharp_1.stl</uri>
						<scale>0.001 0.001 0.001</scale>
					</mesh>
				</geometry>
			</collision>
			<visual name="G_sharp_1_visual">
				<geometry>
					<mesh>
						<uri>model://xylophone/meshes/CAD/G_sharp_1.stl</uri>
						<scale>0.001 0.001 0.001</scale>
					</mesh>
				</geometry>
			</visual>
		</link>
		<link name="E_2">
			<self_collide>false</self_collide>
			<pose frame="">0.7419999999999999 0.047 0.32261127284612506 0.0 -0.0 0.0</pose>
			<inertial>
				<pose frame="">0.0 0.0 0.0 0 0 0</pose>
				<mass>0.06315893807017048</mass>
				<inertia>
					<ixx>0.006776682670196654</ixx>
					<ixy>-0.0016879844058792252</ixy>
					<ixz>-0.0007339307279334735</ixz>
					<iyy>0.04147204850015954</iyy>
					<iyz>-0.015119047623901191</iyz>
					<izz>0.03486434072745703</izz>
				</inertia>
			</inertial>
			<collision name="E_2_collision">
				<geometry>
					<mesh>
						<uri>model://xylophone/meshes/CAD/E_2.stl</uri>
						<scale>0.001 0.001 0.001</scale>
					</mesh>
				</geometry>
			</collision>
			<visual name="E_2_visual">
				<geometry>
					<mesh>
						<uri>model://xylophone/meshes/CAD/E_2.stl</uri>
						<scale>0.001 0.001 0.001</scale>
					</mesh>
				</geometry>
			</visual>
		</link>
		<link name="E_1">
			<self_collide>false</self_collide>
			<pose frame="">0.436 0.047 0.34465093881689757 0.0 -0.0 0.0</pose>
			<inertial>
				<pose frame="">0.0 0.0 0.0 0 0 0</pose>
				<mass>0.08850293807017058</mass>
				<inertia>
					<ixx>0.010956638299004577</ixx>
					<ixy>-0.0013896615123592004</ixy>
					<ixz>-0.0010985164794851808</ixz>
					<iyy>0.02767254021815714</iyy>
					<iyz>-0.013299172119386905</iyz>
					<izz>0.016952612880646707</izz>
				</inertia>
			</inertial>
			<collision name="E_1_collision">
				<geometry>
					<mesh>
						<uri>model://xylophone/meshes/CAD/E_1.stl</uri>
						<scale>0.001 0.001 0.001</scale>
					</mesh>
				</geometry>
			</collision>
			<visual name="E_1_visual">
				<geometry>
					<mesh>
						<uri>model://xylophone/meshes/CAD/E_1.stl</uri>
						<scale>0.001 0.001 0.001</scale>
					</mesh>
				</geometry>
			</visual>
		</link>
		<link name="F_sharp_0">
			<self_collide>false</self_collide>
			<pose frame="">0.19799999999999987 0.077 0.14121739733752653 0.0 -0.0 0.0</pose>
			<inertial>
				<pose frame="">0.0 0.0 0.0 0 0 0</pose>
				<mass>0.10666613807016981</mass>
				<inertia>
					<ixx>0.00316549168100438</ixx>
					<ixy>-0.0013941370225257924</ixy>
					<ixz>-0.0009943313781930877</ixz>
					<iyy>0.006890556636698837</iyy>
					<iyz>-0.0029824623548780622</iyz>
					<izz>0.004663261625967515</izz>
				</inertia>
			</inertial>
			<collision name="F_sharp_0_collision">
				<geometry>
					<mesh>
						<uri>model://xylophone/meshes/CAD/F_sharp_0.stl</uri>
						<scale>0.001 0.001 0.001</scale>
					</mesh>
				</geometry>
			</collision>
			<visual name="F_sharp_0_visual">
				<geometry>
					<mesh>
						<uri>model://xylophone/meshes/CAD/F_sharp_0.stl</uri>
						<scale>0.001 0.001 0.001</scale>
					</mesh>
				</geometry>
			</visual>
		</link>
		<link name="D_sharp_0">
			<self_collide>false</self_collide>
			<pose frame="">0.10999999999999989 0.077 0.13588963115798583 0.0 -0.0 0.0</pose>
			<inertial>
				<pose frame="">0.0 0.0 0.0 0 0 0</pose>
				<mass>0.11553653807016968</mass>
				<inertia>
					<ixx>0.0033647858899961565</ixx>
					<ixy>-0.0008389115303613814</ixy>
					<ixz>-0.001036377918318385</ixz>
					<iyy>0.004268184019857178</iyy>
					<iyz>-0.00172700620487318</iyz>
					<izz>0.0019195892705340782</izz>
				</inertia>
			</inertial>
			<collision name="D_sharp_0_collision">
				<geometry>
					<mesh>
						<uri>model://xylophone/meshes/CAD/D_sharp_0.stl</uri>
						<scale>0.001 0.001 0.001</scale>
					</mesh>
				</geometry>
			</collision>
			<visual name="D_sharp_0_visual">
				<geometry>
					<mesh>
						<uri>model://xylophone/meshes/CAD/D_sharp_0.stl</uri>
						<scale>0.001 0.001 0.001</scale>
					</mesh>
				</geometry>
			</visual>
		</link>
		<link name="D_sharp_2">
			<self_collide>false</self_collide>
			<pose frame="">0.72 0.077 0.17282073762980205 0.0 -0.0 0.0</pose>
			<inertial>
				<pose frame="">0.0 0.0 0.0 0 0 0</pose>
				<mass>0.06484853807017024</mass>
				<inertia>
					<ixx>0.002350377922216777</ixx>
					<ixy>-0.003082471999201735</ixy>
					<ixz>-0.000739891962901395</ixz>
					<iyy>0.03569024969689167</iyy>
					<iyz>-0.00806928727922475</iyz>
					<izz>0.03391038022734796</izz>
				</inertia>
			</inertial>
			<collision name="D_sharp_2_collision">
				<geometry>
					<mesh>
						<uri>model://xylophone/meshes/CAD/D_sharp_2.stl</uri>
						<scale>0.001 0.001 0.001</scale>
					</mesh>
				</geometry>
			</collision>
			<visual name="D_sharp_2_visual">
				<geometry>
					<mesh>
						<uri>model://xylophone/meshes/CAD/D_sharp_2.stl</uri>
						<scale>0.001 0.001 0.001</scale>
					</mesh>
				</geometry>
			</visual>
		</link>
		<link name="F_2">
			<self_collide>false</self_collide>
			<pose frame="">0.7860000000000001 0.047 0.31944217054967416 0.0 -0.0 0.0</pose>
			<inertial>
				<pose frame="">0.0 0.0 0.0 0 0 0</pose>
				<mass>0.0610469380701703</mass>
				<inertia>
					<ixx>0.006418349275110676</ixx>
					<ixy>-0.0017283179140210494</ixy>
					<ixz>-0.0007024322664210403</ixz>
					<iyy>0.04405765593494668</iyy>
					<iyz>-0.015327942029051557</iyz>
					<izz>0.03780263688533015</izz>
				</inertia>
			</inertial>
			<collision name="F_2_collision">
				<geometry>
					<mesh>
						<uri>model://xylophone/meshes/CAD/F_2.stl</uri>
						<scale>0.001 0.001 0.001</scale>
					</mesh>
				</geometry>
			</collision>
			<visual name="F_2_visual">
				<geometry>
					<mesh>
						<uri>model://xylophone/meshes/CAD/F_2.stl</uri>
						<scale>0.001 0.001 0.001</scale>
					</mesh>
				</geometry>
			</visual>
		</link>
		<link name="F_1">
			<self_collide>false</self_collide>
			<pose frame="">0.48200000000000004 0.047 0.3413377864160625 0.0 -0.0 0.0</pose>
			<inertial>
				<pose frame="">0.0 0.0 0.0 0 0 0</pose>
				<mass>0.08427893807017009</mass>
				<inertia>
					<ixx>0.010213372765568525</ixx>
					<ixy>-0.001462980436815501</ixy>
					<ixz>-0.0010360519654122112</ixz>
					<iyy>0.02969028626886696</iyy>
					<iyz>-0.01386600000315188</iyz>
					<izz>0.019702335120792572</izz>
				</inertia>
			</inertial>
			<collision name="F_1_collision">
				<geometry>
					<mesh>
						<uri>model://xylophone/meshes/CAD/F_1.stl</uri>
						<scale>0.001 0.001 0.001</scale>
					</mesh>
				</geometry>
			</collision>
			<visual name="F_1_visual">
				<geometry>
					<mesh>
						<uri>model://xylophone/meshes/CAD/F_1.stl</uri>
						<scale>0.001 0.001 0.001</scale>
					</mesh>
				</geometry>
			</visual>
		</link>
		<link name="D_0">
			<self_collide>false</self_collide>
			<pose frame="">0.09200000000000003 0.047 0.36942755677096856 0.0 -0.0 0.0</pose>
			<inertial>
				<pose frame="">0.0 0.0 0.0 0 0 0</pose>
				<mass>0.11722613807017017</mass>
				<inertia>
					<ixx>0.016910654596469177</ixx>
					<ixy>-0.0003883643091120617</ixy>
					<ixz>-0.0015594817057755525</ixz>
					<iyy>0.017759880232879766</iyy>
					<iyz>-0.0039842073976757665</iyz>
					<izz>0.0011627041371047348</izz>
				</inertia>
			</inertial>
			<collision name="D_0_collision">
				<geometry>
					<mesh>
						<uri>model://xylophone/meshes/CAD/D_0.stl</uri>
						<scale>0.001 0.001 0.001</scale>
					</mesh>
				</geometry>
			</collision>
			<visual name="D_0_visual">
				<geometry>
					<mesh>
						<uri>model://xylophone/meshes/CAD/D_0.stl</uri>
						<scale>0.001 0.001 0.001</scale>
					</mesh>
				</geometry>
			</visual>
		</link>
		<link name="D_sharp_1">
			<self_collide>false</self_collide>
			<pose frame="">0.41500000000000004 0.077 0.15435518439389392 0.0 -0.0 0.0</pose>
			<inertial>
				<pose frame="">0.0 0.0 0.0 0 0 0</pose>
				<mass>0.09019253807017003</mass>
				<inertia>
					<ixx>0.002889968225146669</ixx>
					<ixy>-0.002470864318704525</ixy>
					<ixz>-0.0009190209823018652</ixz>
					<iyy>0.018037158073699412</iyy>
					<iyz>-0.005777506812691346</iyz>
					<izz>0.0159405396452258</izz>
				</inertia>
			</inertial>
			<collision name="D_sharp_1_collision">
				<geometry>
					<mesh>
						<uri>model://xylophone/meshes/CAD/D_sharp_1.stl</uri>
						<scale>0.001 0.001 0.001</scale>
					</mesh>
				</geometry>
			</collision>
			<visual name="D_sharp_1_visual">
				<geometry>
					<mesh>
						<uri>model://xylophone/meshes/CAD/D_sharp_1.stl</uri>
						<scale>0.001 0.001 0.001</scale>
					</mesh>
				</geometry>
			</visual>
		</link>
		<link name="H_2">
			<self_collide>false</self_collide>
			<pose frame="">0.914 0.047 0.3102229638690896 0.0 -0.0 0.0</pose>
			<inertial>
				<pose frame="">0.0 0.0 0.0 0 0 0</pose>
				<mass>0.04795253807017022</mass>
				<inertia>
					<ixx>0.0047312969911926265</ixx>
					<ixy>-0.0015789180149794447</ixy>
					<ixz>-0.0005359261131454447</ixz>
					<iyy>0.04473121963173661</iyy>
					<iyz>-0.013597016995717776</iyz>
					<izz>0.04012825589963812</izz>
				</inertia>
			</inertial>
			<collision name="H_2_collision">
				<geometry>
					<mesh>
						<uri>model://xylophone/meshes/CAD/H_2.stl</uri>
						<scale>0.001 0.001 0.001</scale>
					</mesh>
				</geometry>
			</collision>
			<visual name="H_2_visual">
				<geometry>
					<mesh>
						<uri>model://xylophone/meshes/CAD/H_2.stl</uri>
						<scale>0.001 0.001 0.001</scale>
					</mesh>
				</geometry>
			</visual>
		</link>
		<link name="A_sharp_0">
			<self_collide>false</self_collide>
			<pose frame="">0.28400000000000003 0.077 0.14642407792207765 0.0 -0.0 0.0</pose>
			<inertial>
				<pose frame="">0.0 0.0 0.0 0 0 0</pose>
				<mass>0.0986405380701699</mass>
				<inertia>
					<ixx>0.002998958647972093</ixx>
					<ixy>-0.00184924858557173</ixy>
					<ixz>-0.0009534337918963429</ixz>
					<iyy>0.010532560876897051</iyy>
					<iyz>-0.004101874970324101</iyz>
					<izz>0.008401232473598018</izz>
				</inertia>
			</inertial>
			<collision name="A_sharp_0_collision">
				<geometry>
					<mesh>
						<uri>model://xylophone/meshes/CAD/A_sharp_0.stl</uri>
						<scale>0.001 0.001 0.001</scale>
					</mesh>
				</geometry>
			</collision>
			<visual name="A_sharp_0_visual">
				<geometry>
					<mesh>
						<uri>model://xylophone/meshes/CAD/A_sharp_0.stl</uri>
						<scale>0.001 0.001 0.001</scale>
					</mesh>
				</geometry>
			</visual>
		</link>
		<link name="C_1">
			<self_collide>false</self_collide>
			<pose frame="">0.35000000000000003 0.047 0.3508450933054153 0.0 -0.0 0.0</pose>
			<inertial>
				<pose frame="">0.0 0.0 0.0 0 0 0</pose>
				<mass>0.09610613807017017</mass>
				<inertia>
					<ixx>0.012374982490303455</ixx>
					<ixy>-0.0012113556873597092</ixy>
					<ixz>-0.0012142858949303606</ixz>
					<iyy>0.02403066339075229</iyy>
					<iyz>-0.01180140952904279</iyz>
					<izz>0.011912712681142978</izz>
				</inertia>
			</inertial>
			<collision name="C_1_collision">
				<geometry>
					<mesh>
						<uri>model://xylophone/meshes/CAD/C_1.stl</uri>
						<scale>0.001 0.001 0.001</scale>
					</mesh>
				</geometry>
			</collision>
			<visual name="C_1_visual">
				<geometry>
					<mesh>
						<uri>model://xylophone/meshes/CAD/C_1.stl</uri>
						<scale>0.001 0.001 0.001</scale>
					</mesh>
				</geometry>
			</visual>
		</link>
		<link name="D_1">
			<self_collide>false</self_collide>
			<pose frame="">0.39299999999999996 0.047 0.3477480160611564 0.0 -0.0 0.0</pose>
			<inertial>
				<pose frame="">0.0 0.0 0.0 0 0 0</pose>
				<mass>0.09230453807017</mass>
				<inertia>
					<ixx>0.011654930566775962</ixx>
					<ixy>-0.0013063929401274355</ixy>
					<ixz>-0.0011559801872754506</ixz>
					<iyy>0.025798527148172243</iyy>
					<iyz>-0.012614830185825881</iyz>
					<izz>0.014390467952490424</izz>
				</inertia>
			</inertial>
			<collision name="D_1_collision">
				<geometry>
					<mesh>
						<uri>model://xylophone/meshes/CAD/D_1.stl</uri>
						<scale>0.001 0.001 0.001</scale>
					</mesh>
				</geometry>
			</collision>
			<visual name="D_1_visual">
				<geometry>
					<mesh>
						<uri>model://xylophone/meshes/CAD/D_1.stl</uri>
						<scale>0.001 0.001 0.001</scale>
					</mesh>
				</geometry>
			</visual>
		</link>
		<link name="A_0">
			<self_collide>false</self_collide>
			<pose frame="">0.26299999999999996 0.047 0.3571112728461251 0.0 -0.0 0.0</pose>
			<inertial>
				<pose frame="">0.0 0.0 0.0 0 0 0</pose>
				<mass>0.1028645380701703</mass>
				<inertia>
					<ixx>0.013766366551468495</ixx>
					<ixy>-0.0009742336498350126</ixy>
					<ixz>-0.0013228623591391</ixz>
					<iyy>0.020755844962491093</iyy>
					<iyz>-0.009661050597703679</iyz>
					<izz>0.00726457314211674</izz>
				</inertia>
			</inertial>
			<collision name="A_0_collision">
				<geometry>
					<mesh>
						<uri>model://xylophone/meshes/CAD/A_0.stl</uri>
						<scale>0.001 0.001 0.001</scale>
					</mesh>
				</geometry>
			</collision>
			<visual name="A_0_visual">
				<geometry>
					<mesh>
						<uri>model://xylophone/meshes/CAD/A_0.stl</uri>
						<scale>0.001 0.001 0.001</scale>
					</mesh>
				</geometry>
			</visual>
		</link>
		<link name="A_sharp_1">
			<self_collide>false</self_collide>
			<pose frame="">0.5890000000000002 0.077 0.16488963115798577 0.0 -0.0 0.0</pose>
			<inertial>
				<pose frame="">0.0 0.0 0.0 0 0 0</pose>
				<mass>0.07583093807017009</mass>
				<inertia>
					<ixx>0.0026001315650246203</ixx>
					<ixy>-0.002948565258241258</ixy>
					<ixz>-0.0008254447806099445</ixz>
					<iyy>0.028582904923696778</iyy>
					<iyz>-0.007364703141464567</iyz>
					<izz>0.026649846393745215</izz>
				</inertia>
			</inertial>
			<collision name="A_sharp_1_collision">
				<geometry>
					<mesh>
						<uri>model://xylophone/meshes/CAD/A_sharp_1.stl</uri>
						<scale>0.001 0.001 0.001</scale>
					</mesh>
				</geometry>
			</collision>
			<visual name="A_sharp_1_visual">
				<geometry>
					<mesh>
						<uri>model://xylophone/meshes/CAD/A_sharp_1.stl</uri>
						<scale>0.001 0.001 0.001</scale>
					</mesh>
				</geometry>
			</visual>
		</link>
		<link name="C_0">
			<self_collide>false</self_collide>
			<pose frame="">0.04800000000000006 0.047 0.37259665906741946 0.0 -0.0 0.0</pose>
			<inertial>
				<pose frame="">0.0 0.0 0.0 0 0 0</pose>
				<mass>0.12145013807016966</mass>
				<inertia>
					<ixx>0.01786276346648574</ixx>
					<ixy>-0.00020992409761153559</ixy>
					<ixz>-0.0016295125974327455</ixz>
					<iyy>0.01799445747121547</iyy>
					<iyz>-0.0021720843996044835</iyz>
					<izz>0.0004564618494238703</izz>
				</inertia>
			</inertial>
			<collision name="C_0_collision">
				<geometry>
					<mesh>
						<uri>model://xylophone/meshes/CAD/C_0.stl</uri>
						<scale>0.001 0.001 0.001</scale>
					</mesh>
				</geometry>
			</collision>
			<visual name="C_0_visual">
				<geometry>
					<mesh>
						<uri>model://xylophone/meshes/CAD/C_0.stl</uri>
						<scale>0.001 0.001 0.001</scale>
					</mesh>
				</geometry>
			</visual>
		</link>
		<link name="E_0">
			<self_collide>false</self_collide>
			<pose frame="">0.1340000000000001 0.047 0.36640250457890167 0.0 -0.0 0.0</pose>
			<inertial>
				<pose frame="">0.0 0.0 0.0 0 0 0</pose>
				<mass>0.11342453807017015</mass>
				<inertia>
					<ixx>0.016063249225884365</ixx>
					<ixy>-0.0005473200295198604</ixy>
					<ixz>-0.001496568016957458</ixz>
					<iyy>0.017961542096853036</iyy>
					<iyz>-0.005568896428619424</iyz>
					<izz>0.0022016109620628115</izz>
				</inertia>
			</inertial>
			<collision name="E_0_collision">
				<geometry>
					<mesh>
						<uri>model://xylophone/meshes/CAD/E_0.stl</uri>
						<scale>0.001 0.001 0.001</scale>
					</mesh>
				</geometry>
			</collision>
			<visual name="E_0_visual">
				<geometry>
					<mesh>
						<uri>model://xylophone/meshes/CAD/E_0.stl</uri>
						<scale>0.001 0.001 0.001</scale>
					</mesh>
				</geometry>
			</visual>
		</link>
		<link name="C_sharp_2">
			<self_collide>false</self_collide>
			<pose frame="">0.676 0.077 0.17015685454003168 0.0 -0.0 0.0</pose>
			<inertial>
				<pose frame="">0.0 0.0 0.0 0 0 0</pose>
				<mass>0.06949493807017026</mass>
				<inertia>
					<ixx>0.0024755895463835177</ixx>
					<ixy>-0.0031014000482116172</ixy>
					<ixz>-0.0007806634469993412</ixz>
					<iyy>0.03393555778653065</iyy>
					<iyz>-0.007993785063573648</iyz>
					<izz>0.0320713309392202</izz>
				</inertia>
			</inertial>
			<collision name="C_sharp_2_collision">
				<geometry>
					<mesh>
						<uri>model://xylophone/meshes/CAD/C_sharp_2.stl</uri>
						<scale>0.001 0.001 0.001</scale>
					</mesh>
				</geometry>
			</collision>
			<visual name="C_sharp_2_visual">
				<geometry>
					<mesh>
						<uri>model://xylophone/meshes/CAD/C_sharp_2.stl</uri>
						<scale>0.001 0.001 0.001</scale>
					</mesh>
				</geometry>
			</visual>
		</link>
		<link name="G_sharp_0">
			<self_collide>false</self_collide>
			<pose frame="">0.24100000000000005 0.077 0.1438207376298021 0.0 -0.0 0.0</pose>
			<inertial>
				<pose frame="">0.0 0.0 0.0 0 0 0</pose>
				<mass>0.10286453807016993</mass>
				<inertia>
					<ixx>0.003090648588542799</ixx>
					<ixy>-0.001636441327862372</ixy>
					<ixz>-0.0009765768493308498</ixz>
					<iyy>0.00862471336147003</iyy>
					<iyz>-0.003565333494746001</iyz>
					<izz>0.006438835241600288</izz>
				</inertia>
			</inertial>
			<collision name="G_sharp_0_collision">
				<geometry>
					<mesh>
						<uri>model://xylophone/meshes/CAD/G_sharp_0.stl</uri>
						<scale>0.001 0.001 0.001</scale>
					</mesh>
				</geometry>
			</collision>
			<visual name="G_sharp_0_visual">
				<geometry>
					<mesh>
						<uri>model://xylophone/meshes/CAD/G_sharp_0.stl</uri>
						<scale>0.001 0.001 0.001</scale>
					</mesh>
				</geometry>
			</visual>
		</link>
		<link name="G_sharp_2">
			<self_collide>false</self_collide>
			<pose frame="">0.8480000000000001 0.077 0.18057021570913395 0.0 -0.0 0.0</pose>
			<inertial>
				<pose frame="">0.0 0.0 0.0 0 0 0</pose>
				<mass>0.05471093807017026</mass>
				<inertia>
					<ixx>0.0021017141753126526</ixx>
					<ixy>-0.0030630892781868483</ixy>
					<ixz>-0.0006522515415628283</ixz>
					<iyy>0.04121044425832942</iyy>
					<iyz>-0.008377667034681733</iyz>
					<izz>0.03959010199808983</izz>
				</inertia>
			</inertial>
			<collision name="G_sharp_2_collision">
				<geometry>
					<mesh>
						<uri>model://xylophone/meshes/CAD/G_sharp_2.stl</uri>
						<scale>0.001 0.001 0.001</scale>
					</mesh>
				</geometry>
			</collision>
			<visual name="G_sharp_2_visual">
				<geometry>
					<mesh>
						<uri>model://xylophone/meshes/CAD/G_sharp_2.stl</uri>
						<scale>0.001 0.001 0.001</scale>
					</mesh>
				</geometry>
			</visual>
		</link>
		<link name="F_sharp_2">
			<self_collide>false</self_collide>
			<pose frame="">0.806 0.077 0.1780274182143532 0.0 -0.0 0.0</pose>
			<inertial>
				<pose frame="">0.0 0.0 0.0 0 0 0</pose>
				<mass>0.058934938070170244</mass>
				<inertia>
					<ixx>0.0022234634391478333</ixx>
					<ixy>-0.0031360821988525886</ixy>
					<ixz>-0.0006926919287384051</ixz>
					<iyy>0.040257579717000384</iyy>
					<iyz>-0.008456636581751144</iyz>
					<izz>0.03855262841692562</izz>
				</inertia>
			</inertial>
			<collision name="F_sharp_2_collision">
				<geometry>
					<mesh>
						<uri>model://xylophone/meshes/CAD/F_sharp_2.stl</uri>
						<scale>0.001 0.001 0.001</scale>
					</mesh>
				</geometry>
			</collision>
			<visual name="F_sharp_2_visual">
				<geometry>
					<mesh>
						<uri>model://xylophone/meshes/CAD/F_sharp_2.stl</uri>
						<scale>0.001 0.001 0.001</scale>
					</mesh>
				</geometry>
			</visual>
		</link>
		<link name="A_sharp_2">
			<self_collide>false</self_collide>
			<pose frame="">0.892 0.077 0.18323409879890432 0.0 -0.0 0.0</pose>
			<inertial>
				<pose frame="">0.0 0.0 0.0 0 0 0</pose>
				<mass>0.05048693807017009</mass>
				<inertia>
					<ixx>0.0019778487755216937</ixx>
					<ixy>-0.0029733488810555443</ixy>
					<ixz>-0.0006107885165269652</ixz>
					<iyy>0.04193248344868889</iyy>
					<iyz>-0.00825193423992213</iyz>
					<izz>0.04039886636424026</izz>
				</inertia>
			</inertial>
			<collision name="A_sharp_2_collision">
				<geometry>
					<mesh>
						<uri>model://xylophone/meshes/CAD/A_sharp_2.stl</uri>
						<scale>0.001 0.001 0.001</scale>
					</mesh>
				</geometry>
			</collision>
			<visual name="A_sharp_2_visual">
				<geometry>
					<mesh>
						<uri>model://xylophone/meshes/CAD/A_sharp_2.stl</uri>
						<scale>0.001 0.001 0.001</scale>
					</mesh>
				</geometry>
			</visual>
		</link>
		<link name="Rahmen">
			<self_collide>false</self_collide>
			<pose frame="">0.5045000000000001 0.0 0.27950640783566505 0.0 -0.0 0.0</pose>
			<inertial>
				<pose frame="">0.0 0.0 0.0 0 0 0</pose>
				<mass>33.44399151305883</mass>
				<inertia>
					<ixx>2.111848523553803</ixx>
					<ixy>-0.372089901902542</ixy>
					<ixz>-0.17620214928006567</ixz>
					<iyy>12.825581269072549</iyy>
					<iyz>-3.3242190638066083</iyz>
					<izz>10.778784624204897</izz>
				</inertia>
			</inertial>
			<collision name="Rahmen_collision">
				<geometry>
					<mesh>
						<uri>model://xylophone/meshes/CAD/Rahmen.stl</uri>
						<scale>0.001 0.001 0.001</scale>
					</mesh>
				</geometry>
			</collision>
			<visual name="Rahmen_visual">
				<geometry>
					<mesh>
						<uri>model://xylophone/meshes/CAD/Rahmen.stl</uri>
						<scale>0.001 0.001 0.001</scale>
					</mesh>
				</geometry>
			</visual>
		</link>
		<joint name="C_0" type="prismatic">
			<parent>Rahmen</parent>
			<child>C_0</child>
			<pose frame="">0.00011982754286582242 -0.012000000000000002 0.07289669467158262 0 0 0</pose>
			<axis>
				<xyz>0 1 0</xyz>
				<limit>
					<lower>0</lower>
					<upper>0.005</upper>
				</limit>
				<use_parent_model_frame>0</use_parent_model_frame>
			</axis>
		</joint>
		<joint name="D_0" type="prismatic">
			<parent>Rahmen</parent>
			<child>D_0</child>
			<pose frame="">-5.8628435302381375e-05 -0.012000000000000002 0.07005910557563262 0 0 0</pose>
			<axis>
				<xyz>0 1 0</xyz>
				<limit>
					<lower>0</lower>
					<upper>0.005</upper>
				</limit>
				<use_parent_model_frame>0</use_parent_model_frame>
			</axis>
		</joint>
		<joint name="E_0" type="prismatic">
			<parent>Rahmen</parent>
			<child>E_0</child>
			<pose frame="">0.00012472702496548748 -0.012000000000000002 0.06803307636954414 0 0 0</pose>
			<axis>
				<xyz>0 1 0</xyz>
				<limit>
					<lower>0</lower>
					<upper>0.005</upper>
				</limit>
				<use_parent_model_frame>0</use_parent_model_frame>
			</axis>
		</joint>
		<joint name="F_0" type="prismatic">
			<parent>Rahmen</parent>
			<child>F_0</child>
			<pose frame="">-9.811895895730061e-05 -0.012000000000000002 0.06622312232003147 0 0 0</pose>
			<axis>
				<xyz>0 1 0</xyz>
				<limit>
					<lower>0</lower>
					<upper>0.005</upper>
				</limit>
				<use_parent_model_frame>0</use_parent_model_frame>
			</axis>
		</joint>
		<joint name="G_0" type="prismatic">
			<parent>Rahmen</parent>
			<child>G_0</child>
			<pose frame="">-6.8892063984193895e-06 -0.012000000000000002 0.06385203663482372 0 0 0</pose>
			<axis>
				<xyz>0 1 0</xyz>
				<limit>
					<lower>0</lower>
					<upper>0.005</upper>
				</limit>
				<use_parent_model_frame>0</use_parent_model_frame>
			</axis>
		</joint>
		<joint name="A_0" type="prismatic">
			<parent>Rahmen</parent>
			<child>A_0</child>
			<pose frame="">0.0002685919615785437 -0.012000000000000002 0.061761516767463574 0 0 0</pose>
			<axis>
				<xyz>0 1 0</xyz>
				<limit>
					<lower>0</lower>
					<upper>0.005</upper>
				</limit>
				<use_parent_model_frame>0</use_parent_model_frame>
			</axis>
		</joint>
		<joint name="H_0" type="prismatic">
			<parent>Rahmen</parent>
			<child>H_0</child>
			<pose frame="">-1.989724299242823e-06 -0.012000000000000002 0.06008054404049446 0 0 0</pose>
			<axis>
				<xyz>0 1 0</xyz>
				<limit>
					<lower>0</lower>
					<upper>0.005</upper>
				</limit>
				<use_parent_model_frame>0</use_parent_model_frame>
			</axis>
		</joint>
		<joint name="G_1" type="prismatic">
			<parent>Rahmen</parent>
			<child>G_1</child>
			<pose frame="">1.360467714860647e-05 -0.012000000000000002 0.0498440198602691 0 0 0</pose>
			<axis>
				<xyz>0 1 0</xyz>
				<limit>
					<lower>0</lower>
					<upper>0.005</upper>
				</limit>
				<use_parent_model_frame>0</use_parent_model_frame>
			</axis>
		</joint>
		<joint name="A_1" type="prismatic">
			<parent>Rahmen</parent>
			<child>A_1</child>
			<pose frame="">-0.00021258700297444478 -0.012000000000000002 0.04781799065418071 0 0 0</pose>
			<axis>
				<xyz>0 1 0</xyz>
				<limit>
					<lower>0</lower>
					<upper>0.005</upper>
				</limit>
				<use_parent_model_frame>0</use_parent_model_frame>
			</axis>
		</joint>
		<joint name="H_1" type="prismatic">
			<parent>Rahmen</parent>
			<child>H_1</child>
			<pose frame="">-2.5885846507094358e-05 -0.012000000000000002 0.04587152089120444 0 0 0</pose>
			<axis>
				<xyz>0 1 0</xyz>
				<limit>
					<lower>0</lower>
					<upper>0.005</upper>
				</limit>
				<use_parent_model_frame>0</use_parent_model_frame>
			</axis>
		</joint>
		<joint name="C_2" type="prismatic">
			<parent>Rahmen</parent>
			<child>C_2</child>
			<pose frame="">-6.782611121266768e-05 -0.012000000000000002 0.04330696322218138 0 0 0</pose>
			<axis>
				<xyz>0 1 0</xyz>
				<limit>
					<lower>0</lower>
					<upper>0.005</upper>
				</limit>
				<use_parent_model_frame>0</use_parent_model_frame>
			</axis>
		</joint>
		<joint name="D_2" type="prismatic">
			<parent>Rahmen</parent>
			<child>D_2</child>
			<pose frame="">-0.00020189208362708655 -0.012000000000000002 0.04121644335482138 0 0 0</pose>
			<axis>
				<xyz>0 1 0</xyz>
				<limit>
					<lower>0</lower>
					<upper>0.005</upper>
				</limit>
				<use_parent_model_frame>0</use_parent_model_frame>
			</axis>
		</joint>
		<joint name="E_2" type="prismatic">
			<parent>Rahmen</parent>
			<child>E_2</child>
			<pose frame="">-0.00010731663486865273 -0.012000000000000002 0.03933446425311672 0 0 0</pose>
			<axis>
				<xyz>0 1 0</xyz>
				<limit>
					<lower>0</lower>
					<upper>0.005</upper>
				</limit>
				<use_parent_model_frame>0</use_parent_model_frame>
			</axis>
		</joint>
		<joint name="F_2" type="prismatic">
			<parent>Rahmen</parent>
			<child>F_2</child>
			<pose frame="">0.00012377452735350402 -0.012000000000000002 0.037589000864876036 0 0 0</pose>
			<axis>
				<xyz>0 1 0</xyz>
				<limit>
					<lower>0</lower>
					<upper>0.005</upper>
				</limit>
				<use_parent_model_frame>0</use_parent_model_frame>
			</axis>
		</joint>
		<joint name="G_2" type="prismatic">
			<parent>Rahmen</parent>
			<child>G_2</child>
			<pose frame="">3.409856069353623e-05 -0.012000000000000002 0.03542645594532392 0 0 0</pose>
			<axis>
				<xyz>0 1 0</xyz>
				<limit>
					<lower>0</lower>
					<upper>0.005</upper>
				</limit>
				<use_parent_model_frame>0</use_parent_model_frame>
			</axis>
		</joint>
		<joint name="A_2" type="prismatic">
			<parent>Rahmen</parent>
			<child>A_2</child>
			<pose frame="">3.654830174326662e-05 -0.012000000000000002 0.0331994203645003 0 0 0</pose>
			<axis>
				<xyz>0 1 0</xyz>
				<limit>
					<lower>0</lower>
					<upper>0.005</upper>
				</limit>
				<use_parent_model_frame>0</use_parent_model_frame>
			</axis>
		</joint>
		<joint name="H_2" type="prismatic">
			<parent>Rahmen</parent>
			<child>H_2</child>
			<pose frame="">-0.00023403338413473308 -0.012000000000000002 0.031245416210603914 0 0 0</pose>
			<axis>
				<xyz>0 1 0</xyz>
				<limit>
					<lower>0</lower>
					<upper>0.005</upper>
				</limit>
				<use_parent_model_frame>0</use_parent_model_frame>
			</axis>
		</joint>
		<joint name="C_3" type="prismatic">
			<parent>Rahmen</parent>
			<child>C_3</child>
			<pose frame="">-4.733222766830636e-05 -0.012000000000000002 0.029025915020700205 0 0 0</pose>
			<axis>
				<xyz>0 1 0</xyz>
				<limit>
					<lower>0</lower>
					<upper>0.005</upper>
				</limit>
				<use_parent_model_frame>0</use_parent_model_frame>
			</axis>
		</joint>
		<joint name="A_sharp_2" type="prismatic">
			<parent>Rahmen</parent>
			<child>A_sharp_2</child>
			<pose frame="">6.0978041974948383e-05 -0.012000000000000002 0.032235117418680126 0 0 0</pose>
			<axis>
				<xyz>0 1 0</xyz>
				<limit>
					<lower>0</lower>
					<upper>0.005</upper>
				</limit>
				<use_parent_model_frame>0</use_parent_model_frame>
			</axis>
		</joint>
		<joint name="G_sharp_2" type="prismatic">
			<parent>Rahmen</parent>
			<child>G_sharp_2</child>
			<pose frame="">4.197273514051858e-05 -0.012000000000000002 0.033937886855462555 0 0 0</pose>
			<axis>
				<xyz>0 1 0</xyz>
				<limit>
					<lower>0</lower>
					<upper>0.005</upper>
				</limit>
				<use_parent_model_frame>0</use_parent_model_frame>
			</axis>
		</joint>
		<joint name="F_sharp_2" type="prismatic">
			<parent>Rahmen</parent>
			<child>F_sharp_2</child>
			<pose frame="">-0.0002470279963149835 -0.012000000000000002 0.03626923934658606 0 0 0</pose>
			<axis>
				<xyz>0 1 0</xyz>
				<limit>
					<lower>0</lower>
					<upper>0.005</upper>
				</limit>
				<use_parent_model_frame>0</use_parent_model_frame>
			</axis>
		</joint>
		<joint name="D_sharp_2" type="prismatic">
			<parent>Rahmen</parent>
			<child>D_sharp_2</child>
			<pose frame="">-1.9848281516487986e-06 -0.012000000000000002 0.03940112876457438 0 0 0</pose>
			<axis>
				<xyz>0 1 0</xyz>
				<limit>
					<lower>0</lower>
					<upper>0.005</upper>
				</limit>
				<use_parent_model_frame>0</use_parent_model_frame>
			</axis>
		</joint>
		<joint name="C_sharp_2" type="prismatic">
			<parent>Rahmen</parent>
			<child>C_sharp_2</child>
			<pose frame="">0.0001054005336699504 -0.012000000000000002 0.04169304054385155 0 0 0</pose>
			<axis>
				<xyz>0 1 0</xyz>
				<limit>
					<lower>0</lower>
					<upper>0.005</upper>
				</limit>
				<use_parent_model_frame>0</use_parent_model_frame>
			</axis>
		</joint>
		<joint name="A_sharp_1" type="prismatic">
			<parent>Rahmen</parent>
			<child>A_sharp_1</child>
			<pose frame="">-0.00043499060839664595 -0.012000000000000002 0.04595865761992382 0 0 0</pose>
			<axis>
				<xyz>0 1 0</xyz>
				<limit>
					<lower>0</lower>
					<upper>0.005</upper>
				</limit>
				<use_parent_model_frame>0</use_parent_model_frame>
			</axis>
		</joint>
		<joint name="G_sharp_1" type="prismatic">
			<parent>Rahmen</parent>
			<child>G_sharp_1</child>
			<pose frame="">0.0001738179108667026 -0.012000000000000002 0.04772154145345432 0 0 0</pose>
			<axis>
				<xyz>0 1 0</xyz>
				<limit>
					<lower>0</lower>
					<upper>0.005</upper>
				</limit>
				<use_parent_model_frame>0</use_parent_model_frame>
			</axis>
		</joint>
		<joint name="F_sharp_1" type="prismatic">
			<parent>Rahmen</parent>
			<child>F_sharp_1</child>
			<pose frame="">-9.557450717956328e-05 -0.012000000000000002 0.04952359670095115 0 0 0</pose>
			<axis>
				<xyz>0 1 0</xyz>
				<limit>
					<lower>0</lower>
					<upper>0.005</upper>
				</limit>
				<use_parent_model_frame>0</use_parent_model_frame>
			</axis>
		</joint>
		<joint name="G_sharp_0" type="prismatic">
			<parent>Rahmen</parent>
			<child>G_sharp_0</child>
			<pose frame="">-8.628905572006573e-05 -0.012000000000000002 0.061451715199614426 0 0 0</pose>
			<axis>
				<xyz>0 1 0</xyz>
				<limit>
					<lower>0</lower>
					<upper>0.005</upper>
				</limit>
				<use_parent_model_frame>0</use_parent_model_frame>
			</axis>
		</joint>
		<joint name="F_sharp_0" type="prismatic">
			<parent>Rahmen</parent>
			<child>F_sharp_0</child>
			<pose frame="">-1.7944255478816728e-05 -0.012000000000000002 0.06334894274189383 0 0 0</pose>
			<axis>
				<xyz>0 1 0</xyz>
				<limit>
					<lower>0</lower>
					<upper>0.005</upper>
				</limit>
				<use_parent_model_frame>0</use_parent_model_frame>
			</axis>
		</joint>
		<joint name="D_sharp_0" type="prismatic">
			<parent>Rahmen</parent>
			<child>D_sharp_0</child>
			<pose frame="">-0.00014081545498381587 -0.012000000000000002 0.06684081577144456 0 0 0</pose>
			<axis>
				<xyz>0 1 0</xyz>
				<limit>
					<lower>0</lower>
					<upper>0.005</upper>
				</limit>
				<use_parent_model_frame>0</use_parent_model_frame>
			</axis>
		</joint>
		<joint name="C_sharp_0" type="prismatic">
			<parent>Rahmen</parent>
			<child>C_sharo_0</child>
			<pose frame="">-4.7358472216805226e-05 -0.0010100731977195476 0.03380236384355687 0 0 0</pose>
			<axis>
				<xyz>0 1 0</xyz>
				<limit>
					<lower>0</lower>
					<upper>0.005</upper>
				</limit>
				<use_parent_model_frame>0</use_parent_model_frame>
			</axis>
		</joint>
		<joint name="A_sharp_0" type="prismatic">
			<parent>Rahmen</parent>
			<child>A_sharp_0</child>
			<pose frame="">-1.3411305962023335e-05 -0.012000000000000002 0.05955448765733502 0 0 0</pose>
			<axis>
				<xyz>0 1 0</xyz>
				<limit>
					<lower>0</lower>
					<upper>0.005</upper>
				</limit>
				<use_parent_model_frame>0</use_parent_model_frame>
			</axis>
		</joint>
		<joint name="C_1" type="prismatic">
			<parent>Rahmen</parent>
			<child>C_1</child>
			<pose frame="">-0.0001804457024673667 -0.012000000000000002 0.05847159636571753 0 0 0</pose>
			<axis>
				<xyz>0 1 0</xyz>
				<limit>
					<lower>0</lower>
					<upper>0.005</upper>
				</limit>
				<use_parent_model_frame>0</use_parent_model_frame>
			</axis>
		</joint>
		<joint name="D_1" type="prismatic">
			<parent>Rahmen</parent>
			<child>D_1</child>
			<pose frame="">-4.148024795426864e-05 -0.012000000000000002 0.055698497931038635 0 0 0</pose>
			<axis>
				<xyz>0 1 0</xyz>
				<limit>
					<lower>0</lower>
					<upper>0.005</upper>
				</limit>
				<use_parent_model_frame>0</use_parent_model_frame>
			</axis>
		</joint>
		<joint name="E_1" type="prismatic">
			<parent>Rahmen</parent>
			<child>E_1</child>
			<pose frame="">-3.903050690489351e-05 -0.012000000000000002 0.05388100949060544 0 0 0</pose>
			<axis>
				<xyz>0 1 0</xyz>
				<limit>
					<lower>0</lower>
					<upper>0.005</upper>
				</limit>
				<use_parent_model_frame>0</use_parent_model_frame>
			</axis>
		</joint>
		<joint name="F_1" type="prismatic">
			<parent>Rahmen</parent>
			<child>F_1</child>
			<pose frame="">0.00023979635727208403 -0.012000000000000002 0.05173353335289399 0 0 0</pose>
			<axis>
				<xyz>0 1 0</xyz>
				<limit>
					<lower>0</lower>
					<upper>0.005</upper>
				</limit>
				<use_parent_model_frame>0</use_parent_model_frame>
			</axis>
		</joint>
		<joint name="C_sharp_1" type="prismatic">
			<parent>Rahmen</parent>
			<child>C_sharp_1</child>
			<pose frame="">-0.00017298520645525172 -0.012000000000000002 0.055638946977786666 0 0 0</pose>
			<axis>
				<xyz>0 1 0</xyz>
				<limit>
					<lower>0</lower>
					<upper>0.005</upper>
				</limit>
				<use_parent_model_frame>0</use_parent_model_frame>
			</axis>
		</joint>
		<joint name="D_sharp_1" type="prismatic">
			<parent>Rahmen</parent>
			<child>D_sharp_1</child>
			<pose frame="">4.111509330236629e-05 -0.012000000000000002 0.05345927433550903 0 0 0</pose>
			<axis>
				<xyz>0 1 0</xyz>
				<limit>
					<lower>0</lower>
					<upper>0.005</upper>
				</limit>
				<use_parent_model_frame>0</use_parent_model_frame>
			</axis>
		</joint>
	</model>
</sdf>
