<?xml version="1.0" ?>
<sdf version="1.6">
	<model name="roboy_2_0_arm_elbow">
		<link name="lower_arm_left">
			<pose frame="">-0.062174670440439686 0.10714697785709816 0.05286765569319583 0.0 -0.0 0.0</pose>
			<inertial>
				<pose frame="">0.0 0.0 0.0 0 0 0</pose>
				<mass>3.8582284060926453</mass>
				<inertia>
					<ixx>0.18971836897918026</ixx>
					<ixy>-0.0309528235564941</ixy>
					<ixz>0.038514077904953994</ixz>
					<iyy>0.14410096249647508</iyy>
					<iyz>0.005118004224149154</iyz>
					<izz>0.08295756148744363</izz>
				</inertia>
			</inertial>
			<collision name="lower_arm_left_collision">
				<geometry>
					<mesh>
						<uri>model://roboy_2_0_arm_elbow/meshes/CAD/lower_arm_left.stl</uri>
						<scale>0.001 0.001 0.001</scale>
					</mesh>
				</geometry>
			</collision>
			<visual name="lower_arm_left_visual">
				<geometry>
					<mesh>
						<uri>model://roboy_2_0_arm_elbow/meshes/CAD/lower_arm_left.stl</uri>
						<scale>0.001 0.001 0.001</scale>
					</mesh>
				</geometry>
			</visual>
		</link>
		<link name="upper_arm_left">
			<pose frame="">0.26919188699848934 0.5522710766465077 -0.011159413645630624 0.0 -0.0 0.0</pose>
			<inertial>
				<pose frame="">0.0 0.0 0.0 0 0 0</pose>
				<mass>5.639369491412749</mass>
				<inertia>
					<ixx>1.0578982805155832</ixx>
					<ixy>-0.5584768438257014</ixy>
					<ixz>0.01540548720524839</ixz>
					<iyy>0.3110322619087838</iyy>
					<iyz>0.008008248173422642</iyz>
					<izz>1.349885480093592</izz>
				</inertia>
			</inertial>
			<collision name="upper_arm_left_collision">
				<geometry>
					<mesh>
						<uri>model://roboy_2_0_arm_elbow/meshes/CAD/upper_arm_left.stl</uri>
						<scale>0.001 0.001 0.001</scale>
					</mesh>
				</geometry>
			</collision>
			<visual name="upper_arm_left_visual">
				<geometry>
					<mesh>
						<uri>model://roboy_2_0_arm_elbow/meshes/CAD/upper_arm_left.stl</uri>
						<scale>0.001 0.001 0.001</scale>
					</mesh>
				</geometry>
			</visual>
		</link>
		<link name="torso">
			<pose frame="">-0.00499999999999861 0.04650000000000084 -0.005674885790744078 0.0 -0.0 0.0</pose>
			<inertial>
				<pose frame="">0.0 0.0 0.0 0 0 0</pose>
				<mass>1009.4088329334594</mass>
				<inertia>
					<ixx>201.02825499880788</ixx>
					<ixy>-0.24907599639102407</ixy>
					<ixz>-0.41259217549213667</ixz>
					<iyy>390.40795490790646</iyy>
					<iyz>-0.5243784771751449</iyz>
					<izz>200.37906434842714</izz>
				</inertia>
			</inertial>
			<collision name="torso_collision">
				<geometry>
					<mesh>
						<uri>model://roboy_2_0_arm_elbow/meshes/CAD/torso.stl</uri>
						<scale>0.001 0.001 0.001</scale>
					</mesh>
				</geometry>
			</collision>
			<visual name="torso_visual">
				<geometry>
					<mesh>
						<uri>model://roboy_2_0_arm_elbow/meshes/CAD/torso.stl</uri>
						<scale>0.001 0.001 0.001</scale>
					</mesh>
				</geometry>
			</visual>
		</link>
		<link name="shoulder_left_link2">
			<pose frame="">0.2876048416483075 0.5944435631591347 -0.013042466787542933 0.0 -0.0 0.0</pose>
			<inertial>
				<pose frame="">0.0 0.0 0.0 0 0 0</pose>
				<mass>0.006828310129289385</mass>
				<inertia>
					<ixx>0.0024145799992969486</ixx>
					<ixy>-0.001167489727575427</ixy>
					<ixz>5.294387202679595e-05</ixz>
					<iyy>0.0005663596265234957</iyy>
					<iyz>2.5605807844821626e-05</iyz>
					<izz>0.0029780439025690335</izz>
				</inertia>
			</inertial>
			<collision name="shoulder_left_link2_collision">
				<geometry>
					<mesh>
						<uri>model://roboy_2_0_arm_elbow/meshes/CAD/shoulder_left_link2.stl</uri>
						<scale>0.001 0.001 0.001</scale>
					</mesh>
				</geometry>
			</collision>
			<visual name="shoulder_left_link2_visual">
				<geometry>
					<mesh>
						<uri>model://roboy_2_0_arm_elbow/meshes/CAD/shoulder_left_link2.stl</uri>
						<scale>0.001 0.001 0.001</scale>
					</mesh>
				</geometry>
			</visual>
		</link>
		<link name="shoulder_left_link3">
			<pose frame="">0.2876048416483075 0.5944435631591348 -0.013042466787542941 0.0 -0.0 0.0</pose>
			<inertial>
				<pose frame="">0.0 0.0 0.0 0 0 0</pose>
				<mass>0.005913329964322322</mass>
				<inertia>
					<ixx>0.0020798217468755596</ixx>
					<ixy>-0.0010054463742006988</ixy>
					<ixz>4.545728721015062e-05</ixz>
					<iyy>0.00048752696840872773</iyy>
					<iyz>2.198779157620949e-05</iyz>
					<izz>0.0025651650656281387</izz>
				</inertia>
			</inertial>
			<collision name="shoulder_left_link3_collision">
				<geometry>
					<mesh>
						<uri>model://roboy_2_0_arm_elbow/meshes/CAD/shoulder_left_link3.stl</uri>
						<scale>0.001 0.001 0.001</scale>
					</mesh>
				</geometry>
			</collision>
			<visual name="shoulder_left_link3_visual">
				<geometry>
					<mesh>
						<uri>model://roboy_2_0_arm_elbow/meshes/CAD/shoulder_left_link3.stl</uri>
						<scale>0.001 0.001 0.001</scale>
					</mesh>
				</geometry>
			</visual>
		</link>
		<joint name="shoulder_left_axis_1" type="revolute">
			<parent>torso</parent>
			<child>shoulder_left_link2</child>
			<pose frame="">-0.000270200396726068 -0.00011817639554919878 -0.005288740862922948 0 0 0</pose>
			<axis>
				<xyz>0.051010494316667994 0.02231024242210457 0.9984488883025681</xyz>
				<limit>
					<lower>-3.141592653589793</lower>
					<upper>3.141592653589793</upper>
				</limit>
				<use_parent_model_frame>0</use_parent_model_frame>
			</axis>
		</joint>
		<joint name="shoulder_left_axis_2" type="revolute">
			<parent>shoulder_left_link2</parent>
			<child>shoulder_left_link3</child>
			<pose frame="">0.004578533530624433 -0.002000306655299653 -0.00018921943271977827 0 0 0</pose>
			<axis>
				<xyz>-0.9157067061247516 0.40006133105988256 0.03784388654395071</xyz>
				<limit>
					<lower>-3.141592653589793</lower>
					<upper>3.141592653589793</upper>
				</limit>
				<use_parent_model_frame>0</use_parent_model_frame>
			</axis>
		</joint>
		<joint name="shoulder_left_axis_3" type="revolute">
			<parent>shoulder_left_link3</parent>
			<child>upper_arm_left</child>
			<pose frame="">0.013174544123758593 0.030283102900493474 -0.0013497569990229108 0 0 0</pose>
			<axis>
				<xyz>-0.3985964849665964 -0.9162167781009379 0.04083696485553867</xyz>
				<limit>
					<lower>-3.141592653589793</lower>
					<upper>3.141592653589793</upper>
				</limit>
				<use_parent_model_frame>0</use_parent_model_frame>
			</axis>
		</joint>
		<joint name="elbow_left" type="revolute">
			<parent>upper_arm_left</parent>
			<child>lower_arm_left</child>
			<pose frame="">0.20466592542909823 0.19841579881621096 -0.04793978715055786 0 0 0</pose>
			<axis>
				<xyz>0.91711553259892 -0.39841323779271304 0.012883781173668424</xyz>
				<limit>
					<lower>-0.0</lower>
					<upper>1.5707963267948966</upper>
				</limit>
				<use_parent_model_frame>0</use_parent_model_frame>
			</axis>
		</joint>
		<plugin filename="libmyomuscle_plugin.so" name="myomuscle_plugin">
			<myoMuscle name="motor0">
				<link name="torso">
					<viaPoint type="FIXPOINT">0.23757805790055161 0.42944722178973777 0.015492439711174616</viaPoint>
					<viaPoint type="FIXPOINT">0.2718871356728519 0.5683871510708945 0.012838404526322811</viaPoint>
					<viaPoint type="FIXPOINT">0.28894109223784553 0.5762546353826103 0.010689615277497923</viaPoint>
				</link>
				<link name="upper_arm_left">
					<viaPoint type="FIXPOINT">0.008971915210692388 -0.030080267677511898 0.02315513067384921</viaPoint>
				</link>
			</myoMuscle>
			<myoMuscle name="motor1">
				<link name="torso">
					<viaPoint type="FIXPOINT">0.24003539451940126 0.4672940494831832 0.025509439663540263</viaPoint>
				</link>
				<link name="upper_arm_left">
					<viaPoint type="FIXPOINT">-0.02544197435322115 -0.015274648629666389 0.019430592551692376</viaPoint>
				</link>
			</myoMuscle>
			<myoMuscle name="motor2">
				<link name="torso">
					<viaPoint type="FIXPOINT">0.2512180133128348 0.5145590997255809 0.028667405657349203</viaPoint>
				</link>
				<link name="upper_arm_left">
					<viaPoint type="FIXPOINT">-0.008406479233189544 -0.02217147979933763 0.03097151002180964</viaPoint>
				</link>
			</myoMuscle>
			<myoMuscle name="motor3">
				<link name="torso">
					<viaPoint type="FIXPOINT">0.28063665292590523 0.5580004259562044 0.028534400330321574</viaPoint>
				</link>
				<link name="upper_arm_left">
					<viaPoint type="FIXPOINT">0.011203370942538626 -0.031235925708646733 0.019007347717904428</viaPoint>
				</link>
			</myoMuscle>
			<myoMuscle name="motor4">
				<link name="torso">
					<viaPoint type="FIXPOINT">0.30339350272539195 0.5961449530207843 -7.360778653264788e-16</viaPoint>
				</link>
				<link name="upper_arm_left">
					<viaPoint type="FIXPOINT">0.01753440712105295 -0.034842627003797234 -0.00011727322358580539</viaPoint>
				</link>
			</myoMuscle>
			<myoMuscle name="motor5">
				<link name="torso">
					<viaPoint type="FIXPOINT">0.23414595021784673 0.427938701226947 -0.053841948186743455</viaPoint>
					<viaPoint type="FIXPOINT">0.26979225356546843 0.5677688240604152 -0.026839119223290568</viaPoint>
					<viaPoint type="FIXPOINT">0.2865401700456306 0.5761408124917585 -0.026075605770313627</viaPoint>
				</link>
				<link name="upper_arm_left">
					<viaPoint type="FIXPOINT">0.0062024764232587876 -0.03087456072633934 -0.021697203248254002</viaPoint>
				</link>
			</myoMuscle>
			<myoMuscle name="motor6">
				<link name="torso">
					<viaPoint type="FIXPOINT">0.2769871340021255 0.5564042514238009 -0.04289909901328127</viaPoint>
				</link>
				<link name="upper_arm_left">
					<viaPoint type="FIXPOINT">0.0066350450686528005 -0.031102334608566765 -0.022585366976324184</viaPoint>
				</link>
			</myoMuscle>
			<myoMuscle name="motor7">
				<link name="torso">
					<viaPoint type="FIXPOINT">0.24756132617262158 0.5129597900609095 -0.04290640006488961</viaPoint>
				</link>
				<link name="upper_arm_left">
					<viaPoint type="FIXPOINT">-0.013733824420951954 -0.022509175237489104 -0.02860351718637292</viaPoint>
				</link>
			</myoMuscle>
			<myoMuscle name="motor8">
				<link name="torso">
					<viaPoint type="FIXPOINT">0.23617466540192045 0.4656054988488306 -0.05005816161190855</viaPoint>
				</link>
				<link name="upper_arm_left">
					<viaPoint type="FIXPOINT">-0.025949632883207875 -0.015646532449082002 -0.018355690193059996</viaPoint>
				</link>
			</myoMuscle>
			<myoMuscle name="motor10">
				<link name="upper_arm_left">
					<viaPoint type="FIXPOINT">-0.09222260158358574 -0.2062417322395298 0.046467027317421174</viaPoint>
				</link>
				<link name="lower_arm_left">
					<viaPoint type="FIXPOINT">0.2104829804207845 0.17041721666353432 -0.031633802031941466</viaPoint>
				</link>
			</myoMuscle>
			<myoMuscle name="motor9">
				<link name="upper_arm_left">
					<viaPoint type="FIXPOINT">-0.09935716818400096 -0.2294320480850139 -0.022251162854238744</viaPoint>
					<!--<viaPoint type="FIXPOINT">-0.11887118635185258 -0.27190261860939297 -0.024138198158888832</viaPoint>-->
				</link>
				<link name="lower_arm_left">
					<viaPoint type="FIXPOINT">0.21249547 0.17322148 -0.088165266</viaPoint>
				</link>
			</myoMuscle>
		</plugin>
	</model>
</sdf>
