<sdf version="1.6">
    <model name="PaBiRoboy">
        <self_collide>true</self_collide>

        <joint name="fixed in Air" type="revolute">
            <parent>world</parent>
            <child>hip</child>
            <axis>
                <xyz>0.9999999999999951 5.068636417698733e-16 -4.612020293685559e-16</xyz>
                <limit>
                    <lower>0</lower>
                    <upper>0</upper>
                </limit>
                <use_parent_model_frame>0</use_parent_model_frame>
            </axis>
        </joint>

        <link name="hip">
			<pose frame="">0.0 0.0 0.0 1.5707963267948966 -0.0 0.0</pose>
			<inertial>
				<pose frame="">-0.15125821162161793 0.8435193516675794 -0.5044157572562253 0 0 0</pose>
				<mass>4.405541905239567</mass>
				<inertia>
					<ixx>4.313798985370431</ixx>
					<ixy>0.5622255786308064</ixy>
					<ixz>1.8743765144752222</ixz>
					<iyy>1.2586475930136802</iyy>
					<iyz>-0.33644587130654774</iyz>
					<izz>3.2577165443858265</izz>
				</inertia>
			</inertial>
			<collision name="hip_collision">
				<geometry>
					<mesh>
						<uri>model://PaBiRoboy/meshes/CAD/hip.stl</uri>
						<scale>0.001 0.001 0.001</scale>
					</mesh>
				</geometry>
			</collision>
			<visual name="hip_visual">
				<geometry>
					<mesh>
						<uri>model://PaBiRoboy/meshes/CAD/hip.stl</uri>
						<scale>0.001 0.001 0.001</scale>
					</mesh>
				</geometry>
			</visual>
		</link>
		<link name="thigh2">
			<pose frame="">0.0 0.0 0.0 1.5707963267948966 -0.0 0.0</pose>
			<inertial>
				<pose frame="">-0.1500064130667476 0.49904027640246995 -0.4191050675461911 0 0 0</pose>
				<mass>2.32360802336218</mass>
				<inertia>
					<ixx>1.0085621021669475</ixx>
					<ixy>0.17399921351961514</ixy>
					<ixz>0.4867446473572951</ixz>
					<iyy>0.46340216998601674</iyy>
					<iyz>-0.14620573692253305</iyz>
					<izz>0.6502660298470969</izz>
				</inertia>
			</inertial>
			<collision name="thigh2_collision">
				<geometry>
					<mesh>
						<uri>model://PaBiRoboy/meshes/CAD/thigh2.stl</uri>
						<scale>0.001 0.001 0.001</scale>
					</mesh>
				</geometry>
			</collision>
			<visual name="thigh2_visual">
				<geometry>
					<mesh>
						<uri>model://PaBiRoboy/meshes/CAD/thigh2.stl</uri>
						<scale>0.001 0.001 0.001</scale>
					</mesh>
				</geometry>
			</visual>
		</link>
		<link name="shank2">
			<pose frame="">0.0 0.0 0.0 1.5707963267948966 -0.0 0.0</pose>
			<inertial>
				<pose frame="">-0.14997129897898462 0.06867833959161324 -0.3955545220342582 0 0 0</pose>
				<mass>1.8702733137462277</mass>
				<inertia>
					<ixx>0.3230345439739656</ixx>
					<ixy>0.019295738580400342</ixy>
					<ixz>0.05351150205548587</ixz>
					<iyy>0.346407226475997</iyy>
					<iyz>-0.11095117962951102</iyz>
					<izz>0.08083404930300939</izz>
				</inertia>
			</inertial>
			<collision name="shank2_collision">
				<geometry>
					<mesh>
						<uri>model://PaBiRoboy/meshes/CAD/shank2.stl</uri>
						<scale>0.001 0.001 0.001</scale>
					</mesh>
				</geometry>
			</collision>
			<visual name="shank2_visual">
				<geometry>
					<mesh>
						<uri>model://PaBiRoboy/meshes/CAD/shank2.stl</uri>
						<scale>0.001 0.001 0.001</scale>
					</mesh>
				</geometry>
			</visual>
		</link>
		<link name="shank1">
			<pose frame="">0.0 0.0 0.0 1.5707963267948966 -0.0 0.0</pose>
			<inertial>
				<pose frame="">-0.15025660985577624 0.06867833959161293 -0.6124545596777253 0 0 0</pose>
				<mass>1.870273313746213</mass>
				<inertia>
					<ixx>0.7319457828739452</ixx>
					<ixy>0.01933010804512573</ixy>
					<ixz>0.07596494928311523</ixz>
					<iyy>0.7554786582420415</iyy>
					<iyz>-0.17210964455917419</iyz>
					<izz>0.08099424216907215</izz>
				</inertia>
			</inertial>
			<collision name="shank1_collision">
				<geometry>
					<mesh>
						<uri>model://PaBiRoboy/meshes/CAD/shank1.stl</uri>
						<scale>0.001 0.001 0.001</scale>
					</mesh>
				</geometry>
			</collision>
			<visual name="shank1_visual">
				<geometry>
					<mesh>
						<uri>model://PaBiRoboy/meshes/CAD/shank1.stl</uri>
						<scale>0.001 0.001 0.001</scale>
					</mesh>
				</geometry>
			</visual>
		</link>
		<link name="thigh1">
			<pose frame="">0.0 0.0 0.0 1.5707963267948966 -0.0 0.0</pose>
			<inertial>
				<pose frame="">-0.15024683969227431 0.49904027640251786 -0.5889052928097906 0 0 0</pose>
				<mass>2.323608023363278</mass>
				<inertia>
					<ixx>1.4062712213379644</ixx>
					<ixy>0.1742123320949664</ixy>
					<ixz>0.6821166910815772</ixz>
					<iyy>0.8612790275864698</iyy>
					<iyz>-0.20571955931119765</iyz>
					<izz>0.650433768277288</izz>
				</inertia>
			</inertial>
			<collision name="thigh1_collision">
				<geometry>
					<mesh>
						<uri>model://PaBiRoboy/meshes/CAD/thigh1.stl</uri>
						<scale>0.001 0.001 0.001</scale>
					</mesh>
				</geometry>
			</collision>
			<visual name="thigh1_visual">
				<geometry>
					<mesh>
						<uri>model://PaBiRoboy/meshes/CAD/thigh1.stl</uri>
						<scale>0.001 0.001 0.001</scale>
					</mesh>
				</geometry>
			</visual>
		</link>
		<joint name="knee1" type="revolute">
			<parent>thigh1</parent>
			<child>shank1</child>
			<pose frame="">-0.13219042630655004 0.3194244082948523 -0.5889040318805461 0 0 0</pose>
			<axis>
				<xyz>-1.0000000000000002 6.661338147750264e-16 1.9539925233402755e-14</xyz>
				<limit>
					<lower>-1.1344640137963142</lower>
					<upper>1.1344640137963142</upper>
				</limit>
				<use_parent_model_frame>0</use_parent_model_frame>
			</axis>
		</joint>
		<joint name="groin_left" type="revolute">
			<parent>hip</parent>
			<child>thigh1</child>
			<pose frame="">-0.13219042630655092 0.6994244082948515 -0.5889040318805455 0 0 0</pose>
			<axis>
				<xyz>-1.0000000000000002 6.661338147750831e-16 1.2473341541195986e-16</xyz>
				<limit>
					<lower>-1.1344640137963142</lower>
					<upper>1.1344640137963142</upper>
				</limit>
				<use_parent_model_frame>0</use_parent_model_frame>
			</axis>
		</joint>
		<joint name="knee2" type="revolute">
			<parent>thigh2</parent>
			<child>shank2</child>
			<pose frame="">-0.1319499999999862 0.3194244082948532 -0.4191040318805436 0 0 0</pose>
			<axis>
				<xyz>-1.0000000000000002 6.661338147750586e-16 1.9539925233402752e-14</xyz>
				<limit>
					<lower>-1.1344640137963142</lower>
					<upper>1.1344640137963142</upper>
				</limit>
				<use_parent_model_frame>0</use_parent_model_frame>
			</axis>
		</joint>
		<joint name="groin2" type="revolute">
			<parent>hip</parent>
			<child>thigh2</child>
			<pose frame="">-0.13194999999998636 0.6994244082948534 -0.4191040318805435 0 0 0</pose>
			<axis>
				<xyz>-1.0000000000000002 6.66133814775083e-16 8.396061623727715e-16</xyz>
				<limit>
					<lower>-1.1344640137963142</lower>
					<upper>1.1344640137963142</upper>
				</limit>
				<use_parent_model_frame>0</use_parent_model_frame>
			</axis>
		</joint>
		<plugin filename="libmyomuscle_plugin.so" name="myomuscle_plugin">
			<myoMuscle name="motor0">
                <link name="hip">
                    <viaPoint type="FIXPOINT">-0.14987304541315427 0.8260657269708438 -0.6230649090956234</viaPoint>
                </link>
                <link name="thigh1">
                    <viaPoint type="FIXPOINT">-0.14873668348497077 0.6994244082948515 -0.6069040318805452</viaPoint>
                </link>
                <spanningJoint name="groin1">flexor</spanningJoint>
			</myoMuscle>
			<myoMuscle name="motor1">
                <link name="hip">
                    <viaPoint type="FIXPOINT">-0.14967304541315266 0.8006650192418192 -0.5555743433353161</viaPoint>
                </link>
                <link name="thigh1">
                    <viaPoint type="FIXPOINT">-0.1528696790131815 0.6994244082948515 -0.5699040318805452</viaPoint>
                </link>
                <spanningJoint name="groin1">extensor</spanningJoint>
			</myoMuscle>
			<myoMuscle name="motor2">
                <link name="hip">
                    <viaPoint type="FIXPOINT">-0.14961249293535375 0.8016650205245989 -0.4534256566646845</viaPoint>
                </link>
                <link name="thigh2">
                    <viaPoint type="FIXPOINT">-0.15262925270661692 0.6994244082948534 -0.4371040318805431</viaPoint>
                </link>
                <spanningJoint name="groin2">flexor</spanningJoint>
			</myoMuscle>
			<myoMuscle name="motor3">
                <link name="hip">
                    <viaPoint type="FIXPOINT">-0.15315193919234 0.8270652140318927 -0.3859065975460083</viaPoint>
                </link>
                <link name="thigh2">
                    <viaPoint type="FIXPOINT">-0.15262925270661692 0.6994244082948534 -0.40110403188054317</viaPoint>
                </link>
                <spanningJoint name="groin2">extensor</spanningJoint>
			</myoMuscle>
			<myoMuscle name="motor4">
                <link name="thigh1">
                    <viaPoint type="FIXPOINT">-0.15049042630655085 0.4300398008330037 -0.6246249836954886</viaPoint>
                </link>
                <link name="shank1">
                    <viaPoint type="FIXPOINT">-0.1528696790131806 0.3194244082948523 -0.6069040318805462</viaPoint>
                </link>
                <spanningJoint name="knee1">flexor</spanningJoint>
			</myoMuscle>
			<myoMuscle name="motor5">
                <link name="thigh1">
                    <viaPoint type="FIXPOINT">-0.14843319548080247 0.45676853156612246 -0.5551587490003942</viaPoint>
                </link>
                <link name="shank1">
                    <viaPoint type="FIXPOINT">-0.15319042630654997 0.3194244082948523 -0.5709040318805463</viaPoint>
                </link>
                <spanningJoint name="knee1">extensor</spanningJoint>
			</myoMuscle>
			<myoMuscle name="motor6">
                <link name="thigh2">
                    <viaPoint type="FIXPOINT">-0.15173221543122778 0.4567680186606401 -0.4528778081190668</viaPoint>
                </link>
                <link name="shank2">
                    <viaPoint type="FIXPOINT">-0.15262925270661679 0.3194244082948532 -0.4371040318805436</viaPoint>
                </link>
                <spanningJoint name="knee2">flexor</spanningJoint>
			</myoMuscle>
			<myoMuscle name="motor7">
                <link name="thigh2">
                    <viaPoint type="FIXPOINT">-0.14757331585826142 0.43003980083300436 -0.38423436635631497</viaPoint>
                </link>
                <link name="shank2">
                    <viaPoint type="FIXPOINT">-0.15262925270661679 0.3194244082948532 -0.40110403188054367</viaPoint>
                </link>
                <spanningJoint name="knee2">extensor</spanningJoint>
			</myoMuscle>
		</plugin>
    </model>
</sdf>
