<?xml version="1.0" ?>
<sdf version="1.6">
	<model name="PaBiRoboy">
		<link name="Hip">
			<pose frame="">0.0 0.0 0.0 1.5707963267948966 -0.0 0.0</pose>
			<inertial>
				<pose frame="">-0.15125821162161793 0.8435193516675794 -0.5044157572562253 0 0 0</pose>
				<mass>4.405541905239567</mass>
				<inertia>
					<ixx>4.313798985370431</ixx>
					<ixy>0.5622255786308064</ixy>
					<ixz>1.8743765144752222</ixz>
					<iyy>1.2586475930136802</iyy>
					<iyz>-0.33644587130654774</iyz>
					<izz>3.2577165443858265</izz>
				</inertia>
			</inertial>
			<collision name="Hip_collision">
				<geometry>
					<mesh>
						<uri>model://PaBiRoboy/meshes/Hip.stl</uri>
						<scale>0.001 0.001 0.001</scale>
					</mesh>
				</geometry>
			</collision>
			<visual name="Hip_visual">
				<geometry>
					<mesh>
						<uri>model://PaBiRoboy/meshes/Hip.stl</uri>
						<scale>0.001 0.001 0.001</scale>
					</mesh>
				</geometry>
			</visual>
		</link>
		<link name="Thigh_2">
			<pose frame="">0.0 0.0 0.0 1.5707963267948966 -0.0 0.0</pose>
			<inertial>
				<pose frame="">-0.1500064130667476 0.49904027640246995 -0.4191050675461911 0 0 0</pose>
				<mass>2.32360802336218</mass>
				<inertia>
					<ixx>1.0085621021669475</ixx>
					<ixy>0.17399921351961514</ixy>
					<ixz>0.4867446473572951</ixz>
					<iyy>0.46340216998601674</iyy>
					<iyz>-0.14620573692253305</iyz>
					<izz>0.6502660298470969</izz>
				</inertia>
			</inertial>
			<collision name="Thigh_2_collision">
				<geometry>
					<mesh>
						<uri>model://PaBiRoboy/meshes/Thigh_2.stl</uri>
						<scale>0.001 0.001 0.001</scale>
					</mesh>
				</geometry>
			</collision>
			<visual name="Thigh_2_visual">
				<geometry>
					<mesh>
						<uri>model://PaBiRoboy/meshes/Thigh_2.stl</uri>
						<scale>0.001 0.001 0.001</scale>
					</mesh>
				</geometry>
			</visual>
		</link>
		<link name="Shank_2">
			<pose frame="">0.0 0.0 0.0 1.5707963267948966 -0.0 0.0</pose>
			<inertial>
				<pose frame="">-0.14997129897898462 0.06867833959161324 -0.3955545220342582 0 0 0</pose>
				<mass>1.8702733137462277</mass>
				<inertia>
					<ixx>0.3230345439739656</ixx>
					<ixy>0.019295738580400342</ixy>
					<ixz>0.05351150205548587</ixz>
					<iyy>0.346407226475997</iyy>
					<iyz>-0.11095117962951102</iyz>
					<izz>0.08083404930300939</izz>
				</inertia>
			</inertial>
			<collision name="Shank_2_collision">
				<geometry>
					<mesh>
						<uri>model://PaBiRoboy/meshes/Shank_2.stl</uri>
						<scale>0.001 0.001 0.001</scale>
					</mesh>
				</geometry>
			</collision>
			<visual name="Shank_2_visual">
				<geometry>
					<mesh>
						<uri>model://PaBiRoboy/meshes/Shank_2.stl</uri>
						<scale>0.001 0.001 0.001</scale>
					</mesh>
				</geometry>
			</visual>
		</link>
		<link name="Shank_1">
			<pose frame="">0.0 0.0 0.0 1.5707963267948966 -0.0 0.0</pose>
			<inertial>
				<pose frame="">-0.15025660985577624 0.06867833959161293 -0.6124545596777253 0 0 0</pose>
				<mass>1.870273313746213</mass>
				<inertia>
					<ixx>0.7319457828739452</ixx>
					<ixy>0.01933010804512573</ixy>
					<ixz>0.07596494928311523</ixz>
					<iyy>0.7554786582420415</iyy>
					<iyz>-0.17210964455917419</iyz>
					<izz>0.08099424216907215</izz>
				</inertia>
			</inertial>
			<collision name="Shank_1_collision">
				<geometry>
					<mesh>
						<uri>model://PaBiRoboy/meshes/Shank_1.stl</uri>
						<scale>0.001 0.001 0.001</scale>
					</mesh>
				</geometry>
			</collision>
			<visual name="Shank_1_visual">
				<geometry>
					<mesh>
						<uri>model://PaBiRoboy/meshes/Shank_1.stl</uri>
						<scale>0.001 0.001 0.001</scale>
					</mesh>
				</geometry>
			</visual>
		</link>
		<link name="Thigh_1">
			<pose frame="">0.0 0.0 0.0 1.5707963267948966 -0.0 0.0</pose>
			<inertial>
				<pose frame="">-0.15024683969227431 0.49904027640251786 -0.5889052928097906 0 0 0</pose>
				<mass>2.323608023363278</mass>
				<inertia>
					<ixx>1.4062712213379644</ixx>
					<ixy>0.1742123320949664</ixy>
					<ixz>0.6821166910815772</ixz>
					<iyy>0.8612790275864698</iyy>
					<iyz>-0.20571955931119765</iyz>
					<izz>0.650433768277288</izz>
				</inertia>
			</inertial>
			<collision name="Thigh_1_collision">
				<geometry>
					<mesh>
						<uri>model://PaBiRoboy/meshes/Thigh_1.stl</uri>
						<scale>0.001 0.001 0.001</scale>
					</mesh>
				</geometry>
			</collision>
			<visual name="Thigh_1_visual">
				<geometry>
					<mesh>
						<uri>model://PaBiRoboy/meshes/Thigh_1.stl</uri>
						<scale>0.001 0.001 0.001</scale>
					</mesh>
				</geometry>
			</visual>
		</link>
		<joint name="Groin_2" type="revolute">
			<parent>Hip</parent>
			<child>Thigh_2</child>
			<pose frame="">-0.13194999999998636 0.6994244082948534 -0.4191040318805435 0 0 0</pose>
			<axis>
				<xyz>-1.0000000000000002 6.66133814775083e-16 8.396061623727715e-16</xyz>
				<limit>
					<lower>-1.1344640137963142</lower>
					<upper>1.1344640137963142</upper>
				</limit>
				<use_parent_model_frame>0</use_parent_model_frame>
			</axis>
		</joint>
		<joint name="Knee_1" type="revolute">
			<parent>Thigh_1</parent>
			<child>Shank_1</child>
			<pose frame="">-0.13219042630655004 0.3194244082948523 -0.5889040318805461 0 0 0</pose>
			<axis>
				<xyz>-1.0000000000000002 6.661338147750264e-16 1.9539925233402755e-14</xyz>
				<limit>
					<lower>-1.1344640137963142</lower>
					<upper>1.1344640137963142</upper>
				</limit>
				<use_parent_model_frame>0</use_parent_model_frame>
			</axis>
		</joint>
		<joint name="Groin_1" type="revolute">
			<parent>Hip</parent>
			<child>Thigh_1</child>
			<pose frame="">-0.13219042630655092 0.6994244082948515 -0.5889040318805455 0 0 0</pose>
			<axis>
				<xyz>-1.0000000000000002 6.661338147750831e-16 1.2473341541195986e-16</xyz>
				<limit>
					<lower>-1.1344640137963142</lower>
					<upper>1.1344640137963142</upper>
				</limit>
				<use_parent_model_frame>0</use_parent_model_frame>
			</axis>
		</joint>
		<joint name="Knee_2" type="revolute">
			<parent>Thigh_2</parent>
			<child>Shank_2</child>
			<pose frame="">-0.1319499999999862 0.3194244082948532 -0.4191040318805436 0 0 0</pose>
			<axis>
				<xyz>-1.0000000000000002 6.661338147750586e-16 1.9539925233402752e-14</xyz>
				<limit>
					<lower>-1.1344640137963142</lower>
					<upper>1.1344640137963142</upper>
				</limit>
				<use_parent_model_frame>0</use_parent_model_frame>
			</axis>
		</joint>
	</model>
</sdf>
