<?xml version="1.0" ?>
<sdf version="1.6">
	<model name="nst_arm">
		<link name="base">
			<pose frame="">0.2318776307046543 -0.0004091653878194841 -0.19994945208141934 0.0 -0.0 0.0</pose>
			<inertial>
				<pose frame="">0.0 0.0 0.0 0 0 0</pose>
				<mass>4.577961140921004</mass>
				<inertia>
					<ixx>0.6964976209856898</ixx>
					<ixy>0.004041223051748183</ixy>
					<ixz>-0.005206946489626654</ixz>
					<iyy>1.0200578188137344</iyy>
					<iyz>0.33124472614717915</iyz>
					<izz>0.3252572774699202</izz>
				</inertia>
			</inertial>
			<!-- <collision name="base_collision">
				<geometry>
					<mesh>
						<uri>model://nst_arm/meshes/CAD/base.stl</uri>
						<scale>0.001 0.001 0.001</scale>
					</mesh>
				</geometry>
			</collision> -->
			<visual name="base_visual">
				<geometry>
					<mesh>
						<uri>model://nst_arm/meshes/CAD/base.stl</uri>
						<scale>0.001 0.001 0.001</scale>
					</mesh>
				</geometry>
			</visual>
		</link>
		<link name="lower_arm">
			<pose frame="">0.10591533731110124 0.006953888748240781 -0.15347161377806026 0.0 -0.0 0.0</pose>
			<inertial>
				<pose frame="">0.0 0.0 0.0 0 0 0</pose>
				<mass>1.7573168608238436</mass>
				<inertia>
					<ixx>0.4991</ixx>
					<ixy>-0.316</ixy>
					<ixz>0.041</ixz>
					<iyy>0.2367</iyy>
					<iyz>0.0264</iyz>
					<izz>0.7157</izz>
				</inertia>
			</inertial>
			<!-- <collision name="lower_arm_collision">
				<geometry>
					<mesh>
						<uri>model://nst_arm/meshes/CAD/upper_arm.stl</uri>
						<scale>0.001 0.001 0.001</scale>
					</mesh>
				</geometry>
			</collision> -->
			<visual name="lower_arm_visual">
				<geometry>
					<mesh>
						<uri>model://nst_arm/meshes/CAD/lower_arm.stl</uri>
						<scale>0.001 0.001 0.001</scale>
					</mesh>
				</geometry>
			</visual>
		</link>
		<link name="upper_arm">
			<pose frame="">0.14498270117118414 0.3494536197891962 -0.08816107004258289 0.0 -0.0 0.0</pose>
			<inertial>
				<pose frame="">0.0 0.0 0.0 0 0 0</pose>
				<mass>0.7435346715572437</mass>
				<inertia>
					<ixx>1.0</ixx>
					<ixy>0.0</ixy>
					<ixz>0.0</ixz>
					<iyy>1.0</iyy>
					<iyz>0.0</iyz>
					<izz>1.0</izz>
				</inertia>
			</inertial>
			<!-- <collision name="upper_arm_collision">
				<geometry>
					<mesh>
						<uri>model://nst_arm/meshes/CAD/upper_arm.stl</uri>
						<scale>0.001 0.001 0.001</scale>
					</mesh>
				</geometry>
			</collision> -->
			<visual name="upper_arm_visual">
				<geometry>
					<mesh>
						<uri>model://nst_arm/meshes/CAD/upper_arm.stl</uri>
						<scale>0.001 0.001 0.001</scale>
					</mesh>
				</geometry>
			</visual>
		</link>
		<joint name="lower_joint" type="revolute">
			<parent>lower_arm</parent>
			<child>base</child>
			<pose frame="">0.025622369295345705 0.04106982555646907 -0.10205054791858068 0 0 0</pose>
			<axis>
				<xyz>-1.0 8.88178419700125e-16 -2.38764662138316e-16</xyz>
				<limit>
					<lower>-1.0471975511965976</lower>
					<upper>1.0471975511965976</upper>
				</limit>
				<use_parent_model_frame>0</use_parent_model_frame>
			</axis>
		</joint>
		<joint name="upper_joint" type="revolute">
			<parent>lower_arm</parent>
			<child>upper_arm</child>
			<pose frame="">0.09621729882881531 0.11743501178148627 -0.2107932407611552 0 0 0</pose>
			<axis>
				<xyz>1.0000000000000002 -9.575673587391975e-16 8.881784197001252e-16</xyz>
				<limit>
					<lower>-1.5707963267948966</lower>
					<upper>1.5707963267948966</upper>
				</limit>
				<use_parent_model_frame>0</use_parent_model_frame>
			</axis>
		</joint>
		<joint name="HoldingFrame" type="fixed">
			<parent>world</parent>
			<child>base</child>
			<axis>
				<xyz>1.0 2.0 2.0</xyz>
				<use_parent_model_frame>true</use_parent_model_frame>
			</axis>
		</joint>
		<!-- <plugin filename="libmyomuscle_plugin.so" name="myomuscle_plugin"> -->
			<!-- <myoMuscle name="motor0">
				<link name="base">
					<viaPoint type="FIXPOINT">0.005265138469598831 0.018854448267973025 0.031959978735720325</viaPoint>
				</link>
				<link name="lower_arm">
					<viaPoint type="FIXPOINT">0.1327966152619598 0.10393357520001109 -0.14442203703761572</viaPoint>
				</link>
			</myoMuscle>
			<myoMuscle name="motor1">
				<link name="base">
					<viaPoint type="FIXPOINT">0.004040153864104248 0.020004261966342286 -0.23106056291670726</viaPoint>
				</link>
				<link name="lower_arm">
					<viaPoint type="FIXPOINT">0.1327966152619598 0.10393357520001109 -0.15342203703761573</viaPoint>
				</link>
			</myoMuscle>
			<myoMuscle name="motor2">
				<link name="lower_arm">
					<viaPoint type="FIXPOINT">0.1302024472576578 0.3521967576715883 -0.12258737420410347</viaPoint>
				</link>
				<link name="upper_arm">
					<viaPoint type="FIXPOINT">0.09471749440615554 0.1312151153068114 -0.1945633826317157</viaPoint>
				</link>
			</myoMuscle>
			<myoMuscle name="motor3">
				<link name="lower_arm">
					<viaPoint type="FIXPOINT">0.13396687812014016 0.3271967576715897 -0.17837802021112786</viaPoint>
				</link>
				<link name="upper_arm">
					<viaPoint type="FIXPOINT">0.09471749440615558 0.13121511530681132 -0.22702309889059472</viaPoint>
				</link>
			</myoMuscle>
		</plugin> -->
		<!-- <plugin filename="libgazebo_ros_muscle_interface.so" name="muscle_interface_plugin"/>
		<muscles>model://nst_arm/muscles.osim</muscles> -->
	</model>
</sdf>
