<?xml version="1.0" ?>
<sdf version="1.6">
	<model name="onefinger_model">
		<link name="palm">
			<self_collide>false</self_collide>
			<pose frame="">-0.0005044283092349283 0.005006540677193836 0.007668224054983931 0.0 -0.0 0.0</pose>
			<inertial>
				<pose frame="">0.0 0.0 0.0 0 0 0</pose>
				<mass>15.519964907904049</mass>
				<inertia>
					<ixx>0.2434284649239045</ixx>
					<ixy>3.8951223242934765e-05</ixy>
					<ixz>-0.0006080195938038014</ixz>
					<iyy>0.24306045207104932</iyy>
					<iyz>7.181807744948158e-05</iyz>
					<izz>0.4820858095969215</izz>
				</inertia>
			</inertial>
			<collision name="palm_collision">
				<geometry>
					<mesh>
						<uri>model://onefinger_model/meshes/CAD/palm.stl</uri>
						<scale>0.001 0.001 0.001</scale>
					</mesh>
				</geometry>
			</collision>
			<visual name="palm_visual">
				<geometry>
					<mesh>
						<uri>model://onefinger_model/meshes/CAD/palm.stl</uri>
						<scale>0.001 0.001 0.001</scale>
					</mesh>
				</geometry>
			</visual>
		</link>
		<link name="middle_limb0">
			<self_collide>false</self_collide>
			<pose frame="">-0.000999192146949655 0.005136106525526762 0.18957352808347364 0.0 -0.0 0.0</pose>
			<inertial>
				<pose frame="">0.0 0.0 0.0 0 0 0</pose>
				<mass>0.0004269894659846255</mass>
				<inertia>
					<ixx>1.536165706694535e-05</ixx>
					<ixy>2.1901353957392285e-09</ixy>
					<ixz>-4.1540323626056995e-07</ixz>
					<iyy>1.5353570983419417e-05</iyy>
					<iyz>8.08804386172761e-08</iyz>
					<izz>1.9124488524567362e-08</izz>
				</inertia>
			</inertial>
			<collision name="middle_limb0_collision">
				<geometry>
					<mesh>
						<uri>model://onefinger_model/meshes/CAD/middle_limb0.stl</uri>
						<scale>0.001 0.001 0.001</scale>
					</mesh>
				</geometry>
			</collision>
			<visual name="middle_limb0_visual">
				<geometry>
					<mesh>
						<uri>model://onefinger_model/meshes/CAD/middle_limb0.stl</uri>
						<scale>0.001 0.001 0.001</scale>
					</mesh>
				</geometry>
			</visual>
		</link>
		<link name="middle_limb1">
			<self_collide>false</self_collide>
			<pose frame="">-0.0010000315396339007 0.004241487266417309 0.21424496671555843 0.0 -0.0 0.0</pose>
			<inertial>
				<pose frame="">0.0 0.0 0.0 0 0 0</pose>
				<mass>0.0038294772164651015</mass>
				<inertia>
					<ixx>0.00017682026441395542</ixx>
					<ixy>1.624368902597671e-08</ixy>
					<ixz>-3.4461287752303576e-06</ixz>
					<iyy>0.00017675560773535055</iyy>
					<iyz>8.204701359540707e-07</iyz>
					<izz>1.471685817117294e-07</izz>
				</inertia>
			</inertial>
			<collision name="middle_limb1_collision">
				<geometry>
					<mesh>
						<uri>model://onefinger_model/meshes/CAD/middle_limb1.stl</uri>
						<scale>0.001 0.001 0.001</scale>
					</mesh>
				</geometry>
			</collision>
			<visual name="middle_limb1_visual">
				<geometry>
					<mesh>
						<uri>model://onefinger_model/meshes/CAD/middle_limb1.stl</uri>
						<scale>0.001 0.001 0.001</scale>
					</mesh>
				</geometry>
			</visual>
		</link>
		<link name="middle_limb2">
			<self_collide>false</self_collide>
			<pose frame="">-0.0009998557311284976 0.003470251407169781 0.2539910928863602 0.0 -0.0 0.0</pose>
			<inertial>
				<pose frame="">0.0 0.0 0.0 0 0 0</pose>
				<mass>0.0016247916009061618</mass>
				<inertia>
					<ixx>0.00010501248993342741</ixx>
					<ixy>5.637318285857512e-09</ixy>
					<ixz>-1.4194059213906926e-06</ixz>
					<iyy>0.00010499370001653197</iyy>
					<iyz>4.126266294038791e-07</iyz>
					<izz>4.110199192596718e-08</izz>
				</inertia>
			</inertial>
			<collision name="middle_limb2_collision">
				<geometry>
					<mesh>
						<uri>model://onefinger_model/meshes/CAD/middle_limb2.stl</uri>
						<scale>0.001 0.001 0.001</scale>
					</mesh>
				</geometry>
			</collision>
			<visual name="middle_limb2_visual">
				<geometry>
					<mesh>
						<uri>model://onefinger_model/meshes/CAD/middle_limb2.stl</uri>
						<scale>0.001 0.001 0.001</scale>
					</mesh>
				</geometry>
			</visual>
		</link>
		<link name="middle_limb3">
			<self_collide>false</self_collide>
			<pose frame="">-0.0009999729777675206 0.002735286503544878 0.2811201538211123 0.0 -0.0 0.0</pose>
			<inertial>
				<pose frame="">0.0 0.0 0.0 0 0 0</pose>
				<mass>0.0006943749017269083</mass>
				<inertia>
					<ixx>5.491033077325499e-05</ixx>
					<ixy>1.8992165910331307e-09</ixy>
					<ixz>-5.311514793338946e-07</ixz>
					<iyy>5.490545265591463e-05</iyy>
					<iyz>1.951977238020211e-07</iyz>
					<izz>1.0726690404151148e-08</izz>
				</inertia>
			</inertial>
			<collision name="middle_limb3_collision">
				<geometry>
					<mesh>
						<uri>model://onefinger_model/meshes/CAD/middle_limb3.stl</uri>
						<scale>0.001 0.001 0.001</scale>
					</mesh>
				</geometry>
			</collision>
			<visual name="middle_limb3_visual">
				<geometry>
					<mesh>
						<uri>model://onefinger_model/meshes/CAD/middle_limb3.stl</uri>
						<scale>0.001 0.001 0.001</scale>
					</mesh>
				</geometry>
			</visual>
		</link>
		<joint name="joint0_middle" type="revolute">
			<parent>middle_limb0</parent>
			<child>middle_limb1</child>
			<pose frame="">3.153963346394506e-08 -0.0018395634777707585 -0.025464966715557508 0 0 0</pose>
			<axis>
				<xyz>-5.813707824494912e-16 -0.8660254037844376 -0.4999999999999997</xyz>
				<limit>
					<lower>-0.6108652381980153</lower>
					<upper>0.6108652381980153</upper>
				</limit>
				<use_parent_model_frame>0</use_parent_model_frame>
			</axis>
		</joint>
		<joint name="joint1_middle" type="revolute">
			<parent>middle_limb1</parent>
			<child>middle_limb2</child>
			<pose frame="">0.0054998557311281004 0.0015967358909378428 -0.012586092886359382 0 0 0</pose>
			<axis>
				<xyz>-1.0 1.9056848389644378e-16 5.967448757360217e-16</xyz>
				<limit>
					<lower>0.0</lower>
					<upper>1.9198621771937625</upper>
				</limit>
				<use_parent_model_frame>0</use_parent_model_frame>
			</axis>
		</joint>
		<joint name="joint2_middle" type="revolute">
			<parent>middle_limb2</parent>
			<child>middle_limb3</child>
			<pose frame="">0.00399997297776715 0.0008317007945627281 -0.00796540382111143 0 0 0</pose>
			<axis>
				<xyz>-1.0 1.9056848389644378e-16 5.967448757360217e-16</xyz>
				<limit>
					<lower>0.0</lower>
					<upper>1.2217304763960306</upper>
				</limit>
				<use_parent_model_frame>0</use_parent_model_frame>
			</axis>
		</joint>
		<joint name="palm_middle" type="revolute">
			<parent>palm</parent>
			<child>middle_limb0</child>
			<pose frame="">-0.005000807853050716 -0.0001361065255269006 0.0007064719165271072 0 0 0</pose>
			<axis>
				<xyz>1.0000000000000087 -9.498012591832213e-17 -4.163336342344467e-16</xyz>
				<limit>
					<lower>-1.2217304763960306</lower>
					<upper>0.3490658503988659</upper>
				</limit>
				<use_parent_model_frame>0</use_parent_model_frame>
			</axis>
		</joint>
		<plugin filename="libmusc_plugin.so" name="musc_plugin">
			<myoMuscle name="motor10">
				<link name="palm">
					<viaPoint type="FIXPOINT">4.428309234646155e-06 -6.540677193722644e-06 -0.05165322405498336</viaPoint>
					<viaPoint type="FIXPOINT">0.0018802136548719717 -0.0032594762876914395 -0.10826904610445093</viaPoint>
				</link>
				<link name="middle_limb3">
					<viaPoint type="FIXPOINT">0.0009999729777675206 0.004108308971718817 -0.4875392095665166</viaPoint>
					<viaPoint type="FIXPOINT">0.001495382180722059 0.0035141010783804093 -0.4928701538211124</viaPoint>
					<viaPoint type="FIXPOINT">0.000999972977767528 0.002732538713253576 -0.4940555765711123</viaPoint>
				</link>
				<link name="palm">
					<viaPoint type="FIXPOINT">-0.002478713019064486 -0.0063927612218332135 -0.11485210592902872</viaPoint>
					<viaPoint type="FIXPOINT">4.42830923472401e-06 -0.007176403479329142 -0.12096550310886478</viaPoint>
				</link>
				<link name="middle_limb1">
					<viaPoint type="FIXPOINT">0.001000031539633902 0.0065794875622875795 -0.33717332954461804</viaPoint>
					<viaPoint type="FIXPOINT">0.0018658892193076377 0.005424004593444184 -0.3472716309157539</viaPoint>
					<viaPoint type="FIXPOINT">0.0010000315396339024 0.0022955660900722376 -0.37635037151562617</viaPoint>
				</link>
				<link name="middle_limb2">
					<viaPoint type="FIXPOINT">0.0009998557311284922 0.004894800399956508 -0.4310762171410218</viaPoint>
					<viaPoint type="FIXPOINT">0.0017998557311284847 0.004116860965905099 -0.43495209808015745</viaPoint>
					<viaPoint type="FIXPOINT">0.00039985573112849603 0.003209513659236115 -0.4530596689809836</viaPoint>
				</link>
			</myoMuscle>
			<myoMuscle name="motor11">
				<link name="palm">
					<viaPoint type="FIXPOINT">4.428309234646155e-06 -6.540677193722644e-06 -0.05165322405498336</viaPoint>
					<viaPoint type="FIXPOINT">0.0018802136548719717 -0.0032594762876914395 -0.10826904610445093</viaPoint>
					<viaPoint type="FIXPOINT">-0.002478713019064486 -0.0063927612218332135 -0.11485210592902872</viaPoint>
					<viaPoint type="FIXPOINT">4.42830923472401e-06 -0.007176403479329142 -0.12096550310886478</viaPoint>
				</link>
				<link name="middle_limb1">
					<viaPoint type="FIXPOINT">0.001000031539633902 0.0065794875622875795 -0.33717332954461804</viaPoint>
					<viaPoint type="FIXPOINT">0.0018658892193076377 0.005424004593444184 -0.3472716309157539</viaPoint>
					<viaPoint type="FIXPOINT">0.0010000315396339024 0.0022955660900722376 -0.37635037151562617</viaPoint>
					<viaPoint type="FIXPOINT">0.0010000315396339011 -0.004174499968309528 -0.3836199667155584</viaPoint>
				</link>
				<link name="middle_limb2">
					<viaPoint type="FIXPOINT">0.0009998557311284976 -0.0034032641090620003 -0.4422409678863602</viaPoint>
				</link>
			</myoMuscle>
			<myoMuscle name="motor12">
				<link name="palm">
					<viaPoint type="FIXPOINT">4.428309234646155e-06 -6.540677193722644e-06 -0.05165322405498336</viaPoint>
					<viaPoint type="FIXPOINT">0.0022957161567127254 0.000759263180272638 -0.10826904610445089</viaPoint>
					<viaPoint type="FIXPOINT">-0.0024966202939647785 0.00175926318027264 -0.11522273414913516</viaPoint>
				</link>
				<link name="middle_limb1">
					<viaPoint type="FIXPOINT">6.65696713272837e-06 -0.005289421501140035 -0.3391765770993024</viaPoint>
					<viaPoint type="FIXPOINT">3.103291039462455e-05 -0.005421566065806542 -0.3442950890127831</viaPoint>
					<viaPoint type="FIXPOINT">0.0010000315396339007 -0.004174499968309528 -0.35024496671555844</viaPoint>
				</link>
			</myoMuscle>
			<myoMuscle name="motor13">
				<link name="palm">
					<viaPoint type="FIXPOINT">-0.0024946516405254977 -0.005006540677193853 -0.10826904610445093</viaPoint>
					<viaPoint type="FIXPOINT">0.0030255271206639654 -0.006537351952576501 -0.11510895617330417</viaPoint>
					<viaPoint type="FIXPOINT">0.004504428309234723 -0.0072573865319052 -0.12331935831119617</viaPoint>
				</link>
				<link name="middle_limb1">
					<viaPoint type="FIXPOINT">0.0010000315396338458 -0.00043538939562798697 -0.3417338702301481</viaPoint>
					<viaPoint type="FIXPOINT">-0.004458427813020499 -0.00045273396382626286 -0.34483428245495185</viaPoint>
					<viaPoint type="FIXPOINT">-0.003609808404792505 0.00032550003169047213 -0.34924496671555844</viaPoint>
				</link>
			</myoMuscle>
			<myoMuscle name="motor14">
				<link name="palm">
					<viaPoint type="FIXPOINT">4.428309234646155e-06 -6.540677193722644e-06 -0.05165322405498336</viaPoint>
					<viaPoint type="FIXPOINT">-0.0024946516405254977 -0.005006540677193853 -0.10826904610445093</viaPoint>
					<viaPoint type="FIXPOINT">-0.002478713019064486 -0.0063927612218332135 -0.11485210592902872</viaPoint>
					<viaPoint type="FIXPOINT">-0.004495571690765356 -0.007257386531905198 -0.12331935831119614</viaPoint>
				</link>
				<link name="middle_limb1">
					<viaPoint type="FIXPOINT">0.0010000315396338458 -0.00043538939562798697 -0.3417338702301481</viaPoint>
					<viaPoint type="FIXPOINT">0.006458490892288299 -0.00045273396382626064 -0.34483428245495185</viaPoint>
					<viaPoint type="FIXPOINT">0.005609871484060307 0.00032550003169047213 -0.34924496671555844</viaPoint>
				</link>
			</myoMuscle>
		</plugin>
	</model>
</sdf>
