<?xml version="1.0" ?>
<sdf version="1.6">
	<model name="onefinger_model">
		<link name="palm">
			<self_collide>false</self_collide>
			<pose frame="">-0.0005044283092357059 0.005006540677193889 0.007668224054978296 0.0 -0.0 0.0</pose>
			<inertial>
				<pose frame="">0.0 0.0 0.0 0 0 0</pose>
				<mass>15.519964907903887</mass>
				<inertia>
					<ixx>0.2434284649239264</ixx>
					<ixy>3.895122307311051e-05</ixy>
					<ixz>-0.0006080195938044838</ixz>
					<iyy>0.2430604520722422</iyy>
					<iyz>7.181807529759303e-05</iyz>
					<izz>0.4820858095980941</izz>
				</inertia>
			</inertial>
			<collision name="palm_collision">
				<geometry>
					<mesh>
						<uri>model://onefinger_model/meshes/CAD/palm.stl</uri>
						<scale>0.001 0.001 0.001</scale>
					</mesh>
				</geometry>
			</collision>
			<visual name="palm_visual">
				<geometry>
					<mesh>
						<uri>model://onefinger_model/meshes/CAD/palm.stl</uri>
						<scale>0.001 0.001 0.001</scale>
					</mesh>
				</geometry>
			</visual>
		</link>
		<link name="middle_limb0">
			<self_collide>false</self_collide>
			<pose frame="">-0.0009991921469496546 0.005136106525526762 0.18957352808347364 0.0 -0.0 0.0</pose>
			<inertial>
				<pose frame="">0.0 0.0 0.0 0 0 0</pose>
				<mass>0.0004269894659846257</mass>
				<inertia>
					<ixx>1.5361657066945328e-05</ixx>
					<ixy>2.190135395739229e-09</ixy>
					<ixz>-4.154032362605695e-07</ixz>
					<iyy>1.5353570983419397e-05</iyy>
					<iyz>8.088043861727593e-08</iyz>
					<izz>1.9124488524567345e-08</izz>
				</inertia>
			</inertial>
			<collision name="middle_limb0_collision">
				<geometry>
					<mesh>
						<uri>model://onefinger_model/meshes/CAD/middle_limb0.stl</uri>
						<scale>0.001 0.001 0.001</scale>
					</mesh>
				</geometry>
			</collision>
			<visual name="middle_limb0_visual">
				<geometry>
					<mesh>
						<uri>model://onefinger_model/meshes/CAD/middle_limb0.stl</uri>
						<scale>0.001 0.001 0.001</scale>
					</mesh>
				</geometry>
			</visual>
		</link>
		<link name="middle_limb1">
			<self_collide>false</self_collide>
			<pose frame="">-0.0010000315397478067 0.0042414872664892425 0.21424496671590512 0.0 -0.0 0.0</pose>
			<inertial>
				<pose frame="">0.0 0.0 0.0 0 0 0</pose>
				<mass>0.0038294772165221435</mass>
				<inertia>
					<ixx>0.00017682026442083354</ixx>
					<ixy>1.6243689026005943e-08</ixy>
					<ixz>-3.4461287752462823e-06</ixz>
					<iyy>0.00017675560774222887</iyy>
					<iyz>8.204701359667021e-07</iyz>
					<izz>1.4716858171319738e-07</izz>
				</inertia>
			</inertial>
			<collision name="middle_limb1_collision">
				<geometry>
					<mesh>
						<uri>model://onefinger_model/meshes/CAD/middle_limb1.stl</uri>
						<scale>0.001 0.001 0.001</scale>
					</mesh>
				</geometry>
			</collision>
			<visual name="middle_limb1_visual">
				<geometry>
					<mesh>
						<uri>model://onefinger_model/meshes/CAD/middle_limb1.stl</uri>
						<scale>0.001 0.001 0.001</scale>
					</mesh>
				</geometry>
			</visual>
		</link>
		<link name="middle_limb2">
			<self_collide>false</self_collide>
			<pose frame="">-0.0009998557311284935 0.003470251407169782 0.2539910928863602 0.0 -0.0 0.0</pose>
			<inertial>
				<pose frame="">0.0 0.0 0.0 0 0 0</pose>
				<mass>0.001624791600906159</mass>
				<inertia>
					<ixx>0.00010501248993342754</ixx>
					<ixy>5.637318285857507e-09</ixy>
					<ixz>-1.419405921390696e-06</ixz>
					<iyy>0.00010499370001653213</iyy>
					<iyz>4.1262662940387787e-07</iyz>
					<izz>4.1101991925967326e-08</izz>
				</inertia>
			</inertial>
			<collision name="middle_limb2_collision">
				<geometry>
					<mesh>
						<uri>model://onefinger_model/meshes/CAD/middle_limb2.stl</uri>
						<scale>0.001 0.001 0.001</scale>
					</mesh>
				</geometry>
			</collision>
			<visual name="middle_limb2_visual">
				<geometry>
					<mesh>
						<uri>model://onefinger_model/meshes/CAD/middle_limb2.stl</uri>
						<scale>0.001 0.001 0.001</scale>
					</mesh>
				</geometry>
			</visual>
		</link>
		<link name="middle_limb3">
			<self_collide>false</self_collide>
			<pose frame="">-0.0009999729777675206 0.002735286503544878 0.2811201538211123 0.0 -0.0 0.0</pose>
			<inertial>
				<pose frame="">0.0 0.0 0.0 0 0 0</pose>
				<mass>0.0006943749017269084</mass>
				<inertia>
					<ixx>5.491033077325498e-05</ixx>
					<ixy>1.8992165910331328e-09</ixy>
					<ixz>-5.311514793338947e-07</ixz>
					<iyy>5.490545265591461e-05</iyy>
					<iyz>1.951977238020211e-07</iyz>
					<izz>1.0726690404151148e-08</izz>
				</inertia>
			</inertial>
			<collision name="middle_limb3_collision">
				<geometry>
					<mesh>
						<uri>model://onefinger_model/meshes/CAD/middle_limb3.stl</uri>
						<scale>0.001 0.001 0.001</scale>
					</mesh>
				</geometry>
			</collision>
			<visual name="middle_limb3_visual">
				<geometry>
					<mesh>
						<uri>model://onefinger_model/meshes/CAD/middle_limb3.stl</uri>
						<scale>0.001 0.001 0.001</scale>
					</mesh>
				</geometry>
			</visual>
		</link>
		<joint name="joint0_middle" type="revolute">
			<parent>middle_limb0</parent>
			<child>middle_limb1</child>
			<pose frame="">3.153974736991305e-08 -0.0018395634778426925 -0.025464966715904182 0 0 0</pose>
			<axis>
				<xyz>-5.813707824494912e-16 -0.8660254037844376 -0.4999999999999997</xyz>
				<limit>
					<lower>-0.6108652381980153</lower>
					<upper>0.6108652381980153</upper>
				</limit>
				<use_parent_model_frame>0</use_parent_model_frame>
			</axis>
		</joint>
		<joint name="joint1_middle" type="revolute">
			<parent>middle_limb1</parent>
			<child>middle_limb2</child>
			<pose frame="">0.005499855731128097 0.0015967358909378415 -0.012586092886359382 0 0 0</pose>
			<axis>
				<xyz>-1.0 1.9056848389644378e-16 5.967448757360217e-16</xyz>
				<limit>
					<lower>0.0</lower>
					<upper>1.9198621771937625</upper>
				</limit>
				<use_parent_model_frame>0</use_parent_model_frame>
			</axis>
		</joint>
		<joint name="joint2_middle" type="revolute">
			<parent>middle_limb2</parent>
			<child>middle_limb3</child>
			<pose frame="">0.00399997297776715 0.0008317007945627281 -0.00796540382111143 0 0 0</pose>
			<axis>
				<xyz>-1.0 1.9056848389644378e-16 5.967448757360217e-16</xyz>
				<limit>
					<lower>0.0</lower>
					<upper>1.2217304763960306</upper>
				</limit>
				<use_parent_model_frame>0</use_parent_model_frame>
			</axis>
		</joint>
		<joint name="palm_middle" type="revolute">
			<parent>palm</parent>
			<child>middle_limb0</child>
			<pose frame="">-0.005000807853050716 -0.0001361065255269006 0.0007064719165271072 0 0 0</pose>
			<axis>
				<xyz>1.0000000000000087 -9.498012591832213e-17 -4.163336342344467e-16</xyz>
				<limit>
					<lower>-1.2217304763960306</lower>
					<upper>0.3490658503988659</upper>
				</limit>
				<use_parent_model_frame>0</use_parent_model_frame>
			</axis>
		</joint>
		<plugin filename="libmusc_plugin.so" name="musc_plugin">
			<myoMuscle name="motor10">
				<link name="palm">
					<viaPoint type="FIXPOINT">4.428309235483541e-06 -6.5406771938780755e-06 0.10534677594502188</viaPoint>
					<viaPoint type="FIXPOINT">-0.001871357036401809 -0.0032594762876916295 0.16196259799448945</viaPoint>
				</link>
				<link name="middle_limb3">
					<viaPoint type="FIXPOINT">-2.7022232886309005e-08 0.004108308971718615 -0.005671098075707271</viaPoint>
					<viaPoint type="FIXPOINT">-0.0004954362251874217 0.003514101078380205 -0.0003401538211114641</viaPoint>
					<viaPoint type="FIXPOINT">-2.702223289005601e-08 0.002732538713253371 0.000845268928888494</viaPoint>
				</link>
				<link name="palm">
					<viaPoint type="FIXPOINT">0.0024875696375346525 -0.006392761221833409 0.16854565781906725</viaPoint>
					<viaPoint type="FIXPOINT">4.428309235445655e-06 -0.007176403479329341 0.1746590549989033</viaPoint>
				</link>
				<link name="middle_limb1">
					<viaPoint type="FIXPOINT">3.153974734923515e-08 0.006579487562215494 -0.022286603886844746</viaPoint>
					<viaPoint type="FIXPOINT">-0.0008658261399263805 0.005424004593372094 -0.012188302515708821</viaPoint>
					<viaPoint type="FIXPOINT">3.153974737143961e-08 0.002295566090000129 0.0168904380841634</viaPoint>
				</link>
				<link name="middle_limb2">
					<viaPoint type="FIXPOINT">-1.4426887192525717e-07 0.004894800399956324 -0.00787596863169771</viaPoint>
					<viaPoint type="FIXPOINT">-0.0008001442688719155 0.004116860965904912 -0.004000087692562069</viaPoint>
					<viaPoint type="FIXPOINT">0.0005998557311280837 0.0032095136592359174 0.014107483208264071</viaPoint>
				</link>
			</myoMuscle>
			<myoMuscle name="motor11">
				<link name="palm">
					<viaPoint type="FIXPOINT">4.428309235483541e-06 -6.5406771938780755e-06 0.10534677594502188</viaPoint>
					<viaPoint type="FIXPOINT">-0.001871357036401809 -0.0032594762876916295 0.16196259799448945</viaPoint>
					<viaPoint type="FIXPOINT">0.0024875696375346525 -0.006392761221833409 0.16854565781906725</viaPoint>
					<viaPoint type="FIXPOINT">4.428309235445655e-06 -0.007176403479329341 0.1746590549989033</viaPoint>
				</link>
				<link name="middle_limb1">
					<viaPoint type="FIXPOINT">3.153974734923515e-08 0.006579487562215494 -0.022286603886844746</viaPoint>
					<viaPoint type="FIXPOINT">-0.0008658261399263805 0.005424004593372094 -0.012188302515708821</viaPoint>
					<viaPoint type="FIXPOINT">3.153974737143961e-08 0.002295566090000129 0.0168904380841634</viaPoint>
					<viaPoint type="FIXPOINT">3.153974737574172e-08 -0.004174499968381641 0.02416003328409566</viaPoint>
				</link>
				<link name="middle_limb2">
					<viaPoint type="FIXPOINT">-1.442688719256735e-07 -0.003403264109062192 0.0032887821136406005</viaPoint>
				</link>
			</myoMuscle>
			<myoMuscle name="motor12">
				<link name="palm">
					<viaPoint type="FIXPOINT">4.428309235483541e-06 -6.5406771938780755e-06 0.10534677594502188</viaPoint>
					<viaPoint type="FIXPOINT">-0.002286859538242562 0.0007592631802724482 0.16196259799448942</viaPoint>
					<viaPoint type="FIXPOINT">0.002505476912434947 0.0017592631802724446 0.1689162860391737</viaPoint>
				</link>
				<link name="middle_limb1">
					<viaPoint type="FIXPOINT">0.000993406112248522 -0.00528942150121212 -0.020283356332160416</viaPoint>
					<viaPoint type="FIXPOINT">0.0009690301689866287 -0.005421566065878631 -0.0151648444186797</viaPoint>
					<viaPoint type="FIXPOINT">3.153974735631282e-08 -0.004174499968381621 -0.00921496671590436</viaPoint>
				</link>
			</myoMuscle>
			<myoMuscle name="motor13">
				<link name="palm">
					<viaPoint type="FIXPOINT">0.00250350825899566 -0.005006540677194045 0.16196259799448945</viaPoint>
					<viaPoint type="FIXPOINT">-0.0030166705021937995 -0.006537351952576695 0.1688025080633427</viaPoint>
					<viaPoint type="FIXPOINT">-0.004495571690764552 -0.007257386531905399 0.17701291020123472</viaPoint>
				</link>
				<link name="middle_limb1">
					<viaPoint type="FIXPOINT">3.1539747406966745e-08 -0.00043538939570007427 -0.017726063201314694</viaPoint>
					<viaPoint type="FIXPOINT">0.005458490892401754 -0.0004527339638983535 -0.01462565097651094</viaPoint>
					<viaPoint type="FIXPOINT">0.0046098714841737625 0.00032550003161837924 -0.01021496671590434</viaPoint>
				</link>
			</myoMuscle>
			<myoMuscle name="motor14">
				<link name="palm">
					<viaPoint type="FIXPOINT">4.428309235483541e-06 -6.5406771938780755e-06 0.10534677594502188</viaPoint>
					<viaPoint type="FIXPOINT">0.00250350825899566 -0.005006540677194045 0.16196259799448945</viaPoint>
					<viaPoint type="FIXPOINT">0.0024875696375346525 -0.006392761221833409 0.16854565781906725</viaPoint>
					<viaPoint type="FIXPOINT">0.004504428309235527 -0.007257386531905399 0.17701291020123466</viaPoint>
				</link>
				<link name="middle_limb1">
					<viaPoint type="FIXPOINT">3.1539747406966745e-08 -0.00043538939570007427 -0.017726063201314694</viaPoint>
					<viaPoint type="FIXPOINT">-0.005458427812907044 -0.0004527339638983491 -0.01462565097651094</viaPoint>
					<viaPoint type="FIXPOINT">-0.004609808404679049 0.00032550003161838147 -0.01021496671590434</viaPoint>
				</link>
			</myoMuscle>
		</plugin>
	</model>
</sdf>
