<?xml version="1.0" ?>
<robot name="onefinger_model">
  <joint name="palm_middle" type="revolute">
    <parent link="palm"/>
    <child link="middle_limb0"/>
    <origin rpy="0  0  0" xyz="0.005    0.005   -0.12125"/>
    <axis xyz="-1  0  0"/>
    <limit effort="0.0" lower="-1.2217304764" upper="0.349065850399" velocity="0.0"/>
  </joint>
  <joint name="joint0_middle" type="revolute">
    <parent link="middle_limb0"/>
    <child link="middle_limb1"/>
    <origin rpy="0  0  0" xyz="-0.005   -0.00259  0.0015"/>
    <axis xyz="0      -0.86602  0.5"/>
    <limit effort="0.0" lower="-0.610865238198" upper="0.610865238198" velocity="0.0"/>
  </joint>
  <joint name="joint1_middle" type="revolute">
    <parent link="middle_limb1"/>
    <child link="middle_limb2"/>
    <origin rpy="0  0  0" xyz="-0.0055   0.00266 -0.05262"/>
    <axis xyz="1  0  0"/>
    <limit effort="0.0" lower="0.0" upper="1.91986217719" velocity="0.0"/>
  </joint>
  <joint name="joint2_middle" type="revolute">
    <parent link="middle_limb2"/>
    <child link="middle_limb3"/>
    <origin rpy="0  0  0" xyz="0.0015  -0.0015  -0.03175"/>
    <axis xyz="1  0  0"/>
    <limit effort="0.0" lower="0.0" upper="1.2217304764" velocity="0.0"/>
  </joint>
  <link name="palm">
    <inertial>
      <mass value="15.519964907892248"/>
      <origin rpy="0  0  0" xyz="-0.00049  0.005    0.06136"/>
      <inertia ixx="0.300952685422027" ixy="3.875011271679092e-05" ixz="-0.004755703604047999" iyy="0.3005845351148203" iyz="0.0004837348586251351" izz="0.4820856721425696"/>
    </inertial>
    <collision name="palm_collision">
      <origin rpy="0  0  0" xyz="-0.00049  0.005    0.06136"/>
      <geometry>
        <mesh filename="package://roboy_models/onefinger_model/meshes/CAD/palm.stl" scale="0.001 0.001 0.001"/>
      </geometry>
    </collision>
    <visual name="palm_visual">
      <origin rpy="0  0  0" xyz="-0.00049  0.005    0.06136"/>
      <geometry>
        <mesh filename="package://roboy_models/onefinger_model/meshes/CAD/palm.stl" scale="0.001 0.001 0.001"/>
      </geometry>
    </visual>
  </link>
  <link name="middle_limb0">
    <inertial>
      <mass value="0.0004269894661254722"/>
      <origin rpy="0  0  0" xyz="-0.00499  0.00013  0.0007"/>
      <inertia ixx="6.220931215255127e-06" ixy="-2.9280517172806823e-12" ixz="2.640161236737293e-07" iyy="6.212418826825487e-06" iyz="4.165012047680546e-11" izz="1.8698194242482417e-08"/>
    </inertial>
    <collision name="middle_limb0_collision">
      <origin rpy="0  0  0" xyz="-0.00499  0.00013  0.0007"/>
      <geometry>
        <mesh filename="package://roboy_models/onefinger_model/meshes/CAD/middle_limb0.stl" scale="0.001 0.001 0.001"/>
      </geometry>
    </collision>
    <visual name="middle_limb0_visual">
      <origin rpy="0  0  0" xyz="-0.00499  0.00013  0.0007"/>
      <geometry>
        <mesh filename="package://roboy_models/onefinger_model/meshes/CAD/middle_limb0.stl" scale="0.001 0.001 0.001"/>
      </geometry>
    </visual>
  </link>
  <link name="middle_limb1">
    <inertial>
      <mass value="0.003829477216634554"/>
      <origin rpy="0  0  0" xyz="0       0.00184 -0.02546"/>
      <inertia ixx="8.179745773238127e-05" ixy="-1.0101738763871992e-12" ixz="2.324896654061824e-06" iyy="8.172897133495305e-05" iyz="1.5576496365204838e-11" izz="1.4333886288753813e-07"/>
    </inertial>
    <collision name="middle_limb1_collision">
      <origin rpy="0  0  0" xyz="0       0.00184 -0.02546"/>
      <geometry>
        <mesh filename="package://roboy_models/onefinger_model/meshes/CAD/middle_limb1.stl" scale="0.001 0.001 0.001"/>
      </geometry>
    </collision>
    <visual name="middle_limb1_visual">
      <origin rpy="0  0  0" xyz="0       0.00184 -0.02546"/>
      <geometry>
        <mesh filename="package://roboy_models/onefinger_model/meshes/CAD/middle_limb1.stl" scale="0.001 0.001 0.001"/>
      </geometry>
    </visual>
  </link>
  <link name="middle_limb2">
    <inertial>
      <mass value="0.0016247913530675383"/>
      <origin rpy="0  0  0" xyz="0.0055  -0.00159 -0.01258"/>
      <inertia ixx="5.5779881831287715e-05" ixy="1.1170535485577339e-12" ixz="1.0301843374132042e-06" iyy="5.5759467602634794e-05" iyz="-3.9783898768129506e-11" izz="3.947765546601323e-08"/>
    </inertial>
    <collision name="middle_limb2_collision">
      <origin rpy="0  0  0" xyz="0.0055  -0.00159 -0.01258"/>
      <geometry>
        <mesh filename="package://roboy_models/onefinger_model/meshes/CAD/middle_limb2.stl" scale="0.001 0.001 0.001"/>
      </geometry>
    </collision>
    <visual name="middle_limb2_visual">
      <origin rpy="0  0  0" xyz="0.0055  -0.00159 -0.01258"/>
      <geometry>
        <mesh filename="package://roboy_models/onefinger_model/meshes/CAD/middle_limb2.stl" scale="0.001 0.001 0.001"/>
      </geometry>
    </visual>
  </link>
  <link name="middle_limb3">
    <inertial>
      <mass value="0.0006943748373823943"/>
      <origin rpy="0  0  0" xyz="0.004   -0.00083 -0.00796"/>
      <inertia ixx="3.1269426602180564e-05" ixy="9.770606143494896e-14" ixz="4.0004172461026313e-07" iyy="3.126385415013476e-05" iyz="-3.760132469054611e-12" izz="1.003234975927051e-08"/>
    </inertial>
    <collision name="middle_limb3_collision">
      <origin rpy="0  0  0" xyz="0.004   -0.00083 -0.00796"/>
      <geometry>
        <mesh filename="package://roboy_models/onefinger_model/meshes/CAD/middle_limb3.stl" scale="0.001 0.001 0.001"/>
      </geometry>
    </collision>
    <visual name="middle_limb3_visual">
      <origin rpy="0  0  0" xyz="0.004   -0.00083 -0.00796"/>
      <geometry>
        <mesh filename="package://roboy_models/onefinger_model/meshes/CAD/middle_limb3.stl" scale="0.001 0.001 0.001"/>
      </geometry>
    </visual>
  </link>
</robot>
