<?xml version="1.0" ?>
<robot name="Roboy2.0_Head_simplified">
  <joint name="Roboy2.0_Head_simplified__left_shoulder" type="fixed">
    <parent link="Roboy2.0_Head_simplified__torso"/>
    <child link="Roboy2.0_Head_simplified__upper_arm_left"/>
    <origin rpy="0  0  0" xyz="0.01836 -0.28718  0.29077"/>
    <axis xyz="-0.99844 -0.05101  0.02231"/>
    <limit effort="0.0" lower="-0.0" upper="-0.0" velocity="0.0"/>
  </joint>
  <joint name="Roboy2.0_Head_simplified__right_shoulder" type="fixed">
    <parent link="Roboy2.0_Head_simplified__torso"/>
    <child link="Roboy2.0_Head_simplified__upper_arm_right"/>
    <origin rpy="0  0  0" xyz="-0.01127  0.29602  0.29798"/>
    <axis xyz="0.99844  0.05101 -0.02231"/>
    <limit effort="0.0" lower="-0.0" upper="-0.0" velocity="0.0"/>
  </joint>
  <joint name="Roboy2.0_Head_simplified__neck" type="fixed">
    <parent link="Roboy2.0_Head_simplified__torso"/>
    <child link="Roboy2.0_Head_simplified__head"/>
    <origin rpy="0  0  0" xyz="0.01067  0.005    0.4734"/>
    <axis xyz="0 -1  0"/>
    <limit effort="0.0" lower="-0.0" upper="-0.0" velocity="0.0"/>
  </joint>
  <joint name="Roboy2.0_Head_simplified__elbow_left" type="revolute">
    <parent link="Roboy2.0_Head_simplified__upper_arm_left"/>
    <child link="Roboy2.0_Head_simplified__lower_arm_left"/>
    <origin rpy="0  0  0" xyz="-0.01189  0.02936 -0.30066"/>
    <axis xyz="0       0.99993  0.01119"/>
    <limit effort="0.0" lower="-1.57079632679" upper="-0.0" velocity="0.0"/>
  </joint>
  <joint name="Roboy2.0_Head_simplified__elbow_right" type="revolute">
    <parent link="Roboy2.0_Head_simplified__upper_arm_right"/>
    <child link="Roboy2.0_Head_simplified__lower_arm_right"/>
    <origin rpy="0  0  0" xyz="-0.00923 -0.023   -0.30131"/>
    <axis xyz="0.10135 -0.99475 -0.01345"/>
    <limit effort="0.0" lower="0.0" upper="1.57079632679" velocity="0.0"/>
  </joint>
  <link name="Roboy2.0_Head_simplified__torso">
    <inertial>
      <mass value="59.0832718311782"/>
      <origin rpy="0  0  0" xyz="0     0    -0.305"/>
      <inertia ixx="8.051001198805123" ixy="0.004494269532617076" ixz="0.04493051704857333" iyy="7.279131576408602" iyz="-0.009571163406070839" izz="4.445459472256799"/>
    </inertial>
    <collision name="Roboy2.0_Head_simplified__torso_collision">
      <origin rpy="0  0  0" xyz="0     0    -0.305"/>
      <geometry>
        <mesh filename="package://roboy_models/Roboy2.0_Head_simplified/meshes/CAD/torso.stl OR roboy_models/Roboy2.0_Upper_Body_simplified/meshes/CAD/torso.stl" scale="0.001 0.001 0.001"/>
      </geometry>
    </collision>
    <visual name="Roboy2.0_Head_simplified__torso_visual">
      <origin rpy="0  0  0" xyz="0     0    -0.305"/>
      <geometry>
        <mesh filename="package://roboy_models/Roboy2.0_Head_simplified/meshes/CAD/torso.stl OR roboy_models/Roboy2.0_Upper_Body_simplified/meshes/CAD/torso.stl" scale="0.001 0.001 0.001"/>
      </geometry>
    </visual>
  </link>
  <link name="Roboy2.0_Head_simplified__upper_arm_left">
    <inertial>
      <mass value="15.908363752087764"/>
      <origin rpy="0  0  0" xyz="0  0  0"/>
      <inertia ixx="1.7625511434069268" ixy="0.07244158478595611" ixz="0.6251218203413375" iyy="0.3634874621725613" iyz="-0.032736028946414225" izz="1.460574059311425"/>
    </inertial>
    <collision name="Roboy2.0_Head_simplified__upper_arm_left_collision">
      <origin rpy="0  0  0" xyz="0  0  0"/>
      <geometry>
        <mesh filename="package://roboy_models/Roboy2.0_Head_simplified/meshes/CAD/upper_arm_left.stl OR roboy_models/Roboy2.0_Upper_Body_simplified/meshes/CAD/upper_arm_left.stl" scale="0.001 0.001 0.001"/>
      </geometry>
    </collision>
    <visual name="Roboy2.0_Head_simplified__upper_arm_left_visual">
      <origin rpy="0  0  0" xyz="0  0  0"/>
      <geometry>
        <mesh filename="package://roboy_models/Roboy2.0_Head_simplified/meshes/CAD/upper_arm_left.stl OR roboy_models/Roboy2.0_Upper_Body_simplified/meshes/CAD/upper_arm_left.stl" scale="0.001 0.001 0.001"/>
      </geometry>
    </visual>
  </link>
  <link name="Roboy2.0_Head_simplified__lower_arm_right">
    <inertial>
      <mass value="10.58051047901106"/>
      <origin rpy="0  0  0" xyz="-0.00376  0.02954 -0.26517"/>
      <inertia ixx="1.2559639900199409" ixy="0.06854200852489073" ixz="0.48545353071933806" iyy="0.30330590795286294" iyz="-0.03574265591484113" izz="0.9722516127680956"/>
    </inertial>
    <collision name="Roboy2.0_Head_simplified__lower_arm_right_collision">
      <origin rpy="0  0  0" xyz="-0.00376  0.02954 -0.26517"/>
      <geometry>
        <mesh filename="package://roboy_models/Roboy2.0_Head_simplified/meshes/CAD/lower_arm_right.stl OR roboy_models/Roboy2.0_Upper_Body_simplified/meshes/CAD/lower_arm_right.stl" scale="0.001 0.001 0.001"/>
      </geometry>
    </collision>
    <visual name="Roboy2.0_Head_simplified__lower_arm_right_visual">
      <origin rpy="0  0  0" xyz="-0.00376  0.02954 -0.26517"/>
      <geometry>
        <mesh filename="package://roboy_models/Roboy2.0_Head_simplified/meshes/CAD/lower_arm_right.stl OR roboy_models/Roboy2.0_Upper_Body_simplified/meshes/CAD/lower_arm_right.stl" scale="0.001 0.001 0.001"/>
      </geometry>
    </visual>
  </link>
  <link name="Roboy2.0_Head_simplified__lower_arm_left">
    <inertial>
      <mass value="11.180423145931053"/>
      <origin rpy="0  0  0" xyz="-0.00108 -0.02292 -0.26581"/>
      <inertia ixx="1.2126531732458716" ixy="0.02702430066002528" ixz="-0.48054023459331124" iyy="0.32375849367990517" iyz="0.012916596811184951" izz="0.9006438580402119"/>
    </inertial>
    <collision name="Roboy2.0_Head_simplified__lower_arm_left_collision">
      <origin rpy="0  0  0" xyz="-0.00108 -0.02292 -0.26581"/>
      <geometry>
        <mesh filename="package://roboy_models/Roboy2.0_Head_simplified/meshes/CAD/lower_arm_left.stl OR roboy_models/Roboy2.0_Upper_Body_simplified/meshes/CAD/lower_arm_left.stl" scale="0.001 0.001 0.001"/>
      </geometry>
    </collision>
    <visual name="Roboy2.0_Head_simplified__lower_arm_left_visual">
      <origin rpy="0  0  0" xyz="-0.00108 -0.02292 -0.26581"/>
      <geometry>
        <mesh filename="package://roboy_models/Roboy2.0_Head_simplified/meshes/CAD/lower_arm_left.stl OR roboy_models/Roboy2.0_Upper_Body_simplified/meshes/CAD/lower_arm_left.stl" scale="0.001 0.001 0.001"/>
      </geometry>
    </visual>
  </link>
  <link name="Roboy2.0_Head_simplified__upper_arm_right">
    <inertial>
      <mass value="14.719196946657304"/>
      <origin rpy="0  0  0" xyz="0  0  0"/>
      <inertia ixx="1.8047353374389559" ixy="0.07012722555134064" ixz="-0.673788689539285" iyy="0.39312321166770187" iyz="0.03284392115313039" izz="1.471809237192228"/>
    </inertial>
    <collision name="Roboy2.0_Head_simplified__upper_arm_right_collision">
      <origin rpy="0  0  0" xyz="0  0  0"/>
      <geometry>
        <mesh filename="package://roboy_models/Roboy2.0_Head_simplified/meshes/CAD/upper_arm_right.stl OR roboy_models/Roboy2.0_Upper_Body_simplified/meshes/CAD/upper_arm_right.stl" scale="0.001 0.001 0.001"/>
      </geometry>
    </collision>
    <visual name="Roboy2.0_Head_simplified__upper_arm_right_visual">
      <origin rpy="0  0  0" xyz="0  0  0"/>
      <geometry>
        <mesh filename="package://roboy_models/Roboy2.0_Head_simplified/meshes/CAD/upper_arm_right.stl OR roboy_models/Roboy2.0_Upper_Body_simplified/meshes/CAD/upper_arm_right.stl" scale="0.001 0.001 0.001"/>
      </geometry>
    </visual>
  </link>
  <link name="Roboy2.0_Head_simplified__head">
    <inertial>
      <mass value="2.1752108706476503"/>
      <origin rpy="0  0  0" xyz="0  0  0"/>
      <inertia ixx="0.8451378573180605" ixy="-0.00046727522854294495" ixz="-0.005715381623468909" iyy="0.8577903362812495" iyz="-0.07402430273698146" izz="0.03262463725323261"/>
    </inertial>
    <collision name="Roboy2.0_Head_simplified__head_collision">
      <origin rpy="0  0  0" xyz="0  0  0"/>
      <geometry>
        <mesh filename="package://roboy_models/Roboy2.0_Head_simplified/meshes/CAD/head.stl OR roboy_models/Roboy2.0_Upper_Body_simplified/meshes/CAD/head.stl" scale="0.001 0.001 0.001"/>
      </geometry>
    </collision>
    <visual name="Roboy2.0_Head_simplified__head_visual">
      <origin rpy="0  0  0" xyz="0  0  0"/>
      <geometry>
        <mesh filename="package://roboy_models/Roboy2.0_Head_simplified/meshes/CAD/head.stl OR roboy_models/Roboy2.0_Upper_Body_simplified/meshes/CAD/head.stl" scale="0.001 0.001 0.001"/>
      </geometry>
    </visual>
  </link>
</robot>
