<?xml version="1.0" ?>
<sdf version="1.6">
	<model name="musc-le">
		<link name="base">
			<self_collide>false</self_collide>
			<pose frame="">0.23971216602585307 -0.006119047666083844 -0.30188293847157655 0.0 -0.0 0.0</pose>
			<inertial>
				<pose frame="">0.0 0.0 0.0 0 0 0</pose>
				<mass>4.110817491145606</mass>
				<inertia>
					<ixx>0.6384229692143298</ixx>
					<ixy>0.005630406014713259</ixy>
					<ixz>-0.007247432807289521</ixz>
					<iyy>0.9355691945779377</iyy>
					<iyz>0.29722779118383497</iyz>
					<izz>0.2983475104112492</izz>
				</inertia>
			</inertial>
			<collision name="base_collision">
				<geometry>
					<mesh>
						<uri>model://musc-le/meshes/CAD/base.stl</uri>
						<scale>0.001 0.001 0.001</scale>
					</mesh>
				</geometry>
			</collision>
			<visual name="base_visual">
				<geometry>
					<mesh>
						<uri>model://musc-le/meshes/CAD/base.stl</uri>
						<scale>0.001 0.001 0.001</scale>
					</mesh>
				</geometry>
			</visual>
		</link>
		<link name="lower_arm">
			<self_collide>false</self_collide>
			<pose frame="">0.23714469248795983 0.2671544486921548 -0.2975627401118544 0.0 -0.0 0.0</pose>
			<inertial>
				<pose frame="">0.0 0.0 0.0 0 0 0</pose>
				<mass>1.2901732110513289</mass>
				<inertia>
					<ixx>0.2345064122128461</ixx>
					<ixy>-0.08153764938061651</ixy>
					<ixz>0.1021578972073596</ixz>
					<iyy>0.1871972716611009</iyy>
					<iyz>0.09111528593148031</iyz>
					<izz>0.19276277957793403</izz>
				</inertia>
			</inertial>
			<collision name="lower_arm_collision">
				<geometry>
					<mesh>
						<uri>model://musc-le/meshes/CAD/lower_arm.stl</uri>
						<scale>0.001 0.001 0.001</scale>
					</mesh>
				</geometry>
			</collision>
			<visual name="lower_arm_visual">
				<geometry>
					<mesh>
						<uri>model://musc-le/meshes/CAD/lower_arm.stl</uri>
						<scale>0.001 0.001 0.001</scale>
					</mesh>
				</geometry>
			</visual>
		</link>
		<link name="upper_arm">
			<self_collide>false</self_collide>
			<pose frame="">0.23772306114161412 0.604642048275606 -0.29898749930157065 0.0 -0.0 0.0</pose>
			<inertial>
				<pose frame="">0.0 0.0 0.0 0 0 0</pose>
				<mass>0.7435346715582283</mass>
				<inertia>
					<ixx>0.3495231703787906</ixx>
					<ixy>-0.10688751289004544</ixy>
					<ixz>0.1344176765845846</ixz>
					<iyy>0.10859018120265673</iyy>
					<iyz>0.05284765761749834</iyz>
					<izz>0.3250869683169522</izz>
				</inertia>
			</inertial>
			<collision name="upper_arm_collision">
				<geometry>
					<mesh>
						<uri>model://musc-le/meshes/CAD/upper_arm.stl</uri>
						<scale>0.001 0.001 0.001</scale>
					</mesh>
				</geometry>
			</collision>
			<visual name="upper_arm_visual">
				<geometry>
					<mesh>
						<uri>model://musc-le/meshes/CAD/upper_arm.stl</uri>
						<scale>0.001 0.001 0.001</scale>
					</mesh>
				</geometry>
			</visual>
		</link>
		<joint name="lower_joint" type="revolute">
			<parent>lower_arm</parent>
			<child>base</child>
			<pose frame="">0.017787833974146922 0.04677970783473343 -0.00011706152842346995 0 0 0</pose>
			<axis>
				<xyz>-1.0 8.88178419700125e-16 -2.38764662138316e-16</xyz>
				<limit>
					<lower>-1.0471975511965976</lower>
					<upper>1.0471975511965976</upper>
				</limit>
				<use_parent_model_frame>0</use_parent_model_frame>
			</axis>
		</joint>
		<joint name="upper_joint" type="revolute">
			<parent>lower_arm</parent>
			<child>upper_arm</child>
			<pose frame="">0.00347693885838531 -0.13775341670492344 3.318849783259026e-05 0 0 0</pose>
			<axis>
				<xyz>1.0000000000000002 -9.575673587391975e-16 8.881784197001252e-16</xyz>
				<limit>
					<lower>-1.5707963267948966</lower>
					<upper>1.5707963267948966</upper>
				</limit>
				<use_parent_model_frame>0</use_parent_model_frame>
			</axis>
		</joint>
		<plugin filename="libmusc_plugin.so" name="musc_plugin">
			<myoMuscle name="motor0">
				<link name="base">
					<viaPoint type="FIXPOINT">-0.0025693968515999544 0.024564330546237384 0.13389346512587755</viaPoint>
				</link>
				<link name="lower_arm">
					<viaPoint type="FIXPOINT">0.0015672600851011965 -0.15626698474390296 -0.0003309107038215942</viaPoint>
				</link>
			</myoMuscle>
			<myoMuscle name="motor1">
				<link name="base">
					<viaPoint type="FIXPOINT">-0.003794381457094538 0.02571414424460665 -0.12912707652655006</viaPoint>
				</link>
				<link name="lower_arm">
					<viaPoint type="FIXPOINT">0.0015672600851011965 -0.15626698474390296 -0.00933091070382158</viaPoint>
				</link>
			</myoMuscle>
			<myoMuscle name="motor2">
				<link name="lower_arm">
					<viaPoint type="FIXPOINT">-0.001026907919200788 0.09199619772767427 0.02150375212969067</viaPoint>
				</link>
				<link name="upper_arm">
					<viaPoint type="FIXPOINT">0.001977134435725532 -0.12397331317959832 0.016263046627272112</viaPoint>
				</link>
			</myoMuscle>
			<myoMuscle name="motor3">
				<link name="lower_arm">
					<viaPoint type="FIXPOINT">0.002737522943281583 0.06699619772767562 -0.03428689387733371</viaPoint>
				</link>
				<link name="upper_arm">
					<viaPoint type="FIXPOINT">0.0019771344357255674 -0.1239733131795984 -0.01619666963160693</viaPoint>
				</link>
			</myoMuscle>
		</plugin>
	</model>
</sdf>
