<?xml version="1.0" ?>
<sdf version="1.6">
	<model name="TestCube">
		<link name="rigidGroup_1">
			<pose frame="">0.0 0.0 0.016666666666666666 0.0 -0.0 0.0</pose>
			<inertial>
				<pose frame="">0.0 0.0 0 0 0 0</pose>
				<mass>2.9437499999999996</mass>
				<inertia>
					<ixx>0.004292968750000002</ixx>
					<ixy>0.0</ixy>
					<ixz>0.0</ixz>
					<iyy>0.004292968749999999</iyy>
					<iyz>0.0</iyz>
					<izz>0.0061328125</izz>
				</inertia>
			</inertial>
			<collision name="rigidGroup_1_collision">
				<geometry>
					<mesh>
						<uri>model://TestCube/meshes/CAD/rigidGroup_1.stl</uri>
						<scale>0.001 0.001 0.001</scale>
					</mesh>
				</geometry>
			</collision>
			<visual name="rigidGroup_1_visual">
				<geometry>
					<mesh>
						<uri>model://TestCube/meshes/CAD/rigidGroup_1.stl</uri>
						<scale>0.001 0.001 0.001</scale>
					</mesh>
				</geometry>
			</visual>
		</link>
		<link name="rigidGroup_2">
			<pose frame="">0.037500000000000006 0.0 0.06250000000000001 0.0 -0.0 0.0</pose>
			<inertial>
				<pose frame="">0 0 0 0 0 0</pose>
				<mass>0.7359374999999999</mass>
				<inertia>
					<ixx>0.006132812499999998</ixx>
					<ixy>-3.346656285430072e-20</ixy>
					<ixz>2.788880237858393e-19</ixz>
					<iyy>0.007052734374999998</iyy>
					<iyz>-0.0024147949218749996</iyz>
					<izz>0.0012265624999999998</izz>
				</inertia>
			</inertial>
			<collision name="rigidGroup_2_collision">
				<geometry>
					<mesh>
						<uri>model://TestCube/meshes/CAD/rigidGroup_2.stl</uri>
						<scale>0.001 0.001 0.001</scale>
					</mesh>
				</geometry>
			</collision>
			<visual name="rigidGroup_2_visual">
				<geometry>
					<mesh>
						<uri>model://TestCube/meshes/CAD/rigidGroup_2.stl</uri>
						<scale>0.001 0.001 0.001</scale>
					</mesh>
				</geometry>
			</visual>
		</link>
		<link name="rigidGroup_3">
			<pose frame="">-0.037500000000000006 0.0 0.08750000000000002 0.0 -0.0 0.0</pose>
			<inertial>
				<pose frame="">0 0 0 0 0 0</pose>
				<mass>0.7359374999999999</mass>
				<inertia>
					<ixx>0.0061328124999999985</ixx>
					<ixy>0.0</ixy>
					<ixz>0.0</ixz>
					<iyy>0.007052734374999999</iyy>
					<iyz>0.002414794921875</iyz>
					<izz>0.0012265624999999998</izz>
				</inertia>
			</inertial>
			<collision name="rigidGroup_3_collision">
				<geometry>
					<mesh>
						<uri>model://TestCube/meshes/CAD/rigidGroup_3.stl</uri>
						<scale>0.001 0.001 0.001</scale>
					</mesh>
				</geometry>
			</collision>
			<visual name="rigidGroup_3_visual">
				<geometry>
					<mesh>
						<uri>model://TestCube/meshes/CAD/rigidGroup_3.stl</uri>
						<scale>0.001 0.001 0.001</scale>
					</mesh>
				</geometry>
			</visual>
		</link>
		<joint name="joint_1" type="revolute">
			<parent>rigidGroup_1</parent>
			<child>rigidGroup_2</child>
			<pose frame="">-0.012500000000000004 0.0 -0.01250000000000001 0 0 0</pose>
			<axis>
				<xyz>0.0 1.0 0.0</xyz>
				<limit>
					<lower>-1.5707963267948966</lower>
					<upper>1.5707963267948966</upper>
				</limit>
				<use_parent_model_frame>0</use_parent_model_frame>
			</axis>
		</joint>
		<joint name="joint_2" type="revolute">
			<parent>rigidGroup_1</parent>
			<child>rigidGroup_3</child>
			<pose frame="">0.012500000000000004 0.0 -0.03750000000000002 0 0 0</pose>
			<axis>
				<xyz>0.0 -1.0 0.0</xyz>
				<limit>
					<lower>-1.5707963267948966</lower>
					<upper>1.5707963267948966</upper>
				</limit>
				<use_parent_model_frame>0</use_parent_model_frame>
			</axis>
		</joint>
		<plugin filename="libmyomuscle_plugin.so" name="myomuscle_plugin"/>
	</model>
</sdf>
