<sdf version="1.5">
    <model name="legs_with_muscles_simplified">
        <link name="halterung">
            <pose frame="">0 0 0 0 -0 0</pose>
            <inertial>
                <pose frame="">1.1276 0.210176 -0.90845 0 -0 0</pose>
                <mass>10.8434</mass>
                <inertia>
                    <ixx>4.12271</ixx>
                    <ixy>-0.000292386</ixy>
                    <ixz>0.000533211</ixz>
                    <iyy>6.85623</iyy>
                    <iyz>-0.0478948</iyz>
                    <izz>4.28379</izz>
                </inertia>
            </inertial>
            <collision name="halterung_collision">
                <pose frame="">0 0 0 0 -0 0</pose>
                <geometry>
                    <mesh>
                        <scale>1 1 1</scale>
                        <uri>model://legs_with_muscles_simplified/cad/halterung.STL</uri>
                    </mesh>
                </geometry>
            </collision>
            <visual name="halterung_visual">
                <pose frame="">0 0 0 0 -0 0</pose>
                <geometry>
                    <mesh>
                        <scale>1 1 1</scale>
                        <uri>model://legs_with_muscles_simplified/cad/halterung.STL</uri>
                    </mesh>
                </geometry>
            </visual>
        </link>

        <plugin filename="libforce_compensating_halterung.so" name="ForceCompensatingHalterung" />

        <joint name="attachment" type="prismatic">
            <child>hip</child>
            <parent>halterung</parent>
            <axis>
                <xyz>0 0 1</xyz>
                <limit>
                    <lower>-0.1</lower>
                    <upper>-0.1</upper>
                </limit>
                <dynamics>
                    <spring_reference>0</spring_reference>
                    <spring_stiffness>0</spring_stiffness>
                </dynamics>
                <use_parent_model_frame>1</use_parent_model_frame>
            </axis>
            <sensor name="force_torque_halterung" type="force_torque">
                <plugin filename="libforce_torque_plugin_halterung.so" name="force_torque_halterung" />
                <update_rate>10</update_rate>
            </sensor>
        </joint>

        <link name="hip">
            <self_collide>true</self_collide>
            <pose frame="">1.1274 0.36147 0.784 -0 0 0</pose>
            <inertial>
                <pose frame="">-0.015888 -0.021368 0.178945 0 -0 0</pose>
                <mass>1.51173</mass>
                <inertia>
                    <ixx>0.00636164</ixx>
                    <ixy>8.74375e-05</ixy>
                    <ixz>0.000422629</ixz>
                    <iyy>0.0224549</iyy>
                    <iyz>-0.000322312</iyz>
                    <izz>0.0238516</izz>
                </inertia>
            </inertial>
            <collision name="hip_collision">
                <pose frame="">0 0 0 0 -0 0</pose>
                <geometry>
                    <mesh>
                        <scale>1 1 1</scale>
                        <uri>model://legs_with_muscles_simplified/cad/hip.STL</uri>
                    </mesh>
                </geometry>
            </collision>
            <visual name="hip_visual">
                <pose frame="">0 0 0 0 -0 0</pose>
                <geometry>
                    <mesh>
                        <scale>1 1 1</scale>
                        <uri>model://legs_with_muscles_simplified/cad/hip.STL</uri>
                    </mesh>
                </geometry>
            </visual>
        </link>

        <link name="thigh_left">
            <self_collide>true</self_collide>
            <pose frame="">1.3259 0.31786 0.9168 -0.10152 -0.3963 -1.5708</pose>
            <inertial>
                <pose frame="">0.000286 -0.010412 -0.183991 0 -0 0</pose>
                <mass>0.659681</mass>
                <inertia>
                    <ixx>0.0113357</ixx>
                    <ixy>-2.79421e-05</ixy>
                    <ixz>0.000115542</ixz>
                    <iyy>0.0115361</iyy>
                    <iyz>0.000112057</iyz>
                    <izz>0.00109214</izz>
                </inertia>
            </inertial>
            <collision name="thigh_left_collision">
                <pose frame="">0 0 0 0 -0 0</pose>
                <geometry>
                    <mesh>
                        <scale>1 1 1</scale>
                        <uri>model://legs_with_muscles_simplified/cad/thigh_left.STL</uri>
                    </mesh>
                </geometry>
            </collision>
            <visual name="thigh_left_visual">
                <pose frame="">0 0 0 0 -0 0</pose>
                <geometry>
                    <mesh>
                        <scale>1 1 1</scale>
                        <uri>model://legs_with_muscles_simplified/cad/thigh_left.STL</uri>
                    </mesh>
                </geometry>
            </visual>
        </link>

        <joint name="groin_left" type="universal">
            <child>thigh_left</child>
            <parent>hip</parent>
            <axis>
                <xyz>-0.999998 5.26837e-06 5.31484e-06</xyz>
                <limit>
                    <lower>-0.5</lower>
                    <upper>0.5</upper>
                </limit>
                <dynamics>
                    <damping>0.0</damping>
                    <friction>0.0</friction>
                </dynamics>
                <use_parent_model_frame>1</use_parent_model_frame>
            </axis>
        </joint>

        <link name="shank_left">
            <self_collide>true</self_collide>
            <pose frame="">1.26469 0.180001 0.52905 -0.220311 0.093629 -0.039303</pose>
            <inertial>
                <pose frame="">0.02057 -0.021545 -0.147737 0 -0 0</pose>
                <mass>0.577599</mass>
                <inertia>
                    <ixx>0.00491098</ixx>
                    <ixy>2.22216e-06</ixy>
                    <ixz>-5.14211e-06</ixz>
                    <iyy>0.0044954</iyy>
                    <iyz>7.55149e-05</iyz>
                    <izz>0.000636166</izz>
                </inertia>
            </inertial>
            <collision name="shank_left_collision">
                <pose frame="">0 0 0 0 -0 0</pose>
                <geometry>
                    <mesh>
                        <scale>1 1 1</scale>
                        <uri>model://legs_with_muscles_simplified/cad/shank_left.STL</uri>
                    </mesh>
                </geometry>
            </collision>
            <visual name="shank_left_visual">
                <pose frame="">0 0 0 0 -0 0</pose>
                <geometry>
                    <mesh>
                        <scale>1 1 1</scale>
                        <uri>model://legs_with_muscles_simplified/cad/shank_left.STL</uri>
                    </mesh>
                </geometry>
            </visual>
        </link>

        <joint name="knee_left" type="revolute">
            <child>shank_left</child>
            <parent>thigh_left</parent>
            <axis>
                <xyz>-0.994851 0.039121 0.093492</xyz>
                <limit>
                    <lower>-2.0</lower>
                    <upper>0.0</upper>
                </limit>
                <dynamics>
                    <damping>0.01</damping>
                    <friction>0.1</friction>
                </dynamics>
                <use_parent_model_frame>1</use_parent_model_frame>
            </axis>
        </joint>

        <link name="foot_left">
            <self_collide>true</self_collide>
            <pose frame="">1.25306 0.089157 0.224046 0.09363 0.001166 1.53161</pose>
            <inertial>
                <pose frame="">-0.036499 0.002038 -0.076713 0 -0 0</pose>
                <mass>0.286522</mass>
                <inertia>
                    <ixx>0.000354226</ixx>
                    <ixy>-4.01085e-05</ixy>
                    <ixz>0.000184642</ixz>
                    <iyy>0.00123644</iyy>
                    <iyz>-8.15882e-06</iyz>
                    <izz>0.00110135</izz>
                </inertia>
            </inertial>
            <collision name="foot_left_collision">
                <pose frame="">0 0 0 0 -0 0</pose>
                <geometry>
                    <mesh>
                        <scale>1 1 1</scale>
                        <uri>model://legs_with_muscles_simplified/cad/foot_left.STL</uri>
                    </mesh>
                </geometry>
                <surface>
                    <friction>
                        <ode>
                            <mu>10000</mu>
                            <mu2>10000</mu2>
                        </ode>
                    </friction>
                </surface>
            </collision>
            <visual name="foot_left_visual">
                <pose frame="">0 0 0 0 -0 0</pose>
                <geometry>
                    <mesh>
                        <scale>1 1 1</scale>
                        <uri>model://legs_with_muscles_simplified/cad/foot_left.STL</uri>
                    </mesh>
                </geometry>
            </visual>
        </link>

        <joint name="ankle_left" type="revolute">
            <child>foot_left</child>
            <parent>shank_left</parent>
            <axis>
                <xyz>0.994851 -0.039117 -0.093493</xyz>
                <limit>
                    <lower>-1.0</lower>
                    <upper>1.0</upper>
                </limit>
                <dynamics>
                    <damping>0.01</damping>
                    <friction>0.1</friction>
                </dynamics>
                <use_parent_model_frame>1</use_parent_model_frame>
            </axis>
            <sensor name="force_torque_ankle_left" type="force_torque">
                <plugin filename="libforce_torque_plugin.so" name="force_torque_ankle_left" />
                <update_rate>10</update_rate>
            </sensor>
        </joint>

        <link name="thigh_right">
            <self_collide>true</self_collide>
            <pose frame="">0.9289 0.31786 0.9168 0.19207 0.42058 1.5708</pose>
            <inertial>
                <pose frame="">0.001676 -0.010411 -0.183991 0 -0 0</pose>
                <mass>0.659685</mass>
                <inertia>
                    <ixx>0.0113355</ixx>
                    <ixy>-1.8392e-05</ixy>
                    <ixz>-9.10039e-05</ixz>
                    <iyy>0.0115343</iyy>
                    <iyz>0.000112017</iyz>
                    <izz>0.00109035</izz>
                </inertia>
            </inertial>
            <collision name="thigh_right_collision">
                <pose frame="">0 0 0 0 -0 0</pose>
                <geometry>
                    <mesh>
                        <scale>1 1 1</scale>
                        <uri>model://legs_with_muscles_simplified/cad/thigh_right.STL</uri>
                    </mesh>
                </geometry>
            </collision>
            <visual name="thigh_right_visual">
                <pose frame="">0 0 0 0 -0 0</pose>
                <geometry>
                    <mesh>
                        <scale>1 1 1</scale>
                        <uri>model://legs_with_muscles_simplified/cad/thigh_right.STL</uri>
                    </mesh>
                </geometry>
            </visual>
        </link>

        <joint name="groin_right" type="universal">
            <child>thigh_right</child>
            <parent>hip</parent>
            <axis>
                <xyz>0.999999 3.36658e-06 -9.38235e-07</xyz>
                <limit>
                    <lower>-0.5</lower>
                    <upper>0.5</upper>
                </limit>
                <dynamics>
                    <damping>0.01</damping>
                    <friction>0.1</friction>
                </dynamics>
                <use_parent_model_frame>1</use_parent_model_frame>
            </axis>
        </joint>

        <link name="shank_right">
            <self_collide>true</self_collide>
            <pose frame="">0.830785 0.173575 0.5391 0.049149 0.175148 -0.079232</pose>
            <inertial>
                <pose frame="">0.02057 -0.021545 -0.147737 0 -0 0</pose>
                <mass>0.577597</mass>
                <inertia>
                    <ixx>0.00491097</ixx>
                    <ixy>2.22339e-06</ixy>
                    <ixz>-5.14968e-06</ixz>
                    <iyy>0.0044954</iyy>
                    <iyz>7.56232e-05</iyz>
                    <izz>0.000636156</izz>
                </inertia>
            </inertial>
            <collision name="shank_right_collision">
                <pose frame="">0 0 0 0 -0 0</pose>
                <geometry>
                    <mesh>
                        <scale>1 1 1</scale>
                        <uri>model://legs_with_muscles_simplified/cad/shank_right.STL</uri>
                    </mesh>
                </geometry>
            </collision>
            <visual name="shank_right_visual">
                <pose frame="">0 0 0 0 -0 0</pose>
                <geometry>
                    <mesh>
                        <scale>1 1 1</scale>
                        <uri>model://legs_with_muscles_simplified/cad/shank_right.STL</uri>
                    </mesh>
                </geometry>
            </visual>
        </link>

        <joint name="knee_right" type="revolute">
            <child>shank_right</child>
            <parent>thigh_right</parent>
            <axis>
                <xyz>-0.981611 0.077939 0.174254</xyz>
                <limit>
                    <lower>-2.0</lower>
                    <upper>0.0</upper>
                </limit>
                <dynamics>
                    <spring_reference>0</spring_reference>
                    <spring_stiffness>0</spring_stiffness>
                </dynamics>
                <use_parent_model_frame>1</use_parent_model_frame>
            </axis>
        </joint>

        <link name="foot_right">
            <self_collide>true</self_collide>
            <pose frame="">0.795171 0.169482 0.222667 0.215101 -0.615676 1.36606</pose>
            <inertial>
                <pose frame="">-0.041774 -0.001423 -0.058865 0 -0 0</pose>
                <mass>0.137654</mass>
                <inertia>
                    <ixx>0.000176657</ixx>
                    <ixy>3.25039e-05</ixy>
                    <ixz>0.000214945</ixz>
                    <iyy>0.000751517</iyy>
                    <iyz>7.22661e-06</iyz>
                    <izz>0.000642128</izz>
                </inertia>
            </inertial>
            <collision name="foot_right_collision">
                <pose frame="">0 0 0 0 -0 0</pose>
                <geometry>
                    <mesh>
                        <scale>1 1 1</scale>
                        <uri>model://legs_with_muscles_simplified/cad/foot_right.STL</uri>
                    </mesh>
                </geometry>
                <surface>
                    <friction>
                        <ode>
                            <mu>10000</mu>
                            <mu2>10000</mu2>
                        </ode>
                    </friction>
                </surface>
            </collision>
            <visual name="foot_right_visual">
                <pose frame="">0 0 0 0 -0 0</pose>
                <geometry>
                    <mesh>
                        <scale>1 1 1</scale>
                        <uri>model://legs_with_muscles_simplified/cad/foot_right.STL</uri>
                    </mesh>
                </geometry>
            </visual>
        </link>

        <joint name="ankle_right" type="revolute">
            <child>foot_right</child>
            <parent>shank_right</parent>
            <axis>
                <xyz>0.981612 -0.077935 -0.174254</xyz>
                <limit>
                    <lower>-1.0</lower>
                    <upper>1.0</upper>
                </limit>
                <dynamics>
                    <damping>0.0</damping>
                    <friction>0.0</friction>
                </dynamics>
                <use_parent_model_frame>1</use_parent_model_frame>
            </axis>
            <sensor name="force_torque_ankle_right" type="force_torque">
                <plugin filename="libforce_torque_plugin.so" name="force_torque_ankle_right" />
                <update_rate>10</update_rate>
            </sensor>
        </joint>

        <plugin filename="libWalkController.so" name="walkController">
            <myoMuscle name="motor0">
                <link name="hip">
                    <viaPoint type="FIXPOINT">0.183393 -0.084726 0.205866</viaPoint>
                </link>
                <link name="thigh_left">
                    <viaPoint type="FIXPOINT">0.025100 0.000764 -0.064595</viaPoint>
                </link>
                <spanningJoint name="groin_left">extensor</spanningJoint>
            </myoMuscle>

            <myoMuscle name="motor1">
                <link name="hip">
                    <viaPoint type="FIXPOINT">0.185599 0.010843 0.181247</viaPoint>
                </link>
                <link name="thigh_left">
                    <viaPoint type="FIXPOINT">-0.000043 0.024390 -0.063752</viaPoint>
                </link>
                <spanningJoint name="groin_left">extensor</spanningJoint>
            </myoMuscle>

            <myoMuscle name="motor2">
                <link name="hip">
                    <viaPoint type="FIXPOINT">0.185656 0.011172 0.182494</viaPoint>
                </link>
                <link name="thigh_left">
                    <viaPoint type="FIXPOINT">-0.024817 0.000441 -0.064241</viaPoint>
                </link>
                <spanningJoint name="groin_left">extensor</spanningJoint>
            </myoMuscle>

            <myoMuscle name="motor3">
                <link name="thigh_left">
                    <viaPoint type="FIXPOINT">0.003493 -0.054921 -0.105452</viaPoint>
                </link>
                <link name="hip">
                    <viaPoint type="FIXPOINT">0.154889 -0.046439 0.144846</viaPoint>
                </link>
                <spanningJoint name="groin_left">flexor</spanningJoint>
            </myoMuscle>

            <myoMuscle name="motor4">
                <link name="thigh_left">
                    <viaPoint type="FIXPOINT">-0.035482 -0.000749 -0.329542</viaPoint>
                </link>
                <link name="shank_left">
                    <viaPoint type="FIXPOINT">0.019173 0.001305 -0.053000</viaPoint>
                </link>
                <spanningJoint name="knee_left">extensor</spanningJoint>
            </myoMuscle>

            <myoMuscle name="motor5">
                <link name="thigh_left">
                    <viaPoint type="FIXPOINT">0.032773 0.000074 -0.329491</viaPoint>
                </link>
                <link name="shank_left">
                    <viaPoint type="FIXPOINT">0.017193 -0.043785 -0.053000</viaPoint>
                </link>
                <spanningJoint name="knee_left">flexor</spanningJoint>
            </myoMuscle>

            <myoMuscle name="motor6">
                <link name="shank_left">
                    <viaPoint type="FIXPOINT">0.018940 -0.053314 -0.233449</viaPoint>
                </link>
                <link name="foot_left">
                    <viaPoint type="FIXPOINT">-0.042941 -0.001341 -0.024222</viaPoint>
                </link>
                <spanningJoint name="ankle_left">extensor</spanningJoint>
            </myoMuscle>

            <myoMuscle name="motor7">
                <link name="shank_left">
                    <viaPoint type="FIXPOINT">0.018918 0.008469 -0.232968</viaPoint>
                </link>
                <link name="foot_left">
                    <viaPoint type="FIXPOINT">0.040030 0.000076 -0.022690</viaPoint>
                </link>
                <spanningJoint name="ankle_left">flexor</spanningJoint>
            </myoMuscle>

            <myoMuscle name="motor8">
                <link name="hip">
                    <viaPoint type="FIXPOINT">-0.184878 -0.085229 0.205781</viaPoint>
                </link>
                <link name="thigh_right">
                    <viaPoint type="FIXPOINT">-0.024866 0.000448 -0.063830</viaPoint>
                </link>
                <spanningJoint name="groin_right">extensor</spanningJoint>
            </myoMuscle>

            <myoMuscle name="motor9">
                <link name="hip">
                    <viaPoint type="FIXPOINT">-0.230107 -0.034395 0.218452</viaPoint>
                </link>
                <link name="thigh_right">
                    <viaPoint type="FIXPOINT">-0.000182 0.024079 -0.064310</viaPoint>
                </link>
                <spanningJoint name="groin_right">extensor</spanningJoint>
            </myoMuscle>

            <myoMuscle name="motor10">
                <link name="hip">
                    <viaPoint type="FIXPOINT">-0.185232 0.011356 0.183027</viaPoint>
                </link>
                <link name="thigh_right">
                    <viaPoint type="FIXPOINT">0.024328 -0.000028 -0.064339</viaPoint>
                </link>
                <spanningJoint name="groin_right">extensor</spanningJoint>
            </myoMuscle>

            <myoMuscle name="motor11">
                <link name="thigh_right">
                    <viaPoint type="FIXPOINT">-0.001469 -0.053012 -0.107943</viaPoint>
                </link>
                <link name="hip">
                    <viaPoint type="FIXPOINT">-0.153967 -0.046307 0.144022</viaPoint>
                </link>
                <spanningJoint name="groin_right">flexor</spanningJoint>
            </myoMuscle>

            <myoMuscle name="motor12">
                <link name="thigh_right">
                    <viaPoint type="FIXPOINT">-0.033081 -0.000652 -0.328793</viaPoint>
                </link>
                <link name="shank_right">
                    <viaPoint type="FIXPOINT">0.017193 -0.043785 -0.053000</viaPoint>
                </link>
                <spanningJoint name="knee_right">extensor</spanningJoint>
            </myoMuscle>

            <myoMuscle name="motor13">
                <link name="thigh_right">
                    <viaPoint type="FIXPOINT">0.032773 0.000074 -0.329491</viaPoint>
                </link>
                <link name="shank_right">
                    <viaPoint type="FIXPOINT">0.019173 0.001305 -0.053000</viaPoint>
                </link>
                <spanningJoint name="knee_right">flexor</spanningJoint>
            </myoMuscle>

            <myoMuscle name="motor14">
                <link name="shank_right">
                    <viaPoint type="FIXPOINT">0.018940 -0.053314 -0.233449</viaPoint>
                </link>
                <link name="foot_right">
                    <viaPoint type="FIXPOINT">-0.042941 -0.001341 -0.024222</viaPoint>
                </link>
                <spanningJoint name="ankle_right">extensor</spanningJoint>
            </myoMuscle>

            <myoMuscle name="motor15">
                <link name="shank_right">
                    <viaPoint type="FIXPOINT">0.018918 0.008469 -0.232968</viaPoint>
                </link>
                <link name="foot_right">
                    <viaPoint type="FIXPOINT">0.040030 0.000076 -0.022690</viaPoint>
                </link>
                <spanningJoint name="ankle_right">flexor</spanningJoint>
            </myoMuscle>

            <foot_sole_left>0 0 -0.1085</foot_sole_left>
            <foot_sole_right>0 0 -0.1085</foot_sole_right>
        </plugin>
    </model>
</sdf>