<?xml version="1.0" ?>
<robot name="roboy_infineon_game">
  <joint name="elbow_right_rot1" type="revolute">
    <parent link="elbow_right"/>
    <child link="lower_arm_right"/>
    <origin rpy="0 0 0" xyz="0.01877  0.00257 -0.06612"/>
    <axis xyz="-0.01118  0.0229   0.99967"/>
    <limit effort="0.0" lower="-1.57079632679" upper="1.57079632679" velocity="0.0"/>
  </joint>
  <joint name="hip_joint" type="revolute">
    <parent link="base"/>
    <child link="torso"/>
    <origin rpy="0 0 0" xyz="0      0.00152 0.29933"/>
    <axis xyz="0 0 1"/>
    <limit effort="0.0" lower="-1.0471975512" upper="1.0471975512" velocity="0.0"/>
  </joint>
  <joint name="sphere_left_axis0" type="revolute">
    <parent link="torso"/>
    <child link="sphere_left_link1"/>
    <origin rpy="0 0 0" xyz="0.29218 0.00768 0.24927"/>
    <axis xyz="0 1 0"/>
    <limit effort="0.0" lower="-3.14159265359" upper="3.14159265359" velocity="0.0"/>
  </joint>
  <joint name="sphere_left_axis1" type="revolute">
    <parent link="sphere_left_link1"/>
    <child link="sphere_left_link2"/>
    <origin rpy="0 0 0" xyz="0 0 0"/>
    <axis xyz="1 0 0"/>
    <limit effort="0.0" lower="-3.14159265359" upper="3.14159265359" velocity="0.0"/>
  </joint>
  <joint name="sphere_left_axis2" type="revolute">
    <parent link="sphere_left_link2"/>
    <child link="upper_arm_left"/>
    <origin rpy="0 0 0" xyz="0 0 0"/>
    <axis xyz="0 0 1"/>
    <limit effort="0.0" lower="-3.14159265359" upper="3.14159265359" velocity="0.0"/>
  </joint>
  <joint name="elbow_left_rot1" type="revolute">
    <parent link="elbow_left"/>
    <child link="lower_arm_left"/>
    <origin rpy="0 0 0" xyz="-0.01877  0.00257 -0.06612"/>
    <axis xyz="-0.01118 -0.0229  -0.99967"/>
    <limit effort="0.0" lower="-1.57079632679" upper="1.57079632679" velocity="0.0"/>
  </joint>
  <joint name="elbow_left_rot0" type="revolute">
    <parent link="upper_arm_left"/>
    <child link="elbow_left"/>
    <origin rpy="0 0 0" xyz="0.01493 -0.01022 -0.26751"/>
    <axis xyz="-0.99863 -0.05074  0.01234"/>
    <limit effort="0.0" lower="0.0" upper="1.57079632679" velocity="0.0"/>
  </joint>
  <joint name="left_palm_ring" type="revolute">
    <parent link="palm"/>
    <child link="left_ring_limb0"/>
    <origin rpy="0 0 0" xyz="-0.00541  0.02706 -0.10052"/>
    <axis xyz="0.0506  -0.97015 -0.23715"/>
    <limit effort="0.0" lower="-1.2217304764" upper="0.349065850399" velocity="0.0"/>
  </joint>
  <joint name="left_palm_index" type="revolute">
    <parent link="palm"/>
    <child link="left_index_limb0"/>
    <origin rpy="0 0 0" xyz="-0.00284 -0.01188 -0.09578"/>
    <axis xyz="0.06912 -0.95751  0.27999"/>
    <limit effort="0.0" lower="-1.2217304764" upper="0.349065850399" velocity="0.0"/>
  </joint>
  <joint name="left_palm_thumb" type="revolute">
    <parent link="palm"/>
    <child link="left_thumb_limb0"/>
    <origin rpy="0 0 0" xyz="-0.02788 -0.00743 -0.04579"/>
    <axis xyz="-0.87306  0.30848  0.37761"/>
    <limit effort="0.0" lower="-1.2217304764" upper="0.872664625997" velocity="0.0"/>
  </joint>
  <joint name="left_palm_little" type="fixed">
    <parent link="palm"/>
    <child link="left_little_limb0"/>
    <origin rpy="0 0 0" xyz="-0.00591  0.04283 -0.08809"/>
    <axis xyz="-0.03578  0.87635  0.48032"/>
    <limit effort="0.0" lower="0.0" upper="0.0" velocity="0.0"/>
  </joint>
  <joint name="left_palm_middle" type="revolute">
    <parent link="palm"/>
    <child link="left_middle_limb0"/>
    <origin rpy="0 0 0" xyz="-0.0051   0.02017 -0.10367"/>
    <axis xyz="0.06197 -0.99783  0.02217"/>
    <limit effort="0.0" lower="-1.2217304764" upper="0.349065850399" velocity="0.0"/>
  </joint>
  <joint name="left_wrist_0" type="revolute">
    <parent link="lower_arm_left"/>
    <child link="wrist_left_1"/>
    <origin rpy="0 0 0" xyz="-0.01441 -0.00671 -0.26206"/>
    <axis xyz="-0.99743 -0.06112  0.03722"/>
    <limit effort="0.0" lower="-0.523598775598" upper="0.523598775598" velocity="0.0"/>
  </joint>
  <joint name="left_wrist_1" type="revolute">
    <parent link="wrist_left_1"/>
    <child link="palm"/>
    <origin rpy="0 0 0" xyz="0.01155 -0.01682  0"/>
    <axis xyz="-0.06197  0.99783 -0.02217"/>
    <limit effort="0.0" lower="-0.523598775598" upper="0.523598775598" velocity="0.0"/>
  </joint>
  <joint name="left_joint0_ring" type="revolute">
    <parent link="left_ring_limb0"/>
    <child link="left_ring_limb1"/>
    <origin rpy="0 0 0" xyz="0.00228 0.00708 0.00313"/>
    <axis xyz="0.8891  -0.06439  0.45314"/>
    <limit effort="0.0" lower="-0.314159265359" upper="0.314159265359" velocity="0.0"/>
  </joint>
  <joint name="left_joint1_ring" type="revolute">
    <parent link="left_ring_limb1"/>
    <child link="left_ring_limb2"/>
    <origin rpy="0 0 0" xyz="-0.00504  0.00685 -0.05229"/>
    <axis xyz="-0.0506   0.97015  0.23715"/>
    <limit effort="0.0" lower="0.0" upper="1.91986217719" velocity="0.0"/>
  </joint>
  <joint name="left_joint2_ring" type="revolute">
    <parent link="left_ring_limb2"/>
    <child link="left_ring_limb3"/>
    <origin rpy="0 0 0" xyz="-0.00018  0.00899 -0.03052"/>
    <axis xyz="-0.0506   0.97015  0.23715"/>
    <limit effort="0.0" lower="0.0" upper="1.2217304764" velocity="0.0"/>
  </joint>
  <joint name="left_joint0_little" type="revolute">
    <parent link="left_little_limb0"/>
    <child link="left_little_limb1"/>
    <origin rpy="0 0 0" xyz="0.00228 0.0059  0.00501"/>
    <axis xyz="0.8526  -0.22396  0.47213"/>
    <limit effort="0.0" lower="-0.314159265359" upper="0.314159265359" velocity="0.0"/>
  </joint>
  <joint name="left_joint1_little" type="revolute">
    <parent link="left_little_limb1"/>
    <child link="left_little_limb2"/>
    <origin rpy="0 0 0" xyz="-0.00114  0.02045 -0.04885"/>
    <axis xyz="-0.03578  0.87635  0.48032"/>
    <limit effort="0.0" lower="0.0" upper="1.91986217719" velocity="0.0"/>
  </joint>
  <joint name="left_joint2_little" type="revolute">
    <parent link="left_little_limb2"/>
    <child link="left_little_limb3"/>
    <origin rpy="0 0 0" xyz="0.00224  0.01662 -0.02704"/>
    <axis xyz="-0.03578  0.87635  0.48032"/>
    <limit effort="0.0" lower="0.0" upper="1.2217304764" velocity="0.0"/>
  </joint>
  <joint name="left_joint0_thumb" type="revolute">
    <parent link="left_thumb_limb0"/>
    <child link="left_thumb_limb1"/>
    <origin rpy="0 0 0" xyz="0.0061  -0.00503 -0.00164"/>
    <axis xyz="-0.14859 -0.90592  0.39651"/>
    <limit effort="0.0" lower="-0.314159265359" upper="0.314159265359" velocity="0.0"/>
  </joint>
  <joint name="left_joint1_thumb" type="revolute">
    <parent link="left_thumb_limb1"/>
    <child link="left_thumb_limb2"/>
    <origin rpy="0 0 0" xyz="-0.02109  0.01479 -0.04629"/>
    <axis xyz="0.87306 -0.30848 -0.37761"/>
    <limit effort="0.0" lower="0.0" upper="1.91986217719" velocity="0.0"/>
  </joint>
  <joint name="left_joint2_thumb" type="revolute">
    <parent link="left_thumb_limb2"/>
    <child link="left_thumb_limb3"/>
    <origin rpy="0 0 0" xyz="0.01536 0.02584 0.01043"/>
    <axis xyz="0.87306 -0.30848 -0.37761"/>
    <limit effort="0.0" lower="0.0" upper="1.2217304764" velocity="0.0"/>
  </joint>
  <joint name="left_joint0_index" type="revolute">
    <parent link="left_index_limb0"/>
    <child link="left_index_limb1"/>
    <origin rpy="0 0 0" xyz="0.0021   0.00776 -0.00075"/>
    <axis xyz="0.87306 0.19386 0.4474"/>
    <limit effort="0.0" lower="-0.314159265359" upper="0.314159265359" velocity="0.0"/>
  </joint>
  <joint name="left_joint1_index" type="revolute">
    <parent link="left_index_limb1"/>
    <child link="left_index_limb2"/>
    <origin rpy="0 0 0" xyz="-0.00325 -0.02026 -0.04884"/>
    <axis xyz="-0.06912  0.95751 -0.27999"/>
    <limit effort="0.0" lower="0.0" upper="1.91986217719" velocity="0.0"/>
  </joint>
  <joint name="left_joint2_index" type="revolute">
    <parent link="left_index_limb2"/>
    <child link="left_index_limb3"/>
    <origin rpy="0 0 0" xyz="0.0008  -0.00742 -0.03093"/>
    <axis xyz="-0.06912  0.95751 -0.27999"/>
    <limit effort="0.0" lower="0.0" upper="1.2217304764" velocity="0.0"/>
  </joint>
  <joint name="left_joint0_middle" type="revolute">
    <parent link="left_middle_limb0"/>
    <child link="left_middle_limb1"/>
    <origin rpy="0 0 0" xyz="0.00295 -0.00479  0.00151"/>
    <axis xyz="0.88169 0.06514 0.46729"/>
    <limit effort="0.0" lower="-0.610865238198" upper="0.610865238198" velocity="0.0"/>
  </joint>
  <joint name="left_joint1_middle" type="revolute">
    <parent link="left_middle_limb1"/>
    <child link="left_middle_limb2"/>
    <origin rpy="0 0 0" xyz="-0.0042  -0.00693 -0.05235"/>
    <axis xyz="-0.06197  0.99783 -0.02217"/>
    <limit effort="0.0" lower="0.0" upper="1.91986217719" velocity="0.0"/>
  </joint>
  <joint name="left_joint2_middle" type="revolute">
    <parent link="left_middle_limb2"/>
    <child link="left_middle_limb3"/>
    <origin rpy="0 0 0" xyz="0.00026  0.00081 -0.0318"/>
    <axis xyz="-0.06197  0.99783 -0.02217"/>
    <limit effort="0.0" lower="0.0" upper="1.2217304764" velocity="0.0"/>
  </joint>
  <joint name="right_joint0_little" type="revolute">
    <parent link="right_little_limb0"/>
    <child link="right_little_limb1"/>
    <origin rpy="0 0 0" xyz="-0.00291 -0.00718 -0.00225"/>
    <axis xyz="-0.86944 -0.20532  0.44935"/>
    <limit effort="0.0" lower="-0.314159265359" upper="0.314159265359" velocity="0.0"/>
  </joint>
  <joint name="right_joint1_little" type="revolute">
    <parent link="right_little_limb1"/>
    <child link="right_little_limb2"/>
    <origin rpy="0 0 0" xyz="0.00333  0.02999 -0.04354"/>
    <axis xyz="-0.04139 -0.87607 -0.48039"/>
    <limit effort="0.0" lower="0.0" upper="1.91986217719" velocity="0.0"/>
  </joint>
  <joint name="right_joint2_little" type="revolute">
    <parent link="right_little_limb2"/>
    <child link="right_little_limb3"/>
    <origin rpy="0 0 0" xyz="-0.00129  0.014   -0.02854"/>
    <axis xyz="-0.04139 -0.87607 -0.48039"/>
    <limit effort="0.0" lower="0.0" upper="1.2217304764" velocity="0.0"/>
  </joint>
  <joint name="sphere_right_axis0" type="revolute">
    <parent link="torso"/>
    <child link="sphere_right_link1"/>
    <origin rpy="0 0 0" xyz="-0.29218  0.00768  0.24927"/>
    <axis xyz="0.05101  0.99844 -0.02231"/>
    <limit effort="0.0" lower="-3.14159265359" upper="3.14159265359" velocity="0.0"/>
  </joint>
  <joint name="sphere_right_axis2" type="revolute">
    <parent link="sphere_right_link2"/>
    <child link="upper_arm_right"/>
    <origin rpy="0 0 0" xyz="0 0 0"/>
    <axis xyz="0.01118 -0.0229  -0.99967"/>
    <limit effort="0.0" lower="-3.14159265359" upper="3.14159265359" velocity="0.0"/>
  </joint>
  <joint name="sphere_right_axis1" type="revolute">
    <parent link="sphere_right_link1"/>
    <child link="sphere_right_link2"/>
    <origin rpy="0 0 0" xyz="0 0 0"/>
    <axis xyz="-0.99863  0.05074 -0.01234"/>
    <limit effort="0.0" lower="-3.14159265359" upper="3.14159265359" velocity="0.0"/>
  </joint>
  <joint name="elbow_right_rot0" type="revolute">
    <parent link="upper_arm_right"/>
    <child link="elbow_right"/>
    <origin rpy="0 0 0" xyz="-0.01492 -0.01024 -0.26851"/>
    <axis xyz="-0.99863  0.05074 -0.01234"/>
    <limit effort="0.0" lower="0.0" upper="1.57079632679" velocity="0.0"/>
  </joint>
  <joint name="right_palm_thumb" type="revolute">
    <parent link="right_palm"/>
    <child link="right_thumb_limb0"/>
    <origin rpy="0 0 0" xyz="0.0243  -0.04223 -0.04634"/>
    <axis xyz="-0.88416 -0.326   -0.33463"/>
    <limit effort="0.0" lower="-1.0471975512" upper="0.785398163397" velocity="0.0"/>
  </joint>
  <joint name="right_palm_little" type="revolute">
    <parent link="right_palm"/>
    <child link="right_little_limb0"/>
    <origin rpy="0 0 0" xyz="-0.00018  0.02034 -0.0804"/>
    <axis xyz="-0.04139 -0.87607 -0.48039"/>
    <limit effort="0.0" lower="-0.523598775598" upper="0.523598775598" velocity="0.0"/>
  </joint>
  <joint name="right_palm_ring" type="revolute">
    <parent link="right_palm"/>
    <child link="right_index_limb0"/>
    <origin rpy="0 0 0" xyz="-0.00094  0.00644 -0.09624"/>
    <axis xyz="-0.04215 -0.97058 -0.23705"/>
    <limit effort="0.0" lower="-0.523598775598" upper="0.523598775598" velocity="0.0"/>
  </joint>
  <joint name="right_palm_middle" type="revolute">
    <parent link="right_palm"/>
    <child link="right_middle_limb0"/>
    <origin rpy="0 0 0" xyz="-0.00181 -0.013   -0.10299"/>
    <axis xyz="-0.04003 -0.99894  0.02244"/>
    <limit effort="0.0" lower="-0.523598775598" upper="0.523598775598" velocity="0.0"/>
  </joint>
  <joint name="right_palm_index" type="revolute">
    <parent link="right_palm"/>
    <child link="right_ring_limb0"/>
    <origin rpy="0 0 0" xyz="-0.00256 -0.03273 -0.09924"/>
    <axis xyz="-0.03519 -0.95923  0.28041"/>
    <limit effort="0.0" lower="-0.523598775598" upper="0.523598775598" velocity="0.0"/>
  </joint>
  <joint name="right_wrist_0" type="revolute">
    <parent link="lower_arm_right"/>
    <child link="wrist_right_1"/>
    <origin rpy="0 0 0" xyz="0.01274 -0.00645 -0.26461"/>
    <axis xyz="0.9991  -0.04032 -0.01255"/>
    <limit effort="0.0" lower="-0.523598775598" upper="0.523598775598" velocity="0.0"/>
  </joint>
  <joint name="right_wrist_1" type="revolute">
    <parent link="wrist_right_1"/>
    <child link="right_palm"/>
    <origin rpy="0 0 0" xyz="-0.00979  0.0179  -0.00026"/>
    <axis xyz="0.04003  0.99894 -0.02244"/>
    <limit effort="0.0" lower="-0.523598775598" upper="0.523598775598" velocity="0.0"/>
  </joint>
  <joint name="right_joint0_ring" type="revolute">
    <parent link="right_ring_limb0"/>
    <child link="right_ring_limb1"/>
    <origin rpy="0 0 0" xyz="-0.00282 -0.00667  0.00357"/>
    <axis xyz="-0.85357  0.17478  0.49077"/>
    <limit effort="0.0" lower="-0.314159265359" upper="0.314159265359" velocity="0.0"/>
  </joint>
  <joint name="right_joint1_ring" type="revolute">
    <parent link="right_ring_limb1"/>
    <child link="right_ring_limb2"/>
    <origin rpy="0 0 0" xyz="0.00162 -0.00955 -0.05208"/>
    <axis xyz="-0.03519 -0.95923  0.28041"/>
    <limit effort="0.0" lower="0.0" upper="1.91986217719" velocity="0.0"/>
  </joint>
  <joint name="right_joint2_ring" type="revolute">
    <parent link="right_ring_limb2"/>
    <child link="right_ring_limb3"/>
    <origin rpy="0 0 0" xyz="-0.00229 -0.01025 -0.03003"/>
    <axis xyz="-0.03519 -0.95923  0.28041"/>
    <limit effort="0.0" lower="0.0" upper="1.2217304764" velocity="0.0"/>
  </joint>
  <joint name="right_joint0_thumb" type="revolute">
    <parent link="right_thumb_limb0"/>
    <child link="right_thumb_limb1"/>
    <origin rpy="0 0 0" xyz="-0.0063  -0.00496 -0.00092"/>
    <axis xyz="0.10974 -0.84116  0.52951"/>
    <limit effort="0.0" lower="-0.314159265359" upper="0.314159265359" velocity="0.0"/>
  </joint>
  <joint name="right_joint1_thumb" type="revolute">
    <parent link="right_thumb_limb1"/>
    <child link="right_thumb_limb2"/>
    <origin rpy="0 0 0" xyz="-0.00151  0.00049 -0.05295"/>
    <axis xyz="0.98121 0.17672 0.07737"/>
    <limit effort="0.0" lower="0.0" upper="1.91986217719" velocity="0.0"/>
  </joint>
  <joint name="right_joint2_thumb" type="revolute">
    <parent link="right_thumb_limb2"/>
    <child link="right_thumb_limb3"/>
    <origin rpy="0 0 0" xyz="-0.0046   0.03033  0.00843"/>
    <axis xyz="0.98121 0.17672 0.07737"/>
    <limit effort="0.0" lower="0.0" upper="1.2217304764" velocity="0.0"/>
  </joint>
  <joint name="right_joint0_index" type="revolute">
    <parent link="right_index_limb0"/>
    <child link="right_index_limb1"/>
    <origin rpy="0 0 0" xyz="-0.0029  -0.00753 -0.00028"/>
    <axis xyz="-0.86394 -0.08376  0.49657"/>
    <limit effort="0.0" lower="-0.314159265359" upper="0.314159265359" velocity="0.0"/>
  </joint>
  <joint name="right_joint1_index" type="revolute">
    <parent link="right_index_limb1"/>
    <child link="right_index_limb2"/>
    <origin rpy="0 0 0" xyz="0.00275  0.01772 -0.04985"/>
    <axis xyz="-0.04215 -0.97058 -0.23705"/>
    <limit effort="0.0" lower="0.0" upper="1.91986217719" velocity="0.0"/>
  </joint>
  <joint name="right_joint2_index" type="revolute">
    <parent link="right_index_limb2"/>
    <child link="right_index_limb3"/>
    <origin rpy="0 0 0" xyz="-0.00164  0.00614 -0.03117"/>
    <axis xyz="-0.04215 -0.97058 -0.23705"/>
    <limit effort="0.0" lower="0.0" upper="1.2217304764" velocity="0.0"/>
  </joint>
  <joint name="right_joint0_middle" type="revolute">
    <parent link="right_middle_limb0"/>
    <child link="right_middle_limb1"/>
    <origin rpy="0 0 0" xyz="-0.00287 -0.00735  0.0017"/>
    <axis xyz="-0.85853  0.04588  0.5107"/>
    <limit effort="0.0" lower="-0.610865238198" upper="0.610865238198" velocity="0.0"/>
  </joint>
  <joint name="right_joint1_middle" type="revolute">
    <parent link="right_middle_limb1"/>
    <child link="right_middle_limb2"/>
    <origin rpy="0 0 0" xyz="0.00217  0.00423 -0.05276"/>
    <axis xyz="-0.04003 -0.99894  0.02244"/>
    <limit effort="0.0" lower="0.0" upper="1.91986217719" velocity="0.0"/>
  </joint>
  <joint name="right_joint2_middle" type="revolute">
    <parent link="right_middle_limb2"/>
    <child link="right_middle_limb3"/>
    <origin rpy="0 0 0" xyz="-0.00198 -0.00213 -0.03168"/>
    <axis xyz="-0.04003 -0.99894  0.02244"/>
    <limit effort="0.0" lower="0.0" upper="1.2217304764" velocity="0.0"/>
  </joint>
  <joint name="zed_camera_mount" type="fixed">
    <parent link="head"/>
    <child link="zed_camera"/>
    <origin rpy="0 0 0" xyz="0.0215  -0.05812  0.22344"/>
    <axis xyz="0 0 0"/>
    <limit effort="0" lower="0" upper="0" velocity="0"/>
  </joint>
  <joint name="zed_camera_right" type="fixed">
    <parent link="zed_camera"/>
    <child link="zed_camera_right_lense"/>
    <origin rpy="0 0 0" xyz="-0.0815  -0.00166 -0.00782"/>
    <axis xyz="0 0 0"/>
    <limit effort="0" lower="0" upper="0" velocity="0"/>
  </joint>
  <joint name="zed_camera_left" type="fixed">
    <parent link="zed_camera"/>
    <child link="zed_camera_left_lense"/>
    <origin rpy="0 0 0" xyz="0.03848 -0.00166 -0.00782"/>
    <axis xyz="0 0 0"/>
    <limit effort="0" lower="0" upper="0" velocity="0"/>
  </joint>
  <joint name="sphere_head_axis0" type="revolute">
    <parent link="torso"/>
    <child link="sphere_head_link1"/>
    <origin rpy="0 0 0" xyz="0      0      0.43291"/>
    <axis xyz="0 1 0"/>
    <limit effort="0.0" lower="-0.523598775598" upper="0.523598775598" velocity="0.0"/>
  </joint>
  <joint name="sphere_head_axis2" type="revolute">
    <parent link="shere_head_link2"/>
    <child link="head"/>
    <origin rpy="0 0 0" xyz="0 0 0"/>
    <axis xyz="0 0 1"/>
    <limit effort="0.0" lower="-0.523598775598" upper="0.523598775598" velocity="0.0"/>
  </joint>
  <joint name="sphere_head_axis1" type="revolute">
    <parent link="sphere_head_link1"/>
    <child link="shere_head_link2"/>
    <origin rpy="0 0 0" xyz="0 0 0"/>
    <axis xyz="1 0 0"/>
    <limit effort="0.0" lower="-0.523598775598" upper="0.523598775598" velocity="0.0"/>
  </joint>
  <link name="torso">
    <inertial>
      <mass value="15.585466930961344"/>
      <origin rpy="0 0 0" xyz="0      -0.00152 -0.29933"/>
      <inertia ixx="5.079695742797729" ixy="-0.0010843678464796012" ixz="0.058514557722415025" iyy="5.3496159845193185" iyz="-0.013299822122575307" izz="0.36673495668717304"/>
    </inertial>
    <collision name="torso_collision">
      <origin rpy="0 0 0" xyz="0      -0.00152 -0.29933"/>
      <geometry>
        <mesh filename="package://roboy_models/roboy_infineon_game/meshes/CAD/torso.stl" scale="0.001 0.001 0.001"/>
      </geometry>
    </collision>
    <visual name="torso_visual">
      <origin rpy="0 0 0" xyz="0      -0.00152 -0.29933"/>
      <geometry>
        <mesh filename="package://roboy_models/roboy_infineon_game/meshes/CAD/torso.stl" scale="0.001 0.001 0.001"/>
      </geometry>
    </visual>
  </link>
  <link name="base">
    <inertial>
      <mass value="0.717302060129989"/>
      <origin rpy="0 0 0" xyz="0 0 0"/>
      <inertia ixx="0.006625207321646713" ixy="2.0197911925526476e-05" ixz="-3.596569361034858e-05" iyy="0.014899467579983833" iyz="5.481457241322389e-06" izz="0.012889085164410688"/>
    </inertial>
    <collision name="base_collision">
      <origin rpy="0 0 0" xyz="0 0 0"/>
      <geometry>
        <mesh filename="package://roboy_models/roboy_infineon_game/meshes/CAD/base.stl" scale="0.001 0.001 0.001"/>
      </geometry>
    </collision>
    <visual name="base_visual">
      <origin rpy="0 0 0" xyz="0 0 0"/>
      <geometry>
        <mesh filename="package://roboy_models/roboy_infineon_game/meshes/CAD/base.stl" scale="0.001 0.001 0.001"/>
      </geometry>
    </visual>
  </link>
  <link name="elbow_left">
    <inertial>
      <mass value="0.1568153717147207"/>
      <origin rpy="0 0 0" xyz="-0.01465  0.00368 -0.03741"/>
      <inertia ixx="0.009431644446213878" ixy="-0.00012519644702725964" ixz="-9.890526254867459e-05" iyy="0.022865485940365013" iyz="-0.011162058463724776" izz="0.01354205131758522"/>
    </inertial>
    <collision name="elbow_left_collision">
      <origin rpy="0 0 0" xyz="-0.01465  0.00368 -0.03741"/>
      <geometry>
        <mesh filename="package://roboy_models/roboy_infineon_game/meshes/CAD/elbow_left.stl" scale="0.001 0.001 0.001"/>
      </geometry>
    </collision>
    <visual name="elbow_left_visual">
      <origin rpy="0 0 0" xyz="-0.01465  0.00368 -0.03741"/>
      <geometry>
        <mesh filename="package://roboy_models/roboy_infineon_game/meshes/CAD/elbow_left.stl" scale="0.001 0.001 0.001"/>
      </geometry>
    </visual>
  </link>
  <link name="elbow_right">
    <inertial>
      <mass value="0.17375098956097507"/>
      <origin rpy="0 0 0" xyz="0.01505  0.00359 -0.03935"/>
      <inertia ixx="0.010199495812814567" ixy="0.00013263312204776155" ixz="-0.00010418886940174745" iyy="0.025041161383884545" iyz="0.012203592993939928" izz="0.014951862960773376"/>
    </inertial>
    <collision name="elbow_right_collision">
      <origin rpy="0 0 0" xyz="0.01505  0.00359 -0.03935"/>
      <geometry>
        <mesh filename="package://roboy_models/roboy_infineon_game/meshes/CAD/elbow_right.stl" scale="0.001 0.001 0.001"/>
      </geometry>
    </collision>
    <visual name="elbow_right_visual">
      <origin rpy="0 0 0" xyz="0.01505  0.00359 -0.03935"/>
      <geometry>
        <mesh filename="package://roboy_models/roboy_infineon_game/meshes/CAD/elbow_right.stl" scale="0.001 0.001 0.001"/>
      </geometry>
    </visual>
  </link>
  <link name="sphere_right_link1">
    <inertial>
      <mass value="0.04675596089362309"/>
      <origin rpy="0 0 0" xyz="0 0 0"/>
      <inertia ixx="0.01408241240995392" ixy="0.0001258297032379935" ixz="-0.000236265028387936" iyy="0.018069961524930532" iyz="0.00749469769415799" izz="0.004001456627830663"/>
    </inertial>
    <collision name="sphere_right_link1_collision">
      <origin rpy="0 0 0" xyz="0 0 0"/>
      <geometry>
        <mesh filename="package://roboy_models/roboy_infineon_game/meshes/CAD/sphere_right_link1.stl" scale="0.001 0.001 0.001"/>
      </geometry>
    </collision>
    <visual name="sphere_right_link1_visual">
      <origin rpy="0 0 0" xyz="0 0 0"/>
      <geometry>
        <mesh filename="package://roboy_models/roboy_infineon_game/meshes/CAD/sphere_right_link1.stl" scale="0.001 0.001 0.001"/>
      </geometry>
    </visual>
  </link>
  <link name="sphere_right_link2">
    <inertial>
      <mass value="0.031339415773582444"/>
      <origin rpy="0 0 0" xyz="0 0 0"/>
      <inertia ixx="0.009437802344317998" ixy="8.43380330440342e-05" ixz="-0.0001583577865898864" iyy="0.012110566274240927" iyz="0.005023522284944857" izz="0.002680779704713365"/>
    </inertial>
    <collision name="sphere_right_link2_collision">
      <origin rpy="0 0 0" xyz="0 0 0"/>
      <geometry>
        <mesh filename="package://roboy_models/roboy_infineon_game/meshes/CAD/sphere_right_link2.stl" scale="0.001 0.001 0.001"/>
      </geometry>
    </collision>
    <visual name="sphere_right_link2_visual">
      <origin rpy="0 0 0" xyz="0 0 0"/>
      <geometry>
        <mesh filename="package://roboy_models/roboy_infineon_game/meshes/CAD/sphere_right_link2.stl" scale="0.001 0.001 0.001"/>
      </geometry>
    </visual>
  </link>
  <link name="sphere_left_link1">
    <inertial>
      <mass value="0.046755519327953354"/>
      <origin rpy="0 0 0" xyz="0 0 0"/>
      <inertia ixx="0.014082280743277947" ixy="-0.00012582855239671661" ixz="-0.00023626280923146897" iyy="0.018069794508113902" iyz="-0.0074946294466258015" izz="0.004001421202848276"/>
    </inertial>
    <collision name="sphere_left_link1_collision">
      <origin rpy="0 0 0" xyz="0 0 0"/>
      <geometry>
        <mesh filename="package://roboy_models/roboy_infineon_game/meshes/CAD/sphere_left_link1.stl" scale="0.001 0.001 0.001"/>
      </geometry>
    </collision>
    <visual name="sphere_left_link1_visual">
      <origin rpy="0 0 0" xyz="0 0 0"/>
      <geometry>
        <mesh filename="package://roboy_models/roboy_infineon_game/meshes/CAD/sphere_left_link1.stl" scale="0.001 0.001 0.001"/>
      </geometry>
    </visual>
  </link>
  <link name="sphere_left_link2">
    <inertial>
      <mass value="0.03134020848172157"/>
      <origin rpy="0 0 0" xyz="0 0 0"/>
      <inertia ixx="0.009438041528757955" ixy="-8.434003849461378e-05" ixz="-0.00015836161156868728" iyy="0.012110871144511353" iyz="-0.0050236476632439745" izz="0.002680845512452334"/>
    </inertial>
    <collision name="sphere_left_link2_collision">
      <origin rpy="0 0 0" xyz="0 0 0"/>
      <geometry>
        <mesh filename="package://roboy_models/roboy_infineon_game/meshes/CAD/sphere_left_link2.stl" scale="0.001 0.001 0.001"/>
      </geometry>
    </collision>
    <visual name="sphere_left_link2_visual">
      <origin rpy="0 0 0" xyz="0 0 0"/>
      <geometry>
        <mesh filename="package://roboy_models/roboy_infineon_game/meshes/CAD/sphere_left_link2.stl" scale="0.001 0.001 0.001"/>
      </geometry>
    </visual>
  </link>
  <link name="palm">
    <inertial>
      <mass value="0.051047603764359704"/>
      <origin rpy="0 0 0" xyz="-0.005    0.01716 -0.05248"/>
      <inertia ixx="0.0005642976234324479" ixy="6.973757646592466e-05" ixz="-2.2140404687012035e-05" iyy="0.0045620445863501415" iyz="0.0014255480384397687" izz="0.004038855487756269"/>
    </inertial>
    <collision name="palm_collision">
      <origin rpy="0 0 0" xyz="-0.005    0.01716 -0.05248"/>
      <geometry>
        <mesh filename="package://roboy_models/roboy_infineon_game/meshes/CAD/palm.stl" scale="0.001 0.001 0.001"/>
      </geometry>
    </collision>
    <visual name="palm_visual">
      <origin rpy="0 0 0" xyz="-0.005    0.01716 -0.05248"/>
      <geometry>
        <mesh filename="package://roboy_models/roboy_infineon_game/meshes/CAD/palm.stl" scale="0.001 0.001 0.001"/>
      </geometry>
    </visual>
  </link>
  <link name="left_ring_limb0">
    <inertial>
      <mass value="0.00042698927905567593"/>
      <origin rpy="0 0 0" xyz="-0.00047  0.0071   0.00247"/>
      <inertia ixx="9.06817921051976e-06" ixy="-1.4556070812605406e-06" ixz="7.552339396282292e-07" iyy="4.2381568843882405e-05" iyz="1.7329692668618087e-05" izz="3.345029005361239e-05"/>
    </inertial>
    <collision name="left_ring_limb0_collision">
      <origin rpy="0 0 0" xyz="-0.00047  0.0071   0.00247"/>
      <geometry>
        <mesh filename="package://roboy_models/roboy_infineon_game/meshes/CAD/left_ring_limb0.stl" scale="0.001 0.001 0.001"/>
      </geometry>
    </collision>
    <visual name="left_ring_limb0_visual">
      <origin rpy="0 0 0" xyz="-0.00047  0.0071   0.00247"/>
      <geometry>
        <mesh filename="package://roboy_models/roboy_infineon_game/meshes/CAD/left_ring_limb0.stl" scale="0.001 0.001 0.001"/>
      </geometry>
    </visual>
  </link>
  <link name="left_ring_limb1">
    <inertial>
      <mass value="0.003829241517863796"/>
      <origin rpy="0 0 0" xyz="-0.00312  0.00586 -0.02465"/>
      <inertia ixx="0.00011176994574178268" ixy="-1.9283372411789186e-05" ixz="1.1889390832434235e-05" iyy="0.00040905730130950095" iyz="0.0001808457030477495" izz="0.0002999547975012437"/>
    </inertial>
    <collision name="left_ring_limb1_collision">
      <origin rpy="0 0 0" xyz="-0.00312  0.00586 -0.02465"/>
      <geometry>
        <mesh filename="package://roboy_models/roboy_infineon_game/meshes/CAD/left_ring_limb1.stl" scale="0.001 0.001 0.001"/>
      </geometry>
    </collision>
    <visual name="left_ring_limb1_visual">
      <origin rpy="0 0 0" xyz="-0.00312  0.00586 -0.02465"/>
      <geometry>
        <mesh filename="package://roboy_models/roboy_infineon_game/meshes/CAD/left_ring_limb1.stl" scale="0.001 0.001 0.001"/>
      </geometry>
    </visual>
  </link>
  <link name="left_ring_limb2">
    <inertial>
      <mass value="0.0016247461735835922"/>
      <origin rpy="0 0 0" xyz="0.00067  0.00838 -0.01097"/>
      <inertia ixx="7.152150998565983e-05" ixy="-1.2381976282458702e-05" ixz="9.288629337823387e-06" iyy="0.00019585674302424993" iyz="9.384126673223814e-05" izz="0.0001268136600453599"/>
    </inertial>
    <collision name="left_ring_limb2_collision">
      <origin rpy="0 0 0" xyz="0.00067  0.00838 -0.01097"/>
      <geometry>
        <mesh filename="package://roboy_models/roboy_infineon_game/meshes/CAD/left_ring_limb2.stl" scale="0.001 0.001 0.001"/>
      </geometry>
    </collision>
    <visual name="left_ring_limb2_visual">
      <origin rpy="0 0 0" xyz="0.00067  0.00838 -0.01097"/>
      <geometry>
        <mesh filename="package://roboy_models/roboy_infineon_game/meshes/CAD/left_ring_limb2.stl" scale="0.001 0.001 0.001"/>
      </geometry>
    </visual>
  </link>
  <link name="left_ring_limb3">
    <inertial>
      <mass value="0.0006943752997715763"/>
      <origin rpy="0 0 0" xyz="0.00022  0.0058  -0.00681"/>
      <inertia ixx="3.888234617440118e-05" ixy="-6.5141595890306356e-06" ixz="5.504069186137751e-06" iyy="9.150325153719992e-05" iyz="4.508974955285808e-05" izz="5.421689295120942e-05"/>
    </inertial>
    <collision name="left_ring_limb3_collision">
      <origin rpy="0 0 0" xyz="0.00022  0.0058  -0.00681"/>
      <geometry>
        <mesh filename="package://roboy_models/roboy_infineon_game/meshes/CAD/left_ring_limb3.stl" scale="0.001 0.001 0.001"/>
      </geometry>
    </collision>
    <visual name="left_ring_limb3_visual">
      <origin rpy="0 0 0" xyz="0.00022  0.0058  -0.00681"/>
      <geometry>
        <mesh filename="package://roboy_models/roboy_infineon_game/meshes/CAD/left_ring_limb3.stl" scale="0.001 0.001 0.001"/>
      </geometry>
    </visual>
  </link>
  <link name="left_little_limb0">
    <inertial>
      <mass value="0.00042697827343766043"/>
      <origin rpy="0 0 0" xyz="-0.00042  0.00623  0.00421"/>
      <inertia ixx="7.646330676015054e-06" ixy="-3.229440615653373e-06" ixz="1.514279653395261e-06" iyy="4.060311614946017e-05" iyz="1.561188282137106e-05" izz="3.359281331926145e-05"/>
    </inertial>
    <collision name="left_little_limb0_collision">
      <origin rpy="0 0 0" xyz="-0.00042  0.00623  0.00421"/>
      <geometry>
        <mesh filename="package://roboy_models/roboy_infineon_game/meshes/CAD/left_little_limb0.stl" scale="0.001 0.001 0.001"/>
      </geometry>
    </collision>
    <visual name="left_little_limb0_visual">
      <origin rpy="0 0 0" xyz="-0.00042  0.00623  0.00421"/>
      <geometry>
        <mesh filename="package://roboy_models/roboy_infineon_game/meshes/CAD/left_little_limb0.stl" scale="0.001 0.001 0.001"/>
      </geometry>
    </visual>
  </link>
  <link name="left_little_limb1">
    <inertial>
      <mass value="0.00382922696560545"/>
      <origin rpy="0 0 0" xyz="-0.00119  0.01222 -0.02238"/>
      <inertia ixx="9.591805033342318e-05" ixy="-4.19251146246524e-05" ixz="2.3154071936643988e-05" iyy="0.0003915328668441594" iyz="0.0001640127271946591" izz="0.00030774724342872513"/>
    </inertial>
    <collision name="left_little_limb1_collision">
      <origin rpy="0 0 0" xyz="-0.00119  0.01222 -0.02238"/>
      <geometry>
        <mesh filename="package://roboy_models/roboy_infineon_game/meshes/CAD/left_little_limb1.stl" scale="0.001 0.001 0.001"/>
      </geometry>
    </collision>
    <visual name="left_little_limb1_visual">
      <origin rpy="0 0 0" xyz="-0.00119  0.01222 -0.02238"/>
      <geometry>
        <mesh filename="package://roboy_models/roboy_infineon_game/meshes/CAD/left_little_limb1.stl" scale="0.001 0.001 0.001"/>
      </geometry>
    </visual>
  </link>
  <link name="left_little_limb2">
    <inertial>
      <mass value="0.001624745378245611"/>
      <origin rpy="0 0 0" xyz="0.00171  0.0109  -0.00832"/>
      <inertia ixx="6.26962034034003e-05" ixy="-2.6682281240723343e-05" ixz="1.7760009025081236e-05" iyy="0.00018677954268692663" iyz="8.59906224613511e-05" izz="0.0001351543531672839"/>
    </inertial>
    <collision name="left_little_limb2_collision">
      <origin rpy="0 0 0" xyz="0.00171  0.0109  -0.00832"/>
      <geometry>
        <mesh filename="package://roboy_models/roboy_infineon_game/meshes/CAD/left_little_limb2.stl" scale="0.001 0.001 0.001"/>
      </geometry>
    </collision>
    <visual name="left_little_limb2_visual">
      <origin rpy="0 0 0" xyz="0.00171  0.0109  -0.00832"/>
      <geometry>
        <mesh filename="package://roboy_models/roboy_infineon_game/meshes/CAD/left_little_limb2.stl" scale="0.001 0.001 0.001"/>
      </geometry>
    </visual>
  </link>
  <link name="left_little_limb3">
    <inertial>
      <mass value="0.000694375681967843"/>
      <origin rpy="0 0 0" xyz="0.00088  0.00735 -0.00502"/>
      <inertia ixx="3.449222678789113e-05" ixy="-1.4034988499413473e-05" ixz="1.0446836648953337e-05" iyy="8.69155199850427e-05" iyz="4.1610921373092544e-05" izz="5.947922868536202e-05"/>
    </inertial>
    <collision name="left_little_limb3_collision">
      <origin rpy="0 0 0" xyz="0.00088  0.00735 -0.00502"/>
      <geometry>
        <mesh filename="package://roboy_models/roboy_infineon_game/meshes/CAD/left_little_limb3.stl" scale="0.001 0.001 0.001"/>
      </geometry>
    </collision>
    <visual name="left_little_limb3_visual">
      <origin rpy="0 0 0" xyz="0.00088  0.00735 -0.00502"/>
      <geometry>
        <mesh filename="package://roboy_models/roboy_infineon_game/meshes/CAD/left_little_limb3.stl" scale="0.001 0.001 0.001"/>
      </geometry>
    </visual>
  </link>
  <link name="left_thumb_limb0">
    <inertial>
      <mass value="0.0004270936562641884"/>
      <origin rpy="0 0 0" xyz="0.00682 -0.00232 -0.00217"/>
      <inertia ixx="4.2954154434823164e-06" ixy="3.5856713228812274e-06" ixz="-1.2892733424284021e-06" iyy="3.3730810405179924e-05" iyz="1.0736282567274773e-05" izz="3.030110157342035e-05"/>
    </inertial>
    <collision name="left_thumb_limb0_collision">
      <origin rpy="0 0 0" xyz="0.00682 -0.00232 -0.00217"/>
      <geometry>
        <mesh filename="package://roboy_models/roboy_infineon_game/meshes/CAD/left_thumb_limb0.stl" scale="0.001 0.001 0.001"/>
      </geometry>
    </collision>
    <visual name="left_thumb_limb0_visual">
      <origin rpy="0 0 0" xyz="0.00682 -0.00232 -0.00217"/>
      <geometry>
        <mesh filename="package://roboy_models/roboy_infineon_game/meshes/CAD/left_thumb_limb0.stl" scale="0.001 0.001 0.001"/>
      </geometry>
    </visual>
  </link>
  <link name="left_thumb_limb1">
    <inertial>
      <mass value="0.0038294622261042174"/>
      <origin rpy="0 0 0" xyz="-0.00768  0.00684 -0.02336"/>
      <inertia ixx="5.701444125449982e-05" ixy="2.7109060915844808e-05" ixz="-1.232065833914162e-05" iyy="0.0003051794258941571" iyz="0.00011530159318711529" izz="0.0002541204850231677"/>
    </inertial>
    <collision name="left_thumb_limb1_collision">
      <origin rpy="0 0 0" xyz="-0.00768  0.00684 -0.02336"/>
      <geometry>
        <mesh filename="package://roboy_models/roboy_infineon_game/meshes/CAD/left_thumb_limb1.stl" scale="0.001 0.001 0.001"/>
      </geometry>
    </collision>
    <visual name="left_thumb_limb1_visual">
      <origin rpy="0 0 0" xyz="-0.00768  0.00684 -0.02336"/>
      <geometry>
        <mesh filename="package://roboy_models/roboy_infineon_game/meshes/CAD/left_thumb_limb1.stl" scale="0.001 0.001 0.001"/>
      </geometry>
    </visual>
  </link>
  <link name="left_thumb_limb2">
    <inertial>
      <mass value="0.0016247934834448725"/>
      <origin rpy="0 0 0" xyz="0.01018 0.00924 0.00143"/>
      <inertia ixx="3.188852123783219e-05" ixy="4.220357558259184e-06" ixz="-2.400387342304833e-06" iyy="0.0001354626794148631" iyz="5.722906827633372e-05" izz="0.00010416792303185145"/>
    </inertial>
    <collision name="left_thumb_limb2_collision">
      <origin rpy="0 0 0" xyz="0.01018 0.00924 0.00143"/>
      <geometry>
        <mesh filename="package://roboy_models/roboy_infineon_game/meshes/CAD/left_thumb_limb2.stl" scale="0.001 0.001 0.001"/>
      </geometry>
    </collision>
    <visual name="left_thumb_limb2_visual">
      <origin rpy="0 0 0" xyz="0.01018 0.00924 0.00143"/>
      <geometry>
        <mesh filename="package://roboy_models/roboy_infineon_game/meshes/CAD/left_thumb_limb2.stl" scale="0.001 0.001 0.001"/>
      </geometry>
    </visual>
  </link>
  <link name="left_thumb_limb3">
    <inertial>
      <mass value="0.0006943751960180326"/>
      <origin rpy="0 0 0" xyz="0.0064  -0.00206  0.0059"/>
      <inertia ixx="1.0799336517044251e-05" ixy="-7.554325018620578e-07" ixz="3.583927852315045e-07" iyy="5.9322218131798904e-05" iyz="2.2844468975509682e-05" izz="4.855150125463113e-05"/>
    </inertial>
    <collision name="left_thumb_limb3_collision">
      <origin rpy="0 0 0" xyz="0.0064  -0.00206  0.0059"/>
      <geometry>
        <mesh filename="package://roboy_models/roboy_infineon_game/meshes/CAD/left_thumb_limb3.stl" scale="0.001 0.001 0.001"/>
      </geometry>
    </collision>
    <visual name="left_thumb_limb3_visual">
      <origin rpy="0 0 0" xyz="0.0064  -0.00206  0.0059"/>
      <geometry>
        <mesh filename="package://roboy_models/roboy_infineon_game/meshes/CAD/left_thumb_limb3.stl" scale="0.001 0.001 0.001"/>
      </geometry>
    </visual>
  </link>
  <link name="left_index_limb0">
    <inertial>
      <mass value="0.00042704072295925323"/>
      <origin rpy="0 0 0" xyz="-0.00064  0.00737 -0.00141"/>
      <inertia ixx="9.199217389559458e-06" ixy="3.1904597853014466e-06" ixz="-1.6317709860340043e-06" iyy="4.2856673715446425e-05" iyz="1.737713351264253e-05" izz="3.426661588961933e-05"/>
    </inertial>
    <collision name="left_index_limb0_collision">
      <origin rpy="0 0 0" xyz="-0.00064  0.00737 -0.00141"/>
      <geometry>
        <mesh filename="package://roboy_models/roboy_infineon_game/meshes/CAD/left_index_limb0.stl" scale="0.001 0.001 0.001"/>
      </geometry>
    </collision>
    <visual name="left_index_limb0_visual">
      <origin rpy="0 0 0" xyz="-0.00064  0.00737 -0.00141"/>
      <geometry>
        <mesh filename="package://roboy_models/roboy_infineon_game/meshes/CAD/left_index_limb0.stl" scale="0.001 0.001 0.001"/>
      </geometry>
    </visual>
  </link>
  <link name="left_index_limb1">
    <inertial>
      <mass value="0.0038291847047877674"/>
      <origin rpy="0 0 0" xyz="-0.0023  -0.00729 -0.02436"/>
      <inertia ixx="0.00011331668399670983" ixy="3.6116693545215206e-05" ixz="-2.172178421726994e-05" iyy="0.0004144267564259643" iyz="0.00018170411666070416" izz="0.00030986425785158023"/>
    </inertial>
    <collision name="left_index_limb1_collision">
      <origin rpy="0 0 0" xyz="-0.0023  -0.00729 -0.02436"/>
      <geometry>
        <mesh filename="package://roboy_models/roboy_infineon_game/meshes/CAD/left_index_limb1.stl" scale="0.001 0.001 0.001"/>
      </geometry>
    </collision>
    <visual name="left_index_limb1_visual">
      <origin rpy="0 0 0" xyz="-0.0023  -0.00729 -0.02436"/>
      <geometry>
        <mesh filename="package://roboy_models/roboy_infineon_game/meshes/CAD/left_index_limb1.stl" scale="0.001 0.001 0.001"/>
      </geometry>
    </visual>
  </link>
  <link name="left_index_limb2">
    <inertial>
      <mass value="0.0016247456622690932"/>
      <origin rpy="0 0 0" xyz="0.00097  0.00181 -0.01367"/>
      <inertia ixx="7.244898466919644e-05" ixy="2.044648361124246e-05" ixz="-1.4961835108664842e-05" iyy="0.00019884834999383725" iyz="9.462078216177411e-05" izz="0.0001328902998482613"/>
    </inertial>
    <collision name="left_index_limb2_collision">
      <origin rpy="0 0 0" xyz="0.00097  0.00181 -0.01367"/>
      <geometry>
        <mesh filename="package://roboy_models/roboy_infineon_game/meshes/CAD/left_index_limb2.stl" scale="0.001 0.001 0.001"/>
      </geometry>
    </collision>
    <visual name="left_index_limb2_visual">
      <origin rpy="0 0 0" xyz="0.00097  0.00181 -0.01367"/>
      <geometry>
        <mesh filename="package://roboy_models/roboy_infineon_game/meshes/CAD/left_index_limb2.stl" scale="0.001 0.001 0.001"/>
      </geometry>
    </visual>
  </link>
  <link name="left_index_limb3">
    <inertial>
      <mass value="0.0006943760025212351"/>
      <origin rpy="0 0 0" xyz="0.0004   0.00163 -0.00879"/>
      <inertia ixx="3.935759681532587e-05" ixy="1.0237034950993482e-05" ixz="-8.414635593280202e-06" iyy="9.296092902776221e-05" iyz="4.558360122304754e-05" izz="5.738801562279048e-05"/>
    </inertial>
    <collision name="left_index_limb3_collision">
      <origin rpy="0 0 0" xyz="0.0004   0.00163 -0.00879"/>
      <geometry>
        <mesh filename="package://roboy_models/roboy_infineon_game/meshes/CAD/left_index_limb3.stl" scale="0.001 0.001 0.001"/>
      </geometry>
    </collision>
    <visual name="left_index_limb3_visual">
      <origin rpy="0 0 0" xyz="0.0004   0.00163 -0.00879"/>
      <geometry>
        <mesh filename="package://roboy_models/roboy_infineon_game/meshes/CAD/left_index_limb3.stl" scale="0.001 0.001 0.001"/>
      </geometry>
    </visual>
  </link>
  <link name="left_middle_limb0">
    <inertial>
      <mass value="0.0004269917809018472"/>
      <origin rpy="0 0 0" xyz="0.00019 -0.00497  0.00082"/>
      <inertia ixx="9.628320322458132e-06" ixy="8.121391793774464e-07" ixz="-4.3386151683294725e-07" iyy="4.322094123558565e-05" iyz="1.7964981111057085e-05" izz="3.3642006588304284e-05"/>
    </inertial>
    <collision name="left_middle_limb0_collision">
      <origin rpy="0 0 0" xyz="0.00019 -0.00497  0.00082"/>
      <geometry>
        <mesh filename="package://roboy_models/roboy_infineon_game/meshes/CAD/left_middle_limb0.stl" scale="0.001 0.001 0.001"/>
      </geometry>
    </collision>
    <visual name="left_middle_limb0_visual">
      <origin rpy="0 0 0" xyz="0.00019 -0.00497  0.00082"/>
      <geometry>
        <mesh filename="package://roboy_models/roboy_infineon_game/meshes/CAD/left_middle_limb0.stl" scale="0.001 0.001 0.001"/>
      </geometry>
    </visual>
  </link>
  <link name="left_middle_limb1">
    <inertial>
      <mass value="0.0038292272976380203"/>
      <origin rpy="0 0 0" xyz="-0.00274 -0.00073 -0.02537"/>
      <inertia ixx="0.00011795815464596243" ixy="7.871452020142755e-06" ixz="-4.918826780153353e-06" iyy="0.0004192273567608528" iyz="0.00018763217452860546" izz="0.00030175595034477766"/>
    </inertial>
    <collision name="left_middle_limb1_collision">
      <origin rpy="0 0 0" xyz="-0.00274 -0.00073 -0.02537"/>
      <geometry>
        <mesh filename="package://roboy_models/roboy_infineon_game/meshes/CAD/left_middle_limb1.stl" scale="0.001 0.001 0.001"/>
      </geometry>
    </collision>
    <visual name="left_middle_limb1_visual">
      <origin rpy="0 0 0" xyz="-0.00274 -0.00073 -0.02537"/>
      <geometry>
        <mesh filename="package://roboy_models/roboy_infineon_game/meshes/CAD/left_middle_limb1.stl" scale="0.001 0.001 0.001"/>
      </geometry>
    </visual>
  </link>
  <link name="left_middle_limb2">
    <inertial>
      <mass value="0.0016247457191924265"/>
      <origin rpy="0 0 0" xyz="0.0008   0.00527 -0.01275"/>
      <inertia ixx="7.494878668026111e-05" ixy="3.7522701164539915e-06" ixz="-2.8763021033515174e-06" iyy="0.00020216047274025515" iyz="9.750724551735193e-05" izz="0.00012745200906002257"/>
    </inertial>
    <collision name="left_middle_limb2_collision">
      <origin rpy="0 0 0" xyz="0.0008   0.00527 -0.01275"/>
      <geometry>
        <mesh filename="package://roboy_models/roboy_infineon_game/meshes/CAD/left_middle_limb2.stl" scale="0.001 0.001 0.001"/>
      </geometry>
    </collision>
    <visual name="left_middle_limb2_visual">
      <origin rpy="0 0 0" xyz="0.0008   0.00527 -0.01275"/>
      <geometry>
        <mesh filename="package://roboy_models/roboy_infineon_game/meshes/CAD/left_middle_limb2.stl" scale="0.001 0.001 0.001"/>
      </geometry>
    </visual>
  </link>
  <link name="left_middle_limb3">
    <inertial>
      <mass value="0.0006943750023357814"/>
      <origin rpy="0 0 0" xyz="0.00029  0.00384 -0.00807"/>
      <inertia ixx="4.0581182569994296e-05" ixy="1.722188766212528e-06" ixz="-1.487393936346671e-06" iyy="9.484863245837088e-05" iyz="4.6904740955860724e-05" izz="5.438112051354127e-05"/>
    </inertial>
    <collision name="left_middle_limb3_collision">
      <origin rpy="0 0 0" xyz="0.00029  0.00384 -0.00807"/>
      <geometry>
        <mesh filename="package://roboy_models/roboy_infineon_game/meshes/CAD/left_middle_limb3.stl" scale="0.001 0.001 0.001"/>
      </geometry>
    </collision>
    <visual name="left_middle_limb3_visual">
      <origin rpy="0 0 0" xyz="0.00029  0.00384 -0.00807"/>
      <geometry>
        <mesh filename="package://roboy_models/roboy_infineon_game/meshes/CAD/left_middle_limb3.stl" scale="0.001 0.001 0.001"/>
      </geometry>
    </visual>
  </link>
  <link name="wrist_left_1">
    <inertial>
      <mass value="0.012764273069100234"/>
      <origin rpy="0 0 0" xyz="0.0099  0.00063 0.00106"/>
      <inertia ixx="2.9934913504206502e-05" ixy="1.6311025100062298e-05" ixz="-2.6058950431388023e-06" iyy="0.0010588612289813193" iyz="0.0001668482339759435" izz="0.0010339768891506353"/>
    </inertial>
    <collision name="wrist_left_1_collision">
      <origin rpy="0 0 0" xyz="0.0099  0.00063 0.00106"/>
      <geometry>
        <mesh filename="package://roboy_models/roboy_infineon_game/meshes/CAD/wrist_left_1.stl" scale="0.001 0.001 0.001"/>
      </geometry>
    </collision>
    <visual name="wrist_left_1_visual">
      <origin rpy="0 0 0" xyz="0.0099  0.00063 0.00106"/>
      <geometry>
        <mesh filename="package://roboy_models/roboy_infineon_game/meshes/CAD/wrist_left_1.stl" scale="0.001 0.001 0.001"/>
      </geometry>
    </visual>
  </link>
  <link name="right_ring_limb0">
    <inertial>
      <mass value="0.00042704466709723077"/>
      <origin rpy="0 0 0" xyz="-0.00011 -0.007    0.00277"/>
      <inertia ixx="9.587454972047968e-06" ixy="-3.290558462622337e-06" ixz="-1.6826607960000105e-06" iyy="4.471529987170614e-05" iyz="-1.812854670762791e-05" izz="3.5748703714543334e-05"/>
    </inertial>
    <collision name="right_ring_limb0_collision">
      <origin rpy="0 0 0" xyz="-0.00011 -0.007    0.00277"/>
      <geometry>
        <mesh filename="package://roboy_models/roboy_infineon_game/meshes/CAD/right_ring_limb0.stl" scale="0.001 0.001 0.001"/>
      </geometry>
    </collision>
    <visual name="right_ring_limb0_visual">
      <origin rpy="0 0 0" xyz="-0.00011 -0.007    0.00277"/>
      <geometry>
        <mesh filename="package://roboy_models/roboy_infineon_game/meshes/CAD/right_ring_limb0.stl" scale="0.001 0.001 0.001"/>
      </geometry>
    </visual>
  </link>
  <link name="right_ring_limb1">
    <inertial>
      <mass value="0.0038294637337122697"/>
      <origin rpy="0 0 0" xyz="0.00124 -0.00719 -0.02446"/>
      <inertia ixx="0.00011732204121978117" ixy="-3.728399043645363e-05" ixz="-2.2255940650543876e-05" iyy="0.00043394572469656283" iyz="-0.00018968683916815353" izz="0.00032549134472503955"/>
    </inertial>
    <collision name="right_ring_limb1_collision">
      <origin rpy="0 0 0" xyz="0.00124 -0.00719 -0.02446"/>
      <geometry>
        <mesh filename="package://roboy_models/roboy_infineon_game/meshes/CAD/right_ring_limb1.stl" scale="0.001 0.001 0.001"/>
      </geometry>
    </collision>
    <visual name="right_ring_limb1_visual">
      <origin rpy="0 0 0" xyz="0.00124 -0.00719 -0.02446"/>
      <geometry>
        <mesh filename="package://roboy_models/roboy_infineon_game/meshes/CAD/right_ring_limb1.stl" scale="0.001 0.001 0.001"/>
      </geometry>
    </visual>
  </link>
  <link name="right_ring_limb2">
    <inertial>
      <mass value="0.0016247905112063861"/>
      <origin rpy="0 0 0" xyz="-0.00208 -0.00873 -0.01051"/>
      <inertia ixx="7.450996319439101e-05" ixy="-2.1155918715524178e-05" ixz="-1.5232910124406943e-05" iyy="0.00020905983593805355" iyz="-9.899368448248243e-05" izz="0.00014108556203364106"/>
    </inertial>
    <collision name="right_ring_limb2_collision">
      <origin rpy="0 0 0" xyz="-0.00208 -0.00873 -0.01051"/>
      <geometry>
        <mesh filename="package://roboy_models/roboy_infineon_game/meshes/CAD/right_ring_limb2.stl" scale="0.001 0.001 0.001"/>
      </geometry>
    </collision>
    <visual name="right_ring_limb2_visual">
      <origin rpy="0 0 0" xyz="-0.00208 -0.00873 -0.01051"/>
      <geometry>
        <mesh filename="package://roboy_models/roboy_infineon_game/meshes/CAD/right_ring_limb2.stl" scale="0.001 0.001 0.001"/>
      </geometry>
    </visual>
  </link>
  <link name="right_ring_limb3">
    <inertial>
      <mass value="0.0006943693287827213"/>
      <origin rpy="0 0 0" xyz="-0.00115 -0.00603 -0.00651"/>
      <inertia ixx="4.0337945313612636e-05" ixy="-1.0618402229477374e-05" ixz="-8.541310237938289e-06" iyy="9.788769858731229e-05" iyz="-4.778942818421739e-05" izz="6.135060367845747e-05"/>
    </inertial>
    <collision name="right_ring_limb3_collision">
      <origin rpy="0 0 0" xyz="-0.00115 -0.00603 -0.00651"/>
      <geometry>
        <mesh filename="package://roboy_models/roboy_infineon_game/meshes/CAD/right_ring_limb3.stl" scale="0.001 0.001 0.001"/>
      </geometry>
    </collision>
    <visual name="right_ring_limb3_visual">
      <origin rpy="0 0 0" xyz="-0.00115 -0.00603 -0.00651"/>
      <geometry>
        <mesh filename="package://roboy_models/roboy_infineon_game/meshes/CAD/right_ring_limb3.stl" scale="0.001 0.001 0.001"/>
      </geometry>
    </visual>
  </link>
  <link name="right_little_limb0">
    <inertial>
      <mass value="0.0004269761331021115"/>
      <origin rpy="0 0 0" xyz="-0.00018 -0.00691 -0.00298"/>
      <inertia ixx="8.005226502427981e-06" ixy="3.2234397919500516e-06" ixz="1.5138317838690567e-06" iyy="4.256929142722267e-05" iyz="-1.638417456653172e-05" izz="3.5169267424042466e-05"/>
    </inertial>
    <collision name="right_little_limb0_collision">
      <origin rpy="0 0 0" xyz="-0.00018 -0.00691 -0.00298"/>
      <geometry>
        <mesh filename="package://roboy_models/roboy_infineon_game/meshes/CAD/right_little_limb0.stl" scale="0.001 0.001 0.001"/>
      </geometry>
    </collision>
    <visual name="right_little_limb0_visual">
      <origin rpy="0 0 0" xyz="-0.00018 -0.00691 -0.00298"/>
      <geometry>
        <mesh filename="package://roboy_models/roboy_infineon_game/meshes/CAD/right_little_limb0.stl" scale="0.001 0.001 0.001"/>
      </geometry>
    </visual>
  </link>
  <link name="right_little_limb1">
    <inertial>
      <mass value="0.0038294645545937137"/>
      <origin rpy="0 0 0" xyz="0.00205  0.01216 -0.02235"/>
      <inertia ixx="9.968039587364946e-05" ixy="4.203376867826319e-05" ixz="2.3252540454633822e-05" iyy="0.00040804707645783033" iyz="-0.00017104019585269278" izz="0.00032009989656558"/>
    </inertial>
    <collision name="right_little_limb1_collision">
      <origin rpy="0 0 0" xyz="0.00205  0.01216 -0.02235"/>
      <geometry>
        <mesh filename="package://roboy_models/roboy_infineon_game/meshes/CAD/right_little_limb1.stl" scale="0.001 0.001 0.001"/>
      </geometry>
    </collision>
    <visual name="right_little_limb1_visual">
      <origin rpy="0 0 0" xyz="0.00205  0.01216 -0.02235"/>
      <geometry>
        <mesh filename="package://roboy_models/roboy_infineon_game/meshes/CAD/right_little_limb1.stl" scale="0.001 0.001 0.001"/>
      </geometry>
    </visual>
  </link>
  <link name="right_little_limb2">
    <inertial>
      <mass value="0.0016247909938853248"/>
      <origin rpy="0 0 0" xyz="-0.00171  0.00129 -0.01366"/>
      <inertia ixx="6.465661566226048e-05" ixy="2.677797276693304e-05" ixz="1.7867793855862892e-05" iyy="0.00019297782648839836" iyz="-8.892339062529009e-05" izz="0.00013913357757391624"/>
    </inertial>
    <collision name="right_little_limb2_collision">
      <origin rpy="0 0 0" xyz="-0.00171  0.00129 -0.01366"/>
      <geometry>
        <mesh filename="package://roboy_models/roboy_infineon_game/meshes/CAD/right_little_limb2.stl" scale="0.001 0.001 0.001"/>
      </geometry>
    </collision>
    <visual name="right_little_limb2_visual">
      <origin rpy="0 0 0" xyz="-0.00171  0.00129 -0.01366"/>
      <geometry>
        <mesh filename="package://roboy_models/roboy_infineon_game/meshes/CAD/right_little_limb2.stl" scale="0.001 0.001 0.001"/>
      </geometry>
    </visual>
  </link>
  <link name="right_little_limb3">
    <inertial>
      <mass value="0.0006943610312385798"/>
      <origin rpy="0 0 0" xyz="-0.00093  0.00035 -0.00889"/>
      <inertia ixx="3.5439337157308614e-05" ixy="1.4069849269219954e-05" ixz="1.0512993600822055e-05" iyy="8.932925169119139e-05" iyz="-4.281256915080496e-05" izz="6.080882531457406e-05"/>
    </inertial>
    <collision name="right_little_limb3_collision">
      <origin rpy="0 0 0" xyz="-0.00093  0.00035 -0.00889"/>
      <geometry>
        <mesh filename="package://roboy_models/roboy_infineon_game/meshes/CAD/right_little_limb3.stl" scale="0.001 0.001 0.001"/>
      </geometry>
    </collision>
    <visual name="right_little_limb3_visual">
      <origin rpy="0 0 0" xyz="-0.00093  0.00035 -0.00889"/>
      <geometry>
        <mesh filename="package://roboy_models/roboy_infineon_game/meshes/CAD/right_little_limb3.stl" scale="0.001 0.001 0.001"/>
      </geometry>
    </visual>
  </link>
  <link name="right_thumb_limb0">
    <inertial>
      <mass value="0.0004269869930711359"/>
      <origin rpy="0 0 0" xyz="-0.00691 -0.00235 -0.00185"/>
      <inertia ixx="4.62522378009493e-06" ixy="-3.6166496356268653e-06" ixz="-1.3376776670367353e-06" iyy="3.486759567301274e-05" iyz="-1.1340383258843193e-05" izz="3.1100305331303816e-05"/>
    </inertial>
    <collision name="right_thumb_limb0_collision">
      <origin rpy="0 0 0" xyz="-0.00691 -0.00235 -0.00185"/>
      <geometry>
        <mesh filename="package://roboy_models/roboy_infineon_game/meshes/CAD/right_thumb_limb0.stl" scale="0.001 0.001 0.001"/>
      </geometry>
    </collision>
    <visual name="right_thumb_limb0_visual">
      <origin rpy="0 0 0" xyz="-0.00691 -0.00235 -0.00185"/>
      <geometry>
        <mesh filename="package://roboy_models/roboy_infineon_game/meshes/CAD/right_thumb_limb0.stl" scale="0.001 0.001 0.001"/>
      </geometry>
    </visual>
  </link>
  <link name="right_thumb_limb1">
    <inertial>
      <mass value="0.003829458173656318"/>
      <origin rpy="0 0 0" xyz="0.00178  0.00124 -0.02543"/>
      <inertia ixx="6.363545058017145e-05" ixy="-3.3528952589441784e-05" ixz="-1.5658238645710643e-05" iyy="0.00032962603423865566" iyz="-0.00012563820142866668" izz="0.00027439344699374275"/>
    </inertial>
    <collision name="right_thumb_limb1_collision">
      <origin rpy="0 0 0" xyz="0.00178  0.00124 -0.02543"/>
      <geometry>
        <mesh filename="package://roboy_models/roboy_infineon_game/meshes/CAD/right_thumb_limb1.stl" scale="0.001 0.001 0.001"/>
      </geometry>
    </collision>
    <visual name="right_thumb_limb1_visual">
      <origin rpy="0 0 0" xyz="0.00178  0.00124 -0.02543"/>
      <geometry>
        <mesh filename="package://roboy_models/roboy_infineon_game/meshes/CAD/right_thumb_limb1.stl" scale="0.001 0.001 0.001"/>
      </geometry>
    </visual>
  </link>
  <link name="right_thumb_limb2">
    <inertial>
      <mass value="0.0016247977614161058"/>
      <origin rpy="0 0 0" xyz="0.003   0.0132  0.00277"/>
      <inertia ixx="3.661038435334497e-05" ixy="-8.83590957250207e-06" ixz="-4.979698869532481e-06" iyy="0.0001506619501847771" iyz="-6.408276971986917e-05" izz="0.00011572373933049977"/>
    </inertial>
    <collision name="right_thumb_limb2_collision">
      <origin rpy="0 0 0" xyz="0.003   0.0132  0.00277"/>
      <geometry>
        <mesh filename="package://roboy_models/roboy_infineon_game/meshes/CAD/right_thumb_limb2.stl" scale="0.001 0.001 0.001"/>
      </geometry>
    </collision>
    <visual name="right_thumb_limb2_visual">
      <origin rpy="0 0 0" xyz="0.003   0.0132  0.00277"/>
      <geometry>
        <mesh filename="package://roboy_models/roboy_infineon_game/meshes/CAD/right_thumb_limb2.stl" scale="0.001 0.001 0.001"/>
      </geometry>
    </visual>
  </link>
  <link name="right_thumb_limb3">
    <inertial>
      <mass value="0.0006943700234389779"/>
      <origin rpy="0 0 0" xyz="0.00301 0.00237 0.00808"/>
      <inertia ixx="1.2609736256468777e-05" ixy="-1.895305225498406e-07" ixz="-9.9891035782412e-08" iyy="6.341198063428603e-05" iyz="-2.527752011664486e-05" izz="5.0810600371268904e-05"/>
    </inertial>
    <collision name="right_thumb_limb3_collision">
      <origin rpy="0 0 0" xyz="0.00301 0.00237 0.00808"/>
      <geometry>
        <mesh filename="package://roboy_models/roboy_infineon_game/meshes/CAD/right_thumb_limb3.stl" scale="0.001 0.001 0.001"/>
      </geometry>
    </collision>
    <visual name="right_thumb_limb3_visual">
      <origin rpy="0 0 0" xyz="0.00301 0.00237 0.00808"/>
      <geometry>
        <mesh filename="package://roboy_models/roboy_infineon_game/meshes/CAD/right_thumb_limb3.stl" scale="0.001 0.001 0.001"/>
      </geometry>
    </visual>
  </link>
  <link name="right_index_limb0">
    <inertial>
      <mass value="0.00042698738441955704"/>
      <origin rpy="0 0 0" xyz="-0.00017 -0.00745 -0.00109"/>
      <inertia ixx="9.45176932027795e-06" ixy="1.465525325567367e-06" ixz="7.577540410377742e-07" iyy="4.443833759650408e-05" iyz="-1.8134938225725124e-05" izz="3.511906337482363e-05"/>
    </inertial>
    <collision name="right_index_limb0_collision">
      <origin rpy="0 0 0" xyz="-0.00017 -0.00745 -0.00109"/>
      <geometry>
        <mesh filename="package://roboy_models/roboy_infineon_game/meshes/CAD/right_index_limb0.stl" scale="0.001 0.001 0.001"/>
      </geometry>
    </collision>
    <visual name="right_index_limb0_visual">
      <origin rpy="0 0 0" xyz="-0.00017 -0.00745 -0.00109"/>
      <geometry>
        <mesh filename="package://roboy_models/roboy_infineon_game/meshes/CAD/right_index_limb0.stl" scale="0.001 0.001 0.001"/>
      </geometry>
    </visual>
  </link>
  <link name="right_index_limb1">
    <inertial>
      <mass value="0.0038295036091319148"/>
      <origin rpy="0 0 0" xyz="0.00177  0.00597 -0.02476"/>
      <inertia ixx="0.00011574170551435824" ixy="1.9682293378000257e-05" ixz="1.1993241636132798e-05" iyy="0.00043092947859403195" iyz="-0.00018959314308408272" izz="0.0003178115338879012"/>
    </inertial>
    <collision name="right_index_limb1_collision">
      <origin rpy="0 0 0" xyz="0.00177  0.00597 -0.02476"/>
      <geometry>
        <mesh filename="package://roboy_models/roboy_infineon_game/meshes/CAD/right_index_limb1.stl" scale="0.001 0.001 0.001"/>
      </geometry>
    </collision>
    <visual name="right_index_limb1_visual">
      <origin rpy="0 0 0" xyz="0.00177  0.00597 -0.02476"/>
      <geometry>
        <mesh filename="package://roboy_models/roboy_infineon_game/meshes/CAD/right_index_limb1.stl" scale="0.001 0.001 0.001"/>
      </geometry>
    </visual>
  </link>
  <link name="right_index_limb2">
    <inertial>
      <mass value="0.0016247908299257088"/>
      <origin rpy="0 0 0" xyz="-0.00186 -0.00228 -0.01351"/>
      <inertia ixx="7.35827430231125e-05" ixy="1.2810515009102333e-05" ixz="9.399005941712123e-06" iyy="0.00020744834482133232" iyz="-9.876778932106627e-05" izz="0.00013633112644627268"/>
    </inertial>
    <collision name="right_index_limb2_collision">
      <origin rpy="0 0 0" xyz="-0.00186 -0.00228 -0.01351"/>
      <geometry>
        <mesh filename="package://roboy_models/roboy_infineon_game/meshes/CAD/right_index_limb2.stl" scale="0.001 0.001 0.001"/>
      </geometry>
    </collision>
    <visual name="right_index_limb2_visual">
      <origin rpy="0 0 0" xyz="-0.00186 -0.00228 -0.01351"/>
      <geometry>
        <mesh filename="package://roboy_models/roboy_infineon_game/meshes/CAD/right_index_limb2.stl" scale="0.001 0.001 0.001"/>
      </geometry>
    </visual>
  </link>
  <link name="right_index_limb3">
    <inertial>
      <mass value="0.0006943611681336561"/>
      <origin rpy="0 0 0" xyz="-0.00102 -0.00195 -0.00867"/>
      <inertia ixx="3.986907827098813e-05" ixy="6.788112545400644e-06" ixz="5.572310653857104e-06" iyy="9.712784154365344e-05" iyz="-4.7613312155997766e-05" izz="5.8853260572159194e-05"/>
    </inertial>
    <collision name="right_index_limb3_collision">
      <origin rpy="0 0 0" xyz="-0.00102 -0.00195 -0.00867"/>
      <geometry>
        <mesh filename="package://roboy_models/roboy_infineon_game/meshes/CAD/right_index_limb3.stl" scale="0.001 0.001 0.001"/>
      </geometry>
    </collision>
    <visual name="right_index_limb3_visual">
      <origin rpy="0 0 0" xyz="-0.00102 -0.00195 -0.00867"/>
      <geometry>
        <mesh filename="package://roboy_models/roboy_infineon_game/meshes/CAD/right_index_limb3.stl" scale="0.001 0.001 0.001"/>
      </geometry>
    </visual>
  </link>
  <link name="right_middle_limb0">
    <inertial>
      <mass value="0.0004269918296598001"/>
      <origin rpy="0 0 0" xyz="-0.00015 -0.00748  0.00087"/>
      <inertia ixx="1.0029446726150395e-05" ixy="-9.201328705192526e-07" ixz="-4.898390927169781e-07" iyy="4.5260861939898244e-05" iyz="-1.8775163119391247e-05" izz="3.5289601730655314e-05"/>
    </inertial>
    <collision name="right_middle_limb0_collision">
      <origin rpy="0 0 0" xyz="-0.00015 -0.00748  0.00087"/>
      <geometry>
        <mesh filename="package://roboy_models/roboy_infineon_game/meshes/CAD/right_middle_limb0.stl" scale="0.001 0.001 0.001"/>
      </geometry>
    </collision>
    <visual name="right_middle_limb0_visual">
      <origin rpy="0 0 0" xyz="-0.00015 -0.00748  0.00087"/>
      <geometry>
        <mesh filename="package://roboy_models/roboy_infineon_game/meshes/CAD/right_middle_limb0.stl" scale="0.001 0.001 0.001"/>
      </geometry>
    </visual>
  </link>
  <link name="right_middle_limb1">
    <inertial>
      <mass value="0.0038294512883095943"/>
      <origin rpy="0 0 0" xyz="0.00149 -0.00063 -0.02548"/>
      <inertia ixx="0.0001220995002252948" ixy="-8.84602084566386e-06" ixz="-5.463878879035804e-06" iyy="0.0004407681185915827" iyz="-0.0001963880630114403" izz="0.0003192348454917731"/>
    </inertial>
    <collision name="right_middle_limb1_collision">
      <origin rpy="0 0 0" xyz="0.00149 -0.00063 -0.02548"/>
      <geometry>
        <mesh filename="package://roboy_models/roboy_infineon_game/meshes/CAD/right_middle_limb1.stl" scale="0.001 0.001 0.001"/>
      </geometry>
    </collision>
    <visual name="right_middle_limb1_visual">
      <origin rpy="0 0 0" xyz="0.00149 -0.00063 -0.02548"/>
      <geometry>
        <mesh filename="package://roboy_models/roboy_infineon_game/meshes/CAD/right_middle_limb1.stl" scale="0.001 0.001 0.001"/>
      </geometry>
    </visual>
  </link>
  <link name="right_middle_limb2">
    <inertial>
      <mass value="0.00162475332634857"/>
      <origin rpy="0 0 0" xyz="-0.00198 -0.0057  -0.01243"/>
      <inertia ixx="7.708536294896418e-05" ixy="-4.165721795611402e-06" ixz="-3.126632561339439e-06" iyy="0.0002134940935107954" iyz="-0.00010240478305222905" izz="0.0001366820596855284"/>
    </inertial>
    <collision name="right_middle_limb2_collision">
      <origin rpy="0 0 0" xyz="-0.00198 -0.0057  -0.01243"/>
      <geometry>
        <mesh filename="package://roboy_models/roboy_infineon_game/meshes/CAD/right_middle_limb2.stl" scale="0.001 0.001 0.001"/>
      </geometry>
    </collision>
    <visual name="right_middle_limb2_visual">
      <origin rpy="0 0 0" xyz="-0.00198 -0.0057  -0.01243"/>
      <geometry>
        <mesh filename="package://roboy_models/roboy_infineon_game/meshes/CAD/right_middle_limb2.stl" scale="0.001 0.001 0.001"/>
      </geometry>
    </visual>
  </link>
  <link name="right_middle_limb3">
    <inertial>
      <mass value="0.000694374972226315"/>
      <origin rpy="0 0 0" xyz="-0.00109 -0.00413 -0.00786"/>
      <inertia ixx="4.160128555471066e-05" ixy="-1.9011642771947149e-06" ixz="-1.5978520866732432e-06" iyy="0.00010033470064135955" iyz="-4.9405443710589625e-05" izz="5.886083487126691e-05"/>
    </inertial>
    <collision name="right_middle_limb3_collision">
      <origin rpy="0 0 0" xyz="-0.00109 -0.00413 -0.00786"/>
      <geometry>
        <mesh filename="package://roboy_models/roboy_infineon_game/meshes/CAD/right_middle_limb3.stl" scale="0.001 0.001 0.001"/>
      </geometry>
    </collision>
    <visual name="right_middle_limb3_visual">
      <origin rpy="0 0 0" xyz="-0.00109 -0.00413 -0.00786"/>
      <geometry>
        <mesh filename="package://roboy_models/roboy_infineon_game/meshes/CAD/right_middle_limb3.stl" scale="0.001 0.001 0.001"/>
      </geometry>
    </visual>
  </link>
  <link name="right_palm">
    <inertial>
      <mass value="0.051043858395731695"/>
      <origin rpy="0 0 0" xyz="0.0006  -0.01811 -0.05182"/>
      <inertia ixx="0.0005967987886009216" ixy="-7.481603074127008e-05" ixz="-2.4476678546845737e-05" iyy="0.004717995512074524" iyz="-0.0014947026086855695" izz="0.00416268235589044"/>
    </inertial>
    <collision name="right_palm_collision">
      <origin rpy="0 0 0" xyz="0.0006  -0.01811 -0.05182"/>
      <geometry>
        <mesh filename="package://roboy_models/roboy_infineon_game/meshes/CAD/right_palm.stl" scale="0.001 0.001 0.001"/>
      </geometry>
    </collision>
    <visual name="right_palm_visual">
      <origin rpy="0 0 0" xyz="0.0006  -0.01811 -0.05182"/>
      <geometry>
        <mesh filename="package://roboy_models/roboy_infineon_game/meshes/CAD/right_palm.stl" scale="0.001 0.001 0.001"/>
      </geometry>
    </visual>
  </link>
  <link name="wrist_right_1">
    <inertial>
      <mass value="0.012762562533547066"/>
      <origin rpy="0 0 0" xyz="-0.01109  0.00048  0.00157"/>
      <inertia ixx="3.3598610122705056e-05" ixy="-1.6203943852234875e-05" ixz="-2.737975008929542e-06" iyy="0.0010832094855845558" iyz="-0.0001794781509676559" izz="0.0010546398114598741"/>
    </inertial>
    <collision name="wrist_right_1_collision">
      <origin rpy="0 0 0" xyz="-0.01109  0.00048  0.00157"/>
      <geometry>
        <mesh filename="package://roboy_models/roboy_infineon_game/meshes/CAD/wrist_right_1.stl" scale="0.001 0.001 0.001"/>
      </geometry>
    </collision>
    <visual name="wrist_right_1_visual">
      <origin rpy="0 0 0" xyz="-0.01109  0.00048  0.00157"/>
      <geometry>
        <mesh filename="package://roboy_models/roboy_infineon_game/meshes/CAD/wrist_right_1.stl" scale="0.001 0.001 0.001"/>
      </geometry>
    </visual>
  </link>
  <link name="upper_arm_left">
    <inertial>
      <mass value="1.1809063299087657"/>
      <origin rpy="0 0 0" xyz="0.01098 -0.0026  -0.15154"/>
      <inertia ixx="0.19249766652753011" ixy="-0.002306536219501519" ixz="-0.00308957055005115" iyy="0.29973060108842253" iyz="-0.14192192697254485" izz="0.1110008660147678"/>
    </inertial>
    <collision name="upper_arm_left_collision">
      <origin rpy="0 0 0" xyz="0.01098 -0.0026  -0.15154"/>
      <geometry>
        <mesh filename="package://roboy_models/roboy_infineon_game/meshes/CAD/upper_arm_left.stl" scale="0.001 0.001 0.001"/>
      </geometry>
    </collision>
    <visual name="upper_arm_left_visual">
      <origin rpy="0 0 0" xyz="0.01098 -0.0026  -0.15154"/>
      <geometry>
        <mesh filename="package://roboy_models/roboy_infineon_game/meshes/CAD/upper_arm_left.stl" scale="0.001 0.001 0.001"/>
      </geometry>
    </visual>
  </link>
  <link name="lower_arm_left">
    <inertial>
      <mass value="1.4159186820881697"/>
      <origin rpy="0 0 0" xyz="-0.00158 -0.00276 -0.12014"/>
      <inertia ixx="0.01972434282329412" ixy="0.0004868562622172685" ixz="3.1776791738782414e-05" iyy="0.136151454541662" iyz="-0.03856056416354946" izz="0.11772500908251425"/>
    </inertial>
    <collision name="lower_arm_left_collision">
      <origin rpy="0 0 0" xyz="-0.00158 -0.00276 -0.12014"/>
      <geometry>
        <mesh filename="package://roboy_models/roboy_infineon_game/meshes/CAD/lower_arm_left.stl" scale="0.001 0.001 0.001"/>
      </geometry>
    </collision>
    <visual name="lower_arm_left_visual">
      <origin rpy="0 0 0" xyz="-0.00158 -0.00276 -0.12014"/>
      <geometry>
        <mesh filename="package://roboy_models/roboy_infineon_game/meshes/CAD/lower_arm_left.stl" scale="0.001 0.001 0.001"/>
      </geometry>
    </visual>
  </link>
  <link name="lower_arm_right">
    <inertial>
      <mass value="1.3992272098398935"/>
      <origin rpy="0 0 0" xyz="0.00143 -0.00283 -0.12369"/>
      <inertia ixx="0.01810948009587912" ixy="-0.0005189063901736044" ixz="3.997741962255835e-05" iyy="0.13328089869101623" iyz="0.036310470825779366" izz="0.1164677650951653"/>
    </inertial>
    <collision name="lower_arm_right_collision">
      <origin rpy="0 0 0" xyz="0.00143 -0.00283 -0.12369"/>
      <geometry>
        <mesh filename="package://roboy_models/roboy_infineon_game/meshes/CAD/lower_arm_right.stl" scale="0.001 0.001 0.001"/>
      </geometry>
    </collision>
    <visual name="lower_arm_right_visual">
      <origin rpy="0 0 0" xyz="0.00143 -0.00283 -0.12369"/>
      <geometry>
        <mesh filename="package://roboy_models/roboy_infineon_game/meshes/CAD/lower_arm_right.stl" scale="0.001 0.001 0.001"/>
      </geometry>
    </visual>
  </link>
  <link name="upper_arm_right">
    <inertial>
      <mass value="1.0958327493576236"/>
      <origin rpy="0 0 0" xyz="-0.01036 -0.00496 -0.15098"/>
      <inertia ixx="0.17904121063195466" ixy="0.0013740892922223082" ixz="-0.0018804876410868322" iyy="0.27814383199006454" iyz="0.1316285036742264" izz="0.10257941706215243"/>
    </inertial>
    <collision name="upper_arm_right_collision">
      <origin rpy="0 0 0" xyz="-0.01036 -0.00496 -0.15098"/>
      <geometry>
        <mesh filename="package://roboy_models/roboy_infineon_game/meshes/CAD/upper_arm_right.stl" scale="0.001 0.001 0.001"/>
      </geometry>
    </collision>
    <visual name="upper_arm_right_visual">
      <origin rpy="0 0 0" xyz="-0.01036 -0.00496 -0.15098"/>
      <geometry>
        <mesh filename="package://roboy_models/roboy_infineon_game/meshes/CAD/upper_arm_right.stl" scale="0.001 0.001 0.001"/>
      </geometry>
    </visual>
  </link>
  <link name="zed_camera_left_lense">
    <inertial>
      <mass value="0.005755421855273298"/>
      <origin rpy="0 0 0" xyz="1.000e-05 -2.347e-02  4.980e-03"/>
      <inertia ixx="0.005224792510686209" ixy="2.3943361940981148e-05" ixz="0.0003792235752580479" iyy="0.005217664057780662" iyz="-0.00032814642300882987" izz="4.878008912156887e-05"/>
    </inertial>
    <collision name="zed_camera_left_lense_collision">
      <origin rpy="0 0 0" xyz="1.000e-05 -2.347e-02  4.980e-03"/>
      <geometry>
        <mesh filename="package://roboy_models/roboy_infineon_game/meshes/CAD/zed_camera_left_lense.stl" scale="0.001 0.001 0.001"/>
      </geometry>
    </collision>
    <visual name="zed_camera_left_lense_visual">
      <origin rpy="0 0 0" xyz="1.000e-05 -2.347e-02  4.980e-03"/>
      <geometry>
        <mesh filename="package://roboy_models/roboy_infineon_game/meshes/CAD/zed_camera_left_lense.stl" scale="0.001 0.001 0.001"/>
      </geometry>
    </visual>
  </link>
  <link name="zed_camera_right_lense">
    <inertial>
      <mass value="0.005755421855273129"/>
      <origin rpy="0 0 0" xyz="0      -0.02347  0.00498"/>
      <inertia ixx="0.00522479251052088" ixy="-2.3942806253133926e-05" ixz="0.0003792235752696656" iyy="0.005217663109890817" iyz="0.00032813891497161525" izz="4.8779141402285844e-05"/>
    </inertial>
    <collision name="zed_camera_right_lense_collision">
      <origin rpy="0 0 0" xyz="0      -0.02347  0.00498"/>
      <geometry>
        <mesh filename="package://roboy_models/roboy_infineon_game/meshes/CAD/zed_camera_right_lense.stl" scale="0.001 0.001 0.001"/>
      </geometry>
    </collision>
    <visual name="zed_camera_right_lense_visual">
      <origin rpy="0 0 0" xyz="0      -0.02347  0.00498"/>
      <geometry>
        <mesh filename="package://roboy_models/roboy_infineon_game/meshes/CAD/zed_camera_right_lense.stl" scale="0.001 0.001 0.001"/>
      </geometry>
    </visual>
  </link>
  <link name="zed_camera">
    <inertial>
      <mass value="0.009633907989064926"/>
      <origin rpy="0 0 0" xyz="-0.0215   0.00029 -0.00824"/>
      <inertia ixx="0.008684211865767441" ixy="2.378834282957646e-06" ixz="0.0005290164856765297" iyy="0.008666687394562656" iyz="-3.706378187021515e-05" izz="4.725222619253178e-05"/>
    </inertial>
    <collision name="zed_camera_collision">
      <origin rpy="0 0 0" xyz="-0.0215   0.00029 -0.00824"/>
      <geometry>
        <mesh filename="package://roboy_models/roboy_infineon_game/meshes/CAD/zed_camera.stl" scale="0.001 0.001 0.001"/>
      </geometry>
    </collision>
    <visual name="zed_camera_visual">
      <origin rpy="0 0 0" xyz="-0.0215   0.00029 -0.00824"/>
      <geometry>
        <mesh filename="package://roboy_models/roboy_infineon_game/meshes/CAD/zed_camera.stl" scale="0.001 0.001 0.001"/>
      </geometry>
    </visual>
  </link>
  <link name="sphere_head_link1">
    <inertial>
      <mass value="0.02393810080236978"/>
      <origin rpy="0 0 0" xyz="0 0 0"/>
      <inertia ixx="0.012837399546969178" ixy="1.6371452804531116e-20" ixz="-2.6684678750160264e-05" iyy="0.012837344069708764" iyz="7.817357872141884e-18" izz="2.0130352188598093e-06"/>
    </inertial>
    <collision name="sphere_head_link1_collision">
      <origin rpy="0 0 0" xyz="0 0 0"/>
      <geometry>
        <mesh filename="package://roboy_models/roboy_infineon_game/meshes/CAD/sphere_head_link1.stl" scale="0.001 0.001 0.001"/>
      </geometry>
    </collision>
    <visual name="sphere_head_link1_visual">
      <origin rpy="0 0 0" xyz="0 0 0"/>
      <geometry>
        <mesh filename="package://roboy_models/roboy_infineon_game/meshes/CAD/sphere_head_link1.stl" scale="0.001 0.001 0.001"/>
      </geometry>
    </visual>
  </link>
  <link name="shere_head_link2">
    <inertial>
      <mass value="0.01604641751649573"/>
      <origin rpy="0 0 0" xyz="0 0 0"/>
      <inertia ixx="0.00860486097319985" ixy="1.1080546202801855e-20" ixz="-1.7887530011413227e-05" iyy="0.008604823785150114" iyz="5.230538224765269e-18" izz="9.21477182908014e-07"/>
    </inertial>
    <collision name="shere_head_link2_collision">
      <origin rpy="0 0 0" xyz="0 0 0"/>
      <geometry>
        <mesh filename="package://roboy_models/roboy_infineon_game/meshes/CAD/shere_head_link2.stl" scale="0.001 0.001 0.001"/>
      </geometry>
    </collision>
    <visual name="shere_head_link2_visual">
      <origin rpy="0 0 0" xyz="0 0 0"/>
      <geometry>
        <mesh filename="package://roboy_models/roboy_infineon_game/meshes/CAD/shere_head_link2.stl" scale="0.001 0.001 0.001"/>
      </geometry>
    </visual>
  </link>
  <link name="head">
    <inertial>
      <mass value="2.0690288729005957"/>
      <origin rpy="0 0 0" xyz="0.00064 0.04449 0.14806"/>
      <inertia ixx="1.6405545784076312" ixy="-9.6882839740856e-05" ixz="-0.08661510611492024" iyy="1.629789251542146" iyz="-0.0013000314402526782" izz="0.030622929355755123"/>
    </inertial>
    <collision name="head_collision">
      <origin rpy="0 0 0" xyz="0.00064 0.04449 0.14806"/>
      <geometry>
        <mesh filename="package://roboy_models/roboy_infineon_game/meshes/CAD/head.stl" scale="0.001 0.001 0.001"/>
      </geometry>
    </collision>
    <visual name="head_visual">
      <origin rpy="0 0 0" xyz="0.00064 0.04449 0.14806"/>
      <geometry>
        <mesh filename="package://roboy_models/roboy_infineon_game/meshes/CAD/head.stl" scale="0.001 0.001 0.001"/>
      </geometry>
    </visual>
  </link>
</robot>
