<?xml version="1.0" ?>
<sdf version="1.6">
	<model name="roboy_infineon_game">
		<link name="torso">
			<self_collide>false</self_collide>
			<pose frame="">0.0 0.0 0.0 0.0 -0.0 0.0</pose>
			<inertial>
				<pose frame="">0.0 0.0 0.0 0 0 0</pose>
				<mass>15.585466930961344</mass>
				<inertia>
					<ixx>5.079695742797729</ixx>
					<ixy>-0.0010843678464796012</ixy>
					<ixz>0.058514557722415025</ixz>
					<iyy>5.3496159845193185</iyy>
					<iyz>-0.013299822122575307</iyz>
					<izz>0.36673495668717304</izz>
				</inertia>
			</inertial>
			<collision name="torso_collision">
				<geometry>
					<mesh>
						<uri>model://roboy_infineon_game/meshes/CAD/torso.stl</uri>
						<scale>0.001 0.001 0.001</scale>
					</mesh>
				</geometry>
			</collision>
			<visual name="torso_visual">
				<geometry>
					<mesh>
						<uri>model://roboy_infineon_game/meshes/CAD/torso.stl</uri>
						<scale>0.001 0.001 0.001</scale>
					</mesh>
				</geometry>
			</visual>
		</link>
		<link name="base">
			<self_collide>false</self_collide>
			<pose frame="">0.0 0.0 0.0 0.0 -0.0 0.0</pose>
			<inertial>
				<pose frame="">0.0 0.0 0.0 0 0 0</pose>
				<mass>0.717302060129989</mass>
				<inertia>
					<ixx>0.006625207321646713</ixx>
					<ixy>2.0197911925526476e-05</ixy>
					<ixz>-3.596569361034858e-05</ixz>
					<iyy>0.014899467579983833</iyy>
					<iyz>5.481457241322389e-06</iyz>
					<izz>0.012889085164410688</izz>
				</inertia>
			</inertial>
			<collision name="base_collision">
				<geometry>
					<mesh>
						<uri>model://roboy_infineon_game/meshes/CAD/base.stl</uri>
						<scale>0.001 0.001 0.001</scale>
					</mesh>
				</geometry>
			</collision>
			<visual name="base_visual">
				<geometry>
					<mesh>
						<uri>model://roboy_infineon_game/meshes/CAD/base.stl</uri>
						<scale>0.001 0.001 0.001</scale>
					</mesh>
				</geometry>
			</visual>
		</link>
		<link name="elbow_left">
			<self_collide>false</self_collide>
			<pose frame="">0.29246099888775795 0.0026748602287507495 0.24368371806851602 0.0 -0.0 0.0</pose>
			<inertial>
				<pose frame="">0.0 0.0 0.0 0 0 0</pose>
				<mass>0.1568153717147207</mass>
				<inertia>
					<ixx>0.009431644446213878</ixx>
					<ixy>-0.00012519644702725964</ixy>
					<ixz>-9.890526254867459e-05</ixz>
					<iyy>0.022865485940365013</iyy>
					<iyz>-0.011162058463724776</iyz>
					<izz>0.01354205131758522</izz>
				</inertia>
			</inertial>
			<collision name="elbow_left_collision">
				<geometry>
					<mesh>
						<uri>model://roboy_infineon_game/meshes/CAD/elbow_left.stl</uri>
						<scale>0.001 0.001 0.001</scale>
					</mesh>
				</geometry>
			</collision>
			<visual name="elbow_left_visual">
				<geometry>
					<mesh>
						<uri>model://roboy_infineon_game/meshes/CAD/elbow_left.stl</uri>
						<scale>0.001 0.001 0.001</scale>
					</mesh>
				</geometry>
			</visual>
		</link>
		<link name="elbow_right">
			<self_collide>false</self_collide>
			<pose frame="">-0.2920543656145918 0.002562699282440758 0.24074349587380134 0.0 -0.0 0.0</pose>
			<inertial>
				<pose frame="">0.0 0.0 0.0 0 0 0</pose>
				<mass>0.17375098956097507</mass>
				<inertia>
					<ixx>0.010199495812814567</ixx>
					<ixy>0.00013263312204776155</ixy>
					<ixz>-0.00010418886940174745</ixz>
					<iyy>0.025041161383884545</iyy>
					<iyz>0.012203592993939928</iyz>
					<izz>0.014951862960773376</izz>
				</inertia>
			</inertial>
			<collision name="elbow_right_collision">
				<geometry>
					<mesh>
						<uri>model://roboy_infineon_game/meshes/CAD/elbow_right.stl</uri>
						<scale>0.001 0.001 0.001</scale>
					</mesh>
				</geometry>
			</collision>
			<visual name="elbow_right_visual">
				<geometry>
					<mesh>
						<uri>model://roboy_infineon_game/meshes/CAD/elbow_right.stl</uri>
						<scale>0.001 0.001 0.001</scale>
					</mesh>
				</geometry>
			</visual>
		</link>
		<link name="sphere_right_link1">
			<self_collide>false</self_collide>
			<pose frame="">-0.2921799666276166 0.009210766199563016 0.5486137623678263 0.0 -0.0 0.0</pose>
			<inertial>
				<pose frame="">0.0 0.0 0.0 0 0 0</pose>
				<mass>0.04675596089362309</mass>
				<inertia>
					<ixx>0.01408241240995392</ixx>
					<ixy>0.0001258297032379935</ixy>
					<ixz>-0.000236265028387936</ixz>
					<iyy>0.018069961524930532</iyy>
					<iyz>0.00749469769415799</iyz>
					<izz>0.004001456627830663</izz>
				</inertia>
			</inertial>
			<collision name="sphere_right_link1_collision">
				<geometry>
					<mesh>
						<uri>model://roboy_infineon_game/meshes/CAD/sphere_right_link1.stl</uri>
						<scale>0.001 0.001 0.001</scale>
					</mesh>
				</geometry>
			</collision>
			<visual name="sphere_right_link1_visual">
				<geometry>
					<mesh>
						<uri>model://roboy_infineon_game/meshes/CAD/sphere_right_link1.stl</uri>
						<scale>0.001 0.001 0.001</scale>
					</mesh>
				</geometry>
			</visual>
		</link>
		<link name="sphere_right_link2">
			<self_collide>false</self_collide>
			<pose frame="">-0.29218017249450917 0.009210470824623786 0.5486137597402447 0.0 -0.0 0.0</pose>
			<inertial>
				<pose frame="">0.0 0.0 0.0 0 0 0</pose>
				<mass>0.031339415773582444</mass>
				<inertia>
					<ixx>0.009437802344317998</ixx>
					<ixy>8.43380330440342e-05</ixy>
					<ixz>-0.0001583577865898864</ixz>
					<iyy>0.012110566274240927</iyy>
					<iyz>0.005023522284944857</iyz>
					<izz>0.002680779704713365</izz>
				</inertia>
			</inertial>
			<collision name="sphere_right_link2_collision">
				<geometry>
					<mesh>
						<uri>model://roboy_infineon_game/meshes/CAD/sphere_right_link2.stl</uri>
						<scale>0.001 0.001 0.001</scale>
					</mesh>
				</geometry>
			</collision>
			<visual name="sphere_right_link2_visual">
				<geometry>
					<mesh>
						<uri>model://roboy_infineon_game/meshes/CAD/sphere_right_link2.stl</uri>
						<scale>0.001 0.001 0.001</scale>
					</mesh>
				</geometry>
			</visual>
		</link>
		<link name="sphere_left_link1">
			<self_collide>false</self_collide>
			<pose frame="">0.2921800522273415 0.009210766240973228 0.5486137870423141 0.0 -0.0 0.0</pose>
			<inertial>
				<pose frame="">0.0 0.0 0.0 0 0 0</pose>
				<mass>0.046755519327953354</mass>
				<inertia>
					<ixx>0.014082280743277947</ixx>
					<ixy>-0.00012582855239671661</ixy>
					<ixz>-0.00023626280923146897</ixz>
					<iyy>0.018069794508113902</iyy>
					<iyz>-0.0074946294466258015</iyz>
					<izz>0.004001421202848276</izz>
				</inertia>
			</inertial>
			<collision name="sphere_left_link1_collision">
				<geometry>
					<mesh>
						<uri>model://roboy_infineon_game/meshes/CAD/sphere_left_link1.stl</uri>
						<scale>0.001 0.001 0.001</scale>
					</mesh>
				</geometry>
			</collision>
			<visual name="sphere_left_link1_visual">
				<geometry>
					<mesh>
						<uri>model://roboy_infineon_game/meshes/CAD/sphere_left_link1.stl</uri>
						<scale>0.001 0.001 0.001</scale>
					</mesh>
				</geometry>
			</visual>
		</link>
		<link name="sphere_left_link2">
			<self_collide>false</self_collide>
			<pose frame="">0.29218006602859276 0.009210460048202269 0.5486137752945566 0.0 -0.0 0.0</pose>
			<inertial>
				<pose frame="">0.0 0.0 0.0 0 0 0</pose>
				<mass>0.03134020848172157</mass>
				<inertia>
					<ixx>0.009438041528757955</ixx>
					<ixy>-8.434003849461378e-05</ixy>
					<ixz>-0.00015836161156868728</ixz>
					<iyy>0.012110871144511353</iyy>
					<iyz>-0.0050236476632439745</iyz>
					<izz>0.002680845512452334</izz>
				</inertia>
			</inertial>
			<collision name="sphere_left_link2_collision">
				<geometry>
					<mesh>
						<uri>model://roboy_infineon_game/meshes/CAD/sphere_left_link2.stl</uri>
						<scale>0.001 0.001 0.001</scale>
					</mesh>
				</geometry>
			</collision>
			<visual name="sphere_left_link2_visual">
				<geometry>
					<mesh>
						<uri>model://roboy_infineon_game/meshes/CAD/sphere_left_link2.stl</uri>
						<scale>0.001 0.001 0.001</scale>
					</mesh>
				</geometry>
			</visual>
		</link>
		<link name="palm">
			<self_collide>false</self_collide>
			<pose frame="">0.28048106895562624 -0.004816513726425601 -0.09958356781881773 0.0 -0.0 0.0</pose>
			<inertial>
				<pose frame="">0.0 0.0 0.0 0 0 0</pose>
				<mass>0.051047603764359704</mass>
				<inertia>
					<ixx>0.0005642976234324479</ixx>
					<ixy>6.973757646592466e-05</ixy>
					<ixz>-2.2140404687012035e-05</ixz>
					<iyy>0.0045620445863501415</iyy>
					<iyz>0.0014255480384397687</iyz>
					<izz>0.004038855487756269</izz>
				</inertia>
			</inertial>
			<collision name="palm_collision">
				<geometry>
					<mesh>
						<uri>model://roboy_infineon_game/meshes/CAD/palm.stl</uri>
						<scale>0.001 0.001 0.001</scale>
					</mesh>
				</geometry>
			</collision>
			<visual name="palm_visual">
				<geometry>
					<mesh>
						<uri>model://roboy_infineon_game/meshes/CAD/palm.stl</uri>
						<scale>0.001 0.001 0.001</scale>
					</mesh>
				</geometry>
			</visual>
		</link>
		<link name="left_ring_limb0">
			<self_collide>false</self_collide>
			<pose frame="">0.2795964084599445 0.012193108245881339 -0.14515559433110864 0.0 -0.0 0.0</pose>
			<inertial>
				<pose frame="">0.0 0.0 0.0 0 0 0</pose>
				<mass>0.00042698927905567593</mass>
				<inertia>
					<ixx>9.06817921051976e-06</ixx>
					<ixy>-1.4556070812605406e-06</ixy>
					<ixz>7.552339396282292e-07</ixz>
					<iyy>4.2381568843882405e-05</iyy>
					<iyz>1.7329692668618087e-05</iyz>
					<izz>3.345029005361239e-05</izz>
				</inertia>
			</inertial>
			<collision name="left_ring_limb0_collision">
				<geometry>
					<mesh>
						<uri>model://roboy_infineon_game/meshes/CAD/left_ring_limb0.stl</uri>
						<scale>0.001 0.001 0.001</scale>
					</mesh>
				</geometry>
			</collision>
			<visual name="left_ring_limb0_visual">
				<geometry>
					<mesh>
						<uri>model://roboy_infineon_game/meshes/CAD/left_ring_limb0.stl</uri>
						<scale>0.001 0.001 0.001</scale>
					</mesh>
				</geometry>
			</visual>
		</link>
		<link name="left_ring_limb1">
			<self_collide>false</self_collide>
			<pose frame="">0.2792400665944989 0.018036744598779488 -0.16913970309588147 0.0 -0.0 0.0</pose>
			<inertial>
				<pose frame="">0.0 0.0 0.0 0 0 0</pose>
				<mass>0.003829241517863796</mass>
				<inertia>
					<ixx>0.00011176994574178268</ixx>
					<ixy>-1.9283372411789186e-05</ixy>
					<ixz>1.1889390832434235e-05</ixz>
					<iyy>0.00040905730130950095</iyy>
					<iyz>0.0001808457030477495</iyz>
					<izz>0.0002999547975012437</izz>
				</inertia>
			</inertial>
			<collision name="left_ring_limb1_collision">
				<geometry>
					<mesh>
						<uri>model://roboy_infineon_game/meshes/CAD/left_ring_limb1.stl</uri>
						<scale>0.001 0.001 0.001</scale>
					</mesh>
				</geometry>
			</collision>
			<visual name="left_ring_limb1_visual">
				<geometry>
					<mesh>
						<uri>model://roboy_infineon_game/meshes/CAD/left_ring_limb1.stl</uri>
						<scale>0.001 0.001 0.001</scale>
					</mesh>
				</geometry>
			</visual>
		</link>
		<link name="left_ring_limb2">
			<self_collide>false</self_collide>
			<pose frame="">0.2779978678244679 0.027410876916966177 -0.20775200048419643 0.0 -0.0 0.0</pose>
			<inertial>
				<pose frame="">0.0 0.0 0.0 0 0 0</pose>
				<mass>0.0016247461735835922</mass>
				<inertia>
					<ixx>7.152150998565983e-05</ixx>
					<ixy>-1.2381976282458702e-05</ixy>
					<ixz>9.288629337823387e-06</ixz>
					<iyy>0.00019585674302424993</iyy>
					<iyz>9.384126673223814e-05</iyz>
					<izz>0.0001268136600453599</izz>
				</inertia>
			</inertial>
			<collision name="left_ring_limb2_collision">
				<geometry>
					<mesh>
						<uri>model://roboy_infineon_game/meshes/CAD/left_ring_limb2.stl</uri>
						<scale>0.001 0.001 0.001</scale>
					</mesh>
				</geometry>
			</collision>
			<visual name="left_ring_limb2_visual">
				<geometry>
					<mesh>
						<uri>model://roboy_infineon_game/meshes/CAD/left_ring_limb2.stl</uri>
						<scale>0.001 0.001 0.001</scale>
					</mesh>
				</geometry>
			</visual>
		</link>
		<link name="left_ring_limb3">
			<self_collide>false</self_collide>
			<pose frame="">0.27735795596507784 0.0338219607381365 -0.2341146804387935 0.0 -0.0 0.0</pose>
			<inertial>
				<pose frame="">0.0 0.0 0.0 0 0 0</pose>
				<mass>0.0006943752997715763</mass>
				<inertia>
					<ixx>3.888234617440118e-05</ixx>
					<ixy>-6.5141595890306356e-06</ixy>
					<ixz>5.504069186137751e-06</ixz>
					<iyy>9.150325153719992e-05</iyy>
					<iyz>4.508974955285808e-05</iyz>
					<izz>5.421689295120942e-05</izz>
				</inertia>
			</inertial>
			<collision name="left_ring_limb3_collision">
				<geometry>
					<mesh>
						<uri>model://roboy_infineon_game/meshes/CAD/left_ring_limb3.stl</uri>
						<scale>0.001 0.001 0.001</scale>
					</mesh>
				</geometry>
			</collision>
			<visual name="left_ring_limb3_visual">
				<geometry>
					<mesh>
						<uri>model://roboy_infineon_game/meshes/CAD/left_ring_limb3.stl</uri>
						<scale>0.001 0.001 0.001</scale>
					</mesh>
				</geometry>
			</visual>
		</link>
		<link name="left_little_limb0">
			<self_collide>false</self_collide>
			<pose frame="">0.27915114694464427 0.02709385515314198 -0.13097852422324896 0.0 -0.0 0.0</pose>
			<inertial>
				<pose frame="">0.0 0.0 0.0 0 0 0</pose>
				<mass>0.00042697827343766043</mass>
				<inertia>
					<ixx>7.646330676015054e-06</ixx>
					<ixy>-3.229440615653373e-06</ixy>
					<ixz>1.514279653395261e-06</ixz>
					<iyy>4.060311614946017e-05</iyy>
					<iyz>1.561188282137106e-05</iyz>
					<izz>3.359281331926145e-05</izz>
				</inertia>
			</inertial>
			<collision name="left_little_limb0_collision">
				<geometry>
					<mesh>
						<uri>model://roboy_infineon_game/meshes/CAD/left_little_limb0.stl</uri>
						<scale>0.001 0.001 0.001</scale>
					</mesh>
				</geometry>
			</collision>
			<visual name="left_little_limb0_visual">
				<geometry>
					<mesh>
						<uri>model://roboy_infineon_game/meshes/CAD/left_little_limb0.stl</uri>
						<scale>0.001 0.001 0.001</scale>
					</mesh>
				</geometry>
			</visual>
		</link>
		<link name="left_little_limb1">
			<self_collide>false</self_collide>
			<pose frame="">0.2806662337999544 0.0389844580875805 -0.1525616523653503 0.0 -0.0 0.0</pose>
			<inertial>
				<pose frame="">0.0 0.0 0.0 0 0 0</pose>
				<mass>0.00382922696560545</mass>
				<inertia>
					<ixx>9.591805033342318e-05</ixx>
					<ixy>-4.19251146246524e-05</ixy>
					<ixz>2.3154071936643988e-05</ixz>
					<iyy>0.0003915328668441594</iyy>
					<iyz>0.0001640127271946591</iyz>
					<izz>0.00030774724342872513</izz>
				</inertia>
			</inertial>
			<collision name="left_little_limb1_collision">
				<geometry>
					<mesh>
						<uri>model://roboy_infineon_game/meshes/CAD/left_little_limb1.stl</uri>
						<scale>0.001 0.001 0.001</scale>
					</mesh>
				</geometry>
			</collision>
			<visual name="left_little_limb1_visual">
				<geometry>
					<mesh>
						<uri>model://roboy_infineon_game/meshes/CAD/left_little_limb1.stl</uri>
						<scale>0.001 0.001 0.001</scale>
					</mesh>
				</geometry>
			</visual>
		</link>
		<link name="left_little_limb2">
			<self_collide>false</self_collide>
			<pose frame="">0.2824377864908987 0.05812786770839102 -0.18735691582593864 0.0 -0.0 0.0</pose>
			<inertial>
				<pose frame="">0.0 0.0 0.0 0 0 0</pose>
				<mass>0.001624745378245611</mass>
				<inertia>
					<ixx>6.26962034034003e-05</ixx>
					<ixy>-2.6682281240723343e-05</ixy>
					<ixz>1.7760009025081236e-05</ixz>
					<iyy>0.00018677954268692663</iyy>
					<iyz>8.59906224613511e-05</iyz>
					<izz>0.0001351543531672839</izz>
				</inertia>
			</inertial>
			<collision name="left_little_limb2_collision">
				<geometry>
					<mesh>
						<uri>model://roboy_infineon_game/meshes/CAD/left_little_limb2.stl</uri>
						<scale>0.001 0.001 0.001</scale>
					</mesh>
				</geometry>
			</collision>
			<visual name="left_little_limb2_visual">
				<geometry>
					<mesh>
						<uri>model://roboy_infineon_game/meshes/CAD/left_little_limb2.stl</uri>
						<scale>0.001 0.001 0.001</scale>
					</mesh>
				</geometry>
			</visual>
		</link>
		<link name="left_little_limb3">
			<self_collide>false</self_collide>
			<pose frame="">0.28385527326115656 0.07119829171724 -0.2110983713326573 0.0 -0.0 0.0</pose>
			<inertial>
				<pose frame="">0.0 0.0 0.0 0 0 0</pose>
				<mass>0.000694375681967843</mass>
				<inertia>
					<ixx>3.449222678789113e-05</ixx>
					<ixy>-1.4034988499413473e-05</ixy>
					<ixz>1.0446836648953337e-05</ixz>
					<iyy>8.69155199850427e-05</iyy>
					<iyz>4.1610921373092544e-05</iyz>
					<izz>5.947922868536202e-05</izz>
				</inertia>
			</inertial>
			<collision name="left_little_limb3_collision">
				<geometry>
					<mesh>
						<uri>model://roboy_infineon_game/meshes/CAD/left_little_limb3.stl</uri>
						<scale>0.001 0.001 0.001</scale>
					</mesh>
				</geometry>
			</collision>
			<visual name="left_little_limb3_visual">
				<geometry>
					<mesh>
						<uri>model://roboy_infineon_game/meshes/CAD/left_little_limb3.stl</uri>
						<scale>0.001 0.001 0.001</scale>
					</mesh>
				</geometry>
			</visual>
		</link>
		<link name="left_thumb_limb0">
			<self_collide>false</self_collide>
			<pose frame="">0.2644295859619111 -0.03174337817796616 -0.0950594448663973 0.0 -0.0 0.0</pose>
			<inertial>
				<pose frame="">0.0 0.0 0.0 0 0 0</pose>
				<mass>0.0004270936562641884</mass>
				<inertia>
					<ixx>4.2954154434823164e-06</ixx>
					<ixy>3.5856713228812274e-06</ixy>
					<ixz>-1.2892733424284021e-06</ixz>
					<iyy>3.3730810405179924e-05</iyy>
					<iyz>1.0736282567274773e-05</iyz>
					<izz>3.030110157342035e-05</izz>
				</inertia>
			</inertial>
			<collision name="left_thumb_limb0_collision">
				<geometry>
					<mesh>
						<uri>model://roboy_infineon_game/meshes/CAD/left_thumb_limb0.stl</uri>
						<scale>0.001 0.001 0.001</scale>
					</mesh>
				</geometry>
			</collision>
			<visual name="left_thumb_limb0_visual">
				<geometry>
					<mesh>
						<uri>model://roboy_infineon_game/meshes/CAD/left_thumb_limb0.stl</uri>
						<scale>0.001 0.001 0.001</scale>
					</mesh>
				</geometry>
			</visual>
		</link>
		<link name="left_thumb_limb1">
			<self_collide>false</self_collide>
			<pose frame="">0.25601678779750325 -0.027597929846522075 -0.11789614266275274 0.0 -0.0 0.0</pose>
			<inertial>
				<pose frame="">0.0 0.0 0.0 0 0 0</pose>
				<mass>0.0038294622261042174</mass>
				<inertia>
					<ixx>5.701444125449982e-05</ixx>
					<ixy>2.7109060915844808e-05</ixy>
					<ixz>-1.232065833914162e-05</ixz>
					<iyy>0.0003051794258941571</iyy>
					<iyz>0.00011530159318711529</iyz>
					<izz>0.0002541204850231677</izz>
				</inertia>
			</inertial>
			<collision name="left_thumb_limb1_collision">
				<geometry>
					<mesh>
						<uri>model://roboy_infineon_game/meshes/CAD/left_thumb_limb1.stl</uri>
						<scale>0.001 0.001 0.001</scale>
					</mesh>
				</geometry>
			</collision>
			<visual name="left_thumb_limb1_visual">
				<geometry>
					<mesh>
						<uri>model://roboy_infineon_game/meshes/CAD/left_thumb_limb1.stl</uri>
						<scale>0.001 0.001 0.001</scale>
					</mesh>
				</geometry>
			</visual>
		</link>
		<link name="left_thumb_limb2">
			<self_collide>false</self_collide>
			<pose frame="">0.2527938234162815 -0.010414646178071023 -0.13938463128655398 0.0 -0.0 0.0</pose>
			<inertial>
				<pose frame="">0.0 0.0 0.0 0 0 0</pose>
				<mass>0.0016247934834448725</mass>
				<inertia>
					<ixx>3.188852123783219e-05</ixx>
					<ixy>4.220357558259184e-06</ixy>
					<ixz>-2.400387342304833e-06</ixz>
					<iyy>0.0001354626794148631</iyy>
					<iyz>5.722906827633372e-05</iyz>
					<izz>0.00010416792303185145</izz>
				</inertia>
			</inertial>
			<collision name="left_thumb_limb2_collision">
				<geometry>
					<mesh>
						<uri>model://roboy_infineon_game/meshes/CAD/left_thumb_limb2.stl</uri>
						<scale>0.001 0.001 0.001</scale>
					</mesh>
				</geometry>
			</collision>
			<visual name="left_thumb_limb2_visual">
				<geometry>
					<mesh>
						<uri>model://roboy_infineon_game/meshes/CAD/left_thumb_limb2.stl</uri>
						<scale>0.001 0.001 0.001</scale>
					</mesh>
				</geometry>
			</visual>
		</link>
		<link name="left_thumb_limb3">
			<self_collide>false</self_collide>
			<pose frame="">0.26437179297274505 0.004119908573246436 -0.12448983402572526 0.0 -0.0 0.0</pose>
			<inertial>
				<pose frame="">0.0 0.0 0.0 0 0 0</pose>
				<mass>0.0006943751960180326</mass>
				<inertia>
					<ixx>1.0799336517044251e-05</ixx>
					<ixy>-7.554325018620578e-07</ixy>
					<ixz>3.583927852315045e-07</ixz>
					<iyy>5.9322218131798904e-05</iyy>
					<iyz>2.2844468975509682e-05</iyz>
					<izz>4.855150125463113e-05</izz>
				</inertia>
			</inertial>
			<collision name="left_thumb_limb3_collision">
				<geometry>
					<mesh>
						<uri>model://roboy_infineon_game/meshes/CAD/left_thumb_limb3.stl</uri>
						<scale>0.001 0.001 0.001</scale>
					</mesh>
				</geometry>
			</collision>
			<visual name="left_thumb_limb3_visual">
				<geometry>
					<mesh>
						<uri>model://roboy_infineon_game/meshes/CAD/left_thumb_limb3.stl</uri>
						<scale>0.001 0.001 0.001</scale>
					</mesh>
				</geometry>
			</visual>
		</link>
		<link name="left_index_limb0">
			<self_collide>false</self_collide>
			<pose frame="">0.2819987832022405 -0.026491039588919123 -0.1442962246758965 0.0 -0.0 0.0</pose>
			<inertial>
				<pose frame="">0.0 0.0 0.0 0 0 0</pose>
				<mass>0.00042704072295925323</mass>
				<inertia>
					<ixx>9.199217389559458e-06</ixx>
					<ixy>3.1904597853014466e-06</ixy>
					<ixz>-1.6317709860340043e-06</ixz>
					<iyy>4.2856673715446425e-05</iyy>
					<iyz>1.737713351264253e-05</iyz>
					<izz>3.426661588961933e-05</izz>
				</inertia>
			</inertial>
			<collision name="left_index_limb0_collision">
				<geometry>
					<mesh>
						<uri>model://roboy_infineon_game/meshes/CAD/left_index_limb0.stl</uri>
						<scale>0.001 0.001 0.001</scale>
					</mesh>
				</geometry>
			</collision>
			<visual name="left_index_limb0_visual">
				<geometry>
					<mesh>
						<uri>model://roboy_infineon_game/meshes/CAD/left_index_limb0.stl</uri>
						<scale>0.001 0.001 0.001</scale>
					</mesh>
				</geometry>
			</visual>
		</link>
		<link name="left_index_limb1">
			<self_collide>false</self_collide>
			<pose frame="">0.28243445818457813 -0.03339070300492502 -0.1679971275156317 0.0 -0.0 0.0</pose>
			<inertial>
				<pose frame="">0.0 0.0 0.0 0 0 0</pose>
				<mass>0.0038291847047877674</mass>
				<inertia>
					<ixx>0.00011331668399670983</ixx>
					<ixy>3.6116693545215206e-05</ixy>
					<ixz>-2.172178421726994e-05</ixz>
					<iyy>0.0004144267564259643</iyy>
					<iyz>0.00018170411666070416</iyz>
					<izz>0.00030986425785158023</izz>
				</inertia>
			</inertial>
			<collision name="left_index_limb1_collision">
				<geometry>
					<mesh>
						<uri>model://roboy_infineon_game/meshes/CAD/left_index_limb1.stl</uri>
						<scale>0.001 0.001 0.001</scale>
					</mesh>
				</geometry>
			</collision>
			<visual name="left_index_limb1_visual">
				<geometry>
					<mesh>
						<uri>model://roboy_infineon_game/meshes/CAD/left_index_limb1.stl</uri>
						<scale>0.001 0.001 0.001</scale>
					</mesh>
				</geometry>
			</visual>
		</link>
		<link name="left_index_limb2">
			<self_collide>false</self_collide>
			<pose frame="">0.2824673351478068 -0.04454584021237155 -0.20615300945087522 0.0 -0.0 0.0</pose>
			<inertial>
				<pose frame="">0.0 0.0 0.0 0 0 0</pose>
				<mass>0.0016247456622690932</mass>
				<inertia>
					<ixx>7.244898466919644e-05</ixx>
					<ixy>2.044648361124246e-05</ixy>
					<ixz>-1.4961835108664842e-05</ixz>
					<iyy>0.00019884834999383725</iyy>
					<iyz>9.462078216177411e-05</iyz>
					<izz>0.0001328902998482613</izz>
				</inertia>
			</inertial>
			<collision name="left_index_limb2_collision">
				<geometry>
					<mesh>
						<uri>model://roboy_infineon_game/meshes/CAD/left_index_limb2.stl</uri>
						<scale>0.001 0.001 0.001</scale>
					</mesh>
				</geometry>
			</collision>
			<visual name="left_index_limb2_visual">
				<geometry>
					<mesh>
						<uri>model://roboy_infineon_game/meshes/CAD/left_index_limb2.stl</uri>
						<scale>0.001 0.001 0.001</scale>
					</mesh>
				</geometry>
			</visual>
		</link>
		<link name="left_index_limb3">
			<self_collide>false</self_collide>
			<pose frame="">0.2826977734236964 -0.05214710964992337 -0.2322042989904067 0.0 -0.0 0.0</pose>
			<inertial>
				<pose frame="">0.0 0.0 0.0 0 0 0</pose>
				<mass>0.0006943760025212351</mass>
				<inertia>
					<ixx>3.935759681532587e-05</ixx>
					<ixy>1.0237034950993482e-05</ixy>
					<ixz>-8.414635593280202e-06</ixz>
					<iyy>9.296092902776221e-05</iyy>
					<iyz>4.558360122304754e-05</iyz>
					<izz>5.738801562279048e-05</izz>
				</inertia>
			</inertial>
			<collision name="left_index_limb3_collision">
				<geometry>
					<mesh>
						<uri>model://roboy_infineon_game/meshes/CAD/left_index_limb3.stl</uri>
						<scale>0.001 0.001 0.001</scale>
					</mesh>
				</geometry>
			</collision>
			<visual name="left_index_limb3_visual">
				<geometry>
					<mesh>
						<uri>model://roboy_infineon_game/meshes/CAD/left_index_limb3.stl</uri>
						<scale>0.001 0.001 0.001</scale>
					</mesh>
				</geometry>
			</visual>
		</link>
		<link name="left_middle_limb0">
			<self_collide>false</self_collide>
			<pose frame="">0.2805799969672889 -0.006777319928252212 -0.1499487369148 0.0 -0.0 0.0</pose>
			<inertial>
				<pose frame="">0.0 0.0 0.0 0 0 0</pose>
				<mass>0.0004269917809018472</mass>
				<inertia>
					<ixx>9.628320322458132e-06</ixx>
					<ixy>8.121391793774464e-07</ixy>
					<ixz>-4.3386151683294725e-07</ixz>
					<iyy>4.322094123558565e-05</iyy>
					<iyz>1.7964981111057085e-05</iyz>
					<izz>3.3642006588304284e-05</izz>
				</inertia>
			</inertial>
			<collision name="left_middle_limb0_collision">
				<geometry>
					<mesh>
						<uri>model://roboy_infineon_game/meshes/CAD/left_middle_limb0.stl</uri>
						<scale>0.001 0.001 0.001</scale>
					</mesh>
				</geometry>
			</collision>
			<visual name="left_middle_limb0_visual">
				<geometry>
					<mesh>
						<uri>model://roboy_infineon_game/meshes/CAD/left_middle_limb0.stl</uri>
						<scale>0.001 0.001 0.001</scale>
					</mesh>
				</geometry>
			</visual>
		</link>
		<link name="left_middle_limb1">
			<self_collide>false</self_collide>
			<pose frame="">0.28058948264097894 -0.00732596509120916 -0.1746310681357879 0.0 -0.0 0.0</pose>
			<inertial>
				<pose frame="">0.0 0.0 0.0 0 0 0</pose>
				<mass>0.0038292272976380203</mass>
				<inertia>
					<ixx>0.00011795815464596243</ixx>
					<ixy>7.871452020142755e-06</ixy>
					<ixz>-4.918826780153353e-06</ixz>
					<iyy>0.0004192273567608528</iyy>
					<iyz>0.00018763217452860546</iyz>
					<izz>0.00030175595034477766</izz>
				</inertia>
			</inertial>
			<collision name="left_middle_limb1_collision">
				<geometry>
					<mesh>
						<uri>model://roboy_infineon_game/meshes/CAD/left_middle_limb1.stl</uri>
						<scale>0.001 0.001 0.001</scale>
					</mesh>
				</geometry>
			</collision>
			<visual name="left_middle_limb1_visual">
				<geometry>
					<mesh>
						<uri>model://roboy_infineon_game/meshes/CAD/left_middle_limb1.stl</uri>
						<scale>0.001 0.001 0.001</scale>
					</mesh>
				</geometry>
			</visual>
		</link>
		<link name="left_middle_limb2">
			<self_collide>false</self_collide>
			<pose frame="">0.2799363751264317 -0.008249583153230091 -0.21436823187738874 0.0 -0.0 0.0</pose>
			<inertial>
				<pose frame="">0.0 0.0 0.0 0 0 0</pose>
				<mass>0.0016247457191924265</mass>
				<inertia>
					<ixx>7.494878668026111e-05</ixx>
					<ixy>3.7522701164539915e-06</ixy>
					<ixz>-2.8763021033515174e-06</ixz>
					<iyy>0.00020216047274025515</iyy>
					<iyz>9.750724551735193e-05</iyz>
					<izz>0.00012745200906002257</izz>
				</inertia>
			</inertial>
			<collision name="left_middle_limb2_collision">
				<geometry>
					<mesh>
						<uri>model://roboy_infineon_game/meshes/CAD/left_middle_limb2.stl</uri>
						<scale>0.001 0.001 0.001</scale>
					</mesh>
				</geometry>
			</collision>
			<visual name="left_middle_limb2_visual">
				<geometry>
					<mesh>
						<uri>model://roboy_infineon_game/meshes/CAD/left_middle_limb2.stl</uri>
						<scale>0.001 0.001 0.001</scale>
					</mesh>
				</geometry>
			</visual>
		</link>
		<link name="left_middle_limb3">
			<self_collide>false</self_collide>
			<pose frame="">0.2796985560629554 -0.00886725304537568 -0.2414987501182129 0.0 -0.0 0.0</pose>
			<inertial>
				<pose frame="">0.0 0.0 0.0 0 0 0</pose>
				<mass>0.0006943750023357814</mass>
				<inertia>
					<ixx>4.0581182569994296e-05</ixx>
					<ixy>1.722188766212528e-06</ixy>
					<ixz>-1.487393936346671e-06</ixz>
					<iyy>9.484863245837088e-05</iyy>
					<iyz>4.6904740955860724e-05</iyz>
					<izz>5.438112051354127e-05</izz>
				</inertia>
			</inertial>
			<collision name="left_middle_limb3_collision">
				<geometry>
					<mesh>
						<uri>model://roboy_infineon_game/meshes/CAD/left_middle_limb3.stl</uri>
						<scale>0.001 0.001 0.001</scale>
					</mesh>
				</geometry>
			</collision>
			<visual name="left_middle_limb3_visual">
				<geometry>
					<mesh>
						<uri>model://roboy_infineon_game/meshes/CAD/left_middle_limb3.stl</uri>
						<scale>0.001 0.001 0.001</scale>
					</mesh>
				</geometry>
			</visual>
		</link>
		<link name="wrist_left_1">
			<self_collide>false</self_collide>
			<pose frame="">0.28382910812159284 -0.00451726677178151 -0.046027861261340286 0.0 -0.0 0.0</pose>
			<inertial>
				<pose frame="">0.0 0.0 0.0 0 0 0</pose>
				<mass>0.012764273069100234</mass>
				<inertia>
					<ixx>2.9934913504206502e-05</ixx>
					<ixy>1.6311025100062298e-05</ixy>
					<ixz>-2.6058950431388023e-06</ixz>
					<iyy>0.0010588612289813193</iyy>
					<iyz>0.0001668482339759435</iyz>
					<izz>0.0010339768891506353</izz>
				</inertia>
			</inertial>
			<collision name="wrist_left_1_collision">
				<geometry>
					<mesh>
						<uri>model://roboy_infineon_game/meshes/CAD/wrist_left_1.stl</uri>
						<scale>0.001 0.001 0.001</scale>
					</mesh>
				</geometry>
			</collision>
			<visual name="wrist_left_1_visual">
				<geometry>
					<mesh>
						<uri>model://roboy_infineon_game/meshes/CAD/wrist_left_1.stl</uri>
						<scale>0.001 0.001 0.001</scale>
					</mesh>
				</geometry>
			</visual>
		</link>
		<link name="right_ring_limb0">
			<self_collide>false</self_collide>
			<pose frame="">-0.288061461137791 -0.02674765468182867 -0.14736590729152163 0.0 -0.0 0.0</pose>
			<inertial>
				<pose frame="">0.0 0.0 0.0 0 0 0</pose>
				<mass>0.00042704466709723077</mass>
				<inertia>
					<ixx>9.587454972047968e-06</ixx>
					<ixy>-3.290558462622337e-06</ixy>
					<ixz>-1.6826607960000105e-06</ixz>
					<iyy>4.471529987170614e-05</iyy>
					<iyz>-1.812854670762791e-05</iyz>
					<izz>3.5748703714543334e-05</izz>
				</inertia>
			</inertial>
			<collision name="right_ring_limb0_collision">
				<geometry>
					<mesh>
						<uri>model://roboy_infineon_game/meshes/CAD/right_ring_limb0.stl</uri>
						<scale>0.001 0.001 0.001</scale>
					</mesh>
				</geometry>
			</collision>
			<visual name="right_ring_limb0_visual">
				<geometry>
					<mesh>
						<uri>model://roboy_infineon_game/meshes/CAD/right_ring_limb0.stl</uri>
						<scale>0.001 0.001 0.001</scale>
					</mesh>
				</geometry>
			</visual>
		</link>
		<link name="right_ring_limb1">
			<self_collide>false</self_collide>
			<pose frame="">-0.28953161833729324 -0.0336132176808416 -0.17103415783880593 0.0 -0.0 0.0</pose>
			<inertial>
				<pose frame="">0.0 0.0 0.0 0 0 0</pose>
				<mass>0.0038294637337122697</mass>
				<inertia>
					<ixx>0.00011732204121978117</ixx>
					<ixy>-3.728399043645363e-05</ixy>
					<ixz>-2.2255940650543876e-05</ixz>
					<iyy>0.00043394572469656283</iyy>
					<iyz>-0.00018968683916815353</iyz>
					<izz>0.00032549134472503955</izz>
				</inertia>
			</inertial>
			<collision name="right_ring_limb1_collision">
				<geometry>
					<mesh>
						<uri>model://roboy_infineon_game/meshes/CAD/right_ring_limb1.stl</uri>
						<scale>0.001 0.001 0.001</scale>
					</mesh>
				</geometry>
			</collision>
			<visual name="right_ring_limb1_visual">
				<geometry>
					<mesh>
						<uri>model://roboy_infineon_game/meshes/CAD/right_ring_limb1.stl</uri>
						<scale>0.001 0.001 0.001</scale>
					</mesh>
				</geometry>
			</visual>
		</link>
		<link name="right_ring_limb2">
			<self_collide>false</self_collide>
			<pose frame="">-0.29123020773526814 -0.04469977163559198 -0.20917271229443163 0.0 -0.0 0.0</pose>
			<inertial>
				<pose frame="">0.0 0.0 0.0 0 0 0</pose>
				<mass>0.0016247905112063861</mass>
				<inertia>
					<ixx>7.450996319439101e-05</ixx>
					<ixy>-2.1155918715524178e-05</ixy>
					<ixz>-1.5232910124406943e-05</ixz>
					<iyy>0.00020905983593805355</iyy>
					<iyz>-9.899368448248243e-05</iyz>
					<izz>0.00014108556203364106</izz>
				</inertia>
			</inertial>
			<collision name="right_ring_limb2_collision">
				<geometry>
					<mesh>
						<uri>model://roboy_infineon_game/meshes/CAD/right_ring_limb2.stl</uri>
						<scale>0.001 0.001 0.001</scale>
					</mesh>
				</geometry>
			</collision>
			<visual name="right_ring_limb2_visual">
				<geometry>
					<mesh>
						<uri>model://roboy_infineon_game/meshes/CAD/right_ring_limb2.stl</uri>
						<scale>0.001 0.001 0.001</scale>
					</mesh>
				</geometry>
			</visual>
		</link>
		<link name="right_ring_limb3">
			<self_collide>false</self_collide>
			<pose frame="">-0.2925979452514443 -0.05225882398155253 -0.23520186284201614 0.0 -0.0 0.0</pose>
			<inertial>
				<pose frame="">0.0 0.0 0.0 0 0 0</pose>
				<mass>0.0006943693287827213</mass>
				<inertia>
					<ixx>4.0337945313612636e-05</ixx>
					<ixy>-1.0618402229477374e-05</ixy>
					<ixz>-8.541310237938289e-06</ixz>
					<iyy>9.788769858731229e-05</iyy>
					<iyz>-4.778942818421739e-05</iyz>
					<izz>6.135060367845747e-05</izz>
				</inertia>
			</inertial>
			<collision name="right_ring_limb3_collision">
				<geometry>
					<mesh>
						<uri>model://roboy_infineon_game/meshes/CAD/right_ring_limb3.stl</uri>
						<scale>0.001 0.001 0.001</scale>
					</mesh>
				</geometry>
			</collision>
			<visual name="right_ring_limb3_visual">
				<geometry>
					<mesh>
						<uri>model://roboy_infineon_game/meshes/CAD/right_ring_limb3.stl</uri>
						<scale>0.001 0.001 0.001</scale>
					</mesh>
				</geometry>
			</visual>
		</link>
		<link name="right_little_limb0">
			<self_collide>false</self_collide>
			<pose frame="">-0.2857517084846127 0.02641914768435289 -0.13428354256564387 0.0 -0.0 0.0</pose>
			<inertial>
				<pose frame="">0.0 0.0 0.0 0 0 0</pose>
				<mass>0.0004269761331021115</mass>
				<inertia>
					<ixx>8.005226502427981e-06</ixx>
					<ixy>3.2234397919500516e-06</ixy>
					<ixz>1.5138317838690567e-06</ixz>
					<iyy>4.256929142722267e-05</iyy>
					<iyz>-1.638417456653172e-05</iyz>
					<izz>3.5169267424042466e-05</izz>
				</inertia>
			</inertial>
			<collision name="right_little_limb0_collision">
				<geometry>
					<mesh>
						<uri>model://roboy_infineon_game/meshes/CAD/right_little_limb0.stl</uri>
						<scale>0.001 0.001 0.001</scale>
					</mesh>
				</geometry>
			</collision>
			<visual name="right_little_limb0_visual">
				<geometry>
					<mesh>
						<uri>model://roboy_infineon_game/meshes/CAD/right_little_limb0.stl</uri>
						<scale>0.001 0.001 0.001</scale>
					</mesh>
				</geometry>
			</visual>
		</link>
		<link name="right_little_limb1">
			<self_collide>false</self_collide>
			<pose frame="">-0.286438789006176 0.03830880263145893 -0.15590853997157988 0.0 -0.0 0.0</pose>
			<inertial>
				<pose frame="">0.0 0.0 0.0 0 0 0</pose>
				<mass>0.0038294645545937137</mass>
				<inertia>
					<ixx>9.968039587364946e-05</ixx>
					<ixy>4.203376867826319e-05</ixy>
					<ixz>2.3252540454633822e-05</ixz>
					<iyy>0.00040804707645783033</iyy>
					<iyz>-0.00017104019585269278</iyz>
					<izz>0.00032009989656558</izz>
				</inertia>
			</inertial>
			<collision name="right_little_limb1_collision">
				<geometry>
					<mesh>
						<uri>model://roboy_infineon_game/meshes/CAD/right_little_limb1.stl</uri>
						<scale>0.001 0.001 0.001</scale>
					</mesh>
				</geometry>
			</collision>
			<visual name="right_little_limb1_visual">
				<geometry>
					<mesh>
						<uri>model://roboy_infineon_game/meshes/CAD/right_little_limb1.stl</uri>
						<scale>0.001 0.001 0.001</scale>
					</mesh>
				</geometry>
			</visual>
		</link>
		<link name="right_little_limb2">
			<self_collide>false</self_collide>
			<pose frame="">-0.2868764613580131 0.05743756144799022 -0.1907545188182187 0.0 -0.0 0.0</pose>
			<inertial>
				<pose frame="">0.0 0.0 0.0 0 0 0</pose>
				<mass>0.0016247909938853248</mass>
				<inertia>
					<ixx>6.465661566226048e-05</ixx>
					<ixy>2.677797276693304e-05</ixy>
					<ixz>1.7867793855862892e-05</ixz>
					<iyy>0.00019297782648839836</iyy>
					<iyz>-8.892339062529009e-05</iyz>
					<izz>0.00013913357757391624</izz>
				</inertia>
			</inertial>
			<collision name="right_little_limb2_collision">
				<geometry>
					<mesh>
						<uri>model://roboy_infineon_game/meshes/CAD/right_little_limb2.stl</uri>
						<scale>0.001 0.001 0.001</scale>
					</mesh>
				</geometry>
			</collision>
			<visual name="right_little_limb2_visual">
				<geometry>
					<mesh>
						<uri>model://roboy_infineon_game/meshes/CAD/right_little_limb2.stl</uri>
						<scale>0.001 0.001 0.001</scale>
					</mesh>
				</geometry>
			</visual>
		</link>
		<link name="right_little_limb3">
			<self_collide>false</self_collide>
			<pose frame="">-0.28738358365638034 0.07050234186124438 -0.21453647788450098 0.0 -0.0 0.0</pose>
			<inertial>
				<pose frame="">0.0 0.0 0.0 0 0 0</pose>
				<mass>0.0006943610312385798</mass>
				<inertia>
					<ixx>3.5439337157308614e-05</ixx>
					<ixy>1.4069849269219954e-05</ixy>
					<ixz>1.0512993600822055e-05</ixz>
					<iyy>8.932925169119139e-05</iyy>
					<iyz>-4.281256915080496e-05</iyz>
					<izz>6.080882531457406e-05</izz>
				</inertia>
			</inertial>
			<collision name="right_little_limb3_collision">
				<geometry>
					<mesh>
						<uri>model://roboy_infineon_game/meshes/CAD/right_little_limb3.stl</uri>
						<scale>0.001 0.001 0.001</scale>
					</mesh>
				</geometry>
			</collision>
			<visual name="right_little_limb3_visual">
				<geometry>
					<mesh>
						<uri>model://roboy_infineon_game/meshes/CAD/right_little_limb3.stl</uri>
						<scale>0.001 0.001 0.001</scale>
					</mesh>
				</geometry>
			</visual>
		</link>
		<link name="right_thumb_limb0">
			<self_collide>false</self_collide>
			<pose frame="">-0.26799475329483785 -0.03159960947508675 -0.09909814086467657 0.0 -0.0 0.0</pose>
			<inertial>
				<pose frame="">0.0 0.0 0.0 0 0 0</pose>
				<mass>0.0004269869930711359</mass>
				<inertia>
					<ixx>4.62522378009493e-06</ixx>
					<ixy>-3.6166496356268653e-06</ixy>
					<ixz>-1.3376776670367353e-06</ixz>
					<iyy>3.486759567301274e-05</iyy>
					<iyz>-1.1340383258843193e-05</iyz>
					<izz>3.1100305331303816e-05</izz>
				</inertia>
			</inertial>
			<collision name="right_thumb_limb0_collision">
				<geometry>
					<mesh>
						<uri>model://roboy_infineon_game/meshes/CAD/right_thumb_limb0.stl</uri>
						<scale>0.001 0.001 0.001</scale>
					</mesh>
				</geometry>
			</collision>
			<visual name="right_thumb_limb0_visual">
				<geometry>
					<mesh>
						<uri>model://roboy_infineon_game/meshes/CAD/right_thumb_limb0.stl</uri>
						<scale>0.001 0.001 0.001</scale>
					</mesh>
				</geometry>
			</visual>
		</link>
		<link name="right_thumb_limb1">
			<self_collide>false</self_collide>
			<pose frame="">-0.26560228396782704 -0.03296919535876446 -0.12360281869974803 0.0 -0.0 0.0</pose>
			<inertial>
				<pose frame="">0.0 0.0 0.0 0 0 0</pose>
				<mass>0.003829458173656318</mass>
				<inertia>
					<ixx>6.363545058017145e-05</ixx>
					<ixy>-3.3528952589441784e-05</ixy>
					<ixz>-1.5658238645710643e-05</ixz>
					<iyy>0.00032962603423865566</iyy>
					<iyz>-0.00012563820142866668</iyz>
					<izz>0.00027439344699374275</izz>
				</inertia>
			</inertial>
			<collision name="right_thumb_limb1_collision">
				<geometry>
					<mesh>
						<uri>model://roboy_infineon_game/meshes/CAD/right_thumb_limb1.stl</uri>
						<scale>0.001 0.001 0.001</scale>
					</mesh>
				</geometry>
			</collision>
			<visual name="right_thumb_limb1_visual">
				<geometry>
					<mesh>
						<uri>model://roboy_infineon_game/meshes/CAD/right_thumb_limb1.stl</uri>
						<scale>0.001 0.001 0.001</scale>
					</mesh>
				</geometry>
			</visual>
		</link>
		<link name="right_thumb_limb2">
			<self_collide>false</self_collide>
			<pose frame="">-0.2658938792571181 -0.020518014683342804 -0.1483472730218265 0.0 -0.0 0.0</pose>
			<inertial>
				<pose frame="">0.0 0.0 0.0 0 0 0</pose>
				<mass>0.0016247977614161058</mass>
				<inertia>
					<ixx>3.661038435334497e-05</ixx>
					<ixy>-8.83590957250207e-06</ixy>
					<ixz>-4.979698869532481e-06</ixz>
					<iyy>0.0001506619501847771</iyy>
					<iyz>-6.408276971986917e-05</iyz>
					<izz>0.00011572373933049977</izz>
				</inertia>
			</inertial>
			<collision name="right_thumb_limb2_collision">
				<geometry>
					<mesh>
						<uri>model://roboy_infineon_game/meshes/CAD/right_thumb_limb2.stl</uri>
						<scale>0.001 0.001 0.001</scale>
					</mesh>
				</geometry>
			</collision>
			<visual name="right_thumb_limb2_visual">
				<geometry>
					<mesh>
						<uri>model://roboy_infineon_game/meshes/CAD/right_thumb_limb2.stl</uri>
						<scale>0.001 0.001 0.001</scale>
					</mesh>
				</geometry>
			</visual>
		</link>
		<link name="right_thumb_limb3">
			<self_collide>false</self_collide>
			<pose frame="">-0.2704910223677974 -0.0010124969749080797 -0.1345981178032768 0.0 -0.0 0.0</pose>
			<inertial>
				<pose frame="">0.0 0.0 0.0 0 0 0</pose>
				<mass>0.0006943700234389779</mass>
				<inertia>
					<ixx>1.2609736256468777e-05</ixx>
					<ixy>-1.895305225498406e-07</ixy>
					<ixz>-9.9891035782412e-08</ixz>
					<iyy>6.341198063428603e-05</iyy>
					<iyz>-2.527752011664486e-05</iyz>
					<izz>5.0810600371268904e-05</izz>
				</inertia>
			</inertial>
			<collision name="right_thumb_limb3_collision">
				<geometry>
					<mesh>
						<uri>model://roboy_infineon_game/meshes/CAD/right_thumb_limb3.stl</uri>
						<scale>0.001 0.001 0.001</scale>
					</mesh>
				</geometry>
			</collision>
			<visual name="right_thumb_limb3_visual">
				<geometry>
					<mesh>
						<uri>model://roboy_infineon_game/meshes/CAD/right_thumb_limb3.stl</uri>
						<scale>0.001 0.001 0.001</scale>
					</mesh>
				</geometry>
			</visual>
		</link>
		<link name="right_index_limb0">
			<self_collide>false</self_collide>
			<pose frame="">-0.28650973723692685 0.011979767804072996 -0.14823575586037044 0.0 -0.0 0.0</pose>
			<inertial>
				<pose frame="">0.0 0.0 0.0 0 0 0</pose>
				<mass>0.00042698738441955704</mass>
				<inertia>
					<ixx>9.45176932027795e-06</ixx>
					<ixy>1.465525325567367e-06</ixy>
					<ixz>7.577540410377742e-07</ixz>
					<iyy>4.443833759650408e-05</iyy>
					<iyz>-1.8134938225725124e-05</iyz>
					<izz>3.511906337482363e-05</izz>
				</inertia>
			</inertial>
			<collision name="right_index_limb0_collision">
				<geometry>
					<mesh>
						<uri>model://roboy_infineon_game/meshes/CAD/right_index_limb0.stl</uri>
						<scale>0.001 0.001 0.001</scale>
					</mesh>
				</geometry>
			</collision>
			<visual name="right_index_limb0_visual">
				<geometry>
					<mesh>
						<uri>model://roboy_infineon_game/meshes/CAD/right_index_limb0.stl</uri>
						<scale>0.001 0.001 0.001</scale>
					</mesh>
				</geometry>
			</visual>
		</link>
		<link name="right_index_limb1">
			<self_collide>false</self_collide>
			<pose frame="">-0.2874682256397429 0.01787122945634528 -0.1721907856825165 0.0 -0.0 0.0</pose>
			<inertial>
				<pose frame="">0.0 0.0 0.0 0 0 0</pose>
				<mass>0.0038295036091319148</mass>
				<inertia>
					<ixx>0.00011574170551435824</ixx>
					<ixy>1.9682293378000257e-05</ixy>
					<ixz>1.1993241636132798e-05</ixz>
					<iyy>0.00043092947859403195</iyy>
					<iyz>-0.00018959314308408272</iyz>
					<izz>0.0003178115338879012</izz>
				</inertia>
			</inertial>
			<collision name="right_index_limb1_collision">
				<geometry>
					<mesh>
						<uri>model://roboy_infineon_game/meshes/CAD/right_index_limb1.stl</uri>
						<scale>0.001 0.001 0.001</scale>
					</mesh>
				</geometry>
			</collision>
			<visual name="right_index_limb1_visual">
				<geometry>
					<mesh>
						<uri>model://roboy_infineon_game/meshes/CAD/right_index_limb1.stl</uri>
						<scale>0.001 0.001 0.001</scale>
					</mesh>
				</geometry>
			</visual>
		</link>
		<link name="right_index_limb2">
			<self_collide>false</self_collide>
			<pose frame="">-0.28834307510807117 0.02733713247662425 -0.21079117524604526 0.0 -0.0 0.0</pose>
			<inertial>
				<pose frame="">0.0 0.0 0.0 0 0 0</pose>
				<mass>0.0016247908299257088</mass>
				<inertia>
					<ixx>7.35827430231125e-05</ixx>
					<ixy>1.2810515009102333e-05</ixy>
					<ixz>9.399005941712123e-06</ixz>
					<iyy>0.00020744834482133232</iyy>
					<iyz>-9.876778932106627e-05</iyz>
					<izz>0.00013633112644627268</izz>
				</inertia>
			</inertial>
			<collision name="right_index_limb2_collision">
				<geometry>
					<mesh>
						<uri>model://roboy_infineon_game/meshes/CAD/right_index_limb2.stl</uri>
						<scale>0.001 0.001 0.001</scale>
					</mesh>
				</geometry>
			</collision>
			<visual name="right_index_limb2_visual">
				<geometry>
					<mesh>
						<uri>model://roboy_infineon_game/meshes/CAD/right_index_limb2.stl</uri>
						<scale>0.001 0.001 0.001</scale>
					</mesh>
				</geometry>
			</visual>
		</link>
		<link name="right_index_limb3">
			<self_collide>false</self_collide>
			<pose frame="">-0.2891485924741874 0.03380635148686757 -0.2371355712169334 0.0 -0.0 0.0</pose>
			<inertial>
				<pose frame="">0.0 0.0 0.0 0 0 0</pose>
				<mass>0.0006943611681336561</mass>
				<inertia>
					<ixx>3.986907827098813e-05</ixx>
					<ixy>6.788112545400644e-06</ixy>
					<ixz>5.572310653857104e-06</ixz>
					<iyy>9.712784154365344e-05</iyy>
					<iyz>-4.7613312155997766e-05</iyz>
					<izz>5.8853260572159194e-05</izz>
				</inertia>
			</inertial>
			<collision name="right_index_limb3_collision">
				<geometry>
					<mesh>
						<uri>model://roboy_infineon_game/meshes/CAD/right_index_limb3.stl</uri>
						<scale>0.001 0.001 0.001</scale>
					</mesh>
				</geometry>
			</collision>
			<visual name="right_index_limb3_visual">
				<geometry>
					<mesh>
						<uri>model://roboy_infineon_game/meshes/CAD/right_index_limb3.stl</uri>
						<scale>0.001 0.001 0.001</scale>
					</mesh>
				</geometry>
			</visual>
		</link>
		<link name="right_middle_limb0">
			<self_collide>false</self_collide>
			<pose frame="">-0.28735582005810617 -0.007498164543992087 -0.15301574447218877 0.0 -0.0 0.0</pose>
			<inertial>
				<pose frame="">0.0 0.0 0.0 0 0 0</pose>
				<mass>0.0004269918296598001</mass>
				<inertia>
					<ixx>1.0029446726150395e-05</ixx>
					<ixy>-9.201328705192526e-07</ixy>
					<ixz>-4.898390927169781e-07</ixz>
					<iyy>4.5260861939898244e-05</iyy>
					<iyz>-1.8775163119391247e-05</iyz>
					<izz>3.5289601730655314e-05</izz>
				</inertia>
			</inertial>
			<collision name="right_middle_limb0_collision">
				<geometry>
					<mesh>
						<uri>model://roboy_infineon_game/meshes/CAD/right_middle_limb0.stl</uri>
						<scale>0.001 0.001 0.001</scale>
					</mesh>
				</geometry>
			</collision>
			<visual name="right_middle_limb0_visual">
				<geometry>
					<mesh>
						<uri>model://roboy_infineon_game/meshes/CAD/right_middle_limb0.stl</uri>
						<scale>0.001 0.001 0.001</scale>
					</mesh>
				</geometry>
			</visual>
		</link>
		<link name="right_middle_limb1">
			<self_collide>false</self_collide>
			<pose frame="">-0.28858135675877367 -0.00800375693807138 -0.17766785876596106 0.0 -0.0 0.0</pose>
			<inertial>
				<pose frame="">0.0 0.0 0.0 0 0 0</pose>
				<mass>0.0038294512883095943</mass>
				<inertia>
					<ixx>0.0001220995002252948</ixx>
					<ixy>-8.84602084566386e-06</ixy>
					<ixz>-5.463878879035804e-06</ixz>
					<iyy>0.0004407681185915827</iyy>
					<iyz>-0.0001963880630114403</iyz>
					<izz>0.0003192348454917731</izz>
				</inertia>
			</inertial>
			<collision name="right_middle_limb1_collision">
				<geometry>
					<mesh>
						<uri>model://roboy_infineon_game/meshes/CAD/right_middle_limb1.stl</uri>
						<scale>0.001 0.001 0.001</scale>
					</mesh>
				</geometry>
			</collision>
			<visual name="right_middle_limb1_visual">
				<geometry>
					<mesh>
						<uri>model://roboy_infineon_game/meshes/CAD/right_middle_limb1.stl</uri>
						<scale>0.001 0.001 0.001</scale>
					</mesh>
				</geometry>
			</visual>
		</link>
		<link name="right_middle_limb2">
			<self_collide>false</self_collide>
			<pose frame="">-0.289886319824799 -0.008843936220138444 -0.21739145311344996 0.0 -0.0 0.0</pose>
			<inertial>
				<pose frame="">0.0 0.0 0.0 0 0 0</pose>
				<mass>0.00162475332634857</mass>
				<inertia>
					<ixx>7.708536294896418e-05</ixx>
					<ixy>-4.165721795611402e-06</ixy>
					<ixz>-3.126632561339439e-06</ixz>
					<iyy>0.0002134940935107954</iyy>
					<iyz>-0.00010240478305222905</iyz>
					<izz>0.0001366820596855284</izz>
				</inertia>
			</inertial>
			<collision name="right_middle_limb2_collision">
				<geometry>
					<mesh>
						<uri>model://roboy_infineon_game/meshes/CAD/right_middle_limb2.stl</uri>
						<scale>0.001 0.001 0.001</scale>
					</mesh>
				</geometry>
			</collision>
			<visual name="right_middle_limb2_visual">
				<geometry>
					<mesh>
						<uri>model://roboy_infineon_game/meshes/CAD/right_middle_limb2.stl</uri>
						<scale>0.001 0.001 0.001</scale>
					</mesh>
				</geometry>
			</visual>
		</link>
		<link name="right_middle_limb3">
			<self_collide>false</self_collide>
			<pose frame="">-0.2909853311911106 -0.009408983186911078 -0.24450194210727091 0.0 -0.0 0.0</pose>
			<inertial>
				<pose frame="">0.0 0.0 0.0 0 0 0</pose>
				<mass>0.000694374972226315</mass>
				<inertia>
					<ixx>4.160128555471066e-05</ixx>
					<ixy>-1.9011642771947149e-06</ixy>
					<ixz>-1.5978520866732432e-06</ixz>
					<iyy>0.00010033470064135955</iyy>
					<iyz>-4.9405443710589625e-05</iyz>
					<izz>5.886083487126691e-05</izz>
				</inertia>
			</inertial>
			<collision name="right_middle_limb3_collision">
				<geometry>
					<mesh>
						<uri>model://roboy_infineon_game/meshes/CAD/right_middle_limb3.stl</uri>
						<scale>0.001 0.001 0.001</scale>
					</mesh>
				</geometry>
			</collision>
			<visual name="right_middle_limb3_visual">
				<geometry>
					<mesh>
						<uri>model://roboy_infineon_game/meshes/CAD/right_middle_limb3.stl</uri>
						<scale>0.001 0.001 0.001</scale>
					</mesh>
				</geometry>
			</visual>
		</link>
		<link name="right_palm">
			<self_collide>false</self_collide>
			<pose frame="">-0.2847750732470909 -0.005126146472413973 -0.10272322116060892 0.0 -0.0 0.0</pose>
			<inertial>
				<pose frame="">0.0 0.0 0.0 0 0 0</pose>
				<mass>0.051043858395731695</mass>
				<inertia>
					<ixx>0.0005967987886009216</ixx>
					<ixy>-7.481603074127008e-05</ixy>
					<ixz>-2.4476678546845737e-05</ixz>
					<iyy>0.004717995512074524</iyy>
					<iyz>-0.0014947026086855695</iyz>
					<izz>0.00416268235589044</izz>
				</inertia>
			</inertial>
			<collision name="right_palm_collision">
				<geometry>
					<mesh>
						<uri>model://roboy_infineon_game/meshes/CAD/right_palm.stl</uri>
						<scale>0.001 0.001 0.001</scale>
					</mesh>
				</geometry>
			</collision>
			<visual name="right_palm_visual">
				<geometry>
					<mesh>
						<uri>model://roboy_infineon_game/meshes/CAD/right_palm.stl</uri>
						<scale>0.001 0.001 0.001</scale>
					</mesh>
				</geometry>
			</visual>
		</link>
		<link name="wrist_right_1">
			<self_collide>false</self_collide>
			<pose frame="">-0.2866867429541464 -0.004438948463968548 -0.04906136020057027 0.0 -0.0 0.0</pose>
			<inertial>
				<pose frame="">0.0 0.0 0.0 0 0 0</pose>
				<mass>0.012762562533547066</mass>
				<inertia>
					<ixx>3.3598610122705056e-05</ixx>
					<ixy>-1.6203943852234875e-05</ixy>
					<ixz>-2.737975008929542e-06</ixz>
					<iyy>0.0010832094855845558</iyy>
					<iyz>-0.0001794781509676559</iyz>
					<izz>0.0010546398114598741</izz>
				</inertia>
			</inertial>
			<collision name="wrist_right_1_collision">
				<geometry>
					<mesh>
						<uri>model://roboy_infineon_game/meshes/CAD/wrist_right_1.stl</uri>
						<scale>0.001 0.001 0.001</scale>
					</mesh>
				</geometry>
			</collision>
			<visual name="wrist_right_1_visual">
				<geometry>
					<mesh>
						<uri>model://roboy_infineon_game/meshes/CAD/wrist_right_1.stl</uri>
						<scale>0.001 0.001 0.001</scale>
					</mesh>
				</geometry>
			</visual>
		</link>
		<link name="upper_arm_left">
			<self_collide>false</self_collide>
			<pose frame="">0.3031614980118546 0.006609929036444388 0.39707393398958857 0.0 -0.0 0.0</pose>
			<inertial>
				<pose frame="">0.0 0.0 0.0 0 0 0</pose>
				<mass>1.1809063299087657</mass>
				<inertia>
					<ixx>0.19249766652753011</ixx>
					<ixy>-0.002306536219501519</ixy>
					<ixz>-0.00308957055005115</ixz>
					<iyy>0.29973060108842253</iyy>
					<iyz>-0.14192192697254485</iyz>
					<izz>0.1110008660147678</izz>
				</inertia>
			</inertial>
			<collision name="upper_arm_left_collision">
				<geometry>
					<mesh>
						<uri>model://roboy_infineon_game/meshes/CAD/upper_arm_left.stl</uri>
						<scale>0.001 0.001 0.001</scale>
					</mesh>
				</geometry>
			</collision>
			<visual name="upper_arm_left_visual">
				<geometry>
					<mesh>
						<uri>model://roboy_infineon_game/meshes/CAD/upper_arm_left.stl</uri>
						<scale>0.001 0.001 0.001</scale>
					</mesh>
				</geometry>
			</visual>
		</link>
		<link name="lower_arm_left">
			<self_collide>false</self_collide>
			<pose frame="">0.28675767529886037 -0.001202415048591372 0.09482767053657241 0.0 -0.0 0.0</pose>
			<inertial>
				<pose frame="">0.0 0.0 0.0 0 0 0</pose>
				<mass>1.4159186820881697</mass>
				<inertia>
					<ixx>0.01972434282329412</ixx>
					<ixy>0.0004868562622172685</ixy>
					<ixz>3.1776791738782414e-05</ixz>
					<iyy>0.136151454541662</iyy>
					<iyz>-0.03856056416354946</iyz>
					<izz>0.11772500908251425</izz>
				</inertia>
			</inertial>
			<collision name="lower_arm_left_collision">
				<geometry>
					<mesh>
						<uri>model://roboy_infineon_game/meshes/CAD/lower_arm_left.stl</uri>
						<scale>0.001 0.001 0.001</scale>
					</mesh>
				</geometry>
			</collision>
			<visual name="lower_arm_left_visual">
				<geometry>
					<mesh>
						<uri>model://roboy_infineon_game/meshes/CAD/lower_arm_left.stl</uri>
						<scale>0.001 0.001 0.001</scale>
					</mesh>
				</geometry>
			</visual>
		</link>
		<link name="lower_arm_right">
			<self_collide>false</self_collide>
			<pose frame="">-0.2869031619781162 -0.0012965388826141296 0.09028067021725633 0.0 -0.0 0.0</pose>
			<inertial>
				<pose frame="">0.0 0.0 0.0 0 0 0</pose>
				<mass>1.3992272098398935</mass>
				<inertia>
					<ixx>0.01810948009587912</ixx>
					<ixy>-0.0005189063901736044</ixy>
					<ixz>3.997741962255835e-05</ixz>
					<iyy>0.13328089869101623</iyy>
					<iyz>0.036310470825779366</iyz>
					<izz>0.1164677650951653</izz>
				</inertia>
			</inertial>
			<collision name="lower_arm_right_collision">
				<geometry>
					<mesh>
						<uri>model://roboy_infineon_game/meshes/CAD/lower_arm_right.stl</uri>
						<scale>0.001 0.001 0.001</scale>
					</mesh>
				</geometry>
			</collision>
			<visual name="lower_arm_right_visual">
				<geometry>
					<mesh>
						<uri>model://roboy_infineon_game/meshes/CAD/lower_arm_right.stl</uri>
						<scale>0.001 0.001 0.001</scale>
					</mesh>
				</geometry>
			</visual>
		</link>
		<link name="upper_arm_right">
			<self_collide>false</self_collide>
			<pose frame="">-0.3025447305327433 0.004242982300476203 0.3976314908587195 0.0 -0.0 0.0</pose>
			<inertial>
				<pose frame="">0.0 0.0 0.0 0 0 0</pose>
				<mass>1.0958327493576236</mass>
				<inertia>
					<ixx>0.17904121063195466</ixx>
					<ixy>0.0013740892922223082</ixy>
					<ixz>-0.0018804876410868322</ixz>
					<iyy>0.27814383199006454</iyy>
					<iyz>0.1316285036742264</iyz>
					<izz>0.10257941706215243</izz>
				</inertia>
			</inertial>
			<collision name="upper_arm_right_collision">
				<geometry>
					<mesh>
						<uri>model://roboy_infineon_game/meshes/CAD/upper_arm_right.stl</uri>
						<scale>0.001 0.001 0.001</scale>
					</mesh>
				</geometry>
			</collision>
			<visual name="upper_arm_right_visual">
				<geometry>
					<mesh>
						<uri>model://roboy_infineon_game/meshes/CAD/upper_arm_right.stl</uri>
						<scale>0.001 0.001 0.001</scale>
					</mesh>
				</geometry>
			</visual>
		</link>
		<link name="zed_camera_left_lense">
			<self_collide>false</self_collide>
			<pose frame="">0.05999964724565572 -0.08173913560527492 0.9528625747224352 0.0 -0.0 0.0</pose>
			<inertial>
				<pose frame="">0.0 0.0 0.0 0 0 0</pose>
				<mass>0.005755421855273298</mass>
				<inertia>
					<ixx>0.005224792510686209</ixx>
					<ixy>2.3943361940981148e-05</ixy>
					<ixz>0.0003792235752580479</ixz>
					<iyy>0.005217664057780662</iyy>
					<iyz>-0.00032814642300882987</iyz>
					<izz>4.878008912156887e-05</izz>
				</inertia>
			</inertial>
			<collision name="zed_camera_left_lense_collision">
				<geometry>
					<mesh>
						<uri>model://roboy_infineon_game/meshes/CAD/zed_camera_left_lense.stl</uri>
						<scale>0.001 0.001 0.001</scale>
					</mesh>
				</geometry>
			</collision>
			<visual name="zed_camera_left_lense_visual">
				<geometry>
					<mesh>
						<uri>model://roboy_infineon_game/meshes/CAD/zed_camera_left_lense.stl</uri>
						<scale>0.001 0.001 0.001</scale>
					</mesh>
				</geometry>
			</visual>
		</link>
		<link name="zed_camera_right_lense">
			<self_collide>false</self_collide>
			<pose frame="">-0.06000035275434433 -0.08173913560527538 0.9528625747224347 0.0 -0.0 0.0</pose>
			<inertial>
				<pose frame="">0.0 0.0 0.0 0 0 0</pose>
				<mass>0.005755421855273129</mass>
				<inertia>
					<ixx>0.00522479251052088</ixx>
					<ixy>-2.3942806253133926e-05</ixy>
					<ixz>0.0003792235752696656</ixz>
					<iyy>0.005217663109890817</iyy>
					<iyz>0.00032813891497161525</iyz>
					<izz>4.8779141402285844e-05</izz>
				</inertia>
			</inertial>
			<collision name="zed_camera_right_lense_collision">
				<geometry>
					<mesh>
						<uri>model://roboy_infineon_game/meshes/CAD/zed_camera_right_lense.stl</uri>
						<scale>0.001 0.001 0.001</scale>
					</mesh>
				</geometry>
			</collision>
			<visual name="zed_camera_right_lense_visual">
				<geometry>
					<mesh>
						<uri>model://roboy_infineon_game/meshes/CAD/zed_camera_right_lense.stl</uri>
						<scale>0.001 0.001 0.001</scale>
					</mesh>
				</geometry>
			</visual>
		</link>
		<link name="zed_camera">
			<self_collide>false</self_collide>
			<pose frame="">-3.51796944748628e-07 -0.05630729805909612 0.9474568704182059 0.0 -0.0 0.0</pose>
			<inertial>
				<pose frame="">0.0 0.0 0.0 0 0 0</pose>
				<mass>0.009633907989064926</mass>
				<inertia>
					<ixx>0.008684211865767441</ixx>
					<ixy>2.378834282957646e-06</ixy>
					<ixz>0.0005290164856765297</ixz>
					<iyy>0.008666687394562656</iyy>
					<iyz>-3.706378187021515e-05</iyz>
					<izz>4.725222619253178e-05</izz>
				</inertia>
			</inertial>
			<collision name="zed_camera_collision">
				<geometry>
					<mesh>
						<uri>model://roboy_infineon_game/meshes/CAD/zed_camera.stl</uri>
						<scale>0.001 0.001 0.001</scale>
					</mesh>
				</geometry>
			</collision>
			<visual name="zed_camera_visual">
				<geometry>
					<mesh>
						<uri>model://roboy_infineon_game/meshes/CAD/zed_camera.stl</uri>
						<scale>0.001 0.001 0.001</scale>
					</mesh>
				</geometry>
			</visual>
		</link>
		<link name="sphere_head_link1">
			<self_collide>false</self_collide>
			<pose frame="">-4.421395705191362e-16 0.001522343501028229 0.7322504206362658 0.0 -0.0 0.0</pose>
			<inertial>
				<pose frame="">0.0 0.0 0.0 0 0 0</pose>
				<mass>0.02393810080236978</mass>
				<inertia>
					<ixx>0.012837399546969178</ixx>
					<ixy>1.6371452804531116e-20</ixy>
					<ixz>-2.6684678750160264e-05</ixz>
					<iyy>0.012837344069708764</iyy>
					<iyz>7.817357872141884e-18</iyz>
					<izz>2.0130352188598093e-06</izz>
				</inertia>
			</inertial>
			<collision name="sphere_head_link1_collision">
				<geometry>
					<mesh>
						<uri>model://roboy_infineon_game/meshes/CAD/sphere_head_link1.stl</uri>
						<scale>0.001 0.001 0.001</scale>
					</mesh>
				</geometry>
			</collision>
			<visual name="sphere_head_link1_visual">
				<geometry>
					<mesh>
						<uri>model://roboy_infineon_game/meshes/CAD/sphere_head_link1.stl</uri>
						<scale>0.001 0.001 0.001</scale>
					</mesh>
				</geometry>
			</visual>
		</link>
		<link name="shere_head_link2">
			<self_collide>false</self_collide>
			<pose frame="">-4.547233432837245e-16 0.0015223435010281892 0.7322504206362658 0.0 -0.0 0.0</pose>
			<inertial>
				<pose frame="">0.0 0.0 0.0 0 0 0</pose>
				<mass>0.01604641751649573</mass>
				<inertia>
					<ixx>0.00860486097319985</ixx>
					<ixy>1.1080546202801855e-20</ixy>
					<ixz>-1.7887530011413227e-05</ixz>
					<iyy>0.008604823785150114</iyy>
					<iyz>5.230538224765269e-18</iyz>
					<izz>9.21477182908014e-07</izz>
				</inertia>
			</inertial>
			<collision name="shere_head_link2_collision">
				<geometry>
					<mesh>
						<uri>model://roboy_infineon_game/meshes/CAD/shere_head_link2.stl</uri>
						<scale>0.001 0.001 0.001</scale>
					</mesh>
				</geometry>
			</collision>
			<visual name="shere_head_link2_visual">
				<geometry>
					<mesh>
						<uri>model://roboy_infineon_game/meshes/CAD/shere_head_link2.stl</uri>
						<scale>0.001 0.001 0.001</scale>
					</mesh>
				</geometry>
			</visual>
		</link>
		<link name="head">
			<self_collide>false</self_collide>
			<pose frame="">0.0006470497602335966 0.04601890562464172 0.8803170317244866 0.0 -0.0 0.0</pose>
			<inertial>
				<pose frame="">0.0 0.0 0.0 0 0 0</pose>
				<mass>2.0690288729005957</mass>
				<inertia>
					<ixx>1.6405545784076312</ixx>
					<ixy>-9.6882839740856e-05</ixy>
					<ixz>-0.08661510611492024</ixz>
					<iyy>1.629789251542146</iyy>
					<iyz>-0.0013000314402526782</iyz>
					<izz>0.030622929355755123</izz>
				</inertia>
			</inertial>
			<collision name="head_collision">
				<geometry>
					<mesh>
						<uri>model://roboy_infineon_game/meshes/CAD/head.stl</uri>
						<scale>0.001 0.001 0.001</scale>
					</mesh>
				</geometry>
			</collision>
			<visual name="head_visual">
				<geometry>
					<mesh>
						<uri>model://roboy_infineon_game/meshes/CAD/head.stl</uri>
						<scale>0.001 0.001 0.001</scale>
					</mesh>
				</geometry>
			</visual>
		</link>
		<joint name="elbow_right_rot1" type="revolute">
			<parent>elbow_right</parent>
			<child>lower_arm_right</child>
			<pose frame="">-0.0014317049176436924 0.0028331904169266796 0.12369312705704288 0 0 0</pose>
			<axis>
				<xyz>-0.011188426489532841 0.02290925222533375 0.999674939805517</xyz>
				<limit>
					<lower>-1.5707963267948966</lower>
					<upper>1.5707963267948966</upper>
				</limit>
				<use_parent_model_frame>0</use_parent_model_frame>
			</axis>
		</joint>
		<joint name="hip_joint" type="revolute">
			<parent>base</parent>
			<child>torso</child>
			<pose frame="">5.5511151231258616e-18 0.0015223435010247668 0.29933579273187944 0 0 0</pose>
			<axis>
				<xyz>7.618466126492377e-15 7.291449532173658e-15 0.9999999999999987</xyz>
				<limit>
					<lower>-1.0471975511965976</lower>
					<upper>1.0471975511965976</upper>
				</limit>
				<use_parent_model_frame>0</use_parent_model_frame>
			</axis>
		</joint>
		<joint name="sphere_left_axis0" type="revolute">
			<parent>torso</parent>
			<child>sphere_left_link1</child>
			<pose frame="">3.92834461848679e-09 -1.6697847606161888e-07 -3.766154499373897e-08 0 0 0</pose>
			<axis>
				<xyz>0.9986354432836129 0.0507442963281684 -0.012339684270769946</xyz>
				<limit>
					<lower>-3.141592653589793</lower>
					<upper>3.141592653589793</upper>
				</limit>
				<use_parent_model_frame>0</use_parent_model_frame>
			</axis>
		</joint>
		<joint name="sphere_left_axis1" type="revolute">
			<parent>sphere_left_link1</parent>
			<child>sphere_left_link2</child>
			<pose frame="">-9.872906829855311e-09 1.3921429488861215e-07 -2.5913787453646363e-08 0 0 0</pose>
			<axis>
				<xyz>-0.05101049431667498 0.9984488883025682 -0.022310242422111</xyz>
				<limit>
					<lower>-3.141592653589793</lower>
					<upper>3.141592653589793</upper>
				</limit>
				<use_parent_model_frame>0</use_parent_model_frame>
			</axis>
		</joint>
		<joint name="sphere_left_axis2" type="revolute">
			<parent>sphere_left_link2</parent>
			<child>upper_arm_left</child>
			<pose frame="">-0.010981441799160089 0.002600669110199173 0.1515398154161143 0 0 0</pose>
			<axis>
				<xyz>-0.011188426489534178 -0.022909252225333673 -0.9996749398055222</xyz>
				<limit>
					<lower>-3.141592653589793</lower>
					<upper>3.141592653589793</upper>
				</limit>
				<use_parent_model_frame>0</use_parent_model_frame>
			</axis>
		</joint>
		<joint name="elbow_left_rot1" type="revolute">
			<parent>elbow_left</parent>
			<child>lower_arm_left</child>
			<pose frame="">0.0015883800233880408 0.0027619758351275737 0.12014580167753089 0 0 0</pose>
			<axis>
				<xyz>-0.011188426489533953 -0.02290925222533381 -0.9996749398055156</xyz>
				<limit>
					<lower>-1.5707963267948966</lower>
					<upper>1.5707963267948966</upper>
				</limit>
				<use_parent_model_frame>0</use_parent_model_frame>
			</axis>
		</joint>
		<joint name="elbow_left_rot0" type="revolute">
			<parent>upper_arm_left</parent>
			<child>elbow_left</child>
			<pose frame="">0.014657053051454198 -0.0036865574491576703 0.037410123739794056 0 0 0</pose>
			<axis>
				<xyz>-0.9986354432836098 -0.05074429632816584 0.01233968427076895</xyz>
				<limit>
					<lower>0.0</lower>
					<upper>1.5707963267948966</upper>
				</limit>
				<use_parent_model_frame>0</use_parent_model_frame>
			</axis>
		</joint>
		<joint name="left_palm_ring" type="revolute">
			<parent>palm</parent>
			<child>left_ring_limb0</child>
			<pose frame="">0.00047947296305451915 -0.0071028275077075174 -0.002469700387219991 0 0 0</pose>
			<axis>
				<xyz>0.050604388836559724 -0.9701521422675976 -0.2371582102396819</xyz>
				<limit>
					<lower>-1.2217304763960306</lower>
					<upper>0.3490658503988659</upper>
				</limit>
				<use_parent_model_frame>0</use_parent_model_frame>
			</axis>
		</joint>
		<joint name="left_palm_index" type="revolute">
			<parent>palm</parent>
			<child>left_index_limb0</child>
			<pose frame="">0.0006414784881238944 -0.007372597735733848 0.0014172925078354659 0 0 0</pose>
			<axis>
				<xyz>0.06912902351813048 -0.9575096097515242 0.27999379518292145</xyz>
				<limit>
					<lower>-1.2217304763960306</lower>
					<upper>0.3490658503988659</upper>
				</limit>
				<use_parent_model_frame>0</use_parent_model_frame>
			</axis>
		</joint>
		<joint name="left_palm_thumb" type="revolute">
			<parent>palm</parent>
			<child>left_thumb_limb0</child>
			<pose frame="">-0.006829099149611544 0.002329204369364022 0.0021701069823619433 0 0 0</pose>
			<axis>
				<xyz>-0.873064821657724 0.30848418159828894 0.3776179642011197</xyz>
				<limit>
					<lower>-1.2217304763960306</lower>
					<upper>0.8726646259971648</upper>
				</limit>
				<use_parent_model_frame>0</use_parent_model_frame>
			</axis>
		</joint>
		<joint name="left_palm_little" type="revolute">
			<parent>palm</parent>
			<child>left_little_limb0</child>
			<pose frame="">0.0004220016841042451 -0.006230811664412714 -0.004216383465517115 0 0 0</pose>
			<axis>
				<xyz>-0.03578159729659995 0.8763588714153954 0.48032781075683695</xyz>
				<limit>
					<lower>0.0</lower>
					<upper>0.0</upper>
				</limit>
				<use_parent_model_frame>0</use_parent_model_frame>
			</axis>
		</joint>
		<joint name="left_palm_middle" type="revolute">
			<parent>palm</parent>
			<child>left_middle_limb0</child>
			<pose frame="">-0.00019935548262122184 0.004979448644513177 -0.0008217277835981563 0 0 0</pose>
			<axis>
				<xyz>0.06197857490501392 -0.9978311478764826 0.022173330382834325</xyz>
				<limit>
					<lower>-1.2217304763960306</lower>
					<upper>0.3490658503988659</upper>
				</limit>
				<use_parent_model_frame>0</use_parent_model_frame>
			</axis>
		</joint>
		<joint name="left_wrist_0" type="revolute">
			<parent>lower_arm_left</parent>
			<child>wrist_left_1</child>
			<pose frame="">-0.009900625387204905 -0.0006389576348573278 -0.0010673226779252954 0 0 0</pose>
			<axis>
				<xyz>-0.9974356911086111 -0.06112686075287353 0.03722296330474326</xyz>
				<limit>
					<lower>-0.5235987755982988</lower>
					<upper>0.5235987755982988</upper>
				</limit>
				<use_parent_model_frame>0</use_parent_model_frame>
			</axis>
		</joint>
		<joint name="left_wrist_1" type="revolute">
			<parent>wrist_left_1</parent>
			<child>palm</child>
			<pose frame="">0.0050051137730206105 -0.017159923719313328 0.052485576039957835 0 0 0</pose>
			<axis>
				<xyz>-0.061978574905012226 0.9978311478764739 -0.022173330382831865</xyz>
				<limit>
					<lower>-0.5235987755982988</lower>
					<upper>0.5235987755982988</upper>
				</limit>
				<use_parent_model_frame>0</use_parent_model_frame>
			</axis>
		</joint>
		<joint name="left_joint0_ring" type="revolute">
			<parent>left_ring_limb0</parent>
			<child>left_ring_limb1</child>
			<pose frame="">0.003123608865376859 -0.005863510177838169 0.02465252334877098 0 0 0</pose>
			<axis>
				<xyz>0.8891089843840378 -0.06439579474630672 0.45314279814049113</xyz>
				<limit>
					<lower>-0.3141592653589793</lower>
					<upper>0.3141592653589793</upper>
				</limit>
				<use_parent_model_frame>0</use_parent_model_frame>
			</axis>
		</joint>
		<joint name="left_joint1_ring" type="revolute">
			<parent>left_ring_limb1</parent>
			<child>left_ring_limb2</child>
			<pose frame="">-0.0006773791841910892 -0.008387065996035573 0.01097353028800626 0 0 0</pose>
			<axis>
				<xyz>-0.05060438883655716 0.970152142267596 0.2371582102396832</xyz>
				<limit>
					<lower>0.0</lower>
					<upper>1.9198621771937625</upper>
				</limit>
				<use_parent_model_frame>0</use_parent_model_frame>
			</axis>
		</joint>
		<joint name="left_joint2_ring" type="revolute">
			<parent>left_ring_limb2</parent>
			<child>left_ring_limb3</child>
			<pose frame="">-0.00022403313413484229 -0.00580063120702476 0.006814800099545515 0 0 0</pose>
			<axis>
				<xyz>-0.05060438883655716 0.970152142267596 0.2371582102396832</xyz>
				<limit>
					<lower>0.0</lower>
					<upper>1.2217304763960306</upper>
				</limit>
				<use_parent_model_frame>0</use_parent_model_frame>
			</axis>
		</joint>
		<joint name="left_joint0_little" type="revolute">
			<parent>left_little_limb0</parent>
			<child>left_little_limb1</child>
			<pose frame="">0.001196360870214299 -0.012220609354407377 0.022385602543725406 0 0 0</pose>
			<axis>
				<xyz>0.8526026737150941 -0.2239620970573153 0.4721330954885197</xyz>
				<limit>
					<lower>-0.3141592653589793</lower>
					<upper>0.3141592653589793</upper>
				</limit>
				<use_parent_model_frame>0</use_parent_model_frame>
			</axis>
		</joint>
		<joint name="left_joint1_little" type="revolute">
			<parent>left_little_limb1</parent>
			<child>left_little_limb2</child>
			<pose frame="">-0.0017154642844630175 -0.01090827709870335 0.008323874779935387 0 0 0</pose>
			<axis>
				<xyz>-0.03578159729659464 0.8763588714153906 0.48032781075682773</xyz>
				<limit>
					<lower>0.0</lower>
					<upper>1.9198621771937625</upper>
				</limit>
				<use_parent_model_frame>0</use_parent_model_frame>
			</axis>
		</joint>
		<joint name="left_joint2_little" type="revolute">
			<parent>left_little_limb2</parent>
			<child>left_little_limb3</child>
			<pose frame="">-0.0008883950117415651 -0.0073549608186726624 0.0050253626084123225 0 0 0</pose>
			<axis>
				<xyz>-0.03578159729659464 0.8763588714153906 0.48032781075682773</xyz>
				<limit>
					<lower>0.0</lower>
					<upper>1.2217304763960306</upper>
				</limit>
				<use_parent_model_frame>0</use_parent_model_frame>
			</axis>
		</joint>
		<joint name="left_joint0_thumb" type="revolute">
			<parent>left_thumb_limb0</parent>
			<child>left_thumb_limb1</child>
			<pose frame="">0.007685901851841663 -0.006847645364755888 0.023364209131367258 0 0 0</pose>
			<axis>
				<xyz>-0.148594441795708 -0.905923346896432 0.3965130280525724</xyz>
				<limit>
					<lower>-0.3141592653589793</lower>
					<upper>0.3141592653589793</upper>
				</limit>
				<use_parent_model_frame>0</use_parent_model_frame>
			</axis>
		</joint>
		<joint name="left_joint1_thumb" type="revolute">
			<parent>left_thumb_limb1</parent>
			<child>left_thumb_limb2</child>
			<pose frame="">-0.010186635004473565 -0.009239552623159467 -0.0014391827417710346 0 0 0</pose>
			<axis>
				<xyz>0.8730648216577273 -0.3084841815982943 -0.37761796420111854</xyz>
				<limit>
					<lower>0.0</lower>
					<upper>1.9198621771937625</upper>
				</limit>
				<use_parent_model_frame>0</use_parent_model_frame>
			</axis>
		</joint>
		<joint name="left_joint2_thumb" type="revolute">
			<parent>left_thumb_limb2</parent>
			<child>left_thumb_limb3</child>
			<pose frame="">-0.006404199700305924 0.002067842513242528 -0.00590334178719635 0 0 0</pose>
			<axis>
				<xyz>0.8730648216577293 -0.3084841815982934 -0.37761796420111976</xyz>
				<limit>
					<lower>0.0</lower>
					<upper>1.2217304763960306</upper>
				</limit>
				<use_parent_model_frame>0</use_parent_model_frame>
			</axis>
		</joint>
		<joint name="left_joint0_index" type="revolute">
			<parent>left_index_limb0</parent>
			<child>left_index_limb1</child>
			<pose frame="">0.0023065390758301874 0.0072899734837700075 0.024360453637531327 0 0 0</pose>
			<axis>
				<xyz>0.8730677488103025 0.1938619101206322 0.44740391794406403</xyz>
				<limit>
					<lower>-0.3141592653589793</lower>
					<upper>0.3141592653589793</upper>
				</limit>
				<use_parent_model_frame>0</use_parent_model_frame>
			</axis>
		</joint>
		<joint name="left_joint1_index" type="revolute">
			<parent>left_index_limb1</parent>
			<child>left_index_limb2</child>
			<pose frame="">-0.000979299172113066 -0.0018164023172026855 0.013673398294191763 0 0 0</pose>
			<axis>
				<xyz>-0.06912902351812825 0.9575096097515153 -0.27999379518291617</xyz>
				<limit>
					<lower>0.0</lower>
					<upper>1.9198621771937625</upper>
				</limit>
				<use_parent_model_frame>0</use_parent_model_frame>
			</axis>
		</joint>
		<joint name="left_joint2_index" type="revolute">
			<parent>left_index_limb2</parent>
			<child>left_index_limb3</child>
			<pose frame="">-0.0004054797710447744 -0.001635813198442051 0.008791965705564984 0 0 0</pose>
			<axis>
				<xyz>-0.06912902351812825 0.9575096097515153 -0.27999379518291617</xyz>
				<limit>
					<lower>0.0</lower>
					<upper>1.2217304763960306</upper>
				</limit>
				<use_parent_model_frame>0</use_parent_model_frame>
			</axis>
		</joint>
		<joint name="left_joint0_middle" type="revolute">
			<parent>left_middle_limb0</parent>
			<child>left_middle_limb1</child>
			<pose frame="">0.002746145928821733 0.0007343855568856284 0.025373353428292694 0 0 0</pose>
			<axis>
				<xyz>0.8816980702028427 0.06514916293255926 0.4672944463288279</xyz>
				<limit>
					<lower>-0.6108652381980153</lower>
					<upper>0.6108652381980153</upper>
				</limit>
				<use_parent_model_frame>0</use_parent_model_frame>
			</axis>
		</joint>
		<joint name="left_joint1_middle" type="revolute">
			<parent>left_middle_limb1</parent>
			<child>left_middle_limb2</child>
			<pose frame="">-0.0008013766352842566 -0.005278261207652304 0.012756089222415704 0 0 0</pose>
			<axis>
				<xyz>-0.06197857490501356 0.9978311478764739 -0.022173330382834047</xyz>
				<limit>
					<lower>0.0</lower>
					<upper>1.9198621771937625</upper>
				</limit>
				<use_parent_model_frame>0</use_parent_model_frame>
			</axis>
		</joint>
		<joint name="left_joint2_middle" type="revolute">
			<parent>left_middle_limb2</parent>
			<child>left_middle_limb3</child>
			<pose frame="">-0.0002965953151962708 -0.0038475942370413065 0.008077577425113098 0 0 0</pose>
			<axis>
				<xyz>-0.06197857490501356 0.9978311478764739 -0.022173330382834047</xyz>
				<limit>
					<lower>0.0</lower>
					<upper>1.2217304763960306</upper>
				</limit>
				<use_parent_model_frame>0</use_parent_model_frame>
			</axis>
		</joint>
		<joint name="right_joint0_little" type="revolute">
			<parent>right_little_limb0</parent>
			<child>right_little_limb1</child>
			<pose frame="">-0.0020511895950651037 -0.01216143925093458 0.02235496504341869 0 0 0</pose>
			<axis>
				<xyz>-0.8694401728225339 -0.2053218033488408 0.4493514692887</xyz>
				<limit>
					<lower>-0.3141592653589793</lower>
					<upper>0.3141592653589793</upper>
				</limit>
				<use_parent_model_frame>0</use_parent_model_frame>
			</axis>
		</joint>
		<joint name="right_joint1_little" type="revolute">
			<parent>right_little_limb1</parent>
			<child>right_little_limb2</child>
			<pose frame="">0.0017175689061325273 -0.0012935718665164054 0.01365959032662861 0 0 0</pose>
			<axis>
				<xyz>-0.041394626438209924 -0.8760736530046254 -0.48039716840669594</xyz>
				<limit>
					<lower>0.0</lower>
					<upper>1.9198621771937625</upper>
				</limit>
				<use_parent_model_frame>0</use_parent_model_frame>
			</axis>
		</joint>
		<joint name="right_joint2_little" type="revolute">
			<parent>right_little_limb2</parent>
			<child>right_little_limb3</child>
			<pose frame="">0.0009298391382652227 -0.00035659679267809887 0.008896482805692258 0 0 0</pose>
			<axis>
				<xyz>-0.041394626438209924 -0.8760736530046254 -0.48039716840669594</xyz>
				<limit>
					<lower>0.0</lower>
					<upper>1.2217304763960306</upper>
				</limit>
				<use_parent_model_frame>0</use_parent_model_frame>
			</axis>
		</joint>
		<joint name="sphere_right_axis0" type="revolute">
			<parent>torso</parent>
			<child>sphere_right_link1</child>
			<pose frame="">-8.958507585532516e-08 -1.6805291934152146e-07 -1.2962123818738291e-08 0 0 0</pose>
			<axis>
				<xyz>0.05101049431667335 0.998448888302569 -0.02231024242211098</xyz>
				<limit>
					<lower>-3.141592653589793</lower>
					<upper>3.141592653589793</upper>
				</limit>
				<use_parent_model_frame>0</use_parent_model_frame>
			</axis>
		</joint>
		<joint name="sphere_right_axis2" type="revolute">
			<parent>sphere_right_link2</parent>
			<child>upper_arm_right</child>
			<pose frame="">0.010364674320050823 0.004967615846167491 0.15098225854698308 0 0 0</pose>
			<axis>
				<xyz>0.011188426489535868 -0.0229092522253335 -0.9996749398055187</xyz>
				<limit>
					<lower>-3.141592653589793</lower>
					<upper>3.141592653589793</upper>
				</limit>
				<use_parent_model_frame>0</use_parent_model_frame>
			</axis>
		</joint>
		<joint name="sphere_right_axis1" type="revolute">
			<parent>sphere_right_link1</parent>
			<child>sphere_right_link2</child>
			<pose frame="">1.1628181670886307e-07 1.2732201988385762e-07 -1.033454232413078e-08 0 0 0</pose>
			<axis>
				<xyz>-0.9986354432836146 0.050744296328166724 -0.012339684270771775</xyz>
				<limit>
					<lower>-3.141592653589793</lower>
					<upper>3.141592653589793</upper>
				</limit>
				<use_parent_model_frame>0</use_parent_model_frame>
			</axis>
		</joint>
		<joint name="elbow_right_rot0" type="revolute">
			<parent>upper_arm_right</parent>
			<child>elbow_right</child>
			<pose frame="">-0.01505249789813128 -0.003597305755071375 0.03935067099470405 0 0 0</pose>
			<axis>
				<xyz>-0.9986354432836139 0.05074429632816527 -0.012339684270768671</xyz>
				<limit>
					<lower>0.0</lower>
					<upper>1.5707963267948966</upper>
				</limit>
				<use_parent_model_frame>0</use_parent_model_frame>
			</axis>
		</joint>
		<joint name="right_palm_thumb" type="revolute">
			<parent>right_palm</parent>
			<child>right_thumb_limb0</child>
			<pose frame="">0.006913555379475511 0.0023496417621602993 0.0018550198327431566 0 0 0</pose>
			<axis>
				<xyz>-0.8841609893958954 -0.32600906642819866 -0.3346302936631516</xyz>
				<limit>
					<lower>-1.0471975511965976</lower>
					<upper>0.7853981633974483</upper>
				</limit>
				<use_parent_model_frame>0</use_parent_model_frame>
			</axis>
		</joint>
		<joint name="right_palm_little" type="revolute">
			<parent>right_palm</parent>
			<child>right_little_limb0</child>
			<pose frame="">0.00018051010012559487 0.006914733503752708 0.002984891992666796 0 0 0</pose>
			<axis>
				<xyz>-0.041394626438208314 -0.8760736530046356 -0.48039716840669383</xyz>
				<limit>
					<lower>-0.5235987755982988</lower>
					<upper>0.5235987755982988</upper>
				</limit>
				<use_parent_model_frame>0</use_parent_model_frame>
			</axis>
		</joint>
		<joint name="right_palm_ring" type="revolute">
			<parent>right_palm</parent>
			<child>right_index_limb0</child>
			<pose frame="">0.00017836762893324475 0.00745171760935289 0.0010931886598593366 0 0 0</pose>
			<axis>
				<xyz>-0.04215172688600319 -0.9705816527417793 -0.23705376453788035</xyz>
				<limit>
					<lower>-0.5235987755982988</lower>
					<upper>0.5235987755982988</upper>
				</limit>
				<use_parent_model_frame>0</use_parent_model_frame>
			</axis>
		</joint>
		<joint name="right_palm_middle" type="revolute">
			<parent>right_palm</parent>
			<child>right_middle_limb0</child>
			<pose frame="">0.00015474476294347284 0.007481312857304265 -0.0008728455497451649 0 0 0</pose>
			<axis>
				<xyz>-0.040036256805539204 -0.9989461168065898 0.02244446163432123</xyz>
				<limit>
					<lower>-0.5235987755982988</lower>
					<upper>0.5235987755982988</upper>
				</limit>
				<use_parent_model_frame>0</use_parent_model_frame>
			</axis>
		</joint>
		<joint name="right_palm_index" type="revolute">
			<parent>right_palm</parent>
			<child>right_ring_limb0</child>
			<pose frame="">0.00011113310031674929 0.007001663285264665 -0.002779328799488887 0 0 0</pose>
			<axis>
				<xyz>-0.0351923819868204 -0.9592340538475436 0.28041313483737057</xyz>
				<limit>
					<lower>-0.5235987755982988</lower>
					<upper>0.5235987755982988</upper>
				</limit>
				<use_parent_model_frame>0</use_parent_model_frame>
			</axis>
		</joint>
		<joint name="right_wrist_0" type="revolute">
			<parent>lower_arm_right</parent>
			<child>wrist_right_1</child>
			<pose frame="">0.011094392792996502 -0.00048043688755383066 -0.0015766831427710404 0 0 0</pose>
			<axis>
				<xyz>0.9991077747968851 -0.04032476901588526 -0.012552583169695573</xyz>
				<limit>
					<lower>-0.5235987755982988</lower>
					<upper>0.5235987755982988</upper>
				</limit>
				<use_parent_model_frame>0</use_parent_model_frame>
			</axis>
		</joint>
		<joint name="right_wrist_1" type="revolute">
			<parent>wrist_right_1</parent>
			<child>right_palm</child>
			<pose frame="">-0.0006072740553287304 0.01811172823967358 0.0518242018619488 0 0 0</pose>
			<axis>
				<xyz>0.040036256805536914 0.9989461168065814 -0.022444461634318753</xyz>
				<limit>
					<lower>-0.5235987755982988</lower>
					<upper>0.5235987755982988</upper>
				</limit>
				<use_parent_model_frame>0</use_parent_model_frame>
			</axis>
		</joint>
		<joint name="right_joint0_ring" type="revolute">
			<parent>right_ring_limb0</parent>
			<child>right_ring_limb1</child>
			<pose frame="">-0.0012433880171631628 0.007197319485333855 0.02446432881538488 0 0 0</pose>
			<axis>
				<xyz>-0.8535784840269218 0.17478286830417905 0.4907695187699456</xyz>
				<limit>
					<lower>-0.3141592653589793</lower>
					<upper>0.3141592653589793</upper>
				</limit>
				<use_parent_model_frame>0</use_parent_model_frame>
			</axis>
		</joint>
		<joint name="right_joint1_ring" type="revolute">
			<parent>right_ring_limb1</parent>
			<child>right_ring_limb2</child>
			<pose frame="">0.0020827324399513712 0.008731865154189 0.010517823331837341 0 0 0</pose>
			<axis>
				<xyz>-0.03519238198682357 -0.9592340538475406 0.28041313483737174</xyz>
				<limit>
					<lower>0.0</lower>
					<upper>1.9198621771937625</upper>
				</limit>
				<use_parent_model_frame>0</use_parent_model_frame>
			</axis>
		</joint>
		<joint name="right_joint2_ring" type="revolute">
			<parent>right_ring_limb2</parent>
			<child>right_ring_limb3</child>
			<pose frame="">0.001157711948893052 0.0060314757883469915 0.0065130973140347945 0 0 0</pose>
			<axis>
				<xyz>-0.03519238198682357 -0.9592340538475406 0.28041313483737174</xyz>
				<limit>
					<lower>0.0</lower>
					<upper>1.2217304763960306</upper>
				</limit>
				<use_parent_model_frame>0</use_parent_model_frame>
			</axis>
		</joint>
		<joint name="right_joint0_thumb" type="revolute">
			<parent>right_thumb_limb0</parent>
			<child>right_thumb_limb1</child>
			<pose frame="">-0.0017808744488742433 -0.0012493472902915803 0.025438526161727284 0 0 0</pose>
			<axis>
				<xyz>0.10974897304326547 -0.8411689793059581 0.5295185654623882</xyz>
				<limit>
					<lower>-0.3141592653589793</lower>
					<upper>0.3141592653589793</upper>
				</limit>
				<use_parent_model_frame>0</use_parent_model_frame>
			</axis>
		</joint>
		<joint name="right_joint1_thumb" type="revolute">
			<parent>right_thumb_limb1</parent>
			<child>right_thumb_limb2</child>
			<pose frame="">-0.003007494408159488 -0.013209055622875901 -0.002771685655305607 0 0 0</pose>
			<axis>
				<xyz>0.9812143067148611 0.17672632745303177 0.07737111530181631</xyz>
				<limit>
					<lower>0.0</lower>
					<upper>1.9198621771937625</upper>
				</limit>
				<use_parent_model_frame>0</use_parent_model_frame>
			</axis>
		</joint>
		<joint name="right_joint2_thumb" type="revolute">
			<parent>right_thumb_limb2</parent>
			<child>right_thumb_limb3</child>
			<pose frame="">-0.0030103886950531944 -0.0023784913797670576 -0.008088260436486295 0 0 0</pose>
			<axis>
				<xyz>0.9812143067148589 0.1767263274530319 0.07737111530181681</xyz>
				<limit>
					<lower>0.0</lower>
					<upper>1.2217304763960306</upper>
				</limit>
				<use_parent_model_frame>0</use_parent_model_frame>
			</axis>
		</joint>
		<joint name="right_joint0_index" type="revolute">
			<parent>right_index_limb0</parent>
			<child>right_index_limb1</child>
			<pose frame="">-0.0017711038092445364 -0.005970396673751799 0.024760050966664372 0 0 0</pose>
			<axis>
				<xyz>-0.8639406297828083 -0.08376341175657515 0.49657857289798146</xyz>
				<limit>
					<lower>-0.3141592653589793</lower>
					<upper>0.3141592653589793</upper>
				</limit>
				<use_parent_model_frame>0</use_parent_model_frame>
			</axis>
		</joint>
		<joint name="right_joint1_index" type="revolute">
			<parent>right_index_limb1</parent>
			<child>right_index_limb2</child>
			<pose frame="">0.0018601689559756452 0.0022860997903869328 0.013510045590608116 0 0 0</pose>
			<axis>
				<xyz>-0.042151726885999524 -0.9705816527417711 -0.2370537645378768</xyz>
				<limit>
					<lower>0.0</lower>
					<upper>1.9198621771937625</upper>
				</limit>
				<use_parent_model_frame>0</use_parent_model_frame>
			</axis>
		</joint>
		<joint name="right_joint2_index" type="revolute">
			<parent>right_index_limb2</parent>
			<child>right_index_limb3</child>
			<pose frame="">0.0010204803719345535 0.0019579771807173964 0.00867549261444328 0 0 0</pose>
			<axis>
				<xyz>-0.042151726885999524 -0.9705816527417711 -0.2370537645378768</xyz>
				<limit>
					<lower>0.0</lower>
					<upper>1.2217304763960306</upper>
				</limit>
				<use_parent_model_frame>0</use_parent_model_frame>
			</axis>
		</joint>
		<joint name="right_joint0_middle" type="revolute">
			<parent>right_middle_limb0</parent>
			<child>right_middle_limb1</child>
			<pose frame="">-0.0014955819717922126 0.0006324590149577347 0.0254797187010775 0 0 0</pose>
			<axis>
				<xyz>-0.8585305031204695 0.04588321320781076 0.5107054982643501</xyz>
				<limit>
					<lower>-0.6108652381980153</lower>
					<upper>0.6108652381980153</upper>
				</limit>
				<use_parent_model_frame>0</use_parent_model_frame>
			</axis>
		</joint>
		<joint name="right_joint1_middle" type="revolute">
			<parent>right_middle_limb1</parent>
			<child>right_middle_limb2</child>
			<pose frame="">0.001984753474472605 0.005705735056296938 0.012438818970224332 0 0 0</pose>
			<axis>
				<xyz>-0.04003625680553906 -0.9989461168065813 0.022444461634321018</xyz>
				<limit>
					<lower>0.0</lower>
					<upper>1.9198621771937625</upper>
				</limit>
				<use_parent_model_frame>0</use_parent_model_frame>
			</axis>
		</joint>
		<joint name="right_joint2_middle" type="revolute">
			<parent>right_middle_limb2</parent>
			<child>right_middle_limb3</child>
			<pose frame="">0.0010981917577530709 0.0041368358656200845 0.007862553658948812 0 0 0</pose>
			<axis>
				<xyz>-0.04003625680553906 -0.9989461168065813 0.022444461634321018</xyz>
				<limit>
					<lower>0.0</lower>
					<upper>1.2217304763960306</upper>
				</limit>
				<use_parent_model_frame>0</use_parent_model_frame>
			</axis>
		</joint>
		<joint name="zed_camera_mount" type="fixed">
			<parent>head</parent>
			<child>zed_camera</child>
			<pose frame="">0.02150000000000037 -0.00029300170238104605 0.008241004058337609 0 0 0</pose>
		</joint>
		<joint name="zed_camera_right" type="fixed">
			<parent>zed_camera</parent>
			<child>zed_camera_right_lense</child>
			<pose frame="">-1.9539925233402755e-16 0.02347554241761132 -0.004989880579626345 0 0 0</pose>
		</joint>
		<joint name="zed_camera_left" type="fixed">
			<parent>zed_camera</parent>
			<child>zed_camera_left_lense</child>
			<pose frame="">-1.7810504170983066e-05 0.023475542389803428 -0.0049898807104521836 0 0 0</pose>
		</joint>
		<joint name="sphere_head_axis0" type="revolute">
			<parent>torso</parent>
			<child>sphere_head_link1</child>
			<pose frame="">-1.3223469747428082e-17 -4.718447854656916e-18 0.0 0 0 0</pose>
			<axis>
				<xyz>2.2122894501686084e-15 1.0000000000000004 -6.44129320794164e-15</xyz>
				<limit>
					<lower>-0.5235987755982988</lower>
					<upper>0.5235987755982988</upper>
				</limit>
				<use_parent_model_frame>0</use_parent_model_frame>
			</axis>
		</joint>
		<joint name="sphere_head_axis2" type="revolute">
			<parent>shere_head_link2</parent>
			<child>head</child>
			<pose frame="">-0.0006470497602340519 -0.0444965621236135 -0.14806661108822083 0 0 0</pose>
			<axis>
				<xyz>-3.447412565064088e-15 6.4412932079416446e-15 1.0</xyz>
				<limit>
					<lower>-0.5235987755982988</lower>
					<upper>0.5235987755982988</upper>
				</limit>
				<use_parent_model_frame>0</use_parent_model_frame>
			</axis>
		</joint>
		<joint name="sphere_head_axis1" type="revolute">
			<parent>sphere_head_link1</parent>
			<child>shere_head_link2</child>
			<pose frame="">-6.396969828395951e-19 3.608224830031759e-17 0.0 0 0 0</pose>
			<axis>
				<xyz>1.0000000000000004 -2.2122894501685863e-15 3.4474125650641005e-15</xyz>
				<limit>
					<lower>-0.5235987755982988</lower>
					<upper>0.5235987755982988</upper>
				</limit>
				<use_parent_model_frame>0</use_parent_model_frame>
			</axis>
		</joint>
		<plugin filename="libmusc_plugin.so" name="musc_plugin">
			<myoMuscle name="motor0">
				<link name="torso">
					<viaPoint type="FIXPOINT">0.28894109223784714 -0.010689615277494027 0.57625463538261</viaPoint>
				</link>
				<link name="upper_arm_left">
					<viaPoint type="FIXPOINT">0.009107007608153169 -0.019682640290078185 0.10332093461370115</viaPoint>
				</link>
			</myoMuscle>
			<myoMuscle name="motor1">
				<link name="torso">
					<viaPoint type="FIXPOINT">0.24003539451940256 -0.0255094396635371 0.46729404948318215</viaPoint>
				</link>
				<link name="upper_arm_left">
					<viaPoint type="FIXPOINT">-0.027693307907051514 -0.018344644528211277 0.10370214367214033</viaPoint>
				</link>
			</myoMuscle>
			<myoMuscle name="motor2">
				<link name="torso">
					<viaPoint type="FIXPOINT">0.2512180133128362 -0.028667405657345723 0.5145590997255798</viaPoint>
				</link>
				<link name="upper_arm_left">
					<viaPoint type="FIXPOINT">-0.0015912445044721224 -0.013292366835686976 0.10029325065513789</viaPoint>
				</link>
			</myoMuscle>
			<myoMuscle name="motor3">
				<link name="torso">
					<viaPoint type="FIXPOINT">0.28063665292590684 -0.028534400330317792 0.5580004259562042</viaPoint>
				</link>
				<link name="upper_arm_left">
					<viaPoint type="FIXPOINT">0.009445707262648071 -0.020187854306989356 0.10332872170412913</viaPoint>
				</link>
			</myoMuscle>
			<myoMuscle name="motor4">
				<link name="torso">
					<viaPoint type="FIXPOINT">0.3033935027253936 5.329351681328665e-15 0.596144953020783</viaPoint>
				</link>
				<link name="upper_arm_left">
					<viaPoint type="FIXPOINT">0.018050177151123527 0.004001514052404988 0.10267807938646527</viaPoint>
				</link>
			</myoMuscle>
			<myoMuscle name="motor5">
				<link name="torso">
					<viaPoint type="FIXPOINT">0.2769871340021271 0.04289909901328503 0.5564042514238003</viaPoint>
				</link>
				<link name="upper_arm_left">
					<viaPoint type="FIXPOINT">0.007177908382792105 0.024200683793200752 0.10233686417653758</viaPoint>
				</link>
			</myoMuscle>
			<myoMuscle name="motor6">
				<link name="torso">
					<viaPoint type="FIXPOINT">0.247561326172623 0.04290640006489306 0.512959790060908</viaPoint>
				</link>
				<link name="upper_arm_left">
					<viaPoint type="FIXPOINT">-0.0030923031893949115 0.01608845754789791 0.09963673901769823</viaPoint>
				</link>
			</myoMuscle>
			<myoMuscle name="motor7">
				<link name="torso">
					<viaPoint type="FIXPOINT">0.23617466540192175 0.050058161611911685 0.465605498848829</viaPoint>
				</link>
				<link name="upper_arm_left">
					<viaPoint type="FIXPOINT">-0.030174246989763596 0.018727337772520315 0.10288034294896882</viaPoint>
				</link>
			</myoMuscle>
			<myoMuscle name="motor8">
				<link name="torso">
					<viaPoint type="FIXPOINT">0.2865401700456322 0.026075605770317516 0.576140812491758</viaPoint>
				</link>
				<link name="upper_arm_left">
					<viaPoint type="FIXPOINT">0.006892451578780019 0.023663754118190505 0.10235236368463035</viaPoint>
				</link>
			</myoMuscle>
			<myoMuscle name="motor27">
				<link name="base">
					<viaPoint type="FIXPOINT">-0.19499999851461478 -0.11347765649897372 0.08723717349165262</viaPoint>
				</link>
				<link name="torso">
					<viaPoint type="FIXPOINT">0.13543876459810386 -0.06208086211104811 0.32683191492848634</viaPoint>
				</link>
			</myoMuscle>
			<myoMuscle name="motor28">
				<link name="base">
					<viaPoint type="FIXPOINT">0.1949999985146147 -0.1134776564989737 0.0872371734916526</viaPoint>
				</link>
				<link name="torso">
					<viaPoint type="FIXPOINT">-0.13663898856535112 -0.06000468869766767 0.32502942598649015</viaPoint>
				</link>
			</myoMuscle>
			<myoMuscle name="motor29">
				<link name="base">
					<viaPoint type="FIXPOINT">-0.22500000148538477 0.0015223435010262346 0.08723717349165344</viaPoint>
				</link>
				<link name="torso">
					<viaPoint type="FIXPOINT">-0.15008296104407917 2.500672069228397e-06 0.31561285492544516</viaPoint>
				</link>
			</myoMuscle>
			<myoMuscle name="motor30">
				<link name="base">
					<viaPoint type="FIXPOINT">0.2250000014853848 0.0015223435010263528 0.08723717349165344</viaPoint>
				</link>
				<link name="torso">
					<viaPoint type="FIXPOINT">0.15008296104408234 2.5006720701115108e-06 0.31561285492544544</viaPoint>
				</link>
			</myoMuscle>
			<myoMuscle name="motor31">
				<link name="base">
					<viaPoint type="FIXPOINT">-0.19499999851461464 0.11652234350102626 0.08723717349165426</viaPoint>
				</link>
				<link name="torso">
					<viaPoint type="FIXPOINT">0.11845723973009747 0.06717115764172317 0.29715852041937835</viaPoint>
				</link>
			</myoMuscle>
			<myoMuscle name="motor32">
				<link name="base">
					<viaPoint type="FIXPOINT">0.19499999851461486 0.1165223435010261 0.08723717349165426</viaPoint>
				</link>
				<link name="torso">
					<viaPoint type="FIXPOINT">-0.11544125735968605 0.06857597545288843 0.2934261837171483</viaPoint>
				</link>
			</myoMuscle>
			<myoMuscle name="motor9">
				<link name="upper_arm_left">
					<viaPoint type="FIXPOINT">-0.014868521600138358 0.06223755093369616 -0.03434204972672397</viaPoint>
				</link>
				<link name="elbow_left">
					<viaPoint type="FIXPOINT">-0.005883179528660136 0.035276291213785775 -0.00015881767874180498</viaPoint>
				</link>
			</myoMuscle>
			<myoMuscle name="motor10">
				<link name="upper_arm_left">
					<viaPoint type="FIXPOINT">-0.009118540788150824 -0.0663654113251906 -0.03145924818101235</viaPoint>
				</link>
				<link name="elbow_left">
					<viaPoint type="FIXPOINT">-0.0020836081540628014 -0.0369670719228775 -0.012207839824122714</viaPoint>
				</link>
			</myoMuscle>
			<myoMuscle name="motor11">
				<link name="upper_arm_left">
					<viaPoint type="FIXPOINT">0.034922643989017066 -0.0060313711315078625 -0.09361286618881788</viaPoint>
				</link>
				<link name="elbow_left">
					<viaPoint type="FIXPOINT">0.034895878738565894 -0.008970327410124865 -0.02689274315300441</viaPoint>
				</link>
				<link name="lower_arm_left">
					<viaPoint type="FIXPOINT">-0.015052310925987272 -0.03492722527484661 0.11318600256142126</viaPoint>
				</link>
			</myoMuscle>
			<myoMuscle name="motor12">
				<link name="upper_arm_left">
					<viaPoint type="FIXPOINT">0.02673383335409074 -0.00644747436139885 -0.09351168077779728</viaPoint>
				</link>
				<link name="elbow_left">
					<viaPoint type="FIXPOINT">0.03673749832206862 0.013578404265092586 -0.03385115823519424</viaPoint>
				</link>
				<link name="lower_arm_left">
					<viaPoint type="FIXPOINT">-0.018858472519075065 0.0370348424589558 0.11207963072279849</viaPoint>
				</link>
			</myoMuscle>
			<myoMuscle name="motor13">
				<link name="torso">
					<viaPoint type="FIXPOINT">-0.2865417124191222 0.027567759775711326 0.5754772798049546</viaPoint>
				</link>
				<link name="upper_arm_right">
					<viaPoint type="FIXPOINT">-0.007514813271136376 0.026042155480271358 0.10229464428540219</viaPoint>
				</link>
			</myoMuscle>
			<myoMuscle name="motor14">
				<link name="torso">
					<viaPoint type="FIXPOINT">-0.2361746654013883 0.051580505123396486 0.4649412915804758</viaPoint>
				</link>
				<link name="upper_arm_right">
					<viaPoint type="FIXPOINT">0.029551885297426778 0.021105739134609648 0.12482262354974076</viaPoint>
				</link>
			</myoMuscle>
			<myoMuscle name="motor15">
				<link name="torso">
					<viaPoint type="FIXPOINT">-0.2475613261720895 0.04442874357637785 0.5122955827925547</viaPoint>
				</link>
				<link name="upper_arm_right">
					<viaPoint type="FIXPOINT">0.00246994149703859 0.01846685890997876 0.09957901961847014</viaPoint>
				</link>
			</myoMuscle>
			<myoMuscle name="motor16">
				<link name="torso">
					<viaPoint type="FIXPOINT">-0.276988676375617 0.04439125301867884 0.5557407187369969</viaPoint>
				</link>
				<link name="upper_arm_right">
					<viaPoint type="FIXPOINT">-0.007800270075149171 0.02657908515528246 0.10227914477730941</viaPoint>
				</link>
			</myoMuscle>
			<myoMuscle name="motor17">
				<link name="torso">
					<viaPoint type="FIXPOINT">-0.3100988054292128 0.0015223435010265783 0.5915377063521623</viaPoint>
				</link>
			</myoMuscle>
			<myoMuscle name="motor18">
				<link name="upper_arm_right">
					<viaPoint type="FIXPOINT">-0.018825437428894604 0.003387170006399481 0.10268723258967512</viaPoint>
				</link>
			</myoMuscle>
			<myoMuscle name="motor19">
				<link name="torso">
					<viaPoint type="FIXPOINT">-0.28063819529939676 -0.02704224632492396 0.5573368932694007</viaPoint>
				</link>
				<link name="upper_arm_right">
					<viaPoint type="FIXPOINT">-0.00972936930050942 -0.017304238927997314 0.10326321521447299</viaPoint>
				</link>
			</myoMuscle>
			<myoMuscle name="motor20">
				<link name="torso">
					<viaPoint type="FIXPOINT">-0.25121801331230276 -0.027145062145860932 0.5138948924572266</viaPoint>
				</link>
				<link name="upper_arm_right">
					<viaPoint type="FIXPOINT">0.0009688828121158366 -0.010913965473606107 0.10023553125590973</viaPoint>
				</link>
			</myoMuscle>
			<myoMuscle name="motor21">
				<link name="torso">
					<viaPoint type="FIXPOINT">-0.2400353945188691 -0.023987096152052287 0.4666298422148289</viaPoint>
				</link>
				<link name="upper_arm_right">
					<viaPoint type="FIXPOINT">0.027648467588486873 -0.01615061999120826 0.10365511323809636</viaPoint>
				</link>
			</myoMuscle>
			<myoMuscle name="motor22">
				<link name="torso">
					<viaPoint type="FIXPOINT">-0.28894263461133707 -0.009197461272100206 0.5755911026958066</viaPoint>
				</link>
				<link name="upper_arm_right">
					<viaPoint type="FIXPOINT">-0.010068068955003576 -0.017809452944907704 0.10327100230490097</viaPoint>
				</link>
			</myoMuscle>
			<myoMuscle name="motor23">
				<link name="upper_arm_right">
					<viaPoint type="FIXPOINT">0.009826792374754555 0.06497065472283199 -0.046631490858719926</viaPoint>
				</link>
				<link name="elbow_right">
					<viaPoint type="FIXPOINT">0.00547654625549324 0.03538845216009587 0.0027814045159734848</viaPoint>
				</link>
			</myoMuscle>
			<myoMuscle name="motor24">
				<link name="upper_arm_right">
					<viaPoint type="FIXPOINT">0.009829533305246123 -0.06511420161794504 -0.022360851245113268</viaPoint>
				</link>
				<link name="elbow_right">
					<viaPoint type="FIXPOINT">0.0031012347745808457 -0.03400956411921123 -0.009332622529310122</viaPoint>
				</link>
			</myoMuscle>
			<myoMuscle name="motor25">
				<link name="upper_arm_right">
					<viaPoint type="FIXPOINT">-0.03553941146812839 -0.0036644243955396105 -0.09417042305794805</viaPoint>
				</link>
				<link name="elbow_right">
					<viaPoint type="FIXPOINT">-0.03714413159523538 0.013690565211402684 -0.030910936040478846</viaPoint>
				</link>
				<link name="lower_arm_right">
					<viaPoint type="FIXPOINT">-0.017241690742177625 0.03892605803769787 0.11417913364015686</viaPoint>
				</link>
			</myoMuscle>
			<myoMuscle name="motor26">
				<link name="upper_arm_right">
					<viaPoint type="FIXPOINT">-0.027350600833202777 -0.004080527625430568 -0.09406923764692782</viaPoint>
				</link>
				<link name="elbow_right">
					<viaPoint type="FIXPOINT">-0.035302512011732505 -0.00885816646381484 -0.02395252095828962</viaPoint>
				</link>
				<link name="lower_arm_right">
					<viaPoint type="FIXPOINT">-0.0207802768683014 -0.03304290395977767 0.1155887557442382</viaPoint>
				</link>
			</myoMuscle>
			<myoMuscle name="motor33">
				<link name="torso">
					<viaPoint type="FIXPOINT">-0.05130415696557286 -0.04299353000294861 0.6913291597077097</viaPoint>
				</link>
				<link name="head">
					<viaPoint type="FIXPOINT">-0.05041110993763421 -0.05800173243057134 -0.13589175198733486</viaPoint>
				</link>
			</myoMuscle>
			<myoMuscle name="motor34">
				<link name="torso">
					<viaPoint type="FIXPOINT">-0.0512451101485844 0.04499993636822131 0.6915254724006062</viaPoint>
				</link>
				<link name="head">
					<viaPoint type="FIXPOINT">-0.050411109937634126 -0.03076089509889395 -0.1406950465860001</viaPoint>
				</link>
			</myoMuscle>
			<myoMuscle name="motor35">
				<link name="torso">
					<viaPoint type="FIXPOINT">0.051245110148584135 0.04499993636822098 0.6915254724006069</viaPoint>
				</link>
				<link name="head">
					<viaPoint type="FIXPOINT">0.04911701041716604 -0.030760895098894122 -0.14069504658599982</viaPoint>
				</link>
			</myoMuscle>
			<myoMuscle name="motor36">
				<link name="torso">
					<viaPoint type="FIXPOINT">0.05130415696557248 -0.04299353000294856 0.6913291597077091</viaPoint>
				</link>
				<link name="head">
					<viaPoint type="FIXPOINT">0.049117010417165964 -0.05800173243057152 -0.13589175198733458</viaPoint>
				</link>
			</myoMuscle>
		</plugin>
	</model>
</sdf>
