<?xml version="1.0" ?>
<sdf version="1.6">
	<model name="roboy_2_0_head_simplified">
		<link name="head">
			<pose frame="">-0.04263868288679361 0.1141799546132749 0.0021230716783150277 0.0 -0.0 0.0</pose>
			<inertial>
				<pose frame="">0.0 0.0 0.0 0 0 0</pose>
				<mass>2.1986973590671695</mass>
				<inertia>
					<ixx>1.9457059620139492</ixx>
					<ixy>0.00489667266323444</ixy>
					<ixz>0.020134037757221272</ixz>
					<iyy>0.025068367005669546</iyy>
					<iyz>-4.347639029543933e-05</iyz>
					<izz>1.9405524949959996</izz>
				</inertia>
			</inertial>
			<collision name="head_collision">
				<geometry>
					<mesh>
						<uri>model://roboy_2_0_head_simplified/meshes/CAD/head.stl</uri>
						<scale>0.001 0.001 0.001</scale>
					</mesh>
				</geometry>
			</collision>
			<visual name="head_visual">
				<geometry>
					<mesh>
						<uri>model://roboy_2_0_head_simplified/meshes/CAD/head.stl</uri>
						<scale>0.001 0.001 0.001</scale>
					</mesh>
				</geometry>
			</visual>
		</link>
		<link name="torso">
			<pose frame="">-0.18288603813234197 0.08808368851563954 0.270707755550752 0.0 -0.0 0.0</pose>
			<inertial>
				<pose frame="">0.0 0.0 0.0 0 0 0</pose>
				<mass>9.905500987745402</mass>
				<inertia>
					<ixx>5.102515153204172</ixx>
					<ixy>0.03548511098175889</ixy>
					<ixz>0.03185551555726029</ixz>
					<iyy>0.09826501266906054</iyy>
					<iyz>-0.00021552215771056786</iyz>
					<izz>5.169245999115969</izz>
				</inertia>
			</inertial>
			<collision name="torso_collision">
				<geometry>
					<mesh>
						<uri>model://roboy_2_0_head_simplified/meshes/CAD/torso.stl</uri>
						<scale>0.001 0.001 0.001</scale>
					</mesh>
				</geometry>
			</collision>
			<visual name="torso_visual">
				<geometry>
					<mesh>
						<uri>model://roboy_2_0_head_simplified/meshes/CAD/torso.stl</uri>
						<scale>0.001 0.001 0.001</scale>
					</mesh>
				</geometry>
			</visual>
		</link>
		<link name="neck_link_3">
			<pose frame="">-0.10770908554300349 -0.1559729359249347 -0.005671871040206634 0.0 -0.0 0.0</pose>
			<inertial>
				<pose frame="">0.0 0.0 0.0 0 0 0</pose>
				<mass>0.017192417326343357</mass>
				<inertia>
					<ixx>0.010466481866131364</ixx>
					<ixy>6.613662178595011e-05</ixy>
					<ixz>7.607999592631023e-05</ixz>
					<iyy>1.532435475756012e-06</iyy>
					<iyz>-4.808145207666988e-07</iyz>
					<izz>0.01046633989777193</izz>
				</inertia>
			</inertial>
			<collision name="neck_link_3_collision">
				<geometry>
					<mesh>
						<uri>model://roboy_2_0_head_simplified/meshes/CAD/neck_link_3.stl</uri>
						<scale>0.001 0.001 0.001</scale>
					</mesh>
				</geometry>
			</collision>
			<visual name="neck_link_3_visual">
				<geometry>
					<mesh>
						<uri>model://roboy_2_0_head_simplified/meshes/CAD/neck_link_3.stl</uri>
						<scale>0.001 0.001 0.001</scale>
					</mesh>
				</geometry>
			</visual>
		</link>
		<link name="neck_link_2">
			<pose frame="">-0.0030146535136215515 0.6598560509539079 0.003015865394987667 0.0 -0.0 0.0</pose>
			<inertial>
				<pose frame="">0.0 0.0 0.0 0 0 0</pose>
				<mass>0.011947622039161101</mass>
				<inertia>
					<ixx>0.007306934101953244</ixx>
					<ixy>3.731904905578473e-05</ixy>
					<ixz>5.298587603583067e-05</ixz>
					<iyy>1.2142544508732947e-06</iyy>
					<iyz>-2.706890477535063e-07</iyz>
					<izz>0.0073063714624777435</izz>
				</inertia>
			</inertial>
			<collision name="neck_link_2_collision">
				<geometry>
					<mesh>
						<uri>model://roboy_2_0_head_simplified/meshes/CAD/neck_link_2.stl</uri>
						<scale>0.001 0.001 0.001</scale>
					</mesh>
				</geometry>
			</collision>
			<visual name="neck_link_2_visual">
				<geometry>
					<mesh>
						<uri>model://roboy_2_0_head_simplified/meshes/CAD/neck_link_2.stl</uri>
						<scale>0.001 0.001 0.001</scale>
					</mesh>
				</geometry>
			</visual>
		</link>
		<joint name="neck_axis_2" type="revolute">
			<parent>neck_link_3</parent>
			<child>neck_link_2</child>
			<pose frame="">-0.010048936464961123 0.1221049695705743 -0.008687708220672311 0 0 0</pose>
			<axis>
				<xyz>-1.0 -3.432848736779223e-15 6.123233995736762e-17</xyz>
				<limit>
					<lower>-0.5235987755982988</lower>
					<upper>0.5235987755982988</upper>
				</limit>
				<use_parent_model_frame>0</use_parent_model_frame>
			</axis>
		</joint>
		<joint name="neck_axis_3" type="revolute">
			<parent>neck_link_2</parent>
			<child>head</child>
			<pose frame="">0.03957509290821096 0.6651160173239627 0.0021511822282383837 0 0 0</pose>
			<axis>
				<xyz>1.4220056966830026e-15 -0.2588190451025207 0.9659258262890682</xyz>
				<limit>
					<lower>-3.141592653589793</lower>
					<upper>3.141592653589793</upper>
				</limit>
				<use_parent_model_frame>0</use_parent_model_frame>
			</axis>
		</joint>
		<joint name="neck_axis_1" type="revolute">
			<parent>torso</parent>
			<child>neck_link_3</child>
			<pose frame="">0.1027090855430024 0.9269309134843582 2.8214521977654174e-08 0 0 0</pose>
			<axis>
				<xyz>-3.4580022271808862e-15 1.0 -6.328575552895589e-17</xyz>
				<limit>
					<lower>-0.5235987755982988</lower>
					<upper>0.5235987755982988</upper>
				</limit>
				<use_parent_model_frame>0</use_parent_model_frame>
			</axis>
		</joint>
		<plugin filename="libmyomuscle_plugin.so" name="myomuscle_plugin">
			<myoMuscle name="motor0">
				<link name="torso">
					<viaPoint type="FIXPOINT">0.12658188116676855 0.6504530281152279 -0.23186676783751942</viaPoint>
				</link>
				<link name="head">
					<viaPoint type="FIXPOINT">-0.010192010234251026 0.6797791087412351 0.009605437441072428</viaPoint>
				</link>
			</myoMuscle>
			<myoMuscle name="motor1">
				<link name="torso">
					<viaPoint type="FIXPOINT">0.1266409279837568 0.650649340808125 -0.31986023420868925</viaPoint>
				</link>
				<link name="head">
					<viaPoint type="FIXPOINT">-0.010192010234250554 0.6817914520638507 -0.01798523728580579</viaPoint>
				</link>
			</myoMuscle>
			<myoMuscle name="motor2">
				<link name="torso">
					<viaPoint type="FIXPOINT">0.22913114828092526 0.6506493408081256 -0.3198602342086891</viaPoint>
				</link>
				<link name="head">
					<viaPoint type="FIXPOINT">0.08933611012054954 0.6817914520638511 -0.017985237285804083</viaPoint>
				</link>
			</myoMuscle>
			<myoMuscle name="motor3">
				<link name="torso">
					<viaPoint type="FIXPOINT">0.22919019509791386 0.6504530281152274 -0.23186676783751956</viaPoint>
				</link>
				<link name="head">
					<viaPoint type="FIXPOINT">0.08933611012054908 0.6793806308619986 0.009570575143975005</viaPoint>
				</link>
			</myoMuscle>
		</plugin>
	</model>
</sdf>
