<?xml version="1.0" ?>
<robot name="roboy_2_0_head_simplified">
  <joint name="neck_axis_1" type="revolute">
    <parent link="torso"/>
    <child link="neck_link_3"/>
    <origin rpy="0  0  0" xyz="-0.005    0.77095 -0.00567"/>
    <axis xyz="0  1  0"/>
    <limit effort="0.0" lower="-0.523598775598" upper="0.523598775598" velocity="0.0"/>
  </joint>
  <joint name="neck_axis_2" type="revolute">
    <parent link="neck_link_3"/>
    <child link="neck_link_2"/>
    <origin rpy="0  0  0" xyz="-0.00806  0.011    0"/>
    <axis xyz="-1  0  0"/>
    <limit effort="0.0" lower="-0.523598775598" upper="0.523598775598" velocity="0.0"/>
  </joint>
  <joint name="neck_axis_3" type="revolute">
    <parent link="neck_link_2"/>
    <child link="head"/>
    <origin rpy="0  0  0" xyz="0.01    -0.00266  0.00994"/>
    <axis xyz="0      -0.25881  0.96592"/>
    <limit effort="0.0" lower="-0.523598775598" upper="0.523598775598" velocity="0.0"/>
  </joint>
  <link name="head">
    <inertial>
      <mass value="1"/>
      <origin rpy="0  0  0" xyz="0       0.04735  0.00223"/>
      <inertia ixx="0.1" ixy="0.0" ixz="0.0" iyy="0.1" iyz="0.0" izz="0.1"/>
    </inertial>
    <collision name="head_collision">
      <origin rpy="0  0  0" xyz="0       0.04735  0.00223"/>
      <geometry>
        <mesh filename="package://roboy_models/roboy_2_0_head_simplified/meshes/CAD/head.stl" scale="0.001 0.001 0.001"/>
      </geometry>
    </collision>
    <visual name="head_visual">
      <origin rpy="0  0  0" xyz="0       0.04735  0.00223"/>
      <geometry>
        <mesh filename="package://roboy_models/roboy_2_0_head_simplified/meshes/CAD/head.stl" scale="0.001 0.001 0.001"/>
      </geometry>
    </visual>
  </link>
  <link name="torso">
    <inertial>
      <mass value="15.19643184820694"/>
      <origin rpy="0  0  0" xyz="-0.005    0.5984  -0.00567"/>
      <inertia ixx="7.149288915311806" ixy="0.05145516205284005" ixz="0.04998115873744463" iyy="0.33522698206645624" iyz="-0.00036564929950994913" izz="7.215981643618872"/>
    </inertial>
    <collision name="torso_collision">
      <origin rpy="0  0  0" xyz="-0.005    0.5984  -0.00567"/>
      <geometry>
        <mesh filename="package://roboy_models/roboy_2_0_head_simplified/meshes/CAD/torso.stl" scale="0.001 0.001 0.001"/>
      </geometry>
    </collision>
    <visual name="torso_visual">
      <origin rpy="0  0  0" xyz="-0.005    0.5984  -0.00567"/>
      <geometry>
        <mesh filename="package://roboy_models/roboy_2_0_head_simplified/meshes/CAD/torso.stl" scale="0.001 0.001 0.001"/>
      </geometry>
    </visual>
  </link>
  <link name="neck_link_3">
    <inertial>
      <mass value="0.1"/>
      <origin rpy="0  0  0" xyz="-0.00406  0.011    0"/>
        <inertia ixx="0.1" ixy="0.0" ixz="0.0" iyy="0.1" iyz="0.0" izz="0.1"/>
    </inertial>
    <collision name="neck_link_3_collision">
      <origin rpy="0  0  0" xyz="-0.00406  0.011    0"/>
      <geometry>
        <mesh filename="package://roboy_models/roboy_2_0_head_simplified/meshes/CAD/neck_link_3.stl" scale="0.001 0.001 0.001"/>
      </geometry>
    </collision>
    <visual name="neck_link_3_visual">
      <origin rpy="0  0  0" xyz="-0.00406  0.011    0"/>
      <geometry>
        <mesh filename="package://roboy_models/roboy_2_0_head_simplified/meshes/CAD/neck_link_3.stl" scale="0.001 0.001 0.001"/>
      </geometry>
    </visual>
  </link>
  <link name="neck_link_2">
    <inertial>
        <mass value="0.1"/>
        <origin rpy="0  0  0" xyz="0.004  0     0"/>
        <inertia ixx="0.1" ixy="0.0" ixz="0.0" iyy="0.1" iyz="0.0" izz="0.1"/>
    </inertial>
    <collision name="neck_link_2_collision">
      <origin rpy="0  0  0" xyz="0.004  0     0"/>
      <geometry>
        <mesh filename="package://roboy_models/roboy_2_0_head_simplified/meshes/CAD/neck_link_2.stl" scale="0.001 0.001 0.001"/>
      </geometry>
    </collision>
    <visual name="neck_link_2_visual">
      <origin rpy="0  0  0" xyz="0.004  0     0"/>
      <geometry>
        <mesh filename="package://roboy_models/roboy_2_0_head_simplified/meshes/CAD/neck_link_2.stl" scale="0.001 0.001 0.001"/>
      </geometry>
    </visual>
  </link>
</robot>
