<?xml version="1.0" ?>
<sdf version="1.5">
	<model name="robot">
		<link name="rootX">
			<pose>0.0 0.0 0.0 0.0 -0.0 0.0</pose>
			<inertial>
				<mass>1.0</mass>
				<pose>0 0 0 0 0 0</pose>
				<inertia>
					<ixx>1.0</ixx>
					<ixy>0.0</ixy>
					<ixz>0.0</ixz>
					<iyy>1.0</iyy>
					<iyz>0.0</iyz>
					<izz>1.0</izz>
				</inertia>
			</inertial>
			<visual name="VIS_Cube">
				<pose>0.0 0.0 0.0 -1.5707963705062866 -0.0 0.0</pose>
				<geometry>
					<mesh>
						<uri>model://robot25/meshes/visual/VIS_Cube.dae</uri>
					</mesh>
				</geometry>
			</visual>
		</link>
		<link name="child1">
			<pose>0.0 0.0 0.0 0.0 -0.0 0.0</pose>
			<inertial>
				<mass>1.0</mass>
				<pose>0 0 0 0 0 0</pose>
				<inertia>
					<ixx>1.0</ixx>
					<ixy>0.0</ixy>
					<ixz>0.0</ixz>
					<iyy>1.0</iyy>
					<iyz>0.0</iyz>
					<izz>1.0</izz>
				</inertia>
			</inertial>
		</link>
		<link name="child2">
			<pose>0.0 0.0 0.0 0.0 -0.0 0.0</pose>
			<inertial>
				<mass>1.0</mass>
				<pose>0 0 0 0 0 0</pose>
				<inertia>
					<ixx>1.0</ixx>
					<ixy>0.0</ixy>
					<ixz>0.0</ixz>
					<iyy>1.0</iyy>
					<iyz>0.0</iyz>
					<izz>1.0</izz>
				</inertia>
			</inertial>
		</link>
		<link name="child2b">
			<pose>0.0 0.0 0.0 0.0 -0.0 0.0</pose>
			<inertial>
				<mass>1.0</mass>
				<pose>0 0 0 0 0 0</pose>
				<inertia>
					<ixx>1.0</ixx>
					<ixy>0.0</ixy>
					<ixz>0.0</ixz>
					<iyy>1.0</iyy>
					<iyz>0.0</iyz>
					<izz>1.0</izz>
				</inertia>
			</inertial>
		</link>
		<joint name="child1" type="revolute">
			<parent>rootX</parent>
			<child>child1</child>
			<axis>
				<xyz>0.0 0.0 1.0</xyz>
				<use_parent_model_frame>true</use_parent_model_frame>
				<limit>
					<lower>-1.5707963267948966</lower>
					<upper>1.5707963267948966</upper>
				</limit>
			</axis>
		</joint>
		<joint name="child2" type="revolute">
			<parent>child1</parent>
			<child>child2</child>
			<axis>
				<xyz>0.0 0.0 1.0</xyz>
				<use_parent_model_frame>true</use_parent_model_frame>
				<limit>
					<lower>-1.5707963267948966</lower>
					<upper>1.5707963267948966</upper>
				</limit>
			</axis>
		</joint>
		<joint name="child2b" type="revolute">
			<parent>child1</parent>
			<child>child2b</child>
			<axis>
				<xyz>0.0 0.0 1.0</xyz>
				<use_parent_model_frame>true</use_parent_model_frame>
				<limit>
					<lower>-1.5707963267948966</lower>
					<upper>1.5707963267948966</upper>
				</limit>
			</axis>
		</joint>
	</model>
</sdf>
