<?xml version="1.0" ?>
<sdf version="1.6">
	<model name="roboy_head_n1">
		<link name="torso">
			<self_collide>false</self_collide>
			<pose frame="">2.715578361398044e-05 5.0269559445188826e-05 0.039112063721334675 0.0 -0.0 0.0</pose>
			<inertial>
				<pose frame="">0.0 0.0 0.0 0 0 0</pose>
				<mass>2.8182226276900506</mass>
				<inertia>
					<ixx>0.00920044628505286</ixx>
					<ixy>-0.00010266233228603997</ixy>
					<ixz>-5.068213757466779e-06</ixz>
					<iyy>0.02921337638211357</iyy>
					<iyz>-2.7385913299349453e-06</iyz>
					<izz>0.02876136555162473</izz>
				</inertia>
			</inertial>
			<collision name="torso_collision">
				<geometry>
					<mesh>
						<uri>model://roboy_head_n1/meshes/CAD/torso.stl</uri>
						<scale>0.001 0.001 0.001</scale>
					</mesh>
				</geometry>
			</collision>
			<visual name="torso_visual">
				<geometry>
					<mesh>
						<uri>model://roboy_head_n1/meshes/CAD/torso.stl</uri>
						<scale>0.001 0.001 0.001</scale>
					</mesh>
				</geometry>
			</visual>
		</link>
		<link name="head">
			<self_collide>false</self_collide>
			<pose frame="">-0.0009784526167496209 -0.0034283386307003842 0.12751898921723873 0.0 -0.0 0.0</pose>
			<inertial>
				<pose frame="">0.0 0.0 0.0 0 0 0</pose>
				<mass>4.447937855398802</mass>
				<inertia>
					<ixx>0.2549505961019082</ixx>
					<ixy>2.164538614556499e-05</ixy>
					<ixz>0.025585053799151495</ixz>
					<iyy>0.2440812599112836</iyy>
					<iyz>0.0014855207294459567</iyz>
					<izz>0.04219081483270649</izz>
				</inertia>
			</inertial>
			<collision name="head_collision">
				<geometry>
					<mesh>
						<uri>model://roboy_head_n1/meshes/CAD/head.stl</uri>
						<scale>0.001 0.001 0.001</scale>
					</mesh>
				</geometry>
			</collision>
			<visual name="head_visual">
				<geometry>
					<mesh>
						<uri>model://roboy_head_n1/meshes/CAD/head.stl</uri>
						<scale>0.001 0.001 0.001</scale>
					</mesh>
				</geometry>
			</visual>
		</link>
		<link name="sphere_link1">
			<self_collide>false</self_collide>
			<pose frame="">-5.604056462918166e-18 -1.234792101998918e-18 0.08600000000000002 0.0 -0.0 0.0</pose>
			<inertial>
				<pose frame="">0.0 0.0 0.0 0 0 0</pose>
				<mass>0.011414575959381956</mass>
				<inertia>
					<ixx>8.499192814490792e-05</ixx>
					<ixy>-4.282598581317743e-22</ixy>
					<ixz>8.673617379884036e-22</ixz>
					<iyy>8.499192814490792e-05</iyy>
					<iyz>2.6020852139652107e-21</iyz>
					<izz>5.697243493189931e-07</izz>
				</inertia>
			</inertial>
			<collision name="sphere_link1_collision">
				<geometry>
					<mesh>
						<uri>model://roboy_head_n1/meshes/CAD/sphere_link1.stl</uri>
						<scale>0.001 0.001 0.001</scale>
					</mesh>
				</geometry>
			</collision>
			<visual name="sphere_link1_visual">
				<geometry>
					<mesh>
						<uri>model://roboy_head_n1/meshes/CAD/sphere_link1.stl</uri>
						<scale>0.001 0.001 0.001</scale>
					</mesh>
				</geometry>
			</visual>
		</link>
		<link name="shere_link2">
			<self_collide>false</self_collide>
			<pose frame="">1.140664646607983e-17 -3.4170623364457646e-11 0.08599999995033868 0.0 -0.0 0.0</pose>
			<inertial>
				<pose frame="">0.0 0.0 0.0 0 0 0</pose>
				<mass>0.007651528005590793</mass>
				<inertia>
					<ixx>5.6848063069270376e-05</ixx>
					<ixy>1.0299920638612292e-22</ixy>
					<ixz>2.4323716435112332e-14</ixz>
					<iyy>5.6848063072644474e-05</iyy>
					<iyz>-9.367506770274759e-21</iyz>
					<izz>2.5736200669141965e-07</izz>
				</inertia>
			</inertial>
			<collision name="shere_link2_collision">
				<geometry>
					<mesh>
						<uri>model://roboy_head_n1/meshes/CAD/shere_link2.stl</uri>
						<scale>0.001 0.001 0.001</scale>
					</mesh>
				</geometry>
			</collision>
			<visual name="shere_link2_visual">
				<geometry>
					<mesh>
						<uri>model://roboy_head_n1/meshes/CAD/shere_link2.stl</uri>
						<scale>0.001 0.001 0.001</scale>
					</mesh>
				</geometry>
			</visual>
		</link>
		<joint name="sphere_axis0" type="revolute">
			<parent>torso</parent>
			<child>sphere_link1</child>
			<pose frame="">5.604056462918166e-18 1.234792101998918e-18 -1.7763568394002505e-17 0 0 0</pose>
			<axis>
				<xyz>1.0 0.0 0.0</xyz>
				<limit>
					<lower>-3.141592653589793</lower>
					<upper>3.141592653589793</upper>
				</limit>
				<use_parent_model_frame>0</use_parent_model_frame>
			</axis>
		</joint>
		<joint name="sphere_axis2" type="revolute">
			<parent>shere_link2</parent>
			<child>head</child>
			<pose frame="">0.0009784526167496209 0.0034283386307003842 -0.04151898921723872 0 0 0</pose>
			<axis>
				<xyz>0.0 0.0 1.0</xyz>
				<limit>
					<lower>-3.141592653589793</lower>
					<upper>3.141592653589793</upper>
				</limit>
				<use_parent_model_frame>0</use_parent_model_frame>
			</axis>
		</joint>
		<joint name="sphere_axis1" type="revolute">
			<parent>sphere_link1</parent>
			<child>shere_link2</child>
			<pose frame="">-1.140664646607983e-17 3.4170623364457646e-11 4.96613239420185e-11 0 0 0</pose>
			<axis>
				<xyz>0.0 -1.0 0.0</xyz>
				<limit>
					<lower>-3.141592653589793</lower>
					<upper>3.141592653589793</upper>
				</limit>
				<use_parent_model_frame>0</use_parent_model_frame>
			</axis>
		</joint>
		<plugin filename="libmusc_plugin.so" name="musc_plugin">
			<myoMuscle name="motor1">
				<link name="torso">
					<viaPoint type="FIXPOINT">-0.05358839537892295 0.0003226171093922606 0.011387936546886097</viaPoint>
				</link>
				<link name="head">
					<viaPoint type="FIXPOINT">-2.1547383250379998e-05 0.053428338630700366 -0.0430189892172387</viaPoint>
				</link>
			</myoMuscle>
			<myoMuscle name="motor2">
				<link name="torso">
					<viaPoint type="FIXPOINT">-0.053400240145459694 0.0502501116525012 0.0113879385139305</viaPoint>
				</link>
				<link name="head">
					<viaPoint type="FIXPOINT">-0.03537688644257775 0.038783677690027746 -0.0430189892172387</viaPoint>
				</link>
			</myoMuscle>
			<myoMuscle name="motor0">
				<link name="torso">
					<viaPoint type="FIXPOINT">-0.05365150360342555 -0.04961649420268938 0.011387938513930482</viaPoint>
				</link>
				<link name="head">
					<viaPoint type="FIXPOINT">-0.03537688644257777 -0.03192700042862702 -0.04301898921723872</viaPoint>
				</link>
			</myoMuscle>
			<myoMuscle name="motor5">
				<link name="torso">
					<viaPoint type="FIXPOINT">0.05373122460909098 0.05008771086325833 0.011387938513930518</viaPoint>
				</link>
				<link name="head">
					<viaPoint type="FIXPOINT">0.03533379167607702 0.038783677690027746 -0.0430189892172387</viaPoint>
				</link>
			</myoMuscle>
			<myoMuscle name="motor3">
				<link name="torso">
					<viaPoint type="FIXPOINT">0.053425769157142505 -0.04962152967611314 0.011387938513930482</viaPoint>
				</link>
				<link name="head">
					<viaPoint type="FIXPOINT">0.03533379167607701 -0.031927000428627034 -0.04301898921723872</viaPoint>
				</link>
			</myoMuscle>
			<myoMuscle name="motor4">
				<link name="torso">
					<viaPoint type="FIXPOINT">0.05357065240144661 0.0005484341403558182 0.011387936546886248</viaPoint>
				</link>
				<link name="head">
					<viaPoint type="FIXPOINT">-2.1547383250379998e-05 0.053428338630700366 -0.0430189892172387</viaPoint>
				</link>
			</myoMuscle>
		</plugin>
	</model>
</sdf>
