<?xml version="1.0" ?>
<sdf version="1.6">
	<model name="roboy_head_n1">
		<link name="torso">
			<self_collide>false</self_collide>
			<pose frame="">0.0 0.0 0.018000000000000082 0.0 -0.0 0.0</pose>
			<inertial>
				<pose frame="">0.0 0.0 0.0 0 0 0</pose>
				<mass>2.8170542694004315</mass>
				<inertia>
					<ixx>0.009196642593315553</ixx>
					<ixy>-0.00010265601750131497</ixy>
					<ixz>-5.064097456116601e-06</ixz>
					<iyy>0.02919952797512435</iyy>
					<iyz>-2.73679539643961e-06</iyz>
					<izz>0.02874745599050461</izz>
				</inertia>
			</inertial>
			<collision name="torso_collision">
				<geometry>
					<mesh>
						<uri>model://roboy_head_n1/meshes/CAD/torso.stl</uri>
						<scale>0.001 0.001 0.001</scale>
					</mesh>
				</geometry>
			</collision>
			<visual name="torso_visual">
				<geometry>
					<mesh>
						<uri>model://roboy_head_n1/meshes/CAD/torso.stl</uri>
						<scale>0.001 0.001 0.001</scale>
					</mesh>
				</geometry>
			</visual>
		</link>
		<link name="head">
			<self_collide>false</self_collide>
			<pose frame="">-0.0012864651230326135 -0.018938663567331 0.2208447129872736 0.0 -0.0 0.0</pose>
			<inertial>
				<pose frame="">0.0 0.0 0.0 0 0 0</pose>
				<mass>3.3845008321022276</mass>
				<inertia>
					<ixx>0.21518385906925128</ixx>
					<ixy>2.1730969157770015e-05</ixy>
					<ixz>0.017305167719458055</ixz>
					<iyy>0.21072138440262836</iyy>
					<iyz>0.0014851909087189455</iyz>
					<izz>0.030171420523955834</izz>
				</inertia>
			</inertial>
			<collision name="head_collision">
				<geometry>
					<mesh>
						<uri>model://roboy_head_n1/meshes/CAD/head.stl</uri>
						<scale>0.001 0.001 0.001</scale>
					</mesh>
				</geometry>
			</collision>
			<visual name="head_visual">
				<geometry>
					<mesh>
						<uri>model://roboy_head_n1/meshes/CAD/head.stl</uri>
						<scale>0.001 0.001 0.001</scale>
					</mesh>
				</geometry>
			</visual>
		</link>
		<link name="sphere_link1">
			<self_collide>false</self_collide>
			<pose frame="">-5.604056462918166e-18 -1.234792101998918e-18 0.08600000000000002 0.0 -0.0 0.0</pose>
			<inertial>
				<pose frame="">0.0 0.0 0.0 0 0 0</pose>
				<mass>0.011414575959381956</mass>
				<inertia>
					<ixx>8.499192814490792e-05</ixx>
					<ixy>-4.282598581317743e-22</ixy>
					<ixz>8.673617379884036e-22</ixz>
					<iyy>8.499192814490792e-05</iyy>
					<iyz>2.6020852139652107e-21</iyz>
					<izz>5.697243493189931e-07</izz>
				</inertia>
			</inertial>
			<collision name="sphere_link1_collision">
				<geometry>
					<mesh>
						<uri>model://roboy_head_n1/meshes/CAD/sphere_link1.stl</uri>
						<scale>0.001 0.001 0.001</scale>
					</mesh>
				</geometry>
			</collision>
			<visual name="sphere_link1_visual">
				<geometry>
					<mesh>
						<uri>model://roboy_head_n1/meshes/CAD/sphere_link1.stl</uri>
						<scale>0.001 0.001 0.001</scale>
					</mesh>
				</geometry>
			</visual>
		</link>
		<link name="shere_link2">
			<self_collide>false</self_collide>
			<pose frame="">1.140664646607983e-17 -3.4170623364457646e-11 0.08599999995033868 0.0 -0.0 0.0</pose>
			<inertial>
				<pose frame="">0.0 0.0 0.0 0 0 0</pose>
				<mass>0.007651528005590793</mass>
				<inertia>
					<ixx>5.6848063069270376e-05</ixx>
					<ixy>1.0299920638612292e-22</ixy>
					<ixz>2.4323716435112332e-14</ixz>
					<iyy>5.6848063072644474e-05</iyy>
					<iyz>-9.367506770274759e-21</iyz>
					<izz>2.5736200669141965e-07</izz>
				</inertia>
			</inertial>
			<collision name="shere_link2_collision">
				<geometry>
					<mesh>
						<uri>model://roboy_head_n1/meshes/CAD/shere_link2.stl</uri>
						<scale>0.001 0.001 0.001</scale>
					</mesh>
				</geometry>
			</collision>
			<visual name="shere_link2_visual">
				<geometry>
					<mesh>
						<uri>model://roboy_head_n1/meshes/CAD/shere_link2.stl</uri>
						<scale>0.001 0.001 0.001</scale>
					</mesh>
				</geometry>
			</visual>
		</link>
		<joint name="sphere_axis0" type="revolute">
			<parent>torso</parent>
			<child>sphere_link1</child>
			<pose frame="">5.604056462918166e-18 1.234792101998918e-18 -1.7763568394002505e-17 0 0 0</pose>
			<axis>
				<xyz>1.0 0.0 0.0</xyz>
				<limit>
					<lower>-3.141592653589793</lower>
					<upper>3.141592653589793</upper>
				</limit>
				<use_parent_model_frame>0</use_parent_model_frame>
			</axis>
		</joint>
		<joint name="sphere_axis2" type="revolute">
			<parent>shere_link2</parent>
			<child>head</child>
			<pose frame="">0.0012864651230326135 0.018938663567331 -0.1348447129872736 0 0 0</pose>
			<axis>
				<xyz>0.0 0.0 1.0</xyz>
				<limit>
					<lower>-3.141592653589793</lower>
					<upper>3.141592653589793</upper>
				</limit>
				<use_parent_model_frame>0</use_parent_model_frame>
			</axis>
		</joint>
		<joint name="sphere_axis1" type="revolute">
			<parent>sphere_link1</parent>
			<child>shere_link2</child>
			<pose frame="">-1.140664646607983e-17 3.4170623364457646e-11 4.96613239420185e-11 0 0 0</pose>
			<axis>
				<xyz>0.0 -1.0 0.0</xyz>
				<limit>
					<lower>-3.141592653589793</lower>
					<upper>3.141592653589793</upper>
				</limit>
				<use_parent_model_frame>0</use_parent_model_frame>
			</axis>
		</joint>
		<plugin filename="libmusc_plugin.so" name="musc_plugin">
			<myoMuscle name="motor1">
				<link name="torso">
					<viaPoint type="FIXPOINT">-0.053561239595308965 0.00037288666883744935 0.03250000026822069</viaPoint>
				</link>
				<link name="head">
					<viaPoint type="FIXPOINT">0.00028646512303261265 0.06893866356733098 -0.13634471298727358</viaPoint>
				</link>
			</myoMuscle>
			<myoMuscle name="motor2">
				<link name="torso">
					<viaPoint type="FIXPOINT">-0.053373084361845714 0.05030038121194639 0.03250000223526509</viaPoint>
				</link>
				<link name="head">
					<viaPoint type="FIXPOINT">-0.03506887393629476 0.05429400262665836 -0.13634471298727358</viaPoint>
				</link>
			</myoMuscle>
			<myoMuscle name="motor0">
				<link name="torso">
					<viaPoint type="FIXPOINT">-0.05362434781981157 -0.04956622464324419 0.03250000223526508</viaPoint>
				</link>
				<link name="head">
					<viaPoint type="FIXPOINT">-0.03506887393629477 -0.016416675491996408 -0.1363447129872736</viaPoint>
				</link>
			</myoMuscle>
			<myoMuscle name="motor5">
				<link name="torso">
					<viaPoint type="FIXPOINT">0.05375838039270496 0.050137980422703524 0.03250000223526511</viaPoint>
				</link>
				<link name="head">
					<viaPoint type="FIXPOINT">0.03564180418236001 0.05429400262665836 -0.13634471298727358</viaPoint>
				</link>
			</myoMuscle>
			<myoMuscle name="motor3">
				<link name="torso">
					<viaPoint type="FIXPOINT">0.053452924940756485 -0.04957126011666795 0.03250000223526508</viaPoint>
				</link>
				<link name="head">
					<viaPoint type="FIXPOINT">0.03564180418236 -0.016416675491996414 -0.1363447129872736</viaPoint>
				</link>
			</myoMuscle>
			<myoMuscle name="motor4">
				<link name="torso">
					<viaPoint type="FIXPOINT">0.053597808185060596 0.000598703699801007 0.03250000026822084</viaPoint>
				</link>
				<link name="head">
					<viaPoint type="FIXPOINT">0.00028646512303261265 0.06893866356733098 -0.13634471298727358</viaPoint>
				</link>
			</myoMuscle>
		</plugin>
	</model>
</sdf>
