<?xml version="1.0" ?>
<sdf version="1.6">
	<model name="Roboy2.0_Upper_Body_Xylophone_simplified">
		<link name="torso">
			<pose frame="">0.0 0.0 0.0 1.5707963267948966 -0.0 0.0</pose>
			<inertial>
				<pose frame="">0.02494441213202311 0.30446255653838167 -0.07596034001837408 0 0 0</pose>
				<mass>44.366372631254045</mass>
				<inertia>
					<ixx>5.084329765240959</ixx>
					<ixy>-0.33732459114401914</ixy>
					<ixz>0.9977462527957461</ixz>
					<iyy>1.4262743714156474</iyy>
					<iyz>0.08470612375751892</iyz>
					<izz>5.776260803502761</izz>
				</inertia>
			</inertial>
			<collision name="torso_collision">
				<geometry>
					<mesh>
						<uri>model://Roboy2.0_Upper_Body_Xylophone_simplified/meshes/CAD/torso.stl</uri>
						<scale>0.001 0.001 0.001</scale>
					</mesh>
				</geometry>
			</collision>
			<visual name="torso_visual">
				<geometry>
					<mesh>
						<uri>model://Roboy2.0_Upper_Body_Xylophone_simplified/meshes/CAD/torso.stl</uri>
						<scale>0.001 0.001 0.001</scale>
					</mesh>
				</geometry>
			</visual>
		</link>
		<link name="lower_arm_left">
			<pose frame="">0.0 0.0 0.0 1.5707963267948966 -0.0 0.0</pose>
			<inertial>
				<pose frame="">0.4218585748056636 0.044155354486449 0.07021743780370533 0 0 0</pose>
				<mass>11.160292042396323</mass>
				<inertia>
					<ixx>0.13863092402174093</ixx>
					<ixy>-0.20792778439810883</ixy>
					<ixz>-0.035014054733443364</ixz>
					<iyy>2.1030819822194555</iyy>
					<iyz>-0.33027512471872805</iyz>
					<izz>2.0180132317934367</izz>
				</inertia>
			</inertial>
			<collision name="lower_arm_left_collision">
				<geometry>
					<mesh>
						<uri>model://Roboy2.0_Upper_Body_Xylophone_simplified/meshes/CAD/lower_arm_left.stl</uri>
						<scale>0.001 0.001 0.001</scale>
					</mesh>
				</geometry>
			</collision>
			<visual name="lower_arm_left_visual">
				<geometry>
					<mesh>
						<uri>model://Roboy2.0_Upper_Body_Xylophone_simplified/meshes/CAD/lower_arm_left.stl</uri>
						<scale>0.001 0.001 0.001</scale>
					</mesh>
				</geometry>
			</visual>
		</link>
		<link name="lower_arm_right">
			<pose frame="">0.0 0.0 0.0 1.5707963267948966 -0.0 0.0</pose>
			<inertial>
				<pose frame="">-0.3966056601809948 0.05476547096355852 0.07701303620710433 0 0 0</pose>
				<mass>10.567468714534456</mass>
				<inertia>
					<ixx>0.14679805754758138</ixx>
					<ixy>0.22953405119229475</ixy>
					<ixz>-0.04461785983037274</ixz>
					<iyy>1.7773313493338534</iyy>
					<iyz>0.3227271403829937</iyz>
					<izz>1.7036616036475114</izz>
				</inertia>
			</inertial>
			<collision name="lower_arm_right_collision">
				<geometry>
					<mesh>
						<uri>model://Roboy2.0_Upper_Body_Xylophone_simplified/meshes/CAD/lower_arm_right.stl</uri>
						<scale>0.001 0.001 0.001</scale>
					</mesh>
				</geometry>
			</collision>
			<visual name="lower_arm_right_visual">
				<geometry>
					<mesh>
						<uri>model://Roboy2.0_Upper_Body_Xylophone_simplified/meshes/CAD/lower_arm_right.stl</uri>
						<scale>0.001 0.001 0.001</scale>
					</mesh>
				</geometry>
			</visual>
		</link>
		<link name="upper_arm_right">
			<pose frame="">0.0 0.0 0.0 1.5707963267948966 -0.0 0.0</pose>
			<inertial>
				<pose frame="">-0.3436821284798914 0.2019303915482636 -0.0750748857737886 0 0 0</pose>
				<mass>14.701878299666145</mass>
				<inertia>
					<ixx>0.7418453402357069</ixx>
					<ixy>1.0044608608343297</ixy>
					<ixz>0.222798393738411</ixz>
					<iyy>1.8629733841419163</iyy>
					<iyz>-0.3790820618114177</iyz>
					<izz>2.3858683555717057</izz>
				</inertia>
			</inertial>
			<collision name="upper_arm_right_collision">
				<geometry>
					<mesh>
						<uri>model://Roboy2.0_Upper_Body_Xylophone_simplified/meshes/CAD/upper_arm_right.stl</uri>
						<scale>0.001 0.001 0.001</scale>
					</mesh>
				</geometry>
			</collision>
			<visual name="upper_arm_right_visual">
				<geometry>
					<mesh>
						<uri>model://Roboy2.0_Upper_Body_Xylophone_simplified/meshes/CAD/upper_arm_right.stl</uri>
						<scale>0.001 0.001 0.001</scale>
					</mesh>
				</geometry>
			</visual>
		</link>
		<link name="upper_arm_left">
			<pose frame="">0.0 0.0 0.0 1.5707963267948966 -0.0 0.0</pose>
			<inertial>
				<pose frame="">0.3838654723969493 0.18838995681585718 -0.07500129431339037 0 0 0</pose>
				<mass>15.762170028675348</mass>
				<inertia>
					<ixx>0.7228069763964793</ixx>
					<ixy>-1.122776601393155</ixy>
					<ixz>0.22270263074125546</ixz>
					<iyy>2.4537374048817195</iyy>
					<iyz>0.4540855554837279</iyz>
					<izz>2.945221048755521</izz>
				</inertia>
			</inertial>
			<collision name="upper_arm_left_collision">
				<geometry>
					<mesh>
						<uri>model://Roboy2.0_Upper_Body_Xylophone_simplified/meshes/CAD/upper_arm_left.stl</uri>
						<scale>0.001 0.001 0.001</scale>
					</mesh>
				</geometry>
			</collision>
			<visual name="upper_arm_left_visual">
				<geometry>
					<mesh>
						<uri>model://Roboy2.0_Upper_Body_Xylophone_simplified/meshes/CAD/upper_arm_left.stl</uri>
						<scale>0.001 0.001 0.001</scale>
					</mesh>
				</geometry>
			</visual>
		</link>
		<link name="xylophone">
			<pose frame="">0.0 0.0 0.0 1.5707963267948966 -0.0 0.0</pose>
			<inertial>
				<pose frame="">0.08542006905058443 0.05810365371245605 0.41016486313194 0 0 0</pose>
				<mass>16.89336568245832</mass>
				<inertia>
					<ixx>3.1714799998266447</ixx>
					<ixy>-0.04085639136195328</ixy>
					<ixz>-0.3934851016105787</ixz>
					<iyy>3.8136085768896035</iyy>
					<iyz>-0.5937715789869452</iyz>
					<izz>1.1943205265853776</izz>
				</inertia>
			</inertial>
			<collision name="xylophone_collision">
				<geometry>
					<mesh>
						<uri>model://Roboy2.0_Upper_Body_Xylophone_simplified/meshes/CAD/xylophone.stl</uri>
						<scale>0.001 0.001 0.001</scale>
					</mesh>
				</geometry>
			</collision>
			<visual name="xylophone_visual">
				<geometry>
					<mesh>
						<uri>model://Roboy2.0_Upper_Body_Xylophone_simplified/meshes/CAD/xylophone.stl</uri>
						<scale>0.001 0.001 0.001</scale>
					</mesh>
				</geometry>
			</visual>
		</link>
		<link name="head">
			<pose frame="">0.0 0.0 0.0 1.5707963267948966 -0.0 0.0</pose>
			<inertial>
				<pose frame="">0.026117252197405454 0.6445895428517184 -0.07955038899526541 0 0 0</pose>
				<mass>19.451383457723413</mass>
				<inertia>
					<ixx>8.449661011283913</ixx>
					<ixy>-0.3300412477283012</ixy>
					<ixz>1.0028274528099066</ixz>
					<iyy>0.32714376051840144</iyy>
					<iyz>0.0397787258565029</iyz>
					<izz>8.357433654381174</izz>
				</inertia>
			</inertial>
			<collision name="head_collision">
				<geometry>
					<mesh>
						<uri>model://Roboy2.0_Upper_Body_Xylophone_simplified/meshes/CAD/head.stl</uri>
						<scale>0.001 0.001 0.001</scale>
					</mesh>
				</geometry>
			</collision>
			<visual name="head_visual">
				<geometry>
					<mesh>
						<uri>model://Roboy2.0_Upper_Body_Xylophone_simplified/meshes/CAD/head.stl</uri>
						<scale>0.001 0.001 0.001</scale>
					</mesh>
				</geometry>
			</visual>
		</link>
		<joint name="shoulder_left" type="ball">
			<parent>torso</parent>
			<child>upper_arm_left</child>
			<pose frame="">0.31699999999999934 0.33219733006283036 -0.07501511820306705 0 0 0</pose>
		</joint>
		<joint name="shoulder_right" type="ball">
			<parent>torso</parent>
			<child>upper_arm_right</child>
			<pose frame="">-0.2669999999999994 0.33219733006283036 -0.07501511820306705 0 0 0</pose>
		</joint>
		<joint name="torso_xylophone" type="fixed">
			<parent>torso</parent>
			<child>xylophone</child>
			<pose frame="">0.025 0.06 -0.07499999999999997 0 0 0</pose>
		</joint>
		<joint name="neck" type="revolute">
			<parent>torso</parent>
			<child>head</child>
			<pose frame="">0.024999999999999967 0.510514627904387 -0.07500000000000012 0 0 0</pose>
			<axis>
				<xyz>-0.9999999999999993 1.2246467991473505e-16 -6.123233995736772e-17</xyz>
				<limit>
					<lower>-0.5235987755982988</lower>
					<upper>-0.0</upper>
				</limit>
				<use_parent_model_frame>0</use_parent_model_frame>
			</axis>
		</joint>
		<joint name="elbow_right" type="revolute">
			<parent>upper_arm_right</parent>
			<child>lower_arm_right</child>
			<pose frame="">-0.37823672288337945 0.05176763999042153 -0.07001511820344772 0 0 0</pose>
			<axis>
				<xyz>-0.9063077870366526 0.422618261740698 1.3526011560063936e-15</xyz>
				<limit>
					<lower>-0.0</lower>
					<upper>1.5707963267948966</upper>
				</limit>
				<use_parent_model_frame>0</use_parent_model_frame>
			</axis>
		</joint>
		<joint name="elbow_left" type="revolute">
			<parent>upper_arm_left</parent>
			<child>lower_arm_left</child>
			<pose frame="">0.3955729268951643 0.040301073233661486 -0.07001511820830639 0 0 0</pose>
			<axis>
				<xyz>-0.9396926207859089 -0.34202014332566577 5.218270874272637e-18</xyz>
				<limit>
					<lower>-0.0</lower>
					<upper>1.5707963267948966</upper>
				</limit>
				<use_parent_model_frame>0</use_parent_model_frame>
			</axis>
		</joint>
		<plugin filename="libmyomuscle_plugin.so" name="myomuscle_plugin">
			<myoMuscle name="motor0">
				<link name="torso">
					<viaPoint type="FIXPOINT">-0.2624999999999994 0.3587079775594231 -0.05622911820307104</viaPoint>
				</link>
				<link name="upper_arm_right">
					<viaPoint type="FIXPOINT">-0.3052234048314776 0.2960681418205898 -0.05210933995740811</viaPoint>
				</link>
			</myoMuscle>
			<myoMuscle name="motor1">
				<link name="torso">
					<viaPoint type="FIXPOINT">-0.21425355454762707 0.2488961215106018 -0.04635792192137814</viaPoint>
				</link>
				<link name="upper_arm_right">
					<viaPoint type="FIXPOINT">-0.27142244372662644 0.2803064948043986 -0.05725325347277762</viaPoint>
				</link>
			</myoMuscle>
			<myoMuscle name="motor10">
				<link name="torso">
					<viaPoint type="FIXPOINT">0.27467742946426194 0.2961985770354281 -0.11326492580401734</viaPoint>
				</link>
				<link name="upper_arm_left">
					<viaPoint type="FIXPOINT">0.3360713175268411 0.28710247898103164 -0.10491095153640036</viaPoint>
				</link>
			</myoMuscle>
			<myoMuscle name="motor11">
				<link name="torso">
					<viaPoint type="FIXPOINT">0.3035266226867993 0.3399579775594231 -0.11078735460920125</viaPoint>
				</link>
				<link name="upper_arm_left">
					<viaPoint type="FIXPOINT">0.3519290870000086 0.2928742350511198 -0.09792089644872873</viaPoint>
				</link>
			</myoMuscle>
			<myoMuscle name="motor12">
				<link name="torso">
					<viaPoint type="FIXPOINT">0.3035266226867993 0.3399579775594231 -0.03924288179693285</viaPoint>
				</link>
				<link name="upper_arm_left">
					<viaPoint type="FIXPOINT">0.3618170200998233 0.29647314837786787 -0.07251728928467488</viaPoint>
				</link>
			</myoMuscle>
			<myoMuscle name="motor13">
				<link name="torso">
					<viaPoint type="FIXPOINT">0.274677429464261 0.296198577035435 -0.04157992864415353</viaPoint>
				</link>
				<link name="upper_arm_left">
					<viaPoint type="FIXPOINT">0.3337241261242424 0.2862481711763602 -0.045015118203067014</viaPoint>
				</link>
			</myoMuscle>
			<myoMuscle name="motor14">
				<link name="torso">
					<viaPoint type="FIXPOINT">0.264253554547627 0.2488961215106018 -0.04635792192137814</viaPoint>
				</link>
				<link name="upper_arm_left">
					<viaPoint type="FIXPOINT">0.3178011437285923 0.2804526795435988 -0.05751136957056986</viaPoint>
				</link>
			</myoMuscle>
			<myoMuscle name="motor15">
				<link name="torso">
					<viaPoint type="FIXPOINT">0.31249999999999933 0.3587079775594231 -0.05622911820307104</viaPoint>
				</link>
				<link name="upper_arm_left">
					<viaPoint type="FIXPOINT">0.35524851691505044 0.29408240873492775 -0.05564180349028178</viaPoint>
				</link>
			</myoMuscle>
			<myoMuscle name="motor16">
				<link name="upper_arm_left">
					<viaPoint type="FIXPOINT">0.38107885453327073 0.15874532603413094 -0.010634563165491108</viaPoint>
				</link>
				<link name="lower_arm_left">
					<viaPoint type="FIXPOINT">0.4216210664901475 0.04446093184186633 0.19298488179169518</viaPoint>
				</link>
			</myoMuscle>
			<myoMuscle name="motor17">
				<link name="upper_arm_left">
					<viaPoint type="FIXPOINT">0.38560751992549186 0.16039362543785152 -0.13939567323016447</viaPoint>
				</link>
				<link name="lower_arm_left">
					<viaPoint type="FIXPOINT">0.41946331069324333 0.019689370968846084 -0.08171514126227301</viaPoint>
					<viaPoint type="FIXPOINT">0.4338995622963907 0.010726041869345426 -0.05146959085948637</viaPoint>
				</link>
			</myoMuscle>
			<myoMuscle name="motor18">
				<link name="upper_arm_right">
					<viaPoint type="FIXPOINT">-0.3503201270823888 0.16702692976008862 -0.010634563175972951</viaPoint>
				</link>
				<link name="lower_arm_right">
					<viaPoint type="FIXPOINT">-0.39657272357997403 0.05480096794053291 0.19298488179654935</viaPoint>
				</link>
			</myoMuscle>
			<myoMuscle name="motor19">
				<link name="upper_arm_right">
					<viaPoint type="FIXPOINT">-0.3459523533880261 0.1649902034373195 -0.13939567324064622</viaPoint>
				</link>
				<link name="lower_arm_right">
					<viaPoint type="FIXPOINT">-0.4156146260100581 0.03881059302265426 -0.08171514125744246</viaPoint>
					<viaPoint type="FIXPOINT">-0.408406035148094 0.029424349390156826 -0.04601511820348161</viaPoint>
				</link>
			</myoMuscle>
			<myoMuscle name="motor2">
				<link name="torso">
					<viaPoint type="FIXPOINT">-0.22467742946426103 0.296198577035435 -0.04157992864415353</viaPoint>
				</link>
				<link name="upper_arm_right">
					<viaPoint type="FIXPOINT">-0.2854097484274984 0.28682888210336255 -0.04525321393795082</viaPoint>
				</link>
			</myoMuscle>
			<myoMuscle name="motor20">
				<link name="torso">
					<viaPoint type="FIXPOINT">0.07624511014858434 0.47218967966872677 -0.1184775928671928</viaPoint>
				</link>
				<link name="head">
					<viaPoint type="FIXPOINT">0.07476406017740031 0.5246755284819655 -0.08535407659967521</viaPoint>
				</link>
			</myoMuscle>
			<myoMuscle name="motor21">
				<link name="torso">
					<viaPoint type="FIXPOINT">0.07630415696557233 0.4719933669758296 -0.030484126496023476</viaPoint>
				</link>
				<link name="head">
					<viaPoint type="FIXPOINT">0.07476406017740032 0.5198722338833004 -0.058113239267997926</viaPoint>
				</link>
			</myoMuscle>
			<myoMuscle name="motor22">
				<link name="torso">
					<viaPoint type="FIXPOINT">-0.02555953786004804 0.470811155606576 -0.11315941019947079</viaPoint>
				</link>
				<link name="head">
					<viaPoint type="FIXPOINT">-0.024764060177399703 0.524872490032568 -0.08531934696414174</viaPoint>
				</link>
			</myoMuscle>
			<myoMuscle name="motor23">
				<link name="torso">
					<viaPoint type="FIXPOINT">-0.025897548204351244 0.4696873741006191 -0.030897007852793125</viaPoint>
				</link>
				<link name="head">
					<viaPoint type="FIXPOINT">-0.024764060177399686 0.5200691954339027 -0.05807850963246446</viaPoint>
				</link>
			</myoMuscle>
			<myoMuscle name="motor3">
				<link name="torso">
					<viaPoint type="FIXPOINT">-0.2535266226867994 0.3399579775594231 -0.03924288179693285</viaPoint>
				</link>
				<link name="upper_arm_right">
					<viaPoint type="FIXPOINT">-0.31476004539652136 0.30051515034914145 -0.07751294712146212</viaPoint>
				</link>
			</myoMuscle>
			<myoMuscle name="motor4">
				<link name="torso">
					<viaPoint type="FIXPOINT">-0.2535266226867994 0.3399579775594231 -0.11078735460920125</viaPoint>
				</link>
				<link name="upper_arm_right">
					<viaPoint type="FIXPOINT">-0.30522340483147803 0.2960681418205903 -0.0979208964487329</viaPoint>
				</link>
			</myoMuscle>
			<myoMuscle name="motor5">
				<link name="torso">
					<viaPoint type="FIXPOINT">-0.22467742946426203 0.2961985770354281 -0.11326492580401734</viaPoint>
				</link>
				<link name="upper_arm_right">
					<viaPoint type="FIXPOINT">-0.2854097484274974 0.2868288821033624 -0.10477702246818822</viaPoint>
				</link>
			</myoMuscle>
			<myoMuscle name="motor6">
				<link name="torso">
					<viaPoint type="FIXPOINT">-0.21425355454762607 0.24889612151060203 -0.12204291908124164</viaPoint>
				</link>
				<link name="upper_arm_right">
					<viaPoint type="FIXPOINT">-0.2877003789792368 0.2890003985906046 -0.08500235362592751</viaPoint>
				</link>
			</myoMuscle>
			<myoMuscle name="motor7">
				<link name="torso">
					<viaPoint type="FIXPOINT">-0.26196938381224405 0.35940959284851176 -0.09306232393058546</viaPoint>
				</link>
				<link name="upper_arm_right">
					<viaPoint type="FIXPOINT">-0.3147600453965214 0.30051515034914145 -0.07251728928467784</viaPoint>
				</link>
			</myoMuscle>
			<myoMuscle name="motor8">
				<link name="torso">
					<viaPoint type="FIXPOINT">0.311969383812244 0.35940959284851176 -0.09306232393058546</viaPoint>
				</link>
				<link name="lower_arm_right">
					<viaPoint type="FIXPOINT">0.3618170200998233 0.29647314837786787 -0.07751294712145915</viaPoint>
				</link>
			</myoMuscle>
			<myoMuscle name="motor9">
				<link name="torso">
					<viaPoint type="FIXPOINT">0.264253554547626 0.24889612151060203 -0.12204291908124164</viaPoint>
				</link>
				<link name="upper_arm_left">
					<viaPoint type="FIXPOINT">0.3178011437285923 0.2804526795435988 -0.09251886683556418</viaPoint>
				</link>
			</myoMuscle>
		</plugin>
	</model>
</sdf>
