<?xml version="1.0" ?>
<sdf version="1.6">
	<model name="Roboy2.0_Upper_Body_Xylophone_simplified">
		<link name="torso">
			<pose frame="">0.0171072270884182 -0.07282429789700436 -0.007384132961275871 3.141592653589793 -0.0 0.0</pose>
			<inertial>
				<pose frame="">0.024944412132023235 0.30446255702690134 -0.07596034001837398 0 0 0</pose>
				<mass>44.366401554455614</mass>
				<inertia>
					<ixx>5.084329779543895</ixx>
					<ixy>-0.33732459157758143</ixy>
					<ixz>0.9977462543376078</ixz>
					<iyy>1.426274371415649</iyy>
					<iyz>0.08470612375751883</iyz>
					<izz>5.776260817805694</izz>
				</inertia>
			</inertial>
			<collision name="torso_collision">
				<geometry>
					<mesh>
						<uri>model://Roboy2.0_Upper_Body_Xylophone_simplified/meshes/CAD/torso.stl</uri>
						<scale>0.001 0.001 0.001</scale>
					</mesh>
				</geometry>
			</collision>
			<visual name="torso_visual">
				<geometry>
					<mesh>
						<uri>model://Roboy2.0_Upper_Body_Xylophone_simplified/meshes/CAD/torso.stl</uri>
						<scale>0.001 0.001 0.001</scale>
					</mesh>
				</geometry>
			</visual>
		</link>
		<link name="lower_arm_left">
			<pose frame="">0.376834965263582 -0.044159643074456495 -0.12823461346172402 3.141592653589793 -0.0 0.0</pose>
			<inertial>
				<pose frame="">0.4218585748056638 0.044155354486449055 0.07021743780370543 0 0 0</pose>
				<mass>11.160292042397005</mass>
				<inertia>
					<ixx>0.13863092402174101</ixx>
					<ixy>-0.2079277843981089</ixy>
					<ixz>-0.03501405473344339</ixz>
					<iyy>2.1030819822194555</iyy>
					<iyz>-0.33027512471872833</iyz>
					<izz>2.0180132317934376</izz>
				</inertia>
			</inertial>
			<collision name="lower_arm_left_collision">
				<geometry>
					<mesh>
						<uri>model://Roboy2.0_Upper_Body_Xylophone_simplified/meshes/CAD/lower_arm_left.stl</uri>
						<scale>0.001 0.001 0.001</scale>
					</mesh>
				</geometry>
			</collision>
			<visual name="lower_arm_left_visual">
				<geometry>
					<mesh>
						<uri>model://Roboy2.0_Upper_Body_Xylophone_simplified/meshes/CAD/lower_arm_left.stl</uri>
						<scale>0.001 0.001 0.001</scale>
					</mesh>
				</geometry>
			</visual>
		</link>
		<link name="lower_arm_right">
			<pose frame="">-0.4000408136107143 -0.054763271309809784 -0.019997393022703876 3.141592653589793 -0.0 0.0</pose>
			<inertial>
				<pose frame="">-0.3966056601809948 0.054765470963558535 0.07701303620710433 0 0 0</pose>
				<mass>10.56746871453503</mass>
				<inertia>
					<ixx>0.14679805754758138</ixx>
					<ixy>0.22953405119229478</ixy>
					<ixz>-0.04461785983037275</ixz>
					<iyy>1.7773313493338534</iyy>
					<iyz>0.3227271403829937</iyz>
					<izz>1.7036616036475116</izz>
				</inertia>
			</inertial>
			<collision name="lower_arm_right_collision">
				<geometry>
					<mesh>
						<uri>model://Roboy2.0_Upper_Body_Xylophone_simplified/meshes/CAD/lower_arm_right.stl</uri>
						<scale>0.001 0.001 0.001</scale>
					</mesh>
				</geometry>
			</collision>
			<visual name="lower_arm_right_visual">
				<geometry>
					<mesh>
						<uri>model://Roboy2.0_Upper_Body_Xylophone_simplified/meshes/CAD/lower_arm_right.stl</uri>
						<scale>0.001 0.001 0.001</scale>
					</mesh>
				</geometry>
			</visual>
		</link>
		<link name="upper_arm_right">
			<pose frame="">0.0005715205076527562 -0.11867654943011129 0.02425851851562387 3.141592653589793 -0.0 0.0</pose>
			<inertial>
				<pose frame="">-0.343682128477569 0.20193039155258788 -0.07507488354152014 0 0 0</pose>
				<mass>14.701877801271605</mass>
				<inertia>
					<ixx>0.7418453354202262</ixx>
					<ixy>1.004460860966377</ixy>
					<ixz>0.2227983843809847</ixz>
					<iyy>1.862973379407515</iyy>
					<iyz>-0.3790820518855856</iyz>
					<izz>2.3858683558479927</izz>
				</inertia>
			</inertial>
			<collision name="upper_arm_right_collision">
				<geometry>
					<mesh>
						<uri>model://Roboy2.0_Upper_Body_Xylophone_simplified/meshes/CAD/upper_arm_right.stl</uri>
						<scale>0.001 0.001 0.001</scale>
					</mesh>
				</geometry>
			</collision>
			<visual name="upper_arm_right_visual">
				<geometry>
					<mesh>
						<uri>model://Roboy2.0_Upper_Body_Xylophone_simplified/meshes/CAD/upper_arm_right.stl</uri>
						<scale>0.001 0.001 0.001</scale>
					</mesh>
				</geometry>
			</visual>
		</link>
		<link name="upper_arm_left">
			<pose frame="">0.17185854880457854 -0.11729431601539941 0.025003717729237346 3.141592653589793 -0.0 0.0</pose>
			<inertial>
				<pose frame="">0.38386547239695057 0.18838995681585388 -0.07500129434617261 0 0 0</pose>
				<mass>15.762158879848903</mass>
				<inertia>
					<ixx>0.7228069764740275</ixx>
					<ixy>-1.122776601393209</ixy>
					<ixz>0.22270263087879827</ixz>
					<iyy>2.453737404959412</iyy>
					<iyz>0.4540855556477728</iyz>
					<izz>2.945221048755704</izz>
				</inertia>
			</inertial>
			<collision name="upper_arm_left_collision">
				<geometry>
					<mesh>
						<uri>model://Roboy2.0_Upper_Body_Xylophone_simplified/meshes/CAD/upper_arm_left.stl</uri>
						<scale>0.001 0.001 0.001</scale>
					</mesh>
				</geometry>
			</collision>
			<visual name="upper_arm_left_visual">
				<geometry>
					<mesh>
						<uri>model://Roboy2.0_Upper_Body_Xylophone_simplified/meshes/CAD/upper_arm_left.stl</uri>
						<scale>0.001 0.001 0.001</scale>
					</mesh>
				</geometry>
			</visual>
		</link>
		<link name="xylophone">
			<pose frame="">0.04814391635740023 0.0 0.0 3.141592653589793 -0.0 0.0</pose>
			<inertial>
				<pose frame="">0.08542006905058443 0.05810365371245605 0.41016486313194 0 0 0</pose>
				<mass>16.893365682458292</mass>
				<inertia>
					<ixx>3.1714799998266447</ixx>
					<ixy>-0.04085639136195328</ixy>
					<ixz>-0.3934851016105787</ixz>
					<iyy>3.8136085768896035</iyy>
					<iyz>-0.5937715789869452</iyz>
					<izz>1.1943205265853776</izz>
				</inertia>
			</inertial>
			<collision name="xylophone_collision">
				<geometry>
					<mesh>
						<uri>model://Roboy2.0_Upper_Body_Xylophone_simplified/meshes/CAD/xylophone.stl</uri>
						<scale>0.001 0.001 0.001</scale>
					</mesh>
				</geometry>
			</collision>
			<visual name="xylophone_visual">
				<geometry>
					<mesh>
						<uri>model://Roboy2.0_Upper_Body_Xylophone_simplified/meshes/CAD/xylophone.stl</uri>
						<scale>0.001 0.001 0.001</scale>
					</mesh>
				</geometry>
			</visual>
		</link>
		<link name="head">
			<pose frame="">0.012208050767255858 0.01803128381745022 0.016717933701993586 3.141592653589793 -0.0 0.0</pose>
			<inertial>
				<pose frame="">0.026117252197405495 0.64458954285172 -0.07955038899526548 0 0 0</pose>
				<mass>19.451397938736363</mass>
				<inertia>
					<ixx>8.44966101128403</ixx>
					<ixy>-0.33004124772830523</ixy>
					<ixz>1.0028274528099188</ixz>
					<iyy>0.32714376051839344</iyy>
					<iyz>0.03977872585650413</iyz>
					<izz>8.357433654381285</izz>
				</inertia>
			</inertial>
			<collision name="head_collision">
				<geometry>
					<mesh>
						<uri>model://Roboy2.0_Upper_Body_Xylophone_simplified/meshes/CAD/head.stl</uri>
						<scale>0.001 0.001 0.001</scale>
					</mesh>
				</geometry>
			</collision>
			<visual name="head_visual">
				<geometry>
					<mesh>
						<uri>model://Roboy2.0_Upper_Body_Xylophone_simplified/meshes/CAD/head.stl</uri>
						<scale>0.001 0.001 0.001</scale>
					</mesh>
				</geometry>
			</visual>
		</link>
		<joint name="shoulder_left" type="ball">
			<parent>torso</parent>
			<child>upper_arm_left</child>
			<pose frame="">0.33410722708841756 0.06763098524179119 0.40502162795983476 0 0 0</pose>
		</joint>
		<joint name="shoulder_right" type="ball">
			<parent>torso</parent>
			<child>upper_arm_right</child>
			<pose frame="">-0.24989277291158118 0.06763098524179119 0.40502162795983476 0 0 0</pose>
		</joint>
		<joint name="torso_xylophone" type="fixed">
			<parent>torso</parent>
			<child>xylophone</child>
			<pose frame="">0.04210722708841819 0.0676158670387241 0.13282429789700437 0 0 0</pose>
		</joint>
		<joint name="neck" type="revolute">
			<parent>torso</parent>
			<child>head</child>
			<pose frame="">0.04210722708841816 0.06761586703872424 0.5833389258013914 0 0 0</pose>
			<axis>
				<xyz>-0.9999999999999993 1.2246467991473505e-16 -6.123233995736772e-17</xyz>
				<limit>
					<lower>-0.5235987755982988</lower>
					<upper>-0.0</upper>
				</limit>
				<use_parent_model_frame>0</use_parent_model_frame>
			</axis>
		</joint>
		<joint name="elbow_right" type="revolute">
			<parent>upper_arm_right</parent>
			<child>lower_arm_right</child>
			<pose frame="">-0.3776652023757267 0.09427363671907159 0.1704441894205328 0 0 0</pose>
			<axis>
				<xyz>-0.9063077870366526 0.422618261740698 1.3526011560063936e-15</xyz>
				<limit>
					<lower>-0.0</lower>
					<upper>1.5707963267948966</upper>
				</limit>
				<use_parent_model_frame>0</use_parent_model_frame>
			</axis>
		</joint>
		<joint name="elbow_left" type="revolute">
			<parent>upper_arm_left</parent>
			<child>lower_arm_left</child>
			<pose frame="">0.5674314756997428 0.09501883593754373 0.15759538924906089 0 0 0</pose>
			<axis>
				<xyz>-0.9396926207859089 -0.34202014332566577 5.218270874272637e-18</xyz>
				<limit>
					<lower>-0.0</lower>
					<upper>1.5707963267948966</upper>
				</limit>
				<use_parent_model_frame>0</use_parent_model_frame>
			</axis>
		</joint>
		<plugin filename="libmyomuscle_plugin.so" name="myomuscle_plugin">
			<myoMuscle name="motor0">
				<link name="torso">
					<viaPoint type="FIXPOINT">-0.2624999999999994 0.05622911820307104 0.3587079775594231</viaPoint>
				</link>
				<link name="upper_arm_right">
					<viaPoint type="FIXPOINT">-0.3052234048314776 0.05210933995740811 0.2960681418205898</viaPoint>
				</link>
			</myoMuscle>
			<myoMuscle name="motor1">
				<link name="torso">
					<viaPoint type="FIXPOINT">-0.21425355454762707 0.04635792192137814 0.2488961215106018</viaPoint>
				</link>
				<link name="upper_arm_right">
					<viaPoint type="FIXPOINT">-0.27142244372662644 0.05725325347277762 0.2803064948043986</viaPoint>
				</link>
			</myoMuscle>
			<myoMuscle name="motor10">
				<link name="torso">
					<viaPoint type="FIXPOINT">0.27467742946426194 0.11326492580401734 0.2961985770354281</viaPoint>
				</link>
				<link name="upper_arm_left">
					<viaPoint type="FIXPOINT">0.3360713175268411 0.10491095153640036 0.28710247898103164</viaPoint>
				</link>
			</myoMuscle>
			<myoMuscle name="motor11">
				<link name="torso">
					<viaPoint type="FIXPOINT">0.3035266226867993 0.11078735460920125 0.3399579775594231</viaPoint>
				</link>
				<link name="upper_arm_left">
					<viaPoint type="FIXPOINT">0.3519290870000086 0.09792089644872873 0.2928742350511198</viaPoint>
				</link>
			</myoMuscle>
			<myoMuscle name="motor12">
				<link name="torso">
					<viaPoint type="FIXPOINT">0.3035266226867993 0.03924288179693285 0.3399579775594231</viaPoint>
				</link>
				<link name="upper_arm_left">
					<viaPoint type="FIXPOINT">0.3618170200998233 0.07251728928467488 0.29647314837786787</viaPoint>
				</link>
			</myoMuscle>
			<myoMuscle name="motor13">
				<link name="torso">
					<viaPoint type="FIXPOINT">0.274677429464261 0.04157992864415353 0.296198577035435</viaPoint>
				</link>
				<link name="upper_arm_left">
					<viaPoint type="FIXPOINT">0.3337241261242424 0.045015118203067014 0.2862481711763602</viaPoint>
				</link>
			</myoMuscle>
			<myoMuscle name="motor14">
				<link name="torso">
					<viaPoint type="FIXPOINT">0.264253554547627 0.04635792192137814 0.2488961215106018</viaPoint>
				</link>
				<link name="upper_arm_left">
					<viaPoint type="FIXPOINT">0.3178011437285923 0.05751136957056986 0.2804526795435988</viaPoint>
				</link>
			</myoMuscle>
			<myoMuscle name="motor15">
				<link name="torso">
					<viaPoint type="FIXPOINT">0.31249999999999933 0.05622911820307104 0.3587079775594231</viaPoint>
				</link>
				<link name="upper_arm_left">
					<viaPoint type="FIXPOINT">0.35524851691505044 0.05564180349028178 0.29408240873492775</viaPoint>
				</link>
			</myoMuscle>
			<myoMuscle name="motor16">
				<link name="upper_arm_left">
					<viaPoint type="FIXPOINT">0.38107885453327073 0.010634563165491108 0.15874532603413094</viaPoint>
				</link>
				<link name="lower_arm_left">
					<viaPoint type="FIXPOINT">0.4216210664901475 -0.19298488179169518 0.04446093184186633</viaPoint>
				</link>
			</myoMuscle>
			<myoMuscle name="motor17">
				<link name="upper_arm_left">
					<viaPoint type="FIXPOINT">0.38560751992549186 0.13939567323016447 0.16039362543785152</viaPoint>
				</link>
				<link name="lower_arm_left">
					<viaPoint type="FIXPOINT">0.41946331069324333 0.08171514126227301 0.019689370968846084</viaPoint>
					<viaPoint type="FIXPOINT">0.4338995622963907 0.05146959085948637 0.010726041869345426</viaPoint>
				</link>
			</myoMuscle>
			<myoMuscle name="motor18">
				<link name="upper_arm_right">
					<viaPoint type="FIXPOINT">-0.3503201270823888 0.010634563175972951 0.16702692976008862</viaPoint>
				</link>
				<link name="lower_arm_right">
					<viaPoint type="FIXPOINT">-0.39657272357997403 -0.19298488179654935 0.05480096794053291</viaPoint>
				</link>
			</myoMuscle>
			<myoMuscle name="motor19">
				<link name="upper_arm_right">
					<viaPoint type="FIXPOINT">-0.3459523533880261 0.13939567324064622 0.1649902034373195</viaPoint>
				</link>
				<link name="lower_arm_right">
					<viaPoint type="FIXPOINT">-0.4156146260100581 0.08171514125744246 0.03881059302265426</viaPoint>
					<viaPoint type="FIXPOINT">-0.408406035148094 0.04601511820348161 0.029424349390156826</viaPoint>
				</link>
			</myoMuscle>
			<myoMuscle name="motor2">
				<link name="torso">
					<viaPoint type="FIXPOINT">-0.22467742946426103 0.04157992864415353 0.296198577035435</viaPoint>
				</link>
				<link name="upper_arm_right">
					<viaPoint type="FIXPOINT">-0.2854097484274984 0.04525321393795082 0.28682888210336255</viaPoint>
				</link>
			</myoMuscle>
			<myoMuscle name="motor20">
				<link name="torso">
					<viaPoint type="FIXPOINT">0.07624511014858434 0.1184775928671928 0.47218967966872677</viaPoint>
				</link>
				<link name="head">
					<viaPoint type="FIXPOINT">0.07476406017740031 0.08535407659967521 0.5246755284819655</viaPoint>
				</link>
			</myoMuscle>
			<myoMuscle name="motor21">
				<link name="torso">
					<viaPoint type="FIXPOINT">0.07630415696557233 0.030484126496023476 0.4719933669758296</viaPoint>
				</link>
				<link name="head">
					<viaPoint type="FIXPOINT">0.07476406017740032 0.058113239267997926 0.5198722338833004</viaPoint>
				</link>
			</myoMuscle>
			<myoMuscle name="motor22">
				<link name="torso">
					<viaPoint type="FIXPOINT">-0.02555953786004804 0.11315941019947079 0.470811155606576</viaPoint>
				</link>
				<link name="head">
					<viaPoint type="FIXPOINT">-0.024764060177399703 0.08531934696414174 0.524872490032568</viaPoint>
				</link>
			</myoMuscle>
			<myoMuscle name="motor23">
				<link name="torso">
					<viaPoint type="FIXPOINT">-0.025897548204351244 0.030897007852793125 0.4696873741006191</viaPoint>
				</link>
				<link name="head">
					<viaPoint type="FIXPOINT">-0.024764060177399686 0.05807850963246446 0.5200691954339027</viaPoint>
				</link>
			</myoMuscle>
			<myoMuscle name="motor3">
				<link name="torso">
					<viaPoint type="FIXPOINT">-0.2535266226867994 0.03924288179693285 0.3399579775594231</viaPoint>
				</link>
				<link name="upper_arm_right">
					<viaPoint type="FIXPOINT">-0.31476004539652136 0.07751294712146212 0.30051515034914145</viaPoint>
				</link>
			</myoMuscle>
			<myoMuscle name="motor4">
				<link name="torso">
					<viaPoint type="FIXPOINT">-0.2535266226867994 0.11078735460920125 0.3399579775594231</viaPoint>
				</link>
				<link name="upper_arm_right">
					<viaPoint type="FIXPOINT">-0.30522340483147803 0.0979208964487329 0.2960681418205903</viaPoint>
				</link>
			</myoMuscle>
			<myoMuscle name="motor5">
				<link name="torso">
					<viaPoint type="FIXPOINT">-0.22467742946426203 0.11326492580401734 0.2961985770354281</viaPoint>
				</link>
				<link name="upper_arm_right">
					<viaPoint type="FIXPOINT">-0.2854097484274974 0.10477702246818822 0.2868288821033624</viaPoint>
				</link>
			</myoMuscle>
			<myoMuscle name="motor6">
				<link name="torso">
					<viaPoint type="FIXPOINT">-0.21425355454762607 0.12204291908124164 0.24889612151060203</viaPoint>
				</link>
				<link name="upper_arm_right">
					<viaPoint type="FIXPOINT">-0.2877003789792368 0.08500235362592751 0.2890003985906046</viaPoint>
				</link>
			</myoMuscle>
			<myoMuscle name="motor7">
				<link name="torso">
					<viaPoint type="FIXPOINT">-0.26196938381224405 0.09306232393058546 0.35940959284851176</viaPoint>
				</link>
				<link name="upper_arm_right">
					<viaPoint type="FIXPOINT">-0.3147600453965214 0.07251728928467784 0.30051515034914145</viaPoint>
				</link>
			</myoMuscle>
			<myoMuscle name="motor8">
				<link name="torso">
					<viaPoint type="FIXPOINT">0.311969383812244 0.09306232393058546 0.35940959284851176</viaPoint>
				</link>
				<link name="lower_arm_right">
					<viaPoint type="FIXPOINT">0.3618170200998233 0.07751294712145915 0.29647314837786787</viaPoint>
				</link>
			</myoMuscle>
			<myoMuscle name="motor9">
				<link name="torso">
					<viaPoint type="FIXPOINT">0.264253554547626 0.12204291908124164 0.24889612151060203</viaPoint>
				</link>
				<link name="upper_arm_left">
					<viaPoint type="FIXPOINT">0.3178011437285923 0.09251886683556418 0.2804526795435988</viaPoint>
				</link>
			</myoMuscle>
		</plugin>
	</model>
</sdf>
