<?xml version="1.0" ?>
<sdf version="1.6">
	<model name="6DOF_arm">
		<link name="base">
			<self_collide>false</self_collide>
			<pose frame="">0.0 0.0 0.0 0.0 -0.0 0.0</pose>
			<inertial>
				<pose frame="">0.0 0.0 0.0 0 0 0</pose>
				<mass>1000</mass>
				<inertia>
					<ixx>0.1</ixx>
					<ixy>0.0</ixy>
					<ixz>0.0</ixz>
					<iyy>0.1</iyy>
					<iyz>0.0</iyz>
					<izz>0.1</izz>
				</inertia>
			</inertial>
			<collision name="base_collision">
				<geometry>
					<mesh>
						<uri>model://6DOF_arm/meshes/CAD/base.stl</uri>
						<scale>0.001 0.001 0.001</scale>
					</mesh>
				</geometry>
			</collision>
			<visual name="base_visual">
				<geometry>
					<mesh>
						<uri>model://6DOF_arm/meshes/CAD/base.stl</uri>
						<scale>0.001 0.001 0.001</scale>
					</mesh>
				</geometry>
			</visual>
		</link>
		<link name="link0">
			<self_collide>false</self_collide>
			<pose frame="">0.0 0.0 0.02 0.0 -0.0 0.0</pose>
			<inertial>
				<pose frame="">0.0 0.0 0.0 0 0 0</pose>
				<mass>0.1</mass>
				<inertia>
					<ixx>0.1</ixx>
					<ixy>0.0</ixy>
					<ixz>0.0</ixz>
					<iyy>0.1</iyy>
					<iyz>0.0</iyz>
					<izz>0.1</izz>
				</inertia>
			</inertial>
			<collision name="link0_collision">
				<geometry>
					<mesh>
						<uri>model://6DOF_arm/meshes/CAD/link0.stl</uri>
						<scale>0.001 0.001 0.001</scale>
					</mesh>
				</geometry>
			</collision>
			<visual name="link0_visual">
				<geometry>
					<mesh>
						<uri>model://6DOF_arm/meshes/CAD/link0.stl</uri>
						<scale>0.001 0.001 0.001</scale>
					</mesh>
				</geometry>
			</visual>
		</link>
		<link name="link1">
			<self_collide>false</self_collide>
			<pose frame="">0.15 0.0 0.03 0.0 -0.0 0.0</pose>
			<inertial>
				<pose frame="">0.0 0.0 0.0 0 0 0</pose>
				<mass>0.1</mass>
				<inertia>
					<ixx>0.1</ixx>
					<ixy>0.0</ixy>
					<ixz>0.0</ixz>
					<iyy>0.1</iyy>
					<iyz>0.0</iyz>
					<izz>0.1</izz>
				</inertia>
			</inertial>
			<collision name="link1_collision">
				<geometry>
					<mesh>
						<uri>model://6DOF_arm/meshes/CAD/link1.stl</uri>
						<scale>0.001 0.001 0.001</scale>
					</mesh>
				</geometry>
			</collision>
			<visual name="link1_visual">
				<geometry>
					<mesh>
						<uri>model://6DOF_arm/meshes/CAD/link1.stl</uri>
						<scale>0.001 0.001 0.001</scale>
					</mesh>
				</geometry>
			</visual>
		</link>
		<link name="link2">
			<self_collide>false</self_collide>
			<pose frame="">0.035093333532153326 -0.09641814145298089 0.04 0.0 -0.0 0.0</pose>
			<inertial>
				<pose frame="">0.0 0.0 0.0 0 0 0</pose>
				<mass>0.1</mass>
				<inertia>
					<ixx>0.1</ixx>
					<ixy>0.0</ixy>
					<ixz>0.0</ixz>
					<iyy>0.1</iyy>
					<iyz>0.0</iyz>
					<izz>0.1</izz>
				</inertia>
			</inertial>
			<collision name="link2_collision">
				<geometry>
					<mesh>
						<uri>model://6DOF_arm/meshes/CAD/link2.stl</uri>
						<scale>0.001 0.001 0.001</scale>
					</mesh>
				</geometry>
			</collision>
			<visual name="link2_visual">
				<geometry>
					<mesh>
						<uri>model://6DOF_arm/meshes/CAD/link2.stl</uri>
						<scale>0.001 0.001 0.001</scale>
					</mesh>
				</geometry>
			</visual>
		</link>
		<link name="link4">
			<self_collide>false</self_collide>
			<pose frame="">-0.04944244929145149 -0.03547729840260427 0.3166941705973708 0.0 -0.0 0.0</pose>
			<inertial>
				<pose frame="">0.0 0.0 0.0 0 0 0</pose>
				<mass>0.1</mass>
				<inertia>
					<ixx>0.1</ixx>
					<ixy>0.0</ixy>
					<ixz>0.0</ixz>
					<iyy>0.1</iyy>
					<iyz>0.0</iyz>
					<izz>0.1</izz>
				</inertia>
			</inertial>
			<collision name="link4_collision">
				<geometry>
					<mesh>
						<uri>model://6DOF_arm/meshes/CAD/link4.stl</uri>
						<scale>0.001 0.001 0.001</scale>
					</mesh>
				</geometry>
			</collision>
			<visual name="link4_visual">
				<geometry>
					<mesh>
						<uri>model://6DOF_arm/meshes/CAD/link4.stl</uri>
						<scale>0.001 0.001 0.001</scale>
					</mesh>
				</geometry>
			</visual>
		</link>
		<link name="link5">
			<self_collide>false</self_collide>
			<pose frame="">-0.038270048942510765 -0.09157591939286722 0.4319532737715608 0.0 -0.0 0.0</pose>
			<inertial>
				<pose frame="">0.0 0.0 0.0 0 0 0</pose>
				<mass>0.1</mass>
				<inertia>
					<ixx>0.1</ixx>
					<ixy>0.0</ixy>
					<ixz>0.0</ixz>
					<iyy>0.1</iyy>
					<iyz>0.0</iyz>
					<izz>0.1</izz>
				</inertia>
			</inertial>
			<collision name="link5_collision">
				<geometry>
					<mesh>
						<uri>model://6DOF_arm/meshes/CAD/link5.stl</uri>
						<scale>0.001 0.001 0.001</scale>
					</mesh>
				</geometry>
			</collision>
			<visual name="link5_visual">
				<geometry>
					<mesh>
						<uri>model://6DOF_arm/meshes/CAD/link5.stl</uri>
						<scale>0.001 0.001 0.001</scale>
					</mesh>
				</geometry>
			</visual>
		</link>
		<link name="link3">
			<self_collide>false</self_collide>
			<pose frame="">-0.10979554041120702 -0.05759528468760276 0.14000000000000004 0.0 -0.0 0.0</pose>
			<inertial>
				<pose frame="">0.0 0.0 0.0 0 0 0</pose>
				<mass>0.1</mass>
				<inertia>
					<ixx>0.1</ixx>
					<ixy>0.0</ixy>
					<ixz>0.0</ixz>
					<iyy>0.1</iyy>
					<iyz>0.0</iyz>
					<izz>0.1</izz>
				</inertia>
			</inertial>
			<collision name="link3_collision">
				<geometry>
					<mesh>
						<uri>model://6DOF_arm/meshes/CAD/link3.stl</uri>
						<scale>0.001 0.001 0.001</scale>
					</mesh>
				</geometry>
			</collision>
			<visual name="link3_visual">
				<geometry>
					<mesh>
						<uri>model://6DOF_arm/meshes/CAD/link3.stl</uri>
						<scale>0.001 0.001 0.001</scale>
					</mesh>
				</geometry>
			</visual>
		</link>
		<joint name="joint0" type="revolute">
			<parent>base</parent>
			<child>link0</child>
			<pose frame="">0.0 0.0 -0.01 0 0 0</pose>
			<axis>
				<xyz>0.0 0.0 -1.0</xyz>
				<limit>
					<lower>-3.141592653589793</lower>
					<upper>3.141592653589793</upper>
				</limit>
				<use_parent_model_frame>0</use_parent_model_frame>
			</axis>
		</joint>
		<joint name="joint1" type="revolute">
			<parent>link0</parent>
			<child>link1</child>
			<pose frame="">0.0 0.0 -0.01 0 0 0</pose>
			<axis>
				<xyz>0.0 0.0 1.0</xyz>
				<limit>
					<lower>-3.141592653589793</lower>
					<upper>3.141592653589793</upper>
				</limit>
				<use_parent_model_frame>0</use_parent_model_frame>
			</axis>
		</joint>
		<joint name="joint2" type="revolute">
			<parent>link1</parent>
			<child>link2</child>
			<pose frame="">0.0 0.0 -0.01 0 0 0</pose>
			<axis>
				<xyz>0.0 0.0 1.0</xyz>
				<limit>
					<lower>-3.141592653589793</lower>
					<upper>3.141592653589793</upper>
				</limit>
				<use_parent_model_frame>0</use_parent_model_frame>
			</axis>
		</joint>
		<joint name="joint3" type="revolute">
			<parent>link2</parent>
			<child>link3</child>
			<pose frame="">5.329070518200751e-17 -3.552713678800501e-17 -0.10000000000000003 0 0 0</pose>
			<axis>
				<xyz>0.0 0.0 1.0</xyz>
				<limit>
					<lower>-3.141592653589793</lower>
					<upper>3.141592653589793</upper>
				</limit>
				<use_parent_model_frame>0</use_parent_model_frame>
			</axis>
		</joint>
		<joint name="joint4" type="revolute">
			<parent>link3</parent>
			<child>link4</child>
			<pose frame="">-0.06035309111975555 -0.022117986284998503 -0.07660495596341164 0 0 0</pose>
			<axis>
				<xyz>-0.34202014332567154 0.9396926207859064 -4.595957498144083e-16</xyz>
				<limit>
					<lower>-3.141592653589793</lower>
					<upper>3.141592653589793</upper>
				</limit>
				<use_parent_model_frame>0</use_parent_model_frame>
			</axis>
		</joint>
		<joint name="joint5" type="revolute">
			<parent>link4</parent>
			<child>link5</child>
			<pose frame="">0.04928376467721066 0.07810286553766731 -0.03858631648770363 0 0 0</pose>
			<axis>
				<xyz>-0.6930533810288743 0.6194725963584857 0.3686878264946125</xyz>
				<limit>
					<lower>-3.141592653589793</lower>
					<upper>3.141592653589793</upper>
				</limit>
				<use_parent_model_frame>0</use_parent_model_frame>
			</axis>
		</joint>

		<!--<plugin filename="libmoveit_plugin.so" name="moveit_plugin"></plugin>-->
		<plugin filename="libmusc_plugin.so" name="musc_plugin">
			<myoMuscle name="motor0">
				<link name="base">
					<viaPoint type="FIXPOINT">-0.3535533905932736 0.3535533905932738 0.23500000000000001</viaPoint>
				</link>
				<link name="link3">
					<viaPoint type="FIXPOINT">0.01887676909069857 0.015384004374797717 -0.07252237046363565</viaPoint>
				</link>
			</myoMuscle>
			<myoMuscle name="motor1">
				<link name="base">
					<viaPoint type="FIXPOINT">-0.49999999999999994 3.552713678800501e-17 0.23500000000000001</viaPoint>
				</link>
				<link name="link3">
					<viaPoint type="FIXPOINT">0.02545461743620008 0.01777814537807735 0.07909182690965107</viaPoint>
				</link>
			</myoMuscle>
			<myoMuscle name="motor2">
				<link name="base">
					<viaPoint type="FIXPOINT">-0.3535533905932738 -0.3535533905932738 0.23500000000000001</viaPoint>
				</link>
				<link name="link3">
					<viaPoint type="FIXPOINT">-0.03092693981095458 -0.0027430632214627336 -0.07252237046363558</viaPoint>
				</link>
			</myoMuscle>
			<myoMuscle name="motor3">
				<link name="base">
					<viaPoint type="FIXPOINT">7.105427357601002e-17 -0.4999999999999999 0.23500000000000001</viaPoint>
				</link>
				<link name="link3">
					<viaPoint type="FIXPOINT">-0.04314294388117123 -0.007189325084696483 0.07909182690965111</viaPoint>
				</link>
			</myoMuscle>
			<myoMuscle name="motor4">
				<link name="base">
					<viaPoint type="FIXPOINT">0.3535533905932736 -0.3535533905932738 0.23500000000000001</viaPoint>
				</link>
				<link name="link3">
					<viaPoint type="FIXPOINT">-0.013520891265131337 -0.015480135761085813 2.612588616361933e-06</viaPoint>
				</link>
			</myoMuscle>
			<myoMuscle name="motor5">
				<link name="base">
					<viaPoint type="FIXPOINT">0.4999999999999999 3.552713678800501e-17 0.23500000000000001</viaPoint>
				</link>
				<link name="link4">
					<viaPoint type="FIXPOINT">0.022324918590849334 0.023132578472214393 -0.024122824004097616</viaPoint>
				</link>
			</myoMuscle>
			<myoMuscle name="motor7">
				<link name="base">
					<viaPoint type="FIXPOINT">0.0 0.49999999999999994 0.23500000000000001</viaPoint>
				</link>
				<link name="link4">
					<viaPoint type="FIXPOINT">0.054134197004600065 0.0448398828329227 0.047809575573323715</viaPoint>
				</link>
			</myoMuscle>
			<myoMuscle name="motor8">
				<link name="base">
					<viaPoint type="FIXPOINT">0.0 0.49999999999999994 0.485</viaPoint>
				</link>
				<link name="link5">
					<viaPoint type="FIXPOINT">-0.013555337440477962 -0.009598158189616797 -0.03657546823082349</viaPoint>
				</link>
			</myoMuscle>
			<myoMuscle name="motor9">
				<link name="base">
					<viaPoint type="FIXPOINT">-0.3535533905932736 0.3535533905932738 0.485</viaPoint>
				</link>
				<link name="link5">
					<viaPoint type="FIXPOINT">-0.025357807925518738 -0.04918003170023283 0.056354901882654074</viaPoint>
				</link>
			</myoMuscle>
			<myoMuscle name="motor10">
				<link name="base">
					<viaPoint type="FIXPOINT">-0.49999999999999994 3.552713678800501e-17 0.485</viaPoint>
				</link>
				<link name="link5">
					<viaPoint type="FIXPOINT">0.05614150339446157 0.07024282523853935 0.00890062557275364</viaPoint>
				</link>
			</myoMuscle>
			<myoMuscle name="motor11">
				<link name="base">
					<viaPoint type="FIXPOINT">-0.3535533905932738 -0.3535533905932738 0.485</viaPoint>
				</link>
				<link name="link5">
					<viaPoint type="FIXPOINT">-0.05326324513207477 -0.05371917022656991 0.011525416097629915</viaPoint>
				</link>
			</myoMuscle>
			<myoMuscle name="motor12">
				<link name="base">
					<viaPoint type="FIXPOINT">7.105427357601002e-17 -0.4999999999999999 0.485</viaPoint>
				</link>
				<link name="link4">
					<viaPoint type="FIXPOINT">-0.06105356390893197 -0.03370827115421843 -0.03674119075132467</viaPoint>
				</link>
			</myoMuscle>
			<myoMuscle name="motor14">
				<link name="base">
					<viaPoint type="FIXPOINT">0.4999999999999999 -1.0658141036401502e-16 0.485</viaPoint>
				</link>
				<link name="link4">
					<viaPoint type="FIXPOINT">-0.04019865317547889 0.006232822193215775 -0.06464785233079795</viaPoint>
				</link>
			</myoMuscle>
			<myoMuscle name="motor15">
				<link name="base">
					<viaPoint type="FIXPOINT">0.3535533905932738 0.3535533905932736 0.485</viaPoint>
				</link>
				<link name="link3">
					<viaPoint type="FIXPOINT">0.040041588119665426 0.004015012408477316 2.6125886162908787e-06</viaPoint>
				</link>
			</myoMuscle>
			<endEffector link="link5" name="endeffector0">-0.049181493587140704 -0.07821440155553411 0.03865675979939539</endEffector>
		</plugin>
	</model>
</sdf>
