<?xml version="1.0" ?>
<sdf version="1.6">
	<model name="6DOF_arm">
		<link name="base">
			<self_collide>false</self_collide>
			<pose frame="">0.0 0.0 0.0 0.0 -0.0 0.0</pose>
			<inertial>
				<pose frame="">0.0 0.0 0.0 0 0 0</pose>
				<mass>0.1</mass>
				<inertia>
					<ixx>0.1</ixx>
					<ixy>0.0</ixy>
					<ixz>0.0</ixz>
					<iyy>0.1</iyy>
					<iyz>0.0</iyz>
					<izz>0.1</izz>
				</inertia>
			</inertial>
			<collision name="base_collision">
				<geometry>
					<mesh>
						<uri>model://6DOF_arm/meshes/CAD/base.stl</uri>
						<scale>0.001 0.001 0.001</scale>
					</mesh>
				</geometry>
			</collision>
			<visual name="base_visual">
				<geometry>
					<mesh>
						<uri>model://6DOF_arm/meshes/CAD/base.stl</uri>
						<scale>0.001 0.001 0.001</scale>
					</mesh>
				</geometry>
			</visual>
		</link>
		<link name="sphere_link2">
			<self_collide>false</self_collide>
			<pose frame="">0.0 0.0 0.028000000000000008 0.0 -0.0 0.0</pose>
			<inertial>
				<pose frame="">0.0 0.0 0.0 0 0 0</pose>
				<mass>0.1</mass>
				<inertia>
					<ixx>0.1</ixx>
					<ixy>0.0</ixy>
					<ixz>0.0</ixz>
					<iyy>0.1</iyy>
					<iyz>0.0</iyz>
					<izz>0.1</izz>
				</inertia>
			</inertial>
			<collision name="sphere_link2_collision">
				<geometry>
					<mesh>
						<uri>model://6DOF_arm/meshes/CAD/sphere_link2.stl</uri>
						<scale>0.001 0.001 0.001</scale>
					</mesh>
				</geometry>
			</collision>
			<visual name="sphere_link2_visual">
				<geometry>
					<mesh>
						<uri>model://6DOF_arm/meshes/CAD/sphere_link2.stl</uri>
						<scale>0.001 0.001 0.001</scale>
					</mesh>
				</geometry>
			</visual>
		</link>
		<link name="sphere_link1">
			<self_collide>false</self_collide>
			<pose frame="">0.0 0.0 0.028000000000000008 0.0 -0.0 0.0</pose>
			<inertial>
				<pose frame="">0.0 0.0 0.0 0 0 0</pose>
				<mass>0.1</mass>
				<inertia>
					<ixx>0.1</ixx>
					<ixy>0.0</ixy>
					<ixz>0.0</ixz>
					<iyy>0.1</iyy>
					<iyz>0.0</iyz>
					<izz>0.1</izz>
				</inertia>
			</inertial>
			<collision name="sphere_link1_collision">
				<geometry>
					<mesh>
						<uri>model://6DOF_arm/meshes/CAD/sphere_link1.stl</uri>
						<scale>0.001 0.001 0.001</scale>
					</mesh>
				</geometry>
			</collision>
			<visual name="sphere_link1_visual">
				<geometry>
					<mesh>
						<uri>model://6DOF_arm/meshes/CAD/sphere_link1.stl</uri>
						<scale>0.001 0.001 0.001</scale>
					</mesh>
				</geometry>
			</visual>
		</link>
		<link name="sphere_link0">
			<self_collide>false</self_collide>
			<pose frame="">0.0 0.0 0.028000000000000008 0.0 -0.0 0.0</pose>
			<inertial>
				<pose frame="">0.0 0.0 0.0 0 0 0</pose>
				<mass>0.1</mass>
				<inertia>
					<ixx>0.1</ixx>
					<ixy>0.0</ixy>
					<ixz>0.0</ixz>
					<iyy>0.1</iyy>
					<iyz>0.0</iyz>
					<izz>0.1</izz>
				</inertia>
			</inertial>
			<collision name="sphere_link0_collision">
				<geometry>
					<mesh>
						<uri>model://6DOF_arm/meshes/CAD/sphere_link0.stl</uri>
						<scale>0.001 0.001 0.001</scale>
					</mesh>
				</geometry>
			</collision>
			<visual name="sphere_link0_visual">
				<geometry>
					<mesh>
						<uri>model://6DOF_arm/meshes/CAD/sphere_link0.stl</uri>
						<scale>0.001 0.001 0.001</scale>
					</mesh>
				</geometry>
			</visual>
		</link>
		<link name="sphere_link4">
			<self_collide>false</self_collide>
			<pose frame="">0.0 -0.08682817558290781 0.0888018744480523 0.0 -0.0 0.0</pose>
			<inertial>
				<pose frame="">0.0 0.0 0.0 0 0 0</pose>
				<mass>0.1</mass>
				<inertia>
					<ixx>0.1</ixx>
					<ixy>0.0</ixy>
					<ixz>0.0</ixz>
					<iyy>0.1</iyy>
					<iyz>0.0</iyz>
					<izz>0.1</izz>
				</inertia>
			</inertial>
			<collision name="sphere_link4_collision">
				<geometry>
					<mesh>
						<uri>model://6DOF_arm/meshes/CAD/sphere_link4.stl</uri>
						<scale>0.001 0.001 0.001</scale>
					</mesh>
				</geometry>
			</collision>
			<visual name="sphere_link4_visual">
				<geometry>
					<mesh>
						<uri>model://6DOF_arm/meshes/CAD/sphere_link4.stl</uri>
						<scale>0.001 0.001 0.001</scale>
					</mesh>
				</geometry>
			</visual>
		</link>
		<link name="sphere_link5">
			<self_collide>false</self_collide>
			<pose frame="">0.0 -0.08682817558290781 0.0888018744480523 0.0 -0.0 0.0</pose>
			<inertial>
				<pose frame="">0.0 0.0 0.0 0 0 0</pose>
				<mass>0.1</mass>
				<inertia>
					<ixx>0.1</ixx>
					<ixy>0.0</ixy>
					<ixz>0.0</ixz>
					<iyy>0.1</iyy>
					<iyz>0.0</iyz>
					<izz>0.1</izz>
				</inertia>
			</inertial>
			<collision name="sphere_link5_collision">
				<geometry>
					<mesh>
						<uri>model://6DOF_arm/meshes/CAD/sphere_link5.stl</uri>
						<scale>0.001 0.001 0.001</scale>
					</mesh>
				</geometry>
			</collision>
			<visual name="sphere_link5_visual">
				<geometry>
					<mesh>
						<uri>model://6DOF_arm/meshes/CAD/sphere_link5.stl</uri>
						<scale>0.001 0.001 0.001</scale>
					</mesh>
				</geometry>
			</visual>
		</link>
		<link name="end_effector">
			<self_collide>false</self_collide>
			<pose frame="">0.0 -0.08682817558290781 0.0888018744480523 0.0 -0.0 0.0</pose>
			<inertial>
				<pose frame="">0.0 0.0 0.0 0 0 0</pose>
				<mass>0.1</mass>
				<inertia>
					<ixx>0.1</ixx>
					<ixy>0.0</ixy>
					<ixz>0.0</ixz>
					<iyy>0.1</iyy>
					<iyz>0.0</iyz>
					<izz>0.1</izz>
				</inertia>
			</inertial>
			<collision name="end_effector_collision">
				<geometry>
					<mesh>
						<uri>model://6DOF_arm/meshes/CAD/end_effector.stl</uri>
						<scale>0.001 0.001 0.001</scale>
					</mesh>
				</geometry>
			</collision>
			<visual name="end_effector_visual">
				<geometry>
					<mesh>
						<uri>model://6DOF_arm/meshes/CAD/end_effector.stl</uri>
						<scale>0.001 0.001 0.001</scale>
					</mesh>
				</geometry>
			</visual>
		</link>
		<joint name="sphere_axis0" type="revolute">
			<parent>sphere_link2</parent>
			<child>sphere_link4</child>
			<pose frame="">0.0 0.0 0.0 0 0 0</pose>
			<axis>
				<xyz>1.0 0.0 0.0</xyz>
				<limit>
					<lower>-3.141592653589793</lower>
					<upper>3.141592653589793</upper>
				</limit>
				<use_parent_model_frame>0</use_parent_model_frame>
			</axis>
		</joint>
		<joint name="sphere_axis2" type="revolute">
			<parent>sphere_link5</parent>
			<child>end_effector</child>
			<pose frame="">0.0 0.0 0.0 0 0 0</pose>
			<axis>
				<xyz>0.0 0.0 1.0</xyz>
				<limit>
					<lower>-3.141592653589793</lower>
					<upper>3.141592653589793</upper>
				</limit>
				<use_parent_model_frame>0</use_parent_model_frame>
			</axis>
		</joint>
		<joint name="sphere_axis1" type="revolute">
			<parent>sphere_link4</parent>
			<child>sphere_link5</child>
			<pose frame="">0.0 0.0 0.0 0 0 0</pose>
			<axis>
				<xyz>0.0 -1.0 0.0</xyz>
				<limit>
					<lower>-3.141592653589793</lower>
					<upper>3.141592653589793</upper>
				</limit>
				<use_parent_model_frame>0</use_parent_model_frame>
			</axis>
		</joint>
		<joint name="sphere_axis0" type="revolute">
			<parent>sphere_link2</parent>
			<child>sphere_link1</child>
			<pose frame="">0.0 0.0 0.0 0 0 0</pose>
			<axis>
				<xyz>1.0 0.0 0.0</xyz>
				<limit>
					<lower>-3.141592653589793</lower>
					<upper>3.141592653589793</upper>
				</limit>
				<use_parent_model_frame>0</use_parent_model_frame>
			</axis>
		</joint>
		<joint name="sphere_axis2" type="revolute">
			<parent>sphere_link0</parent>
			<child>base</child>
			<pose frame="">0.0 0.0 0.028000000000000008 0 0 0</pose>
			<axis>
				<xyz>0.0 0.0 -1.0</xyz>
				<limit>
					<lower>-3.141592653589793</lower>
					<upper>3.141592653589793</upper>
				</limit>
				<use_parent_model_frame>0</use_parent_model_frame>
			</axis>
		</joint>
		<joint name="sphere_axis1" type="revolute">
			<parent>sphere_link1</parent>
			<child>sphere_link0</child>
			<pose frame="">0.0 0.0 0.0 0 0 0</pose>
			<axis>
				<xyz>0.0 1.0 0.0</xyz>
				<limit>
					<lower>-3.141592653589793</lower>
					<upper>3.141592653589793</upper>
				</limit>
				<use_parent_model_frame>0</use_parent_model_frame>
			</axis>
		</joint>
		<plugin filename="libmusc_plugin.so" name="musc_plugin">
			<myoMuscle name="motor0">
				<link name="sphere_link2">
					<viaPoint type="FIXPOINT">0.0 0.14422205101855956 0.11199999999999999</viaPoint>
					<viaPoint type="FIXPOINT">-0.014000000000000002 -0.030000000447034835 0.02100000073015689</viaPoint>
				</link>
			</myoMuscle>
			<myoMuscle name="motor1">
				<link name="sphere_link2">
					<viaPoint type="FIXPOINT">-0.14422205101855956 0.0 0.177</viaPoint>
					<viaPoint type="FIXPOINT">-0.014000000000000002 -0.05900000087916851 0.04100000102818012</viaPoint>
				</link>
			</myoMuscle>
			<myoMuscle name="motor2">
				<link name="sphere_link2">
					<viaPoint type="FIXPOINT">0.14422205101855956 0.0 0.04699999999999999</viaPoint>
					<viaPoint type="FIXPOINT">0.014000000000000002 -0.030000000447034835 0.02100000073015689</viaPoint>
				</link>
			</myoMuscle>
			<myoMuscle name="motor3">
				<link name="sphere_link2">
					<viaPoint type="FIXPOINT">0.14422205101855956 0.0 0.177</viaPoint>
					<viaPoint type="FIXPOINT">0.014000000000000002 -0.05900000087916851 0.04100000102818012</viaPoint>
				</link>
			</myoMuscle>
			<myoMuscle name="motor4">
				<link name="end_effector">
					<viaPoint type="FIXPOINT">0.0 0.23105022660146737 0.1811981255519477</viaPoint>
					<viaPoint type="FIXPOINT">0.0 0.01 0.026100992011690315</viaPoint>
				</link>
			</myoMuscle>
			<myoMuscle name="motor5">
				<link name="end_effector">
					<viaPoint type="FIXPOINT">0.14422205101855956 0.08682817558290781 0.1811981255519477</viaPoint>
					<viaPoint type="FIXPOINT">0.0 0.01 0.062100992548132124</viaPoint>
				</link>
			</myoMuscle>
			<myoMuscle name="motor6">
				<link name="end_effector">
					<viaPoint type="FIXPOINT">-0.14422205101855956 0.08682817558290781 0.1811981255519477</viaPoint>
					<viaPoint type="FIXPOINT">0.0 0.010999999999999996 0.08366082502974273</viaPoint>
				</link>
			</myoMuscle>
			<myoMuscle name="motor7">
				<link name="end_effector">
					<viaPoint type="FIXPOINT">0.14422205101855956 0.08682817558290781 0.0511981255519477</viaPoint>
					<viaPoint type="FIXPOINT">0.014000000000000002 0.0 0.08366076195323131</viaPoint>
				</link>
			</myoMuscle>
			<myoMuscle name="motor8">
				<link name="end_effector">
					<viaPoint type="FIXPOINT">0.0 -0.05739387543565176 0.1161981255519477</viaPoint>
					<viaPoint type="FIXPOINT">0.0 -0.010999999999999996 0.08366082502974273</viaPoint>
				</link>
			</myoMuscle>
			<myoMuscle name="motor9">
				<link name="end_effector">
					<viaPoint type="FIXPOINT">-0.14422205101855956 0.08682817558290781 0.0511981255519477</viaPoint>
					<viaPoint type="FIXPOINT">-0.014000000000000002 0.0 0.08366076195323131</viaPoint>
				</link>
			</myoMuscle>
			<myoMuscle name="motor10">
				<link name="end_effector">
					<viaPoint type="FIXPOINT">0.0 -0.05739387543565176 0.0511981255519477</viaPoint>
					<viaPoint type="FIXPOINT">0.0 -0.01 0.062100992548132124</viaPoint>
				</link>
			</myoMuscle>
			<myoMuscle name="motor11">
				<link name="end_effector">
					<viaPoint type="FIXPOINT">0.0 -0.05739387543565176 -0.013801874448052302</viaPoint>
					<viaPoint type="FIXPOINT">0.0 -0.01 0.026100992011690315</viaPoint>
				</link>
			</myoMuscle>
			<endEffector link="end_effector" name="endeffector0">0.0 0.0 0.083</endEffector>
		</plugin>
	</model>
</sdf>
