<?xml version="1.0" ?>
<sdf version="1.6">
	<model name="roboy_2_0_left_arm_elbow">
		<link name="lower_arm_left">
			<pose frame="">0.10972190940178642 0.15088310595616336 0.00014627974945071565 0.0 -0.0 0.0</pose>
			<inertial>
				<pose frame="">0.0 0.0 0.0 0 0 0</pose>
				<mass>3.8582284060970817</mass>
				<inertia>
					<ixx>0.18971836897917466</ixx>
					<ixy>-0.030952823556496385</ixy>
					<ixz>0.038514077904953335</ixz>
					<iyy>0.144100962496475</iyy>
					<iyz>0.005118004224149041</iyz>
					<izz>0.08295756148743653</izz>
				</inertia>
			</inertial>
			<collision name="lower_arm_left_collision">
				<geometry>
					<mesh>
						<uri>model://roboy_2_0_left_arm_elbow/meshes/CAD/lower_arm_left.stl</uri>
						<scale>0.001 0.001 0.001</scale>
					</mesh>
				</geometry>
			</collision>
			<visual name="lower_arm_left_visual">
				<geometry>
					<mesh>
						<uri>model://roboy_2_0_left_arm_elbow/meshes/CAD/lower_arm_left.stl</uri>
						<scale>0.001 0.001 0.001</scale>
					</mesh>
				</geometry>
			</visual>
		</link>
		<link name="upper_arm_left">
			<pose frame="">0.2232479978786525 0.4137790891466708 -0.005836054937101297 0.0 -0.0 0.0</pose>
			<inertial>
				<pose frame="">0.0 0.0 0.0 0 0 0</pose>
				<mass>5.639369491411923</mass>
				<inertia>
					<ixx>1.057898280516026</ixx>
					<ixy>-0.5584768438259633</ixy>
					<ixz>0.015405487205218987</ixz>
					<iyy>0.3110322619089415</iyy>
					<iyz>0.008008248173405223</iyz>
					<izz>1.3498854800941886</izz>
				</inertia>
			</inertial>
			<collision name="upper_arm_left_collision">
				<geometry>
					<mesh>
						<uri>model://roboy_2_0_left_arm_elbow/meshes/CAD/upper_arm_left.stl</uri>
						<scale>0.001 0.001 0.001</scale>
					</mesh>
				</geometry>
			</collision>
			<visual name="upper_arm_left_visual">
				<geometry>
					<mesh>
						<uri>model://roboy_2_0_left_arm_elbow/meshes/CAD/upper_arm_left.stl</uri>
						<scale>0.001 0.001 0.001</scale>
					</mesh>
				</geometry>
			</visual>
		</link>
		<link name="torso">
			<pose frame="">-0.00499999999999861 0.04650000000000084 -0.005674885790744078 0.0 -0.0 0.0</pose>
			<inertial>
				<pose frame="">0.0 0.0 0.0 0 0 0</pose>
				<mass>1008.7023329334594</mass>
				<inertia>
					<ixx>200.83316516318143</ixx>
					<ixy>-0.20846990889102412</ixy>
					<ixz>-0.34181574811566934</ixz>
					<iyy>390.190150920655</iyy>
					<iyz>-0.4312515990482134</iyz>
					<izz>200.29462600005215</izz>
				</inertia>
			</inertial>
			<collision name="torso_collision">
				<geometry>
					<mesh>
						<uri>model://roboy_2_0_left_arm_elbow/meshes/CAD/torso.stl</uri>
						<scale>0.001 0.001 0.001</scale>
					</mesh>
				</geometry>
			</collision>
			<visual name="torso_visual">
				<geometry>
					<mesh>
						<uri>model://roboy_2_0_left_arm_elbow/meshes/CAD/torso.stl</uri>
						<scale>0.001 0.001 0.001</scale>
					</mesh>
				</geometry>
			</visual>
		</link>
		<link name="shoulder_left_link2">
			<pose frame="">0.2876048416483075 0.5944435631591347 -0.013042466787542933 0.0 -0.0 0.0</pose>
			<inertial>
				<pose frame="">0.0 0.0 0.0 0 0 0</pose>
				<mass>0.006828310129289385</mass>
				<inertia>
					<ixx>0.0024145799992969486</ixx>
					<ixy>-0.0011674897275754273</ixy>
					<ixz>5.294387202679595e-05</ixz>
					<iyy>0.0005663596265234957</iyy>
					<iyz>2.5605807844821626e-05</iyz>
					<izz>0.0029780439025690335</izz>
				</inertia>
			</inertial>
			<collision name="shoulder_left_link2_collision">
				<geometry>
					<mesh>
						<uri>model://roboy_2_0_left_arm_elbow/meshes/CAD/shoulder_left_link2.stl</uri>
						<scale>0.001 0.001 0.001</scale>
					</mesh>
				</geometry>
			</collision>
			<visual name="shoulder_left_link2_visual">
				<geometry>
					<mesh>
						<uri>model://roboy_2_0_left_arm_elbow/meshes/CAD/shoulder_left_link2.stl</uri>
						<scale>0.001 0.001 0.001</scale>
					</mesh>
				</geometry>
			</visual>
		</link>
		<link name="shoulder_left_link3">
			<pose frame="">0.2876048416483075 0.5944435631591348 -0.013042466787542941 0.0 -0.0 0.0</pose>
			<inertial>
				<pose frame="">0.0 0.0 0.0 0 0 0</pose>
				<mass>0.00591332996432232</mass>
				<inertia>
					<ixx>0.0020798217468755596</ixx>
					<ixy>-0.0010054463742006988</ixy>
					<ixz>4.545728721015062e-05</ixz>
					<iyy>0.00048752696840872773</iyy>
					<iyz>2.198779157620949e-05</iyz>
					<izz>0.0025651650656281387</izz>
				</inertia>
			</inertial>
			<collision name="shoulder_left_link3_collision">
				<geometry>
					<mesh>
						<uri>model://roboy_2_0_left_arm_elbow/meshes/CAD/shoulder_left_link3.stl</uri>
						<scale>0.001 0.001 0.001</scale>
					</mesh>
				</geometry>
			</collision>
			<visual name="shoulder_left_link3_visual">
				<geometry>
					<mesh>
						<uri>model://roboy_2_0_left_arm_elbow/meshes/CAD/shoulder_left_link3.stl</uri>
						<scale>0.001 0.001 0.001</scale>
					</mesh>
				</geometry>
			</visual>
		</link>
		<link name="key_G">
			<pose frame="">-0.02249999999999881 0.24275000000000013 0.4618251142092557 0.0 -0.0 0.0</pose>
			<inertial>
				<pose frame="">0.0 0.0 0.0 0 0 0</pose>
				<mass>0.7065000000000017</mass>
				<inertia>
					<ixx>0.19354377812642742</ixx>
					<ixy>-0.009521265000000317</ixy>
					<ixz>-0.07021202205448598</ixz>
					<iyy>0.16630013725142764</iyy>
					<iyz>-0.022011807557275286</iyz>
					<izz>0.03350794087500019</izz>
				</inertia>
			</inertial>
			<collision name="key_G_collision">
				<geometry>
					<mesh>
						<uri>model://roboy_2_0_left_arm_elbow/meshes/CAD/key_G.stl</uri>
						<scale>0.001 0.001 0.001</scale>
					</mesh>
				</geometry>
			</collision>
			<visual name="key_G_visual">
				<geometry>
					<mesh>
						<uri>model://roboy_2_0_left_arm_elbow/meshes/CAD/key_G.stl</uri>
						<scale>0.001 0.001 0.001</scale>
					</mesh>
				</geometry>
			</visual>
		</link>
		<joint name="shoulder_left_axis_1" type="revolute">
			<parent>torso</parent>
			<child>shoulder_left_link2</child>
			<pose frame="">-0.000270200396726068 -0.00011817639554919878 -0.005288740862922948 0 0 0</pose>
			<axis>
				<xyz>0.051010494316667994 0.02231024242210457 0.9984488883025681</xyz>
				<limit>
					<lower>-3.141592653589793</lower>
					<upper>3.141592653589793</upper>
				</limit>
				<use_parent_model_frame>0</use_parent_model_frame>
			</axis>
		</joint>
		<joint name="shoulder_left_axis_2" type="revolute">
			<parent>shoulder_left_link2</parent>
			<child>shoulder_left_link3</child>
			<pose frame="">0.004578533530624433 -0.002000306655299653 -0.00018921943271977827 0 0 0</pose>
			<axis>
				<xyz>-0.9157067061247516 0.40006133105988256 0.03784388654395071</xyz>
				<limit>
					<lower>-3.141592653589793</lower>
					<upper>3.141592653589793</upper>
				</limit>
				<use_parent_model_frame>0</use_parent_model_frame>
			</axis>
		</joint>
		<joint name="shoulder_left_axis_3" type="revolute">
			<parent>shoulder_left_link3</parent>
			<child>upper_arm_left</child>
			<pose frame="">0.05911843324359545 0.16877509040033034 -0.006673115707552237 0 0 0</pose>
			<axis>
				<xyz>-0.3985964849665964 -0.9162167781009379 0.04083696485553867</xyz>
				<limit>
					<lower>-3.141592653589793</lower>
					<upper>3.141592653589793</upper>
				</limit>
				<use_parent_model_frame>0</use_parent_model_frame>
			</axis>
		</joint>
		<joint name="elbow_left" type="revolute">
			<parent>upper_arm_left</parent>
			<child>lower_arm_left</child>
			<pose frame="">0.03276934558687211 0.1546796707171458 0.004781588793187244 0 0 0</pose>
			<axis>
				<xyz>0.91711553259892 -0.39841323779271304 0.012883781173668424</xyz>
				<limit>
					<lower>-3.141592653589793</lower>
					<upper>3.141592653589793</upper>
				</limit>
				<use_parent_model_frame>0</use_parent_model_frame>
			</axis>
		</joint>
		<plugin filename="libmyomuscle_plugin.so" name="myomuscle_plugin">
			<myoMuscle name="motor0">
				<link name="torso">
					<viaPoint type="FIXPOINT">0.23757805790055161 0.42944722178973777 0.015492439711174616</viaPoint>
					<viaPoint type="FIXPOINT">0.2718871356728519 0.5683871510708945 0.012838404526322811</viaPoint>
					<viaPoint type="FIXPOINT">0.28894109223784553 0.5762546353826103 0.010689615277497923</viaPoint>
				</link>
				<link name="upper_arm_left">
					<viaPoint type="FIXPOINT">0.05491580433052924 0.10841171982232496 0.017831771965319883</viaPoint>
				</link>
			</myoMuscle>
			<myoMuscle name="motor1">
				<link name="torso">
					<viaPoint type="FIXPOINT">0.24003539451940126 0.4672940494831832 0.025509439663540263</viaPoint>
				</link>
				<link name="upper_arm_left">
					<viaPoint type="FIXPOINT">0.020501914766615704 0.12321733887017047 0.01410723384316305</viaPoint>
				</link>
			</myoMuscle>
			<myoMuscle name="motor2">
				<link name="torso">
					<viaPoint type="FIXPOINT">0.2512180133128348 0.5145590997255809 0.028667405657349203</viaPoint>
				</link>
				<link name="upper_arm_left">
					<viaPoint type="FIXPOINT">0.044237920094962996 0.10944032785810763 0.010149046674318436</viaPoint>
				</link>
			</myoMuscle>
			<myoMuscle name="motor3">
				<link name="torso">
					<viaPoint type="FIXPOINT">0.28063665292590523 0.5580004259562044 0.028534400330321574</viaPoint>
				</link>
				<link name="upper_arm_left">
					<viaPoint type="FIXPOINT">0.04607031345514102 0.12741039589756034 0.012005733160551051</viaPoint>
				</link>
			</myoMuscle>
			<myoMuscle name="motor4">
				<link name="torso">
					<viaPoint type="FIXPOINT">0.30339350272539195 0.5961449530207843 -7.360778653264788e-16</viaPoint>
				</link>
				<link name="upper_arm_left">
					<viaPoint type="FIXPOINT">0.06347829624088981 0.10364936049603962 -0.005440631932115131</viaPoint>
				</link>
			</myoMuscle>
			<myoMuscle name="motor5">
				<link name="torso">
					<viaPoint type="FIXPOINT">0.2769871340021255 0.5564042514238009 -0.04289909901328127</viaPoint>
				</link>
				<link name="upper_arm_left">
					<viaPoint type="FIXPOINT">0.04432968965363042 0.12664910668643628 -0.02206419544634254</viaPoint>
				</link>
			</myoMuscle>
			<myoMuscle name="motor6">
				<link name="torso">
					<viaPoint type="FIXPOINT">0.24756132617262158 0.5129597900609095 -0.04290640006488961</viaPoint>
				</link>
				<link name="upper_arm_left">
					<viaPoint type="FIXPOINT">0.04273686141004042 0.10878381622066825 -0.01923177770926636</viaPoint>
				</link>
			</myoMuscle>
			<myoMuscle name="motor7">
				<link name="torso">
					<viaPoint type="FIXPOINT">0.23617466540192045 0.4656054988488306 -0.05005816161190855</viaPoint>
				</link>
				<link name="upper_arm_left">
					<viaPoint type="FIXPOINT">0.01999425623662898 0.12284545505075485 -0.02367904890158932</viaPoint>
				</link>
			</myoMuscle>
			<myoMuscle name="motor8">
				<link name="torso">
					<viaPoint type="FIXPOINT">0.23414595021784673 0.427938701226947 -0.053841948186743455</viaPoint>
					<viaPoint type="FIXPOINT">0.26979225356546843 0.5677688240604152 -0.026839119223290568</viaPoint>
					<viaPoint type="FIXPOINT">0.2865401700456306 0.5761408124917585 -0.026075605770313627</viaPoint>
				</link>
				<link name="upper_arm_left">
					<viaPoint type="FIXPOINT">0.05328738919638248 0.10711033026042195 -0.027260597325893914</viaPoint>
				</link>
			</myoMuscle>
			<myoMuscle name="motor10">
				<link name="upper_arm_left">
					<viaPoint type="FIXPOINT">-0.04627871246374887 -0.06774974473969295 0.041143668608891855</viaPoint>
				</link>
				<link name="lower_arm_left">
					<viaPoint type="FIXPOINT">0.03858640057855839 0.12668108856446914 0.021087573911803645</viaPoint>
				</link>
			</myoMuscle>
			<myoMuscle name="motor9">
				<link name="upper_arm_left">
					<viaPoint type="FIXPOINT">-0.0534132790641641 -0.09094006058517706 -0.02757452156276807</viaPoint>
				</link>
				<link name="lower_arm_left">
					<viaPoint type="FIXPOINT">0.040598791244850344 0.12948535208095127 -0.035443891553970173</viaPoint>
				</link>
			</myoMuscle>
		</plugin>
	</model>
</sdf>
