<?xml version="1.0" ?>
<robot name="roboy_hand_left">
  <joint name="joint0_ring" type="revolute">
    <parent link="ring_limb0"/>
    <child link="ring_limb1"/>
    <origin rpy="0  0  0" xyz="0.00665 -0.00192  0.00416"/>
    <axis xyz="-0.19826 -0.64278  0.73994"/>
    <limit effort="0.0" lower="-0.314159265359" upper="0.314159265359" velocity="0.0"/>
  </joint>
  <joint name="joint1_ring" type="revolute">
    <parent link="ring_limb1"/>
    <child link="ring_limb2"/>
    <origin rpy="0  0  0" xyz="0.00772 -0.01549 -0.05007"/>
    <axis xyz="0.96592  0       0.25881"/>
    <limit effort="0.0" lower="0.0" upper="1.91986217719" velocity="0.0"/>
  </joint>
  <joint name="joint2_ring" type="revolute">
    <parent link="ring_limb2"/>
    <child link="ring_limb3"/>
    <origin rpy="0  0  0" xyz="0.00903 -0.01226 -0.02793"/>
    <axis xyz="0.96592  0       0.25881"/>
    <limit effort="0.0" lower="0.0" upper="1.2217304764" velocity="0.0"/>
  </joint>
  <joint name="joint0_index" type="revolute">
    <parent link="index_limb0"/>
    <child link="index_limb1"/>
    <origin rpy="0  0  0" xyz="0.00763 -0.00259 -0.00049"/>
    <axis xyz="0.12941 -0.86602  0.48296"/>
    <limit effort="0.0" lower="-0.314159265359" upper="0.314159265359" velocity="0.0"/>
  </joint>
  <joint name="joint1_index" type="revolute">
    <parent link="index_limb1"/>
    <child link="index_limb2"/>
    <origin rpy="0  0  0" xyz="-0.01893  0.00266 -0.0494"/>
    <axis xyz="0.96592  0      -0.25881"/>
    <limit effort="0.0" lower="0.0" upper="1.91986217719" velocity="0.0"/>
  </joint>
  <joint name="joint2_index" type="revolute">
    <parent link="index_limb2"/>
    <child link="index_limb3"/>
    <origin rpy="0  0  0" xyz="-0.00676 -0.0015  -0.03105"/>
    <axis xyz="0.96592  0      -0.25881"/>
    <limit effort="0.0" lower="0.0" upper="1.2217304764" velocity="0.0"/>
  </joint>
  <joint name="joint0_thumb" type="revolute">
    <parent link="thumb_limb0"/>
    <child link="thumb_limb1"/>
    <origin rpy="0  0  0" xyz="-0.00445 -0.00673 -0.00026"/>
    <axis xyz="-0.60127 -0.07913  0.79511"/>
    <limit effort="0.0" lower="-0.314159265359" upper="0.314159265359" velocity="0.0"/>
  </joint>
  <joint name="joint1_thumb" type="revolute">
    <parent link="thumb_limb1"/>
    <child link="thumb_limb2"/>
    <origin rpy="0  0  0" xyz="-0.00504  0.03856 -0.03596"/>
    <axis xyz="-0.55768 -0.67107 -0.48851"/>
    <limit effort="0.0" lower="0.0" upper="1.91986217719" velocity="0.0"/>
  </joint>
  <joint name="joint2_thumb" type="revolute">
    <parent link="thumb_limb2"/>
    <child link="thumb_limb3"/>
    <origin rpy="0  0  0" xyz="-0.00823  0.02096 -0.02247"/>
    <axis xyz="-0.55768 -0.67107 -0.48851"/>
    <limit effort="0.0" lower="0.0" upper="1.2217304764" velocity="0.0"/>
  </joint>
  <joint name="joint0_little" type="revolute">
    <parent link="little_limb0"/>
    <child link="little_limb1"/>
    <origin rpy="0  0  0" xyz="0.00553 -0.00229  0.00542"/>
    <axis xyz="-0.32139 -0.76604  0.55667"/>
    <limit effort="0.0" lower="-0.314159265359" upper="0.314159265359" velocity="0.0"/>
  </joint>
  <joint name="joint1_little" type="revolute">
    <parent link="little_limb1"/>
    <child link="little_limb2"/>
    <origin rpy="0  0  0" xyz="0.02138 -0.00651 -0.04803"/>
    <axis xyz="0.86602  0       0.5"/>
    <limit effort="0.0" lower="0.0" upper="1.91986217719" velocity="0.0"/>
  </joint>
  <joint name="joint2_little" type="revolute">
    <parent link="little_limb2"/>
    <child link="little_limb3"/>
    <origin rpy="0  0  0" xyz="0.0168  -0.00699 -0.0261"/>
    <axis xyz="0.86602  0       0.5"/>
    <limit effort="0.0" lower="0.0" upper="1.2217304764" velocity="0.0"/>
  </joint>
  <joint name="palm_ring" type="revolute">
    <parent link="palm"/>
    <child link="ring_limb0"/>
    <origin rpy="0  0  0" xyz="0.01182  0.005   -0.11795"/>
    <axis xyz="-0.96592  0      -0.25881"/>
    <limit effort="0.0" lower="-0.349065850399" upper="1.2217304764" velocity="0.0"/>
  </joint>
  <joint name="palm_index" type="revolute">
    <parent link="palm"/>
    <child link="index_limb0"/>
    <origin rpy="0  0  0" xyz="-0.02731  0.005   -0.11406"/>
    <axis xyz="-0.96592  0       0.25881"/>
    <limit effort="0.0" lower="-0.349065850399" upper="1.2217304764" velocity="0.0"/>
  </joint>
  <joint name="palm_thumb" type="revolute">
    <parent link="palm"/>
    <child link="thumb_limb0"/>
    <origin rpy="0  0  0" xyz="-0.02242  0.03156 -0.06491"/>
    <axis xyz="0.35355  0.86602  0.35355"/>
    <limit effort="0.0" lower="-0.349065850399" upper="1.2217304764" velocity="0.0"/>
  </joint>
  <joint name="palm_little" type="revolute">
    <parent link="palm"/>
    <child link="little_limb0"/>
    <origin rpy="0  0  0" xyz="0.02731  0.005   -0.10516"/>
    <axis xyz="0.86602  0       0.5"/>
    <limit effort="0.0" lower="-0.349065850399" upper="1.2217304764" velocity="0.0"/>
  </joint>
  <joint name="palm_middle" type="revolute">
    <parent link="palm"/>
    <child link="middle_limb0"/>
    <origin rpy="0  0  0" xyz="0.005    0.005   -0.12125"/>
    <axis xyz="-1  0  0"/>
    <limit effort="0.0" lower="-0.349065850399" upper="1.2217304764" velocity="0.0"/>
  </joint>
  <joint name="joint0_middle" type="revolute">
    <parent link="middle_limb0"/>
    <child link="middle_limb1"/>
    <origin rpy="0  0  0" xyz="-0.005   -0.00259  0.0015"/>
    <axis xyz="0      -0.86602  0.5"/>
    <limit effort="0.0" lower="-0.610865238198" upper="0.610865238198" velocity="0.0"/>
  </joint>
  <joint name="joint1_middle" type="revolute">
    <parent link="middle_limb1"/>
    <child link="middle_limb2"/>
    <origin rpy="0  0  0" xyz="-0.0055   0.00266 -0.05262"/>
    <axis xyz="1  0  0"/>
    <limit effort="0.0" lower="0.0" upper="1.91986217719" velocity="0.0"/>
  </joint>
  <joint name="joint2_middle" type="revolute">
    <parent link="middle_limb2"/>
    <child link="middle_limb3"/>
    <origin rpy="0  0  0" xyz="0.0015  -0.0015  -0.03175"/>
    <axis xyz="1  0  0"/>
    <limit effort="0.0" lower="0.0" upper="1.2217304764" velocity="0.0"/>
  </joint>
  <link name="palm">
    <inertial>
      <mass value="15.51996490789225"/>
      <origin rpy="0  0  0" xyz="-0.0005   0.005    0.06701"/>
      <inertia ixx="0.3009526854219939" ixy="3.875011271603236e-05" ixz="-0.004755703604050438" iyy="0.30058453511478506" iyz="0.000483734858635136" izz="0.4820856721425655"/>
    </inertial>
    <collision name="palm_collision">
      <origin rpy="0  0  0" xyz="-0.0005   0.005    0.06701"/>
      <geometry>
        <mesh filename="package://roboy_models/roboy_hand_left/meshes/CAD/palm.stl" scale="0.001 0.001 0.001"/>
      </geometry>
    </collision>
    <visual name="palm_visual">
      <origin rpy="0  0  0" xyz="-0.0005   0.005    0.06701"/>
      <geometry>
        <mesh filename="package://roboy_models/roboy_hand_left/meshes/CAD/palm.stl" scale="0.001 0.001 0.001"/>
      </geometry>
    </visual>
  </link>
  <link name="ring_limb0">
    <inertial>
      <mass value="0.00042698636882981177"/>
      <origin rpy="0  0  0" xyz="0.00665 -0.00192  0.00416"/>
      <inertia ixx="5.705186481949885e-06" ixy="-4.324087879365972e-08" ixz="2.641937076803221e-07" iyy="5.8478299020484355e-06" iyz="9.311486939256466e-07" izz="1.7250855397973203e-07"/>
    </inertial>
    <collision name="ring_limb0_collision">
      <origin rpy="0  0  0" xyz="0.00665 -0.00192  0.00416"/>
      <geometry>
        <mesh filename="package://roboy_models/roboy_hand_left/meshes/CAD/ring_limb0.stl" scale="0.001 0.001 0.001"/>
      </geometry>
    </collision>
    <visual name="ring_limb0_visual">
      <origin rpy="0  0  0" xyz="0.00665 -0.00192  0.00416"/>
      <geometry>
        <mesh filename="package://roboy_models/roboy_hand_left/meshes/CAD/ring_limb0.stl" scale="0.001 0.001 0.001"/>
      </geometry>
    </visual>
  </link>
  <link name="ring_limb1">
    <inertial>
      <mass value="0.0038293627956683374"/>
      <origin rpy="0  0  0" xyz="0.00374 -0.00775 -0.01397"/>
      <inertia ixx="7.339305240733882e-05" ixy="4.5333714979377463e-07" ixz="-2.363350150911811e-06" iyy="7.562026048709583e-05" iyz="1.326758501226994e-05" izz="2.6724907739687623e-06"/>
    </inertial>
    <collision name="ring_limb1_collision">
      <origin rpy="0  0  0" xyz="0.00374 -0.00775 -0.01397"/>
      <geometry>
        <mesh filename="package://roboy_models/roboy_hand_left/meshes/CAD/ring_limb1.stl" scale="0.001 0.001 0.001"/>
      </geometry>
    </collision>
    <visual name="ring_limb1_visual">
      <origin rpy="0  0  0" xyz="0.00374 -0.00775 -0.01397"/>
      <geometry>
        <mesh filename="package://roboy_models/roboy_hand_left/meshes/CAD/ring_limb1.stl" scale="0.001 0.001 0.001"/>
      </geometry>
    </visual>
  </link>
  <link name="ring_limb2">
    <inertial>
      <mass value="0.0016247546846143888"/>
      <origin rpy="0  0  0" xyz="0.00868 -0.01059 -0.01116"/>
      <inertia ixx="4.952114754535432e-05" ixy="1.0349551422480936e-06" ixz="-5.190824251251476e-06" iyy="5.0888514110337396e-05" iyz="9.727635364613637e-06" izz="2.5202897538577816e-06"/>
    </inertial>
    <collision name="ring_limb2_collision">
      <origin rpy="0  0  0" xyz="0.00868 -0.01059 -0.01116"/>
      <geometry>
        <mesh filename="package://roboy_models/roboy_hand_left/meshes/CAD/ring_limb2.stl" scale="0.001 0.001 0.001"/>
      </geometry>
    </collision>
    <visual name="ring_limb2_visual">
      <origin rpy="0  0  0" xyz="0.00868 -0.01059 -0.01116"/>
      <geometry>
        <mesh filename="package://roboy_models/roboy_hand_left/meshes/CAD/ring_limb2.stl" scale="0.001 0.001 0.001"/>
      </geometry>
    </visual>
  </link>
  <link name="ring_limb3">
    <inertial>
      <mass value="0.0006943747393556967"/>
      <origin rpy="0  0  0" xyz="0.00589 -0.00711 -0.00654"/>
      <inertia ixx="2.7724203122666904e-05" ixy="8.04556350827874e-07" ixz="-3.88080690438467e-06" iyy="2.833338006682713e-05" iyz="5.62830242491731e-06" izz="1.7278764706781248e-06"/>
    </inertial>
    <collision name="ring_limb3_collision">
      <origin rpy="0  0  0" xyz="0.00589 -0.00711 -0.00654"/>
      <geometry>
        <mesh filename="package://roboy_models/roboy_hand_left/meshes/CAD/ring_limb3.stl" scale="0.001 0.001 0.001"/>
      </geometry>
    </collision>
    <visual name="ring_limb3_visual">
      <origin rpy="0  0  0" xyz="0.00589 -0.00711 -0.00654"/>
      <geometry>
        <mesh filename="package://roboy_models/roboy_hand_left/meshes/CAD/ring_limb3.stl" scale="0.001 0.001 0.001"/>
      </geometry>
    </visual>
  </link>
  <link name="little_limb0">
    <inertial>
      <mass value="0.00042697760738809185"/>
      <origin rpy="0  0  0" xyz="0.00553 -0.00229  0.00542"/>
      <inertia ixx="4.358718150772959e-06" ixy="-7.493171975799024e-08" ixz="2.2595565845173542e-07" iyy="4.827445330536455e-06" iyz="1.4402328836258603e-06" izz="4.972716102335973e-07"/>
    </inertial>
    <collision name="little_limb0_collision">
      <origin rpy="0  0  0" xyz="0.00553 -0.00229  0.00542"/>
      <geometry>
        <mesh filename="package://roboy_models/roboy_hand_left/meshes/CAD/little_limb0.stl" scale="0.001 0.001 0.001"/>
      </geometry>
    </collision>
    <visual name="little_limb0_visual">
      <origin rpy="0  0  0" xyz="0.00553 -0.00229  0.00542"/>
      <geometry>
        <mesh filename="package://roboy_models/roboy_hand_left/meshes/CAD/little_limb0.stl" scale="0.001 0.001 0.001"/>
      </geometry>
    </visual>
  </link>
  <link name="little_limb1">
    <inertial>
      <mass value="0.0038295299079184925"/>
      <origin rpy="0  0  0" xyz="0.00779 -0.00512 -0.0135"/>
      <inertia ixx="5.7514966584619234e-05" ixy="7.69428043763215e-08" ixz="-1.1825753341278165e-07" iyy="6.563626623073629e-05" iyz="2.1607017644695314e-05" izz="8.272843071274782e-06"/>
    </inertial>
    <collision name="little_limb1_collision">
      <origin rpy="0  0  0" xyz="0.00779 -0.00512 -0.0135"/>
      <geometry>
        <mesh filename="package://roboy_models/roboy_hand_left/meshes/CAD/little_limb1.stl" scale="0.001 0.001 0.001"/>
      </geometry>
    </collision>
    <visual name="little_limb1_visual">
      <origin rpy="0  0  0" xyz="0.00779 -0.00512 -0.0135"/>
      <geometry>
        <mesh filename="package://roboy_models/roboy_hand_left/meshes/CAD/little_limb1.stl" scale="0.001 0.001 0.001"/>
      </geometry>
    </visual>
  </link>
  <link name="little_limb2">
    <inertial>
      <mass value="0.0016247887224868657"/>
      <origin rpy="0  0  0" xyz="0.01214 -0.00768 -0.01003"/>
      <inertia ixx="3.953051894007263e-05" ixy="8.192564325235668e-07" ixz="-1.946036724757944e-06" iyy="4.633950305361068e-05" iyz="1.6500908905874007e-05" izz="7.033957594461363e-06"/>
    </inertial>
    <collision name="little_limb2_collision">
      <origin rpy="0  0  0" xyz="0.01214 -0.00768 -0.01003"/>
      <geometry>
        <mesh filename="package://roboy_models/roboy_hand_left/meshes/CAD/little_limb2.stl" scale="0.001 0.001 0.001"/>
      </geometry>
    </collision>
    <visual name="little_limb2_visual">
      <origin rpy="0  0  0" xyz="0.01214 -0.00768 -0.01003"/>
      <geometry>
        <mesh filename="package://roboy_models/roboy_hand_left/meshes/CAD/little_limb2.stl" scale="0.001 0.001 0.001"/>
      </geometry>
    </visual>
  </link>
  <link name="little_limb3">
    <inertial>
      <mass value="0.0006943841369259078"/>
      <origin rpy="0  0  0" xyz="0.00799 -0.00515 -0.00584"/>
      <inertia ixx="2.2278033154814918e-05" ixy="7.108674911360864e-07" ixz="-1.6182091500147428e-06" iyy="2.6426415270327275e-05" iyz="9.723352873712757e-06" izz="4.391842749863516e-06"/>
    </inertial>
    <collision name="little_limb3_collision">
      <origin rpy="0  0  0" xyz="0.00799 -0.00515 -0.00584"/>
      <geometry>
        <mesh filename="package://roboy_models/roboy_hand_left/meshes/CAD/little_limb3.stl" scale="0.001 0.001 0.001"/>
      </geometry>
    </collision>
    <visual name="little_limb3_visual">
      <origin rpy="0  0  0" xyz="0.00799 -0.00515 -0.00584"/>
      <geometry>
        <mesh filename="package://roboy_models/roboy_hand_left/meshes/CAD/little_limb3.stl" scale="0.001 0.001 0.001"/>
      </geometry>
    </visual>
  </link>
  <link name="thumb_limb0">
    <inertial>
      <mass value="0.0004269869854769076"/>
      <origin rpy="0  0  0" xyz="-0.00445 -0.00673 -0.00026"/>
      <inertia ixx="2.187345901376329e-06" ixy="2.6041441303855705e-07" ixz="7.068430869983882e-07" iyy="2.1860922722038135e-06" iyz="-7.087151807390433e-07" izz="5.2954710935376e-07"/>
    </inertial>
    <collision name="thumb_limb0_collision">
      <origin rpy="0  0  0" xyz="-0.00445 -0.00673 -0.00026"/>
      <geometry>
        <mesh filename="package://roboy_models/roboy_hand_left/meshes/CAD/thumb_limb0.stl" scale="0.001 0.001 0.001"/>
      </geometry>
    </collision>
    <visual name="thumb_limb0_visual">
      <origin rpy="0  0  0" xyz="-0.00445 -0.00673 -0.00026"/>
      <geometry>
        <mesh filename="package://roboy_models/roboy_hand_left/meshes/CAD/thumb_limb0.stl" scale="0.001 0.001 0.001"/>
      </geometry>
    </visual>
  </link>
  <link name="thumb_limb1">
    <inertial>
      <mass value="0.003829514276330661"/>
      <origin rpy="0  0  0" xyz="-0.00545  0.01186 -0.01007"/>
      <inertia ixx="3.466673252696076e-05" ixy="4.969993693721742e-06" ixz="1.3818308383065876e-05" iyy="3.1204944877994445e-05" iyz="-9.926992475413504e-06" izz="1.0686989874062502e-05"/>
    </inertial>
    <collision name="thumb_limb1_collision">
      <origin rpy="0  0  0" xyz="-0.00545  0.01186 -0.01007"/>
      <geometry>
        <mesh filename="package://roboy_models/roboy_hand_left/meshes/CAD/thumb_limb1.stl" scale="0.001 0.001 0.001"/>
      </geometry>
    </collision>
    <visual name="thumb_limb1_visual">
      <origin rpy="0  0  0" xyz="-0.00545  0.01186 -0.01007"/>
      <geometry>
        <mesh filename="package://roboy_models/roboy_hand_left/meshes/CAD/thumb_limb1.stl" scale="0.001 0.001 0.001"/>
      </geometry>
    </visual>
  </link>
  <link name="thumb_limb2">
    <inertial>
      <mass value="0.0016247778058410922"/>
      <origin rpy="0  0  0" xyz="-0.0106   0.00872 -0.01114"/>
      <inertia ixx="2.819866688749151e-05" ixy="4.3533460241831e-06" ixz="1.2572145783390779e-05" iyy="2.2896835264485272e-05" iyz="-7.072129742863295e-06" izz="1.0217118337391893e-05"/>
    </inertial>
    <collision name="thumb_limb2_collision">
      <origin rpy="0  0  0" xyz="-0.0106   0.00872 -0.01114"/>
      <geometry>
        <mesh filename="package://roboy_models/roboy_hand_left/meshes/CAD/thumb_limb2.stl" scale="0.001 0.001 0.001"/>
      </geometry>
    </collision>
    <visual name="thumb_limb2_visual">
      <origin rpy="0  0  0" xyz="-0.0106   0.00872 -0.01114"/>
      <geometry>
        <mesh filename="package://roboy_models/roboy_hand_left/meshes/CAD/thumb_limb2.stl" scale="0.001 0.001 0.001"/>
      </geometry>
    </visual>
  </link>
  <link name="thumb_limb3">
    <inertial>
      <mass value="0.0006943656467187061"/>
      <origin rpy="0  0  0" xyz="-0.00737  0.00516 -0.00687"/>
      <inertia ixx="1.72030364166971e-05" ixy="2.710633482504116e-06" ixz="7.943381005990716e-06" iyy="1.3278497300311874e-05" iyz="-4.056624081746005e-06" izz="6.697438090106148e-06"/>
    </inertial>
    <collision name="thumb_limb3_collision">
      <origin rpy="0  0  0" xyz="-0.00737  0.00516 -0.00687"/>
      <geometry>
        <mesh filename="package://roboy_models/roboy_hand_left/meshes/CAD/thumb_limb3.stl" scale="0.001 0.001 0.001"/>
      </geometry>
    </collision>
    <visual name="thumb_limb3_visual">
      <origin rpy="0  0  0" xyz="-0.00737  0.00516 -0.00687"/>
      <geometry>
        <mesh filename="package://roboy_models/roboy_hand_left/meshes/CAD/thumb_limb3.stl" scale="0.001 0.001 0.001"/>
      </geometry>
    </visual>
  </link>
  <link name="index_limb0">
    <inertial>
      <mass value="0.00042704116717113877"/>
      <origin rpy="0  0  0" xyz="0.00763 -0.00259 -0.00049"/>
      <inertia ixx="5.696396315690578e-06" ixy="4.352364376914485e-08" ixz="2.526333252288327e-07" iyy="5.856562158492153e-06" iyz="-9.786861419484769e-07" izz="1.8738275226371262e-07"/>
    </inertial>
    <collision name="index_limb0_collision">
      <origin rpy="0  0  0" xyz="0.00763 -0.00259 -0.00049"/>
      <geometry>
        <mesh filename="package://roboy_models/roboy_hand_left/meshes/CAD/index_limb0.stl" scale="0.001 0.001 0.001"/>
      </geometry>
    </collision>
    <visual name="index_limb0_visual">
      <origin rpy="0  0  0" xyz="0.00763 -0.00259 -0.00049"/>
      <geometry>
        <mesh filename="package://roboy_models/roboy_hand_left/meshes/CAD/index_limb0.stl" scale="0.001 0.001 0.001"/>
      </geometry>
    </visual>
  </link>
  <link name="index_limb1">
    <inertial>
      <mass value="0.003829507376002895"/>
      <origin rpy="0  0  0" xyz="-0.0042  -0.00233 -0.01569"/>
      <inertia ixx="7.514124865470068e-05" ixy="4.179435612957661e-07" ixz="2.227679305068093e-06" iyy="7.777573781621204e-05" iyz="-1.4224170065896735e-05" izz="2.846316815254311e-06"/>
    </inertial>
    <collision name="index_limb1_collision">
      <origin rpy="0  0  0" xyz="-0.0042  -0.00233 -0.01569"/>
      <geometry>
        <mesh filename="package://roboy_models/roboy_hand_left/meshes/CAD/index_limb1.stl" scale="0.001 0.001 0.001"/>
      </geometry>
    </collision>
    <visual name="index_limb1_visual">
      <origin rpy="0  0  0" xyz="-0.0042  -0.00233 -0.01569"/>
      <geometry>
        <mesh filename="package://roboy_models/roboy_hand_left/meshes/CAD/index_limb1.stl" scale="0.001 0.001 0.001"/>
      </geometry>
    </visual>
  </link>
  <link name="index_limb2">
    <inertial>
      <mass value="0.0016247911690079706"/>
      <origin rpy="0  0  0" xyz="0.0012  -0.005   -0.01675"/>
      <inertia ixx="5.140399571045076e-05" ixy="2.0283352480938564e-07" ixz="9.888273079042716e-07" iyy="5.356532861477246e-05" iyz="-1.0584698043685778e-05" izz="2.2212247949077796e-06"/>
    </inertial>
    <collision name="index_limb2_collision">
      <origin rpy="0  0  0" xyz="0.0012  -0.005   -0.01675"/>
      <geometry>
        <mesh filename="package://roboy_models/roboy_hand_left/meshes/CAD/index_limb2.stl" scale="0.001 0.001 0.001"/>
      </geometry>
    </collision>
    <visual name="index_limb2_visual">
      <origin rpy="0  0  0" xyz="0.0012  -0.005   -0.01675"/>
      <geometry>
        <mesh filename="package://roboy_models/roboy_hand_left/meshes/CAD/index_limb2.stl" scale="0.001 0.001 0.001"/>
      </geometry>
    </visual>
  </link>
  <link name="index_limb3">
    <inertial>
      <mass value="0.0006943833373514077"/>
      <origin rpy="0  0  0" xyz="0.00132 -0.0035  -0.01051"/>
      <inertia ixx="2.8861067291193085e-05" ixy="8.20490915103934e-08" ixz="3.84310202223995e-07" iyy="3.0175821782166257e-05" iyz="-6.1717782996808486e-06" izz="1.3303596105164953e-06"/>
    </inertial>
    <collision name="index_limb3_collision">
      <origin rpy="0  0  0" xyz="0.00132 -0.0035  -0.01051"/>
      <geometry>
        <mesh filename="package://roboy_models/roboy_hand_left/meshes/CAD/index_limb3.stl" scale="0.001 0.001 0.001"/>
      </geometry>
    </collision>
    <visual name="index_limb3_visual">
      <origin rpy="0  0  0" xyz="0.00132 -0.0035  -0.01051"/>
      <geometry>
        <mesh filename="package://roboy_models/roboy_hand_left/meshes/CAD/index_limb3.stl" scale="0.001 0.001 0.001"/>
      </geometry>
    </visual>
  </link>
  <link name="middle_limb0">
    <inertial>
      <mass value="0.0004269894661254721"/>
      <origin rpy="0  0  0" xyz="-0.005   -0.00259  0.0015"/>
      <inertia ixx="6.2209312152551215e-06" ixy="-2.9280517172806823e-12" ixz="2.6401612367372897e-07" iyy="6.212418826825482e-06" iyz="4.1650120476653675e-11" izz="1.8698194242482394e-08"/>
    </inertial>
    <collision name="middle_limb0_collision">
      <origin rpy="0  0  0" xyz="-0.005   -0.00259  0.0015"/>
      <geometry>
        <mesh filename="package://roboy_models/roboy_hand_left/meshes/CAD/middle_limb0.stl" scale="0.001 0.001 0.001"/>
      </geometry>
    </collision>
    <visual name="middle_limb0_visual">
      <origin rpy="0  0  0" xyz="-0.005   -0.00259  0.0015"/>
      <geometry>
        <mesh filename="package://roboy_models/roboy_hand_left/meshes/CAD/middle_limb0.stl" scale="0.001 0.001 0.001"/>
      </geometry>
    </visual>
  </link>
  <link name="middle_limb1">
    <inertial>
      <mass value="0.003829477216569819"/>
      <origin rpy="0  0  0" xyz="0      -0.00283 -0.01625"/>
      <inertia ixx="8.179745774754788e-05" ixy="-1.0101731220968801e-12" ixz="2.3248966541160553e-06" iyy="8.172897135012069e-05" iyz="1.557628547019334e-11" izz="1.4333886289551482e-07"/>
    </inertial>
    <collision name="middle_limb1_collision">
      <origin rpy="0  0  0" xyz="0      -0.00283 -0.01625"/>
      <geometry>
        <mesh filename="package://roboy_models/roboy_hand_left/meshes/CAD/middle_limb1.stl" scale="0.001 0.001 0.001"/>
      </geometry>
    </collision>
    <visual name="middle_limb1_visual">
      <origin rpy="0  0  0" xyz="0      -0.00283 -0.01625"/>
      <geometry>
        <mesh filename="package://roboy_models/roboy_hand_left/meshes/CAD/middle_limb1.stl" scale="0.001 0.001 0.001"/>
      </geometry>
    </visual>
  </link>
  <link name="middle_limb2">
    <inertial>
      <mass value="0.0016247913530675346"/>
      <origin rpy="0  0  0" xyz="0.0055  -0.0055  -0.01587"/>
      <inertia ixx="5.5779881831288704e-05" ixy="1.1170535493735535e-12" ixz="1.0301843374132322e-06" iyy="5.575946760263578e-05" iyz="-3.978389879753865e-11" izz="3.947765546601525e-08"/>
    </inertial>
    <collision name="middle_limb2_collision">
      <origin rpy="0  0  0" xyz="0.0055  -0.0055  -0.01587"/>
      <geometry>
        <mesh filename="package://roboy_models/roboy_hand_left/meshes/CAD/middle_limb2.stl" scale="0.001 0.001 0.001"/>
      </geometry>
    </collision>
    <visual name="middle_limb2_visual">
      <origin rpy="0  0  0" xyz="0.0055  -0.0055  -0.01587"/>
      <geometry>
        <mesh filename="package://roboy_models/roboy_hand_left/meshes/CAD/middle_limb2.stl" scale="0.001 0.001 0.001"/>
      </geometry>
    </visual>
  </link>
  <link name="middle_limb3">
    <inertial>
      <mass value="0.0006943748373823943"/>
      <origin rpy="0  0  0" xyz="0.004   -0.004   -0.00981"/>
      <inertia ixx="3.126942660218055e-05" ixy="9.770606143560955e-14" ixz="4.0004172461026313e-07" iyy="3.1263854150134745e-05" iyz="-3.760132469094246e-12" izz="1.0032349759270514e-08"/>
    </inertial>
    <collision name="middle_limb3_collision">
      <origin rpy="0  0  0" xyz="0.004   -0.004   -0.00981"/>
      <geometry>
        <mesh filename="package://roboy_models/roboy_hand_left/meshes/CAD/middle_limb3.stl" scale="0.001 0.001 0.001"/>
      </geometry>
    </collision>
    <visual name="middle_limb3_visual">
      <origin rpy="0  0  0" xyz="0.004   -0.004   -0.00981"/>
      <geometry>
        <mesh filename="package://roboy_models/roboy_hand_left/meshes/CAD/middle_limb3.stl" scale="0.001 0.001 0.001"/>
      </geometry>
    </visual>
  </link>
</robot>
