<?xml version="1.0" ?>
<sdf version="1.6">
	<model name="OnefingerWCasprsdf">
		<link name="palm">
			<self_collide>false</self_collide>
			<pose frame="">-0.0004955716943166135 0.005006540677194015 0.06136177594502402 0.0 -0.0 0.0</pose>
			<inertial>
				<pose frame="">0.0 0.0 0.0 0 0 0</pose>
				<mass>15.519964907892248</mass>
				<inertia>
					<ixx>0.300952685422027</ixx>
					<ixy>3.875011271679092e-05</ixy>
					<ixz>-0.004755703604047999</ixz>
					<iyy>0.3005845351148203</iyy>
					<iyz>0.0004837348586251351</iyz>
					<izz>0.4820856721425696</izz>
				</inertia>
			</inertial>
			<collision name="palm_collision">
				<geometry>
					<mesh>
						<uri>model://OnefingerWCasprsdf/meshes/CAD/palm.stl</uri>
						<scale>0.001 0.001 0.001</scale>
					</mesh>
				</geometry>
			</collision>
			<visual name="palm_visual">
				<geometry>
					<mesh>
						<uri>model://OnefingerWCasprsdf/meshes/CAD/palm.stl</uri>
						<scale>0.001 0.001 0.001</scale>
					</mesh>
				</geometry>
			</visual>
		</link>
		<link name="middle_limb0">
			<self_collide>false</self_collide>
			<pose frame="">8.078672351058662e-07 0.005136107528913899 -0.12054352867862637 0.0 -0.0 0.0</pose>
			<inertial>
				<pose frame="">0.0 0.0 0.0 0 0 0</pose>
				<mass>0.0004269894661254722</mass>
				<inertia>
					<ixx>6.220931215255127e-06</ixx>
					<ixy>-2.9280517172806823e-12</ixy>
					<ixz>2.640161236737293e-07</ixz>
					<iyy>6.212418826825487e-06</iyy>
					<iyz>4.165012047680546e-11</iyz>
					<izz>1.8698194242482417e-08</izz>
				</inertia>
			</inertial>
			<collision name="middle_limb0_collision">
				<geometry>
					<mesh>
						<uri>model://OnefingerWCasprsdf/meshes/CAD/middle_limb0.stl</uri>
						<scale>0.001 0.001 0.001</scale>
					</mesh>
				</geometry>
			</collision>
			<visual name="middle_limb0_visual">
				<geometry>
					<mesh>
						<uri>model://OnefingerWCasprsdf/meshes/CAD/middle_limb0.stl</uri>
						<scale>0.001 0.001 0.001</scale>
					</mesh>
				</geometry>
			</visual>
		</link>
		<link name="middle_limb1">
			<self_collide>false</self_collide>
			<pose frame="">3.1551509779459335e-08 0.004241487266738244 -0.14521496753967192 0.0 -0.0 0.0</pose>
			<inertial>
				<pose frame="">0.0 0.0 0.0 0 0 0</pose>
				<mass>0.003829477216634554</mass>
				<inertia>
					<ixx>8.179745773238127e-05</ixx>
					<ixy>-1.0101738763871992e-12</ixy>
					<ixz>2.324896654061824e-06</ixz>
					<iyy>8.172897133495305e-05</iyy>
					<iyz>1.5576496365204838e-11</iyz>
					<izz>1.4333886288753813e-07</izz>
				</inertia>
			</inertial>
			<collision name="middle_limb1_collision">
				<geometry>
					<mesh>
						<uri>model://OnefingerWCasprsdf/meshes/CAD/middle_limb1.stl</uri>
						<scale>0.001 0.001 0.001</scale>
					</mesh>
				</geometry>
			</collision>
			<visual name="middle_limb1_visual">
				<geometry>
					<mesh>
						<uri>model://OnefingerWCasprsdf/meshes/CAD/middle_limb1.stl</uri>
						<scale>0.001 0.001 0.001</scale>
					</mesh>
				</geometry>
			</visual>
		</link>
		<link name="middle_limb2">
			<self_collide>false</self_collide>
			<pose frame="">-1.4426906685347276e-07 0.0034702507302592635 -0.18496109042432443 0.0 -0.0 0.0</pose>
			<inertial>
				<pose frame="">0.0 0.0 0.0 0 0 0</pose>
				<mass>0.0016247913530675383</mass>
				<inertia>
					<ixx>5.5779881831287715e-05</ixx>
					<ixy>1.1170535485577339e-12</ixy>
					<ixz>1.0301843374132042e-06</ixz>
					<iyy>5.5759467602634794e-05</iyy>
					<iyz>-3.9783898768129506e-11</iyz>
					<izz>3.947765546601323e-08</izz>
				</inertia>
			</inertial>
			<collision name="middle_limb2_collision">
				<geometry>
					<mesh>
						<uri>model://OnefingerWCasprsdf/meshes/CAD/middle_limb2.stl</uri>
						<scale>0.001 0.001 0.001</scale>
					</mesh>
				</geometry>
			</collision>
			<visual name="middle_limb2_visual">
				<geometry>
					<mesh>
						<uri>model://OnefingerWCasprsdf/meshes/CAD/middle_limb2.stl</uri>
						<scale>0.001 0.001 0.001</scale>
					</mesh>
				</geometry>
			</visual>
		</link>
		<link name="middle_limb3">
			<self_collide>false</self_collide>
			<pose frame="">-2.702223533261596e-08 0.002735286136530422 -0.2120901544309756 0.0 -0.0 0.0</pose>
			<inertial>
				<pose frame="">0.0 0.0 0.0 0 0 0</pose>
				<mass>0.0006943748373823943</mass>
				<inertia>
					<ixx>3.1269426602180564e-05</ixx>
					<ixy>9.770606143494896e-14</ixy>
					<ixz>4.0004172461026313e-07</ixz>
					<iyy>3.126385415013476e-05</iyy>
					<iyz>-3.760132469054611e-12</iyz>
					<izz>1.003234975927051e-08</izz>
				</inertia>
			</inertial>
			<collision name="middle_limb3_collision">
				<geometry>
					<mesh>
						<uri>model://OnefingerWCasprsdf/meshes/CAD/middle_limb3.stl</uri>
						<scale>0.001 0.001 0.001</scale>
					</mesh>
				</geometry>
			</collision>
			<visual name="middle_limb3_visual">
				<geometry>
					<mesh>
						<uri>model://OnefingerWCasprsdf/meshes/CAD/middle_limb3.stl</uri>
						<scale>0.001 0.001 0.001</scale>
					</mesh>
				</geometry>
			</visual>
		</link>
		<joint name="palm_middle" type="revolute">
			<parent>palm</parent>
			<child>middle_limb0</child>
			<pose frame="">0.004999192132764886 -0.0001361075289138869 -0.0007064713213735807 0 0 0</pose>
			<axis>
				<xyz>-1.0000000000000089 9.930890339105123e-17 -1.4559772246072405e-17</xyz>
				<limit>
					<lower>-1.2217304763960306</lower>
					<upper>0.3490658503988659</upper>
				</limit>
				<use_parent_model_frame>0</use_parent_model_frame>
			</axis>
		</joint>
		<joint name="joint0_middle" type="revolute">
			<parent>middle_limb0</parent>
			<child>middle_limb1</child>
			<pose frame="">-3.155150978682333e-08 -0.0018395634780915455 0.025464967539671958 0 0 0</pose>
			<axis>
				<xyz>-1.468342181063722e-17 -0.8660254037844379 0.49999999999999933</xyz>
				<limit>
					<lower>-0.6108652381980153</lower>
					<upper>0.6108652381980153</upper>
				</limit>
				<use_parent_model_frame>0</use_parent_model_frame>
			</axis>
		</joint>
		<joint name="joint1_middle" type="revolute">
			<parent>middle_limb1</parent>
			<child>middle_limb2</child>
			<pose frame="">-0.005499855730933156 0.0015967365678485413 0.012586090424324325 0 0 0</pose>
			<axis>
				<xyz>1.0 -3.720545412927922e-18 2.292266993421628e-17</xyz>
				<limit>
					<lower>0.0</lower>
					<upper>1.9198621771937625</upper>
				</limit>
				<use_parent_model_frame>0</use_parent_model_frame>
			</axis>
		</joint>
		<joint name="joint2_middle" type="revolute">
			<parent>middle_limb2</parent>
			<child>middle_limb3</child>
			<pose frame="">-0.003999972977764673 0.0008317011615773851 0.007965404430975483 0 0 0</pose>
			<axis>
				<xyz>1.0 -3.720545412927922e-18 2.292266993421628e-17</xyz>
				<limit>
					<lower>0.0</lower>
					<upper>1.2217304763960306</upper>
				</limit>
				<use_parent_model_frame>0</use_parent_model_frame>
			</axis>
		</joint>
		<!--
		<plugin filename="libmusc_plugin.so" name="musc_plugin">
			<myoMuscle name="motor10">
				<link name="palm">
					<viaPoint type="FIXPOINT">-4.428305683668588e-06 -6.54067719390139e-06 -0.10534677594502345</viaPoint>
					<viaPoint type="FIXPOINT">0.001871357039953657 -0.0032594762876916182 -0.16196259799449103</viaPoint>
				</link>
				<link name="middle_limb3">
					<viaPoint type="FIXPOINT">2.7022235332537933e-08 0.004108309338733273 0.005671098685571359</viaPoint>
					<viaPoint type="FIXPOINT">0.000495436225189871 0.0035141014453948655 0.0003401544309755522</viaPoint>
					<viaPoint type="FIXPOINT">2.7022235339851487e-08 0.002732539080268032 -0.0008452683190244059</viaPoint>
				</link>
				<link name="palm">
					<viaPoint type="FIXPOINT">-0.002487569633982801 -0.006392761221833392 -0.16854565781906883</viaPoint>
					<viaPoint type="FIXPOINT">-4.4283056835907335e-06 -0.007176403479329321 -0.17465905499890486</viaPoint>
				</link>
				<link name="middle_limb1">
					<viaPoint type="FIXPOINT">-3.1551509778149186e-08 0.0065794875619666435 0.022286604710612307</viaPoint>
					<viaPoint type="FIXPOINT">0.0008658261281639573 0.005424004593123248 0.0121883033394764</viaPoint>
					<viaPoint type="FIXPOINT">-3.1551509777793995e-08 0.002295566089751302 -0.01689043726039582</viaPoint>
				</link>
				<link name="middle_limb2">
					<viaPoint type="FIXPOINT">1.4426906684792165e-07 0.004894801076867026 0.007875966169662761</viaPoint>
					<viaPoint type="FIXPOINT">0.0008001442690668403 0.004116861642815617 0.0040000852305271195</viaPoint>
					<viaPoint type="FIXPOINT">-0.0005998557309331482 0.0032095143361466328 -0.01410748567029902</viaPoint>
				</link>
			</myoMuscle>
			<myoMuscle name="motor11">
				<link name="palm">
					<viaPoint type="FIXPOINT">-4.428305683668588e-06 -6.54067719390139e-06 -0.10534677594502345</viaPoint>
					<viaPoint type="FIXPOINT">0.001871357039953657 -0.0032594762876916182 -0.16196259799449103</viaPoint>
					<viaPoint type="FIXPOINT">-0.002487569633982801 -0.006392761221833392 -0.16854565781906883</viaPoint>
					<viaPoint type="FIXPOINT">-4.4283056835907335e-06 -0.007176403479329321 -0.17465905499890486</viaPoint>
				</link>
				<link name="middle_limb1">
					<viaPoint type="FIXPOINT">-3.1551509778149186e-08 0.0065794875619666435 0.022286604710612307</viaPoint>
					<viaPoint type="FIXPOINT">0.0008658261281639573 0.005424004593123248 0.0121883033394764</viaPoint>
					<viaPoint type="FIXPOINT">-3.1551509777793995e-08 0.002295566089751302 -0.01689043726039582</viaPoint>
					<viaPoint type="FIXPOINT">-3.1551509779043e-08 -0.004174499968630464 -0.024160032460328083</viaPoint>
				</link>
				<link name="middle_limb2">
					<viaPoint type="FIXPOINT">1.4426906685347276e-07 -0.0034032634321514827 -0.0032887845756755497</viaPoint>
				</link>
			</myoMuscle>
			<myoMuscle name="motor12">
				<link name="palm">
					<viaPoint type="FIXPOINT">-4.428305683668588e-06 -6.54067719390139e-06 -0.10534677594502345</viaPoint>
					<viaPoint type="FIXPOINT">0.0022868595417944106 0.0007592631802724592 -0.16196259799449098</viaPoint>
					<viaPoint type="FIXPOINT">-0.0025054769088830938 0.0017592631802724613 -0.16891628603917525</viaPoint>
				</link>
				<link name="middle_limb1">
					<viaPoint type="FIXPOINT">-0.0009934061240109517 -0.005289421501460969 0.020283357155927995</viaPoint>
					<viaPoint type="FIXPOINT">-0.0009690301807490557 -0.005421566066127477 0.015164845242447279</viaPoint>
					<viaPoint type="FIXPOINT">-3.1551509779459335e-08 -0.004174499968630464 0.009214967539671921</viaPoint>
				</link>
			</myoMuscle>
			<myoMuscle name="motor13">
				<link name="palm">
					<viaPoint type="FIXPOINT">-0.0025035082554438126 -0.005006540677194033 -0.16196259799449103</viaPoint>
					<viaPoint type="FIXPOINT">0.0030166705057456506 -0.006537351952576679 -0.16880250806334426</viaPoint>
					<viaPoint type="FIXPOINT">0.0044955716943164085 -0.0072573865319053785 -0.17701291020123627</viaPoint>
				</link>
				<link name="middle_limb1">
					<viaPoint type="FIXPOINT">-3.1551509834450064e-08 -0.00043538939594892247 0.017726064025082255</viaPoint>
					<viaPoint type="FIXPOINT">-0.005458490904164179 -0.00045273396414719836 0.014625651800278519</viaPoint>
					<viaPoint type="FIXPOINT">-0.004609871495936185 0.00032550003136953663 0.010214967539671918</viaPoint>
				</link>
			</myoMuscle>
			<myoMuscle name="motor14">
				<link name="palm">
					<viaPoint type="FIXPOINT">-4.428305683668588e-06 -6.54067719390139e-06 -0.10534677594502345</viaPoint>
					<viaPoint type="FIXPOINT">-0.0025035082554438126 -0.005006540677194033 -0.16196259799449103</viaPoint>
					<viaPoint type="FIXPOINT">-0.002487569633982801 -0.006392761221833392 -0.16854565781906883</viaPoint>
					<viaPoint type="FIXPOINT">-0.004504428305683671 -0.007257386531905377 -0.17701291020123625</viaPoint>
				</link>
				<link name="middle_limb1">
					<viaPoint type="FIXPOINT">-3.1551509834450064e-08 -0.00043538939594892247 0.017726064025082255</viaPoint>
					<viaPoint type="FIXPOINT">0.005458427801144619 -0.00045273396414719614 0.014625651800278519</viaPoint>
					<viaPoint type="FIXPOINT">0.004609808392916627 0.00032550003136953663 0.010214967539671918</viaPoint>
				</link>
			</myoMuscle>
		</plugin>
		-->
	</model>
</sdf>
