<?xml version="1.0" ?>
<robot name="roboy_2_0_left_arm_simplified">
  <joint name="shoulder_left_axis_1" type="revolute">
    <parent link="torso"/>
    <child link="shoulder_left_joint_link_2"/>
    <origin rpy="0 0 0" xyz="0.28733  0.59432 -0.01833"/>
    <axis xyz="0.05101 0.02231 0.99844"/>
    <limit effort="0.0" lower="0" upper="1.57" velocity="0.0"/>
  </joint>
  <joint name="shoulder_left_axis_2" type="revolute">
    <parent link="shoulder_left_joint_link_2"/>
    <child link="shoulder_left_joint_link_3"/>
    <origin rpy="0 0 0" xyz="0.00523 0.00022 0.00443"/>
    <axis xyz="-0.99836 -0.02463  0.05155"/>
    <limit effort="0.0" lower="-1.57" upper="1.57" velocity="0.0"/>
  </joint>
  <!--<joint name="elbow_left" type="revolute">-->
    <!--<parent link="upper_arm_left"/>-->
    <!--<child link="lower_arm_left"/>-->
    <!--<origin rpy="0 0 0" xyz="-0.01004 -0.31059  0.00492"/>-->
    <!--<axis xyz="9.9969e-01  2.4640e-02 -8.0000e-04"/>-->
    <!--<limit effort="0.0" lower="-0.0" upper="1.57079632679" velocity="0.0"/>-->
  <!--</joint>-->
  <joint name="shoulder_left_axis_3" type="revolute">
    <parent link="shoulder_left_joint_link_3"/>
    <child link="upper_arm_left"/>
    <origin rpy="0 0 0" xyz="-0.00523 -0.01313  0.00028"/>
    <axis xyz="2.4640e-02 -9.9969e-01 -2.9000e-04"/>
    <limit effort="0.0" lower="-1.57" upper="1.57" velocity="0.0"/>
  </joint>
  <!--<link name="lower_arm_left">-->
    <!--<inertial>-->
      <!--<mass value="1"/>-->
      <!--<origin rpy="0 0 0" xyz="0.01684 -0.00459  0.03548"/>-->
      <!--<inertia ixx="0.1" ixy="0" ixz="0" iyy="0.1" iyz="0" izz="0.1"/>-->
    <!--</inertial>-->
    <!--<collision name="lower_arm_left_collision">-->
      <!--<origin rpy="0 0 0" xyz="0.01684 -0.00459  0.03548"/>-->
      <!--<geometry>-->
        <!--<mesh filename="package://roboy_models/roboy_2_0_left_arm_simplified/meshes/CAD/lower_arm_left.stl" scale="0.001 0.001 0.001"/>-->
      <!--</geometry>-->
    <!--</collision>-->
    <!--<visual name="lower_arm_left_visual">-->
      <!--<origin rpy="0 0 0" xyz="0.01684 -0.00459  0.03548"/>-->
      <!--<geometry>-->
        <!--<mesh filename="package://roboy_models/roboy_2_0_left_arm_simplified/meshes/CAD/lower_arm_left.stl" scale="0.001 0.001 0.001"/>-->
      <!--</geometry>-->
    <!--</visual>-->
  <!--</link>-->
  <link name="upper_arm_left">
    <inertial>
      <mass value="1"/>
      <origin rpy="0 0 0" xyz="0.00065 -0.02649  0"/>
      <inertia ixx="0.1" ixy="0" ixz="0" iyy="0.1" iyz="0" izz="0.1"/>
    </inertial>
    <collision name="upper_arm_left_collision">
      <origin rpy="0 0 0" xyz="0.00065 -0.02649  0"/>
      <geometry>
        <mesh filename="package://roboy_models/roboy_2_0_left_arm_simplified/meshes/CAD/upper_arm_left.stl" scale="0.001 0.001 0.001"/>
      </geometry>
    </collision>
    <visual name="upper_arm_left_visual">
      <origin rpy="0 0 0" xyz="0.00065 -0.02649  0"/>
      <geometry>
        <mesh filename="package://roboy_models/roboy_2_0_left_arm_simplified/meshes/CAD/upper_arm_left.stl" scale="0.001 0.001 0.001"/>
      </geometry>
    </visual>
  </link>
  <link name="torso">
    <inertial>
      <mass value="404.9569214971351"/>
      <origin rpy="0 0 0" xyz="-0.005   -0.0035  -0.00567"/>
      <inertia ixx="81.03068172597067" ixy="-0.10385664003910905" ixz="0.0019322581064099833" iyy="154.73194275802973" iyz="-0.006106937920817667" izz="81.24329218684868"/>
    </inertial>
    <collision name="torso_collision">
      <origin rpy="0 0 0" xyz="-0.005   -0.0035  -0.00567"/>
      <geometry>
        <mesh filename="package://roboy_models/roboy_2_0_left_arm_simplified/meshes/CAD/torso.stl" scale="0.001 0.001 0.001"/>
      </geometry>
    </collision>
    <visual name="torso_visual">
      <origin rpy="0 0 0" xyz="-0.005   -0.0035  -0.00567"/>
      <geometry>
        <mesh filename="package://roboy_models/roboy_2_0_left_arm_simplified/meshes/CAD/torso.stl" scale="0.001 0.001 0.001"/>
      </geometry>
    </visual>
  </link>
  <link name="shoulder_left_joint_link_2">
    <inertial>
      <mass value="0.01"/>
      <origin rpy="0 0 0" xyz="-0.0002  -0.0049   0.00472"/>
      <inertia ixx="0.1" ixy="0" ixz="0" iyy="0.1" iyz="0" izz="0.1"/>
    </inertial>
    <collision name="shoulder_left_joint_link_2_collision">
      <origin rpy="0 0 0" xyz="-0.0002  -0.0049   0.00472"/>
      <geometry>
        <mesh filename="package://roboy_models/roboy_2_0_left_arm_simplified/meshes/CAD/shoulder_left_joint_link_2.stl" scale="0.001 0.001 0.001"/>
      </geometry>
    </collision>
    <visual name="shoulder_left_joint_link_2_visual">
      <origin rpy="0 0 0" xyz="-0.0002  -0.0049   0.00472"/>
      <geometry>
        <mesh filename="package://roboy_models/roboy_2_0_left_arm_simplified/meshes/CAD/shoulder_left_joint_link_2.stl" scale="0.001 0.001 0.001"/>
      </geometry>
    </visual>
  </link>
  <link name="shoulder_left_joint_link_3">
    <inertial>
      <mass value="0.01"/>
      <origin rpy="0 0 0" xyz="-0.00543 -0.00513  0.00028"/>
      <inertia ixx="0.1" ixy="0" ixz="0" iyy="0.1" iyz="0" izz="0.1"/>
    </inertial>
    <collision name="shoulder_left_joint_link_3_collision">
      <origin rpy="0 0 0" xyz="-0.00543 -0.00513  0.00028"/>
      <geometry>
        <mesh filename="package://roboy_models/roboy_2_0_left_arm_simplified/meshes/CAD/shoulder_left_joint_link_3.stl" scale="0.001 0.001 0.001"/>
      </geometry>
    </collision>
    <visual name="shoulder_left_joint_link_3_visual">
      <origin rpy="0 0 0" xyz="-0.00543 -0.00513  0.00028"/>
      <geometry>
        <mesh filename="package://roboy_models/roboy_2_0_left_arm_simplified/meshes/CAD/shoulder_left_joint_link_3.stl" scale="0.001 0.001 0.001"/>
      </geometry>
    </visual>
  </link>
</robot>
