<?xml version="1.0" ?>
<sdf version="1.6">
	<model name="roboy_2_0_left_arm_simplified">

		<!--<link name="lower_arm_left">-->
			<!--<pose frame="">0.2941390263982024 0.26622759368394755 0.026799075858034458 0.0 -0.0 0.0</pose>-->
			<!--<inertial>-->
				<!--<pose frame="">0.0 0.0 0.0 0 0 0</pose>-->
				<!--<mass>1</mass>-->
				<!--<inertia>-->
					<!--<ixx>0.1</ixx>-->
					<!--<ixy>0</ixy>-->
					<!--<ixz>0</ixz>-->
					<!--<iyy>0.1</iyy>-->
					<!--<iyz>0</iyz>-->
					<!--<izz>0.1</izz>-->
				<!--</inertia>-->
			<!--</inertial>-->
			<!--<collision name="lower_arm_left_collision">-->
				<!--<geometry>-->
					<!--<mesh>-->
						<!--<uri>model://roboy_2_0_left_arm_simplified/meshes/CAD/lower_arm_left.stl</uri>-->
						<!--<scale>0.001 0.001 0.001</scale>-->
					<!--</mesh>-->
				<!--</geometry>-->
			<!--</collision>-->
			<!--<visual name="lower_arm_left_visual">-->
				<!--<geometry>-->
					<!--<mesh>-->
						<!--<uri>model://roboy_2_0_left_arm_simplified/meshes/CAD/lower_arm_left.stl</uri>-->
						<!--<scale>0.001 0.001 0.001</scale>-->
					<!--</mesh>-->
				<!--</geometry>-->
			<!--</visual>-->
		<!--</link>-->
		<link name="upper_arm_left">
			<pose frame="">0.28798862680022014 0.5549254668876651 -0.013618040340742264 0.0 -0.0 0.0</pose>
			<inertial>
				<pose frame="">0.0 0.0 0.0 0 0 0</pose>
				<mass>1</mass>
				<inertia>
					<ixx>0.1</ixx>
					<ixy>0</ixy>
					<ixz>0</ixz>
					<iyy>0.1</iyy>
					<iyz>0</iyz>
					<izz>0.1</izz>
				</inertia>
			</inertial>
			<collision name="upper_arm_left_collision">
				<geometry>
					<mesh>
						<uri>model://roboy_2_0_left_arm_simplified/meshes/CAD/upper_arm_left.stl</uri>
						<scale>0.001 0.001 0.001</scale>
					</mesh>
				</geometry>
			</collision>
			<visual name="upper_arm_left_visual">
				<geometry>
					<mesh>
						<uri>model://roboy_2_0_left_arm_simplified/meshes/CAD/upper_arm_left.stl</uri>
						<scale>0.001 0.001 0.001</scale>
					</mesh>
				</geometry>
			</visual>
		</link>
		<link name="torso">
			<pose frame="">-0.004999999999998519 -0.0035000000000000144 -0.00567488579074407 0.0 -0.0 0.0</pose>
			<inertial>
				<pose frame="">0.0 0.0 0.0 0 0 0</pose>
				<mass>404.9569214971351</mass>
				<inertia>
					<ixx>81.03068172597067</ixx>
					<ixy>-0.10385664003910905</ixy>
					<ixz>0.0019322581064099833</ixz>
					<iyy>154.73194275802973</iyy>
					<iyz>-0.006106937920817667</iyz>
					<izz>81.24329218684868</izz>
				</inertia>
			</inertial>
			<collision name="torso_collision">
				<geometry>
					<mesh>
						<uri>model://roboy_2_0_left_arm_simplified/meshes/CAD/torso.stl</uri>
						<scale>0.001 0.001 0.001</scale>
					</mesh>
				</geometry>
			</collision>
			<visual name="torso_visual">
				<geometry>
					<mesh>
						<uri>model://roboy_2_0_left_arm_simplified/meshes/CAD/torso.stl</uri>
						<scale>0.001 0.001 0.001</scale>
					</mesh>
				</geometry>
			</visual>
		</link>
		<link name="shoulder_left_joint_link_2">
			<pose frame="">0.28713512179275735 0.5894179501767453 -0.013607855949266324 0.0 -0.0 0.0</pose>
			<inertial>
				<pose frame="">0.0 0.0 0.0 0 0 0</pose>
				<mass>0.01</mass>
				<inertia>
					<ixx>0.1</ixx>
					<ixy>0</ixy>
					<ixz>0</ixz>
					<iyy>0.1</iyy>
					<iyz>0</iyz>
					<izz>0.1</izz>
				</inertia>
			</inertial>
			<collision name="shoulder_left_joint_link_2_collision">
				<geometry>
					<mesh>
						<uri>model://roboy_2_0_left_arm_simplified/meshes/CAD/shoulder_left_joint_link_2.stl</uri>
						<scale>0.001 0.001 0.001</scale>
					</mesh>
				</geometry>
			</collision>
			<visual name="shoulder_left_joint_link_2_visual">
				<geometry>
					<mesh>
						<uri>model://roboy_2_0_left_arm_simplified/meshes/CAD/shoulder_left_joint_link_2.stl</uri>
						<scale>0.001 0.001 0.001</scale>
					</mesh>
				</geometry>
			</visual>
		</link>
		<link name="shoulder_left_joint_link_3">
			<pose frame="">0.28713512179275713 0.5894179501767447 -0.013607855949266296 0.0 -0.0 0.0</pose>
			<inertial>
				<pose frame="">0.0 0.0 0.0 0 0 0</pose>
				<mass>0.01</mass>
				<inertia>
					<ixx>0.1</ixx>
					<ixy>0</ixy>
					<ixz>0</ixz>
					<iyy>0.1</iyy>
					<iyz>0</iyz>
					<izz>0.1</izz>
				</inertia>
			</inertial>
			<collision name="shoulder_left_joint_link_3_collision">
				<geometry>
					<mesh>
						<uri>model://roboy_2_0_left_arm_simplified/meshes/CAD/shoulder_left_joint_link_3.stl</uri>
						<scale>0.001 0.001 0.001</scale>
					</mesh>
				</geometry>
			</collision>
			<visual name="shoulder_left_joint_link_3_visual">
				<geometry>
					<mesh>
						<uri>model://roboy_2_0_left_arm_simplified/meshes/CAD/shoulder_left_joint_link_3.stl</uri>
						<scale>0.001 0.001 0.001</scale>
					</mesh>
				</geometry>
			</visual>
		</link>
		<!--<link name="hand_left">-->
			<!--<pose frame="">0.287078998659723 0.5078150620301657 0.417830876996003 0.0 -0.0 0.0</pose>-->
			<!--<inertial>-->
				<!--<pose frame="">0.0 0.0 0.0 0 0 0</pose>-->
				<!--<mass>1</mass>-->
				<!--<inertia>-->
					<!--<ixx>0.1</ixx>-->
					<!--<ixy>0</ixy>-->
					<!--<ixz>0</ixz>-->
					<!--<iyy>0.1</iyy>-->
					<!--<iyz>0</iyz>-->
					<!--<izz>0.1</izz>-->
				<!--</inertia>-->
			<!--</inertial>-->
			<!--<collision name="hand_left_collision">-->
				<!--<geometry>-->
					<!--<mesh>-->
						<!--<uri>model://roboy_2_0_left_arm_simplified/meshes/CAD/hand_left.stl</uri>-->
						<!--<scale>0.001 0.001 0.001</scale>-->
					<!--</mesh>-->
				<!--</geometry>-->
			<!--</collision>-->
			<!--<visual name="hand_left_visual">-->
				<!--<geometry>-->
					<!--<mesh>-->
						<!--<uri>model://roboy_2_0_left_arm_simplified/meshes/CAD/hand_left.stl</uri>-->
						<!--<scale>0.001 0.001 0.001</scale>-->
					<!--</mesh>-->
				<!--</geometry>-->
			<!--</visual>-->
		<!--</link>-->
		<joint name="shoulder_left_axis_1" type="revolute">
			<parent>torso</parent>
			<child>shoulder_left_joint_link_2</child>
			<pose frame="">0.00019951945882407785 0.00490743658684032 -0.0047233517011995565 0 0 0</pose>
			<axis>
				<xyz>0.051010494316667994 0.02231024242210457 0.9984488883025681</xyz>
				<limit>
					<lower>0</lower>
					<upper>1.57</upper>
				</limit>
				<use_parent_model_frame>0</use_parent_model_frame>
			</axis>
		</joint>
		<joint name="shoulder_left_axis_2" type="revolute">
			<parent>shoulder_left_joint_link_2</parent>
			<child>shoulder_left_joint_link_3</child>
			<pose frame="">0.005431255365339957 0.00513551882804812 -0.0002853869619396554 0 0 0</pose>
			<axis>
				<xyz>-0.9983662720150784 -0.02463124250686317 0.051556656168533395</xyz>
				<limit>
					<lower>-1.57</lower>
					<upper>1.57</upper>
				</limit>
				<use_parent_model_frame>0</use_parent_model_frame>
			</axis>
		</joint>
		<joint name="shoulder_left_axis_3" type="revolute">
			<parent>shoulder_left_joint_link_3</parent>
			<child>upper_arm_left</child>
			<pose frame="">-0.000653199659423791 0.026491947283847708 7.70160822393784e-06 0 0 0</pose>
			<axis>
				<xyz>0.024649043751837536 -0.9996961239187773 -0.00029062672542217393</xyz>
				<limit>
					<lower>-1.57</lower>
					<upper>1.57</upper>
				</limit>
				<use_parent_model_frame>0</use_parent_model_frame>
			</axis>
		</joint>
		<!--<joint name="wrist_left" type="revolute">-->
			<!--<parent>lower_arm_left</parent>-->
			<!--<child>hand_left</child>-->
			<!--<pose frame="">0.007242263387563313 -0.24164862319449779 -0.16521568193271033 0 0 0</pose>-->
			<!--<axis>-->
				<!--<xyz>-0.02384168391198873 -0.000607586479966071 0.9997155620209742</xyz>-->
				<!--<limit>-->
					<!--<lower>-1.5707963267948966</lower>-->
					<!--<upper>1.5707963267948966</upper>-->
				<!--</limit>-->
				<!--<use_parent_model_frame>0</use_parent_model_frame>-->
			<!--</axis>-->
		<!--</joint>-->
		<!--<joint name="elbow_left" type="revolute">-->
			<!--<parent>upper_arm_left</parent>-->
			<!--<child>lower_arm_left</child>-->
			<!--<pose frame="">-0.016846814765604387 0.004596451889486168 -0.035485421788837894 0 0 0</pose>-->
			<!--<axis>-->
				<!--<xyz>0.9996958404329833 0.024649269359735267 -0.0008000881366474141</xyz>-->
				<!--<limit>-->
					<!--<lower>-0.0</lower>-->
					<!--<upper>1.5707963267948966</upper>-->
				<!--</limit>-->
				<!--<use_parent_model_frame>0</use_parent_model_frame>-->
			<!--</axis>-->
		<!--</joint>-->
		<plugin filename="libmyomuscle_plugin.so" name="myomuscle_plugin">
			<myoMuscle name="motor0">
				<link name="torso">
					<viaPoint type="FIXPOINT">0.23757805790055153 0.47944722178973864 0.015492439711174609</viaPoint>
					<viaPoint type="FIXPOINT">0.2718871356728518 0.6183871510708954 0.012838404526322802</viaPoint>
					<viaPoint type="FIXPOINT">0.2889410922378454 0.6262546353826112 0.010689615277497917</viaPoint>
				</link>
				<link name="upper_arm_left">
					<viaPoint type="FIXPOINT">0.024643010975561916 -0.030889028077830505 0.018157453982060336</viaPoint>
				</link>
			</myoMuscle>
			<myoMuscle name="motor1">
				<link name="torso">
					<viaPoint type="FIXPOINT">0.24003539451940115 0.517294049483184 0.02550943966354026</viaPoint>
				</link>
				<link name="upper_arm_left">
					<viaPoint type="FIXPOINT">-0.014973610842486416 -0.03186661393800385 0.02083081693210307</viaPoint>
				</link>
			</myoMuscle>
			<myoMuscle name="motor2">
				<link name="torso">
					<viaPoint type="FIXPOINT">0.25121801331283466 0.5645590997255817 0.0286674056573492</viaPoint>
				</link>
				<link name="upper_arm_left">
					<viaPoint type="FIXPOINT">0.002322440484976696 -0.031442804581393986 0.029950951418864773</viaPoint>
				</link>
			</myoMuscle>
			<myoMuscle name="motor3">
				<link name="torso">
					<viaPoint type="FIXPOINT">0.2806366529259052 0.6080004259562052 0.028534400330321567</viaPoint>
				</link>
				<link name="upper_arm_left">
					<viaPoint type="FIXPOINT">0.021298410479614702 -0.030972572861495067 0.021867341448528265</viaPoint>
				</link>
			</myoMuscle>
			<myoMuscle name="motor4">
				<link name="torso">
					<viaPoint type="FIXPOINT">0.30339350272539184 0.6461449530207852 -7.438494264988549e-16</viaPoint>
				</link>
				<link name="upper_arm_left">
					<viaPoint type="FIXPOINT">0.030726984210491574 -0.03073328741678381 -0.001555849134958922</viaPoint>
				</link>
			</myoMuscle>
			<myoMuscle name="motor5">
				<link name="torso">
					<viaPoint type="FIXPOINT">0.23414595021784665 0.47793870122694787 -0.05384194818674346</viaPoint>
					<viaPoint type="FIXPOINT">0.2697922535654683 0.617768824060416 -0.02683911922329058</viaPoint>
					<viaPoint type="FIXPOINT">0.2865401700456305 0.6261408124917593 -0.026075605770313634</viaPoint>
				</link>
				<link name="upper_arm_left">
					<viaPoint type="FIXPOINT">0.01893690959321905 -0.031017498896779544 -0.023883286999316414</viaPoint>
				</link>
			</myoMuscle>
			<myoMuscle name="motor6">
				<link name="torso">
					<viaPoint type="FIXPOINT">0.27698713400212543 0.6064042514238017 -0.042899099013281275</viaPoint>
				</link>
				<link name="upper_arm_left">
					<viaPoint type="FIXPOINT">0.01893690959321905 -0.031017498896779544 -0.023883286999316414</viaPoint>
				</link>
			</myoMuscle>
			<myoMuscle name="motor7">
				<link name="torso">
					<viaPoint type="FIXPOINT">0.24756132617262147 0.5629597900609103 -0.04290640006488962</viaPoint>
				</link>
				<link name="upper_arm_left">
					<viaPoint type="FIXPOINT">-0.003242745493337296 -0.031562709512321235 -0.029603165480376815</viaPoint>
				</link>
			</myoMuscle>
			<myoMuscle name="motor8">
				<link name="torso">
					<viaPoint type="FIXPOINT">0.23617466540192034 0.5156054988488314 -0.050058161611908555</viaPoint>
				</link>
				<link name="upper_arm_left">
					<viaPoint type="FIXPOINT">-0.018032235047571385 -0.03193108236932467 -0.016823397177565348</viaPoint>
				</link>
			</myoMuscle>
			<!--<myoMuscle name="motor9">-->
				<!--<link name="upper_arm_left">-->
					<!--<viaPoint type="FIXPOINT">0.007773818467739489 -0.23307858925470734 0.032792709973664944</viaPoint>-->
				<!--</link>-->
				<!--<link name="lower_arm_left">-->
					<!--<viaPoint type="FIXPOINT">-0.00025803579214635165 0.010124378815315289 -0.010497302969137392</viaPoint>-->
				<!--</link>-->
			<!--</myoMuscle>-->
			<!--<myoMuscle name="motor10">-->
				<!--<link name="upper_arm_left">-->
					<!--<viaPoint type="FIXPOINT">0.004343548774037877 -0.24983500811143927 -0.03475989047540426</viaPoint>-->
				<!--</link>-->
				<!--<link name="lower_arm_left">-->
					<!--<viaPoint type="FIXPOINT">0.0008712160915301937 -0.03588441931306747 -0.016965149240829893</viaPoint>-->
				<!--</link>-->
			<!--</myoMuscle>-->
		</plugin>
	</model>
</sdf>
